Workbook
Name FID_1: [1]AGR_Fuels!$A$2

Sheet Cover
A3: Colour code
B4: Referenced data (columns and rows headers)
B5: Own calculations (columns and rows headers)
B6: Own assumptions (columns and rows headers)
A7: aaa | B7: Results
B8: Sheets which contains input tables for the RES BY-Template
B9: Sheets which contains input tables (not activated) for the building retrofit SubRes (SubRES_RsdRetrofits_Trans.xlsx)

Sheet TechComm
T1: Vintages
B2: MovedToSysSettings | K2: ~FI_Process | T2: 1 | U2: < 1945 | V2: 1940 | Y2: 12 | Z2: kw equipment
B3: Csets | C3: CommName | D3: CommDesc | E3: Unit | F3: LimType | G3: CTSLvl | H3: PeakTS | I3: Ctype | K3: Sets | L3: TechName | M3: TechDesc | N3: Tact | O3: Tcap | P3: Tslvl | Q3: PrimaryCG | R3: Vintage | T3: 2 | U3: 1945-1969 | V3: 1957 | Y3: 0.25 | Z3: utilization
B4: DEM | C4: ="R_"&U11 -> R_Flat | D4: =M4 & " (DEM)" -> Residential Dwelling - Flat (DEM) | E4: =O4 -> 000units | K4: DMD | L4: ="Rdw_"&U11 -> Rdw_Flat | M4: ="Residential Dwelling - "&T11 -> Residential Dwelling - Flat | N4: 000units | O4: 000units | R4: Yes | T4: 3 | U4: 1970-1979 | V4: 1975 | Y4: =Y2*8.76*Y3*3.6 -> 94.608 | Z4: GJ
C5: ="R_"&U13 -> R_DetH | D5: =M5 & " (DEM)" -> Residential Dwelling - Detached house 1945 to 1969 (DEM) | E5: =O5 -> 000units | L5: ="Rdw_"&U13 -> Rdw_DetH | M5: ="Residential Dwelling - "&T13 -> Residential Dwelling - Detached house 1945 to 1969 | N5: 000units | O5: 000units | R5: Yes | T5: 4 | U5: 1980-1989 | V5: 1985
C6: ="R_"&U15 -> R_SDetH | D6: =M7 & " (DEM)" -> Residential Dwelling - Semi-detached house (DEM) | E6: =O7 -> 000units | L6: ="Rdw_"&U14 -> Rdw_DetH-70 | M6: ="Residential Dwelling - "&T14 -> Residential Dwelling - Detached house 1970 to 2010 | N6: 000units | O6: 000units | R6: Yes | T6: 5 | U6: 1990-1999 | V6: 1995
C7: ='TechELC-RES'!E4 -> RLIG | D7: ="Residential - "&X15& " (DEM)" -> Residential - Lighting (DEM) | E7: =N90 -> M_appliances | L7: ="Rdw_"&U15 -> Rdw_SDetH | M7: ="Residential Dwelling - "&T15 -> Residential Dwelling - Semi-detached house | N7: 000units | O7: 000units | R7: Yes | T7: 6 | U7: 2000-2008 | V7: 2004
C8: ='TechELC-RES'!E21 -> RREF | D8: ="Residential - "&X16& " (DEM)" -> Residential - Refrigerators and freezers (DEM) | E8: =N91 -> M_appliances | K8: PRE | L8: ="R_ES-SH-FL_"&RIGHT(U23,3)&"-R" -> R_ES-SH-FL_ELC-R | M8: ="Residential boiler for sp heat - "&$T$11&" : "&T23&" Resistance" -> Residential boiler for sp heat - Flat : Electricity Resistance | N8: PJ | O8: GW | R8: Yes
C9: ='TechELC-RES'!E38 -> RCWA | D9: ="Residential - "&X17& " (DEM)" -> Residential - Washing machine (DEM) | E9: =N92 -> M_appliances | L9: ="R_ES-SH-FL_"&RIGHT(U23,3)&"-HPA" -> R_ES-SH-FL_ELC-HPA | M9: ="Residential boiler for sp heat - "&$T$11&" : "&T23&" Heat Pump Air" -> Residential boiler for sp heat - Flat : Electricity Heat Pump Air | N9: PJ | O9: GW | R9: Yes
C10: ='TechELC-RES'!E55 -> RCDR | D10: ="Residential - "&X18& " (DEM)" -> Residential - Clothes dryer (DEM) | E10: =N93 -> M_appliances | L10: ="R_ES-SH-FL_"&RIGHT(U23,3)&"-HPG" -> R_ES-SH-FL_ELC-HPG | M10: ="Residential boiler for sp heat - "&$T$11&" : "&T23&" Heat Pump Ground" -> Residential boiler for sp heat - Flat : Electricity Heat Pump Ground | N10: PJ | O10: GW | R10: Yes
C11: ='TechELC-RES'!E72 -> RDWA | D11: ="Residential - "&X19& " (DEM)" -> Residential - Dishwasher (DEM) | E11: =N94 -> M_appliances | L11: ="R_ES-SH-FL_"&RIGHT(U24,3) -> R_ES-SH-FL_GAS | M11: ="Residential boiler for sp heat - "&$T$11&" : "&T24 -> Residential boiler for sp heat - Flat : Gases | N11: PJ | O11: GW | R11: Yes | T11: Flat | U11: Flat | V11: FL
C12: ='TechELC-RES'!E89 -> ROEL | D12: ="Residential - "&X20& " (DEM)" -> Residential - Other ELC (DEM) | E12: =N95 -> M_appliances | L12: ="R_ES-SH-FL_"&RIGHT(U25,3) -> R_ES-SH-FL_HET | M12: ="Residential boiler for sp heat - "&$T$11&" : "&T25 -> Residential boiler for sp heat - Flat : Derived heat | N12: PJ | O12: GW | R12: Yes | T12: Detached house
B13: NRG | C13: ="R_ES-"&V11&"-"&$U$18 -> R_ES-FL-Cook | D13: ="Residential Energy Service for - "&T11&" - "&$T$18 -> Residential Energy Service for - Flat - Cooking | E13: PJ | L13: ="R_ES-SH-FL_"&RIGHT(U26,3) -> R_ES-SH-FL_OIL | M13: ="Residential boiler for sp heat - "&$T$11&" : "&T26 -> Residential boiler for sp heat - Flat : GDO and other liquids (incl. liq. bio.) | N13: PJ | O13: GW | R13: Yes | T13: Detached house 1945 to 1969 | U13: DetH | V13: DH
C14: ="R_ES-"&V13&"-"&$U$18 -> R_ES-DH-Cook | D14: ="Residential Energy Service for - "&T12&" - "&$T$18 -> Residential Energy Service for - Detached house - Cooking | E14: PJ | L14: ="R_ES-SH-FL_"&RIGHT(U27,3) -> R_ES-SH-FL_BIO | M14: ="Residential boiler for sp heat - "&$T$11&" : "&T27 -> Residential boiler for sp heat - Flat : Biomass and wastes | N14: PJ | O14: GW | R14: Yes | T14: Detached house 1970 to 2010 | U14: DetH-70 | V14: DH-70
C15: ="R_ES-"&V15&"-"&$U$18 -> R_ES-SD-Cook | D15: ="Residential Energy Service for - "&T15&" - "&$T$18 -> Residential Energy Service for - Semi-detached house - Cooking | E15: PJ | L15: ="R_ES-SH-FL_"&RIGHT(U28,3) -> R_ES-SH-FL_COA | M15: ="Residential boiler for sp heat - "&$T$11&" : "&T28 -> Residential boiler for sp heat - Flat : Solids | N15: PJ | O15: GW | R15: Yes | T15: Semi-detached house | U15: SDetH | V15: SD | X15: ='TechELC-RES'!A3 -> Lighting
C16: ="R_ES-"&V11&"-"&$U$19 -> R_ES-FL-SpCool | D16: ="Residential Energy Service for - "&T11&" - "&$T$19 -> Residential Energy Service for - Flat - Cooling | E16: PJ | L16: ="R_ES-SH-FL_"&RIGHT(U29,3) -> R_ES-SH-FL_LPG | M16: ="Residential boiler for sp heat - "&$T$11&" : "&T29 -> Residential boiler for sp heat - Flat : LPG | N16: PJ | O16: GW | R16: Yes | X16: ='TechELC-RES'!A20 -> Refrigerators and freezers
C17: ="R_ES-"&V13&"-"&$U$19 -> R_ES-DH-SpCool | D17: ="Residential Energy Service for - "&T12&" - "&$T$19 -> Residential Energy Service for - Detached house - Cooling | E17: PJ | L17: ="R_ES-SH-FL_"&RIGHT(U31,3) -> R_ES-SH-FL_GEO | M17: ="Residential boiler for sp heat - "&$T$11&" : "&T31 -> Residential boiler for sp heat - Flat : Geothermal Energy | N17: PJ | O17: GW | R17: Yes | X17: ='TechELC-RES'!A37 -> Washing machine
C18: ="R_ES-"&V15&"-"&$U$19 -> R_ES-SD-SpCool | D18: ="Residential Energy Service for - "&T15&" - "&$T$19 -> Residential Energy Service for - Semi-detached house - Cooling | E18: PJ | L18: ="R_ES-SH-DH_"&RIGHT(U23,3)&"-R" -> R_ES-SH-DH_ELC-R | M18: ="Residential boiler for sp heat - "&$T$13&" : "&T23&" Resistance" -> Residential boiler for sp heat - Detached house 1945 to 1969 : Electricity Resistance | N18: PJ | O18: GW | R18: Yes | T18: Cooking | U18: Cook | V18: CK | X18: ='TechELC-RES'!A54 -> Clothes dryer
C19: ="R_ES-"&V11&"-"&$U$21 -> R_ES-FL-WatHeat | D19: ="Residential Energy Service for - "&T11&" - "&$T$21 -> Residential Energy Service for - Flat - Water heating | E19: PJ | L19: ="R_ES-SH-DH_"&RIGHT(U23,3)&"-HPA" -> R_ES-SH-DH_ELC-HPA | M19: ="Residential boiler for sp heat - "&$T$13&" : "&T23&" Heat Pump Air" -> Residential boiler for sp heat - Detached house 1945 to 1969 : Electricity Heat Pump Air | N19: PJ | O19: GW | R19: Yes | T19: Cooling | U19: SpCool | V19: SC | X19: ='TechELC-RES'!A71 -> Dishwasher
C20: ="R_ES-"&V13&"-"&$U$21 -> R_ES-DH-WatHeat | D20: ="Residential Energy Service for - "&T12&" - "&$T$21 -> Residential Energy Service for - Detached house - Water heating | E20: PJ | L20: ="R_ES-SH-DH_"&RIGHT(U23,3)&"-HPG" -> R_ES-SH-DH_ELC-HPG | M20: ="Residential boiler for sp heat - "&$T$13&" : "&T23&" Heat Pump Ground" -> Residential boiler for sp heat - Detached house 1945 to 1969 : Electricity Heat Pump Ground | N20: PJ | O20: GW | R20: Yes | T20: Space heating | U20: SpHeat | V20: SH | X20: ='TechELC-RES'!A88 -> Other ELC
C21: ="R_ES-"&V15&"-"&$U$21 -> R_ES-SD-WatHeat | D21: ="Residential Energy Service for - "&T15&" - "&$T$21 -> Residential Energy Service for - Semi-detached house - Water heating | E21: PJ | L21: ="R_ES-SH-DH_"&RIGHT(U24,3) -> R_ES-SH-DH_GAS | M21: ="Residential boiler for sp heat - "&$T$13&" : "&T24 -> Residential boiler for sp heat - Detached house 1945 to 1969 : Gases | N21: PJ | O21: GW | R21: Yes | T21: Water heating | U21: WatHeat | V21: WH
C22: ="R_ES-"&V11&"-"&$U$20 -> R_ES-FL-SpHeat | D22: ="Residential Energy Service for - "&T11&" - "&$T$20 -> Residential Energy Service for - Flat - Space heating | E22: PJ | L22: ="R_ES-SH-DH_"&RIGHT(U25,3) -> R_ES-SH-DH_HET | M22: ="Residential boiler for sp heat - "&$T$13&" : "&T25 -> Residential boiler for sp heat - Detached house 1945 to 1969 : Derived heat | N22: PJ | O22: GW | R22: Yes
C23: ="R_ES-"&V13&"-"&$U$20 -> R_ES-DH-SpHeat | D23: ="Residential Energy Service for - "&T12&" - "&$T$20 -> Residential Energy Service for - Detached house - Space heating | E23: PJ | L23: ="R_ES-SH-DH_"&RIGHT(U26,3) -> R_ES-SH-DH_OIL | M23: ="Residential boiler for sp heat - "&$T$13&" : "&T26 -> Residential boiler for sp heat - Detached house 1945 to 1969 : GDO and other liquids (incl. liq. bio.) | N23: PJ | O23: GW | R23: Yes | T23: Electricity | U23: RSDELC
C24: ="R_ES-"&V15&"-"&$U$20 -> R_ES-SD-SpHeat | D24: ="Residential Energy Service for - "&T15&" - "&$T$20 -> Residential Energy Service for - Semi-detached house - Space heating | E24: PJ | L24: ="R_ES-SH-DH_"&RIGHT(U27,3) -> R_ES-SH-DH_BIO | M24: ="Residential boiler for sp heat - "&$T$13&" : "&T27 -> Residential boiler for sp heat - Detached house 1945 to 1969 : Biomass and wastes | N24: PJ | O24: GW | R24: Yes | T24: Gases | U24: RSDGAS
C25: =U23 -> RSDELC | D25: ="Residential Fuel - "&T23 -> Residential Fuel - Electricity | E25: PJ | G25: DAYNITE | I25: ELC | L25: ="R_ES-SH-DH_"&RIGHT(U28,3) -> R_ES-SH-DH_COA | M25: ="Residential boiler for sp heat - "&$T$13&" : "&T28 -> Residential boiler for sp heat - Detached house 1945 to 1969 : Solids | N25: PJ | O25: GW | R25: Yes | T25: Derived heat | U25: RSDHET
C26: =U24 -> RSDGAS | D26: ="Residential Fuel - "&T24 -> Residential Fuel - Gases | E26: PJ | G26: SEASON | L26: ="R_ES-SH-DH_"&RIGHT(U29,3) -> R_ES-SH-DH_LPG | M26: ="Residential boiler for sp heat - "&$T$13&" : "&T29 -> Residential boiler for sp heat - Detached house 1945 to 1969 : LPG | N26: PJ | O26: GW | R26: Yes | T26: GDO and other liquids (incl. liq. bio.) | U26: RSDOIL
C27: =U25 -> RSDHET | D27: ="Residential Fuel - "&T25 -> Residential Fuel - Derived heat | E27: PJ | G27: SEASON | L27: ="R_ES-SH-DH_"&RIGHT(U31,3) -> R_ES-SH-DH_GEO | M27: ="Residential boiler for sp heat - "&$T$13&" : "&T31 -> Residential boiler for sp heat - Detached house 1945 to 1969 : Geothermal Energy | N27: PJ | O27: GW | R27: Yes | T27: Biomass and wastes | U27: RSDBIO
C28: =U26 -> RSDOIL | D28: ="Residential Fuel - "&T26 -> Residential Fuel - GDO and other liquids (incl. liq. bio.) | E28: PJ | L28: ="R_ES-SH-DH-70_"&RIGHT(U23,3)&"-R" -> R_ES-SH-DH-70_ELC-R | M28: ="Residential boiler for sp heat - "&$T$14&" : "&T23&" Resistance" -> Residential boiler for sp heat - Detached house 1970 to 2010 : Electricity Resistance | N28: PJ | O28: GW | R28: Yes | T28: Solids | U28: RSDCOA
C29: =U27 -> RSDBIO | D29: ="Residential Fuel - "&T27 -> Residential Fuel - Biomass and wastes | E29: PJ | L29: ="R_ES-SH-DH-70_"&RIGHT(U23,3)&"-HPA" -> R_ES-SH-DH-70_ELC-HPA | M29: ="Residential boiler for sp heat - "&$T$14&" : "&T23&" Heat Pump Air" -> Residential boiler for sp heat - Detached house 1970 to 2010 : Electricity Heat Pump Air | N29: PJ | O29: GW | R29: Yes | T29: LPG | U29: RSDLPG
C30: =U28 -> RSDCOA | D30: ="Residential Fuel - "&T28 -> Residential Fuel - Solids | E30: PJ | L30: ="R_ES-SH-DH-70_"&RIGHT(U23,3)&"-HPG" -> R_ES-SH-DH-70_ELC-HPG | M30: ="Residential boiler for sp heat - "&$T$14&" : "&T23&" Heat Pump Ground" -> Residential boiler for sp heat - Detached house 1970 to 2010 : Electricity Heat Pump Ground | N30: PJ | O30: GW | R30: Yes | T30: Solar | U30: RSDSOL
C31: =U29 -> RSDLPG | D31: ="Residential Fuel - "&T29 -> Residential Fuel - LPG | E31: PJ | L31: ="R_ES-SH-DH-70_"&RIGHT(U24,3) -> R_ES-SH-DH-70_GAS | M31: ="Residential boiler for sp heat - "&$T$14&" : "&T24 -> Residential boiler for sp heat - Detached house 1970 to 2010 : Gases | N31: PJ | O31: GW | R31: Yes | T31: Geothermal Energy | U31: RSDGEO
C32: =U30 -> RSDSOL | D32: ="Residential Fuel - "&T30 -> Residential Fuel - Solar | E32: PJ | L32: ="R_ES-SH-DH-70_"&RIGHT(U25,3) -> R_ES-SH-DH-70_HET | M32: ="Residential boiler for sp heat - "&$T$14&" : "&T25 -> Residential boiler for sp heat - Detached house 1970 to 2010 : Derived heat | N32: PJ | O32: GW | R32: Yes
B33: ENV | C33: RSDCO2N | D33: Carbon Dioxide - RSDbustion (RSD) | E33: kt | L33: ="R_ES-SH-DH-70_"&RIGHT(U26,3) -> R_ES-SH-DH-70_OIL | M33: ="Residential boiler for sp heat - "&$T$14&" : "&T26 -> Residential boiler for sp heat - Detached house 1970 to 2010 : GDO and other liquids (incl. liq. bio.) | N33: PJ | O33: GW | R33: Yes
C34: RSDCOXN | D34: Carbon Monoxide - RSDbustion (RSD) | E34: kt | L34: ="R_ES-SH-DH-70_"&RIGHT(U27,3) -> R_ES-SH-DH-70_BIO | M34: ="Residential boiler for sp heat - "&$T$14&" : "&T27 -> Residential boiler for sp heat - Detached house 1970 to 2010 : Biomass and wastes | N34: PJ | O34: GW | R34: Yes
C35: RSDCH4N | D35: Methane - RSDbustion (RSD) | E35: kt | L35: ="R_ES-SH-DH-70_"&RIGHT(U28,3) -> R_ES-SH-DH-70_COA | M35: ="Residential boiler for sp heat - "&$T$14&" : "&T28 -> Residential boiler for sp heat - Detached house 1970 to 2010 : Solids | N35: PJ | O35: GW | R35: Yes
C36: RSDSO2N | D36: Sulphur Dioxide - RSDbustion (RSD) | E36: kt | L36: ="R_ES-SH-DH-70_"&RIGHT(U29,3) -> R_ES-SH-DH-70_LPG | M36: ="Residential boiler for sp heat - "&$T$14&" : "&T29 -> Residential boiler for sp heat - Detached house 1970 to 2010 : LPG | N36: PJ | O36: GW | R36: Yes
C37: RSDNOXN | D37: Nitrogen Oxides - RSDbustion (RSD) | E37: kt | L37: ="R_ES-SH-DH-70_"&RIGHT(U31,3) -> R_ES-SH-DH-70_GEO | M37: ="Residential boiler for sp heat - "&$T$14&" : "&T31 -> Residential boiler for sp heat - Detached house 1970 to 2010 : Geothermal Energy | N37: PJ | O37: GW | R37: Yes
C38: RSDN2ON | D38: Nitrous Oxide - RSDbustion (RSD) | E38: kt | L38: ="R_ES-SH-SD_"&RIGHT(U23,3)&"-R" -> R_ES-SH-SD_ELC-R | M38: ="Residential boiler for sp heat - "&$T$15&" : "&T23&" Resistance" -> Residential boiler for sp heat - Semi-detached house : Electricity Resistance | N38: PJ | O38: GW | R38: Yes
C39: RSDPMAN | D39: Particulate 2.5 - RSDbustion (RSD) | E39: kt | L39: ="R_ES-SH-SD_"&RIGHT(U23,3)&"-HPA" -> R_ES-SH-SD_ELC-HPA | M39: ="Residential boiler for sp heat - "&$T$15&" : "&T23&" Heat Pump Air" -> Residential boiler for sp heat - Semi-detached house : Electricity Heat Pump Air | N39: PJ | O39: GW | R39: Yes
C40: RSDPMBN | D40: Particulate 10 - RSDbustion (RSD) | E40: kt | L40: ="R_ES-SH-SD_"&RIGHT(U23,3)&"-HPG" -> R_ES-SH-SD_ELC-HPG | M40: ="Residential boiler for sp heat - "&$T$15&" : "&T23&" Heat Pump Ground" -> Residential boiler for sp heat - Semi-detached house : Electricity Heat Pump Ground | N40: PJ | O40: GW | R40: Yes
...

Sheet Dwelling stock
A1: Dwellings stock according to construction date | M1: Dwellings stock according to construction date and dwelling type
A2: Source: ENTRANZE | O2: =E3 -> < 1945 | R2: =F3 -> 1945-1969 | U2: =G3 -> 1970-1979 | X2: =H3 -> 1980-1989 | AA2: =I3 -> 1990-1999 | AD2: =J3 -> 2000-2008 | AI2: TOTAL
A3: Code | B3: Country | C3: Source | D3: Unit | E3: < 1945 | F3: 1945-1969 | G3: 1970-1979 | H3: 1980-1989 | I3: 1990-1999 | J3: 2000-2008 | K3: Total dwelling | M3: Country | N3: Unit | O3: ='Data by dwelling type'!H3 -> Flat | P3: ='Data by dwelling type'!I3 -> Detached house | Q3: ='Data by dwelling type'!J3 -> Semi-detached house | R3: =O3 -> Flat | S3: =P3 -> Detached house | T3: =Q3 -> Semi-detached house | U3: =R3 -> Flat | V3: =S3 -> Detached house | W3: =T3 -> Semi-detached house | X3: =U3 -> Flat | Y3: =V3 -> Detached house | ... AF3: =AC3 -> Semi-detached house | AI3: Flat | AJ3: Detached house | AK3: Semi-detached house | AL3: Check
A4: AL | B4: Albania | C4: own assumptions | D4: thousands | E4: =$K$4*(E15/$K$15) -> 88.574382 | F4: =$K$4*(F15/$K$15) -> 322.35404 | G4: =$K$4*(G15/$K$15) -> 256.857 | H4: =$K$4*(H15/$K$15) -> 196.62105 | I4: =$K$4*(I15/$K$15) -> 132.27652 | J4: =$K$4*(J15/$K$15) -> 67.363711 | K4: =Population!E48/(Population!$E$49/'Dwelling stock'!$K$36) -> 1064.0467 | M4: Albania | N4: thousands | O4: =E4*'Data by dwelling type'!AA4 -> 52.739169 | P4: =E4*'Data by dwelling type'!AB4 -> 22.891748 | Q4: =E4*'Data by dwelling type'!AC4 -> 12.943465 | R4: =F4*'Data by dwelling type'!AA4 -> 191.93681 | S4: =F4*'Data by dwelling type'!AB4 -> 83.311308 | T4: =F4*'Data by dwelling type'!AC4 -> 47.105927 | U4: =G4*'Data by dwelling type'!AA4 -> 152.9384 | V4: =G4*'Data by dwelling type'!AB4 -> 66.38382 | W4: =G4*'Data by dwelling type'!AC4 -> 37.534777 | X4: =H4*'Data by dwelling type'!AA4 -> 117.07257 | Y4: =H4*'Data by dwelling type'!AB4 -> 50.816043 | Z4: =H4*'Data by dwelling type'!AC4 -> 28.732436 | AA4: =I4*'Data by dwelling type'!AA4 -> 78.760401 | AB4: =I4*'Data by dwelling type'!AB4 -> 34.186418 | AC4: =I4*'Data by dwelling type'!AC4 -> 19.329704 | AD4: =J4*'Data by dwelling type'!AA4 -> 40.10986 | AE4: =J4*'Data by dwelling type'!AB4 -> 17.409923 | AF4: =J4*'Data by dwelling type'!AC4 -> 9.8439281 | AI4: =O4+R4+U4+X4+AA4+AD4 -> 633.55721 | AJ4: =P4+S4+V4+Y4+AB4+AE4 -> 274.99926 | AK4: =Q4+T4+W4+Z4+AC4+AF4 -> 155.49024 | AL4: =AI4-'Data by dwelling type'!W4 -> 0 | AM4: =AJ4-'Data by dwelling type'!Y4 -> 0 | AN4: =AK4-'Data by dwelling type'!Z4 -> 0
A5: AT | B5: Austria | C5: ENTRANZE | D5: thousands | E5: 858.82293 | F5: 1036.1925 | G5: 533.14752 | H5: 423.02085 | I5: 504.88341 | J5: 206.42195 | K5: =SUM(E5:J5) -> 3562.4891 | M5: Austria | N5: thousands | O5: =E5*'Data by dwelling type'!AA5 -> 426.88055 | P5: =E5*'Data by dwelling type'!AB5 -> 295.16062 | Q5: =E5*'Data by dwelling type'!AC5 -> 136.78175 | R5: =F5*'Data by dwelling type'!AA5 -> 515.04262 | S5: =F5*'Data by dwelling type'!AB5 -> 356.11906 | T5: =F5*'Data by dwelling type'!AC5 -> 165.03078 | U5: =G5*'Data by dwelling type'!AA5 -> 265.0026 | V5: =G5*'Data by dwelling type'!AB5 -> 183.23236 | W5: =G5*'Data by dwelling type'!AC5 -> 84.912558 | X5: =H5*'Data by dwelling type'!AA5 -> 210.2638 | Y5: =H5*'Data by dwelling type'!AB5 -> 145.38398 | Z5: =H5*'Data by dwelling type'!AC5 -> 67.373065 | AA5: =I5*'Data by dwelling type'!AA5 -> 250.95384 | AB5: =I5*'Data by dwelling type'!AB5 -> 173.51854 | AC5: =I5*'Data by dwelling type'!AC5 -> 80.411032 | AD5: =J5*'Data by dwelling type'!AA5 -> 102.60266 | AE5: =J5*'Data by dwelling type'!AB5 -> 70.943181 | AF5: =J5*'Data by dwelling type'!AC5 -> 32.876108 | AI5: =O5+R5+U5+X5+AA5+AD5 -> 1770.7461 | AJ5: =P5+S5+V5+Y5+AB5+AE5 -> 1224.3578 | AK5: =Q5+T5+W5+Z5+AC5+AF5 -> 567.3853 | AL5: =AI5-'Data by dwelling type'!W5 -> -0.25393595 | AM5: =AJ5-'Data by dwelling type'!Y5 -> -0.17558048 | AN5: =AK5-'Data by dwelling type'!Z5 -> -0.081366566
A6: BA | B6: Bosnia | C6: own assumptions | D6: thousands | E6: =$K$6*(E36/$K$36) -> 168.33106 | F6: =$K$6*(F36/$K$36) -> 384.31833 | G6: =$K$6*(G36/$K$36) -> 286.93488 | H6: =$K$6*(H36/$K$36) -> 242.50514 | I6: =$K$6*(I36/$K$36) -> 118.8608 | J6: =$K$6*(J36/$K$36) -> 89.260258 | K6: =Population!E53/(Population!$E$49/'Dwelling stock'!$K$36) -> 1290.2105 | M6: Bosnia | N6: thousands | O6: =E6*'Data by dwelling type'!AA6 -> 79.510186 | P6: =E6*'Data by dwelling type'!AB6 -> 65.41159 | Q6: =E6*'Data by dwelling type'!AC6 -> 23.409285 | R6: =F6*'Data by dwelling type'!AA6 -> 181.5305 | S6: =F6*'Data by dwelling type'!AB6 -> 149.34186 | T6: =F6*'Data by dwelling type'!AC6 -> 53.445972 | U6: =G6*'Data by dwelling type'!AA6 -> 135.532 | V6: =G6*'Data by dwelling type'!AB6 -> 111.49972 | W6: =G6*'Data by dwelling type'!AC6 -> 39.903154 | X6: =H6*'Data by dwelling type'!AA6 -> 114.54588 | Y6: =H6*'Data by dwelling type'!AB6 -> 94.234818 | Z6: =H6*'Data by dwelling type'!AC6 -> 33.724447 | AA6: =I6*'Data by dwelling type'!AA6 -> 56.1432 | AB6: =I6*'Data by dwelling type'!AB6 -> 46.187994 | AC6: =I6*'Data by dwelling type'!AC6 -> 16.529608 | AD6: =J6*'Data by dwelling type'!AA6 -> 42.161557 | AE6: =J6*'Data by dwelling type'!AB6 -> 34.68555 | AF6: =J6*'Data by dwelling type'!AC6 -> 12.413151 | AI6: =O6+R6+U6+X6+AA6+AD6 -> 609.42332 | AJ6: =P6+S6+V6+Y6+AB6+AE6 -> 501.36153 | AK6: =Q6+T6+W6+Z6+AC6+AF6 -> 179.42562 | AL6: =AI6-'Data by dwelling type'!W6 -> 0 | AM6: =AJ6-'Data by dwelling type'!Y6 -> 0 | AN6: =AK6-'Data by dwelling type'!Z6 -> 0
A7: BE | B7: Belgium | C7: ENTRANZE | D7: thousands | E7: 1789.7143 | F7: 994.28571 | G7: 538.09524 | H7: 538.09524 | I7: 396.37202 | J7: 266.4375 | K7: =SUM(E7:J7) -> 4523 | M7: Belgium | N7: thousands | O7: =E7*'Data by dwelling type'!AA7 -> 470.89407 | P7: =E7*'Data by dwelling type'!AB7 -> 494.22455 | Q7: =E7*'Data by dwelling type'!AC7 -> 824.59567 | R7: =F7*'Data by dwelling type'!AA7 -> 261.60781 | S7: =F7*'Data by dwelling type'!AB7 -> 274.56919 | T7: =F7*'Data by dwelling type'!AC7 -> 458.10871 | U7: =G7*'Data by dwelling type'!AA7 -> 141.57894 | V7: =G7*'Data by dwelling type'!AB7 -> 148.59348 | W7: =G7*'Data by dwelling type'!AC7 -> 247.92282 | X7: =H7*'Data by dwelling type'!AA7 -> 141.57894 | Y7: =H7*'Data by dwelling type'!AB7 -> 148.59348 | Z7: =H7*'Data by dwelling type'!AC7 -> 247.92282 | AA7: =I7*'Data by dwelling type'!AA7 -> 104.28996 | AB7: =I7*'Data by dwelling type'!AB7 -> 109.45702 | AC7: =I7*'Data by dwelling type'!AC7 -> 182.62505 | AD7: =J7*'Data by dwelling type'!AA7 -> 70.102719 | AE7: =J7*'Data by dwelling type'!AB7 -> 73.575963 | AF7: =J7*'Data by dwelling type'!AC7 -> 122.75882 | AI7: =O7+R7+U7+X7+AA7+AD7 -> 1190.0524 | AJ7: =P7+S7+V7+Y7+AB7+AE7 -> 1249.0137 | AK7: =Q7+T7+W7+Z7+AC7+AF7 -> 2083.9339 | AL7: =AI7-'Data by dwelling type'!W7 -> 1.0524452 | AM7: =AJ7-'Data by dwelling type'!Y7 -> 1.1045887 | AN7: =AK7-'Data by dwelling type'!Z7 -> 1.8429661
A8: BG | B8: Bulgaria | C8: ENTRANZE | D8: thousands | E8: 435.86831 | F8: 902.31451 | G8: 523.15295 | H8: 492.98588 | I8: 284.70819 | J8: 442.97017 | K8: =SUM(E8:J8) -> 3082 | M8: Bulgaria | N8: thousands | O8: =E8*'Data by dwelling type'!AA8 -> 195.86716 | P8: =E8*'Data by dwelling type'!AB8 -> 155.4937 | Q8: =E8*'Data by dwelling type'!AC8 -> 84.507446 | R8: =F8*'Data by dwelling type'!AA8 -> 405.47518 | S8: =F8*'Data by dwelling type'!AB8 -> 321.8959 | T8: =F8*'Data by dwelling type'!AC8 -> 174.94342 | U8: =G8*'Data by dwelling type'!AA8 -> 235.09046 | V8: =G8*'Data by dwelling type'!AB8 -> 186.63203 | W8: =G8*'Data by dwelling type'!AC8 -> 101.43045 | X8: =H8*'Data by dwelling type'!AA8 -> 221.53422 | Y8: =H8*'Data by dwelling type'!AB8 -> 175.87009 | Z8: =H8*'Data by dwelling type'!AC8 -> 95.58157 | AA8: =I8*'Data by dwelling type'!AA8 -> 127.93999 | AB8: =I8*'Data by dwelling type'!AB8 -> 101.56813 | AC8: =I8*'Data by dwelling type'!AC8 -> 55.200072 | AD8: =J8*'Data by dwelling type'!AA8 -> 199.05854 | AE8: =J8*'Data by dwelling type'!AB8 -> 158.02725 | AF8: =J8*'Data by dwelling type'!AC8 -> 85.884377 | AI8: =O8+R8+U8+X8+AA8+AD8 -> 1384.9655 | AJ8: =P8+S8+V8+Y8+AB8+AE8 -> 1099.4871 | AK8: =Q8+T8+W8+Z8+AC8+AF8 -> 597.54734 | AL8: =AI8-'Data by dwelling type'!W8 -> 0 | AM8: =AJ8-'Data by dwelling type'!Y8 -> 0 | AN8: =AK8-'Data by dwelling type'!Z8 -> 0
A9: CH | B9: Switzerland | C9: ODYSSEE | D9: thousands | E9: =$K$9*(E5/$K$5) -> 933.00397 | F9: =$K$9*(F5/$K$5) -> 1125.6938 | G9: =$K$9*(G5/$K$5) -> 579.19827 | H9: =$K$9*(H5/$K$5) -> 459.55938 | I9: =$K$9*(I5/$K$5) -> 548.49284 | J9: =$K$9*(J5/$K$5) -> 224.25169 | K9: 3870.2 | M9: Switzerland | N9: thousands | O9: =E9*'Data by dwelling type'!AA9 -> 447.84191 | P9: =E9*'Data by dwelling type'!AB9 -> 228.65064 | Q9: =E9*'Data by dwelling type'!AC9 -> 256.51143 | R9: =F9*'Data by dwelling type'!AA9 -> 540.33305 | S9: =F9*'Data by dwelling type'!AB9 -> 275.87301 | T9: =F9*'Data by dwelling type'!AC9 -> 309.48779 | U9: =G9*'Data by dwelling type'!AA9 -> 278.01517 | V9: =G9*'Data by dwelling type'!AB9 -> 141.94372 | W9: =G9*'Data by dwelling type'!AC9 -> 159.23938 | X9: =H9*'Data by dwelling type'!AA9 -> 220.5885 | Y9: =H9*'Data by dwelling type'!AB9 -> 112.6239 | Z9: =H9*'Data by dwelling type'!AC9 -> 126.34698 | AA9: =I9*'Data by dwelling type'!AA9 -> 263.27656 | AB9: =I9*'Data by dwelling type'!AB9 -> 134.41876 | AC9: =I9*'Data by dwelling type'!AC9 -> 150.79752 | AD9: =J9*'Data by dwelling type'!AA9 -> 107.64081 | AE9: =J9*'Data by dwelling type'!AB9 -> 54.957207 | AF9: =J9*'Data by dwelling type'!AC9 -> 61.653674 | AI9: =O9+R9+U9+X9+AA9+AD9 -> 1857.696 | AJ9: =P9+S9+V9+Y9+AB9+AE9 -> 948.46723 | AK9: =Q9+T9+W9+Z9+AC9+AF9 -> 1064.0368 | AL9: =AI9-'Data by dwelling type'!W9 -> 0 | AM9: =AJ9-'Data by dwelling type'!Y9 -> 0 | AN9: =AK9-'Data by dwelling type'!Z9 -> 0
A10: CY | B10: Cyprus | C10: ENTRANZE | D10: thousands | E10: 9.054403 | F10: 30.167848 | G10: 40.839057 | H10: 58.956254 | I10: 50.836032 | J10: 109.3034 | K10: =SUM(E10:J10) -> 299.157 | M10: Cyprus | N10: thousands | O10: =E10*'Data by dwelling type'!AA10 -> 2.5426748 | P10: =E10*'Data by dwelling type'!AB10 -> 3.2215918 | Q10: =E10*'Data by dwelling type'!AC10 -> 3.2901364 | R10: =F10*'Data by dwelling type'!AA10 -> 8.4717929 | S10: =F10*'Data by dwelling type'!AB10 -> 10.733838 | T10: =F10*'Data by dwelling type'!AC10 -> 10.962217 | U10: =G10*'Data by dwelling type'!AA10 -> 11.468502 | V10: =G10*'Data by dwelling type'!AB10 -> 14.530696 | W10: =G10*'Data by dwelling type'!AC10 -> 14.839859 | X10: =H10*'Data by dwelling type'!AA10 -> 16.556208 | Y10: =H10*'Data by dwelling type'!AB10 -> 20.976865 | Z10: =H10*'Data by dwelling type'!AC10 -> 21.423181 | AA10: =I10*'Data by dwelling type'!AA10 -> 14.275872 | AB10: =I10*'Data by dwelling type'!AB10 -> 18.087658 | AC10: =I10*'Data by dwelling type'!AC10 -> 18.472502 | AD10: =J10*'Data by dwelling type'!AA10 -> 30.694792 | AE10: =J10*'Data by dwelling type'!AB10 -> 38.890577 | AF10: =J10*'Data by dwelling type'!AC10 -> 39.718036 | AI10: =O10+R10+U10+X10+AA10+AD10 -> 84.009842 | AJ10: =P10+S10+V10+Y10+AB10+AE10 -> 106.44123 | AK10: =Q10+T10+W10+Z10+AC10+AF10 -> 108.70593 | AL10: =AI10-'Data by dwelling type'!W10 -> -2.8082191e-07 | AM10: =AJ10-'Data by dwelling type'!Y10 -> -3.5580389e-07 | AN10: =AK10-'Data by dwelling type'!Z10 -> -3.6337418e-07
A11: CZ | B11: Czech Rep. | C11: ENTRANZE | D11: thousands | E11: 963.51411 | F11: 1308.6011 | G11: 536.20286 | H11: 621.51031 | I11: 320.81903 | J11: 242.35264 | K11: =SUM(E11:J11) -> 3993 | M11: Czech Rep. | N11: thousands | O11: =E11*'Data by dwelling type'!AA11 -> 553.47062 | P11: =E11*'Data by dwelling type'!AB11 -> 257.44503 | Q11: =E11*'Data by dwelling type'!AC11 -> 152.59846 | R11: =F11*'Data by dwelling type'!AA11 -> 751.69863 | S11: =F11*'Data by dwelling type'!AB11 -> 349.65013 | T11: =F11*'Data by dwelling type'!AC11 -> 207.25229 | U11: =G11*'Data by dwelling type'!AA11 -> 308.01057 | V11: =G11*'Data by dwelling type'!AB11 -> 143.27009 | W11: =G11*'Data by dwelling type'!AC11 -> 84.922193 | X11: =H11*'Data by dwelling type'!AA11 -> 357.01366 | Y11: =H11*'Data by dwelling type'!AB11 -> 166.06372 | Z11: =H11*'Data by dwelling type'!AC11 -> 98.43293 | AA11: =I11*'Data by dwelling type'!AA11 -> 184.28781 | AB11: =I11*'Data by dwelling type'!AB11 -> 85.720864 | AC11: =I11*'Data by dwelling type'!AC11 -> 50.810351 | AD11: =J11*'Data by dwelling type'!AA11 -> 139.21443 | AE11: =J11*'Data by dwelling type'!AB11 -> 64.755131 | AF11: =J11*'Data by dwelling type'!AC11 -> 38.383082 | AI11: =O11+R11+U11+X11+AA11+AD11 -> 2293.6957 | AJ11: =P11+S11+V11+Y11+AB11+AE11 -> 1066.905 | AK11: =Q11+T11+W11+Z11+AC11+AF11 -> 632.39931 | AL11: =AI11-'Data by dwelling type'!W11 -> 0 | AM11: =AJ11-'Data by dwelling type'!Y11 -> 0 | AN11: =AK11-'Data by dwelling type'!Z11 -> 0
A12: DE | B12: Germany | C12: ENTRANZE | D12: thousands | E12: 8480.6087 | F12: 12872.758 | G12: 6635.2386 | H12: 4624.6154 | I12: 4256.3214 | J12: 2340.5295 | K12: =SUM(E12:J12) -> 39210.072 | M12: Germany | N12: thousands | O12: =E12*'Data by dwelling type'!AA12 -> 4572.4328 | P12: =E12*'Data by dwelling type'!AB12 -> 1910.6638 | Q12: =E12*'Data by dwelling type'!AC12 -> 1997.5122 | R12: =F12*'Data by dwelling type'!AA12 -> 6940.5184 | S12: =F12*'Data by dwelling type'!AB12 -> 2900.2061 | T12: =F12*'Data by dwelling type'!AC12 -> 3032.0336 | U12: =G12*'Data by dwelling type'!AA12 -> 3577.477 | V12: =G12*'Data by dwelling type'!AB12 -> 1494.9057 | W12: =G12*'Data by dwelling type'!AC12 -> 1562.8559 | X12: =H12*'Data by dwelling type'!AA12 -> 2493.4228 | Y12: =H12*'Data by dwelling type'!AB12 -> 1041.9164 | Z12: =H12*'Data by dwelling type'!AC12 -> 1089.2762 | AA12: =I12*'Data by dwelling type'!AA12 -> 2294.8522 | AB12: =I12*'Data by dwelling type'!AB12 -> 958.94049 | AC12: =I12*'Data by dwelling type'!AC12 -> 1002.5287 | AD12: =J12*'Data by dwelling type'!AA12 -> 1261.9275 | AE12: =J12*'Data by dwelling type'!AB12 -> 527.31651 | AF12: =J12*'Data by dwelling type'!AC12 -> 551.28544 | AI12: =O12+R12+U12+X12+AA12+AD12 -> 21140.631 | AJ12: =P12+S12+V12+Y12+AB12+AE12 -> 8833.9489 | AK12: =Q12+T12+W12+Z12+AC12+AF12 -> 9235.4921 | AL12: =AI12-'Data by dwelling type'!W12 -> 86.39575 | AM12: =AJ12-'Data by dwelling type'!Y12 -> 36.101839 | AN12: =AK12-'Data by dwelling type'!Z12 -> 37.742831
A13: DK | B13: Denmark | C13: ENTRANZE | D13: thousands | E13: 958.79185 | F13: 696.22 | G13: 430.06494 | H13: 176.1512 | I13: 176.29084 | J13: 233.17129 | K13: =SUM(E13:J13) -> 2670.6901 | M13: Denmark | N13: thousands | O13: =E13*'Data by dwelling type'!AA13 -> 394.10243 | P13: =E13*'Data by dwelling type'!AB13 -> 368.50018 | Q13: =E13*'Data by dwelling type'!AC13 -> 196.18924 | R13: =F13*'Data by dwelling type'!AA13 -> 286.17472 | S13: =F13*'Data by dwelling type'!AB13 -> 267.58383 | T13: =F13*'Data by dwelling type'!AC13 -> 142.46144 | U13: =G13*'Data by dwelling type'!AA13 -> 176.77418 | V13: =G13*'Data by dwelling type'!AB13 -> 165.29032 | W13: =G13*'Data by dwelling type'!AC13 -> 88.000449 | X13: =H13*'Data by dwelling type'!AA13 -> 72.405306 | Y13: =H13*'Data by dwelling type'!AB13 -> 67.701608 | Z13: =H13*'Data by dwelling type'!AC13 -> 36.044289 | AA13: =I13*'Data by dwelling type'!AA13 -> 72.462702 | AB13: =I13*'Data by dwelling type'!AB13 -> 67.755275 | AC13: =I13*'Data by dwelling type'!AC13 -> 36.072861 | AD13: =J13*'Data by dwelling type'!AA13 -> 95.84288 | AE13: =J13*'Data by dwelling type'!AB13 -> 89.616596 | AF13: =J13*'Data by dwelling type'!AC13 -> 47.711813 | AI13: =O13+R13+U13+X13+AA13+AD13 -> 1097.7622 | AJ13: =P13+S13+V13+Y13+AB13+AE13 -> 1026.4478 | AK13: =Q13+T13+W13+Z13+AC13+AF13 -> 546.48009 | AL13: =AI13-'Data by dwelling type'!W13 -> -4.2377811 | AM13: =AJ13-'Data by dwelling type'!Y13 -> -3.9624802 | AN13: =AK13-'Data by dwelling type'!Z13 -> -2.1096217
A14: EE | B14: Estonia | C14: ENTRANZE | D14: thousands | E14: 122.19269 | F14: 180.63845 | G14: 140.31282 | H14: 131.95672 | I14: 42.814177 | J14: 33.705142 | K14: =SUM(E14:J14) -> 651.62 | M14: Estonia | N14: thousands | O14: =E14*'Data by dwelling type'!AA14 -> 91.537889 | P14: =E14*'Data by dwelling type'!AB14 -> 20.940128 | Q14: =E14*'Data by dwelling type'!AC14 -> 9.7146734 | R14: =F14*'Data by dwelling type'!AA14 -> 135.32121 | S14: =F14*'Data by dwelling type'!AB14 -> 30.955962 | T14: =F14*'Data by dwelling type'!AC14 -> 14.361281 | U14: =G14*'Data by dwelling type'!AA14 -> 105.11218 | V14: =G14*'Data by dwelling type'!AB14 -> 24.04537 | W14: =G14*'Data by dwelling type'!AC14 -> 11.155277 | X14: =H14*'Data by dwelling type'!AA14 -> 98.852387 | Y14: =H14*'Data by dwelling type'!AB14 -> 22.613386 | Z14: =H14*'Data by dwelling type'!AC14 -> 10.490942 | AA14: =I14*'Data by dwelling type'!AA14 -> 32.073272 | AB14: =I14*'Data by dwelling type'!AB14 -> 7.3370538 | AC14: =I14*'Data by dwelling type'!AC14 -> 3.4038513 | AD14: =J14*'Data by dwelling type'!AA14 -> 25.249444 | AE14: =J14*'Data by dwelling type'!AB14 -> 5.7760409 | AF14: =J14*'Data by dwelling type'!AC14 -> 2.6796566 | AI14: =O14+R14+U14+X14+AA14+AD14 -> 488.14638 | AJ14: =P14+S14+V14+Y14+AB14+AE14 -> 111.66794 | AK14: =Q14+T14+W14+Z14+AC14+AF14 -> 51.805681 | AL14: =AI14-'Data by dwelling type'!W14 -> -1.1836212 | AM14: =AJ14-'Data by dwelling type'!Y14 -> -0.27076417 | AN14: =AK14-'Data by dwelling type'!Z14 -> -0.12561458
A15: EL | B15: Greece | C15: ENTRANZE | D15: thousands | E15: 320.25842 | F15: 1165.5356 | G15: 928.71793 | H15: 710.92279 | I15: 478.27226 | J15: 243.56699 | K15: =SUM(E15:J15) -> 3847.274 | M15: Greece | N15: thousands | O15: =E15*'Data by dwelling type'!AA15 -> 190.68903 | P15: =E15*'Data by dwelling type'!AB15 -> 82.769702 | Q15: =E15*'Data by dwelling type'!AC15 -> 46.799691 | R15: =F15*'Data by dwelling type'!AA15 -> 693.98597 | S15: =F15*'Data by dwelling type'!AB15 -> 301.22872 | T15: =F15*'Data by dwelling type'!AC15 -> 170.32091 | U15: =G15*'Data by dwelling type'!AA15 -> 552.97943 | V15: =G15*'Data by dwelling type'!AB15 -> 240.024 | W15: =G15*'Data by dwelling type'!AC15 -> 135.7145 | X15: =H15*'Data by dwelling type'!AA15 -> 423.29933 | Y15: =H15*'Data by dwelling type'!AB15 -> 183.73558 | Z15: =H15*'Data by dwelling type'!AC15 -> 103.88788 | AA15: =I15*'Data by dwelling type'!AA15 -> 284.774 | AB15: =I15*'Data by dwelling type'!AB15 -> 123.60784 | AC15: =I15*'Data by dwelling type'!AC15 -> 69.890416 | AD15: =J15*'Data by dwelling type'!AA15 -> 145.02523 | AE15: =J15*'Data by dwelling type'!AB15 -> 62.949062 | AF15: =J15*'Data by dwelling type'!AC15 -> 35.592694 | AI15: =O15+R15+U15+X15+AA15+AD15 -> 2290.753 | AJ15: =P15+S15+V15+Y15+AB15+AE15 -> 994.31491 | AK15: =Q15+T15+W15+Z15+AC15+AF15 -> 562.20609 | AL15: =AI15-'Data by dwelling type'!W15 -> 5.9542208e-07 | AM15: =AJ15-'Data by dwelling type'!Y15 -> 2.5844645e-07 | AN15: =AK15-'Data by dwelling type'!Z15 -> 1.461309e-07
A16: ES | B16: Spain | C16: ENTRANZE | D16: thousands | E16: 2185.8745 | F16: 3885.6862 | G16: 3208.2017 | H16: 2032.6827 | I16: 2012.6953 | J16: 3416.2386 | K16: =SUM(E16:J16) -> 16741.379 | M16: Spain | N16: thousands | O16: =E16*'Data by dwelling type'!AA16 -> 1538.1678 | P16: =E16*'Data by dwelling type'!AB16 -> 201.34424 | Q16: =E16*'Data by dwelling type'!AC16 -> 446.36241 | R16: =F16*'Data by dwelling type'!AA16 -> 2734.3004 | S16: =F16*'Data by dwelling type'!AB16 -> 357.9165 | T16: =F16*'Data by dwelling type'!AC16 -> 793.46929 | U16: =G16*'Data by dwelling type'!AA16 -> 2257.5645 | V16: =G16*'Data by dwelling type'!AB16 -> 295.51236 | W16: =G16*'Data by dwelling type'!AC16 -> 655.12483 | X16: =H16*'Data by dwelling type'!AA16 -> 1430.369 | Y16: =H16*'Data by dwelling type'!AB16 -> 187.23351 | Z16: =H16*'Data by dwelling type'!AC16 -> 415.08016 | AA16: =I16*'Data by dwelling type'!AA16 -> 1416.3042 | AB16: =I16*'Data by dwelling type'!AB16 -> 185.39244 | AC16: =I16*'Data by dwelling type'!AC16 -> 410.99868 | AD16: =J16*'Data by dwelling type'!AA16 -> 2403.9571 | AE16: =J16*'Data by dwelling type'!AB16 -> 314.67496 | AF16: =J16*'Data by dwelling type'!AC16 -> 697.60662 | AI16: =O16+R16+U16+X16+AA16+AD16 -> 11780.663 | AJ16: =P16+S16+V16+Y16+AB16+AE16 -> 1542.074 | AK16: =Q16+T16+W16+Z16+AC16+AF16 -> 3418.642 | AL16: =AI16-'Data by dwelling type'!W16 -> 0 | AM16: =AJ16-'Data by dwelling type'!Y16 -> 0 | AN16: =AK16-'Data by dwelling type'!Z16 -> 0
A17: FI | B17: Finland | C17: ENTRANZE | D17: thousands | E17: 352.23629 | F17: 644.24645 | G17: 511.75318 | H17: 405.4967 | I17: 296.07562 | J17: 289.19176 | K17: =SUM(E17:J17) -> 2499 | M17: Finland | N17: thousands | O17: =E17*'Data by dwelling type'!AA17 -> 156.19788 | P17: =E17*'Data by dwelling type'!AB17 -> 111.65023 | Q17: =E17*'Data by dwelling type'!AC17 -> 84.388178 | R17: =F17*'Data by dwelling type'!AA17 -> 285.68871 | S17: =F17*'Data by dwelling type'!AB17 -> 204.21026 | T17: =F17*'Data by dwelling type'!AC17 -> 154.34748 | U17: =G17*'Data by dwelling type'!AA17 -> 226.93506 | V17: =G17*'Data by dwelling type'!AB17 -> 162.21316 | W17: =G17*'Data by dwelling type'!AC17 -> 122.60497 | X17: =H17*'Data by dwelling type'!AA17 -> 179.81601 | Y17: =H17*'Data by dwelling type'!AB17 -> 128.53247 | Z17: =H17*'Data by dwelling type'!AC17 -> 97.148216 | AA17: =I17*'Data by dwelling type'!AA17 -> 131.29364 | AB17: =I17*'Data by dwelling type'!AB17 -> 93.848682 | AC17: =I17*'Data by dwelling type'!AC17 -> 70.9333 | AD17: =J17*'Data by dwelling type'!AA17 -> 128.24102 | AE17: =J17*'Data by dwelling type'!AB17 -> 91.666666 | AF17: =J17*'Data by dwelling type'!AC17 -> 69.284074 | AI17: =O17+R17+U17+X17+AA17+AD17 -> 1108.1723 | AJ17: =P17+S17+V17+Y17+AB17+AE17 -> 792.12147 | AK17: =Q17+T17+W17+Z17+AC17+AF17 -> 598.70622 | AL17: =AI17-'Data by dwelling type'!W17 -> 22.172315 | AM17: =AJ17-'Data by dwelling type'!Y17 -> 15.848769 | AN17: =AK17-'Data by dwelling type'!Z17 -> 11.978916
A18: FR | B18: France | C18: ENTRANZE | D18: thousands | E18: 7195.8684 | F18: 4866.948 | G18: 5375.9451 | H18: 3961.7485 | I18: 2386.5085 | J18: 3251.5815 | K18: =SUM(E18:J18) -> 27038.6 | M18: France | N18: thousands | O18: =E18*'Data by dwelling type'!AA18 -> 3136.7254 | P18: =E18*'Data by dwelling type'!AB18 -> 2148.6721 | Q18: =E18*'Data by dwelling type'!AC18 -> 1910.4709 | R18: =F18*'Data by dwelling type'!AA18 -> 2121.534 | S18: =F18*'Data by dwelling type'!AB18 -> 1453.2611 | T18: =F18*'Data by dwelling type'!AC18 -> 1292.1529 | U18: =G18*'Data by dwelling type'!AA18 -> 2343.4091 | V18: =G18*'Data by dwelling type'!AB18 -> 1605.2466 | W18: =G18*'Data by dwelling type'!AC18 -> 1427.2894 | X18: =H18*'Data by dwelling type'!AA18 -> 1726.9517 | Y18: =H18*'Data by dwelling type'!AB18 -> 1182.9703 | Z18: =H18*'Data by dwelling type'!AC18 -> 1051.8265 | AA18: =I18*'Data by dwelling type'!AA18 -> 1040.2944 | AB18: =I18*'Data by dwelling type'!AB18 -> 712.60673 | AC18: =I18*'Data by dwelling type'!AC18 -> 633.60735 | AD18: =J18*'Data by dwelling type'!AA18 -> 1417.3853 | AE18: =J18*'Data by dwelling type'!AB18 -> 970.91582 | AF18: =J18*'Data by dwelling type'!AC18 -> 863.28036 | AI18: =O18+R18+U18+X18+AA18+AD18 -> 11786.3 | AJ18: =P18+S18+V18+Y18+AB18+AE18 -> 8073.6726 | AK18: =Q18+T18+W18+Z18+AC18+AF18 -> 7178.6274 | AL18: =AI18-'Data by dwelling type'!W18 -> 0 | AM18: =AJ18-'Data by dwelling type'!Y18 -> 0 | AN18: =AK18-'Data by dwelling type'!Z18 -> 0
A19: HR | B19: Croatia | C19: ENTRANZE | D19: thousands | E19: 220 | F19: 399.72727 | G19: 308.77273 | H19: 244.8 | I19: 131.03333 | J19: 179.66667 | K19: =SUM(E19:J19) -> 1484 | M19: Croatia | N19: thousands | O19: =E19*'Data by dwelling type'!AA19 -> 81.173032 | P19: =E19*'Data by dwelling type'!AB19 -> 102.23827 | Q19: =E19*'Data by dwelling type'!AC19 -> 36.588696 | R19: =F19*'Data by dwelling type'!AA19 -> 147.4867 | S19: =F19*'Data by dwelling type'!AB19 -> 185.76102 | T19: =F19*'Data by dwelling type'!AC19 -> 66.479545 | U19: =G19*'Data by dwelling type'!AA19 -> 113.92736 | V19: =G19*'Data by dwelling type'!AB19 -> 143.49268 | W19: =G19*'Data by dwelling type'!AC19 -> 51.352689 | X19: =H19*'Data by dwelling type'!AA19 -> 90.323447 | Y19: =H19*'Data by dwelling type'!AB19 -> 113.76331 | Z19: =H19*'Data by dwelling type'!AC19 -> 40.71324 | AA19: =I19*'Data by dwelling type'!AA19 -> 48.34715 | AB19: =I19*'Data by dwelling type'!AB19 -> 60.893734 | AC19: =I19*'Data by dwelling type'!AC19 -> 21.792449 | AD19: =J19*'Data by dwelling type'!AA19 -> 66.29131 | AE19: =J19*'Data by dwelling type'!AB19 -> 83.494588 | AF19: =J19*'Data by dwelling type'!AC19 -> 29.880769 | AI19: =O19+R19+U19+X19+AA19+AD19 -> 547.549 | AJ19: =P19+S19+V19+Y19+AB19+AE19 -> 689.64361 | AK19: =Q19+T19+W19+Z19+AC19+AF19 -> 246.80739 | AL19: =AI19-'Data by dwelling type'!W19 -> 0 | AM19: =AJ19-'Data by dwelling type'!Y19 -> 0 | AN19: =AK19-'Data by dwelling type'!Z19 -> 0
A20: HU | B20: Hungary | C20: ENTRANZE | D20: thousands | E20: 768.51013 | F20: 1035.4304 | G20: 620.99765 | H20: 844.19135 | I20: 348.18951 | J20: 410.68093 | K20: =SUM(E20:J20) -> 4028 | M20: Hungary | N20: thousands | O20: =E20*'Data by dwelling type'!AA20 -> 295.53679 | P20: =E20*'Data by dwelling type'!AB20 -> 345.40567 | Q20: =E20*'Data by dwelling type'!AC20 -> 127.56767 | R20: =F20*'Data by dwelling type'!AA20 -> 398.18315 | S20: =F20*'Data by dwelling type'!AB20 -> 465.37258 | T20: =F20*'Data by dwelling type'!AC20 -> 171.87469 | U20: =G20*'Data by dwelling type'!AA20 -> 238.80967 | V20: =G20*'Data by dwelling type'!AB20 -> 279.10642 | W20: =G20*'Data by dwelling type'!AC20 -> 103.08156 | X20: =H20*'Data by dwelling type'!AA20 -> 324.64062 | Y20: =H20*'Data by dwelling type'!AB20 -> 379.42048 | Z20: =H20*'Data by dwelling type'!AC20 -> 140.13026 | AA20: =I20*'Data by dwelling type'!AA20 -> 133.89909 | AB20: =I20*'Data by dwelling type'!AB20 -> 156.49323 | AC20: =I20*'Data by dwelling type'!AC20 -> 57.797186 | AD20: =J20*'Data by dwelling type'!AA20 -> 157.93068 | AE20: =J20*'Data by dwelling type'!AB20 -> 184.5799 | AF20: =J20*'Data by dwelling type'!AC20 -> 68.170355 | AI20: =O20+R20+U20+X20+AA20+AD20 -> 1549 | AJ20: =P20+S20+V20+Y20+AB20+AE20 -> 1810.3783 | AK20: =Q20+T20+W20+Z20+AC20+AF20 -> 668.62171 | AL20: =AI20-'Data by dwelling type'!W20 -> 0 | AM20: =AJ20-'Data by dwelling type'!Y20 -> 0 | AN20: =AK20-'Data by dwelling type'!Z20 -> 0
A21: IE | B21: Ireland | C21: ENTRANZE | D21: thousands | E21: 277.86702 | F21: 252.13665 | G21: 213.07386 | H21: 185.43696 | I21: 240.93846 | J21: 479.95507 | K21: =SUM(E21:J21) -> 1649.408 | M21: Ireland | N21: thousands | O21: =E21*'Data by dwelling type'!AA21 -> 31.327021 | P21: =E21*'Data by dwelling type'!AB21 -> 98.451964 | Q21: =E21*'Data by dwelling type'!AC21 -> 148.08803 | R21: =F21*'Data by dwelling type'!AA21 -> 28.426152 | S21: =F21*'Data by dwelling type'!AB21 -> 89.335354 | T21: =F21*'Data by dwelling type'!AC21 -> 134.37514 | U21: =G21*'Data by dwelling type'!AA21 -> 24.022172 | V21: =G21*'Data by dwelling type'!AB21 -> 75.494889 | W21: =G21*'Data by dwelling type'!AC21 -> 113.5568 | X21: =H21*'Data by dwelling type'!AA21 -> 20.906358 | Y21: =H21*'Data by dwelling type'!AB21 -> 65.702769 | Z21: =H21*'Data by dwelling type'!AC21 -> 98.827828 | AA21: =I21*'Data by dwelling type'!AA21 -> 27.163656 | AB21: =I21*'Data by dwelling type'!AB21 -> 85.367686 | AC21: =I21*'Data by dwelling type'!AC21 -> 128.40711 | AD21: =J21*'Data by dwelling type'!AA21 -> 54.110641 | AE21: =J21*'Data by dwelling type'!AB21 -> 170.05444 | AF21: =J21*'Data by dwelling type'!AC21 -> 255.78999 | AI21: =O21+R21+U21+X21+AA21+AD21 -> 185.956 | AJ21: =P21+S21+V21+Y21+AB21+AE21 -> 584.4071 | AK21: =Q21+T21+W21+Z21+AC21+AF21 -> 879.0449 | AL21: =AI21-'Data by dwelling type'!W21 -> 1.1274105e-07 | AM21: =AJ21-'Data by dwelling type'!Y21 -> 3.5431333e-07 | AN21: =AK21-'Data by dwelling type'!Z21 -> 5.3294559e-07
A22: IS | B22: Iceland | C22: own assumptions | D22: thousands | E22: =$K$22*(E17/$K$17) -> 21.34771 | F22: =$K$22*(F17/$K$17) -> 39.045342 | G22: =$K$22*(G17/$K$17) -> 31.015426 | H22: =$K$22*(H17/$K$17) -> 24.575622 | I22: =$K$22*(I17/$K$17) -> 17.944024 | J22: =$K$22*(J17/$K$17) -> 17.526819 | K22: =Population!E42/(Population!$E$44/'Dwelling stock'!$K$32) -> 151.45494 | M22: Iceland | N22: thousands | O22: =E22*'Data by dwelling type'!AA22 -> 9.4665631 | P22: =E22*'Data by dwelling type'!AB22 -> 6.1429929 | Q22: =E22*'Data by dwelling type'!AC22 -> 5.7381539 | R22: =F22*'Data by dwelling type'!AA22 -> 17.314513 | S22: =F22*'Data by dwelling type'!AB22 -> 11.235644 | T22: =F22*'Data by dwelling type'!AC22 -> 10.495186 | U22: =G22*'Data by dwelling type'!AA22 -> 13.753676 | V22: =G22*'Data by dwelling type'!AB22 -> 8.924964 | W22: =G22*'Data by dwelling type'!AC22 -> 8.3367859 | X22: =H22*'Data by dwelling type'!AA22 -> 10.897969 | Y22: =H22*'Data by dwelling type'!AB22 -> 7.0718532 | Z22: =H22*'Data by dwelling type'!AC22 -> 6.6057999 | AA22: =I22*'Data by dwelling type'!AA22 -> 7.9572112 | AB22: =I22*'Data by dwelling type'!AB22 -> 5.1635522 | AC22: =I22*'Data by dwelling type'!AC22 -> 4.8232608 | AD22: =J22*'Data by dwelling type'!AA22 -> 7.7722031 | AE22: =J22*'Data by dwelling type'!AB22 -> 5.0434977 | AF22: =J22*'Data by dwelling type'!AC22 -> 4.7111182 | AI22: =O22+R22+U22+X22+AA22+AD22 -> 67.162135 | AJ22: =P22+S22+V22+Y22+AB22+AE22 -> 43.582504 | AK22: =Q22+T22+W22+Z22+AC22+AF22 -> 40.710304 | AL22: =AI22-'Data by dwelling type'!W22 -> 0 | AM22: =AJ22-'Data by dwelling type'!Y22 -> 0 | AN22: =AK22-'Data by dwelling type'!Z22 -> 0
A23: IT | B23: Italy | C23: ENTRANZE | D23: thousands | E23: 6492 | F23: 9106.3636 | G23: 5152.0364 | H23: 3732.2 | I23: 1380.9 | J23: 1080.5 | K23: =SUM(E23:J23) -> 26944 | M23: Italy | N23: thousands | O23: =E23*'Data by dwelling type'!AA23 -> 4829.7261 | P23: =E23*'Data by dwelling type'!AB23 -> 598.28263 | Q23: =E23*'Data by dwelling type'!AC23 -> 1063.9913 | R23: =F23*'Data by dwelling type'!AA23 -> 6774.683 | S23: =F23*'Data by dwelling type'!AB23 -> 839.21429 | T23: =F23*'Data by dwelling type'!AC23 -> 1492.4663 | U23: =G23*'Data by dwelling type'!AA23 -> 3832.8596 | V23: =G23*'Data by dwelling type'!AB23 -> 474.79573 | W23: =G23*'Data by dwelling type'!AC23 -> 844.38104 | X23: =H23*'Data by dwelling type'!AA23 -> 2776.5717 | Y23: =H23*'Data by dwelling type'!AB23 -> 343.948 | Z23: =H23*'Data by dwelling type'!AC23 -> 611.68026 | AA23: =I23*'Data by dwelling type'!AA23 -> 1027.3211 | AB23: =I23*'Data by dwelling type'!AB23 -> 127.25947 | AC23: =I23*'Data by dwelling type'!AC23 -> 226.3194 | AD23: =J23*'Data by dwelling type'!AA23 -> 803.83842 | AE23: =J23*'Data by dwelling type'!AB23 -> 99.575537 | AF23: =J23*'Data by dwelling type'!AC23 -> 177.08604 | AI23: =O23+R23+U23+X23+AA23+AD23 -> 20045 | AJ23: =P23+S23+V23+Y23+AB23+AE23 -> 2483.0757 | AK23: =Q23+T23+W23+Z23+AC23+AF23 -> 4415.9243 | AL23: =AI23-'Data by dwelling type'!W23 -> 0 | AM23: =AJ23-'Data by dwelling type'!Y23 -> 0 | AN23: =AK23-'Data by dwelling type'!Z23 -> 0
A24: KS | B24: Kosovo | C24: own estimates | D24: thousands | E24: =$K$24*(E36/$K$36) -> 94.291023 | F24: =$K$24*(F36/$K$36) -> 215.27678 | G24: =$K$24*(G36/$K$36) -> 160.72722 | H24: =$K$24*(H36/$K$36) -> 135.8398 | I24: =$K$24*(I36/$K$36) -> 66.580146 | J24: =$K$24*(J36/$K$36) -> 49.999335 | K24: =Population!E54/(Population!$E$49/'Dwelling stock'!$K$36) -> 722.7143 | M24: Kosovo | N24: thousands | O24: =E24*'Data by dwelling type'!AA24 -> 44.53781 | P24: =E24*'Data by dwelling type'!AB24 -> 36.64045 | Q24: =E24*'Data by dwelling type'!AC24 -> 13.112764 | R24: =F24*'Data by dwelling type'!AA24 -> 101.68472 | S24: =F24*'Data by dwelling type'!AB24 -> 83.654177 | T24: =F24*'Data by dwelling type'!AC24 -> 29.937882 | U24: =G24*'Data by dwelling type'!AA24 -> 75.918555 | V24: =G24*'Data by dwelling type'!AB24 -> 62.456821 | W24: =G24*'Data by dwelling type'!AC24 -> 22.351842 | X24: =H24*'Data by dwelling type'!AA24 -> 64.16313 | Y24: =H24*'Data by dwelling type'!AB24 -> 52.785846 | Z24: =H24*'Data by dwelling type'!AC24 -> 18.890825 | AA24: =I24*'Data by dwelling type'!AA24 -> 31.44874 | AB24: =I24*'Data by dwelling type'!AB24 -> 25.872309 | AC24: =I24*'Data by dwelling type'!AC24 -> 9.2590969 | AD24: =J24*'Data by dwelling type'!AA24 -> 23.616891 | AE24: =J24*'Data by dwelling type'!AB24 -> 19.429189 | AF24: =J24*'Data by dwelling type'!AC24 -> 6.9532543 | AI24: =O24+R24+U24+X24+AA24+AD24 -> 341.36985 | AJ24: =P24+S24+V24+Y24+AB24+AE24 -> 280.83879 | AK24: =Q24+T24+W24+Z24+AC24+AF24 -> 100.50566 | AL24: =AI24-'Data by dwelling type'!W24 -> 0 | AM24: =AJ24-'Data by dwelling type'!Y24 -> 0 | AN24: =AK24-'Data by dwelling type'!Z24 -> 0
A25: LT | B25: Lithuania | C25: ENTRANZE | D25: thousands | E25: 395.49378 | F25: 422.65282 | G25: 278.21591 | H25: 278.21591 | I25: 86.516165 | J25: 75.823214 | K25: =SUM(E25:J25) -> 1536.9178 | M25: Lithuania | N25: thousands | O25: =E25*'Data by dwelling type'!AA25 -> 256.67024 | P25: =E25*'Data by dwelling type'!AB25 -> 92.199782 | Q25: =E25*'Data by dwelling type'!AC25 -> 46.623753 | R25: =F25*'Data by dwelling type'!AA25 -> 274.2961 | S25: =F25*'Data by dwelling type'!AB25 -> 98.531254 | T25: =F25*'Data by dwelling type'!AC25 -> 49.825464 | U25: =G25*'Data by dwelling type'!AA25 -> 180.55845 | V25: =G25*'Data by dwelling type'!AB25 -> 64.859291 | W25: =G25*'Data by dwelling type'!AC25 -> 32.798164 | X25: =H25*'Data by dwelling type'!AA25 -> 180.55845 | Y25: =H25*'Data by dwelling type'!AB25 -> 64.859291 | Z25: =H25*'Data by dwelling type'!AC25 -> 32.798164 | AA25: =I25*'Data by dwelling type'!AA25 -> 56.147849 | AB25: =I25*'Data by dwelling type'!AB25 -> 20.169146 | AC25: =I25*'Data by dwelling type'!AC25 -> 10.19917 | AD25: =J25*'Data by dwelling type'!AA25 -> 49.208265 | AE25: =J25*'Data by dwelling type'!AB25 -> 17.676343 | AF25: =J25*'Data by dwelling type'!AC25 -> 8.9386054 | AI25: =O25+R25+U25+X25+AA25+AD25 -> 997.43936 | AJ25: =P25+S25+V25+Y25+AB25+AE25 -> 358.29511 | AK25: =Q25+T25+W25+Z25+AC25+AF25 -> 181.18332 | AL25: =AI25-'Data by dwelling type'!W25 -> -4.7615006 | AM25: =AJ25-'Data by dwelling type'!Y25 -> -1.7104021 | AN25: =AK25-'Data by dwelling type'!Z25 -> -0.86491925
A26: LU | B26: Luxembourg | C26: ENTRANZE | D26: thousands | E26: 53.226568 | F26: 48.955233 | G26: 26.436617 | H26: 20.547526 | I26: 16.34799 | J26: 22.486065 | K26: =SUM(E26:J26) -> 188 | M26: Luxembourg | N26: thousands | O26: =E26*'Data by dwelling type'!AA26 -> 19.252163 | P26: =E26*'Data by dwelling type'!AB26 -> 14.810399 | Q26: =E26*'Data by dwelling type'!AC26 -> 19.164006 | R26: =F26*'Data by dwelling type'!AA26 -> 17.707212 | S26: =F26*'Data by dwelling type'!AB26 -> 13.621892 | T26: =F26*'Data by dwelling type'!AC26 -> 17.626129 | U26: =G26*'Data by dwelling type'!AA26 -> 9.5621806 | V26: =G26*'Data by dwelling type'!AB26 -> 7.3560417 | W26: =G26*'Data by dwelling type'!AC26 -> 9.5183947 | X26: =H26*'Data by dwelling type'!AA26 -> 7.4320839 | Y26: =H26*'Data by dwelling type'!AB26 -> 5.7173903 | Z26: =H26*'Data by dwelling type'!AC26 -> 7.3980518 | AA26: =I26*'Data by dwelling type'!AA26 -> 5.9131028 | AB26: =I26*'Data by dwelling type'!AB26 -> 4.548861 | AC26: =I26*'Data by dwelling type'!AC26 -> 5.8860262 | AD26: =J26*'Data by dwelling type'!AA26 -> 8.1332576 | AE26: =J26*'Data by dwelling type'!AB26 -> 6.2567927 | AF26: =J26*'Data by dwelling type'!AC26 -> 8.0960147 | AI26: =O26+R26+U26+X26+AA26+AD26 -> 68 | AJ26: =P26+S26+V26+Y26+AB26+AE26 -> 52.311377 | AK26: =Q26+T26+W26+Z26+AC26+AF26 -> 67.688622 | AL26: =AI26-'Data by dwelling type'!W26 -> -3.6170212e-07 | AM26: =AJ26-'Data by dwelling type'!Y26 -> -2.7825201e-07 | AN26: =AK26-'Data by dwelling type'!Z26 -> -3.6004586e-07
A27: LV | B27: Latvia | C27: ENTRANZE | D27: thousands | E27: 206.75285 | F27: 250.74519 | G27: 202.71631 | H27: 195.68071 | I27: 61.251311 | J27: 71.061633 | K27: =SUM(E27:J27) -> 988.208 | M27: Latvia | N27: thousands | O27: =E27*'Data by dwelling type'!AA27 -> 142.81512 | P27: =E27*'Data by dwelling type'!AB27 -> 45.690331 | Q27: =E27*'Data by dwelling type'!AC27 -> 18.247396 | R27: =F27*'Data by dwelling type'!AA27 -> 173.20295 | S27: =F27*'Data by dwelling type'!AB27 -> 55.412202 | T27: =F27*'Data by dwelling type'!AC27 -> 22.13003 | U27: =G27*'Data by dwelling type'!AA27 -> 140.02687 | V27: =G27*'Data by dwelling type'!AB27 -> 44.798296 | W27: =G27*'Data by dwelling type'!AC27 -> 17.891144 | X27: =H27*'Data by dwelling type'!AA27 -> 135.16701 | Y27: =H27*'Data by dwelling type'!AB27 -> 43.243498 | Z27: =H27*'Data by dwelling type'!AC27 -> 17.270202 | AA27: =I27*'Data by dwelling type'!AA27 -> 42.309518 | AB27: =I27*'Data by dwelling type'!AB27 -> 13.535933 | AC27: =I27*'Data by dwelling type'!AC27 -> 5.40586 | AD27: =J27*'Data by dwelling type'!AA27 -> 49.086026 | AE27: =J27*'Data by dwelling type'!AB27 -> 15.703917 | AF27: =J27*'Data by dwelling type'!AC27 -> 6.2716901 | AI27: =O27+R27+U27+X27+AA27+AD27 -> 682.6075 | AJ27: =P27+S27+V27+Y27+AB27+AE27 -> 218.38418 | AK27: =Q27+T27+W27+Z27+AC27+AF27 -> 87.216322 | AL27: =AI27-'Data by dwelling type'!W27 -> 0 | AM27: =AJ27-'Data by dwelling type'!Y27 -> 0 | AN27: =AK27-'Data by dwelling type'!Z27 -> 0
A28: ME | B28: Montenegro | C28: own assumptions | D28: thousands | E28: =$K$28*(E36/$K$36) -> 26.956076 | F28: =$K$28*(F36/$K$36) -> 61.543688 | G28: =$K$28*(G36/$K$36) -> 45.948967 | H28: =$K$28*(H36/$K$36) -> 38.834111 | I28: =$K$28*(I36/$K$36) -> 19.034044 | J28: =$K$28*(J36/$K$36) -> 14.293894 | K28: =Population!E46/(Population!$E$49/'Dwelling stock'!$K$36) -> 206.61078 | M28: Montenegro | N28: thousands | O28: =E28*'Data by dwelling type'!AA28 -> 16.050251 | P28: =E28*'Data by dwelling type'!AB28 -> 6.9667064 | Q28: =E28*'Data by dwelling type'!AC28 -> 3.9391191 | R28: =F28*'Data by dwelling type'!AA28 -> 36.644488 | S28: =F28*'Data by dwelling type'!AB28 -> 15.905757 | T28: =F28*'Data by dwelling type'!AC28 -> 8.9934421 | U28: =G28*'Data by dwelling type'!AA28 -> 27.359043 | V28: =G28*'Data by dwelling type'!AB28 -> 11.875355 | W28: =G28*'Data by dwelling type'!AC28 -> 6.7145697 | X28: =H28*'Data by dwelling type'!AA28 -> 23.122698 | Y28: =H28*'Data by dwelling type'!AB28 -> 10.036544 | Z28: =H28*'Data by dwelling type'!AC28 -> 5.6748684 | AA28: =I28*'Data by dwelling type'!AA28 -> 11.333296 | AB28: =I28*'Data by dwelling type'!AB28 -> 4.9192841 | AC28: =I28*'Data by dwelling type'!AC28 -> 2.7814644 | AD28: =J28*'Data by dwelling type'!AA28 -> 8.5109042 | AE28: =J28*'Data by dwelling type'!AB28 -> 3.6942084 | AF28: =J28*'Data by dwelling type'!AC28 -> 2.0887814 | AI28: =O28+R28+U28+X28+AA28+AD28 -> 123.02068 | AJ28: =P28+S28+V28+Y28+AB28+AE28 -> 53.397855 | AK28: =Q28+T28+W28+Z28+AC28+AF28 -> 30.192245 | AL28: =AI28-'Data by dwelling type'!W28 -> 0 | AM28: =AJ28-'Data by dwelling type'!Y28 -> 0 | AN28: =AK28-'Data by dwelling type'!Z28 -> 0
A29: MK | B29: Macedonia | C29: own assumptions | D29: thousands | E29: =$K$29*(E8/$K$8) -> 97.084107 | F29: =$K$29*(F8/$K$8) -> 200.97905 | G29: =$K$29*(G8/$K$8) -> 116.52565 | H29: =$K$29*(H8/$K$8) -> 109.80632 | I29: =$K$29*(I8/$K$8) -> 63.415118 | J29: =$K$29*(J8/$K$8) -> 98.665956 | K29: =Population!E47/(Population!$E$49/'Dwelling stock'!$K$36) -> 686.47619 | M29: Macedonia | N29: thousands | O29: =E29*'Data by dwelling type'!AA29 -> 45.857106 | P29: =E29*'Data by dwelling type'!AB29 -> 33.189324 | Q29: =E29*'Data by dwelling type'!AC29 -> 18.037676 | R29: =F29*'Data by dwelling type'!AA29 -> 94.931271 | S29: =F29*'Data by dwelling type'!AB29 -> 68.707011 | T29: =F29*'Data by dwelling type'!AC29 -> 37.340767 | U29: =G29*'Data by dwelling type'!AA29 -> 55.040203 | V29: =G29*'Data by dwelling type'!AB29 -> 39.835639 | W29: =G29*'Data by dwelling type'!AC29 -> 21.649804 | X29: =H29*'Data by dwelling type'!AA29 -> 51.866367 | Y29: =H29*'Data by dwelling type'!AB29 -> 37.538559 | Z29: =H29*'Data by dwelling type'!AC29 -> 20.401391 | AA29: =I29*'Data by dwelling type'!AA29 -> 29.953758 | AB29: =I29*'Data by dwelling type'!AB29 -> 21.679191 | AC29: =I29*'Data by dwelling type'!AC29 -> 11.782169 | AD29: =J29*'Data by dwelling type'!AA29 -> 46.604284 | AE29: =J29*'Data by dwelling type'!AB29 -> 33.730098 | AF29: =J29*'Data by dwelling type'!AC29 -> 18.331575 | AI29: =O29+R29+U29+X29+AA29+AD29 -> 324.25299 | AJ29: =P29+S29+V29+Y29+AB29+AE29 -> 234.67982 | AK29: =Q29+T29+W29+Z29+AC29+AF29 -> 127.54338 | AL29: =AI29-'Data by dwelling type'!W29 -> 0 | AM29: =AJ29-'Data by dwelling type'!Y29 -> 0 | AN29: =AK29-'Data by dwelling type'!Z29 -> 0
A30: MT | B30: Malta | C30: ENTRANZE | D30: thousands | E30: 30.9648 | F30: 32.46368 | G30: 21.3312 | H30: 24.5022 | I30: 23.7292 | J30: 8.84892 | K30: =SUM(E30:J30) -> 141.84 | M30: Malta | N30: thousands | O30: =E30*'Data by dwelling type'!AA30 -> 7.7229495 | P30: =E30*'Data by dwelling type'!AB30 -> 1.6869085 | Q30: =E30*'Data by dwelling type'!AC30 -> 21.554942 | R30: =F30*'Data by dwelling type'!AA30 -> 8.096786 | S30: =F30*'Data by dwelling type'!AB30 -> 1.7685649 | T30: =F30*'Data by dwelling type'!AC30 -> 22.598329 | U30: =G30*'Data by dwelling type'!AA30 -> 5.3202275 | V30: =G30*'Data by dwelling type'!AB30 -> 1.1620867 | W30: =G30*'Data by dwelling type'!AC30 -> 14.848886 | X30: =H30*'Data by dwelling type'!AA30 -> 6.1111085 | Y30: =H30*'Data by dwelling type'!AB30 -> 1.3348373 | Z30: =H30*'Data by dwelling type'!AC30 -> 17.056254 | AA30: =I30*'Data by dwelling type'!AA30 -> 5.9183141 | AB30: =I30*'Data by dwelling type'!AB30 -> 1.2927256 | AC30: =I30*'Data by dwelling type'!AC30 -> 16.51816 | AD30: =J30*'Data by dwelling type'!AA30 -> 2.2070145 | AE30: =J30*'Data by dwelling type'!AB30 -> 0.48207379 | AF30: =J30*'Data by dwelling type'!AC30 -> 6.1598317 | AI30: =O30+R30+U30+X30+AA30+AD30 -> 35.3764 | AJ30: =P30+S30+V30+Y30+AB30+AE30 -> 7.7271968 | AK30: =Q30+T30+W30+Z30+AC30+AF30 -> 98.736403 | AL30: =AI30-'Data by dwelling type'!W30 -> 0 | AM30: =AJ30-'Data by dwelling type'!Y30 -> 0 | AN30: =AK30-'Data by dwelling type'!Z30 -> 0
A31: NL | B31: Netherlands | C31: ENTRANZE | D31: thousands | E31: 1588.7156 | F31: 1788.1028 | G31: 1101.6833 | H31: 1071.5752 | I31: 945.3141 | J31: 491.43182 | K31: =SUM(E31:J31) -> 6986.8227 | M31: Netherlands | N31: thousands | O31: =E31*'Data by dwelling type'!AA31 -> 479.97394 | P31: =E31*'Data by dwelling type'!AB31 -> 176.52692 | Q31: =E31*'Data by dwelling type'!AC31 -> 932.21469 | R31: =F31*'Data by dwelling type'!AA31 -> 540.21172 | S31: =F31*'Data by dwelling type'!AB31 -> 198.68143 | T31: =F31*'Data by dwelling type'!AC31 -> 1049.2097 | U31: =G31*'Data by dwelling type'!AA31 -> 332.83445 | V31: =G31*'Data by dwelling type'!AB31 -> 122.41131 | W31: =G31*'Data by dwelling type'!AC31 -> 646.43752 | X31: =H31*'Data by dwelling type'!AA31 -> 323.73835 | Y31: =H31*'Data by dwelling type'!AB31 -> 119.06591 | Z31: =H31*'Data by dwelling type'!AC31 -> 628.7709 | AA31: =I31*'Data by dwelling type'!AA31 -> 285.59306 | AB31: =I31*'Data by dwelling type'!AB31 -> 105.03667 | AC31: =I31*'Data by dwelling type'!AC31 -> 554.68437 | AD31: =J31*'Data by dwelling type'!AA31 -> 148.46866 | AE31: =J31*'Data by dwelling type'!AB31 -> 54.604454 | AF31: =J31*'Data by dwelling type'!AC31 -> 288.35871 | AI31: =O31+R31+U31+X31+AA31+AD31 -> 2110.8202 | AJ31: =P31+S31+V31+Y31+AB31+AE31 -> 776.3267 | AK31: =Q31+T31+W31+Z31+AC31+AF31 -> 4099.6759 | AL31: =AI31-'Data by dwelling type'!W31 -> 3.0211459e-07 | AM31: =AJ31-'Data by dwelling type'!Y31 -> 1.1111308e-07 | AN31: =AK31-'Data by dwelling type'!Z31 -> 5.8677233e-07
