Workbook
Name FID_1: [1]AGR_Fuels!$A$2

Sheet SUP_Diesel
C2: *Declare and characterize the new technologies by sector. Sheet names should indicate the sector as <SectorName>_<Anything>
H6: ~FI_T: EUR10
C7: TechName | D7: *TechDesc | E7: Comm-IN-A | F7: Comm-IN | G7: Comm-OUT-A | H7: Comm-OUT | I7: START | J7: EFF~2025 | K7: EFF~2030 | L7: CEFF | M7: FLO_COST~CCUBCO2 | N7: FLO_COST~CCUFCO2 | O7: AF | P7: INVCOST~2025 | Q7: INVCOST~2030 | R7: FIXOM~2025 | S7: FIXOM~2030 | T7: VAROM~2025 | U7: VAROM~2030 | V7: LIFE | W7: Cap2Act
C8: \I:Technology Name | D8: Technology Description | E8: Auxiliary Input Commodity | F8: Input Commodity | G8: Auxiliary Output Commodity | H8: Output Commodity | I8: Starting Year | J8: Efficiency | P8: €/kW | Q8: €/kW | R8: €/kW | S8: €/kW | T8: €/GJ | U8: €/GJ | V8: Years
A9: Bio + AtmCCUS | C9: =D63 -> S_CCUS_EMIS | D9: =E63 -> Supply convert bio and atm CO2 emission to Diesel | F9: ELCHIG | H9: P2LKER | I9: 2025 | J9: =0.55*J11 -> 0.429 | K9: =0.7*K11 -> 0.546 | M9: =20/1000 -> 0.02 | O9: 0.9 | P9: ='Data electrolyser'!E5*$O$79 -> 995.43686 | Q9: ='Data electrolyser'!F5*$O$79 -> 889.8 | R9: ='Data electrolyser'!I5*$O$79 -> 179.84554 | S9: ='Data electrolyser'!J5*$O$79 -> 20.772433 | T9: ='Data electrolyser'!M5*$O$79 -> 0.11555957 | U9: =T9 -> 0.11555957 | V9: 20 | W9: 31.536
F10: CCUBCO2 | H10: P2LDST | L10: =1/74 -> 0.013513514
A11: Bio + AtmCCUS | C11: =D64 -> S_CCUS_EMIS_H2T | D11: =E64 -> Bio and atm CO2 Hydrogenation to Diesel with centralized tank | F11: SYNH2CT | H11: P2LKER | I11: 2025 | J11: 0.78 | K11: =J11 -> 0.78 | M11: =20/1000 -> 0.02 | O11: 0.9 | P11: =P9-'Data electrolyser'!D5 -> 497.71843 | Q11: =Q9-'Data electrolyser'!E5 -> 392.08157 | R11: ='Data electrolyser'!I5 -> 89.922769 | S11: ='Data electrolyser'!J5 -> 10.386217 | T11: =T9-'Data electrolyser'!M5 -> 0.057779783 | U11: =T11 -> 0.057779783 | V11: 20 | W11: 31.536
F12: CCUBCO2 | H12: P2LDST | L12: =L10 -> 0.013513514
A13: Bio + AtmCCUS | C13: =D65 -> S_CCUS_EMIS_H2U | D13: =E65 -> Bio and atm CO2 Hydrogenation to Diesel with underground storage | F13: SYNH2CU | H13: P2LKER | I13: 2025 | J13: 0.78 | K13: =J13 -> 0.78 | M13: =20/1000 -> 0.02 | O13: 0.9 | P13: =P11 -> 497.71843 | Q13: =Q11 -> 392.08157 | R13: =R11 -> 89.922769 | S13: =S11 -> 10.386217 | T13: =T11 -> 0.057779783 | U13: =U11 -> 0.057779783 | V13: 20 | W13: 31.536
F14: CCUBCO2 | H14: P2LDST | L14: =L12 -> 0.013513514
A15: AtmCCUS | C15: =D66 -> S_CCUS_ATM | D15: =E66 -> Supply convert Atmospheric CO2 to Diesel | F15: ELCHIG | H15: P2LKER | I15: 2030 | J15: 0.333 | O15: =O9 -> 0.9 | P15: =P9*4 -> 3981.7474 | Q15: =Q9*4 -> 3559.2 | R15: =R9*4 -> 719.38215 | S15: =S9*4 -> 83.089732 | T15: =T9*4 -> 0.46223827 | U15: =U9*4 -> 0.46223827 | V15: =V9 -> 20 | W15: =W9 -> 31.536
F16: TOTCO2 | H16: P2LDST | L16: =L12 -> 0.013513514
A17: FosCCUS | C17: =D67 -> S_CCUS_EMIS_FOS | D17: =E67 -> Supply convert fossil CO2 emission to Diesel | F17: ELCHIG | H17: P2LKER_FOS | I17: 2025 | J17: 0.429 | K17: 0.546 | N17: 0.02 | O17: 0.9 | P17: 995.43686 | Q17: 889.8 | R17: 179.84554 | S17: 20.772433 | T17: 0.11555957 | U17: 0.11555957 | V17: 20 | W17: 31.536
F18: CCUFCO2 | H18: P2LDST_FOS | L18: 0.013513514
A19: FosCCUS | C19: =D68 -> S_CCUS_EMIS_FOS_H2T | D19: =E68 -> Fossil CO2 Hydrogenation to Diesel with centralized tank | F19: SYNH2CT | H19: P2LKER_FOS | I19: 2025 | J19: 0.78 | K19: 0.78 | N19: 0.02 | O19: 0.9 | P19: 497.71843 | Q19: 392.08157 | R19: 89.922769 | S19: 10.386217 | T19: 0.057779783 | U19: 0.057779783 | V19: 20 | W19: 31.536
F20: CCUFCO2 | H20: P2LDST_FOS | L20: 0.013513514
A21: FosCCUS | C21: =D69 -> S_CCUS_EMIS_FOS_H2U | D21: =E69 -> Fossil CO2 Hydrogenation to Diesel with underground storage | F21: SYNH2CU | H21: P2LKER_FOS | I21: 2025 | J21: 0.78 | K21: 0.78 | N21: 0.02 | O21: 0.9 | P21: 497.71843 | Q21: 392.08157 | R21: 89.922769 | S21: 10.386217 | T21: 0.057779783 | U21: 0.057779783 | V21: 20 | W21: 31.536
F22: CCUFCO2 | H22: P2LDST_FOS | L22: 0.013513514
P25: 2900 | Q25: EUR/(ton/yr)
P26: =P25/1000 -> 2.9 | Q26: MEUR/(kton/yr)
P28: EUR/ton annuity
P29: =PMT(0.09,20,-Q34*1000,0,1) -> 291.45392 | Q29: =PMT(0.09,20,-R34*1000,0,1) -> 233.16314 | R29: =PMT(0.09,20,-S34*1000,0,1) -> 186.53051 | S29: =PMT(0.09,20,-T34*1000,0,1) -> 149.22441
C30: The following DAC processes have been disabled with late start year
F31: ~FI_T: EUR10
C32: TechName | D32: *TechDesc | E32: Comm-IN | F32: Comm-OUT | G32: Input | H32: Input~2020 | I32: Input~2030 | J32: Input~2050 | K32: Output | L32: Output~2030 | M32: Output~2050 | N32: AF | O32: FLO_COST~CCUFCO2 | P32: FLO_COST~CCUBCO2 | Q32: INVCOST | R32: INVCOST~2020 | S32: INVCOST~2030 | T32: INVCOST~2050 | U32: FIXOM | V32: FIXOM~2020 | W32: FIXOM~2030 | X32: FIXOM~2050 | Y32: VAROM | Z32: VAROM~2020 | AA32: VAROM~2030 | AB32: VAROM~2050 | AC32: LIFE | AD32: Start | AE32: Cap2Act
C33: *Technology Name | D33: Technology Description | E33: Input Commodity | F33: Output Commodity | Q33: k€/(ton/yr); €/kW | R33: k€/(ton/yr); €/kW | S33: k€/(ton/yr); €/kW | T33: k€/(ton/yr); €/kW | U33: k€/(ton/yr); €/kW | V33: k€/(ton/yr); €/kW | W33: k€/(ton/yr); €/kW | X33: k€/(ton/yr); €/kW | Y33: €/ton;€/kWh | Z33: €/ton;€/kWh | AA33: €/ton;€/kWh | AB33: €/ton;€/kWh | AC33: Years
C34: SNK_DAC_JRC | D34: Direct Air Capture - Chemical Absorption | E34: TOTCO2 | G34: 1 | H34: 1 | I34: 1 | J34: 1 | N34: 0.9 | Q34: =2900/1000 -> 2.9 | R34: =Q34*0.8 -> 2.32 | S34: =R34*0.8 -> 1.856 | T34: =S34*0.8 -> 1.4848 | U34: =90/1000 -> 0.09 | V34: =90/1000 -> 0.09 | W34: =90/1000 -> 0.09 | X34: =90/1000 -> 0.09 | Y34: 0.1 | Z34: =Y34*0.8 -> 0.08 | AA34: =Z34*0.8 -> 0.064 | AB34: =AA34*0.8 -> 0.0512 | AC34: 25 | AD34: 2100 | AE34: 1
E35: ELCMED | G35: 0.0025 | H35: =G35*0.8 -> 0.002 | I35: =H35*0.8 -> 0.0016 | J35: =I35*0.8 -> 0.00128
E36: HETHTH | G36: 0.0115 | H36: =G36*0.8 -> 0.0092 | I36: =H36*0.8 -> 0.00736 | J36: =I36*0.8 -> 0.005888
F37: INDSCO2N | K37: 1
C38: SNK_DAC_GAS_JRC | D38: Direct Air Capture - Chemical Absorption - Gas | E38: TOTCO2 | G38: 1 | H38: 1 | I38: 1 | J38: 1 | N38: 0.9 | Q38: =2900/1000 -> 2.9 | R38: =Q38*0.8 -> 2.32 | S38: =R38*0.8 -> 1.856 | T38: =S38*0.8 -> 1.4848 | U38: =90/1000 -> 0.09 | V38: =90/1000 -> 0.09 | W38: =90/1000 -> 0.09 | X38: =90/1000 -> 0.09 | Y38: 0.1 | Z38: =Y38*0.8 -> 0.08 | AA38: =Z38*0.8 -> 0.064 | AB38: =AA38*0.8 -> 0.0512 | AC38: 25 | AD38: 2100 | AE38: 1
E39: ELCMED | G39: 0.0025 | H39: =G39*0.8 -> 0.002 | I39: =H39*0.8 -> 0.0016 | J39: =I39*0.8 -> 0.00128
E40: GASNAT | G40: 0.0115 | H40: =G40*0.8 -> 0.0092 | I40: =H40*0.8 -> 0.00736 | J40: =I40*0.8 -> 0.005888
F41: INDSCO2N | K41: 1
A42: Bio + AtmCCUS | C42: S_CCUS_P2GU | D42: =E72 -> Methanation - Centralized Underground storage - bio and atm CO2 | E42: CCUBCO2 | G42: 54.839594 | H42: 54.839594 | I42: 54.839594 | J42: 54.839594 | N42: 0.95 | P42: =20/1000 -> 0.02 | Q42: 750 | R42: 600 | S42: 450 | T42: 250 | U42: 37.5 | V42: 30 | W42: 22.5 | X42: 12.5 | AC42: 25 | AD42: 2025 | AE42: 31.536
E43: SYNH2CU | G43: 1.3333333 | H43: 1.2820513 | I43: 1.2345679 | J43: 1.2164419
F44: GASP2G | K44: 1 | L44: 1 | M44: 1
F45: HETHTH | K45: 0 | L45: 0 | M45: 0.0001
A46: Bio + AtmCCUS | C46: S_CCUS_P2GT | D46: =E73 -> Methanation - Centralized Tank storage - bio and atm CO2 | E46: CCUBCO2 | G46: 54.839594 | H46: 54.839594 | I46: 54.839594 | J46: 54.839594 | N46: 0.95 | P46: =20/1000 -> 0.02 | Q46: 750 | R46: 600 | S46: 450 | T46: 250 | U46: 37.5 | V46: 30 | W46: 22.5 | X46: 12.5 | AC46: 25 | AD46: 2025 | AE46: 31.536
E47: SYNH2CT | G47: 1.3333333 | H47: 1.2820513 | I47: 1.2345679 | J47: 1.2164419
...

Sheet SUP_Gasoline
C2: *Declare and characterize the new technologies by sector. Sheet names should indicate the sector as <SectorName>_<Anything>
C4: New Processes | AA4: Working hours per year | AC4: 8000 | AD4: h
AA5: 1 plant of MeOH | AC5: 441172 | AD5: t/yr
H6: ~FI_T: EUR10 | AA6: Investment | AC6: 565.48173 | AD6: MEUR
C7: TechName | D7: *TechDesc | E7: Comm-IN-A | F7: Comm-IN | G7: Comm-OUT-A | H7: Comm-OUT | I7: START | J7: EFF~2025 | K7: EFF~2030 | L7: CEFF | M7: FLO_COST~CCUFCO2 | N7: FLO_COST~CCUBCO2 | O7: AF | P7: INVCOST~2025 | Q7: FIXOM~2025 | R7: VAROM~2025 | S7: LIFE | T7: Cap2Act | AA7: I have used the values in EUR2015
C8: \I:Technology Name | D8: Technology Description | E8: Auxiliary Input Commodity | F8: Input Commodity | G8: Auxiliary Output Commodity | H8: Output Commodity | I8: Starting Year | J8: Efficiency | P8: €/kW | Q8: €/kW | R8: €/GJ | S8: Years | AA8: Needs of electricity | AC8: 11.954 | AD8: MWh/tMeOH | AE8: WITH ELECTROLYSER
A9: Bio + AtmCCUS | C9: =D26 -> S_CCUS_EMISMeOH | D9: =E26 -> Supply convert bio and atm CO2 emission to Methanol | F9: ELCHIG | H9: P2LGSL | I9: 2025 | J9: =((AC5*1000*F43)/(8000*3600))/(AC8*AC5/8000) -> 0.45777332 | K9: =0.7*K11 -> 0.57254969 | N9: 0.02 | O9: 0.9 | P9: =AC6*1000000/(AC5*1000*F43/(8000*3.6)) -> 1873.859 | Q9: =31070000/(AC5*1000*F43/(8000*3.6)) -> 102.95788 | R9: =P9*(SUP_Diesel!U9/SUP_Diesel!P9) -> 0.21753497 | S9: 20 | T9: 31.536
F10: CCUBCO2 | H10: OILNAP | L10: =1/F48 -> 0.014327273
A11: Bio + AtmCCUS | C11: =D27 -> S_CCUS_EMISMeOH_H2 | D11: =E27 -> Supply convert bio and atm CO2 emission to Methanol supplied by H2 | F11: SYNH2CU | H11: P2LGSL | I11: 2025 | J11: =((AC5*1000*F43)/(8000*3600))/((AC13*1000*F50)/(8000*3600)) -> 0.81792813 | K11: =J11 -> 0.81792813 | N11: 0.02 | O11: =+O9 -> 0.9 | P11: =AC14*1000000/(441172.2*1000*F43/(8000*3.6)) -> 849.64234 | Q11: =16380000/(AC5*1000*F43/(8000*3.6)) -> 54.279047 | R11: =P11*(SUP_Diesel!U11/SUP_Diesel!P11) -> 0.098634383 | S11: 20 | T11: =+T9 -> 31.536 | AA11: Needs of electricity | AC11: 0.177 | AD11: MWh/tMeOH | AE11: WITHOUT ELECTROLYSER
F12: SYNH2CT | H12: OILNAP
F13: CCUBCO2 | L13: =L10 -> 0.014327273 | AA13: H2 consumption | AC13: 87816 | AD13: t/yr
A14: AtmCCUS | C14: =D28 -> S_CCUS_ATM_MeOH | D14: =E28 -> Supply convert Atmospheric CO2 to Methanol | F14: ELCHIG | H14: P2LGSL | I14: 2030 | J14: 0.333 | K14: =J14 -> 0.333 | O14: =O9 -> 0.9 | P14: =P9*4 -> 7495.4358 | Q14: =Q9*4 -> 411.8315 | R14: =P14*(SUP_Diesel!U15/SUP_Diesel!P15) -> 0.87013989 | S14: =S9 -> 20 | T14: =T9 -> 31.536 | AA14: Investment | AC14: 256.4 | AD14: MEUR
F15: TOTCO2 | H15: OILNAP | L15: =L13 -> 0.014327273
A16: FosCCUS | C16: S_CCUS_EMISMeOH_FOS | D16: Supply convert fossil CO2 emission to Methanol | F16: ELCHIG | H16: P2LGSL_FOS | I16: 2025 | J16: 0.45777332 | K16: 0.57254969 | M16: 0.02 | O16: 0.9 | P16: 1873.859 | Q16: 102.95788 | R16: 0.21753497 | S16: 20 | T16: 31.536
F17: CCUFCO2 | H17: OILNAP | L17: 0.014327273
A18: FosCCUS | C18: S_CCUS_EMISMeOH_FOS_H2 | D18: Supply convert fossil CO2 emission to Methanol supplied by H2 | F18: SYNH2CU | H18: P2LGSL_FOS | I18: 2025 | J18: 0.81792813 | K18: 0.81792813 | M18: 0.02 | O18: 0.9 | P18: 849.64234 | Q18: 54.279047 | R18: 0.098634383 | S18: 20 | T18: 31.536
F19: SYNH2CT | H19: OILNAP
F20: CCUFCO2 | L20: 0.014327273
C23: ~FI_Process
C24: Sets | D24: TechName | E24: TechDesc | F24: Tact | G24: Tcap | H24: Tslvl | I24: PrimaryCG | J24: Vintage
C25: \I: Process Set Membership | D25: Technology Name | E25: Technology Description | F25: Activity Unit | G25: Capacity Unit | H25: Timeslice Operational Level | I25: Operational Commodity Group | J25: Vintage Tracking
A26: Bio + AtmCCUS | C26: PRE | D26: S_CCUS_EMISMeOH | E26: Supply convert bio and atm CO2 emission to Methanol | F26: PJ | G26: GW | H26: DAYNITE
A27: Bio + AtmCCUS | C27: PRE | D27: S_CCUS_EMISMeOH_H2 | E27: Supply convert bio and atm CO2 emission to Methanol supplied by H2 | F27: PJ | G27: GW | H27: DAYNITE
A28: AtmCCUS | C28: PRE | D28: S_CCUS_ATM_MeOH | E28: Supply convert Atmospheric CO2 to Methanol | F28: PJ | G28: GW | H28: DAYNITE | AA28: VAROM~2025
A29: FosCCUS | C29: PRE | D29: S_CCUS_EMISMeOH_FOS | E29: =D16 -> Supply convert fossil CO2 emission to Methanol | F29: PJ | G29: GW | H29: DAYNITE | O29: Compared to the plant | T29: HERE (for CO2 captured from the atmosphere, I maintained the same | AA29: €/kW
A30: FosCCUS | C30: PRE | D30: S_CCUS_EMISMeOH_FOS_H2 | E30: =D18 -> Supply convert fossil CO2 emission to Methanol supplied by H2 | F30: PJ | G30: GW | H30: DAYNITE | O30: without electrolyser | T30: hypothesis you assumed for the case of diesel | AA30: =494310000/(AC5*1000*F43/(8000*3.6)) -> 1638.0144
D33: Calculation | E33: CO2 | F33: =12+2*16 -> 44 | G33: Atomic mass | I33: Assume price for electricity
E34: Carbon | F34: 12 | J34: 30 | K34: €/GJ | L34: =1/0.5 -> 2 | P34: =P9/P11 -> 2.205468 | Q34: Factor of 2.2 | AA34: =308740000/(AC5*1000*F43/(8000*3.6)) -> 1023.0838
E35: Carbon share | F35: =F34/F33 -> 0.27272727 | G35: kg C/ kg CO2 | J35: =J34*3.6 -> 108 | K35: €/MWh
AA36: =AA30*4 -> 6552.0576
E37: Methanol carbon share | F37: 0.375 | G37: kg C/kg Methanol | I37: Assume price for OIL
J38: 25 | K38: €/GJ
E39: Mass ratio | F39: =F37/F35 -> 1.375 | G39: kg CO2/kg Methanol
I40: Cost per CO2 removed
I41: ELC | J41: =(L34*J34-J38)*L10/1000 -> 0.00050145455 | K41: €/ton
F42: Assume you go to methanol | I42: INV | J42: =PMT(0.1,S9,-P9/T9,0,0)*L10/1000 -> 9.9995954e-05 | K42: €/ton
F43: 19.7 | G43: MJ/kg methanol
F44: =F43/F39 -> 14.327273 | G44: MJ/kg C02
F45: =F44 -> 14.327273 | G45: GJ/ton CO2
F46: =F44 -> 14.327273 | G46: TJ/kton CO2
...

Sheet SUP_CCU
E2: ~FI_T
A3: Curr | B3: TechName | C3: *TechDesc | D3: Comm-IN | E3: Comm-OUT | F3: START | G3: INPUT | H3: OUTPUT | I3: INVCOST | J3: FIXOM | K3: LIFE | L3: AF | M3: Cap2Act | N3: VAROM | O3: ACT_BND~UP | P3: EFF
B4: SINKFCCU | C4: Removal by CCU, fossil CO2 | D4: SNKFCO2 | E4: CCUFCO2 | F4: 2015 | I4: 0.0001 | K4: 50 | M4: 1 | P4: 1
B5: SINKBCCU | C5: Removal by CCU, atm and bio CO2 | D5: SNKCO2N | E5: CCUBCO2 | F5: 2015 | I5: 0.0001 | K5: 50 | M5: 1 | P5: 1
A6: EUR15 | B6: SINKEW1 | C6: Removal by EW1 | D6: TOTCO2 | E6: SNKEWE | F6: 2030 | G6: 1 | K6: 1 | M6: 1 | N6: 1 | O6: 0
E7: PERCDR | H7: =G6 -> 1
E8: COLLECTCCUS | H8: 1
A9: EUR15 | B9: SINKEW2 | C9: Removal by EW2 | D9: TOTCO2 | E9: SNKEWE | F9: 2030 | G9: 1 | K9: 1 | M9: 1 | N9: 1 | O9: 0
E10: PERCDR | H10: =G9 -> 1
E11: COLLECTCCUS | H11: 1
A12: EUR15 | B12: SINKEW3 | C12: Removal by EW3 | D12: TOTCO2 | E12: SNKEWE | F12: 2030 | G12: 1 | K12: 1 | M12: 1 | N12: 1 | O12: 0
E13: PERCDR | H13: =G12 -> 1
E14: COLLECTCCUS | H14: 1
A15: EUR15 | B15: SINKEW4 | C15: Removal by EW4 | D15: TOTCO2 | E15: SNKEWE | F15: 2030 | G15: 1 | K15: 1 | M15: 1 | N15: 1 | O15: 0
E16: PERCDR | H16: =G15 -> 1
E17: COLLECTCCUS | H17: 1
A18: EUR15 | B18: SINKEW5 | C18: =D45 -> Removal by EW5 (CCU) | D18: CCUBCO2 | E18: SNKEWE | F18: 2030 | G18: 1 | H18: 1 | K18: 1 | M18: 1 | N18: 1 | O18: 0
A19: EUR15 | B19: SINKSCS1 | C19: Removal by SCS1 | D19: TOTCO2 | E19: SNKSCS | F19: 2030 | G19: 1 | K19: 1 | M19: 1 | N19: 1 | O19: 0
A20: EUR15 | B20: SINKSCS2 | C20: Removal by SCS2 | D20: TOTCO2 | E20: SNKSCS | F20: 2030 | G20: 1 | K20: 1 | M20: 1 | N20: 1 | O20: 0
A21: EUR15 | B21: SINKSCS3 | C21: Removal by SCS3 | D21: TOTCO2 | E21: SNKSCS | F21: 2030 | G21: 1 | K21: 1 | M21: 1 | N21: 1 | O21: 0
A22: EUR15 | B22: SINKSOC1 | C22: Carbon sequestration in organic soils by SOC1 | D22: TOTCO2 | E22: SNKSOC | F22: 2030 | G22: 1 | K22: 1 | M22: 1 | N22: 1 | O22: 0
A23: EUR15 | B23: SINKSOC2 | C23: Carbon sequestration in organic soils by SOC2 | D23: TOTCO2 | E23: SNKSOC | F23: 2030 | G23: 1 | K23: 1 | M23: 1 | N23: 1 | O23: 0
A24: EUR15 | B24: SINKSOC3 | C24: Carbon sequestration in organic soils by SOC3 | D24: TOTCO2 | E24: SNKSOC | F24: 2030 | G24: 1 | K24: 1 | M24: 1 | N24: 1 | O24: 0
A25: EUR15 | B25: SINKPYCCS | C25: Removal by PYCCS land and calorien neutral biochar | D25: TOTCO2 | E25: SNKCHR | F25: 2025 | G25: 80 | H25: =110*0.5*12/44/1000/0.8 -> 0.01875 | I25: 15.854896 | J25: =I25*0.065 -> 1.0305682 | K25: 20 | L25: 0.9 | M25: 1 | N25: 7 | O25: 0
D26: BIOPYC | E26: BIOGAS | G26: 1 | H26: 0.1
D27: SUPELC | E27: PERCDR | G27: =391*3.6/1000/4.166/14 -> 0.024134147 | H27: 80
E28: COLLECTCCUS | H28: 80
A29: EUR15 | B29: SINKPYCCS2 | C29: Removal by PYCCS regular biochar | D29: TOTCO2 | E29: SNKCHR | F29: 2025 | G29: =L72 -> 43.855422 | H29: =L65 -> 0.015662651 | I29: =69.93*0.7677 -> 53.685261 | J29: =3.96*0.7677 -> 3.040092 | K29: 20 | L29: 0.9 | M29: 1 | N29: 0
D30: BIOWOOCHAR | E30: BIOGAS | G30: 1 | H30: =L77 -> 0.045783133
D31: SUPELC | E31: PERCDR | G31: =3000*3.6/1000/1000/L61 -> 0.026024096 | H31: =G29 -> 43.855422
E32: COLLECTCCUS | H32: =H31 -> 43.855422
A33: EUR15 | B33: SUPSNKEW | C33: EW Grinding | D33: SUPELC | F33: 2030 | G33: 0.0019371061 | K33: 1
D34: SNKEWE
B37: ~FI_Process
B38: Sets | C38: TechName | D38: TechDesc | E38: Tact | F38: Tcap | G38: Tslvl | H38: PrimaryCG | I38: Vintage
B39: PRE | C39: SINKFCCU | D39: Removal by CCU, fossil CO2 | E39: kt | F39: kt_a | H39: CCUFCO2 | K39: cost of biochar per t
B40: PRE | C40: SINKBCCU | D40: Removal by CCU, atm and bio CO2 | E40: kt | F40: kt_a | H40: CCUBCO2 | K40: invcost | L40: =I29 -> 53.685261 | M40: MEUR2015/PJ-a
B41: PRE | C41: SINKEW1 | D41: Removal by EW1 (CCS) | E41: kt | F41: kt_a | H41: SNKEWE
B42: PRE | C42: SINKEW2 | D42: Removal by EW2 (CCS) | E42: kt | F42: kt_a | H42: SNKEWE | K42: fixom | L42: =J29 -> 3.040092 | M42: MEUR2015/PJ-a
B43: PRE | C43: SINKEW3 | D43: Removal by EW3 (CCS) | E43: kt | F43: kt_a | H43: SNKEWE | K43: varom | L43: =N29 -> 0 | M43: MEUR2015/PJ-a
...

Sheet Data electrolyser
A3: TechName | B3: AF | C3: INVCOST | D3: INVCOST~2020 | E3: INVCOST~2025 | F3: INVCOST~2030 | G3: FIXOM | H3: FIXOM~2020 | I3: FIXOM~2025 | J3: FIXOM~2030 | K3: VAROM | L3: VAROM~2020 | M3: VAROM~2025 | N3: VAROM~2030 | O3: LIFE | P3: Start | Q3: Cap2Act
A4: *Technology Name | C4: €/kW | D4: €/kW | E4: €/kW | F4: €/kW | G4: €/kW | H4: €/kW | I4: €/kW | J4: €/kW | K4: €/GJ | L4: €/GJ | M4: €/GJ | N4: €/GJ | O4: Years
A5: SELCH2EC02 | B5: 0.9 | C5: 1779.0496 | D5: 497.71843 | E5: 497.71843 | F5: 444.9 | G5: 89.922769 | H5: 89.922769 | I5: 89.922769 | J5: 10.386217 | K5: 0.057779783 | M5: 0.057779783 | O5: 20 | P5: 2015 | Q5: 31.536

Sheet SUP_Diesel_LowAF
C2: *Declare and characterize the new technologies by sector. Sheet names should indicate the sector as <SectorName>_<Anything>
C6: New Processes | H6: ~FI_T: EUR10
C7: TechName | D7: *TechDesc | E7: Comm-IN-A | F7: Comm-IN | G7: Comm-OUT-A | H7: Comm-OUT | I7: START | J7: EFF~2025 | K7: EFF~2030 | L7: CEFF | M7: FLO_COST~CCUFCO2 | N7: FLO_COST~CCUBCO2 | O7: AF | P7: VAROM~2025 | Q7: VAROM~2030 | R7: LIFE | S7: Cap2Act
C8: \I:Technology Name | D8: Technology Description | E8: Auxiliary Input Commodity | F8: Input Commodity | G8: Auxiliary Output Commodity | H8: Output Commodity | I8: Starting Year | J8: Efficiency | P8: €/GJ | Q8: €/GJ | R8: Years
A9: Bio atm CCUS | C9: =D59 -> S_CCUS_EMIS_LowAF | D9: =E59 -> Supply convert bio and atm CO2 emission to Diesel | F9: ELCHIG | H9: P2LKER | I9: 2025 | J9: =0.55*J11 -> 0.429 | K9: =0.7*K11 -> 0.546 | N9: 0.02 | O9: 0.25 | P9: ='Data electrolyser'!M5*$O$78 -> 0.11555957 | Q9: =P9 -> 0.11555957 | R9: 20 | S9: 31.536
C10: =C9 -> S_CCUS_EMIS_LowAF | F10: CCUBCO2 | H10: P2LDST | L10: =1/74 -> 0.013513514
A11: Bio atm CCUS | C11: =D60 -> S_CCUS_EMIS_H2T_LowAF | D11: =E60 -> Bio and atm CO2 Hydrogenation to Diesel with centralized tank | F11: SYNH2CT | H11: P2LKER | I11: 2025 | J11: 0.78 | K11: =J11 -> 0.78 | N11: 0.02 | O11: 0.25 | P11: =P9-'Data electrolyser'!M5 -> 0.057779783 | Q11: =P11 -> 0.057779783 | R11: 20 | S11: 31.536
C12: =C11 -> S_CCUS_EMIS_H2T_LowAF | F12: CCUBCO2 | H12: P2LDST | L12: =L10 -> 0.013513514
A13: Bio atm CCUS | C13: =D61 -> S_CCUS_EMIS_H2U_LowAF | D13: =E61 -> Bio and atm CO2 Hydrogenation to Diesel with underground storage | F13: SYNH2CU | H13: P2LKER | I13: 2025 | J13: 0.78 | K13: =J13 -> 0.78 | N13: 0.02 | O13: 0.25 | P13: =P11 -> 0.057779783 | Q13: =Q11 -> 0.057779783 | R13: 20 | S13: 31.536
C14: =C13 -> S_CCUS_EMIS_H2U_LowAF | F14: CCUBCO2 | H14: P2LDST | L14: =L12 -> 0.013513514
A15: AtmCCUS | C15: =D62 -> S_CCUS_ATM_LowAF | D15: =E62 -> Supply convert Atmospheric CO2 to Diesel | F15: ELCHIG | H15: P2LKER | I15: 2030 | J15: 0.333 | O15: =O9 -> 0.25 | P15: =P9*4 -> 0.46223827 | Q15: =Q9*4 -> 0.46223827 | R15: =R9 -> 20 | S15: =S9 -> 31.536
C16: =C15 -> S_CCUS_ATM_LowAF | F16: TOTCO2 | H16: P2LDST | L16: =L12 -> 0.013513514
A17: Fos CCUS | C17: S_CCUS_EMIS_FOS_LowAF | D17: Supply convert CCS emission to Diesel | F17: ELCHIG | H17: P2LKER_FOS | I17: 2025 | J17: 0.429 | K17: 0.546 | M17: 0.02 | O17: 0.25 | P17: 0.11555957 | Q17: 0.11555957 | R17: 20 | S17: 31.536
C18: =C17 -> S_CCUS_EMIS_FOS_LowAF | F18: CCUFCO2 | H18: P2LDST_FOS | L18: 0.013513514
A19: Fos CCUS | C19: S_CCUS_EMIS_FOS_H2T_LowAF | D19: CO2 Hydrogenation to Diesel with centralized tank | F19: SYNH2CT | H19: P2LKER_FOS | I19: 2025 | J19: 0.78 | K19: 0.78 | M19: 0.02 | O19: 0.25 | P19: 0.057779783 | Q19: 0.057779783 | R19: 20 | S19: 31.536
C20: =C19 -> S_CCUS_EMIS_FOS_H2T_LowAF | F20: CCUFCO2 | H20: P2LDST_FOS | L20: 0.013513514
A21: Fos CCUS | C21: S_CCUS_EMIS_FOS_H2U_LowAF | D21: CO2 Hydrogenation to Diesel with underground storage | F21: SYNH2CU | H21: P2LKER_FOS | I21: 2025 | J21: 0.78 | K21: 0.78 | M21: 0.02 | O21: 0.25 | P21: 0.057779783 | Q21: 0.057779783 | R21: 20 | S21: 31.536
C22: =C21 -> S_CCUS_EMIS_FOS_H2U_LowAF | F22: CCUFCO2 | H22: P2LDST_FOS | L22: 0.013513514
F25: ~FI_T: EUR10
C26: TechName | D26: *TechDesc | E26: Comm-IN | F26: Comm-OUT | G26: Input | H26: Input~2020 | I26: Input~2030 | J26: Input~2050 | K26: Output | L26: Output~2030 | M26: Output~2050 | N26: AF | O26: FLO_COST~CCUFCO2 | P26: FLO_COST~CCUBCO2 | Q26: VAROM | R26: VAROM~2020 | S26: VAROM~2030 | T26: VAROM~2050 | U26: LIFE | V26: Start | W26: Cap2Act | X26: ENV_ACT~SNKDACCS
C27: *Technology Name | D27: Technology Description | E27: Input Commodity | F27: Output Commodity | Q27: €/ton;€/kWh | R27: €/ton;€/kWh | S27: €/ton;€/kWh | T27: €/ton;€/kWh | U27: Years
C28: =D66 -> SNK_DAC_LowAF | D28: =E66 -> Direct Air Capture - Chemical Absorption | E28: TOTCO2 | G28: 1 | H28: 1 | I28: 1 | J28: 1 | N28: 0.25 | Q28: 0.1 | R28: =Q28*0.8 -> 0.08 | S28: =R28*0.8 -> 0.064 | T28: =S28*0.8 -> 0.0512 | U28: 20 | V28: 2025 | W28: 1 | X28: 1
C29: =C28 -> SNK_DAC_LowAF | E29: ELCMED | G29: 0.0025 | H29: 0.002 | I29: 0.0016 | J29: 0.00128
C30: =C29 -> SNK_DAC_LowAF | E30: HETHTH | G30: 0.0115 | H30: 0.0092 | I30: 0.00736 | J30: 0.005888
C31: =C30 -> SNK_DAC_LowAF | F31: INDSCO2N | K31: 1
C32: =D67 -> SNK_DAC_GAS_LowAF | D32: =E67 -> Direct Air Capture - Chemical Absorption | E32: TOTCO2 | G32: 1 | H32: 1 | I32: 1 | J32: 1 | N32: 0.25 | Q32: 0.1 | R32: =Q32*0.8 -> 0.08 | S32: =R32*0.8 -> 0.064 | T32: =S32*0.8 -> 0.0512 | U32: 20 | V32: 2070 | W32: 1 | X32: 0.97340445
C33: =C32 -> SNK_DAC_GAS_LowAF | E33: ELCMED | G33: 0.0025 | H33: 0.002 | I33: 0.0016 | J33: 0.00128
C34: =C33 -> SNK_DAC_GAS_LowAF | E34: GASNAT | G34: 0.0115 | H34: 0.0092 | I34: 0.00736 | J34: 0.005888
C35: =C34 -> SNK_DAC_GAS_LowAF | F35: INDSCO2N | K35: 1
C36: =D68 -> SNK_DAC_ELC_LowAF | D36: =E68 -> Direct Air Capture - Chem. Absorption - ELC | E36: TOTCO2 | G36: 1 | H36: 1 | I36: 1 | J36: 1 | N36: 0.25 | Q36: 0.1 | R36: =Q36*0.8 -> 0.08 | S36: =R36*0.8 -> 0.064 | T36: =S36*0.8 -> 0.0512 | U36: 20 | V36: 2030 | W36: 1 | X36: 1
C37: =C36 -> SNK_DAC_ELC_LowAF | E37: ELCMED | G37: 0.00605304 | H37: 0.00605304 | I37: 0.0057571077 | J37: 0.005328
C38: =C37 -> SNK_DAC_ELC_LowAF | F38: INDSCO2N | K38: 1
C39: =D69 -> S_CCUS_P2GU_LowAF | D39: =E69 -> Methanation - Centralized Underground storage - bio and atm CO2 | E39: CCUBCO2 | G39: 54.839594 | H39: 54.839594 | I39: 54.839594 | J39: 54.839594 | N39: 0.25 | P39: 0.02 | U39: 25 | V39: 2025 | W39: 31.536
C40: =C39 -> S_CCUS_P2GU_LowAF | E40: SYNH2CU | G40: 1.3333333 | H40: 1.2820513 | I40: 1.2345679 | J40: 1.2164419
C41: =C40 -> S_CCUS_P2GU_LowAF | F41: GASP2G | K41: 1 | L41: 1 | M41: 1
C42: =C41 -> S_CCUS_P2GU_LowAF | F42: HETHTH | K42: 0 | L42: 0 | M42: 0.0001
C43: =D70 -> S_CCUS_P2GT_LowAF | D43: =E70 -> Methanation - Centralized Tank storage - bio and atm CO2 | E43: CCUBCO2 | G43: 54.839594 | H43: 54.839594 | I43: 54.839594 | J43: 54.839594 | N43: 0.25 | P43: 0.02 | U43: 25 | V43: 2025 | W43: 31.536
C44: =C43 -> S_CCUS_P2GT_LowAF | E44: SYNH2CT | G44: 1.3333333 | H44: 1.2820513 | I44: 1.2345679 | J44: 1.2164419
C45: =C44 -> S_CCUS_P2GT_LowAF | F45: GASP2G | K45: 1 | L45: 1 | M45: 1
C46: =C45 -> S_CCUS_P2GT_LowAF | F46: HETHTH | K46: 0 | L46: 0 | M46: 0.0001
...

Sheet SUP_Gasoline_LowAF
C2: *Declare and characterize the new technologies by sector. Sheet names should indicate the sector as <SectorName>_<Anything>
C4: New Processes | Z4: Working hours per year | AB4: 8000 | AC4: h
Z5: 1 plant of MeOH | AB5: 441172 | AC5: t/yr
H6: ~FI_T: EUR10 | Z6: Investment | AB6: 565.48173 | AC6: MEUR
C7: TechName | D7: *TechDesc | E7: Comm-IN-A | F7: Comm-IN | G7: Comm-OUT-A | H7: Comm-OUT | I7: START | J7: EFF~2025 | K7: EFF~2030 | L7: CEFF | M7: FLO_COST~CCUFCO2 | N7: FLO_COST~CCUBCO2 | O7: AF | P7: VAROM~2025 | Q7: LIFE | R7: Cap2Act | X7: I have used the values in EUR2015
C8: \I:Technology Name | D8: Technology Description | E8: Auxiliary Input Commodity | F8: Input Commodity | G8: Auxiliary Output Commodity | H8: Output Commodity | I8: Starting Year | J8: Efficiency | P8: €/GJ | Q8: Years | X8: Needs of electricity | Z8: 11.954 | AA8: MWh/tMeOH | AB8: WITH ELECTROLYSER
A9: Bio + AtmCCUS | C9: =D27 -> S_CCUS_EMISMeOH_LowAF | D9: =E27 -> Supply convert bio and atm CO2 emission to Methanol LowAF | F9: ELCHIG | H9: P2LGSL | I9: 2030 | J9: =((AB5*1000*F51)/(8000*3600))/(Z8*AB5/8000) -> 0.45777332 | K9: =0.7*K11 -> 0.57254969 | N9: 0.02 | O9: 0.25 | P9: =SUP_Gasoline!R9 -> 0.21753497 | Q9: 20 | R9: 31.536
F10: CCUBCO2 | H10: OILNAP | L10: =1/F56 -> 0.014327273
A11: Bio + AtmCCUS | C11: =D28 -> S_CCUS_EMISMeOH_H2_LowAF | D11: =E28 -> Supply convert bio and atm CO2 emission to Methanol supplied by H2 LowAF | F11: SYNH2CU | H11: P2LGSL | I11: 2030 | J11: =((AB5*1000*F51)/(8000*3600))/((Z13*1000*F58)/(8000*3600)) -> 0.81792813 | K11: =J11 -> 0.81792813 | N11: 0.02 | O11: =+O9 -> 0.25 | P11: =SUP_Gasoline!R11 -> 0.098634383 | Q11: 20 | R11: =+R9 -> 31.536 | X11: Needs of electricity | Z11: 0.177 | AA11: MWh/tMeOH | AB11: WITHOUT ELECTROLYSER
F12: SYNH2CT | H12: OILNAP
F13: CCUBCO2 | L13: =L10 -> 0.014327273 | X13: H2 consumption | Z13: 87816 | AA13: t/yr
A14: AtmCCUS | C14: =D29 -> S_CCUS_ATM_MeOH_LowAF | D14: =E29 -> Supply convert Atmospheric CO2 to Methanol LowAF | F14: ELCHIG | H14: P2LGSL | I14: 2030 | J14: 0.333 | K14: =J14 -> 0.333 | O14: =O9 -> 0.25 | P14: =SUP_Gasoline!R14 -> 0.87013989 | Q14: =Q9 -> 20 | R14: =R9 -> 31.536 | X14: Investment | Z14: 256.4 | AA14: MEUR
F15: TOTCO2 | H15: OILNAP | L15: =L13 -> 0.014327273
A16: FosCCUS | C16: =D30 -> S_CCUS_EMISMeOH_FOS_LowAF | D16: =E30 -> Supply convert fossil CO2 emission to Methanol LowAF | F16: ELCHIG | H16: P2LGSL_FOS | I16: 2030 | J16: 0.45777332 | K16: 0.57254969 | M16: 0.02 | O16: 0.25 | P16: 0.21753497 | Q16: 20 | R16: 31.536 | X16: VAROM~2025
F17: CCUFCO2 | H17: OILNAP | L17: 0.014327273
A18: FosCCUS | C18: =D31 -> S_CCUS_EMISMeOH_FOS_H2_LowAF | D18: =E31 -> Supply convert fossil CO2 emission to Methanol supplied by H2 LowAF | F18: SYNH2CU | H18: P2LGSL_FOS | I18: 2030 | J18: 0.81792813 | K18: 0.81792813 | M18: 0.02 | O18: 0.25 | P18: 0.098634383 | Q18: 20 | R18: 31.536
F19: SYNH2CT | H19: OILNAP
F20: CCUFCO2 | L20: 0.014327273
C24: ~FI_Process
C25: Sets | D25: TechName | E25: TechDesc | F25: Tact | G25: Tcap | H25: Tslvl | I25: PrimaryCG | J25: Vintage
C26: \I: Process Set Membership | D26: Technology Name | E26: Technology Description | F26: Activity Unit | G26: Capacity Unit | H26: Timeslice Operational Level | I26: Operational Commodity Group | J26: Vintage Tracking
A27: Bio + AtmCCUS | C27: PRE | D27: S_CCUS_EMISMeOH_LowAF | E27: Supply convert bio and atm CO2 emission to Methanol LowAF | F27: PJ | G27: GW | H27: DAYNITE
A28: Bio + AtmCCUS | C28: PRE | D28: S_CCUS_EMISMeOH_H2_LowAF | E28: Supply convert bio and atm CO2 emission to Methanol supplied by H2 LowAF | F28: PJ | G28: GW | H28: DAYNITE
A29: AtmCCUS | C29: PRE | D29: S_CCUS_ATM_MeOH_LowAF | E29: Supply convert Atmospheric CO2 to Methanol LowAF | F29: PJ | G29: GW | H29: DAYNITE
A30: FosCCUS | C30: PRE | D30: S_CCUS_EMISMeOH_FOS_LowAF | E30: Supply convert fossil CO2 emission to Methanol LowAF | F30: PJ | G30: GW | H30: DAYNITE
A31: FosCCUS | C31: PRE | D31: S_CCUS_EMISMeOH_FOS_H2_LowAF | E31: Supply convert fossil CO2 emission to Methanol supplied by H2 LowAF | F31: PJ | G31: GW | H31: DAYNITE
N39: Compared to the plant | Q39: HERE (for CO2 captured from the atmosphere, I maintained the same | X39: €/kW
N40: without electrolyser | Q40: hypothesis you assumed for the case of diesel | X40: =494310000/(AB5*1000*F51/(8000*3.6)) -> 1638.0144
D41: Calculation | E41: CO2 | F41: =12+2*16 -> 44 | G41: Atomic mass | I41: Assume price for electricity
E42: Carbon | F42: 12 | J42: 30 | K42: €/GJ | L42: =1/0.5 -> 2 | X42: =308740000/(AB5*1000*F51/(8000*3.6)) -> 1023.0838
E43: Carbon share | F43: =F42/F41 -> 0.27272727 | G43: kg C/ kg CO2 | J43: =J42*3.6 -> 108 | K43: €/MWh
Z44: =X40*4 -> 6552.0576
E45: Methanol carbon share | F45: 0.375 | G45: kg C/kg Methanol | I45: Assume price for OIL
J46: 25 | K46: €/GJ
E47: Mass ratio | F47: =F45/F43 -> 1.375 | G47: kg CO2/kg Methanol
I48: Cost per CO2 removed
I49: ELC | J49: =(L42*J42-J46)*L10/1000 -> 0.00050145455 | K49: €/ton
F50: Assume you go to methanol | I50: INV | J50: =PMT(0.1,Q9,-SUP_Gasoline!P9/R9,0,0)*L10/1000 -> 9.9995954e-05 | K50: €/ton
F51: 19.7 | G51: MJ/kg methanol
F52: =F51/F47 -> 14.327273 | G52: MJ/kg C02
...

Sheet DACNEW
X1: DAC-costs with these INVCOSTS are around ~400 €/tCO2
H5: ~FI_T | Z5: Values used in 2024-06/2025 | AJ5: From: https://keith.seas.harvard.edu/files/tkg/files/keith_et_al._-_2018_-_a_process_for_capturing_co2_from_the_atmosphere.pdf
B6: Curr | C6: TechName | D6: *TechDesc | E6: Comm-IN | F6: Comm-OUT | G6: CommGrp | H6: Attribute | I6: 2010 | J6: 2020 | K6: 2030 | L6: 2040 | M6: 2050 | N6: Input | O6: Output | P6: AF | Q6: Cap2Act | R6: LIFE | S6: VAROM | T6: FLO_EMIS~2020 | U6: FCOST | V6: START | Z6: TechName | AA6: Attribute | AB6: 2010 | AC6: 2020 | AD6: 2030 | AE6: 2040 | AF6: 2050
C7: *Technology Name | D7: Technology Description | E7: Input Commodity | F7: Output Commodity | G7: Commodity Group | H7: Attribute | I7: Data Year | J7: Data Year | K7: Data Year | L7: Data Year | M7: Data Year | N7: Input | P7: Availa-bility factor | Q7: CapAct | R7: Technical Life | T7: Emissions | V7: Year | Z7: *Technology Name | AA7: Attribute | AB7: Data Year | AC7: Data Year | AD7: Data Year | AE7: Data Year | AF7: Data Year | AJ7: Scenario | AK7: Gas Input (GJ/t CO2) | AL7: Elec Input (kWh/t CO2) | AM7: C-Gas/C-Air | AN7: Capital USD per t co2/a | AO7: O&M (USD/ t CO2) | AP7: Levelised (USD/ t CO2)
B8: EUR10 | C8: SNK_DAC | D8: Direct Air Capture - Chemical Absorption | E8: TOTCO2 | H8: INVCOST | I8: 1.6338772 | J8: 1.6338772 | K8: 1.6338772 | L8: 1.3336523 | M8: 1.2124112 | N8: 1 | P8: 0.82 | Q8: 1 | R8: 20 | V8: 2030 | Z8: SNK_DAC | AA8: INVCOST | AB8: 1.6338772 | AC8: 1.6338772 | AD8: 1.6338772 | AE8: 1.3336523 | AF8: 1.2124112
E9: ELCMED | H9: INPUT | I9: 0.0025 | J9: 0.002 | K9: 0.0016 | M9: 0.00128 | AA9: INPUT | AB9: 0.0025 | AC9: 0.002 | AD9: 0.0016 | AF9: 0.00128
E10: HETHTH | F10: SNKDACCS | G10: INDSCO2N | H10: INPUT | I10: 0.0115 | J10: 0.0092 | K10: 0.00736 | M10: 0.00589 | T10: 1 | AA10: INPUT | AB10: 0.0115 | AC10: 0.0092 | AD10: 0.00736 | AF10: 0.00589
B11: EUR10 | F11: INDSCO2N | H11: FIXOM | I11: 0.065355086 | J11: 0.065355086 | K11: 0.065355086 | M11: 0.048496446 | AA11: FIXOM | AB11: 0.065355086 | AC11: 0.065355086 | AD11: 0.065355086 | AF11: 0.048496446
B12: EUR10 | H12: VAROM | I12: 0.023 | J12: 0.023 | K12: 0.023 | M12: 0.023 | AA12: VAROM | AB12: 0.023 | AC12: 0.023 | AD12: 0.023 | AF12: 0.023
B13: EUR15 | C13: SNK_DAC_GAS | D13: Direct Air Capture - Chem. Absorption - Gas | E13: TOTCO2 | H13: INVCOST | I13: 1.8154191 | J13: 1.8154191 | K13: 1.8154191 | L13: 1.4818359 | M13: 1.3471235 | N13: 1 | P13: 0.82 | Q13: 1 | R13: 20 | V13: 2070 | Z13: SNK_DAC_GAS | AA13: INVCOST | AB13: 1.8154191 | AC13: 1.8154191 | AD13: 1.8154191 | AE13: 1.4818359 | AF13: 1.3471235
E14: ELCMED | F14: SNKDACCS | G14: INDSCO2N | H14: INPUT | I14: 0.0025 | J14: 0.0025 | K14: 0.0019764 | M14: 0.0013176 | T14: 0.97340445 | AA14: INPUT | AB14: 0.0025 | AC14: 0.0025 | AD14: 0.0019764 | AF14: 0.0013176
E15: GASNAT | F15: SUPCO2N | G15: GASNAT | H15: INPUT | I15: 0.00525 | J15: 0.00525 | K15: 0.0049933282 | M15: 0.004749205 | T15: 5.6 | AA15: INPUT | AB15: 0.00525 | AC15: 0.00525 | AD15: 0.0049933282 | AF15: 0.004749205
B16: EUR15 | F16: INDSCO2N | H16: FIXOM | J16: 0.072616762 | K16: 0.072616762 | M16: 0.05388494 | AA16: FIXOM | AC16: 0.072616762 | AD16: 0.072616762 | AF16: 0.05388494
F17: FOSCO2 | T17: 5.6
B18: EUR15 | H18: VAROM | I18: 0.026 | J18: 0.026 | K18: 0.026 | M18: 0.026 | AA18: VAROM | AB18: 0.026 | AC18: 0.026 | AD18: 0.026 | AF18: 0.026
B19: EUR15 | C19: SNK_DAC_ELC | D19: Direct Air Capture - Chem. Absorption - ELC | E19: TOTCO2 | H19: INVCOST | I19: 1.9001234 | J19: 1.9001234 | K19: 1.9001234 | L19: 1.5509757 | M19: 1.4099779 | N19: 1 | P19: 0.82 | Q19: 1 | R19: 20 | V19: 2030 | Z19: SNK_DAC_ELC | AA19: INVCOST | AB19: 1.9001234 | AC19: 1.9001234 | AD19: 1.9001234 | AE19: 1.5509757 | AF19: 1.4099779
E20: ELCMED | F20: SNKDACCS | G20: INDSCO2N | H20: INPUT | J20: 0.00605304 | K20: 0.0057571077 | M20: 0.005328 | T20: 1 | AA20: INPUT | AC20: 0.00605304 | AD20: 0.0057571077 | AF20: 0.005328
B21: EUR15 | F21: INDSCO2N | H21: FIXOM | J21: 0.072204687 | K21: 0.072204687 | M21: 0.053579162 | AA21: FIXOM | AC21: 0.072204687 | AD21: 0.072204687 | AF21: 0.053579162
B22: EUR15 | H22: VAROM | I22: 0.01 | J22: 0.01 | K22: 0.01 | M22: 0.01 | AA22: VAROM | AB22: 0.01 | AC22: 0.01 | AD22: 0.01 | AF22: 0.01
B23: EUR20 | C23: SNK_DAC_SOLID | D23: Direct Air Capture - Solid Sorbent | E23: TOTCO2 | H23: INVCOST | K23: 0.73 | L23: =K23 -> 0.73 | M23: =L23 -> 0.73 | N23: 1 | P23: 0.82 | Q23: 1 | R23: 20 | V23: 2030
E24: ELCMED | F24: SNKDACCS | G24: INDSCO2N | H24: INPUT | K24: 0.0009 | L24: =K24 -> 0.0009 | M24: =L24 -> 0.0009 | T24: 1
E25: HETHTH | F25: INDSCO2N | H25: INPUT | K25: 0.0063 | L25: 0.0063 | M25: 0.0063
B26: EUR20 | H26: FIXOM | K26: =0.04*K23 -> 0.0292 | L26: =0.04*L23 -> 0.0292 | M26: =0.04*M23 -> 0.0292
B27: EUR18 | C27: S+SYNGAS | D27: Methanation, bio and atm CO2 | E27: CCUBCO2 | H27: INVCOST | J27: 790 | K27: 700 | M27: 540 | N27: 56.1 | P27: 0.9 | Q27: 31.536 | R27: 30 | S27: 0.097222222 | U27: =15/1000 -> 0.015 | V27: 2030
B28: EUR18 | E28: ELCHIG | F28: HETHTH | H28: FIXOM | J28: 23.7 | K28: 21 | M28: 16.2 | N28: 0.0229 | O28: 0.097985697
E29: SYNH2CT | F29: GASP2G | H29: INPUT | J29: 1.198 | K29: 1.1850847 | M29: 1.1730714
B30: EUR18 | C30: S+SYNMET | D30: Methanol Synthesis, bio and atm CO2 | E30: CCUBCO2 | H30: INVCOST | J30: 790 | K30: 700 | M30: 540 | N30: 70.125 | P30: 0.9 | Q30: 31.536 | R30: 30 | S30: 0.44166667 | U30: =15/1000 -> 0.015 | V30: 2030
B31: EUR18 | E31: ELCHIG | F31: HETHTH | H31: FIXOM | J31: 23.7 | K31: 21 | M31: 16.2 | N31: 0.0495 | O31: 0.096862034
E32: SYNH2CT | F32: SYNMTAH | H32: INPUT | J32: 1.161 | K32: 1.1523665 | M32: 1.1442241
B33: EUR18 | C33: S+SYNGSL | D33: E-gasoline Synthesis, bio and atm CO2 | E33: ELCHIG | F33: P2LGSL | H33: INVCOST | J33: 307 | K33: 269 | M33: 200 | N33: 0.0164 | P33: 0.9 | Q33: 31.536 | R33: 30 | S33: 0.375 | V33: 2030 | AK33: 319 | AL33: MW
B34: EUR18 | E34: SYNH2CT | F34: HETHTH | H34: FIXOM | J34: 13.815 | K34: 12.105 | M34: 9 | N34: 0.0036 | O34: 0.036396229 | AK34: 145 | AL34: M€
E35: SYNMTAH | H35: INPUT | J35: 1.0562 | K35: 1.0544689 | M35: 1.0527925 | AK35: =AK34/AK33*1000 -> 454.54545 | AL35: €/kW
B36: EUR18 | C36: S+SYNJET | D36: E-JET Synthesis, bio and atm CO2 | E36: ELCHIG | F36: P2LKER | H36: INVCOST | J36: 307 | K36: 269 | M36: 200 | N36: 0.0163 | P36: 0.9 | Q36: 31.536 | R36: 30 | S36: 0.375 | V36: 2030 | AK36: =AK35/3.6/8.76 -> 14.413542 | AL36: €/GJ
B37: EUR18 | E37: SYNH2CT | F37: HETHTH | H37: FIXOM | J37: 13.815 | K37: 12.105 | M37: 9 | N37: 0.024 | O37: 0.042793929
E38: SYNMTAH | H38: INPUT | J38: 1.0482 | K38: 1.0467207 | M38: 1.0452879
B39: EUR18 | C39: S+BIOSNG | D39: Syngas biogasification+ccs | F39: BIOGAS | H39: INVCOST | J39: 2500 | K39: 1600 | M39: 1500 | P39: 0.9 | Q39: 31.536 | R39: 30 | S39: 0.45833333 | V39: 2030 | AJ39: DEA-DATA | AK39: 2020 | AL39: 2025 | AM39: 2030 | AN39: 2040 | AO39: 2050
B40: EUR18 | E40: ELCHIG | F40: HETHTH | H40: FIXOM | J40: 40.2 | K40: 26.2 | M40: 24.1 | N40: 0.061266667 | O40: =((M41+N40)-1)* 0.57 -> 0.24896602 | AJ40: C1) Heat input (MWh/t CO2-output) | AK40: 2.5 | AL40: 2.5 | AM40: 2 | AN40: 1.5 | AO40: 1.5
E41: BIOWOOH2 | F41: SUPCO2N | G41: SUPSCO2N | H41: INPUT | J41: 1.5384615 | K41: =1/0.69 -> 1.4492754 | M41: =1/0.727 -> 1.3755158 | T41: =-1 -> -1 | AJ41: C2) Eletricity input (MWh/t CO2-output) | AK41: 0.35 | AL41: 0.35 | AM41: 0.32 | AN41: 0.3 | AO41: 0.28
F42: SUPSCO2N | H42: OUTPUT | J42: =(J41*110-56)*0.92 -> 104.17231 | K42: =(K41*110-56)*0.92 -> 95.146667 | M42: =(M41*110-56)*0.92 -> 87.682201 | AJ42: Specific investment (mill € /[t CO2 output/hour]) | AK42: 7 | AL42: 7 | AM42: 6 | AN42: 5 | AO42: 4
B43: EUR18 | C43: S+SYNGAS_FOS | D43: Methanation, fossil CO2 | E43: CCUFCO2 | H43: INVCOST | J43: 790 | K43: 700 | M43: 540 | N43: 56.1 | P43: 0.9 | Q43: 31.536 | R43: 30 | S43: 0.097222222 | U43: 0.015 | V43: 2030
...
