Workbook
Name FID_1: [1]AGR_Fuels!$A$2

Sheet Fill Data
B2: ~TFM_Fill-R: w=RES_SpHeat; Hcol=Region
B3: TimeSlice | C3: LimType | D3: Attribute | E3: Year | F3: AllRegions | G3: Pset_CI | H3: Pset_PN | I3: Pset_CO | J3: Cset_CN
D4: ACTFLO | F4: 1 | H4: R_ES-SH* | I4: R_ES-*SpHeat
D5: AFA | F5: 1 | H5: R_ES-SH*
D6: EFF | F6: 1 | H6: R_ES-SH*
B8: ~TFM_Fill-R: w=RES_WatHeat; Hcol=Region
B9: TimeSlice | C9: LimType | D9: Attribute | E9: Year | F9: AllRegions | G9: Pset_CI | H9: Pset_PN | I9: Pset_CO | J9: Cset_CN
D10: AFA | F10: 1 | H10: R_ES-WH*
D11: EFF | F11: 1 | H11: R_ES-WH*
B14: ~TFM_Fill-R: w=RES_SpCool; Hcol=Region
B15: TimeSlice | C15: LimType | D15: Attribute | E15: Year | F15: AllRegions | G15: Pset_CI | H15: Pset_PN | I15: Pset_CO | J15: Cset_CN
D16: AFA | F16: 1 | H16: R_ES-SC*
D17: EFF | F17: 1 | H17: R_ES-SC*
B20: ~TFM_Fill-R: w=RES_Others; Hcol=Region
B21: TimeSlice | C21: LimType | D21: Attribute | E21: Year | F21: AllRegions | G21: Pset_CI | H21: Pset_PN | I21: Pset_CO | J21: Cset_CN
D22: PRC_CAPACT | F22: 1 | H22: R_ES-CK-*
D23: EFF | F23: 1 | H23: R_ES-CK-*
D24: INPUT | F24: 1 | H24: RLIGELC00
D25: INPUT | F25: 1 | H25: RREFELC00
D26: INPUT | F26: 1 | H26: RCWAELC00
D27: INPUT | F27: 1 | H27: RCDRELC00
D28: INPUT | F28: 1 | H28: RDWAELC00
D29: INPUT | F29: 1 | H29: ROELELC00
B34: ~TFM_Fill-R: w=COM_All; Hcol=Region
B35: TimeSlice | C35: LimType | D35: Attribute | E35: Year | F35: AllRegions | G35: Pset_CI | H35: Pset_PN | I35: Pset_CO | J35: Cset_CN
D36: EFF | F36: 1 | H36: C_ES-SH*
D37: EFF | F37: 1 | H37: C_ES-WH*
D38: EFF | F38: 1 | H38: C_ES-SC*
D39: PRC_CAPACT | F39: 1 | H39: C_ES-CK-*
D40: EFF | F40: 1 | H40: C_ES-CK-*
D41: INPUT | F41: 1 | H41: NRbldg_BuildLight
D42: INPUT | F42: 1 | H42: NRbldg_BuildTech
D43: INPUT | F43: 1 | H43: NRbldg_ICTM
D44: INPUT | F44: 1 | H44: NRbldg_Refrig
D45: INPUT | F45: 1 | H45: NRbldg_StLight
D46: INPUT | F46: 1 | H46: NRbldg_Vent
B49: CHANGES
B50: RSD_SpCool | C50: Increased cooling shares
B51: INS-UPD SpCool | C51: Increased cooling shares
B52: RSD_HP | C52: Change FLO_SHAR to electricity

Sheet RES_SpHeat
A1: scenario | B1: attribute | C1: process | D1: commodity | E1: lim_type | F1: time_slice | G1: year | H1: commodity_group | I1: currency | J1: stage | K1: sow | L1: AL | M1: AT | N1: BA | O1: BE | P1: BG | Q1: CH | R1: CY | S1: CZ | T1: DE | U1: DK | V1: EE | W1: EL | X1: ES | Y1: FI | Z1: FR | AA1: HR | AB1: HU | AC1: IE | AD1: IS | AE1: IT | AF1: KS | AG1: LT | AH1: LU | AI1: LV | AJ1: ME | AK1: MK | AL1: MT | AM1: NL | AN1: NO | AO1: PL | AP1: PT | AQ1: RO | AR1: RS | AS1: SE | AT1: SI | AU1: SK | AV1: UK | AW1: year2
A2: BASE | B2: ACTFLO | C2: R_ES-SH-DH-70_BIO | D2: R_ES-DH-70-SpHeat | E2: - | F2: - | G2: 2010 | H2: commodity_group | I2: - | J2: - | K2: - | L2: 0.74633079 | M2: 0.79425199 | N2: 0.76016377 | O2: 0.78997503 | P2: 0.72609118 | Q2: 0.88939691 | R2: 0.56988643 | S2: 0.75698357 | T2: 0.88939691 | U2: 0.84781454 | V2: 0.73363854 | W2: 0.74633079 | X2: 0.70928681 | Y2: 0.83322321 | Z2: 0.79998616 | AA2: 0.70586636 | AB2: 0.76441135 | AC2: 0.76351422 | AD2: 0.84781454 | AE2: 0.76866988 | AF2: 0.76016377 | AG2: 0.74146384 | AH2: 0.79040869 | AI2: 0.79542896 | AJ2: 0.76016377 | AK2: 0.74633079 | AL2: 1.0434129 | AM2: 0.82267628 | AN2: 0.84781454 | AO2: 0.7832275 | AP2: 0.79601791 | AQ2: 0.73191705 | AR2: 0.76016377 | AS2: 0.7 | AT2: 0.78984393 | AU2: 0.7395726 | AV2: 0.81749292 | AW2: -
A3: BASE | B3: ACTFLO | C3: R_ES-SH-DH-70_COA | D3: R_ES-DH-70-SpHeat | E3: - | F3: - | G3: 2010 | H3: commodity_group | I3: - | J3: - | K3: - | L3: 0.7 | M3: 0.84000944 | N3: 0.81118081 | O3: 0.81351118 | P3: 0.76823819 | Q3: 0.92459294 | R3: 0.7 | S3: 0.80041513 | T3: 0.92459294 | U3: 0.7 | V3: 0.77552864 | W3: 0.7 | X3: 0.75325271 | Y3: 0.87390787 | Z3: 0.85293754 | AA3: 0.74878229 | AB3: 0.7876654 | AC3: 0.80013745 | AD3: 0.7 | AE3: 0.79418328 | AF3: 0.81118081 | AG3: 0.80856567 | AH3: 0.84657514 | AI3: 0.8283423 | AJ3: 0.81118081 | AK3: 0.7 | AL3: 0.7 | AM3: 0.87282859 | AN3: 0.7 | AO3: 0.83735337 | AP3: 0.7 | AQ3: 0.78986581 | AR3: 0.81118081 | AS3: 0.7 | AT3: 0.82758004 | AU3: 0.80138951 | AV3: 0.82867758 | AW3: -
A4: BASE | B4: ACTFLO | C4: R_ES-SH-DH-70_ELC-HPA | D4: R_ES-DH-70-SpHeat | E4: - | F4: - | G4: 2010 | H4: commodity_group | I4: - | J4: - | K4: - | L4: 0.72282882 | M4: 0.81928901 | N4: 0.71202455 | O4: 0.799003 | P4: 0.7340881 | Q4: 0.86347572 | R4: 0.70618229 | S4: 0.70582025 | T4: 0.86347572 | U4: 0.8001875 | V4: 0.75698599 | W4: 0.72282882 | X4: 0.71635951 | Y4: 0.81733074 | Z4: 0.81671824 | AA4: 0.71202455 | AB4: 0.72917682 | AC4: 0.75951434 | AD4: 0.8001875 | AE4: 0.76164436 | AF4: 0.71202455 | AG4: 0.72542657 | AH4: 0.78087502 | AI4: 0.7595127 | AJ4: 0.71202455 | AK4: 0.72282882 | AL4: 0.67551175 | AM4: 0.82446857 | AN4: 0.8001875 | AO4: 0.77572558 | AP4: 0.74814389 | AQ4: 0.72440504 | AR4: 0.71202455 | AS4: 0.72971726 | AT4: 0.77385528 | AU4: 0.68382179 | AV4: 0.77247864 | AW4: -
A5: BASE | B5: ACTFLO | C5: R_ES-SH-DH-70_ELC-HPG | D5: R_ES-DH-70-SpHeat | E5: - | F5: - | G5: 2010 | H5: commodity_group | I5: - | J5: - | K5: - | L5: 0.72282882 | M5: 0.81928901 | N5: 0.71202455 | O5: 0.799003 | P5: 0.7340881 | Q5: 0.86347572 | R5: 0.70618229 | S5: 0.70582025 | T5: 0.86347572 | U5: 0.8001875 | V5: 0.75698599 | W5: 0.72282882 | X5: 0.71635951 | Y5: 0.81733074 | Z5: 0.81671824 | AA5: 0.71202455 | AB5: 0.72917682 | AC5: 0.75951434 | AD5: 0.8001875 | AE5: 0.76164436 | AF5: 0.71202455 | AG5: 0.72542657 | AH5: 0.78087502 | AI5: 0.7595127 | AJ5: 0.71202455 | AK5: 0.72282882 | AL5: 0.67551175 | AM5: 0.82446857 | AN5: 0.8001875 | AO5: 0.77572558 | AP5: 0.74814389 | AQ5: 0.72440504 | AR5: 0.71202455 | AS5: 0.72971726 | AT5: 0.77385528 | AU5: 0.68382179 | AV5: 0.77247864 | AW5: -
A6: BASE | B6: ACTFLO | C6: R_ES-SH-DH-70_ELC-R | D6: R_ES-DH-70-SpHeat | E6: - | F6: - | G6: 2010 | H6: commodity_group | I6: - | J6: - | K6: - | L6: 0.72282882 | M6: 0.81928901 | N6: 0.71202455 | O6: 0.799003 | P6: 0.7340881 | Q6: 0.86347572 | R6: 0.70618229 | S6: 0.70582025 | T6: 0.86347572 | U6: 0.8001875 | V6: 0.75698599 | W6: 0.72282882 | X6: 0.71635951 | Y6: 0.81733074 | Z6: 0.81671824 | AA6: 0.71202455 | AB6: 0.72917682 | AC6: 0.75951434 | AD6: 0.8001875 | AE6: 0.76164436 | AF6: 0.71202455 | AG6: 0.72542657 | AH6: 0.78087502 | AI6: 0.7595127 | AJ6: 0.71202455 | AK6: 0.72282882 | AL6: 0.67551175 | AM6: 0.82446857 | AN6: 0.8001875 | AO6: 0.77572558 | AP6: 0.74814389 | AQ6: 0.72440504 | AR6: 0.71202455 | AS6: 0.72971726 | AT6: 0.77385528 | AU6: 0.68382179 | AV6: 0.77247864 | AW6: -
A7: BASE | B7: ACTFLO | C7: R_ES-SH-DH-70_GAS | D7: R_ES-DH-70-SpHeat | E7: - | F7: - | G7: 2010 | H7: commodity_group | I7: - | J7: - | K7: - | L7: 0.78014366 | M7: 0.75592888 | N7: 0.7449943 | O7: 0.74380141 | P7: 0.74639155 | Q7: 0.81017863 | R7: 0.7 | S7: 0.73442601 | T7: 0.81017863 | U7: 0.78641563 | V7: 0.78019664 | W7: 0.78014366 | X7: 0.71577683 | Y7: 0.77841878 | Z7: 0.76097692 | AA7: 0.7449943 | AB7: 0.72153447 | AC7: 0.75604428 | AD7: 0.78641563 | AE7: 0.7268583 | AF7: 0.7449943 | AG7: 0.74154132 | AH7: 0.76486371 | AI7: 0.78490217 | AJ7: 0.7449943 | AK7: 0.78014366 | AL7: 0.7 | AM7: 0.77566284 | AN7: 0.78641563 | AO7: 0.7735443 | AP7: 0.78557278 | AQ7: 0.70221298 | AR7: 0.7449943 | AS7: 0.73166795 | AT7: 0.7894079 | AU7: 0.70945499 | AV7: 0.75515261 | AW7: -
A8: BASE | B8: ACTFLO | C8: R_ES-SH-DH-70_GEO | D8: R_ES-DH-70-SpHeat | E8: - | F8: - | G8: 2010 | H8: commodity_group | I8: - | J8: - | K8: - | L8: 0.85983635 | M8: 0.88333199 | N8: 0.86884496 | O8: 0.83553618 | P8: 0.81206531 | Q8: 0.95587493 | R8: 0.8 | S8: 0.85208331 | T8: 0.95587493 | U8: 0.91841114 | V8: 0.89056812 | W8: 0.76932726 | X8: 0.8 | Y8: 0.91664483 | Z8: 0.88619005 | AA8: 0.82057579 | AB8: 0.78352711 | AC8: 0.8 | AD8: 0.91841114 | AE8: 0.84751573 | AF8: 0.86884496 | AG8: 0.85076796 | AH8: 0.8 | AI8: 0.89852031 | AJ8: 0.86884496 | AK8: 0.85983635 | AL8: 0.8 | AM8: 0.90645522 | AN8: 0.91841114 | AO8: 0.89540543 | AP8: 0.8909757 | AQ8: 0.81167632 | AR8: 0.86884496 | AS8: 0.80134177 | AT8: 0.89751538 | AU8: 0.82350393 | AV8: 0.86559601 | AW8: -
A9: BASE | B9: ACTFLO | C9: R_ES-SH-DH-70_HET | D9: R_ES-DH-70-SpHeat | E9: - | F9: - | G9: 2010 | H9: commodity_group | I9: - | J9: - | K9: - | L9: 0.85983635 | M9: 0.88333199 | N9: 0.86884496 | O9: 0.83553618 | P9: 0.81206531 | Q9: 0.95587493 | R9: 0.8 | S9: 0.85208331 | T9: 0.95587493 | U9: 0.91841114 | V9: 0.89056812 | W9: 0.76932726 | X9: 0.8 | Y9: 0.91664483 | Z9: 0.88619005 | AA9: 0.82057579 | AB9: 0.78352711 | AC9: 0.8 | AD9: 0.91841114 | AE9: 0.84751573 | AF9: 0.86884496 | AG9: 0.85076796 | AH9: 0.8 | AI9: 0.89852031 | AJ9: 0.86884496 | AK9: 0.85983635 | AL9: 0.8 | AM9: 0.90645522 | AN9: 0.91841114 | AO9: 0.89540543 | AP9: 0.8909757 | AQ9: 0.81167632 | AR9: 0.86884496 | AS9: 0.80134177 | AT9: 0.89751538 | AU9: 0.82350393 | AV9: 0.86559601 | AW9: -
A10: BASE | B10: ACTFLO | C10: R_ES-SH-DH-70_LPG | D10: R_ES-DH-70-SpHeat | E10: - | F10: - | G10: 2010 | H10: commodity_group | I10: - | J10: - | K10: - | L10: 0.77466709 | M10: 0.80046714 | N10: 0.78562799 | O10: 0.78828873 | P10: 0.79832009 | Q10: 0.85774115 | R10: 0.58765689 | S10: 0.7 | T10: 0.85774115 | U10: 0.81901204 | V10: 0.81235393 | W10: 0.77466709 | X10: 0.73343396 | Y10: 0.80783474 | Z10: 0.80927992 | AA10: 0.73652624 | AB10: 0.7 | AC10: 0.79660266 | AD10: 0.81901204 | AE10: 0.77871481 | AF10: 0.78562799 | AG10: 0.88346567 | AH10: 0.81205753 | AI10: 0.87388164 | AJ10: 0.78562799 | AK10: 0.77466709 | AL10: 0.7 | AM10: 0.85466749 | AN10: 0.81901204 | AO10: 0.85913534 | AP10: 0.87110463 | AQ10: 0.78550869 | AR10: 0.78562799 | AS10: 0.80143671 | AT10: 0.792354 | AU10: 0.7 | AV10: 0.81555876 | AW10: -
A11: BASE | B11: ACTFLO | C11: R_ES-SH-DH-70_OIL | D11: R_ES-DH-70-SpHeat | E11: - | F11: - | G11: 2010 | H11: commodity_group | I11: - | J11: - | K11: - | L11: 0.77466709 | M11: 0.80046714 | N11: 0.78562799 | O11: 0.78828873 | P11: 0.79832009 | Q11: 0.85774115 | R11: 0.58765689 | S11: 0.7 | T11: 0.85774115 | U11: 0.81901204 | V11: 0.81235393 | W11: 0.77466709 | X11: 0.73343396 | Y11: 0.80783474 | Z11: 0.80927992 | AA11: 0.73652624 | AB11: 0.7 | AC11: 0.79660266 | AD11: 0.81901204 | AE11: 0.77871481 | AF11: 0.78562799 | AG11: 0.88346567 | AH11: 0.81205753 | AI11: 0.87388164 | AJ11: 0.78562799 | AK11: 0.77466709 | AL11: 0.7 | AM11: 0.85466749 | AN11: 0.81901204 | AO11: 0.85913534 | AP11: 0.87110463 | AQ11: 0.78550869 | AR11: 0.78562799 | AS11: 0.80143671 | AT11: 0.792354 | AU11: 0.7 | AV11: 0.81555876 | AW11: -
A12: BASE | B12: ACTFLO | C12: R_ES-SH-DH_BIO | D12: R_ES-DH-SpHeat | E12: - | F12: - | G12: 2010 | H12: commodity_group | I12: - | J12: - | K12: - | L12: 0.74633079 | M12: 0.79425199 | N12: 0.76016377 | O12: 0.78997503 | P12: 0.72609118 | Q12: 0.88939691 | R12: 0.56988643 | S12: 0.75698357 | T12: 0.88939691 | U12: 0.84781454 | V12: 0.73363854 | W12: 0.74633079 | X12: 0.70928681 | Y12: 0.83322321 | Z12: 0.79998616 | AA12: 0.70586636 | AB12: 0.76441135 | AC12: 0.76351422 | AD12: 0.84781454 | AE12: 0.76866988 | AF12: 0.76016377 | AG12: 0.74146384 | AH12: 0.79040869 | AI12: 0.79542896 | AJ12: 0.76016377 | AK12: 0.74633079 | AL12: 1.0434129 | AM12: 0.82267628 | AN12: 0.84781454 | AO12: 0.7832275 | AP12: 0.79601791 | AQ12: 0.73191705 | AR12: 0.76016377 | AS12: 0.7 | AT12: 0.78984393 | AU12: 0.7395726 | AV12: 0.81749292 | AW12: -
A13: BASE | B13: ACTFLO | C13: R_ES-SH-DH_COA | D13: R_ES-DH-SpHeat | E13: - | F13: - | G13: 2010 | H13: commodity_group | I13: - | J13: - | K13: - | L13: 0.7 | M13: 0.84000944 | N13: 0.81118081 | O13: 0.81351118 | P13: 0.76823819 | Q13: 0.92459294 | R13: 0.7 | S13: 0.80041513 | T13: 0.92459294 | U13: 0.7 | V13: 0.77552864 | W13: 0.7 | X13: 0.75325271 | Y13: 0.87390787 | Z13: 0.85293754 | AA13: 0.74878229 | AB13: 0.7876654 | AC13: 0.80013745 | AD13: 0.7 | AE13: 0.79418328 | AF13: 0.81118081 | AG13: 0.80856567 | AH13: 0.84657514 | AI13: 0.8283423 | AJ13: 0.81118081 | AK13: 0.7 | AL13: 0.7 | AM13: 0.87282859 | AN13: 0.7 | AO13: 0.83735337 | AP13: 0.7 | AQ13: 0.78986581 | AR13: 0.81118081 | AS13: 0.7 | AT13: 0.82758004 | AU13: 0.80138951 | AV13: 0.82867758 | AW13: -
... A121: BASE | B121: EFF | C121: R_ES-SH-SD_OIL | D121: - | E121: - | F121: ANNUAL | G121: 2010 | H121: - | I121: - | J121: - | K121: - | L121: 0.75 | M121: 0.8 | N121: 0.75 | O121: 0.8 | P121: 0.75 | Q121: 0.8 | R121: 0.8 | S121: 0.75 | T121: 0.8 | U121: 0.8 | V121: 0.8 | W121: 0.75 | X121: 0.8 | Y121: 0.8 | Z121: 0.8 | AA121: 0.8 | AB121: 0.75 | AC121: 0.8 | AD121: 0.8 | AE121: 0.8 | AF121: 0.75 | AG121: 0.75 | AH121: 0.8 | AI121: 0.75 | AJ121: 0.75 | AK121: 0.75 | AL121: 0.75 | AM121: 0.8 | AN121: 0.8 | AO121: 0.75 | AP121: 0.75 | AQ121: 0.75 | AR121: 0.75 | AS121: 0.8 | AT121: 0.8 | AU121: 0.75 | AV121: 0.8 | AW121: -

Sheet RES_WatHeat
A1: scenario | B1: attribute | C1: process | D1: commodity | E1: lim_type | F1: time_slice | G1: year | H1: commodity_group | I1: currency | J1: stage | K1: sow | L1: AL | M1: AT | N1: BA | O1: BE | P1: BG | Q1: CH | R1: CY | S1: CZ | T1: DE | U1: DK | V1: EE | W1: EL | X1: ES | Y1: FI | Z1: FR | AA1: HR | AB1: HU | AC1: IE | AD1: IS | AE1: IT | AF1: KS | AG1: LT | AH1: LU | AI1: LV | AJ1: ME | AK1: MK | AL1: MT | AM1: NL | AN1: NO | AO1: PL | AP1: PT | AQ1: RO | AR1: RS | AS1: SE | AT1: SI | AU1: SK | AV1: UK | AW1: year2
A2: BASE | B2: AFA | C2: R_ES-WH-DH_BIO | D2: - | E2: UP | F2: - | G2: 2010 | H2: - | I2: - | J2: - | K2: - | L2: 0.024815579 | M2: 0.02616379 | N2: 0.013092413 | O2: 0.022154431 | P2: 0.017639248 | Q2: 0.019789784 | R2: 0.022016615 | S2: 0.016570422 | T2: 0.021416336 | U2: 0.022609527 | V2: 0.020783505 | W2: 0.024236124 | X2: 0.02792954 | Y2: 0.0264163 | Z2: 0.023146812 | AA2: 0.014271101 | AB2: 0.012408249 | AC2: 0.025003153 | AD2: 0.024491869 | AE2: 0.01963372 | AF2: 0.0099620397 | AG2: 0.017074148 | AH2: 0.017815471 | AI2: 0.023953567 | AJ2: 0.017648292 | AK2: 0.014569274 | AL2: 0.010716071 | AM2: 0.021496708 | AN2: 0.035834053 | AO2: 0.021342082 | AP2: 0.03445659 | AQ2: 0.014301223 | AR2: 0.016109247 | AS2: 0.021612123 | AT2: 0.028772249 | AU2: 0.021840343 | AV2: 0.021419366 | AW2: -
A3: BASE | B3: AFA | C3: R_ES-WH-DH_COA | D3: - | E3: UP | F3: - | G3: 2010 | H3: - | I3: - | J3: - | K3: - | L3: 0.024815579 | M3: 0.02616379 | N3: 0.013092413 | O3: 0.022154431 | P3: 0.017639248 | Q3: 0.019789784 | R3: 0.022016615 | S3: 0.016570422 | T3: 0.021416336 | U3: 0.022609527 | V3: 0.020783505 | W3: 0.024236124 | X3: 0.02792954 | Y3: 0.0264163 | Z3: 0.023146812 | AA3: 0.014271101 | AB3: 0.012408249 | AC3: 0.025003153 | AD3: 0.024491869 | AE3: 0.01963372 | AF3: 0.0099620397 | AG3: 0.017074148 | AH3: 0.017815471 | AI3: 0.023953567 | AJ3: 0.017648292 | AK3: 0.014569274 | AL3: 0.010716071 | AM3: 0.021496708 | AN3: 0.035834053 | AO3: 0.021342082 | AP3: 0.03445659 | AQ3: 0.014301223 | AR3: 0.016109247 | AS3: 0.021612123 | AT3: 0.028772249 | AU3: 0.021840343 | AV3: 0.021419366 | AW3: -
A4: BASE | B4: AFA | C4: R_ES-WH-DH_ELC | D4: - | E4: UP | F4: - | G4: 2010 | H4: - | I4: - | J4: - | K4: - | L4: 0.074446738 | M4: 0.07849137 | N4: 0.03927724 | O4: 0.066463294 | P4: 0.052917743 | Q4: 0.059369353 | R4: 0.066049845 | S4: 0.049711265 | T4: 0.064249008 | U4: 0.06782858 | V4: 0.062350515 | W4: 0.072708373 | X4: 0.083788621 | Y4: 0.079248901 | Z4: 0.069440436 | AA4: 0.042813302 | AB4: 0.037224746 | AC4: 0.07500946 | AD4: 0.073475606 | AE4: 0.058901159 | AF4: 0.029886119 | AG4: 0.051222444 | AH4: 0.053446413 | AI4: 0.071860701 | AJ4: 0.052944877 | AK4: 0.043707822 | AL4: 0.032148212 | AM4: 0.064490123 | AN4: 0.10750216 | AO4: 0.064026246 | AP4: 0.10336977 | AQ4: 0.042903668 | AR4: 0.048327741 | AS4: 0.064836369 | AT4: 0.086316746 | AU4: 0.065521028 | AV4: 0.064258097 | AW4: -
A5: BASE | B5: AFA | C5: R_ES-WH-DH_GAS | D5: - | E5: UP | F5: - | G5: 2010 | H5: - | I5: - | J5: - | K5: - | L5: 0.031019474 | M5: 0.032704737 | N5: 0.016365517 | O5: 0.027693039 | P5: 0.02204906 | Q5: 0.02473723 | R5: 0.027520769 | S5: 0.020713027 | T5: 0.02677042 | U5: 0.028261908 | V5: 0.025979381 | W5: 0.030295155 | X5: 0.034911925 | Y5: 0.033020375 | Z5: 0.028933515 | AA5: 0.017838876 | AB5: 0.015510311 | AC5: 0.031253942 | AD5: 0.030614836 | AE5: 0.02454215 | AF5: 0.01245255 | AG5: 0.021342685 | AH5: 0.022269339 | AI5: 0.029941959 | AJ5: 0.022060365 | AK5: 0.018211592 | AL5: 0.013395089 | AM5: 0.026870885 | AN5: 0.044792567 | AO5: 0.026677603 | AP5: 0.043070738 | AQ5: 0.017876528 | AR5: 0.020136559 | AS5: 0.027015154 | AT5: 0.035965311 | AU5: 0.027300428 | AV5: 0.026774207 | AW5: -
A6: BASE | B6: AFA | C6: R_ES-WH-DH_HET | D6: - | E6: UP | F6: - | G6: 2010 | H6: - | I6: - | J6: - | K6: - | L6: 0.024815579 | M6: 0.02616379 | N6: 0.013092413 | O6: 0.022154431 | P6: 0.017639248 | Q6: 0.019789784 | R6: 0.022016615 | S6: 0.016570422 | T6: 0.021416336 | U6: 0.022609527 | V6: 0.020783505 | W6: 0.024236124 | X6: 0.02792954 | Y6: 0.0264163 | Z6: 0.023146812 | AA6: 0.014271101 | AB6: 0.012408249 | AC6: 0.025003153 | AD6: 0.024491869 | AE6: 0.01963372 | AF6: 0.0099620397 | AG6: 0.017074148 | AH6: 0.017815471 | AI6: 0.023953567 | AJ6: 0.017648292 | AK6: 0.014569274 | AL6: 0.010716071 | AM6: 0.021496708 | AN6: 0.035834053 | AO6: 0.021342082 | AP6: 0.03445659 | AQ6: 0.014301223 | AR6: 0.016109247 | AS6: 0.021612123 | AT6: 0.028772249 | AU6: 0.021840343 | AV6: 0.021419366 | AW6: -
A7: BASE | B7: AFA | C7: R_ES-WH-DH_LPG | D7: - | E7: UP | F7: - | G7: 2010 | H7: - | I7: - | J7: - | K7: - | L7: 0.031019474 | M7: 0.032704737 | N7: 0.016365517 | O7: 0.027693039 | P7: 0.02204906 | Q7: 0.02473723 | R7: 0.027520769 | S7: 0.020713027 | T7: 0.02677042 | U7: 0.028261908 | V7: 0.025979381 | W7: 0.030295155 | X7: 0.034911925 | Y7: 0.033020375 | Z7: 0.028933515 | AA7: 0.017838876 | AB7: 0.015510311 | AC7: 0.031253942 | AD7: 0.030614836 | AE7: 0.02454215 | AF7: 0.01245255 | AG7: 0.021342685 | AH7: 0.022269339 | AI7: 0.029941959 | AJ7: 0.022060365 | AK7: 0.018211592 | AL7: 0.013395089 | AM7: 0.026870885 | AN7: 0.044792567 | AO7: 0.026677603 | AP7: 0.043070738 | AQ7: 0.017876528 | AR7: 0.020136559 | AS7: 0.027015154 | AT7: 0.035965311 | AU7: 0.027300428 | AV7: 0.026774207 | AW7: -
A8: BASE | B8: AFA | C8: R_ES-WH-DH_OIL | D8: - | E8: UP | F8: - | G8: 2010 | H8: - | I8: - | J8: - | K8: - | L8: 0.024815579 | M8: 0.02616379 | N8: 0.013092413 | O8: 0.022154431 | P8: 0.017639248 | Q8: 0.019789784 | R8: 0.022016615 | S8: 0.016570422 | T8: 0.021416336 | U8: 0.022609527 | V8: 0.020783505 | W8: 0.024236124 | X8: 0.02792954 | Y8: 0.0264163 | Z8: 0.023146812 | AA8: 0.014271101 | AB8: 0.012408249 | AC8: 0.025003153 | AD8: 0.024491869 | AE8: 0.01963372 | AF8: 0.0099620397 | AG8: 0.017074148 | AH8: 0.017815471 | AI8: 0.023953567 | AJ8: 0.017648292 | AK8: 0.014569274 | AL8: 0.010716071 | AM8: 0.021496708 | AN8: 0.035834053 | AO8: 0.021342082 | AP8: 0.03445659 | AQ8: 0.014301223 | AR8: 0.016109247 | AS8: 0.021612123 | AT8: 0.028772249 | AU8: 0.021840343 | AV8: 0.021419366 | AW8: -
A9: BASE | B9: AFA | C9: R_ES-WH-DH_SOL | D9: - | E9: UP | F9: - | G9: 2010 | H9: - | I9: - | J9: - | K9: - | L9: 0.024815579 | M9: 0.02616379 | N9: 0.013092413 | O9: 0.022154431 | P9: 0.017639248 | Q9: 0.019789784 | R9: 0.022016615 | S9: 0.016570422 | T9: 0.021416336 | U9: 0.022609527 | V9: 0.020783505 | W9: 0.024236124 | X9: 0.02792954 | Y9: 0.0264163 | Z9: 0.023146812 | AA9: 0.014271101 | AB9: 0.012408249 | AC9: 0.025003153 | AD9: 0.024491869 | AE9: 0.01963372 | AF9: 0.0099620397 | AG9: 0.017074148 | AH9: 0.017815471 | AI9: 0.023953567 | AJ9: 0.017648292 | AK9: 0.014569274 | AL9: 0.010716071 | AM9: 0.021496708 | AN9: 0.035834053 | AO9: 0.021342082 | AP9: 0.03445659 | AQ9: 0.014301223 | AR9: 0.016109247 | AS9: 0.021612123 | AT9: 0.028772249 | AU9: 0.021840343 | AV9: 0.021419366 | AW9: -
A10: BASE | B10: AFA | C10: R_ES-WH-FL_BIO | D10: - | E10: UP | F10: - | G10: 2010 | H10: - | I10: - | J10: - | K10: - | L10: 0.093058422 | M10: 0.098114212 | N10: 0.04909655 | O10: 0.083079118 | P10: 0.066147179 | Q10: 0.074211691 | R10: 0.082562306 | S10: 0.062139082 | T10: 0.08031126 | U10: 0.084785725 | V10: 0.077938143 | W10: 0.090885466 | X10: 0.10473578 | Y10: 0.099061126 | Z10: 0.086800545 | AA10: 0.053516628 | AB10: 0.046530933 | AC10: 0.093761825 | AD10: 0.091844508 | AE10: 0.073626449 | AF10: 0.037357649 | AG10: 0.064028055 | AH10: 0.066808016 | AI10: 0.089825876 | AJ10: 0.066181096 | AK10: 0.054634777 | AL10: 0.040185266 | AM10: 0.080612654 | AN10: 0.1343777 | AO10: 0.080032808 | AP10: 0.12921221 | AQ10: 0.053629585 | AR10: 0.060409676 | AS10: 0.081045461 | AT10: 0.10789593 | AU10: 0.081901285 | AV10: 0.080322621 | AW10: -
A11: BASE | B11: AFA | C11: R_ES-WH-FL_COA | D11: - | E11: UP | F11: - | G11: 2010 | H11: - | I11: - | J11: - | K11: - | L11: 0.093058422 | M11: 0.098114212 | N11: 0.04909655 | O11: 0.083079118 | P11: 0.066147179 | Q11: 0.074211691 | R11: 0.082562306 | S11: 0.062139082 | T11: 0.08031126 | U11: 0.084785725 | V11: 0.077938143 | W11: 0.090885466 | X11: 0.10473578 | Y11: 0.099061126 | Z11: 0.086800545 | AA11: 0.053516628 | AB11: 0.046530933 | AC11: 0.093761825 | AD11: 0.091844508 | AE11: 0.073626449 | AF11: 0.037357649 | AG11: 0.064028055 | AH11: 0.066808016 | AI11: 0.089825876 | AJ11: 0.066181096 | AK11: 0.054634777 | AL11: 0.040185266 | AM11: 0.080612654 | AN11: 0.1343777 | AO11: 0.080032808 | AP11: 0.12921221 | AQ11: 0.053629585 | AR11: 0.060409676 | AS11: 0.081045461 | AT11: 0.10789593 | AU11: 0.081901285 | AV11: 0.080322621 | AW11: -
A12: BASE | B12: AFA | C12: R_ES-WH-FL_ELC | D12: - | E12: UP | F12: - | G12: 2010 | H12: - | I12: - | J12: - | K12: - | L12: 0.093058422 | M12: 0.098114212 | N12: 0.04909655 | O12: 0.083079118 | P12: 0.066147179 | Q12: 0.074211691 | R12: 0.082562306 | S12: 0.062139082 | T12: 0.08031126 | U12: 0.084785725 | V12: 0.077938143 | W12: 0.090885466 | X12: 0.10473578 | Y12: 0.099061126 | Z12: 0.086800545 | AA12: 0.053516628 | AB12: 0.046530933 | AC12: 0.093761825 | AD12: 0.091844508 | AE12: 0.073626449 | AF12: 0.037357649 | AG12: 0.064028055 | AH12: 0.066808016 | AI12: 0.089825876 | AJ12: 0.066181096 | AK12: 0.054634777 | AL12: 0.040185266 | AM12: 0.080612654 | AN12: 0.1343777 | AO12: 0.080032808 | AP12: 0.12921221 | AQ12: 0.053629585 | AR12: 0.060409676 | AS12: 0.081045461 | AT12: 0.10789593 | AU12: 0.081901285 | AV12: 0.080322621 | AW12: -
A13: BASE | B13: AFA | C13: R_ES-WH-FL_GAS | D13: - | E13: UP | F13: - | G13: 2010 | H13: - | I13: - | J13: - | K13: - | L13: 0.093058422 | M13: 0.098114212 | N13: 0.04909655 | O13: 0.083079118 | P13: 0.066147179 | Q13: 0.074211691 | R13: 0.082562306 | S13: 0.062139082 | T13: 0.08031126 | U13: 0.084785725 | V13: 0.077938143 | W13: 0.090885466 | X13: 0.10473578 | Y13: 0.099061126 | Z13: 0.086800545 | AA13: 0.053516628 | AB13: 0.046530933 | AC13: 0.093761825 | AD13: 0.091844508 | AE13: 0.073626449 | AF13: 0.037357649 | AG13: 0.064028055 | AH13: 0.066808016 | AI13: 0.089825876 | AJ13: 0.066181096 | AK13: 0.054634777 | AL13: 0.040185266 | AM13: 0.080612654 | AN13: 0.1343777 | AO13: 0.080032808 | AP13: 0.12921221 | AQ13: 0.053629585 | AR13: 0.060409676 | AS13: 0.081045461 | AT13: 0.10789593 | AU13: 0.081901285 | AV13: 0.080322621 | AW13: -
... A49: BASE | B49: EFF | C49: R_ES-WH-SD_SOL | D49: - | E49: - | F49: ANNUAL | G49: 2010 | H49: - | I49: - | J49: - | K49: - | L49: 0.81 | M49: 0.89 | N49: 0.82 | O49: 0.87 | P49: 0.78 | Q49: 0.95 | R49: 0.65 | S49: 0.81 | T49: 0.95 | U49: 0.92 | V49: 0.84 | W49: 0.81 | X49: 0.65 | Y49: 0.92 | Z49: 0.89 | AA49: 0.82 | AB49: 0.8 | AC49: 0.65 | AD49: 0.92 | AE49: 0.85650558 | AF49: 0.82 | AG49: 0.81 | AH49: 0.65 | AI49: 0.84 | AJ49: 0.82 | AK49: 0.81 | AL49: 0.65 | AM49: 0.91 | AN49: 0.92 | AO49: 0.84 | AP49: 0.86 | AQ49: 0.78 | AR49: 0.82 | AS49: 0.84 | AT49: 0.88 | AU49: 0.78 | AV49: 0.65 | AW49: -

Sheet RES_SpCool
A1: scenario | B1: attribute | C1: process | D1: commodity | E1: lim_type | F1: time_slice | G1: year | H1: commodity_group | I1: currency | J1: stage | K1: sow | L1: AL | M1: AT | N1: BA | O1: BE | P1: BG | Q1: CH | R1: CY | S1: CZ | T1: DE | U1: DK | V1: EE | W1: EL | X1: ES | Y1: FI | Z1: FR | AA1: HR | AB1: HU | AC1: IE | AD1: IS | AE1: IT | AF1: KS | AG1: LT | AH1: LU | AI1: LV | AJ1: ME | AK1: MK | AL1: MT | AM1: NL | AN1: NO | AO1: PL | AP1: PT | AQ1: RO | AR1: RS | AS1: SE | AT1: SI | AU1: SK | AV1: UK | AW1: year2
A2: BASE | B2: AFA | C2: R_ES-SC-DH_ELC | D2: - | E2: UP | F2: - | G2: 2010 | H2: - | I2: - | J2: - | K2: - | L2: 0.02288359 | M2: 0.0021302164 | N2: 0.054996059 | O2: 0.0069617957 | P2: 0.0036027425 | Q2: 0.002159531 | R2: 0.049181985 | S2: 0.00039949171 | T2: 0.0019130725 | U2: 0.0014437084 | V2: 8.1419412e-05 | W2: 0.017147161 | X2: 0.012724499 | Y2: 0.00051828235 | Z2: 0.014718315 | AA2: 0.026783388 | AB2: 0.00042401414 | AC2: 0.0011683861 | AD2: 0.00045030461 | AE2: 0.013152332 | AF2: 0.046086779 | AG2: 6.6124823e-05 | AH2: 0.019752038 | AI2: 1.0873074e-05 | AJ2: 0.022813613 | AK2: 0.065256273 | AL2: 0.056542395 | AM2: 0.0045234859 | AN2: 0.0016626781 | AO2: 0.00026127893 | AP2: 0.009162039 | AQ2: 0.00054641281 | AR2: 0.059964651 | AS2: 0.0010973361 | AT2: 0.004211295 | AU2: 0.0013208195 | AV2: 0.00078546003 | AW2: -
A3: BASE | B3: AFA | C3: R_ES-SC-FL_ELC | D3: - | E3: UP | F3: - | G3: 2010 | H3: - | I3: - | J3: - | K3: - | L3: 0.02288359 | M3: 0.0021302164 | N3: 0.054996059 | O3: 0.0069617957 | P3: 0.0036027425 | Q3: 0.002159531 | R3: 0.049181985 | S3: 0.00039949171 | T3: 0.0019130725 | U3: 0.0014437084 | V3: 8.1419412e-05 | W3: 0.017147161 | X3: 0.012724499 | Y3: 0.00051828235 | Z3: 0.014718315 | AA3: 0.026783388 | AB3: 0.00042401414 | AC3: 0.0011683861 | AD3: 0.00045030461 | AE3: 0.013152332 | AF3: 0.046086779 | AG3: 6.6124823e-05 | AH3: 0.019752038 | AI3: 1.0873074e-05 | AJ3: 0.022813613 | AK3: 0.065256273 | AL3: 0.056542395 | AM3: 0.0045234859 | AN3: 0.0016626781 | AO3: 0.00026127893 | AP3: 0.009162039 | AQ3: 0.00054641281 | AR3: 0.059964651 | AS3: 0.0010973361 | AT3: 0.004211295 | AU3: 0.0013208195 | AV3: 0.00078546003 | AW3: -
A4: BASE | B4: AFA | C4: R_ES-SC-SD_ELC | D4: - | E4: UP | F4: - | G4: 2010 | H4: - | I4: - | J4: - | K4: - | L4: 0.02288359 | M4: 0.0021302164 | N4: 0.054996059 | O4: 0.0069617957 | P4: 0.0036027425 | Q4: 0.002159531 | R4: 0.049181985 | S4: 0.00039949171 | T4: 0.0019130725 | U4: 0.0014437084 | V4: 8.1419412e-05 | W4: 0.017147161 | X4: 0.012724499 | Y4: 0.00051828235 | Z4: 0.014718315 | AA4: 0.026783388 | AB4: 0.00042401414 | AC4: 0.0011683861 | AD4: 0.00045030461 | AE4: 0.013152332 | AF4: 0.046086779 | AG4: 6.6124823e-05 | AH4: 0.019752038 | AI4: 1.0873074e-05 | AJ4: 0.022813613 | AK4: 0.065256273 | AL4: 0.056542395 | AM4: 0.0045234859 | AN4: 0.0016626781 | AO4: 0.00026127893 | AP4: 0.009162039 | AQ4: 0.00054641281 | AR4: 0.059964651 | AS4: 0.0010973361 | AT4: 0.004211295 | AU4: 0.0013208195 | AV4: 0.00078546003 | AW4: -
A5: BASE | B5: EFF | C5: R_ES-SC-DH_ELC | D5: - | E5: - | F5: ANNUAL | G5: 2010 | H5: - | I5: - | J5: - | K5: - | L5: 1.95 | M5: 2.1 | N5: 1.97 | O5: 2.05 | P5: 1.9 | Q5: 2.19 | R5: 1.8 | S5: 1.95 | T5: 2.19 | U5: 2.14 | V5: 2 | W5: 1.95 | X5: 2 | Y5: 2.14 | Z5: 2.1 | AA5: 1.97 | AB5: 1.92 | AC5: 2.07 | AD5: 2.14 | AE5: 2.03 | AF5: 1.97 | AG5: 1.95 | AH5: 2.1 | AI5: 2 | AJ5: 1.97 | AK5: 1.95 | AL5: 1.85 | AM5: 2.125 | AN5: 2.14 | AO5: 2 | AP5: 2.03 | AQ5: 1.9 | AR5: 1.97 | AS5: 2 | AT5: 2.07 | AU5: 1.9 | AV5: 2.07 | AW5: -
A6: BASE | B6: EFF | C6: R_ES-SC-FL_ELC | D6: - | E6: - | F6: ANNUAL | G6: 2010 | H6: - | I6: - | J6: - | K6: - | L6: 1.95 | M6: 2.1 | N6: 1.97 | O6: 2.05 | P6: 1.9 | Q6: 2.19 | R6: 1.8 | S6: 1.95 | T6: 2.19 | U6: 2.14 | V6: 2 | W6: 1.95 | X6: 2 | Y6: 2.14 | Z6: 2.1 | AA6: 1.97 | AB6: 1.92 | AC6: 2.07 | AD6: 2.14 | AE6: 2.03 | AF6: 1.97 | AG6: 1.95 | AH6: 2.1 | AI6: 2 | AJ6: 1.97 | AK6: 1.95 | AL6: 1.85 | AM6: 2.125 | AN6: 2.14 | AO6: 2 | AP6: 2.03 | AQ6: 1.9 | AR6: 1.97 | AS6: 2 | AT6: 2.07 | AU6: 1.9 | AV6: 2.07 | AW6: -
A7: BASE | B7: EFF | C7: R_ES-SC-SD_ELC | D7: - | E7: - | F7: ANNUAL | G7: 2010 | H7: - | I7: - | J7: - | K7: - | L7: 1.95 | M7: 2.1 | N7: 1.97 | O7: 2.05 | P7: 1.9 | Q7: 2.19 | R7: 1.8 | S7: 1.95 | T7: 2.19 | U7: 2.14 | V7: 2 | W7: 1.95 | X7: 2 | Y7: 2.14 | Z7: 2.1 | AA7: 1.97 | AB7: 1.92 | AC7: 2.07 | AD7: 2.14 | AE7: 2.03 | AF7: 1.97 | AG7: 1.95 | AH7: 2.1 | AI7: 2 | AJ7: 1.97 | AK7: 1.95 | AL7: 1.85 | AM7: 2.125 | AN7: 2.14 | AO7: 2 | AP7: 2.03 | AQ7: 1.9 | AR7: 1.97 | AS7: 2 | AT7: 2.07 | AU7: 1.9 | AV7: 2.07 | AW7: -

Sheet RES_Others
A1: scenario | B1: attribute | C1: process | D1: commodity | E1: lim_type | F1: time_slice | G1: year | H1: commodity_group | I1: currency | J1: stage | K1: sow | L1: AL | M1: AT | N1: BA | O1: BE | P1: BG | Q1: CH | R1: CY | S1: CZ | T1: DE | U1: DK | V1: EE | W1: EL | X1: ES | Y1: FI | Z1: FR | AA1: HR | AB1: HU | AC1: IE | AD1: IS | AE1: IT | AF1: KS | AG1: LT | AH1: LU | AI1: LV | AJ1: ME | AK1: MK | AL1: MT | AM1: NL | AN1: NO | AO1: PL | AP1: PT | AQ1: RO | AR1: RS | AS1: SE | AT1: SI | AU1: SK | AV1: UK | AW1: year2
A2: BASE | B2: EFF | C2: R_ES-CK-DH_BIO | D2: - | E2: - | F2: ANNUAL | G2: 2010 | H2: - | I2: - | J2: - | K2: - | L2: 0.33 | M2: 0.35 | P2: 0.32 | Q2: 0.35 | S2: 0.32 | V2: 0.32 | W2: 0.33 | X2: 0.33 | AB2: 0.33 | AD2: 0.35 | AG2: 0.32 | AI2: 0.33 | AJ2: 0.33 | AK2: 0.33 | AN2: 0.35 | AO2: 0.33 | AP2: 0.32 | AQ2: 0.32 | AT2: 0.35 | AW2: -
A3: BASE | B3: EFF | C3: R_ES-CK-DH_COA | D3: - | E3: - | F3: ANNUAL | G3: 2010 | H3: - | I3: - | J3: - | K3: - | M3: 0.35 | P3: 0.32 | Q3: 0.35 | X3: 0.33 | AB3: 0.33 | AD3: 0.35 | AN3: 0.35 | AO3: 0.33 | AW3: -
A4: BASE | B4: EFF | C4: R_ES-CK-DH_ELC | D4: - | E4: - | F4: ANNUAL | G4: 2010 | H4: - | I4: - | J4: - | K4: - | L4: 0.81 | M4: 0.83 | N4: 0.81 | O4: 0.83 | P4: 0.8 | Q4: 0.84 | R4: 0.8 | S4: 0.8 | T4: 0.84 | U4: 0.84 | V4: 0.8 | W4: 0.81 | X4: 0.81 | Y4: 0.84 | Z4: 0.84 | AA4: 0.81 | AB4: 0.81 | AC4: 0.83 | AD4: 0.84 | AE4: 0.84 | AF4: 0.81 | AG4: 0.8 | AH4: 0.84 | AI4: 0.81 | AJ4: 0.81 | AK4: 0.81 | AL4: 0.81 | AM4: 0.835 | AN4: 0.84 | AO4: 0.81 | AP4: 0.8 | AQ4: 0.8 | AR4: 0.81 | AS4: 0.85 | AT4: 0.84 | AU4: 0.81 | AV4: 0.83 | AW4: -
A5: BASE | B5: EFF | C5: R_ES-CK-DH_GAS | D5: - | E5: - | F5: ANNUAL | G5: 2010 | H5: - | I5: - | J5: - | K5: - | L5: 0.46 | M5: 0.49 | N5: 0.46 | O5: 0.49 | P5: 0.44 | Q5: 0.49 | S5: 0.45 | T5: 0.49 | U5: 0.49 | V5: 0.45 | W5: 0.46 | X5: 0.46 | Y5: 0.5 | Z5: 0.49 | AA5: 0.46 | AB5: 0.46 | AC5: 0.48 | AD5: 0.49 | AE5: 0.5 | AF5: 0.46 | AG5: 0.45 | AH5: 0.5 | AI5: 0.46 | AJ5: 0.46 | AK5: 0.46 | AM5: 0.485 | AN5: 0.49 | AO5: 0.46 | AP5: 0.44 | AQ5: 0.45 | AR5: 0.46 | AS5: 0.5 | AT5: 0.49 | AU5: 0.46 | AV5: 0.48 | AW5: -
A6: BASE | B6: EFF | C6: R_ES-CK-DH_LPG | D6: - | E6: - | F6: ANNUAL | G6: 2010 | H6: - | I6: - | J6: - | K6: - | L6: 0.43 | M6: 0.45 | N6: 0.43 | O6: 0.45 | P6: 0.41 | Q6: 0.46 | R6: 0.42 | S6: 0.42 | T6: 0.46 | U6: 0.46 | V6: 0.42 | W6: 0.43 | X6: 0.43 | Y6: 0.46 | Z6: 0.46 | AA6: 0.43 | AB6: 0.42 | AC6: 0.45 | AD6: 0.46 | AE6: 0.46 | AF6: 0.43 | AG6: 0.42 | AH6: 0.46 | AI6: 0.43 | AJ6: 0.43 | AK6: 0.43 | AL6: 0.43 | AM6: 0.45 | AN6: 0.46 | AO6: 0.43 | AP6: 0.41 | AQ6: 0.42 | AR6: 0.43 | AT6: 0.46 | AU6: 0.43 | AV6: 0.45 | AW6: -
A7: BASE | B7: EFF | C7: R_ES-CK-FL_BIO | D7: - | E7: - | F7: ANNUAL | G7: 2010 | H7: - | I7: - | J7: - | K7: - | L7: 0.33 | M7: 0.35 | P7: 0.32 | Q7: 0.35 | S7: 0.32 | V7: 0.32 | W7: 0.33 | X7: 0.33 | AB7: 0.33 | AD7: 0.35 | AG7: 0.32 | AI7: 0.33 | AJ7: 0.33 | AK7: 0.33 | AN7: 0.35 | AO7: 0.33 | AP7: 0.32 | AQ7: 0.32 | AT7: 0.35 | AW7: -
A8: BASE | B8: EFF | C8: R_ES-CK-FL_COA | D8: - | E8: - | F8: ANNUAL | G8: 2010 | H8: - | I8: - | J8: - | K8: - | M8: 0.35 | P8: 0.32 | Q8: 0.35 | X8: 0.33 | AB8: 0.33 | AD8: 0.35 | AN8: 0.35 | AO8: 0.33 | AW8: -
A9: BASE | B9: EFF | C9: R_ES-CK-FL_ELC | D9: - | E9: - | F9: ANNUAL | G9: 2010 | H9: - | I9: - | J9: - | K9: - | L9: 0.81 | M9: 0.83 | N9: 0.81 | O9: 0.83 | P9: 0.8 | Q9: 0.84 | R9: 0.8 | S9: 0.8 | T9: 0.84 | U9: 0.84 | V9: 0.8 | W9: 0.81 | X9: 0.81 | Y9: 0.84 | Z9: 0.84 | AA9: 0.81 | AB9: 0.81 | AC9: 0.83 | AD9: 0.84 | AE9: 0.84 | AF9: 0.81 | AG9: 0.8 | AH9: 0.84 | AI9: 0.81 | AJ9: 0.81 | AK9: 0.81 | AL9: 0.81 | AM9: 0.835 | AN9: 0.84 | AO9: 0.81 | AP9: 0.8 | AQ9: 0.8 | AR9: 0.81 | AS9: 0.85 | AT9: 0.84 | AU9: 0.81 | AV9: 0.83 | AW9: -
A10: BASE | B10: EFF | C10: R_ES-CK-FL_GAS | D10: - | E10: - | F10: ANNUAL | G10: 2010 | H10: - | I10: - | J10: - | K10: - | L10: 0.46 | M10: 0.49 | N10: 0.46 | O10: 0.49 | P10: 0.44 | Q10: 0.49 | S10: 0.45 | T10: 0.49 | U10: 0.49 | V10: 0.45 | W10: 0.46 | X10: 0.46 | Y10: 0.5 | Z10: 0.49 | AA10: 0.46 | AB10: 0.46 | AC10: 0.48 | AD10: 0.49 | AE10: 0.5 | AF10: 0.46 | AG10: 0.45 | AH10: 0.5 | AI10: 0.46 | AJ10: 0.46 | AK10: 0.46 | AM10: 0.485 | AN10: 0.49 | AO10: 0.46 | AP10: 0.44 | AQ10: 0.45 | AR10: 0.46 | AS10: 0.5 | AT10: 0.49 | AU10: 0.46 | AV10: 0.48 | AW10: -
A11: BASE | B11: EFF | C11: R_ES-CK-FL_LPG | D11: - | E11: - | F11: ANNUAL | G11: 2010 | H11: - | I11: - | J11: - | K11: - | L11: 0.43 | M11: 0.45 | N11: 0.43 | O11: 0.45 | P11: 0.41 | Q11: 0.46 | R11: 0.42 | S11: 0.42 | T11: 0.46 | U11: 0.46 | V11: 0.42 | W11: 0.43 | X11: 0.43 | Y11: 0.46 | Z11: 0.46 | AA11: 0.43 | AB11: 0.42 | AC11: 0.45 | AD11: 0.46 | AE11: 0.46 | AF11: 0.43 | AG11: 0.42 | AH11: 0.46 | AI11: 0.43 | AJ11: 0.43 | AK11: 0.43 | AL11: 0.43 | AM11: 0.45 | AN11: 0.46 | AO11: 0.43 | AP11: 0.41 | AQ11: 0.42 | AR11: 0.43 | AT11: 0.46 | AU11: 0.43 | AV11: 0.45 | AW11: -
A12: BASE | B12: EFF | C12: R_ES-CK-SD_BIO | D12: - | E12: - | F12: ANNUAL | G12: 2010 | H12: - | I12: - | J12: - | K12: - | L12: 0.33 | M12: 0.35 | P12: 0.32 | Q12: 0.35 | S12: 0.32 | V12: 0.32 | W12: 0.33 | X12: 0.33 | AB12: 0.33 | AD12: 0.35 | AG12: 0.32 | AI12: 0.33 | AJ12: 0.33 | AK12: 0.33 | AN12: 0.35 | AO12: 0.33 | AP12: 0.32 | AQ12: 0.32 | AT12: 0.35 | AW12: -
A13: BASE | B13: EFF | C13: R_ES-CK-SD_COA | D13: - | E13: - | F13: ANNUAL | G13: 2010 | H13: - | I13: - | J13: - | K13: - | M13: 0.35 | P13: 0.32 | Q13: 0.35 | X13: 0.33 | AB13: 0.33 | AD13: 0.35 | AN13: 0.35 | AO13: 0.33 | AW13: -
A14: BASE | B14: EFF | C14: R_ES-CK-SD_ELC | D14: - | E14: - | F14: ANNUAL | G14: 2010 | H14: - | I14: - | J14: - | K14: - | L14: 0.81 | M14: 0.83 | N14: 0.81 | O14: 0.83 | P14: 0.8 | Q14: 0.84 | R14: 0.8 | S14: 0.8 | T14: 0.84 | U14: 0.84 | V14: 0.8 | W14: 0.81 | X14: 0.81 | Y14: 0.84 | Z14: 0.84 | AA14: 0.81 | AB14: 0.81 | AC14: 0.83 | AD14: 0.84 | AE14: 0.84 | AF14: 0.81 | AG14: 0.8 | AH14: 0.84 | AI14: 0.81 | AJ14: 0.81 | AK14: 0.81 | AL14: 0.81 | AM14: 0.835 | AN14: 0.84 | AO14: 0.81 | AP14: 0.8 | AQ14: 0.8 | AR14: 0.81 | AS14: 0.85 | AT14: 0.84 | AU14: 0.81 | AV14: 0.83 | AW14: -
A15: BASE | B15: EFF | C15: R_ES-CK-SD_GAS | D15: - | E15: - | F15: ANNUAL | G15: 2010 | H15: - | I15: - | J15: - | K15: - | L15: 0.46 | M15: 0.49 | N15: 0.46 | O15: 0.49 | P15: 0.44 | Q15: 0.49 | S15: 0.45 | T15: 0.49 | U15: 0.49 | V15: 0.45 | W15: 0.46 | X15: 0.46 | Y15: 0.5 | Z15: 0.49 | AA15: 0.46 | AB15: 0.46 | AC15: 0.48 | AD15: 0.49 | AE15: 0.5 | AF15: 0.46 | AG15: 0.45 | AH15: 0.5 | AI15: 0.46 | AJ15: 0.46 | AK15: 0.46 | AM15: 0.485 | AN15: 0.49 | AO15: 0.46 | AP15: 0.44 | AQ15: 0.45 | AR15: 0.46 | AS15: 0.5 | AT15: 0.49 | AU15: 0.46 | AV15: 0.48 | AW15: -
A16: BASE | B16: EFF | C16: R_ES-CK-SD_LPG | D16: - | E16: - | F16: ANNUAL | G16: 2010 | H16: - | I16: - | J16: - | K16: - | L16: 0.43 | M16: 0.45 | N16: 0.43 | O16: 0.45 | P16: 0.41 | Q16: 0.46 | R16: 0.42 | S16: 0.42 | T16: 0.46 | U16: 0.46 | V16: 0.42 | W16: 0.43 | X16: 0.43 | Y16: 0.46 | Z16: 0.46 | AA16: 0.43 | AB16: 0.42 | AC16: 0.45 | AD16: 0.46 | AE16: 0.46 | AF16: 0.43 | AG16: 0.42 | AH16: 0.46 | AI16: 0.43 | AJ16: 0.43 | AK16: 0.43 | AL16: 0.43 | AM16: 0.45 | AN16: 0.46 | AO16: 0.43 | AP16: 0.41 | AQ16: 0.42 | AR16: 0.43 | AT16: 0.46 | AU16: 0.43 | AV16: 0.45 | AW16: -
A17: BASE | B17: INPUT | C17: RCDRELC00 | D17: RSDELC-other | E17: - | F17: ANNUAL | G17: 2010 | H17: - | I17: - | J17: - | K17: - | L17: 1.3506549 | M17: 1.4528306 | N17: 1.3506549 | O17: 1.4858905 | P17: 1.6097525 | Q17: 1.4528306 | R17: 1.751679 | S17: 1.1982857 | T17: 1.3448908 | U17: 1.3580897 | V17: 1.5711564 | W17: 1.3506549 | X17: 1.6326984 | Y17: 1.4609764 | Z17: 1.5834954 | AA17: 1.471827 | AB17: 1.2406208 | AC17: 1.5168224 | AD17: 1.3802609 | AE17: 1.3592212 | AF17: 1.3506549 | AG17: 1.2966457 | AH17: 1.4336778 | AI17: 1.549689 | AJ17: 1.3506549 | AK17: 1.3506549 | AL17: 1.4233452 | AM17: 1.358695 | AN17: 1.3802609 | AO17: 1.2578488 | AP17: 1.5696323 | AQ17: 1.4106392 | AR17: 1.3506549 | AS17: 1.3802609 | AT17: 1.5277628 | AU17: 1.2447193 | AV17: 1.4703969 | AW17: -
A18: BASE | B18: INPUT | C18: RCWAELC00 | D18: RSDELC-other | E18: - | F18: ANNUAL | G18: 2010 | H18: - | I18: - | J18: - | K18: - | L18: 0.6334404 | M18: 0.69565674 | N18: 0.6334404 | O18: 0.71658654 | P18: 0.79621341 | Q18: 0.69565674 | R18: 0.89315818 | S18: 0.54314893 | T18: 0.62859133 | U18: 0.63571625 | V18: 0.80383409 | W18: 0.6334404 | X18: 0.80949437 | Y18: 0.70077138 | Z18: 0.78025358 | AA18: 0.70772941 | AB18: 0.54783736 | AC18: 0.74142937 | AD18: 0.64982188 | AE18: 0.65557664 | AF18: 0.6334404 | AG18: 0.60000311 | AH18: 0.69303637 | AI18: 0.77359501 | AJ18: 0.6334404 | AK18: 0.6334404 | AL18: 0.6765942 | AM18: 0.63629086 | AN18: 0.64982188 | AO18: 0.57695961 | AP18: 0.76877015 | AQ18: 0.68053958 | AR18: 0.6334404 | AS18: 0.64982188 | AT18: 0.74352222 | AU18: 0.5703685 | AV18: 0.70657716 | AW18: -
A19: BASE | B19: INPUT | C19: RDWAELC00 | D19: RSDELC-other | E19: - | F19: ANNUAL | G19: 2010 | H19: - | I19: - | J19: - | K19: - | L19: 0.83333716 | M19: 0.94166673 | N19: 0.83333716 | O19: 0.97750479 | P19: 1.1191605 | Q19: 0.94166673 | R19: 1.2892961 | S19: 0.68135848 | T19: 0.82820057 | U19: 0.84120604 | V19: 1.0565161 | W19: 0.83333716 | X19: 1.0773286 | Y19: 0.95052782 | Z19: 1.0878365 | AA19: 0.96211546 | AB19: 0.72018985 | AC19: 1.0202179 | AD19: 0.86444861 | AE19: 0.87259244 | AF19: 0.83333716 | AG19: 0.77546577 | AH19: 0.93736822 | AI19: 1.0781964 | AJ19: 0.83333716 | AK19: 0.83333716 | AL19: 0.90854739 | AM19: 0.84158712 | AN19: 0.86444861 | AO19: 0.73776177 | AP19: 1.0214794 | AQ19: 0.87585978 | AR19: 0.83333716 | AS19: 0.86444861 | AT19: 1.0243633 | AU19: 0.72592165 | AV19: 0.96032574 | AW19: -
A20: BASE | B20: INPUT | C20: RLIGELC00 | D20: RSDELC-other | E20: - | F20: ANNUAL | G20: 2010 | H20: - | I20: - | J20: - | K20: - | L20: 0.099564297 | M20: 0.09914047 | N20: 0.099564297 | O20: 0.093281255 | P20: 0.10595351 | Q20: 0.09914047 | R20: 0.10029887 | S20: 0.093740152 | T20: 0.10196711 | U20: 0.098362194 | V20: 0.10029889 | W20: 0.099564297 | X20: 0.094829111 | Y20: 0.09679948 | Z20: 0.09918654 | AA20: 0.09919915 | AB20: 0.098803084 | AC20: 0.099140861 | AD20: 0.098317527 | AE20: 0.096222713 | AF20: 0.099564297 | AG20: 0.10029944 | AH20: 0.09914156 | AI20: 0.10029973 | AJ20: 0.099564297 | AK20: 0.099564297 | AL20: 0.10029896 | AM20: 0.099141613 | AN20: 0.098317527 | AO20: 0.1002986 | AP20: 0.098587313 | AQ20: 0.10401086 | AR20: 0.099564297 | AS20: 0.098317527 | AT20: 0.10029943 | AU20: 0.10029907 | AV20: 0.099772728 | AW20: -
A21: BASE | B21: INPUT | C21: ROELELC00 | D21: RSDELC-other | E21: - | F21: ANNUAL | G21: 2010 | H21: - | I21: - | J21: - | K21: - | L21: 1.1383772 | M21: 1.1826274 | N21: 1.1383772 | O21: 1.2446125 | P21: 1.6265524 | Q21: 1.1826274 | R21: 1.7455907 | S21: 0.88069197 | T21: 1.008183 | U21: 1.0141848 | V21: 1.5334124 | W21: 1.1383772 | X21: 1.5224105 | Y21: 1.1805012 | Z21: 1.3991597 | AA21: 1.2899264 | AB21: 0.94616773 | AC21: 1.3120957 | AD21: 1.0282571 | AE21: 1.1310412 | AF21: 1.1383772 | AG21: 1.0734411 | AH21: 1.1521222 | AI21: 1.5002998 | AJ21: 1.1383772 | AK21: 1.1383772 | AL21: 1.1696571 | AM21: 1.0075969 | AN21: 1.0282571 | AO21: 0.96626589 | AP21: 1.4367497 | AQ21: 1.286239 | AR21: 1.1383772 | AS21: 1.0282571 | AT21: 1.3391207 | AU21: 0.94329319 | AV21: 1.2119484 | AW21: -
A22: BASE | B22: INPUT | C22: RREFELC00 | D22: RSDELC-other | E22: - | F22: ANNUAL | G22: 2010 | H22: - | I22: - | J22: - | K22: - | L22: 1.3855408 | M22: 1.4699645 | N22: 1.3855408 | O22: 1.5324575 | P22: 1.6336805 | Q22: 1.4699645 | R22: 1.7057504 | S22: 1.5920745 | T22: 1.3512032 | U22: 1.3525853 | V22: 1.7125292 | W22: 1.3855408 | X22: 1.4394022 | Y22: 1.4467598 | Z22: 1.5734673 | AA22: 1.5340254 | AB22: 1.5537825 | AC22: 1.4724804 | AD22: 1.4080856 | AE22: 1.442837 | AF22: 1.3855408 | AG22: 1.6334684 | AH22: 1.428193 | AI22: 1.5949706 | AJ22: 1.3855408 | AK22: 1.3855408 | AL22: 1.7219433 | AM22: 1.3108611 | AN22: 1.4080856 | AO22: 1.4663514 | AP22: 1.5560253 | AQ22: 1.406359 | AR22: 1.3855408 | AS22: 1.4080856 | AT22: 1.7348766 | AU22: 1.6743012 | AV22: 1.3160866 | AW22: -
A23: BASE | B23: PRC_CAPACT | C23: R_ES-CK-DH_BIO | D23: - | E23: - | F23: - | G23: - | H23: - | I23: - | J23: - | K23: - | L23: 0.0096401693 | M23: 0.0030415223 | P23: 0.0036540878 | Q23: 0.002 | S23: 0.002828146 | V23: 0.002766056 | W23: 0.0056268448 | X23: 0.0038085079 | AB23: 0.0027436497 | AD23: 0.002 | AG23: 0.0024095487 | AI23: 0.0018732826 | AJ23: 0.0079551734 | AK23: 0.002 | AN23: 0.002 | AO23: 0.0031582031 | AP23: 0.015925988 | AQ23: 0.0026716941 | AT23: 0.0023401915 | AW23: -
A24: BASE | B24: PRC_CAPACT | C24: R_ES-CK-DH_COA | D24: - | E24: - | F24: - | G24: - | H24: - | I24: - | J24: - | K24: - | M24: 0.0030415223 | P24: 0.0036540878 | Q24: 0.002 | X24: 0.0038085079 | AB24: 0.0027436497 | AD24: 0.002 | AN24: 0.002 | AO24: 0.0031582031 | AW24: -
A25: BASE | B25: PRC_CAPACT | C25: R_ES-CK-DH_ELC | D25: - | E25: - | F25: - | G25: - | H25: - | I25: - | J25: - | K25: - | L25: 0.0096401693 | M25: 0.0030415223 | N25: 0.0042581434 | O25: 0.0034102939 | P25: 0.0036540878 | Q25: 0.0035508104 | R25: 0.0031425495 | S25: 0.002828146 | T25: 0.0032488706 | U25: 0.0028361457 | V25: 0.002766056 | W25: 0.0056268448 | X25: 0.0038085079 | Y25: 0.0026293573 | Z25: 0.0046456786 | AA25: 0.0030876066 | AB25: 0.0027436497 | AC25: 0.002970741 | AD25: 0.0022971798 | AE25: 0.0024563707 | AF25: 0.0037550697 | AG25: 0.0024095487 | AH25: 0.0028951277 | AI25: 0.0018732826 | AJ25: 0.0079551734 | AK25: 0.0052408565 | AL25: 0.0040464055 | AM25: 0.0033326077 | AN25: 0.0074120673 | AO25: 0.0031582031 | AP25: 0.015925988 | AQ25: 0.0026716941 | AR25: 0.0048263692 | AS25: 0.0026513054 | AT25: 0.0023401915 | AU25: 0.003632819 | AV25: 0.0020315869 | AW25: -
A26: BASE | B26: PRC_CAPACT | C26: R_ES-CK-DH_GAS | D26: - | E26: - | F26: - | G26: - | H26: - | I26: - | J26: - | K26: - | L26: 0.002 | M26: 0.0030415223 | N26: 0.0042581434 | O26: 0.0034102939 | P26: 0.0036540878 | Q26: 0.0035508104 | S26: 0.002828146 | T26: 0.0032488706 | U26: 0.0028361457 | V26: 0.002766056 | W26: 0.0056268448 | X26: 0.0038085079 | Y26: 0.0026293573 | Z26: 0.0046456786 | AA26: 0.0030876066 | AB26: 0.0027436497 | AC26: 0.002970741 | AD26: 0.002 | AE26: 0.0024563707 | AF26: 0.002 | AG26: 0.0024095487 | AH26: 0.0028951277 | AI26: 0.0018732826 | AJ26: 0.002 | AK26: 0.002 | AM26: 0.0033326077 | AN26: 0.0074120673 | AO26: 0.0031582031 | AP26: 0.015925988 | AQ26: 0.0026716941 | AR26: 0.0048263692 | AS26: 0.0026513054 | AT26: 0.0023401915 | AU26: 0.003632819 | AV26: 0.0020315869 | AW26: -
A27: BASE | B27: PRC_CAPACT | C27: R_ES-CK-DH_LPG | D27: - | E27: - | F27: - | G27: - | H27: - | I27: - | J27: - | K27: - | L27: 0.0096401693 | M27: 0.0030415223 | N27: 0.002 | O27: 0.0034102939 | P27: 0.0036540878 | Q27: 0.002 | R27: 0.0031425495 | S27: 0.002828146 | T27: 0.0032488706 | U27: 0.0028361457 | V27: 0.002766056 | W27: 0.0056268448 | X27: 0.0038085079 | Y27: 0.0026293573 | Z27: 0.0046456786 | AA27: 0.0030876066 | AB27: 0.0027436497 | AC27: 0.002970741 | AD27: 0.0022971798 | AE27: 0.0024563707 | AF27: 0.0037550697 | AG27: 0.0024095487 | AH27: 0.0028951277 | AI27: 0.0018732826 | AJ27: 0.002 | AK27: 0.0052408565 | AL27: 0.0040464055 | AM27: 0.0033326077 | AN27: 0.0074120673 | AO27: 0.0031582031 | AP27: 0.015925988 | AQ27: 0.0026716941 | AR27: 0.0048263692 | AT27: 0.0023401915 | AU27: 0.003632819 | AV27: 0.0020315869 | AW27: -
A28: BASE | B28: PRC_CAPACT | C28: R_ES-CK-FL_BIO | D28: - | E28: - | F28: - | G28: - | H28: - | I28: - | J28: - | K28: - | L28: 0.0096401693 | M28: 0.0030415223 | P28: 0.0036540878 | Q28: 0.002 | S28: 0.002828146 | V28: 0.002766056 | W28: 0.0056268448 | X28: 0.0038085079 | AB28: 0.0027436497 | AD28: 0.002 | AG28: 0.0024095487 | AI28: 0.0018732826 | AJ28: 0.0079551734 | AK28: 0.002 | AN28: 0.002 | AO28: 0.0031582031 | AP28: 0.015925988 | AQ28: 0.0026716941 | AT28: 0.0023401915 | AW28: -
A29: BASE | B29: PRC_CAPACT | C29: R_ES-CK-FL_COA | D29: - | E29: - | F29: - | G29: - | H29: - | I29: - | J29: - | K29: - | M29: 0.0030415223 | P29: 0.0036540878 | Q29: 0.002 | X29: 0.0038085079 | AB29: 0.0027436497 | AD29: 0.002 | AN29: 0.002 | AO29: 0.0031582031 | AW29: -
A30: BASE | B30: PRC_CAPACT | C30: R_ES-CK-FL_ELC | D30: - | E30: - | F30: - | G30: - | H30: - | I30: - | J30: - | K30: - | L30: 0.0096401693 | M30: 0.0030415223 | N30: 0.0042581434 | O30: 0.0034102939 | P30: 0.0036540878 | Q30: 0.0035508104 | R30: 0.0031425495 | S30: 0.002828146 | T30: 0.0032488706 | U30: 0.0028361457 | V30: 0.002766056 | W30: 0.0056268448 | X30: 0.0038085079 | Y30: 0.0026293573 | Z30: 0.0046456786 | AA30: 0.0030876066 | AB30: 0.0027436497 | AC30: 0.002970741 | AD30: 0.0022971798 | AE30: 0.0024563707 | AF30: 0.0037550697 | AG30: 0.0024095487 | AH30: 0.0028951277 | AI30: 0.0018732826 | AJ30: 0.0079551734 | AK30: 0.0052408565 | AL30: 0.0040464055 | AM30: 0.0033326077 | AN30: 0.0074120673 | AO30: 0.0031582031 | AP30: 0.015925988 | AQ30: 0.0026716941 | AR30: 0.0048263692 | AS30: 0.0026513054 | AT30: 0.0023401915 | AU30: 0.003632819 | AV30: 0.0020315869 | AW30: -
A31: BASE | B31: PRC_CAPACT | C31: R_ES-CK-FL_GAS | D31: - | E31: - | F31: - | G31: - | H31: - | I31: - | J31: - | K31: - | L31: 0.002 | M31: 0.0030415223 | N31: 0.0042581434 | O31: 0.0034102939 | P31: 0.0036540878 | Q31: 0.0035508104 | S31: 0.002828146 | T31: 0.0032488706 | U31: 0.0028361457 | V31: 0.002766056 | W31: 0.0056268448 | X31: 0.0038085079 | Y31: 0.0026293573 | Z31: 0.0046456786 | AA31: 0.0030876066 | AB31: 0.0027436497 | AC31: 0.002970741 | AD31: 0.002 | AE31: 0.0024563707 | AF31: 0.002 | AG31: 0.0024095487 | AH31: 0.0028951277 | AI31: 0.0018732826 | AJ31: 0.002 | AK31: 0.002 | AM31: 0.0033326077 | AN31: 0.0074120673 | AO31: 0.0031582031 | AP31: 0.015925988 | AQ31: 0.0026716941 | AR31: 0.0048263692 | AS31: 0.0026513054 | AT31: 0.0023401915 | AU31: 0.003632819 | AV31: 0.0020315869 | AW31: -
A32: BASE | B32: PRC_CAPACT | C32: R_ES-CK-FL_LPG | D32: - | E32: - | F32: - | G32: - | H32: - | I32: - | J32: - | K32: - | L32: 0.0096401693 | M32: 0.0030415223 | N32: 0.002 | O32: 0.0034102939 | P32: 0.0036540878 | Q32: 0.002 | R32: 0.0031425495 | S32: 0.002828146 | T32: 0.0032488706 | U32: 0.0028361457 | V32: 0.002766056 | W32: 0.0056268448 | X32: 0.0038085079 | Y32: 0.0026293573 | Z32: 0.0046456786 | AA32: 0.0030876066 | AB32: 0.0027436497 | AC32: 0.002970741 | AD32: 0.0022971798 | AE32: 0.0024563707 | AF32: 0.0037550697 | AG32: 0.0024095487 | AH32: 0.0028951277 | AI32: 0.0018732826 | AJ32: 0.002 | AK32: 0.0052408565 | AL32: 0.0040464055 | AM32: 0.0033326077 | AN32: 0.0074120673 | AO32: 0.0031582031 | AP32: 0.015925988 | AQ32: 0.0026716941 | AR32: 0.0048263692 | AT32: 0.0023401915 | AU32: 0.003632819 | AV32: 0.0020315869 | AW32: -
A33: BASE | B33: PRC_CAPACT | C33: R_ES-CK-SD_BIO | D33: - | E33: - | F33: - | G33: - | H33: - | I33: - | J33: - | K33: - | L33: 0.0096401693 | M33: 0.0030415223 | P33: 0.0036540878 | Q33: 0.002 | S33: 0.002828146 | V33: 0.002766056 | W33: 0.0056268448 | X33: 0.0038085079 | AB33: 0.0027436497 | AD33: 0.002 | AG33: 0.0024095487 | AI33: 0.0018732826 | AJ33: 0.0079551734 | AK33: 0.002 | AN33: 0.002 | AO33: 0.0031582031 | AP33: 0.015925988 | AQ33: 0.0026716941 | AT33: 0.0023401915 | AW33: -
A34: BASE | B34: PRC_CAPACT | C34: R_ES-CK-SD_COA | D34: - | E34: - | F34: - | G34: - | H34: - | I34: - | J34: - | K34: - | M34: 0.0030415223 | P34: 0.0036540878 | Q34: 0.002 | X34: 0.0038085079 | AB34: 0.0027436497 | AD34: 0.002 | AN34: 0.002 | AO34: 0.0031582031 | AW34: -
A35: BASE | B35: PRC_CAPACT | C35: R_ES-CK-SD_ELC | D35: - | E35: - | F35: - | G35: - | H35: - | I35: - | J35: - | K35: - | L35: 0.0096401693 | M35: 0.0030415223 | N35: 0.0042581434 | O35: 0.0034102939 | P35: 0.0036540878 | Q35: 0.0035508104 | R35: 0.0031425495 | S35: 0.002828146 | T35: 0.0032488706 | U35: 0.0028361457 | V35: 0.002766056 | W35: 0.0056268448 | X35: 0.0038085079 | Y35: 0.0026293573 | Z35: 0.0046456786 | AA35: 0.0030876066 | AB35: 0.0027436497 | AC35: 0.002970741 | AD35: 0.0022971798 | AE35: 0.0024563707 | AF35: 0.0037550697 | AG35: 0.0024095487 | AH35: 0.0028951277 | AI35: 0.0018732826 | AJ35: 0.0079551734 | AK35: 0.0052408565 | AL35: 0.0040464055 | AM35: 0.0033326077 | AN35: 0.0074120673 | AO35: 0.0031582031 | AP35: 0.015925988 | AQ35: 0.0026716941 | AR35: 0.0048263692 | AS35: 0.0026513054 | AT35: 0.0023401915 | AU35: 0.003632819 | AV35: 0.0020315869 | AW35: -
A36: BASE | B36: PRC_CAPACT | C36: R_ES-CK-SD_GAS | D36: - | E36: - | F36: - | G36: - | H36: - | I36: - | J36: - | K36: - | L36: 0.002 | M36: 0.0030415223 | N36: 0.0042581434 | O36: 0.0034102939 | P36: 0.0036540878 | Q36: 0.0035508104 | S36: 0.002828146 | T36: 0.0032488706 | U36: 0.0028361457 | V36: 0.002766056 | W36: 0.0056268448 | X36: 0.0038085079 | Y36: 0.0026293573 | Z36: 0.0046456786 | AA36: 0.0030876066 | AB36: 0.0027436497 | AC36: 0.002970741 | AD36: 0.002 | AE36: 0.0024563707 | AF36: 0.002 | AG36: 0.0024095487 | AH36: 0.0028951277 | AI36: 0.0018732826 | AJ36: 0.002 | AK36: 0.002 | AM36: 0.0033326077 | AN36: 0.0074120673 | AO36: 0.0031582031 | AP36: 0.015925988 | AQ36: 0.0026716941 | AR36: 0.0048263692 | AS36: 0.0026513054 | AT36: 0.0023401915 | AU36: 0.003632819 | AV36: 0.0020315869 | AW36: -
A37: BASE | B37: PRC_CAPACT | C37: R_ES-CK-SD_LPG | D37: - | E37: - | F37: - | G37: - | H37: - | I37: - | J37: - | K37: - | L37: 0.0096401693 | M37: 0.0030415223 | N37: 0.002 | O37: 0.0034102939 | P37: 0.0036540878 | Q37: 0.002 | R37: 0.0031425495 | S37: 0.002828146 | T37: 0.0032488706 | U37: 0.0028361457 | V37: 0.002766056 | W37: 0.0056268448 | X37: 0.0038085079 | Y37: 0.0026293573 | Z37: 0.0046456786 | AA37: 0.0030876066 | AB37: 0.0027436497 | AC37: 0.002970741 | AD37: 0.0022971798 | AE37: 0.0024563707 | AF37: 0.0037550697 | AG37: 0.0024095487 | AH37: 0.0028951277 | AI37: 0.0018732826 | AJ37: 0.002 | AK37: 0.0052408565 | AL37: 0.0040464055 | AM37: 0.0033326077 | AN37: 0.0074120673 | AO37: 0.0031582031 | AP37: 0.015925988 | AQ37: 0.0026716941 | AR37: 0.0048263692 | AT37: 0.0023401915 | AU37: 0.003632819 | AV37: 0.0020315869 | AW37: -

Sheet RSD_HeatCAPEX
B1: Central EU | L1: South EU | V1: East EU | AF1: North EU
B2: ~TFM_INS-TS: EUR17 | L2: ~TFM_INS-TS: EUR17 | V2: ~TFM_INS-TS: EUR17 | AF2: ~TFM_INS-TS: EUR17
B3: Attribute | C3: PSet_PN | D3: Region | E3: *units | F3: 2011 | G3: 2020 | H3: 2030 | I3: 2040 | J3: 2050 | L3: Attribute | M3: PSet_PN | N3: Region | O3: *units | P3: 2011 | Q3: 2020 | R3: 2030 | S3: 2040 | T3: 2050 | V3: Attribute | W3: PSet_PN | X3: Region | Y3: *units | Z3: 2011 | AA3: 2020 | AB3: 2030 | AC3: 2040 | AD3: 2050 | AF3: Attribute | AG3: PSet_PN | AH3: Region | AI3: *units | AJ3: 2011 | AK3: 2020 | AL3: 2030 | AM3: 2040 | AN3: 2050
B4: INVCOST | C4: =RSDTechsCE!B4 -> R_ES-SH-DH_OIL01 | E4: k€/unit | F4: =IFERROR(RSDTechsCE!L4/1000,"") -> 5.527 | G4: =IFERROR(RSDTechsCE!M4/1000,"") -> 5.527 | H4: =IFERROR(RSDTechsCE!N4/1000,"") -> 5.527 | I4: =IFERROR(RSDTechsCE!O4/1000,"") -> 5.527 | J4: =IFERROR(RSDTechsCE!P4/1000,"") -> 5.527
B5: INVCOST | C5: =RSDTechsCE!B5 -> R_ES-SH-DH_OIL02 | E5: k€/unit | F5: =IFERROR(RSDTechsCE!L5/1000,"") -> 5.527 | G5: =IFERROR(RSDTechsCE!M5/1000,"") -> 5.527 | H5: =IFERROR(RSDTechsCE!N5/1000,"") -> 5.527 | I5: =IFERROR(RSDTechsCE!O5/1000,"") -> 5.527 | J5: =IFERROR(RSDTechsCE!P5/1000,"") -> 5.527
B6: INVCOST | C6: =RSDTechsCE!B6 -> R_ES-SH-DH_OIL02-SOLspl | E6: k€/unit | F6: =IFERROR(RSDTechsCE!L6/1000,"") -> 6.294 | G6: =IFERROR(RSDTechsCE!M6/1000,"") -> 6.00036 | H6: =IFERROR(RSDTechsCE!N6/1000,"") -> 5.75566 | I6: =IFERROR(RSDTechsCE!O6/1000,"") -> 4.67898 | J6: =IFERROR(RSDTechsCE!P6/1000,"") -> 4.67898
B7: INVCOST | C7: =RSDTechsCE!B7 -> R_ES-SH-DH_OIL02-BIOspl | E7: k€/unit | F7: =IFERROR(RSDTechsCE!L7/1000,"") -> 4.2 | G7: =IFERROR(RSDTechsCE!M7/1000,"") -> 4.2 | H7: =IFERROR(RSDTechsCE!N7/1000,"") -> 5.1 | I7: =IFERROR(RSDTechsCE!O7/1000,"") -> 5.1 | J7: =IFERROR(RSDTechsCE!P7/1000,"") -> 5.1
B8: INVCOST | C8: =RSDTechsCE!B8 -> R_ES-SH-DH_GAS01 | E8: k€/unit | F8: =IFERROR(RSDTechsCE!L8/1000,"") -> 4.309 | G8: =IFERROR(RSDTechsCE!M8/1000,"") -> 4.309 | H8: =IFERROR(RSDTechsCE!N8/1000,"") -> 4.309 | I8: =IFERROR(RSDTechsCE!O8/1000,"") -> 4.309 | J8: =IFERROR(RSDTechsCE!P8/1000,"") -> 4.309
B9: INVCOST | C9: =RSDTechsCE!B9 -> R_ES-SH-DH_GAS02 | E9: k€/unit | F9: =IFERROR(RSDTechsCE!L9/1000,"") -> 4.309 | G9: =IFERROR(RSDTechsCE!M9/1000,"") -> 4.309 | H9: =IFERROR(RSDTechsCE!N9/1000,"") -> 4.309 | I9: =IFERROR(RSDTechsCE!O9/1000,"") -> 4.309 | J9: =IFERROR(RSDTechsCE!P9/1000,"") -> 4.309
B10: INVCOST | C10: =RSDTechsCE!B10 -> R_ES-SH-DH_GAS01-SOLspl | E10: k€/unit | F10: =IFERROR(RSDTechsCE!L10/1000,"") -> 6.294 | G10: =IFERROR(RSDTechsCE!M10/1000,"") -> 6.00036 | H10: =IFERROR(RSDTechsCE!N10/1000,"") -> 5.75566 | I10: =IFERROR(RSDTechsCE!O10/1000,"") -> 4.67898 | J10: =IFERROR(RSDTechsCE!P10/1000,"") -> 4.67898
B11: INVCOST | C11: =RSDTechsCE!B11 -> R_ES-SH-DH_GAS02-BIOspl | E11: k€/unit | F11: =IFERROR(RSDTechsCE!L11/1000,"") -> 4.2 | G11: =IFERROR(RSDTechsCE!M11/1000,"") -> 4.2 | H11: =IFERROR(RSDTechsCE!N11/1000,"") -> 5.1 | I11: =IFERROR(RSDTechsCE!O11/1000,"") -> 5.1 | J11: =IFERROR(RSDTechsCE!P11/1000,"") -> 5.1
B12: INVCOST | C12: =RSDTechsCE!B12 -> R_ES-SH-DH_BIO01 | E12: k€/unit | F12: =IFERROR(RSDTechsCE!L12/1000,"") -> 16.55 | G12: =IFERROR(RSDTechsCE!M12/1000,"") -> 16.55 | H12: =IFERROR(RSDTechsCE!N12/1000,"") -> 17.72 | I12: =IFERROR(RSDTechsCE!O12/1000,"") -> 17.72 | J12: =IFERROR(RSDTechsCE!P12/1000,"") -> 17.72
B13: INVCOST | C13: =RSDTechsCE!B13 -> R_ES-SH-DH_ELC01 | E13: k€/unit | F13: =IFERROR(RSDTechsCE!L13/1000,"") -> 4 | G13: =IFERROR(RSDTechsCE!M13/1000,"") -> 4 | H13: =IFERROR(RSDTechsCE!N13/1000,"") -> 4 | I13: =IFERROR(RSDTechsCE!O13/1000,"") -> 4 | J13: =IFERROR(RSDTechsCE!P13/1000,"") -> 4
B14: INVCOST | C14: =RSDTechsCE!B14 -> R_ES-SH-DH_ELC02 | E14: k€/unit | F14: =IFERROR(RSDTechsCE!L14/1000,"") -> 15.389 | G14: =IFERROR(RSDTechsCE!M14/1000,"") -> 14.61955 | H14: =IFERROR(RSDTechsCE!N14/1000,"") -> 13.23454 | I14: =IFERROR(RSDTechsCE!O14/1000,"") -> 12.61898 | J14: =IFERROR(RSDTechsCE!P14/1000,"") -> 12.61898
B15: INVCOST | C15: =RSDTechsCE!B15 -> R_ES-SH-DH_ELC02-ELCspl | E15: k€/unit | F15: =IFERROR(RSDTechsCE!L15/1000,"") -> 3.0395388 | G15: =IFERROR(RSDTechsCE!M15/1000,"") -> 3.0395388 | H15: =IFERROR(RSDTechsCE!N15/1000,"") -> 3.0395388 | I15: =IFERROR(RSDTechsCE!O15/1000,"") -> 3.0395388 | J15: =IFERROR(RSDTechsCE!P15/1000,"") -> 3.0395388
... B41: INVCOST | C41: =RSDTechsCE!B41 -> R_ES-CHP-DH-OILspl | E41: k€/unit | F41: =IFERROR(RSDTechsCE!L41/1000,"") -> 5.527 | G41: =IFERROR(RSDTechsCE!M41/1000,"") -> 5.527 | H41: =IFERROR(RSDTechsCE!N41/1000,"") -> 5.527 | I41: =IFERROR(RSDTechsCE!O41/1000,"") -> 5.527 | J41: =IFERROR(RSDTechsCE!P41/1000,"") -> 5.527
B43: ~TFM_INS-TS: EUR17
B44: Attribute | C44: PSet_PN | D44: Region | E44: *units | F44: 2011 | G44: 2020 | H44: 2030 | I44: 2040 | J44: 2050
B45: INVCOST | C45: =RSDTechsCE!B45 -> R_ES-SH-DH-70_OIL01 | E45: k€/unit | F45: =IFERROR(RSDTechsCE!L45/1000,"") -> 5.527 | G45: =IFERROR(RSDTechsCE!M45/1000,"") -> 5.527 | H45: =IFERROR(RSDTechsCE!N45/1000,"") -> 5.527 | I45: =IFERROR(RSDTechsCE!O45/1000,"") -> 5.527 | J45: =IFERROR(RSDTechsCE!P45/1000,"") -> 5.527
B46: INVCOST | C46: =RSDTechsCE!B46 -> R_ES-SH-DH-70_OIL02 | E46: k€/unit | F46: =IFERROR(RSDTechsCE!L46/1000,"") -> 5.527 | G46: =IFERROR(RSDTechsCE!M46/1000,"") -> 5.527 | H46: =IFERROR(RSDTechsCE!N46/1000,"") -> 5.527 | I46: =IFERROR(RSDTechsCE!O46/1000,"") -> 5.527 | J46: =IFERROR(RSDTechsCE!P46/1000,"") -> 5.527
B47: INVCOST | C47: =RSDTechsCE!B47 -> R_ES-SH-DH-70_OIL02-SOLspl | E47: k€/unit | F47: =IFERROR(RSDTechsCE!L47/1000,"") -> 6.294 | G47: =IFERROR(RSDTechsCE!M47/1000,"") -> 6.00036 | H47: =IFERROR(RSDTechsCE!N47/1000,"") -> 5.75566 | I47: =IFERROR(RSDTechsCE!O47/1000,"") -> 4.67898 | J47: =IFERROR(RSDTechsCE!P47/1000,"") -> 4.67898
B48: INVCOST | C48: =RSDTechsCE!B48 -> R_ES-SH-DH-70_OIL02-BIOspl | E48: k€/unit | F48: =IFERROR(RSDTechsCE!L48/1000,"") -> 4.2 | G48: =IFERROR(RSDTechsCE!M48/1000,"") -> 4.2 | H48: =IFERROR(RSDTechsCE!N48/1000,"") -> 5.1 | I48: =IFERROR(RSDTechsCE!O48/1000,"") -> 5.1 | J48: =IFERROR(RSDTechsCE!P48/1000,"") -> 5.1
B49: INVCOST | C49: =RSDTechsCE!B49 -> R_ES-SH-DH-70_GAS01 | E49: k€/unit | F49: =IFERROR(RSDTechsCE!L49/1000,"") -> 4.309 | G49: =IFERROR(RSDTechsCE!M49/1000,"") -> 4.309 | H49: =IFERROR(RSDTechsCE!N49/1000,"") -> 4.309 | I49: =IFERROR(RSDTechsCE!O49/1000,"") -> 4.309 | J49: =IFERROR(RSDTechsCE!P49/1000,"") -> 4.309
B50: INVCOST | C50: =RSDTechsCE!B50 -> R_ES-SH-DH-70_GAS02 | E50: k€/unit | F50: =IFERROR(RSDTechsCE!L50/1000,"") -> 4.309 | G50: =IFERROR(RSDTechsCE!M50/1000,"") -> 4.309 | H50: =IFERROR(RSDTechsCE!N50/1000,"") -> 4.309 | I50: =IFERROR(RSDTechsCE!O50/1000,"") -> 4.309 | J50: =IFERROR(RSDTechsCE!P50/1000,"") -> 4.309
B51: INVCOST | C51: =RSDTechsCE!B51 -> R_ES-SH-DH-70_GAS02-SOLspl | E51: k€/unit | F51: =IFERROR(RSDTechsCE!L51/1000,"") -> 6.294 | G51: =IFERROR(RSDTechsCE!M51/1000,"") -> 6.00036 | H51: =IFERROR(RSDTechsCE!N51/1000,"") -> 5.75566 | I51: =IFERROR(RSDTechsCE!O51/1000,"") -> 4.67898 | J51: =IFERROR(RSDTechsCE!P51/1000,"") -> 4.67898
B52: INVCOST | C52: =RSDTechsCE!B52 -> R_ES-SH-DH-70_GAS02-BIOspl | E52: k€/unit | F52: =IFERROR(RSDTechsCE!L52/1000,"") -> 4.2 | G52: =IFERROR(RSDTechsCE!M52/1000,"") -> 4.2 | H52: =IFERROR(RSDTechsCE!N52/1000,"") -> 5.1 | I52: =IFERROR(RSDTechsCE!O52/1000,"") -> 5.1 | J52: =IFERROR(RSDTechsCE!P52/1000,"") -> 5.1
B53: INVCOST | C53: =RSDTechsCE!B53 -> R_ES-SH-DH-70_BIO01 | E53: k€/unit | F53: =IFERROR(RSDTechsCE!L53/1000,"") -> 16.55 | G53: =IFERROR(RSDTechsCE!M53/1000,"") -> 16.55 | H53: =IFERROR(RSDTechsCE!N53/1000,"") -> 17.72 | I53: =IFERROR(RSDTechsCE!O53/1000,"") -> 17.72 | J53: =IFERROR(RSDTechsCE!P53/1000,"") -> 17.72
B54: INVCOST | C54: =RSDTechsCE!B54 -> R_ES-SH-DH-70_ELC01 | E54: k€/unit | F54: =IFERROR(RSDTechsCE!L54/1000,"") -> 4 | G54: =IFERROR(RSDTechsCE!M54/1000,"") -> 4 | H54: =IFERROR(RSDTechsCE!N54/1000,"") -> 4 | I54: =IFERROR(RSDTechsCE!O54/1000,"") -> 4 | J54: =IFERROR(RSDTechsCE!P54/1000,"") -> 4
B55: INVCOST | C55: =RSDTechsCE!B55 -> R_ES-SH-DH-70_ELC02 | E55: k€/unit | F55: =IFERROR(RSDTechsCE!L55/1000,"") -> 15.389 | G55: =IFERROR(RSDTechsCE!M55/1000,"") -> 14.61955 | H55: =IFERROR(RSDTechsCE!N55/1000,"") -> 13.23454 | I55: =IFERROR(RSDTechsCE!O55/1000,"") -> 12.61898 | J55: =IFERROR(RSDTechsCE!P55/1000,"") -> 12.61898
B56: INVCOST | C56: =RSDTechsCE!B56 -> R_ES-SH-DH-70_ELC02-ELCspl | E56: k€/unit | F56: =IFERROR(RSDTechsCE!L56/1000,"") -> 3.0395388 | G56: =IFERROR(RSDTechsCE!M56/1000,"") -> 3.0395388 | H56: =IFERROR(RSDTechsCE!N56/1000,"") -> 3.0395388 | I56: =IFERROR(RSDTechsCE!O56/1000,"") -> 3.0395388 | J56: =IFERROR(RSDTechsCE!P56/1000,"") -> 3.0395388
... B82: INVCOST | C82: =RSDTechsCE!B82 -> R_ES-CHP-DH-70-OILspl | E82: k€/unit | F82: =IFERROR(RSDTechsCE!L82/1000,"") -> 5.527 | G82: =IFERROR(RSDTechsCE!M82/1000,"") -> 5.527 | H82: =IFERROR(RSDTechsCE!N82/1000,"") -> 5.527 | I82: =IFERROR(RSDTechsCE!O82/1000,"") -> 5.527 | J82: =IFERROR(RSDTechsCE!P82/1000,"") -> 5.527
B84: ~TFM_INS-TS: EUR17
B85: Attribute | C85: PSet_PN | D85: Region | E85: *units | F85: 2011 | G85: 2020 | H85: 2030 | I85: 2040 | J85: 2050
B86: INVCOST | C86: =RSDTechsCE!B86 -> R_ES-SH-SD_OIL01 | E86: k€/unit | F86: =IFERROR(RSDTechsCE!L86/1000,"") -> 5.527 | G86: =IFERROR(RSDTechsCE!M86/1000,"") -> 5.527 | H86: =IFERROR(RSDTechsCE!N86/1000,"") -> 5.527 | I86: =IFERROR(RSDTechsCE!O86/1000,"") -> 5.527 | J86: =IFERROR(RSDTechsCE!P86/1000,"") -> 5.527
