Workbook
Name FID_1: [1]AGR_Fuels!$A$2

Sheet INS_EFF
A1: Yearly efficiencies (Mkm/TJ) | I1: =1/AN1 -> 0.090497738 | AN1: =(12.6+9.5)/2 -> 11.05
E3: ~TFM_INS | AU3: Used to convert 2*EFF into 1 EFF
A4: Vehicle | B4: Subvehicle | C4: Fuel | E4: Attribute | F4: Year | G4: PSET_PN | H4: AllRegions | I4: AT | J4: BE | K4: BG | L4: CY | M4: CZ | N4: DE | O4: DK | P4: EE | Q4: EL | R4: ES | S4: FI | T4: FR | U4: HR | V4: HU | W4: IE | X4: IT | Y4: LT | Z4: LU | AA4: LV | AB4: MT | AC4: NL | AD4: PL | AE4: PT | AF4: RO | AG4: SE | AH4: SI | AI4: SK | AJ4: UK | AK4: CH | AL4: IS | AM4: NO | AN4: AL | AO4: BA | AP4: ME | AQ4: MK | AR4: RS | AS4: KS
A5: Buses | B5: Conventional coaches | C5: Diesel | E5: EFF | F5: 2010 | G5: TRA_Bus_Dis_Coa* | H5: =AVERAGE(I5:AJ5) -> 0.095357143 | I5: 0.09 | J5: 0.08 | K5: 0.1 | L5: 0.1 | M5: 0.11 | N5: 0.11 | O5: 0.09 | P5: 0.1 | Q5: 0.11 | R5: 0.1 | S5: 0.11 | T5: 0.09 | U5: 0.09 | V5: 0.09 | W5: 0.1 | X5: 0.1 | Y5: 0.07 | Z5: 0.08 | AA5: 0.11 | AB5: 0.1 | AC5: 0.09 | AD5: 0.09 | AE5: 0.1 | AF5: 0.1 | AG5: 0.1 | AH5: 0.09 | AI5: 0.11 | AJ5: 0.06 | AK5: 0.08 | AL5: 0.1 | AM5: 0.11 | AN5: 0.11 | AO5: 0.09 | AP5: 0.11 | AQ5: 0.09 | AR5: 0.09 | AS5: 0.09 | AU5: 1
A6: Buses | B6: Conventional coaches | C6: Diesel | E6: EFF | F6: 2020 | G6: TRA_Bus_Dis_Coa* | H6: =AVERAGE(I6:AJ6) -> 0.097668446 | I6: 0.092181455 | J6: 0.081939071 | K6: 0.10242384 | L6: 0.10242384 | M6: 0.11266622 | N6: 0.11266622 | O6: 0.092181455 | P6: 0.10242384 | Q6: 0.11266622 | R6: 0.10242384 | S6: 0.11266622 | T6: 0.092181455 | U6: 0.092181455 | V6: 0.092181455 | W6: 0.10242384 | X6: 0.10242384 | Y6: 0.071696687 | Z6: 0.081939071 | AA6: 0.11266622 | AB6: 0.10242384 | AC6: 0.092181455 | AD6: 0.092181455 | AE6: 0.10242384 | AF6: 0.10242384 | AG6: 0.10242384 | AH6: 0.092181455 | AI6: 0.11266622 | AJ6: 0.061454303 | AK6: 0.081939071 | AL6: 0.10242384 | AM6: 0.11266622 | AN6: 0.11266622 | AO6: 0.092181455 | AP6: 0.11266622 | AQ6: 0.092181455 | AR6: 0.092181455 | AS6: 0.092181455 | AU6: 1.0242384 | AY6: EFF-converter
A7: Buses | B7: Conventional coaches | C7: Diesel | E7: EFF | F7: 2025 | G7: TRA_Bus_Dis_Coa* | H7: =AVERAGE(I7:AJ7) -> 0.098952504 | I7: 0.093393374 | J7: 0.083016333 | K7: 0.10377042 | L7: 0.10377042 | M7: 0.11414746 | N7: 0.11414746 | O7: 0.093393374 | P7: 0.10377042 | Q7: 0.11414746 | R7: 0.10377042 | S7: 0.11414746 | T7: 0.093393374 | U7: 0.093393374 | V7: 0.093393374 | W7: 0.10377042 | X7: 0.10377042 | Y7: 0.072639291 | Z7: 0.083016333 | AA7: 0.11414746 | AB7: 0.10377042 | AC7: 0.093393374 | AD7: 0.093393374 | AE7: 0.10377042 | AF7: 0.10377042 | AG7: 0.10377042 | AH7: 0.093393374 | AI7: 0.11414746 | AJ7: 0.062262249 | AK7: 0.083016333 | AL7: 0.10377042 | AM7: 0.11414746 | AN7: 0.11414746 | AO7: 0.093393374 | AP7: 0.11414746 | AQ7: 0.093393374 | AR7: 0.093393374 | AS7: 0.093393374 | AU7: 1.0377042 | AY7: 2010 | AZ7: 1.67
A8: Buses | B8: Conventional coaches | C8: Diesel | E8: EFF | F8: 2030 | G8: TRA_Bus_Dis_Coa* | H8: =AVERAGE(I8:AJ8) -> 0.10023656 | I8: 0.094605294 | J8: 0.084093594 | K8: 0.10511699 | L8: 0.10511699 | M8: 0.11562869 | N8: 0.11562869 | O8: 0.094605294 | P8: 0.10511699 | Q8: 0.11562869 | R8: 0.10511699 | S8: 0.11562869 | T8: 0.094605294 | U8: 0.094605294 | V8: 0.094605294 | W8: 0.10511699 | X8: 0.10511699 | Y8: 0.073581895 | Z8: 0.084093594 | AA8: 0.11562869 | AB8: 0.10511699 | AC8: 0.094605294 | AD8: 0.094605294 | AE8: 0.10511699 | AF8: 0.10511699 | AG8: 0.10511699 | AH8: 0.094605294 | AI8: 0.11562869 | AJ8: 0.063070196 | AK8: 0.084093594 | AL8: 0.10511699 | AM8: 0.11562869 | AN8: 0.11562869 | AO8: 0.094605294 | AP8: 0.11562869 | AQ8: 0.094605294 | AR8: 0.094605294 | AS8: 0.094605294 | AU8: 1.0511699 | AY8: 2015 | AZ8: 1.6879903
A9: Buses | B9: Conventional coaches | C9: Diesel | E9: EFF | F9: 2035 | G9: TRA_Bus_Dis_Coa* | H9: =AVERAGE(I9:AJ9) -> 0.10152062 | I9: 0.095817213 | J9: 0.085170856 | K9: 0.10646357 | L9: 0.10646357 | M9: 0.11710993 | N9: 0.11710993 | O9: 0.095817213 | P9: 0.10646357 | Q9: 0.11710993 | R9: 0.10646357 | S9: 0.11710993 | T9: 0.095817213 | U9: 0.095817213 | V9: 0.095817213 | W9: 0.10646357 | X9: 0.10646357 | Y9: 0.074524499 | Z9: 0.085170856 | AA9: 0.11710993 | AB9: 0.10646357 | AC9: 0.095817213 | AD9: 0.095817213 | AE9: 0.10646357 | AF9: 0.10646357 | AG9: 0.10646357 | AH9: 0.095817213 | AI9: 0.11710993 | AJ9: 0.063878142 | AK9: 0.085170856 | AL9: 0.10646357 | AM9: 0.11710993 | AN9: 0.11710993 | AO9: 0.095817213 | AP9: 0.11710993 | AQ9: 0.095817213 | AR9: 0.095817213 | AS9: 0.095817213 | AU9: 1.0646357 | AY9: 2020 | AZ9: =AZ8+($AZ$11-$AZ$8)/($AY$11-$AY$8)*(AY9-AY8) -> 1.7104781
A10: Buses | B10: Conventional coaches | C10: Diesel | E10: EFF | F10: 2040 | G10: TRA_Bus_Dis_Coa* | H10: =AVERAGE(I10:AJ10) -> 0.10280468 | I10: 0.097029132 | J10: 0.086248118 | K10: 0.10781015 | L10: 0.10781015 | M10: 0.11859116 | N10: 0.11859116 | O10: 0.097029132 | P10: 0.10781015 | Q10: 0.11859116 | R10: 0.10781015 | S10: 0.11859116 | T10: 0.097029132 | U10: 0.097029132 | V10: 0.097029132 | W10: 0.10781015 | X10: 0.10781015 | Y10: 0.075467103 | Z10: 0.086248118 | AA10: 0.11859116 | AB10: 0.10781015 | AC10: 0.097029132 | AD10: 0.097029132 | AE10: 0.10781015 | AF10: 0.10781015 | AG10: 0.10781015 | AH10: 0.097029132 | AI10: 0.11859116 | AJ10: 0.064686088 | AK10: 0.086248118 | AL10: 0.10781015 | AM10: 0.11859116 | AN10: 0.11859116 | AO10: 0.097029132 | AP10: 0.11859116 | AQ10: 0.097029132 | AR10: 0.097029132 | AS10: 0.097029132 | AU10: 1.0781015 | AY10: 2025 | AZ10: =AZ9+($AZ$11-$AZ$8)/($AY$11-$AY$8)*(AY10-AY9) -> 1.7329659
A11: Buses | B11: Conventional coaches | C11: Diesel | E11: EFF | F11: 2050 | G11: TRA_Bus_Dis_Coa* | H11: =AVERAGE(I11:AJ11) -> 0.10537279 | I11: 0.099452971 | J11: 0.088402641 | K11: 0.1105033 | L11: 0.1105033 | M11: 0.12155363 | N11: 0.12155363 | O11: 0.099452971 | P11: 0.1105033 | Q11: 0.12155363 | R11: 0.1105033 | S11: 0.12155363 | T11: 0.099452971 | U11: 0.099452971 | V11: 0.099452971 | W11: 0.1105033 | X11: 0.1105033 | Y11: 0.077352311 | Z11: 0.088402641 | AA11: 0.12155363 | AB11: 0.1105033 | AC11: 0.099452971 | AD11: 0.099452971 | AE11: 0.1105033 | AF11: 0.1105033 | AG11: 0.1105033 | AH11: 0.099452971 | AI11: 0.12155363 | AJ11: 0.066301981 | AK11: 0.088402641 | AL11: 0.1105033 | AM11: 0.12155363 | AN11: 0.12155363 | AO11: 0.099452971 | AP11: 0.12155363 | AQ11: 0.099452971 | AR11: 0.099452971 | AS11: 0.099452971 | AU11: 1.105033 | AY11: 2030 | AZ11: 1.7554538
A12: Buses | B12: Conventional coaches | C12: Gasolene | E12: EFF | F12: 2010 | G12: TRA_Bus_Gas_Coa* | H12: =AVERAGE(I12:AJ12) -> 0.087053571 | I12: 0.0875 | J12: 0.0875 | K12: 0.0875 | L12: 0.0875 | M12: 0.1 | N12: 0.0875 | O12: 0.09 | P12: 0.0875 | Q12: 0.0875 | R12: 0.0875 | S12: 0.0875 | T12: 0.0875 | U12: 0.0875 | V12: 0.0875 | W12: 0.0875 | X12: 0.0875 | Y12: 0.0875 | Z12: 0.0875 | AA12: 0.0875 | AB12: 0.0875 | AC12: 0.0875 | AD12: 0.0875 | AE12: 0.0875 | AF12: 0.0875 | AG12: 0.0875 | AH12: 0.0875 | AI12: 0.0875 | AJ12: 0.06 | AK12: 0.0875 | AL12: 0.1 | AM12: 0.0875 | AN12: 0.0875 | AO12: 0.0875 | AP12: 0.0875 | AQ12: 0.0875 | AR12: 0.0875 | AS12: 0.0875 | AU12: 1 | AY12: 2035 | AZ12: =AZ11+($AZ$14-$AZ$11)/($AY$14-$AY$11)*(AY12-AY11) -> 1.7779416
A13: Buses | B13: Conventional coaches | C13: Gasolene | E13: EFF | F13: 2020 | G13: TRA_Bus_Gas_Coa* | H13: =AVERAGE(I13:AJ13) -> 0.08916361 | I13: 0.089620859 | J13: 0.089620859 | K13: 0.089620859 | L13: 0.089620859 | M13: 0.10242384 | N13: 0.089620859 | O13: 0.092181455 | P13: 0.089620859 | Q13: 0.089620859 | R13: 0.089620859 | S13: 0.089620859 | T13: 0.089620859 | U13: 0.089620859 | V13: 0.089620859 | W13: 0.089620859 | X13: 0.089620859 | Y13: 0.089620859 | Z13: 0.089620859 | AA13: 0.089620859 | AB13: 0.089620859 | AC13: 0.089620859 | AD13: 0.089620859 | AE13: 0.089620859 | AF13: 0.089620859 | AG13: 0.089620859 | AH13: 0.089620859 | AI13: 0.089620859 | AJ13: 0.061454303 | AK13: 0.089620859 | AL13: 0.10242384 | AM13: 0.089620859 | AN13: 0.089620859 | AO13: 0.089620859 | AP13: 0.089620859 | AQ13: 0.089620859 | AR13: 0.089620859 | AS13: 0.089620859 | AU13: 1.0242384 | AY13: 2040 | AZ13: =AZ12+($AZ$14-$AZ$11)/($AY$14-$AY$11)*(AY13-AY12) -> 1.8004295
A14: Buses | B14: Conventional coaches | C14: Gasolene | E14: EFF | F14: 2025 | G14: TRA_Bus_Gas_Coa* | H14: =AVERAGE(I14:AJ14) -> 0.090335853 | I14: 0.090799114 | J14: 0.090799114 | K14: 0.090799114 | L14: 0.090799114 | M14: 0.10377042 | N14: 0.090799114 | O14: 0.093393374 | P14: 0.090799114 | Q14: 0.090799114 | R14: 0.090799114 | S14: 0.090799114 | T14: 0.090799114 | U14: 0.090799114 | V14: 0.090799114 | W14: 0.090799114 | X14: 0.090799114 | Y14: 0.090799114 | Z14: 0.090799114 | AA14: 0.090799114 | AB14: 0.090799114 | AC14: 0.090799114 | AD14: 0.090799114 | AE14: 0.090799114 | AF14: 0.090799114 | AG14: 0.090799114 | AH14: 0.090799114 | AI14: 0.090799114 | AJ14: 0.062262249 | AK14: 0.090799114 | AL14: 0.10377042 | AM14: 0.090799114 | AN14: 0.090799114 | AO14: 0.090799114 | AP14: 0.090799114 | AQ14: 0.090799114 | AR14: 0.090799114 | AS14: 0.090799114 | AU14: 1.0377042 | AY14: 2050 | AZ14: 1.8454051
A15: Buses | B15: Conventional coaches | C15: Gasolene | E15: EFF | F15: 2030 | G15: TRA_Bus_Gas_Coa* | H15: =AVERAGE(I15:AJ15) -> 0.091508096 | I15: 0.091977369 | J15: 0.091977369 | K15: 0.091977369 | L15: 0.091977369 | M15: 0.10511699 | N15: 0.091977369 | O15: 0.094605294 | P15: 0.091977369 | Q15: 0.091977369 | R15: 0.091977369 | S15: 0.091977369 | T15: 0.091977369 | U15: 0.091977369 | V15: 0.091977369 | W15: 0.091977369 | X15: 0.091977369 | Y15: 0.091977369 | Z15: 0.091977369 | AA15: 0.091977369 | AB15: 0.091977369 | AC15: 0.091977369 | AD15: 0.091977369 | AE15: 0.091977369 | AF15: 0.091977369 | AG15: 0.091977369 | AH15: 0.091977369 | AI15: 0.091977369 | AJ15: 0.063070196 | AK15: 0.091977369 | AL15: 0.10511699 | AM15: 0.091977369 | AN15: 0.091977369 | AO15: 0.091977369 | AP15: 0.091977369 | AQ15: 0.091977369 | AR15: 0.091977369 | AS15: 0.091977369 | AU15: 1.0511699
A16: Buses | B16: Conventional coaches | C16: Gasolene | E16: EFF | F16: 2035 | G16: TRA_Bus_Gas_Coa* | H16: =AVERAGE(I16:AJ16) -> 0.09268034 | I16: 0.093155624 | J16: 0.093155624 | K16: 0.093155624 | L16: 0.093155624 | M16: 0.10646357 | N16: 0.093155624 | O16: 0.095817213 | P16: 0.093155624 | Q16: 0.093155624 | R16: 0.093155624 | S16: 0.093155624 | T16: 0.093155624 | U16: 0.093155624 | V16: 0.093155624 | W16: 0.093155624 | X16: 0.093155624 | Y16: 0.093155624 | Z16: 0.093155624 | AA16: 0.093155624 | AB16: 0.093155624 | AC16: 0.093155624 | AD16: 0.093155624 | AE16: 0.093155624 | AF16: 0.093155624 | AG16: 0.093155624 | AH16: 0.093155624 | AI16: 0.093155624 | AJ16: 0.063878142 | AK16: 0.093155624 | AL16: 0.10646357 | AM16: 0.093155624 | AN16: 0.093155624 | AO16: 0.093155624 | AP16: 0.093155624 | AQ16: 0.093155624 | AR16: 0.093155624 | AS16: 0.093155624 | AU16: 1.0646357
A17: Buses | B17: Conventional coaches | C17: Gasolene | E17: EFF | F17: 2040 | G17: TRA_Bus_Gas_Coa* | H17: =AVERAGE(I17:AJ17) -> 0.093852583 | I17: 0.094333879 | J17: 0.094333879 | K17: 0.094333879 | L17: 0.094333879 | M17: 0.10781015 | N17: 0.094333879 | O17: 0.097029132 | P17: 0.094333879 | Q17: 0.094333879 | R17: 0.094333879 | S17: 0.094333879 | T17: 0.094333879 | U17: 0.094333879 | V17: 0.094333879 | W17: 0.094333879 | X17: 0.094333879 | Y17: 0.094333879 | Z17: 0.094333879 | AA17: 0.094333879 | AB17: 0.094333879 | AC17: 0.094333879 | AD17: 0.094333879 | AE17: 0.094333879 | AF17: 0.094333879 | AG17: 0.094333879 | AH17: 0.094333879 | AI17: 0.094333879 | AJ17: 0.064686088 | AK17: 0.094333879 | AL17: 0.10781015 | AM17: 0.094333879 | AN17: 0.094333879 | AO17: 0.094333879 | AP17: 0.094333879 | AQ17: 0.094333879 | AR17: 0.094333879 | AS17: 0.094333879 | AU17: 1.0781015
A18: Buses | B18: Conventional coaches | C18: Gasolene | E18: EFF | F18: 2050 | G18: TRA_Bus_Gas_Coa* | H18: =AVERAGE(I18:AJ18) -> 0.09619707 | I18: 0.096690388 | J18: 0.096690388 | K18: 0.096690388 | L18: 0.096690388 | M18: 0.1105033 | N18: 0.096690388 | O18: 0.099452971 | P18: 0.096690388 | Q18: 0.096690388 | R18: 0.096690388 | S18: 0.096690388 | T18: 0.096690388 | U18: 0.096690388 | V18: 0.096690388 | W18: 0.096690388 | X18: 0.096690388 | Y18: 0.096690388 | Z18: 0.096690388 | AA18: 0.096690388 | AB18: 0.096690388 | AC18: 0.096690388 | AD18: 0.096690388 | AE18: 0.096690388 | AF18: 0.096690388 | AG18: 0.096690388 | AH18: 0.096690388 | AI18: 0.096690388 | AJ18: 0.066301981 | AK18: 0.096690388 | AL18: 0.1105033 | AM18: 0.096690388 | AN18: 0.096690388 | AO18: 0.096690388 | AP18: 0.096690388 | AQ18: 0.096690388 | AR18: 0.096690388 | AS18: 0.096690388 | AU18: 1.105033
A19: Buses | B19: Conventional coaches | C19: LPG | E19: EFF | F19: 2010 | G19: TRA_Bus_Lpg_Coa* | H19: =AVERAGE(I19:AJ19) -> 0.05 | I19: 0.05 | J19: 0.05 | K19: 0.05 | L19: 0.05 | M19: 0.05 | N19: 0.05 | O19: 0.05 | P19: 0.05 | Q19: 0.05 | R19: 0.05 | S19: 0.05 | T19: 0.05 | U19: 0.05 | V19: 0.05 | W19: 0.05 | X19: 0.05 | Y19: 0.05 | Z19: 0.05 | AA19: 0.05 | AB19: 0.05 | AC19: 0.05 | AD19: 0.05 | AE19: 0.05 | AF19: 0.05 | AG19: 0.05 | AH19: 0.05 | AI19: 0.05 | AJ19: 0.05 | AK19: 0.05 | AL19: 0.05 | AM19: 0.05 | AN19: 0.05 | AO19: 0.05 | AP19: 0.05 | AQ19: 0.05 | AR19: 0.05 | AS19: 0.05 | AU19: 1
A20: Buses | B20: Conventional coaches | C20: LPG | E20: EFF | F20: 2020 | G20: TRA_Bus_Lpg_Coa* | H20: =AVERAGE(I20:AJ20) -> 0.05 | I20: 0.05 | J20: 0.05 | K20: 0.05 | L20: 0.05 | M20: 0.05 | N20: 0.05 | O20: 0.05 | P20: 0.05 | Q20: 0.05 | R20: 0.05 | S20: 0.05 | T20: 0.05 | U20: 0.05 | V20: 0.05 | W20: 0.05 | X20: 0.05 | Y20: 0.05 | Z20: 0.05 | AA20: 0.05 | AB20: 0.05 | AC20: 0.05 | AD20: 0.05 | AE20: 0.05 | AF20: 0.05 | AG20: 0.05 | AH20: 0.05 | AI20: 0.05 | AJ20: 0.05 | AK20: 0.05 | AL20: 0.05 | AM20: 0.05 | AN20: 0.05 | AO20: 0.05 | AP20: 0.05 | AQ20: 0.05 | AR20: 0.05 | AS20: 0.05 | AU20: 1
A21: Buses | B21: Conventional coaches | C21: LPG | E21: EFF | F21: 2025 | G21: TRA_Bus_Lpg_Coa* | H21: =AVERAGE(I21:AJ21) -> 0.05 | I21: 0.05 | J21: 0.05 | K21: 0.05 | L21: 0.05 | M21: 0.05 | N21: 0.05 | O21: 0.05 | P21: 0.05 | Q21: 0.05 | R21: 0.05 | S21: 0.05 | T21: 0.05 | U21: 0.05 | V21: 0.05 | W21: 0.05 | X21: 0.05 | Y21: 0.05 | Z21: 0.05 | AA21: 0.05 | AB21: 0.05 | AC21: 0.05 | AD21: 0.05 | AE21: 0.05 | AF21: 0.05 | AG21: 0.05 | AH21: 0.05 | AI21: 0.05 | AJ21: 0.05 | AK21: 0.05 | AL21: 0.05 | AM21: 0.05 | AN21: 0.05 | AO21: 0.05 | AP21: 0.05 | AQ21: 0.05 | AR21: 0.05 | AS21: 0.05 | AU21: 1
A22: Buses | B22: Conventional coaches | C22: LPG | E22: EFF | F22: 2030 | G22: TRA_Bus_Lpg_Coa* | H22: =AVERAGE(I22:AJ22) -> 0.05 | I22: 0.05 | J22: 0.05 | K22: 0.05 | L22: 0.05 | M22: 0.05 | N22: 0.05 | O22: 0.05 | P22: 0.05 | Q22: 0.05 | R22: 0.05 | S22: 0.05 | T22: 0.05 | U22: 0.05 | V22: 0.05 | W22: 0.05 | X22: 0.05 | Y22: 0.05 | Z22: 0.05 | AA22: 0.05 | AB22: 0.05 | AC22: 0.05 | AD22: 0.05 | AE22: 0.05 | AF22: 0.05 | AG22: 0.05 | AH22: 0.05 | AI22: 0.05 | AJ22: 0.05 | AK22: 0.05 | AL22: 0.05 | AM22: 0.05 | AN22: 0.05 | AO22: 0.05 | AP22: 0.05 | AQ22: 0.05 | AR22: 0.05 | AS22: 0.05 | AU22: 1
A23: Buses | B23: Conventional coaches | C23: LPG | E23: EFF | F23: 2035 | G23: TRA_Bus_Lpg_Coa* | H23: =AVERAGE(I23:AJ23) -> 0.05 | I23: 0.05 | J23: 0.05 | K23: 0.05 | L23: 0.05 | M23: 0.05 | N23: 0.05 | O23: 0.05 | P23: 0.05 | Q23: 0.05 | R23: 0.05 | S23: 0.05 | T23: 0.05 | U23: 0.05 | V23: 0.05 | W23: 0.05 | X23: 0.05 | Y23: 0.05 | Z23: 0.05 | AA23: 0.05 | AB23: 0.05 | AC23: 0.05 | AD23: 0.05 | AE23: 0.05 | AF23: 0.05 | AG23: 0.05 | AH23: 0.05 | AI23: 0.05 | AJ23: 0.05 | AK23: 0.05 | AL23: 0.05 | AM23: 0.05 | AN23: 0.05 | AO23: 0.05 | AP23: 0.05 | AQ23: 0.05 | AR23: 0.05 | AS23: 0.05 | AU23: 1
A24: Buses | B24: Conventional coaches | C24: LPG | E24: EFF | F24: 2040 | G24: TRA_Bus_Lpg_Coa* | H24: =AVERAGE(I24:AJ24) -> 0.05 | I24: 0.05 | J24: 0.05 | K24: 0.05 | L24: 0.05 | M24: 0.05 | N24: 0.05 | O24: 0.05 | P24: 0.05 | Q24: 0.05 | R24: 0.05 | S24: 0.05 | T24: 0.05 | U24: 0.05 | V24: 0.05 | W24: 0.05 | X24: 0.05 | Y24: 0.05 | Z24: 0.05 | AA24: 0.05 | AB24: 0.05 | AC24: 0.05 | AD24: 0.05 | AE24: 0.05 | AF24: 0.05 | AG24: 0.05 | AH24: 0.05 | AI24: 0.05 | AJ24: 0.05 | AK24: 0.05 | AL24: 0.05 | AM24: 0.05 | AN24: 0.05 | AO24: 0.05 | AP24: 0.05 | AQ24: 0.05 | AR24: 0.05 | AS24: 0.05 | AU24: 1
A25: Buses | B25: Conventional coaches | C25: LPG | E25: EFF | F25: 2050 | G25: TRA_Bus_Lpg_Coa* | H25: =AVERAGE(I25:AJ25) -> 0.05 | I25: 0.05 | J25: 0.05 | K25: 0.05 | L25: 0.05 | M25: 0.05 | N25: 0.05 | O25: 0.05 | P25: 0.05 | Q25: 0.05 | R25: 0.05 | S25: 0.05 | T25: 0.05 | U25: 0.05 | V25: 0.05 | W25: 0.05 | X25: 0.05 | Y25: 0.05 | Z25: 0.05 | AA25: 0.05 | AB25: 0.05 | AC25: 0.05 | AD25: 0.05 | AE25: 0.05 | AF25: 0.05 | AG25: 0.05 | AH25: 0.05 | AI25: 0.05 | AJ25: 0.05 | AK25: 0.05 | AL25: 0.05 | AM25: 0.05 | AN25: 0.05 | AO25: 0.05 | AP25: 0.05 | AQ25: 0.05 | AR25: 0.05 | AS25: 0.05 | AU25: 1
A26: Buses | B26: Low and zero emission coaches | C26: CNG | E26: EFF | F26: 2010 | G26: TRA_Bus_Cng_Coa* | H26: =AVERAGE(I26:AJ26) -> 0.0332 | I26: 0.0332 | J26: 0.0332 | K26: 0.0332 | L26: 0.0332 | M26: 0.0332 | N26: 0.0332 | O26: 0.0332 | P26: 0.0332 | Q26: 0.0332 | R26: 0.0332 | S26: 0.0332 | T26: 0.0332 | U26: 0.0332 | V26: 0.0332 | W26: 0.0332 | X26: 0.0332 | Y26: 0.0332 | Z26: 0.0332 | AA26: 0.0332 | AB26: 0.0332 | AC26: 0.0332 | AD26: 0.0332 | AE26: 0.0332 | AF26: 0.0332 | AG26: 0.0332 | AH26: 0.0332 | AI26: 0.0332 | AJ26: 0.0332 | AK26: 0.0332 | AL26: 0.0332 | AM26: 0.0332 | AN26: 0.0332 | AO26: 0.0332 | AP26: 0.0332 | AQ26: 0.0332 | AR26: 0.0332 | AS26: 0.0332 | AU26: 0.83
... A46: Buses | B46: Low and zero emission coaches | C46: Hydrogen | E46: EFF | F46: 2050 | G46: TRA_Bus_GH2_Coa* | H46: =AVERAGE(I46:AJ46) -> 0.21074558 | I46: 0.19890594 | J46: 0.17680528 | K46: 0.2210066 | L46: 0.2210066 | M46: 0.24310726 | N46: 0.24310726 | O46: 0.19890594 | P46: 0.2210066 | Q46: 0.24310726 | R46: 0.2210066 | S46: 0.24310726 | T46: 0.19890594 | U46: 0.19890594 | V46: 0.19890594 | W46: 0.2210066 | X46: 0.2210066 | Y46: 0.15470462 | Z46: 0.17680528 | AA46: 0.24310726 | AB46: 0.2210066 | AC46: 0.19890594 | AD46: 0.19890594 | AE46: 0.2210066 | AF46: 0.2210066 | AG46: 0.2210066 | AH46: 0.19890594 | AI46: 0.24310726 | AJ46: 0.13260396 | AK46: 0.17680528 | AL46: 0.2210066 | AM46: 0.24310726 | AN46: 0.24310726 | AO46: 0.19890594 | AP46: 0.24310726 | AQ46: 0.19890594 | AR46: 0.19890594 | AS46: 0.19890594 | AU46: 2.210066
A47: Buses | B47: Low and zero emission coaches | C47: Electricity | E47: EFF | F47: 2010 | G47: TRA_Bus_Elc_Coa* | H47: 0.30726111
A48: Buses | B48: Low and zero emission coaches | C48: Electricity | E48: EFF | F48: 2020 | G48: TRA_Bus_Elc_Coa* | H48: 0.33298605
A49: Buses | B49: Low and zero emission coaches | C49: Electricity | E49: EFF | F49: 2025 | G49: TRA_Bus_Elc_Coa* | H49: 0.35014672
A50: Buses | B50: Low and zero emission coaches | C50: Electricity | E50: EFF | F50: 2030 | G50: TRA_Bus_Elc_Coa* | H50: 0.36819178
A51: Buses | B51: Low and zero emission coaches | C51: Electricity | E51: EFF | F51: 2035 | G51: TRA_Bus_Elc_Coa* | H51: 0.36819178
A52: Buses | B52: Low and zero emission coaches | C52: Electricity | E52: EFF | F52: 2040 | G52: TRA_Bus_Elc_Coa* | H52: 0.36819178
A53: Buses | B53: Low and zero emission coaches | C53: Electricity | E53: EFF | F53: 2050 | G53: TRA_Bus_Elc_Coa* | H53: 0.36819178
A54: Buses | B54: Conventional urban buses | C54: Diesel | E54: EFF | F54: 2010 | G54: TRA_Bus_Dis_Urb* | H54: =AVERAGE(I54:AJ54) -> 0.083025794 | I54: 0.1 | J54: 0.09 | K54: 0.06 | L54: 0.08 | M54: 0.08 | N54: 0.08 | O54: 0.09 | P54: 0.084722222 | Q54: 0.08 | R54: 0.07 | S54: 0.08 | T54: 0.08 | U54: 0.1 | V54: 0.08 | W54: 0.1 | X54: 0.07 | Y54: 0.1 | Z54: 0.09 | AA54: 0.09 | AB54: 0.08 | AC54: 0.09 | AD54: 0.08 | AE54: 0.07 | AF54: 0.06 | AG54: 0.08 | AH54: 0.1 | AI54: 0.08 | AJ54: 0.08 | AK54: 0.09 | AL54: 0.08 | AM54: 0.08 | AN54: 0.08 | AO54: 0.1 | AP54: 0.08 | AQ54: 0.1 | AR54: 0.1 | AS54: 0.1 | AU54: 1
A55: Buses | B55: Conventional urban buses | C55: Diesel | E55: EFF | F55: 2020 | G55: TRA_Bus_Dis_Urb* | H55: =AVERAGE(I55:AJ55) -> 0.085038205 | I55: 0.10242384 | J55: 0.092181455 | K55: 0.061454303 | L55: 0.081939071 | M55: 0.081939071 | N55: 0.081939071 | O55: 0.092181455 | P55: 0.086775752 | Q55: 0.081939071 | R55: 0.071696687 | S55: 0.081939071 | T55: 0.081939071 | U55: 0.10242384 | V55: 0.081939071 | W55: 0.10242384 | X55: 0.071696687 | Y55: 0.10242384 | Z55: 0.092181455 | AA55: 0.092181455 | AB55: 0.081939071 | AC55: 0.092181455 | AD55: 0.081939071 | AE55: 0.071696687 | AF55: 0.061454303 | AG55: 0.081939071 | AH55: 0.10242384 | AI55: 0.081939071 | AJ55: 0.081939071 | AK55: 0.092181455 | AL55: 0.081939071 | AM55: 0.081939071 | AN55: 0.081939071 | AO55: 0.10242384 | AP55: 0.081939071 | AQ55: 0.10242384 | AR55: 0.10242384 | AS55: 0.10242384 | AU55: 1.0242384
A56: Buses | B56: Conventional urban buses | C56: Diesel | E56: EFF | F56: 2025 | G56: TRA_Bus_Dis_Urb* | H56: =AVERAGE(I56:AJ56) -> 0.086156211 | I56: 0.10377042 | J56: 0.093393374 | K56: 0.062262249 | L56: 0.083016333 | M56: 0.083016333 | N56: 0.083016333 | O56: 0.093393374 | P56: 0.087916602 | Q56: 0.083016333 | R56: 0.072639291 | S56: 0.083016333 | T56: 0.083016333 | U56: 0.10377042 | V56: 0.083016333 | W56: 0.10377042 | X56: 0.072639291 | Y56: 0.10377042 | Z56: 0.093393374 | AA56: 0.093393374 | AB56: 0.083016333 | AC56: 0.093393374 | AD56: 0.083016333 | AE56: 0.072639291 | AF56: 0.062262249 | AG56: 0.083016333 | AH56: 0.10377042 | AI56: 0.083016333 | AJ56: 0.083016333 | AK56: 0.093393374 | AL56: 0.083016333 | AM56: 0.083016333 | AN56: 0.083016333 | AO56: 0.10377042 | AP56: 0.083016333 | AQ56: 0.10377042 | AR56: 0.10377042 | AS56: 0.10377042 | AU56: 1.0377042
A57: Buses | B57: Conventional urban buses | C57: Diesel | E57: EFF | F57: 2030 | G57: TRA_Bus_Dis_Urb* | H57: =AVERAGE(I57:AJ57) -> 0.087274218 | I57: 0.10511699 | J57: 0.094605294 | K57: 0.063070196 | L57: 0.084093594 | M57: 0.084093594 | N57: 0.084093594 | O57: 0.094605294 | P57: 0.089057452 | Q57: 0.084093594 | R57: 0.073581895 | S57: 0.084093594 | T57: 0.084093594 | U57: 0.10511699 | V57: 0.084093594 | W57: 0.10511699 | X57: 0.073581895 | Y57: 0.10511699 | Z57: 0.094605294 | AA57: 0.094605294 | AB57: 0.084093594 | AC57: 0.094605294 | AD57: 0.084093594 | AE57: 0.073581895 | AF57: 0.063070196 | AG57: 0.084093594 | AH57: 0.10511699 | AI57: 0.084093594 | AJ57: 0.084093594 | AK57: 0.094605294 | AL57: 0.084093594 | AM57: 0.084093594 | AN57: 0.084093594 | AO57: 0.10511699 | AP57: 0.084093594 | AQ57: 0.10511699 | AR57: 0.10511699 | AS57: 0.10511699 | AU57: 1.0511699
A58: Buses | B58: Conventional urban buses | C58: Diesel | E58: EFF | F58: 2035 | G58: TRA_Bus_Dis_Urb* | H58: =AVERAGE(I58:AJ58) -> 0.088392224 | I58: 0.10646357 | J58: 0.095817213 | K58: 0.063878142 | L58: 0.085170856 | M58: 0.085170856 | N58: 0.085170856 | O58: 0.095817213 | P58: 0.090198302 | Q58: 0.085170856 | R58: 0.074524499 | S58: 0.085170856 | T58: 0.085170856 | U58: 0.10646357 | V58: 0.085170856 | W58: 0.10646357 | X58: 0.074524499 | Y58: 0.10646357 | Z58: 0.095817213 | AA58: 0.095817213 | AB58: 0.085170856 | AC58: 0.095817213 | AD58: 0.085170856 | AE58: 0.074524499 | AF58: 0.063878142 | AG58: 0.085170856 | AH58: 0.10646357 | AI58: 0.085170856 | AJ58: 0.085170856 | AK58: 0.095817213 | AL58: 0.085170856 | AM58: 0.085170856 | AN58: 0.085170856 | AO58: 0.10646357 | AP58: 0.085170856 | AQ58: 0.10646357 | AR58: 0.10646357 | AS58: 0.10646357 | AU58: 1.0646357
A59: Buses | B59: Conventional urban buses | C59: Diesel | E59: EFF | F59: 2040 | G59: TRA_Bus_Dis_Urb* | H59: =AVERAGE(I59:AJ59) -> 0.08951023 | I59: 0.10781015 | J59: 0.097029132 | K59: 0.064686088 | L59: 0.086248118 | M59: 0.086248118 | N59: 0.086248118 | O59: 0.097029132 | P59: 0.091339152 | Q59: 0.086248118 | R59: 0.075467103 | S59: 0.086248118 | T59: 0.086248118 | U59: 0.10781015 | V59: 0.086248118 | W59: 0.10781015 | X59: 0.075467103 | Y59: 0.10781015 | Z59: 0.097029132 | AA59: 0.097029132 | AB59: 0.086248118 | AC59: 0.097029132 | AD59: 0.086248118 | AE59: 0.075467103 | AF59: 0.064686088 | AG59: 0.086248118 | AH59: 0.10781015 | AI59: 0.086248118 | AJ59: 0.086248118 | AK59: 0.097029132 | AL59: 0.086248118 | AM59: 0.086248118 | AN59: 0.086248118 | AO59: 0.10781015 | AP59: 0.086248118 | AQ59: 0.10781015 | AR59: 0.10781015 | AS59: 0.10781015 | AU59: 1.0781015
A60: Buses | B60: Conventional urban buses | C60: Diesel | E60: EFF | F60: 2050 | G60: TRA_Bus_Dis_Urb* | H60: =AVERAGE(I60:AJ60) -> 0.091746243 | I60: 0.1105033 | J60: 0.099452971 | K60: 0.066301981 | L60: 0.088402641 | M60: 0.088402641 | N60: 0.088402641 | O60: 0.099452971 | P60: 0.093620852 | Q60: 0.088402641 | R60: 0.077352311 | S60: 0.088402641 | T60: 0.088402641 | U60: 0.1105033 | V60: 0.088402641 | W60: 0.1105033 | X60: 0.077352311 | Y60: 0.1105033 | Z60: 0.099452971 | AA60: 0.099452971 | AB60: 0.088402641 | AC60: 0.099452971 | AD60: 0.088402641 | AE60: 0.077352311 | AF60: 0.066301981 | AG60: 0.088402641 | AH60: 0.1105033 | AI60: 0.088402641 | AJ60: 0.088402641 | AK60: 0.099452971 | AL60: 0.088402641 | AM60: 0.088402641 | AN60: 0.088402641 | AO60: 0.1105033 | AP60: 0.088402641 | AQ60: 0.1105033 | AR60: 0.1105033 | AS60: 0.1105033 | AU60: 1.105033
...

Sheet INS_AF
A1: Yearly availability factors (tkm/year)
E3: ~TFM_INS
A4: Vehicle | B4: Subvehicle | C4: Fuel | E4: Attribute | F4: Year | G4: PSET_PN | H4: AllRegions | I4: AL | J4: AT | K4: BA | L4: BE | M4: BG | N4: CH | O4: CY | P4: CZ | Q4: DE | R4: DK | S4: EE | T4: EL | U4: ES | V4: FI | W4: FR | X4: HR | Y4: HU | Z4: IE | AA4: IS | AB4: IT | AC4: KS | AD4: LT | AE4: LU | AF4: LV | AG4: ME | AH4: MK | AI4: MT | AJ4: NL | AK4: NO | AL4: PL | AM4: PT | AN4: RO | AO4: RS | AP4: SE | AQ4: SI | AR4: SK | AS4: UK
A5: Buses | B5: Conventional coaches | C5: Diesel | E5: AF | F5: 2010 | G5: TRA_Bus_Dis_Coa* | H5: =AVERAGE(I5:AS5) -> 66.756157 | I5: 90.5633 | J5: 137.92 | K5: 82.638 | L5: 61.8505 | M5: 27.1992 | N5: 55.6788 | O5: 43.6949 | P5: 50.4533 | Q5: 80.0755 | R5: 37.3013 | S5: 45.6949 | T5: 90.5633 | U5: 79.5897 | V5: 59.8584 | W5: 44.4871 | X5: 82.638 | Y5: 61.7817 | Z5: 54.3276 | AA5: 46.339 | AB5: 42.7829 | AC5: 82.638 | AD5: 15.8658 | AE5: 192.143 | AF5: 89.929 | AG5: 90.5633 | AH5: 21.8232 | AI5: 30.1527 | AJ5: 65.2606 | AK5: 63.8276 | AL5: 33.9756 | AM5: 37.7216 | AN5: 28.9507 | AO5: 82.638 | AP5: 110.72 | AQ5: 115.751 | AR5: 67.5264 | AS5: 65.0539
A6: Buses | B6: Conventional coaches | C6: Diesel | E6: AF | F6: 2020 | G6: TRA_Bus_Dis_Coa* | H6: =AVERAGE(I6:AS6) -> 66.756157 | I6: =I5 -> 90.5633 | J6: =J5 -> 137.92 | K6: =K5 -> 82.638 | L6: =L5 -> 61.8505 | M6: =M5 -> 27.1992 | N6: =N5 -> 55.6788 | O6: =O5 -> 43.6949 | P6: =P5 -> 50.4533 | ... AS6: =AS5 -> 65.0539
A7: Buses | B7: Conventional coaches | C7: Diesel | E7: AF | F7: 2025 | G7: TRA_Bus_Dis_Coa* | H7: =AVERAGE(I7:AS7) -> 66.756157 | I7: =I6 -> 90.5633 | J7: =J6 -> 137.92 | K7: =K6 -> 82.638 | L7: =L6 -> 61.8505 | M7: =M6 -> 27.1992 | N7: =N6 -> 55.6788 | O7: =O6 -> 43.6949 | P7: =P6 -> 50.4533 | ... AS7: =AS6 -> 65.0539
A8: Buses | B8: Conventional coaches | C8: Diesel | E8: AF | F8: 2030 | G8: TRA_Bus_Dis_Coa* | H8: =AVERAGE(I8:AS8) -> 66.756157 | I8: =I7 -> 90.5633 | J8: =J7 -> 137.92 | K8: =K7 -> 82.638 | L8: =L7 -> 61.8505 | M8: =M7 -> 27.1992 | N8: =N7 -> 55.6788 | O8: =O7 -> 43.6949 | P8: =P7 -> 50.4533 | ... AS8: =AS7 -> 65.0539
A9: Buses | B9: Conventional coaches | C9: Diesel | E9: AF | F9: 2035 | G9: TRA_Bus_Dis_Coa* | H9: =AVERAGE(I9:AS9) -> 66.756157 | I9: =I8 -> 90.5633 | J9: =J8 -> 137.92 | K9: =K8 -> 82.638 | L9: =L8 -> 61.8505 | M9: =M8 -> 27.1992 | N9: =N8 -> 55.6788 | O9: =O8 -> 43.6949 | P9: =P8 -> 50.4533 | ... AS9: =AS8 -> 65.0539
A10: Buses | B10: Conventional coaches | C10: Diesel | E10: AF | F10: 2040 | G10: TRA_Bus_Dis_Coa* | H10: =AVERAGE(I10:AS10) -> 66.756157 | I10: =I9 -> 90.5633 | J10: =J9 -> 137.92 | K10: =K9 -> 82.638 | L10: =L9 -> 61.8505 | M10: =M9 -> 27.1992 | N10: =N9 -> 55.6788 | O10: =O9 -> 43.6949 | P10: =P9 -> 50.4533 | ... AS10: =AS9 -> 65.0539
A11: Buses | B11: Conventional coaches | C11: Diesel | E11: AF | F11: 2050 | G11: TRA_Bus_Dis_Coa* | H11: =AVERAGE(I11:AS11) -> 66.756157 | I11: =I10 -> 90.5633 | J11: =J10 -> 137.92 | K11: =K10 -> 82.638 | L11: =L10 -> 61.8505 | M11: =M10 -> 27.1992 | N11: =N10 -> 55.6788 | O11: =O10 -> 43.6949 | P11: =P10 -> 50.4533 | ... AS11: =AS10 -> 65.0539
A12: Buses | B12: Conventional coaches | C12: Gasolene | E12: AF | F12: 2010 | G12: TRA_Bus_Gas_Coa* | H12: =AVERAGE(I12:AS12) -> 39.1639 | P12: 41.3745 | R12: 10.2624 | AA12: 45.0813 | AS12: 59.9374
A13: Buses | B13: Conventional coaches | C13: Gasolene | E13: AF | F13: 2020 | G13: TRA_Bus_Gas_Coa* | H13: =AVERAGE(I13:AS13) -> 39.1639 | P13: =P12 -> 41.3745 | R13: =R12 -> 10.2624 | AA13: =AA12 -> 45.0813 | AS13: =AS12 -> 59.9374
A14: Buses | B14: Conventional coaches | C14: Gasolene | E14: AF | F14: 2025 | G14: TRA_Bus_Gas_Coa* | H14: =AVERAGE(I14:AS14) -> 39.1639 | P14: =P13 -> 41.3745 | R14: =R13 -> 10.2624 | AA14: =AA13 -> 45.0813 | AS14: =AS13 -> 59.9374
A15: Buses | B15: Conventional coaches | C15: Gasolene | E15: AF | F15: 2030 | G15: TRA_Bus_Gas_Coa* | H15: =AVERAGE(I15:AS15) -> 39.1639 | P15: =P14 -> 41.3745 | R15: =R14 -> 10.2624 | AA15: =AA14 -> 45.0813 | AS15: =AS14 -> 59.9374
A16: Buses | B16: Conventional coaches | C16: Gasolene | E16: AF | F16: 2035 | G16: TRA_Bus_Gas_Coa* | H16: =AVERAGE(I16:AS16) -> 39.1639 | P16: =P15 -> 41.3745 | R16: =R15 -> 10.2624 | AA16: =AA15 -> 45.0813 | AS16: =AS15 -> 59.9374
A17: Buses | B17: Conventional coaches | C17: Gasolene | E17: AF | F17: 2040 | G17: TRA_Bus_Gas_Coa* | H17: =AVERAGE(I17:AS17) -> 39.1639 | P17: =P16 -> 41.3745 | R17: =R16 -> 10.2624 | AA17: =AA16 -> 45.0813 | AS17: =AS16 -> 59.9374
A18: Buses | B18: Conventional coaches | C18: Gasolene | E18: AF | F18: 2050 | G18: TRA_Bus_Gas_Coa* | H18: =AVERAGE(I18:AS18) -> 39.1639 | P18: =P17 -> 41.3745 | R18: =R17 -> 10.2624 | AA18: =AA17 -> 45.0813 | AS18: =AS17 -> 59.9374
A19: Buses | B19: Conventional coaches | C19: LPG | E19: AF | F19: 2010 | G19: TRA_Bus_Lpg_Coa* | H19: =AVERAGE(I19:AS19) -> 148.262 | AS19: 148.262
A20: Buses | B20: Conventional coaches | C20: LPG | E20: AF | F20: 2020 | G20: TRA_Bus_Lpg_Coa* | H20: =AVERAGE(I20:AS20) -> 148.262 | AS20: 148.262
A21: Buses | B21: Conventional coaches | C21: LPG | E21: AF | F21: 2025 | G21: TRA_Bus_Lpg_Coa* | H21: =AVERAGE(I21:AS21) -> 148.262 | AS21: 148.262
A22: Buses | B22: Conventional coaches | C22: LPG | E22: AF | F22: 2030 | G22: TRA_Bus_Lpg_Coa* | H22: =AVERAGE(I22:AS22) -> 148.262 | AS22: 148.262
A23: Buses | B23: Conventional coaches | C23: LPG | E23: AF | F23: 2035 | G23: TRA_Bus_Lpg_Coa* | H23: =AVERAGE(I23:AS23) -> 148.262 | AS23: 148.262
A24: Buses | B24: Conventional coaches | C24: LPG | E24: AF | F24: 2040 | G24: TRA_Bus_Lpg_Coa* | H24: =AVERAGE(I24:AS24) -> 148.262 | AS24: 148.262
A25: Buses | B25: Conventional coaches | C25: LPG | E25: AF | F25: 2050 | G25: TRA_Bus_Lpg_Coa* | H25: =AVERAGE(I25:AS25) -> 148.262 | AS25: 148.262
A26: Buses | B26: Low and zero emission coaches | C26: CNG | E26: AF | F26: 2010 | G26: TRA_Bus_Cng_Coa* | H26: =AVERAGE(I26:AS26) -> 16.318 | AP26: 16.318
A27: Buses | B27: Low and zero emission coaches | C27: CNG | E27: AF | F27: 2020 | G27: TRA_Bus_Cng_Coa* | H27: =AVERAGE(I27:AS27) -> 16.318 | AP27: 16.318
A28: Buses | B28: Low and zero emission coaches | C28: CNG | E28: AF | F28: 2025 | G28: TRA_Bus_Cng_Coa* | H28: =AVERAGE(I28:AS28) -> 16.318 | AP28: 16.318
A29: Buses | B29: Low and zero emission coaches | C29: CNG | E29: AF | F29: 2030 | G29: TRA_Bus_Cng_Coa* | H29: =AVERAGE(I29:AS29) -> 16.318 | AP29: 16.318
A30: Buses | B30: Low and zero emission coaches | C30: CNG | E30: AF | F30: 2035 | G30: TRA_Bus_Cng_Coa* | H30: =AVERAGE(I30:AS30) -> 16.318 | AP30: 16.318
A31: Buses | B31: Low and zero emission coaches | C31: CNG | E31: AF | F31: 2040 | G31: TRA_Bus_Cng_Coa* | H31: =AVERAGE(I31:AS31) -> 16.318 | AP31: 16.318
A32: Buses | B32: Low and zero emission coaches | C32: CNG | E32: AF | F32: 2050 | G32: TRA_Bus_Cng_Coa* | H32: =AVERAGE(I32:AS32) -> 16.318 | AP32: 16.318
A33: Buses | B33: Low and zero emission coaches | C33: E85 | E33: AF | F33: 2010 | G33: TRA_Bus_Eth_Coa* | H33: =AVERAGE(I33:AS33) -> 66.756157 | I33: 90.5633 | J33: 137.92 | K33: 82.638 | L33: 61.8505 | M33: 27.1992 | N33: 55.6788 | O33: 43.6949 | P33: 50.4533 | Q33: 80.0755 | R33: 37.3013 | S33: 45.6949 | T33: 90.5633 | U33: 79.5897 | V33: 59.8584 | W33: 44.4871 | X33: 82.638 | Y33: 61.7817 | Z33: 54.3276 | AA33: 46.339 | AB33: 42.7829 | AC33: 82.638 | AD33: 15.8658 | AE33: 192.143 | AF33: 89.929 | AG33: 90.5633 | AH33: 21.8232 | AI33: 30.1527 | AJ33: 65.2606 | AK33: 63.8276 | AL33: 33.9756 | AM33: 37.7216 | AN33: 28.9507 | AO33: 82.638 | AP33: 110.72 | AQ33: 115.751 | AR33: 67.5264 | AS33: 65.0539
A34: Buses | B34: Low and zero emission coaches | C34: E85 | E34: AF | F34: 2020 | G34: TRA_Bus_Eth_Coa* | H34: =AVERAGE(I34:AS34) -> 66.756157 | I34: 90.5633 | J34: 137.92 | K34: 82.638 | L34: 61.8505 | M34: 27.1992 | N34: 55.6788 | O34: 43.6949 | P34: 50.4533 | Q34: 80.0755 | R34: 37.3013 | S34: 45.6949 | T34: 90.5633 | U34: 79.5897 | V34: 59.8584 | W34: 44.4871 | X34: 82.638 | Y34: 61.7817 | Z34: 54.3276 | AA34: 46.339 | AB34: 42.7829 | AC34: 82.638 | AD34: 15.8658 | AE34: 192.143 | AF34: 89.929 | AG34: 90.5633 | AH34: 21.8232 | AI34: 30.1527 | AJ34: 65.2606 | AK34: 63.8276 | AL34: 33.9756 | AM34: 37.7216 | AN34: 28.9507 | AO34: 82.638 | AP34: 110.72 | AQ34: 115.751 | AR34: 67.5264 | AS34: 65.0539
A35: Buses | B35: Low and zero emission coaches | C35: E85 | E35: AF | F35: 2025 | G35: TRA_Bus_Eth_Coa* | H35: =AVERAGE(I35:AS35) -> 66.756157 | I35: 90.5633 | J35: 137.92 | K35: 82.638 | L35: 61.8505 | M35: 27.1992 | N35: 55.6788 | O35: 43.6949 | P35: 50.4533 | Q35: 80.0755 | R35: 37.3013 | S35: 45.6949 | T35: 90.5633 | U35: 79.5897 | V35: 59.8584 | W35: 44.4871 | X35: 82.638 | Y35: 61.7817 | Z35: 54.3276 | AA35: 46.339 | AB35: 42.7829 | AC35: 82.638 | AD35: 15.8658 | AE35: 192.143 | AF35: 89.929 | AG35: 90.5633 | AH35: 21.8232 | AI35: 30.1527 | AJ35: 65.2606 | AK35: 63.8276 | AL35: 33.9756 | AM35: 37.7216 | AN35: 28.9507 | AO35: 82.638 | AP35: 110.72 | AQ35: 115.751 | AR35: 67.5264 | AS35: 65.0539
A36: Buses | B36: Low and zero emission coaches | C36: E85 | E36: AF | F36: 2030 | G36: TRA_Bus_Eth_Coa* | H36: =AVERAGE(I36:AS36) -> 66.756157 | I36: 90.5633 | J36: 137.92 | K36: 82.638 | L36: 61.8505 | M36: 27.1992 | N36: 55.6788 | O36: 43.6949 | P36: 50.4533 | Q36: 80.0755 | R36: 37.3013 | S36: 45.6949 | T36: 90.5633 | U36: 79.5897 | V36: 59.8584 | W36: 44.4871 | X36: 82.638 | Y36: 61.7817 | Z36: 54.3276 | AA36: 46.339 | AB36: 42.7829 | AC36: 82.638 | AD36: 15.8658 | AE36: 192.143 | AF36: 89.929 | AG36: 90.5633 | AH36: 21.8232 | AI36: 30.1527 | AJ36: 65.2606 | AK36: 63.8276 | AL36: 33.9756 | AM36: 37.7216 | AN36: 28.9507 | AO36: 82.638 | AP36: 110.72 | AQ36: 115.751 | AR36: 67.5264 | AS36: 65.0539
A37: Buses | B37: Low and zero emission coaches | C37: E85 | E37: AF | F37: 2035 | G37: TRA_Bus_Eth_Coa* | H37: =AVERAGE(I37:AS37) -> 66.756157 | I37: 90.5633 | J37: 137.92 | K37: 82.638 | L37: 61.8505 | M37: 27.1992 | N37: 55.6788 | O37: 43.6949 | P37: 50.4533 | Q37: 80.0755 | R37: 37.3013 | S37: 45.6949 | T37: 90.5633 | U37: 79.5897 | V37: 59.8584 | W37: 44.4871 | X37: 82.638 | Y37: 61.7817 | Z37: 54.3276 | AA37: 46.339 | AB37: 42.7829 | AC37: 82.638 | AD37: 15.8658 | AE37: 192.143 | AF37: 89.929 | AG37: 90.5633 | AH37: 21.8232 | AI37: 30.1527 | AJ37: 65.2606 | AK37: 63.8276 | AL37: 33.9756 | AM37: 37.7216 | AN37: 28.9507 | AO37: 82.638 | AP37: 110.72 | AQ37: 115.751 | AR37: 67.5264 | AS37: 65.0539
A38: Buses | B38: Low and zero emission coaches | C38: E85 | E38: AF | F38: 2040 | G38: TRA_Bus_Eth_Coa* | H38: =AVERAGE(I38:AS38) -> 66.756157 | I38: 90.5633 | J38: 137.92 | K38: 82.638 | L38: 61.8505 | M38: 27.1992 | N38: 55.6788 | O38: 43.6949 | P38: 50.4533 | Q38: 80.0755 | R38: 37.3013 | S38: 45.6949 | T38: 90.5633 | U38: 79.5897 | V38: 59.8584 | W38: 44.4871 | X38: 82.638 | Y38: 61.7817 | Z38: 54.3276 | AA38: 46.339 | AB38: 42.7829 | AC38: 82.638 | AD38: 15.8658 | AE38: 192.143 | AF38: 89.929 | AG38: 90.5633 | AH38: 21.8232 | AI38: 30.1527 | AJ38: 65.2606 | AK38: 63.8276 | AL38: 33.9756 | AM38: 37.7216 | AN38: 28.9507 | AO38: 82.638 | AP38: 110.72 | AQ38: 115.751 | AR38: 67.5264 | AS38: 65.0539
A39: Buses | B39: Low and zero emission coaches | C39: E85 | E39: AF | F39: 2050 | G39: TRA_Bus_Eth_Coa* | H39: =AVERAGE(I39:AS39) -> 66.756157 | I39: 90.5633 | J39: 137.92 | K39: 82.638 | L39: 61.8505 | M39: 27.1992 | N39: 55.6788 | O39: 43.6949 | P39: 50.4533 | Q39: 80.0755 | R39: 37.3013 | S39: 45.6949 | T39: 90.5633 | U39: 79.5897 | V39: 59.8584 | W39: 44.4871 | X39: 82.638 | Y39: 61.7817 | Z39: 54.3276 | AA39: 46.339 | AB39: 42.7829 | AC39: 82.638 | AD39: 15.8658 | AE39: 192.143 | AF39: 89.929 | AG39: 90.5633 | AH39: 21.8232 | AI39: 30.1527 | AJ39: 65.2606 | AK39: 63.8276 | AL39: 33.9756 | AM39: 37.7216 | AN39: 28.9507 | AO39: 82.638 | AP39: 110.72 | AQ39: 115.751 | AR39: 67.5264 | AS39: 65.0539
A40: Buses | B40: Low and zero emission coaches | C40: Hydrogen | E40: AF | F40: 2010 | G40: TRA_Bus_GH2_Coa* | H40: =AVERAGE(I40:AS40) -> 66.756157 | I40: 90.5633 | J40: 137.92 | K40: 82.638 | L40: 61.8505 | M40: 27.1992 | N40: 55.6788 | O40: 43.6949 | P40: 50.4533 | Q40: 80.0755 | R40: 37.3013 | S40: 45.6949 | T40: 90.5633 | U40: 79.5897 | V40: 59.8584 | W40: 44.4871 | X40: 82.638 | Y40: 61.7817 | Z40: 54.3276 | AA40: 46.339 | AB40: 42.7829 | AC40: 82.638 | AD40: 15.8658 | AE40: 192.143 | AF40: 89.929 | AG40: 90.5633 | AH40: 21.8232 | AI40: 30.1527 | AJ40: 65.2606 | AK40: 63.8276 | AL40: 33.9756 | AM40: 37.7216 | AN40: 28.9507 | AO40: 82.638 | AP40: 110.72 | AQ40: 115.751 | AR40: 67.5264 | AS40: 65.0539
A41: Buses | B41: Low and zero emission coaches | C41: Hydrogen | E41: AF | F41: 2020 | G41: TRA_Bus_GH2_Coa* | H41: =AVERAGE(I41:AS41) -> 66.756157 | I41: =I40 -> 90.5633 | J41: =J40 -> 137.92 | K41: =K40 -> 82.638 | L41: =L40 -> 61.8505 | M41: =M40 -> 27.1992 | N41: =N40 -> 55.6788 | O41: =O40 -> 43.6949 | P41: =P40 -> 50.4533 | ... AS41: =AS40 -> 65.0539
...

Sheet INS_FLO
A1: Occupancy (p/vehicle or t/vehicle)
C3: ~TFM_INS
C4: Attribute | D4: PSET_PN | E4: Other_Indexes | F4: AllRegions | G4: =RdTRABYVals!M$1 -> AT | H4: =RdTRABYVals!O$1 -> BE | I4: =RdTRABYVals!P$1 -> BG | J4: =RdTRABYVals!Q$1 -> CH | K4: =RdTRABYVals!R$1 -> CY | L4: =RdTRABYVals!S$1 -> CZ | M4: =RdTRABYVals!T$1 -> DE | N4: =RdTRABYVals!U$1 -> DK | O4: =RdTRABYVals!V$1 -> EE | P4: =RdTRABYVals!X$1 -> ES | Q4: =RdTRABYVals!Y$1 -> FI | R4: =RdTRABYVals!Z$1 -> FR | S4: =RdTRABYVals!W$1 -> EL | T4: =RdTRABYVals!AA$1 -> HR | U4: =RdTRABYVals!AB$1 -> HU | V4: =RdTRABYVals!AC$1 -> IE | W4: =RdTRABYVals!AD$1 -> IS | X4: =RdTRABYVals!AE$1 -> IT | Y4: =RdTRABYVals!AG$1 -> LT | Z4: =RdTRABYVals!AH$1 -> LU | AA4: =RdTRABYVals!AI$1 -> LV | AB4: =RdTRABYVals!AK$1 -> MK | AC4: =RdTRABYVals!AL$1 -> MT | AD4: =RdTRABYVals!AM$1 -> NL | AE4: =RdTRABYVals!AN$1 -> NO | AF4: =RdTRABYVals!AO$1 -> PL | AG4: =RdTRABYVals!AP$1 -> PT | AH4: =RdTRABYVals!AQ$1 -> RO | AI4: =RdTRABYVals!AS$1 -> SE | AJ4: =RdTRABYVals!AT$1 -> SI | AK4: =RdTRABYVals!AU$1 -> SK | AL4: =RdTRABYVals!AV$1 -> UK | AM4: =RdTRABYVals!L$1 -> AL | AN4: =RdTRABYVals!N$1 -> BA | AO4: =RdTRABYVals!AJ$1 -> ME | AP4: =RdTRABYVals!AR$1 -> RS | AQ4: =RdTRABYVals!AF$1 -> KS
A5: TRA_Bus* | C5: ACTFLO | D5: =A5 -> TRA_Bus* | E5: DEMO | F5: =AVERAGE(G5:AL5) -> 20.686068 | G5: =IFERROR(AVERAGEIFS(RdTRABYVals!M$2:M$999,RdTRABYVals!$B$2:$B$999,"="&$C5,RdTRABYVals!$C$2:$C$999,"="&INS_FLO!$A5),"") -> 18.844231 | H5: =IFERROR(AVERAGEIFS(RdTRABYVals!O$2:O$999,RdTRABYVals!$B$2:$B$999,"="&$C5,RdTRABYVals!$C$2:$C$999,"="&INS_FLO!$A5),"") -> 32.854839 | I5: =IFERROR(AVERAGEIFS(RdTRABYVals!P$2:P$999,RdTRABYVals!$B$2:$B$999,"="&$C5,RdTRABYVals!$C$2:$C$999,"="&INS_FLO!$A5),"") -> 19.464134 | J5: =IFERROR(AVERAGEIFS(RdTRABYVals!Q$2:Q$999,RdTRABYVals!$B$2:$B$999,"="&$C5,RdTRABYVals!$C$2:$C$999,"="&INS_FLO!$A5),"") -> 22.708029 | K5: =IFERROR(AVERAGEIFS(RdTRABYVals!R$2:R$999,RdTRABYVals!$B$2:$B$999,"="&$C5,RdTRABYVals!$C$2:$C$999,"="&INS_FLO!$A5),"") -> 9.6167755 | L5: =IFERROR(AVERAGEIFS(RdTRABYVals!S$2:S$999,RdTRABYVals!$B$2:$B$999,"="&$C5,RdTRABYVals!$C$2:$C$999,"="&INS_FLO!$A5),"") -> 24.425665 | M5: =IFERROR(AVERAGEIFS(RdTRABYVals!T$2:T$999,RdTRABYVals!$B$2:$B$999,"="&$C5,RdTRABYVals!$C$2:$C$999,"="&INS_FLO!$A5),"") -> 20.808901 | N5: =IFERROR(AVERAGEIFS(RdTRABYVals!U$2:U$999,RdTRABYVals!$B$2:$B$999,"="&$C5,RdTRABYVals!$C$2:$C$999,"="&INS_FLO!$A5),"") -> 12 | O5: =IFERROR(AVERAGEIFS(RdTRABYVals!V$2:V$999,RdTRABYVals!$B$2:$B$999,"="&$C5,RdTRABYVals!$C$2:$C$999,"="&INS_FLO!$A5),"") -> 11.532486 | P5: =IFERROR(AVERAGEIFS(RdTRABYVals!X$2:X$999,RdTRABYVals!$B$2:$B$999,"="&$C5,RdTRABYVals!$C$2:$C$999,"="&INS_FLO!$A5),"") -> 24.299999 | Q5: =IFERROR(AVERAGEIFS(RdTRABYVals!Y$2:Y$999,RdTRABYVals!$B$2:$B$999,"="&$C5,RdTRABYVals!$C$2:$C$999,"="&INS_FLO!$A5),"") -> 13 | R5: =IFERROR(AVERAGEIFS(RdTRABYVals!Z$2:Z$999,RdTRABYVals!$B$2:$B$999,"="&$C5,RdTRABYVals!$C$2:$C$999,"="&INS_FLO!$A5),"") -> 17.698154 | S5: =IFERROR(AVERAGEIFS(RdTRABYVals!W$2:W$999,RdTRABYVals!$B$2:$B$999,"="&$C5,RdTRABYVals!$C$2:$C$999,"="&INS_FLO!$A5),"") -> 27.25 | T5: =IFERROR(AVERAGEIFS(RdTRABYVals!AA$2:AA$999,RdTRABYVals!$B$2:$B$999,"="&$C5,RdTRABYVals!$C$2:$C$999,"="&INS_FLO!$A5),"") -> 8.8645163 | U5: =IFERROR(AVERAGEIFS(RdTRABYVals!AB$2:AB$999,RdTRABYVals!$B$2:$B$999,"="&$C5,RdTRABYVals!$C$2:$C$999,"="&INS_FLO!$A5),"") -> 30 | V5: =IFERROR(AVERAGEIFS(RdTRABYVals!AC$2:AC$999,RdTRABYVals!$B$2:$B$999,"="&$C5,RdTRABYVals!$C$2:$C$999,"="&INS_FLO!$A5),"") -> 27.25 | W5: =IFERROR(AVERAGEIFS(RdTRABYVals!AD$2:AD$999,RdTRABYVals!$B$2:$B$999,"="&$C5,RdTRABYVals!$C$2:$C$999,"="&INS_FLO!$A5),"") -> 9.6172838 | X5: =IFERROR(AVERAGEIFS(RdTRABYVals!AE$2:AE$999,RdTRABYVals!$B$2:$B$999,"="&$C5,RdTRABYVals!$C$2:$C$999,"="&INS_FLO!$A5),"") -> 18 | Y5: =IFERROR(AVERAGEIFS(RdTRABYVals!AG$2:AG$999,RdTRABYVals!$B$2:$B$999,"="&$C5,RdTRABYVals!$C$2:$C$999,"="&INS_FLO!$A5),"") -> 31.747139 | Z5: =IFERROR(AVERAGEIFS(RdTRABYVals!AH$2:AH$999,RdTRABYVals!$B$2:$B$999,"="&$C5,RdTRABYVals!$C$2:$C$999,"="&INS_FLO!$A5),"") -> 32.854839 | AA5: =IFERROR(AVERAGEIFS(RdTRABYVals!AI$2:AI$999,RdTRABYVals!$B$2:$B$999,"="&$C5,RdTRABYVals!$C$2:$C$999,"="&INS_FLO!$A5),"") -> 12 | AB5: =IFERROR(AVERAGEIFS(RdTRABYVals!AK$2:AK$999,RdTRABYVals!$B$2:$B$999,"="&$C5,RdTRABYVals!$C$2:$C$999,"="&INS_FLO!$A5),"") -> 35.676472 | AC5: =IFERROR(AVERAGEIFS(RdTRABYVals!AL$2:AL$999,RdTRABYVals!$B$2:$B$999,"="&$C5,RdTRABYVals!$C$2:$C$999,"="&INS_FLO!$A5),"") -> 32.854839 | AD5: =IFERROR(AVERAGEIFS(RdTRABYVals!AM$2:AM$999,RdTRABYVals!$B$2:$B$999,"="&$C5,RdTRABYVals!$C$2:$C$999,"="&INS_FLO!$A5),"") -> 32.854839 | AE5: =IFERROR(AVERAGEIFS(RdTRABYVals!AN$2:AN$999,RdTRABYVals!$B$2:$B$999,"="&$C5,RdTRABYVals!$C$2:$C$999,"="&INS_FLO!$A5),"") -> 12.944118 | AF5: =IFERROR(AVERAGEIFS(RdTRABYVals!AO$2:AO$999,RdTRABYVals!$B$2:$B$999,"="&$C5,RdTRABYVals!$C$2:$C$999,"="&INS_FLO!$A5),"") -> 9.9356022 | AG5: =IFERROR(AVERAGEIFS(RdTRABYVals!AP$2:AP$999,RdTRABYVals!$B$2:$B$999,"="&$C5,RdTRABYVals!$C$2:$C$999,"="&INS_FLO!$A5),"") -> 27.800829 | AH5: =IFERROR(AVERAGEIFS(RdTRABYVals!AQ$2:AQ$999,RdTRABYVals!$B$2:$B$999,"="&$C5,RdTRABYVals!$C$2:$C$999,"="&INS_FLO!$A5),"") -> 19.464134 | AI5: =IFERROR(AVERAGEIFS(RdTRABYVals!AS$2:AS$999,RdTRABYVals!$B$2:$B$999,"="&$C5,RdTRABYVals!$C$2:$C$999,"="&INS_FLO!$A5),"") -> 9.5039015 | AJ5: =IFERROR(AVERAGEIFS(RdTRABYVals!AT$2:AT$999,RdTRABYVals!$B$2:$B$999,"="&$C5,RdTRABYVals!$C$2:$C$999,"="&INS_FLO!$A5),"") -> 21.951725 | AK5: =IFERROR(AVERAGEIFS(RdTRABYVals!AU$2:AU$999,RdTRABYVals!$B$2:$B$999,"="&$C5,RdTRABYVals!$C$2:$C$999,"="&INS_FLO!$A5),"") -> 17.130739 | AL5: =IFERROR(AVERAGEIFS(RdTRABYVals!AV$2:AV$999,RdTRABYVals!$B$2:$B$999,"="&$C5,RdTRABYVals!$C$2:$C$999,"="&INS_FLO!$A5),"") -> 17 | AM5: =IFERROR(AVERAGEIFS(RdTRABYVals!L$2:L$999,RdTRABYVals!$B$2:$B$999,"="&$C5,RdTRABYVals!$C$2:$C$999,"="&INS_FLO!$A5),"") -> 27.25 | AN5: =IFERROR(AVERAGEIFS(RdTRABYVals!N$2:N$999,RdTRABYVals!$B$2:$B$999,"="&$C5,RdTRABYVals!$C$2:$C$999,"="&INS_FLO!$A5),"") -> 8.8645163 | AO5: =IFERROR(AVERAGEIFS(RdTRABYVals!AJ$2:AJ$999,RdTRABYVals!$B$2:$B$999,"="&$C5,RdTRABYVals!$C$2:$C$999,"="&INS_FLO!$A5),"") -> 27.25 | AP5: =IFERROR(AVERAGEIFS(RdTRABYVals!AR$2:AR$999,RdTRABYVals!$B$2:$B$999,"="&$C5,RdTRABYVals!$C$2:$C$999,"="&INS_FLO!$A5),"") -> 8.8645163 | AQ5: =IFERROR(AVERAGEIFS(RdTRABYVals!AF$2:AF$999,RdTRABYVals!$B$2:$B$999,"="&$C5,RdTRABYVals!$C$2:$C$999,"="&INS_FLO!$A5),"") -> 8.8645163
A6: TRA_Car* | C6: ACTFLO | D6: =A6 -> TRA_Car* | E6: DEMO | F6: =AVERAGE(G6:AL6) -> 1.6016996 | G6: =IFERROR(AVERAGEIFS(RdTRABYVals!M$2:M$999,RdTRABYVals!$B$2:$B$999,"="&$C6,RdTRABYVals!$C$2:$C$999,"="&INS_FLO!$A6),"") -> 1.1799999 | H6: =IFERROR(AVERAGEIFS(RdTRABYVals!O$2:O$999,RdTRABYVals!$B$2:$B$999,"="&$C6,RdTRABYVals!$C$2:$C$999,"="&INS_FLO!$A6),"") -> 1.5102819 | I6: =IFERROR(AVERAGEIFS(RdTRABYVals!P$2:P$999,RdTRABYVals!$B$2:$B$999,"="&$C6,RdTRABYVals!$C$2:$C$999,"="&INS_FLO!$A6),"") -> 1.5599999 | J6: =IFERROR(AVERAGEIFS(RdTRABYVals!Q$2:Q$999,RdTRABYVals!$B$2:$B$999,"="&$C6,RdTRABYVals!$C$2:$C$999,"="&INS_FLO!$A6),"") -> 1.6065165 | K6: =IFERROR(AVERAGEIFS(RdTRABYVals!R$2:R$999,RdTRABYVals!$B$2:$B$999,"="&$C6,RdTRABYVals!$C$2:$C$999,"="&INS_FLO!$A6),"") -> 1.4644458 | L6: =IFERROR(AVERAGEIFS(RdTRABYVals!S$2:S$999,RdTRABYVals!$B$2:$B$999,"="&$C6,RdTRABYVals!$C$2:$C$999,"="&INS_FLO!$A6),"") -> 1.38 | M6: =IFERROR(AVERAGEIFS(RdTRABYVals!T$2:T$999,RdTRABYVals!$B$2:$B$999,"="&$C6,RdTRABYVals!$C$2:$C$999,"="&INS_FLO!$A6),"") -> 1.4904687 | N6: =IFERROR(AVERAGEIFS(RdTRABYVals!U$2:U$999,RdTRABYVals!$B$2:$B$999,"="&$C6,RdTRABYVals!$C$2:$C$999,"="&INS_FLO!$A6),"") -> 1.5599999 | O6: =IFERROR(AVERAGEIFS(RdTRABYVals!V$2:V$999,RdTRABYVals!$B$2:$B$999,"="&$C6,RdTRABYVals!$C$2:$C$999,"="&INS_FLO!$A6),"") -> 1.45 | P6: =IFERROR(AVERAGEIFS(RdTRABYVals!X$2:X$999,RdTRABYVals!$B$2:$B$999,"="&$C6,RdTRABYVals!$C$2:$C$999,"="&INS_FLO!$A6),"") -> 1.74 | Q6: =IFERROR(AVERAGEIFS(RdTRABYVals!Y$2:Y$999,RdTRABYVals!$B$2:$B$999,"="&$C6,RdTRABYVals!$C$2:$C$999,"="&INS_FLO!$A6),"") -> 1.4000432 | R6: =IFERROR(AVERAGEIFS(RdTRABYVals!Z$2:Z$999,RdTRABYVals!$B$2:$B$999,"="&$C6,RdTRABYVals!$C$2:$C$999,"="&INS_FLO!$A6),"") -> 1.8285844 | S6: =IFERROR(AVERAGEIFS(RdTRABYVals!W$2:W$999,RdTRABYVals!$B$2:$B$999,"="&$C6,RdTRABYVals!$C$2:$C$999,"="&INS_FLO!$A6),"") -> 1.4975108 | T6: =IFERROR(AVERAGEIFS(RdTRABYVals!AA$2:AA$999,RdTRABYVals!$B$2:$B$999,"="&$C6,RdTRABYVals!$C$2:$C$999,"="&INS_FLO!$A6),"") -> 1.3824637 | U6: =IFERROR(AVERAGEIFS(RdTRABYVals!AB$2:AB$999,RdTRABYVals!$B$2:$B$999,"="&$C6,RdTRABYVals!$C$2:$C$999,"="&INS_FLO!$A6),"") -> 1.84 | V6: =IFERROR(AVERAGEIFS(RdTRABYVals!AC$2:AC$999,RdTRABYVals!$B$2:$B$999,"="&$C6,RdTRABYVals!$C$2:$C$999,"="&INS_FLO!$A6),"") -> 1.4975108 | W6: =IFERROR(AVERAGEIFS(RdTRABYVals!AD$2:AD$999,RdTRABYVals!$B$2:$B$999,"="&$C6,RdTRABYVals!$C$2:$C$999,"="&INS_FLO!$A6),"") -> 2.0627906 | X6: =IFERROR(AVERAGEIFS(RdTRABYVals!AE$2:AE$999,RdTRABYVals!$B$2:$B$999,"="&$C6,RdTRABYVals!$C$2:$C$999,"="&INS_FLO!$A6),"") -> 1.71 | Y6: =IFERROR(AVERAGEIFS(RdTRABYVals!AG$2:AG$999,RdTRABYVals!$B$2:$B$999,"="&$C6,RdTRABYVals!$C$2:$C$999,"="&INS_FLO!$A6),"") -> 1.9999866 | Z6: =IFERROR(AVERAGEIFS(RdTRABYVals!AH$2:AH$999,RdTRABYVals!$B$2:$B$999,"="&$C6,RdTRABYVals!$C$2:$C$999,"="&INS_FLO!$A6),"") -> 1.5102819 | AA6: =IFERROR(AVERAGEIFS(RdTRABYVals!AI$2:AI$999,RdTRABYVals!$B$2:$B$999,"="&$C6,RdTRABYVals!$C$2:$C$999,"="&INS_FLO!$A6),"") -> 1.4330004 | AB6: =IFERROR(AVERAGEIFS(RdTRABYVals!AK$2:AK$999,RdTRABYVals!$B$2:$B$999,"="&$C6,RdTRABYVals!$C$2:$C$999,"="&INS_FLO!$A6),"") -> 1.5599999 | AC6: =IFERROR(AVERAGEIFS(RdTRABYVals!AL$2:AL$999,RdTRABYVals!$B$2:$B$999,"="&$C6,RdTRABYVals!$C$2:$C$999,"="&INS_FLO!$A6),"") -> 1.5102819 | AD6: =IFERROR(AVERAGEIFS(RdTRABYVals!AM$2:AM$999,RdTRABYVals!$B$2:$B$999,"="&$C6,RdTRABYVals!$C$2:$C$999,"="&INS_FLO!$A6),"") -> 1.33 | AE6: =IFERROR(AVERAGEIFS(RdTRABYVals!AN$2:AN$999,RdTRABYVals!$B$2:$B$999,"="&$C6,RdTRABYVals!$C$2:$C$999,"="&INS_FLO!$A6),"") -> 1.7 | AF6: =IFERROR(AVERAGEIFS(RdTRABYVals!AO$2:AO$999,RdTRABYVals!$B$2:$B$999,"="&$C6,RdTRABYVals!$C$2:$C$999,"="&INS_FLO!$A6),"") -> 1.9665447 | AG6: =IFERROR(AVERAGEIFS(RdTRABYVals!AP$2:AP$999,RdTRABYVals!$B$2:$B$999,"="&$C6,RdTRABYVals!$C$2:$C$999,"="&INS_FLO!$A6),"") -> 1.4975108 | AH6: =IFERROR(AVERAGEIFS(RdTRABYVals!AQ$2:AQ$999,RdTRABYVals!$B$2:$B$999,"="&$C6,RdTRABYVals!$C$2:$C$999,"="&INS_FLO!$A6),"") -> 1.9828243 | AI6: =IFERROR(AVERAGEIFS(RdTRABYVals!AS$2:AS$999,RdTRABYVals!$B$2:$B$999,"="&$C6,RdTRABYVals!$C$2:$C$999,"="&INS_FLO!$A6),"") -> 1.4534742 | AJ6: =IFERROR(AVERAGEIFS(RdTRABYVals!AT$2:AT$999,RdTRABYVals!$B$2:$B$999,"="&$C6,RdTRABYVals!$C$2:$C$999,"="&INS_FLO!$A6),"") -> 1.6398644 | AK6: =IFERROR(AVERAGEIFS(RdTRABYVals!AU$2:AU$999,RdTRABYVals!$B$2:$B$999,"="&$C6,RdTRABYVals!$C$2:$C$999,"="&INS_FLO!$A6),"") -> 1.95 | AL6: =IFERROR(AVERAGEIFS(RdTRABYVals!AV$2:AV$999,RdTRABYVals!$B$2:$B$999,"="&$C6,RdTRABYVals!$C$2:$C$999,"="&INS_FLO!$A6),"") -> 1.5599999 | AM6: =IFERROR(AVERAGEIFS(RdTRABYVals!L$2:L$999,RdTRABYVals!$B$2:$B$999,"="&$C6,RdTRABYVals!$C$2:$C$999,"="&INS_FLO!$A6),"") -> 1.4975108 | AN6: =IFERROR(AVERAGEIFS(RdTRABYVals!N$2:N$999,RdTRABYVals!$B$2:$B$999,"="&$C6,RdTRABYVals!$C$2:$C$999,"="&INS_FLO!$A6),"") -> 1.3824637 | AO6: =IFERROR(AVERAGEIFS(RdTRABYVals!AJ$2:AJ$999,RdTRABYVals!$B$2:$B$999,"="&$C6,RdTRABYVals!$C$2:$C$999,"="&INS_FLO!$A6),"") -> 1.4975108 | AP6: =IFERROR(AVERAGEIFS(RdTRABYVals!AR$2:AR$999,RdTRABYVals!$B$2:$B$999,"="&$C6,RdTRABYVals!$C$2:$C$999,"="&INS_FLO!$A6),"") -> 1.3824637 | AQ6: =IFERROR(AVERAGEIFS(RdTRABYVals!AF$2:AF$999,RdTRABYVals!$B$2:$B$999,"="&$C6,RdTRABYVals!$C$2:$C$999,"="&INS_FLO!$A6),"") -> 1.3824637
A7: TRA_Hdt_Dis* | C7: ACTFLO | D7: =A7 -> TRA_Hdt_Dis* | E7: DEMO | F7: =AVERAGE(G7:AL7) -> 9.134747 | G7: =IFERROR(AVERAGEIFS(RdTRABYVals!M$2:M$999,RdTRABYVals!$B$2:$B$999,"="&$C7,RdTRABYVals!$C$2:$C$999,"="&INS_FLO!$A7),"") -> 12.696687 | H7: =IFERROR(AVERAGEIFS(RdTRABYVals!O$2:O$999,RdTRABYVals!$B$2:$B$999,"="&$C7,RdTRABYVals!$C$2:$C$999,"="&INS_FLO!$A7),"") -> 3.6177164 | I7: =IFERROR(AVERAGEIFS(RdTRABYVals!P$2:P$999,RdTRABYVals!$B$2:$B$999,"="&$C7,RdTRABYVals!$C$2:$C$999,"="&INS_FLO!$A7),"") -> 14.902222 | J7: =IFERROR(AVERAGEIFS(RdTRABYVals!Q$2:Q$999,RdTRABYVals!$B$2:$B$999,"="&$C7,RdTRABYVals!$C$2:$C$999,"="&INS_FLO!$A7),"") -> 5.0234684 | K7: =IFERROR(AVERAGEIFS(RdTRABYVals!R$2:R$999,RdTRABYVals!$B$2:$B$999,"="&$C7,RdTRABYVals!$C$2:$C$999,"="&INS_FLO!$A7),"") -> 4.0249714 | L7: =IFERROR(AVERAGEIFS(RdTRABYVals!S$2:S$999,RdTRABYVals!$B$2:$B$999,"="&$C7,RdTRABYVals!$C$2:$C$999,"="&INS_FLO!$A7),"") -> 9.7457024 | M7: =IFERROR(AVERAGEIFS(RdTRABYVals!T$2:T$999,RdTRABYVals!$B$2:$B$999,"="&$C7,RdTRABYVals!$C$2:$C$999,"="&INS_FLO!$A7),"") -> 6.2939784 | N7: =IFERROR(AVERAGEIFS(RdTRABYVals!U$2:U$999,RdTRABYVals!$B$2:$B$999,"="&$C7,RdTRABYVals!$C$2:$C$999,"="&INS_FLO!$A7),"") -> 5.7247237 | O7: =IFERROR(AVERAGEIFS(RdTRABYVals!V$2:V$999,RdTRABYVals!$B$2:$B$999,"="&$C7,RdTRABYVals!$C$2:$C$999,"="&INS_FLO!$A7),"") -> 10.897256 | P7: =IFERROR(AVERAGEIFS(RdTRABYVals!X$2:X$999,RdTRABYVals!$B$2:$B$999,"="&$C7,RdTRABYVals!$C$2:$C$999,"="&INS_FLO!$A7),"") -> 6.2476243 | Q7: 16.5 | R7: =IFERROR(AVERAGEIFS(RdTRABYVals!Z$2:Z$999,RdTRABYVals!$B$2:$B$999,"="&$C7,RdTRABYVals!$C$2:$C$999,"="&INS_FLO!$A7),"") -> 8.2550465 | S7: =IFERROR(AVERAGEIFS(RdTRABYVals!W$2:W$999,RdTRABYVals!$B$2:$B$999,"="&$C7,RdTRABYVals!$C$2:$C$999,"="&INS_FLO!$A7),"") -> 6.473203 | T7: =IFERROR(AVERAGEIFS(RdTRABYVals!AA$2:AA$999,RdTRABYVals!$B$2:$B$999,"="&$C7,RdTRABYVals!$C$2:$C$999,"="&INS_FLO!$A7),"") -> 10.154531 | U7: =IFERROR(AVERAGEIFS(RdTRABYVals!AB$2:AB$999,RdTRABYVals!$B$2:$B$999,"="&$C7,RdTRABYVals!$C$2:$C$999,"="&INS_FLO!$A7),"") -> 9.9489386 | V7: =IFERROR(AVERAGEIFS(RdTRABYVals!AC$2:AC$999,RdTRABYVals!$B$2:$B$999,"="&$C7,RdTRABYVals!$C$2:$C$999,"="&INS_FLO!$A7),"") -> 11.993946 | W7: =IFERROR(AVERAGEIFS(RdTRABYVals!AD$2:AD$999,RdTRABYVals!$B$2:$B$999,"="&$C7,RdTRABYVals!$C$2:$C$999,"="&INS_FLO!$A7),"") -> 7.0785648 | X7: =IFERROR(AVERAGEIFS(RdTRABYVals!AE$2:AE$999,RdTRABYVals!$B$2:$B$999,"="&$C7,RdTRABYVals!$C$2:$C$999,"="&INS_FLO!$A7),"") -> 7.5022434 | Y7: =IFERROR(AVERAGEIFS(RdTRABYVals!AG$2:AG$999,RdTRABYVals!$B$2:$B$999,"="&$C7,RdTRABYVals!$C$2:$C$999,"="&INS_FLO!$A7),"") -> 13.305332 | Z7: =IFERROR(AVERAGEIFS(RdTRABYVals!AH$2:AH$999,RdTRABYVals!$B$2:$B$999,"="&$C7,RdTRABYVals!$C$2:$C$999,"="&INS_FLO!$A7),"") -> 5.2429919 | AA7: =IFERROR(AVERAGEIFS(RdTRABYVals!AI$2:AI$999,RdTRABYVals!$B$2:$B$999,"="&$C7,RdTRABYVals!$C$2:$C$999,"="&INS_FLO!$A7),"") -> 10.474089 | AB7: =IFERROR(AVERAGEIFS(RdTRABYVals!AK$2:AK$999,RdTRABYVals!$B$2:$B$999,"="&$C7,RdTRABYVals!$C$2:$C$999,"="&INS_FLO!$A7),"") -> 12.002561 | AC7: =IFERROR(AVERAGEIFS(RdTRABYVals!AL$2:AL$999,RdTRABYVals!$B$2:$B$999,"="&$C7,RdTRABYVals!$C$2:$C$999,"="&INS_FLO!$A7),"") -> 1.204711 | AD7: =IFERROR(AVERAGEIFS(RdTRABYVals!AM$2:AM$999,RdTRABYVals!$B$2:$B$999,"="&$C7,RdTRABYVals!$C$2:$C$999,"="&INS_FLO!$A7),"") -> 11.101495 | AE7: =IFERROR(AVERAGEIFS(RdTRABYVals!AN$2:AN$999,RdTRABYVals!$B$2:$B$999,"="&$C7,RdTRABYVals!$C$2:$C$999,"="&INS_FLO!$A7),"") -> 12.591807 | AF7: =IFERROR(AVERAGEIFS(RdTRABYVals!AO$2:AO$999,RdTRABYVals!$B$2:$B$999,"="&$C7,RdTRABYVals!$C$2:$C$999,"="&INS_FLO!$A7),"") -> 11.666597 | AG7: =IFERROR(AVERAGEIFS(RdTRABYVals!AP$2:AP$999,RdTRABYVals!$B$2:$B$999,"="&$C7,RdTRABYVals!$C$2:$C$999,"="&INS_FLO!$A7),"") -> 13.56664 | AH7: =IFERROR(AVERAGEIFS(RdTRABYVals!AQ$2:AQ$999,RdTRABYVals!$B$2:$B$999,"="&$C7,RdTRABYVals!$C$2:$C$999,"="&INS_FLO!$A7),"") -> 5.6829781 | AI7: =IFERROR(AVERAGEIFS(RdTRABYVals!AS$2:AS$999,RdTRABYVals!$B$2:$B$999,"="&$C7,RdTRABYVals!$C$2:$C$999,"="&INS_FLO!$A7),"") -> 12.879972 | AJ7: =IFERROR(AVERAGEIFS(RdTRABYVals!AT$2:AT$999,RdTRABYVals!$B$2:$B$999,"="&$C7,RdTRABYVals!$C$2:$C$999,"="&INS_FLO!$A7),"") -> 11.184903 | AK7: =IFERROR(AVERAGEIFS(RdTRABYVals!AU$2:AU$999,RdTRABYVals!$B$2:$B$999,"="&$C7,RdTRABYVals!$C$2:$C$999,"="&INS_FLO!$A7),"") -> 8.0361799 | AL7: =IFERROR(AVERAGEIFS(RdTRABYVals!AV$2:AV$999,RdTRABYVals!$B$2:$B$999,"="&$C7,RdTRABYVals!$C$2:$C$999,"="&INS_FLO!$A7),"") -> 6.2908245 | AM7: =IFERROR(AVERAGEIFS(RdTRABYVals!L$2:L$999,RdTRABYVals!$B$2:$B$999,"="&$C7,RdTRABYVals!$C$2:$C$999,"="&INS_FLO!$A7),"") -> 6.473203 | AN7: =IFERROR(AVERAGEIFS(RdTRABYVals!N$2:N$999,RdTRABYVals!$B$2:$B$999,"="&$C7,RdTRABYVals!$C$2:$C$999,"="&INS_FLO!$A7),"") -> 10.154531 | AO7: =IFERROR(AVERAGEIFS(RdTRABYVals!AJ$2:AJ$999,RdTRABYVals!$B$2:$B$999,"="&$C7,RdTRABYVals!$C$2:$C$999,"="&INS_FLO!$A7),"") -> 6.473203 | AP7: =IFERROR(AVERAGEIFS(RdTRABYVals!AR$2:AR$999,RdTRABYVals!$B$2:$B$999,"="&$C7,RdTRABYVals!$C$2:$C$999,"="&INS_FLO!$A7),"") -> 10.154531 | AQ7: =IFERROR(AVERAGEIFS(RdTRABYVals!AF$2:AF$999,RdTRABYVals!$B$2:$B$999,"="&$C7,RdTRABYVals!$C$2:$C$999,"="&INS_FLO!$A7),"") -> 10.154531
A8: TRA_Hdt_Gas* | C8: ACTFLO | D8: =A8 -> TRA_Hdt_Gas* | E8: DEMO | F8: =AVERAGE(G8:AL8) -> 1.8364432 | G8: 1.8364432 | H8: 1.8364432 | I8: =IFERROR(AVERAGEIFS(RdTRABYVals!P$2:P$999,RdTRABYVals!$B$2:$B$999,"="&$C8,RdTRABYVals!$C$2:$C$999,"="&INS_FLO!$A8),"") -> 2.4181894 | J8: 1.8364432 | K8: =IFERROR(AVERAGEIFS(RdTRABYVals!R$2:R$999,RdTRABYVals!$B$2:$B$999,"="&$C8,RdTRABYVals!$C$2:$C$999,"="&INS_FLO!$A8),"") -> 0.97858094 | L8: =IFERROR(AVERAGEIFS(RdTRABYVals!S$2:S$999,RdTRABYVals!$B$2:$B$999,"="&$C8,RdTRABYVals!$C$2:$C$999,"="&INS_FLO!$A8),"") -> 1.6805943 | M8: 1.8364432 | N8: =IFERROR(AVERAGEIFS(RdTRABYVals!U$2:U$999,RdTRABYVals!$B$2:$B$999,"="&$C8,RdTRABYVals!$C$2:$C$999,"="&INS_FLO!$A8),"") -> 0.71403724 | O8: =IFERROR(AVERAGEIFS(RdTRABYVals!V$2:V$999,RdTRABYVals!$B$2:$B$999,"="&$C8,RdTRABYVals!$C$2:$C$999,"="&INS_FLO!$A8),"") -> 2.0055233 | P8: =IFERROR(AVERAGEIFS(RdTRABYVals!X$2:X$999,RdTRABYVals!$B$2:$B$999,"="&$C8,RdTRABYVals!$C$2:$C$999,"="&INS_FLO!$A8),"") -> 0.89578973 | Q8: =IFERROR(AVERAGEIFS(RdTRABYVals!Y$2:Y$999,RdTRABYVals!$B$2:$B$999,"="&$C8,RdTRABYVals!$C$2:$C$999,"="&INS_FLO!$A8),"") -> 1.6817709 | R8: =IFERROR(AVERAGEIFS(RdTRABYVals!Z$2:Z$999,RdTRABYVals!$B$2:$B$999,"="&$C8,RdTRABYVals!$C$2:$C$999,"="&INS_FLO!$A8),"") -> 1.080112 | S8: =IFERROR(AVERAGEIFS(RdTRABYVals!W$2:W$999,RdTRABYVals!$B$2:$B$999,"="&$C8,RdTRABYVals!$C$2:$C$999,"="&INS_FLO!$A8),"") -> 1.5272753 | T8: =IFERROR(AVERAGEIFS(RdTRABYVals!AA$2:AA$999,RdTRABYVals!$B$2:$B$999,"="&$C8,RdTRABYVals!$C$2:$C$999,"="&INS_FLO!$A8),"") -> 2.786757 | U8: =IFERROR(AVERAGEIFS(RdTRABYVals!AB$2:AB$999,RdTRABYVals!$B$2:$B$999,"="&$C8,RdTRABYVals!$C$2:$C$999,"="&INS_FLO!$A8),"") -> 1.7156413 | V8: =IFERROR(AVERAGEIFS(RdTRABYVals!AC$2:AC$999,RdTRABYVals!$B$2:$B$999,"="&$C8,RdTRABYVals!$C$2:$C$999,"="&INS_FLO!$A8),"") -> 4.5393498 | W8: =IFERROR(AVERAGEIFS(RdTRABYVals!AD$2:AD$999,RdTRABYVals!$B$2:$B$999,"="&$C8,RdTRABYVals!$C$2:$C$999,"="&INS_FLO!$A8),"") -> 1.3488346 | X8: =IFERROR(AVERAGEIFS(RdTRABYVals!AE$2:AE$999,RdTRABYVals!$B$2:$B$999,"="&$C8,RdTRABYVals!$C$2:$C$999,"="&INS_FLO!$A8),"") -> 1.3574516 | Y8: =IFERROR(AVERAGEIFS(RdTRABYVals!AG$2:AG$999,RdTRABYVals!$B$2:$B$999,"="&$C8,RdTRABYVals!$C$2:$C$999,"="&INS_FLO!$A8),"") -> 3.31235 | Z8: =IFERROR(AVERAGEIFS(RdTRABYVals!AH$2:AH$999,RdTRABYVals!$B$2:$B$999,"="&$C8,RdTRABYVals!$C$2:$C$999,"="&INS_FLO!$A8),"") -> 0.85835563 | AA8: =IFERROR(AVERAGEIFS(RdTRABYVals!AI$2:AI$999,RdTRABYVals!$B$2:$B$999,"="&$C8,RdTRABYVals!$C$2:$C$999,"="&INS_FLO!$A8),"") -> 1.9958585 | AB8: =IFERROR(AVERAGEIFS(RdTRABYVals!AK$2:AK$999,RdTRABYVals!$B$2:$B$999,"="&$C8,RdTRABYVals!$C$2:$C$999,"="&INS_FLO!$A8),"") -> 1.9476603 | AC8: 1.8364432 | AD8: =IFERROR(AVERAGEIFS(RdTRABYVals!AM$2:AM$999,RdTRABYVals!$B$2:$B$999,"="&$C8,RdTRABYVals!$C$2:$C$999,"="&INS_FLO!$A8),"") -> 1.8240133 | AE8: =IFERROR(AVERAGEIFS(RdTRABYVals!AN$2:AN$999,RdTRABYVals!$B$2:$B$999,"="&$C8,RdTRABYVals!$C$2:$C$999,"="&INS_FLO!$A8),"") -> 2.8752834 | AF8: =IFERROR(AVERAGEIFS(RdTRABYVals!AO$2:AO$999,RdTRABYVals!$B$2:$B$999,"="&$C8,RdTRABYVals!$C$2:$C$999,"="&INS_FLO!$A8),"") -> 2.2831262 | AG8: 1.8364432 | AH8: =IFERROR(AVERAGEIFS(RdTRABYVals!AQ$2:AQ$999,RdTRABYVals!$B$2:$B$999,"="&$C8,RdTRABYVals!$C$2:$C$999,"="&INS_FLO!$A8),"") -> 1.2736668 | AI8: =IFERROR(AVERAGEIFS(RdTRABYVals!AS$2:AS$999,RdTRABYVals!$B$2:$B$999,"="&$C8,RdTRABYVals!$C$2:$C$999,"="&INS_FLO!$A8),"") -> 1.9768948 | AJ8: =IFERROR(AVERAGEIFS(RdTRABYVals!AT$2:AT$999,RdTRABYVals!$B$2:$B$999,"="&$C8,RdTRABYVals!$C$2:$C$999,"="&INS_FLO!$A8),"") -> 1.9298371 | AK8: 1.8364432 | AL8: =IFERROR(AVERAGEIFS(RdTRABYVals!AV$2:AV$999,RdTRABYVals!$B$2:$B$999,"="&$C8,RdTRABYVals!$C$2:$C$999,"="&INS_FLO!$A8),"") -> 0.90412603 | AM8: =IFERROR(AVERAGEIFS(RdTRABYVals!L$2:L$999,RdTRABYVals!$B$2:$B$999,"="&$C8,RdTRABYVals!$C$2:$C$999,"="&INS_FLO!$A8),"") -> 1.5272753 | AN8: =IFERROR(AVERAGEIFS(RdTRABYVals!N$2:N$999,RdTRABYVals!$B$2:$B$999,"="&$C8,RdTRABYVals!$C$2:$C$999,"="&INS_FLO!$A8),"") -> 2.786757 | AO8: =IFERROR(AVERAGEIFS(RdTRABYVals!AJ$2:AJ$999,RdTRABYVals!$B$2:$B$999,"="&$C8,RdTRABYVals!$C$2:$C$999,"="&INS_FLO!$A8),"") -> 1.5272753 | AP8: =IFERROR(AVERAGEIFS(RdTRABYVals!AR$2:AR$999,RdTRABYVals!$B$2:$B$999,"="&$C8,RdTRABYVals!$C$2:$C$999,"="&INS_FLO!$A8),"") -> 2.786757 | AQ8: =IFERROR(AVERAGEIFS(RdTRABYVals!AF$2:AF$999,RdTRABYVals!$B$2:$B$999,"="&$C8,RdTRABYVals!$C$2:$C$999,"="&INS_FLO!$A8),"") -> 2.786757
