Workbook
Name FID_1: [1]AGR_Fuels!$A$2

Sheet TechSelection
B3: ~TFM_AVA
B4: PSET_SET | C4: PSET_PN | D4: PSET_PD | E4: PSET_CO | F4: PSET_CI | G4: AllRegions | H4: AT | I4: BE | J4: BG | K4: CH | L4: CY | M4: CZ | N4: DE | O4: DK | P4: EE | Q4: ES | R4: FI | S4: FR | T4: EL | U4: HU | V4: IE | W4: IS | X4: IT | Y4: LT | Z4: LU | AA4: LV | AB4: MT | AC4: NL | AD4: NO | AE4: PL | AF4: PT | AG4: RO | AH4: SE | AI4: SI | AJ4: SK | AK4: UK | AL4: AL | AM4: BA | AN4: HR | AO4: KS | AP4: ME | AQ4: MK | AR4: RS
C5: * | G5: 1
C6: PUSPWOO* | W6: 0
C7: ICLSTDPRO01 | G7: 0
C8: INDBGS01 | I8: 0
C9: PUSCSBIO* | H9: 1 | I9: 0 | J9: 0 | K9: 0 | L9: 0 | M9: 1 | N9: 1 | O9: 1 | P9: 1 | Q9: 0 | R9: 1 | S9: 1 | T9: 0 | U9: 1 | V9: 0 | W9: 0 | X9: 0 | Y9: 1 | Z9: 0 | AA9: 1 | AB9: 0 | AC9: 0 | AD9: 0 | AE9: 1 | AF9: 0 | AG9: 1 | AH9: 1 | AI9: 0 | AJ9: 1 | AK9: 0 | AL9: 0 | AM9: 0 | AN9: 0 | AO9: 0 | AP9: 0 | AQ9: 0 | AR9: 0

Sheet INTERPOLSET
C1: Some Interpolation Options copied here to reduce the load on SysSettings
A2: ~TFM_UPD
A3: TimeSlice | B3: LimType | C3: Attribute | D3: Year | E3: AllRegions | F3: Pset_CO | G3: Pset_CI | H3: Pset_PN | I3: Pset_PD | J3: Cset_Set | K3: Cset_CN
C4: Share | D4: 0 | E4: 3
C5: NCAP_BND | D5: 0 | E5: 1
B6: UP | C6: ACT_BND | D6: 0 | E6: 15 | H6: EXP*,IMP*,MIN*
B7: UP,LO | C7: STGOUT_BND | D7: 0 | E7: 1
C8: NCAP_DRATE | D8: 0 | E8: 5
B11: UP,LO | C11: CAP_BND | D11: 0 | E11: 3
C12: COM_PROJ | D12: 0 | E12: 1 | J12: DEM | K12: *MN,*UN,*RN
B13: FX | C13: CHPR | D13: 0 | E13: -1 | H13: PUPO*
C14: ACT_BND | D14: 0 | E14: 1

Sheet CO2_Storage_Potential
A1: ~TFM_INS
A2: TimeSlice | B2: Pset_PN | C2: LimType | D2: Attribute | E2: Year | F2: AllRegions | G2: AT | H2: BE | I2: BG | J2: CY | K2: CZ | L2: DE | M2: DK | N2: EE | O2: ES | P2: FI | Q2: FR | R2: EL | S2: HU | T2: IE | U2: IT | V2: LT | W2: LU | X2: LV | Y2: MT | Z2: NL | AA2: PL | AB2: PT | AC2: RO | AD2: SE | AE2: SI | AF2: SK | AG2: UK | AH2: IS | AI2: CH | AJ2: NO | AK2: HR | AL2: AL | AM2: BA | AN2: MK | AO2: ME | AP2: RS | AQ2: KS | AR2: *EU25
B3: MINSNKCB11 | D3: CUM | G3: 0 | H3: 0 | I3: 0 | J3: 0 | K3: 0 | L3: 21597 | M3: 0 | N3: 0 | O3: 145000 | P3: 0 | Q3: 0 | R3: 0 | S3: 0 | T3: 0 | U3: 0 | V3: 0 | W3: 0 | X3: 0 | Y3: 0 | Z3: 0 | AA3: 0 | AB3: 0 | AC3: 0 | AD3: 0 | AE3: 0 | AF3: 0 | AG3: 0 | AH3: 0 | AI3: 0 | AJ3: 0 | AK3: 0 | AL3: 0 | AM3: 0 | AN3: 0
B4: MINSNKCB21 | D4: CUM | G4: 0 | H4: 0 | I4: 17000 | J4: 0 | K4: 110000 | L4: 0 | M4: 0 | N4: 0 | O4: 0 | P4: 0 | Q4: 0 | R4: 0 | S4: 87000 | T4: 0 | U4: 0 | V4: 0 | W4: 0 | X4: 0 | Y4: 0 | Z4: 0 | AA4: 115000 | AB4: 0 | AC4: 0 | AD4: 0 | AE4: 0 | AF4: 0 | AG4: 0 | AH4: 0 | AI4: 0 | AJ4: 0 | AK4: 0 | AL4: 0 | AM4: 0 | AN4: 0
B5: MINSNKDGF1 | D5: CUM | G5: 0 | H5: 0 | I5: 3000 | J5: 0 | K5: 0 | L5: 0 | M5: 515890 | N5: 0 | O5: 0 | P5: 0 | Q5: 0 | R5: 5000 | S5: 0 | T5: 0 | U5: 0 | V5: 0 | W5: 0 | X5: 0 | Y5: 0 | Z5: 1160000 | AA5: 0 | AB5: 0 | AC5: 0 | AD5: 0 | AE5: 0 | AF5: 0 | AG5: 6390570 | AH5: 0 | AI5: 0 | AJ5: 0 | AK5: 0 | AL5: 0 | AM5: 0 | AN5: 0
B6: MINSNKDGO1 | D6: CUM | G6: 0 | H6: 639600 | I6: 0 | J6: 0 | K6: 33000 | L6: 1491826 | M6: 0 | N6: 0 | O6: 0 | P6: 0 | Q6: 0 | R6: 1600 | S6: 0 | T6: 0 | U6: 1600000 | V6: 0 | W6: 0 | X6: 0 | Y6: 0 | Z6: 8864000 | AA6: 0 | AB6: 0 | AC6: 240000 | AD6: 0 | AE6: 5800 | AF6: 0 | AG6: 0 | AH6: 0 | AI6: 0 | AJ6: 0 | AK6: 0 | AL6: 0 | AM6: 0 | AN6: 0
B7: MINSNKDOF1 | D7: CUM | G7: 0 | H7: 0 | I7: 0 | J7: 0 | K7: 0 | L7: 15220 | M7: 294330 | N7: 0 | O7: 34000 | P7: 0 | Q7: 0 | R7: 63400 | S7: 0 | T7: 0 | U7: 0 | V7: 0 | W7: 0 | X7: 0 | Y7: 0 | Z7: 14660 | AA7: 0 | AB7: 0 | AC7: 0 | AD7: 0 | AE7: 0 | AF7: 0 | AG7: 3553160 | AH7: 0 | AI7: 0 | AJ7: 0 | AK7: 0 | AL7: 0 | AM7: 0 | AN7: 0
B8: MINSNKDOO1 | D8: CUM | G8: 0 | H8: 0 | I8: 0 | J8: 0 | K8: 0 | L8: 40680 | M8: 0 | N8: 0 | O8: 500 | P8: 0 | Q8: 11099 | R8: 0 | S8: 0 | T8: 0 | U8: 210000 | V8: 5700 | W8: 0 | X8: 0 | Y8: 0 | Z8: 20340 | AA8: 682270 | AB8: 0 | AC8: 234590 | AD8: 0 | AE8: 440 | AF8: 0 | AG8: 0 | AH8: 0 | AI8: 0 | AJ8: 0 | AK8: 0 | AL8: 0 | AM8: 0 | AN8: 0
B9: MINSNKDSAOF1 | D9: CUM | G9: 0 | H9: 0 | I9: 0 | J9: 0 | K9: 0 | L9: 6336000 | M9: 14718000 | N9: 0 | O9: 0 | P9: 0 | Q9: 7922000 | R9: 1864000 | S9: 0 | T9: 92277000 | U9: 2709000 | V9: 0 | W9: 0 | X9: 0 | Y9: 0 | Z9: 170000 | AA9: 0 | AB9: 0 | AC9: 0 | AD9: 2250000 | AE9: 0 | AF9: 0 | AG9: 14933000 | AH9: 0 | AI9: 0 | AJ9: 26031000 | AK9: 0 | AL9: 0 | AM9: 0 | AN9: 0
B10: MINSNKDSAON1 | D10: CUM | G10: 0 | H10: 199000 | I10: 2100000 | J10: 0 | K10: 766000 | L10: 20000000 | M10: 1954000 | N10: 0 | O10: 23439 | P10: 0 | Q10: 0 | R10: 255000 | S10: 140000 | T10: 0 | U10: 1963000 | V10: 41500 | W10: 0 | X10: 404000 | Y10: 0 | Z10: 170000 | AA10: 3522600 | AB10: 7700000 | AC10: 7500000 | AD10: 0 | AE10: 92000 | AF10: 1716000 | AG10: 0 | AH10: 0 | AI10: 0 | AJ10: 0 | AK10: 2710000 | AL10: 20000 | AM10: 296062.36 | AN10: 1050000
B11: MINSNKEOR1 | D11: CUM | G11: 0 | H11: 0 | I11: 0 | J11: 0 | K11: 0 | L11: 0 | M11: 0 | N11: 0 | O11: 0 | P11: 0 | Q11: 0 | R11: 0 | S11: 0 | T11: 0 | U11: 0 | V11: 5000 | W11: 0 | X11: 0 | Y11: 0 | Z11: 0 | AA11: 0 | AB11: 0 | AC11: 0 | AD11: 0 | AE11: 0 | AF11: 0 | AG11: 0 | AH11: 0 | AI11: 0 | AJ11: 0 | AK11: 0 | AL11: 0 | AM11: 0 | AN11: 0
B12: MINSNKDOGO1 | D12: CUM | G12: 487500 | H12: 0 | I12: 0 | J12: 0 | K12: 0 | L12: 0 | M12: 0 | N12: 0 | O12: 0 | P12: 0 | Q12: 1007401 | R12: 0 | S12: 389000 | T12: 0 | U12: 0 | V12: 0 | W12: 0 | X12: 0 | Y12: 0 | Z12: 0 | AA12: 82060 | AB12: 0 | AC12: 16000 | AD12: 0 | AE12: 0 | AF12: 0 | AG12: 0 | AH12: 0 | AI12: 0 | AJ12: 0 | AK12: 188830 | AL12: 111000 | AM12: 0 | AN12: 0
B13: MINSNKDOGF1 | D13: CUM | G13: 0 | H13: 0 | I13: 0 | J13: 0 | K13: 0 | L13: 0 | M13: 0 | N13: 0 | O13: 0 | P13: 0 | Q13: 0 | R13: 0 | S13: 0 | T13: 1505000 | U13: 0 | V13: 0 | W13: 0 | X13: 0 | Y13: 0 | Z13: 0 | AA13: 0 | AB13: 0 | AC13: 0 | AD13: 0 | AE13: 0 | AF13: 0 | AG13: 0 | AH13: 0 | AI13: 0 | AJ13: 3157000 | AK13: 0 | AL13: 0 | AM13: 0 | AN13: 0
B14: MINSNKCB31 | D14: CUM | G14: 0 | H14: 0 | I14: 0 | J14: 0 | K14: 0 | L14: 0 | M14: 0 | N14: 0 | O14: 0 | P14: 0 | Q14: 0 | R14: 0 | S14: 0 | T14: 0 | U14: 71000 | V14: 0 | W14: 0 | X14: 0 | Y14: 0 | Z14: 0 | AA14: 0 | AB14: 0 | AC14: 0 | AD14: 0 | AE14: 0 | AF14: 0 | AG14: 0 | AH14: 0 | AI14: 0 | AJ14: 0 | AK14: 0 | AL14: 0 | AM14: 0 | AN14: 0
... B26: MINSNKCB31 | D26: COST | G26: 0 | H26: 0 | I26: 0 | J26: 0 | K26: 0 | L26: 0.0013237097 | M26: 0.0064339897 | N26: 0 | O26: 0.0020136993 | P26: 0 | Q26: 0.0045738976 | R26: 0 | S26: 0.00099070793 | T26: 0 | U26: 0.0014497554 | V26: 0 | W26: 0 | X26: 0 | Y26: 0 | Z26: 0.0016814097 | AA26: 0.0026147658 | AB26: 0 | AC26: 0.00097225907 | AD26: 0 | AE26: 0 | AF26: 0 | AG26: 0.0014014214 | AH26: 0 | AI26: 0 | AJ26: 0.0016814097 | AK26: 0.0026147658 | AL26: 0.0016814097 | AM26: 0.0026147658 | AN26: 0.0016814097
B27: MINSNKAFF1 | D27: CUM | G27: 57981.359 | H27: 18016.499 | J27: 120.7945 | K27: 29020.878 | L27: 152442.66 | M27: 10811.108 | N27: 3956.0198 | O27: 346136.64 | P27: 785.16424 | Q27: 305730.88 | R27: 141178.57 | S27: 31738.754 | T27: 100652.02 | U27: 131454.61 | V27: 15008.716 | W27: 948.23681 | X27: 18451.36 | Y27: 0 | Z27: 30561.008 | AA27: 123300.98 | AB27: 43395.424 | AC27: 149452.99 | AD27: 13498.785 | AE27: 9482.3681 | AF27: 26121.81 | AG27: 333272.02 | AH27: 68671.672 | AI27: 33067.494 | AJ27: 4741.1841 | AR27: 2200000
B28: MINSNKAFF2 | D28: CUM | G28: 83150.54 | H28: 25837.298 | J28: 173.23029 | K28: 41618.578 | L28: 218616.63 | M28: 15504.111 | N28: 5673.2921 | O28: 496391.4 | P28: 1125.9969 | Q28: 438445.87 | R28: 202462.9 | S28: 45516.259 | T28: 144344.14 | U28: 188517.87 | V28: 21523.864 | W28: 1359.8578 | X28: 26460.927 | Y28: 0 | Z28: 43827.264 | AA28: 176824.82 | AB28: 62232.982 | AC28: 214329.18 | AD28: 19358.485 | AE28: 13598.578 | AF28: 37461.051 | AG28: 477942.38 | AH28: 98481.421 | AI28: 47421.792 | AJ28: 6799.289 | AR28: 3155000
B29: MINSNKAFF3 | D29: CUM | G29: 64833.702 | H29: 20145.722 | J29: 135.07021 | K29: 32450.618 | L29: 170458.61 | M29: 12088.784 | N29: 4423.5494 | O29: 387043.69 | P29: 877.95638 | Q29: 341862.71 | R29: 157863.31 | S29: 35489.698 | T29: 112547.25 | U29: 146990.16 | V29: 16782.474 | W29: 1060.3012 | X29: 20631.975 | Y29: 0 | Z29: 34172.764 | AA29: 137872.92 | AB29: 48523.974 | AC29: 167115.62 | AD29: 15094.096 | AE29: 10603.012 | AF29: 29208.933 | AG29: 372658.71 | AH29: 76787.415 | AI29: 36975.47 | AJ29: 5301.5058 | AR29: 2460000
B30: MINSNKAFF4 | D30: CUM | G30: 85127.177 | H30: 26451.497 | J30: 177.34829 | K30: 42607.926 | L30: 223813.54 | M30: 15872.672 | N30: 5808.1564 | O30: 508191.51 | P30: 1152.7639 | Q30: 448868.51 | R30: 207275.81 | S30: 46598.262 | T30: 147775.46 | U30: 192999.27 | V30: 22035.525 | W30: 1392.184 | X30: 27089.951 | Y30: 0 | Z30: 44869.116 | AA30: 181028.26 | AB30: 63712.372 | AC30: 219424.17 | AD30: 19818.671 | AE30: 13921.84 | AF30: 38351.567 | AG30: 489303.92 | AH30: 100822.5 | AI30: 48549.093 | AJ30: 6960.9202 | AR30: 3230000
A31: ANNUAL | B31: MINSNKAFF1 | C31: UP | D31: ACT_BND | E31: 2005 | G31: 0 | H31: 0 | J31: 0 | K31: 0 | L31: 0 | M31: 0 | N31: 0 | O31: 0 | P31: 0 | Q31: 0 | R31: 0 | S31: 0 | T31: 0 | U31: 0 | V31: 0 | W31: 0 | X31: 0 | Y31: 0 | Z31: 0 | AA31: 0 | AB31: 0 | AC31: 0 | AD31: 0 | AE31: 0 | AF31: 0 | AG31: 0 | AH31: 0 | AI31: 0 | AJ31: 0 | AR31: 0
A32: ANNUAL | B32: MINSNKAFF1 | C32: UP | D32: ACT_BND | E32: 2010 | G32: 1062.9037 | H32: 330.27519 | J32: 2.2143828 | K32: 532.00546 | L32: 2794.5511 | M32: 198.18726 | N32: 72.521036 | O32: 6345.3139 | P32: 14.393488 | Q32: 5604.6028 | R32: 2588.0599 | S32: 581.82908 | T32: 1845.1345 | U32: 2409.8021 | V32: 275.13706 | W32: 17.382905 | X32: 338.24697 | Y32: 0 | Z32: 560.23884 | AA32: 2260.3312 | AB32: 795.51701 | AC32: 2739.7451 | AD32: 247.45728 | AE32: 173.82905 | AF32: 478.86028 | AG32: 6109.4821 | AH32: 1258.8766 | AI32: 606.18729 | AJ32: 86.914524 | AR32: 40330
A33: ANNUAL | B33: MINSNKAFF1 | C33: UP | D33: ACT_BND | E33: 2020 | G33: 1352.8105 | H33: 420.35769 | J33: 2.8183553 | K33: 677.10985 | L33: 3556.7644 | M33: 252.2428 | N33: 92.301135 | O33: 8075.997 | P33: 18.319309 | Q33: 7133.2572 | R33: 3293.9527 | S33: 740.52285 | T33: 2348.3945 | U33: 3067.0751 | V33: 350.18064 | W33: 22.124089 | X33: 430.50377 | Y33: 0 | Z33: 713.04388 | AA33: 2876.8361 | AB33: 1012.4941 | AC33: 3487.0101 | AD33: 314.9512 | AE33: 221.24089 | AF33: 609.46933 | AG33: 7775.8422 | AH33: 1602.235 | AI33: 771.52476 | AJ33: 110.62044 | AR33: 51330
A34: ANNUAL | B34: MINSNKAFF1 | C34: UP | D34: ACT_BND | E34: 2030 | G34: 483.09014 | H34: 150.1102 | J34: 1.0064378 | K34: 241.79668 | L34: 1270.1245 | M34: 90.076183 | N34: 32.960838 | O34: 2883.9475 | P34: 6.5418457 | Q34: 2547.2941 | R34: 1176.2742 | S34: 264.44153 | T34: 838.61429 | U34: 1095.2559 | V34: 125.0499 | W34: 7.9005367 | X34: 153.73337 | Y34: 0 | Z34: 254.62876 | AA34: 1027.3214 | AB34: 361.56278 | AC34: 1245.2152 | AD34: 112.46942 | AE34: 79.005367 | AF34: 217.64217 | AG34: 2776.7619 | AH34: 572.15989 | AI34: 275.51235 | AJ34: 39.502684 | AR34: 18330
A35: ANNUAL | B35: MINSNKAFF1 | C35: UP | D35: ACT_BND | E35: 2040 | G35: 483.09014 | H35: 150.1102 | J35: 1.0064378 | K35: 241.79668 | L35: 1270.1245 | M35: 90.076183 | N35: 32.960838 | O35: 2883.9475 | P35: 6.5418457 | Q35: 2547.2941 | R35: 1176.2742 | S35: 264.44153 | T35: 838.61429 | U35: 1095.2559 | V35: 125.0499 | W35: 7.9005367 | X35: 153.73337 | Y35: 0 | Z35: 254.62876 | AA35: 1027.3214 | AB35: 361.56278 | AC35: 1245.2152 | AD35: 112.46942 | AE35: 79.005367 | AF35: 217.64217 | AG35: 2776.7619 | AH35: 572.15989 | AI35: 275.51235 | AJ35: 39.502684 | AR35: 18330
A36: ANNUAL | B36: MINSNKAFF1 | C36: UP | D36: ACT_BND | E36: 2050 | G36: 2415.9778 | H36: 750.71477 | J36: 5.0332871 | K36: 1209.2472 | L36: 6352.0083 | M36: 450.4792 | N36: 164.84015 | O36: 14422.884 | P36: 32.716366 | Q36: 12739.25 | R36: 5882.6543 | S36: 1322.4962 | T36: 4193.9865 | U36: 5477.4747 | V36: 625.38592 | W36: 39.511304 | X36: 768.83461 | Y36: 0 | Z36: 1273.4216 | AA36: 5137.7278 | AB36: 1808.2084 | AC36: 6227.4345 | AD36: 562.46984 | AE36: 395.11304 | AF36: 1088.4483 | AG36: 13886.839 | AH36: 2861.4237 | AI36: 1377.8623 | AJ36: 197.55652 | AR36: 91670
A37: ANNUAL | B37: MINSNKAFF2 | C37: UP | D37: ACT_BND | E37: 2005 | G37: 0 | H37: 0 | J37: 0 | K37: 0 | L37: 0 | M37: 0 | N37: 0 | O37: 0 | P37: 0 | Q37: 0 | R37: 0 | S37: 0 | T37: 0 | U37: 0 | V37: 0 | W37: 0 | X37: 0 | Y37: 0 | Z37: 0 | AA37: 0 | AB37: 0 | AC37: 0 | AD37: 0 | AE37: 0 | AF37: 0 | AG37: 0 | AH37: 0 | AI37: 0 | AJ37: 0 | AR37: 0
A38: ANNUAL | B38: MINSNKAFF2 | C38: UP | D38: ACT_BND | E38: 2010 | G38: 2512.4377 | H38: 780.68768 | J38: 5.2342452 | K38: 1257.5274 | L38: 6605.6175 | M38: 468.46495 | N38: 171.42153 | O38: 14998.73 | P38: 34.022594 | Q38: 13247.875 | R38: 6117.5241 | S38: 1375.2979 | T38: 4361.4348 | U38: 5696.1674 | V38: 650.35497 | W38: 41.088825 | X38: 799.53096 | Y38: 0 | Z38: 1324.264 | AA38: 5342.8558 | AB38: 1880.4026 | AC38: 6476.0699 | AD38: 584.92691 | AE38: 410.88825 | AF38: 1131.9055 | AG38: 14441.283 | AH38: 2975.6684 | AI38: 1432.8746 | AJ38: 205.44413 | AR38: 95330
A39: ANNUAL | B39: MINSNKAFF2 | C39: UP | D39: ACT_BND | E39: 2020 | G39: 0 | H39: 0 | J39: 0 | K39: 0 | L39: 0 | M39: 0 | N39: 0 | O39: 0 | P39: 0 | Q39: 0 | R39: 0 | S39: 0 | T39: 0 | U39: 0 | V39: 0 | W39: 0 | X39: 0 | Y39: 0 | Z39: 0 | AA39: 0 | AB39: 0 | AC39: 0 | AD39: 0 | AE39: 0 | AF39: 0 | AG39: 0 | AH39: 0 | AI39: 0 | AJ39: 0 | AR39: 0
A40: ANNUAL | B40: MINSNKAFF2 | C40: UP | D40: ACT_BND | E40: 2030 | G40: 1932.6241 | H40: 600.52268 | J40: 4.0263003 | K40: 967.31864 | L40: 5081.1909 | M40: 360.35387 | N40: 131.86133 | O40: 11537.363 | P40: 26.170952 | Q40: 10190.566 | R40: 4705.7384 | S40: 1057.9104 | T40: 3354.9147 | U40: 4381.6213 | V40: 500.26781 | W40: 31.606457 | X40: 615.01736 | Y40: 0 | Z40: 1018.654 | AA40: 4109.846 | AB40: 1446.4484 | AC40: 4981.54 | AD40: 449.93905 | AE40: 316.06457 | AF40: 870.68743 | AG40: 11108.562 | AH40: 2288.9517 | AI40: 1102.1997 | AJ40: 158.03229 | AR40: 73330
A41: ANNUAL | B41: MINSNKAFF2 | C41: UP | D41: ACT_BND | E41: 2040 | G41: 1932.6241 | H41: 600.52268 | J41: 4.0263003 | K41: 967.31864 | L41: 5081.1909 | M41: 360.35387 | N41: 131.86133 | O41: 11537.363 | P41: 26.170952 | Q41: 10190.566 | R41: 4705.7384 | S41: 1057.9104 | T41: 3354.9147 | U41: 4381.6213 | V41: 500.26781 | W41: 31.606457 | X41: 615.01736 | Y41: 0 | Z41: 1018.654 | AA41: 4109.846 | AB41: 1446.4484 | AC41: 4981.54 | AD41: 449.93905 | AE41: 316.06457 | AF41: 870.68743 | AG41: 11108.562 | AH41: 2288.9517 | AI41: 1102.1997 | AJ41: 158.03229 | AR41: 73330
A42: ANNUAL | B42: MINSNKAFF2 | C42: UP | D42: ACT_BND | E42: 2050 | G42: 1932.6241 | H42: 600.52268 | J42: 4.0263003 | K42: 967.31864 | L42: 5081.1909 | M42: 360.35387 | N42: 131.86133 | O42: 11537.363 | P42: 26.170952 | Q42: 10190.566 | R42: 4705.7384 | S42: 1057.9104 | T42: 3354.9147 | U42: 4381.6213 | V42: 500.26781 | W42: 31.606457 | X42: 615.01736 | Y42: 0 | Z42: 1018.654 | AA42: 4109.846 | AB42: 1446.4484 | AC42: 4981.54 | AD42: 449.93905 | AE42: 316.06457 | AF42: 870.68743 | AG42: 11108.562 | AH42: 2288.9517 | AI42: 1102.1997 | AJ42: 158.03229 | AR42: 73330
... A54: ANNUAL | B54: MINSNKAFF4 | C54: UP | D54: ACT_BND | E54: 2050 | G54: 3768.7883 | H54: 1171.0725 | J54: 7.8516424 | K54: 1886.3571 | L54: 9908.7727 | M54: 702.72199 | N54: 257.14129 | O54: 22498.881 | P54: 51.035676 | Q54: 19872.507 | R54: 9176.607 | S54: 2063.019 | T54: 6542.381 | U54: 8544.5498 | V54: 975.56657 | W54: 61.635393 | X54: 1199.3384 | Y54: 0 | Z54: 1986.4655 | AA54: 8014.564 | AB54: 2820.7025 | AC54: 9714.4446 | AD54: 877.42104 | AE54: 616.35393 | AF54: 1697.9177 | AG54: 21662.681 | AH54: 4463.6587 | AI54: 2149.3871 | AJ54: 308.17696 | AR54: 143000
B55: MINSNKAFF1 | D55: COST | F55: 0.05
B56: MINSNKAFF2 | D56: COST | F56: 0.1
B57: MINSNKAFF3 | D57: COST | F57: 0.2
B58: MINSNKAFF4 | D58: COST | F58: 0.3
A62: REFERENCES
A63: The CUM CO2 storage capacity data is in kt CO2 and is from the GEOCAPACITY research project. The data was supplied in October 2012 by Andrei Bocin-Dumitriu (ESE-IET JRC). This data assumes the usage of legacy wells. Below in the data sheet there is the same data without considering legacy wells
A64: The COST CO2 storage capacity has rhe
A65: The Afforestation sinking capacity was already in the model supplied by IPTS. It is not clear the data provenience.

Sheet SUP_CCS
A1: XXX~TFM_INS | C1: RDM: Disabled (New Hydrogen chain)
A3: TimeSlice | B3: PSET_PN | C3: Comm_OUT | D3: Comm_IN | E3: LimType | F3: Attribute | G3: Year | H3: AllRegions | I3: AT | J3: BE | K3: BG | L3: CH | M3: CY | N3: CZ | O3: DE | P3: DK | Q3: EE | R3: ES | S3: FI | T3: FR | U3: EL | V3: HU | W3: IE | X3: IS | Y3: IT | Z3: LT | AA3: LU | AB3: LV | AC3: MT | AD3: NL | AE3: NO | AF3: PL | AG3: PT | AH3: RO | AI3: SE | AJ3: SI | AK3: SK | AL3: UK | AM3: AL | AN3: BA | AO3: HR | AP3: KS | AQ3: ME | AR3: MK | AS3: RS | AW3: Country Surface | AX3: RO | AY3: AL | AZ3: BA | BA3: HR | BB3: KS | BC3: ME | BD3: MK | BE3: RS
B4: STORAGE_ELCS | E4: UP | F4: CAP_BND | H4: 0 | I4: 15000 | J4: 110000 | K4: 40000 | L4: 0 | M4: 0 | N4: 150000 | O4: 140000 | P4: 15000 | Q4: 5000 | R4: 120000 | S4: 30000 | T4: 30000 | U4: 30000 | V4: 20000 | W4: 15000 | X4: 5000 | Y4: 90000 | Z4: 4000 | AA4: 4000 | AB4: 4000 | AC4: 4000 | AD4: 70000 | AE4: 10000 | AF4: 70000 | AG4: 10000 | AH4: 40000 | AI4: 10000 | AJ4: 5000 | AK4: 10000 | AL4: 120000 | AM4: =$AH4*AY$5 -> 4845.8205 | AN4: =$AH4*AZ$5 -> 8579.0151 | AO4: =$AH4*BA$5 -> 9495.9961 | AP4: =$AH4*BB$5 -> 1826.7468 | AQ4: =$AH4*BC$5 -> 2317.5372 | AR4: =$AH4*BD$5 -> 4314.4246 | AS4: =$AH4*BE$5 -> 12999.484 | AW4: km2 | AX4: 238391 | AY4: 28880 | AZ4: 51129 | BA4: 56594 | BB4: 10887 | BC4: 13812 | BD4: 25713 | BE4: 77474
B5: STORAGE_INDS | E5: UP | F5: CAP_BND | H5: 0 | I5: 5000 | J5: 15000 | K5: 10000 | L5: 0 | M5: 0 | N5: 15000 | O5: 40000 | P5: 4000 | Q5: 3000 | R5: 25000 | S5: 5000 | T5: 30000 | U5: 5000 | V5: 5000 | W5: 5000 | X5: 0 | Y5: 30000 | Z5: 2000 | AA5: 2000 | AB5: 2000 | AC5: 2000 | AD5: 10000 | AE5: 5000 | AF5: 20000 | AG5: 5000 | AH5: 10000 | AI5: 5000 | AJ5: 5000 | AK5: 5000 | AL5: 15000 | AM5: =$AH5*AY$5 -> 1211.4551 | AN5: =$AH5*AZ$5 -> 2144.7538 | AO5: =$AH5*BA$5 -> 2373.999 | AP5: =$AH5*BB$5 -> 456.6867 | AQ5: =$AH5*BC$5 -> 579.38429 | AR5: =$AH5*BD$5 -> 1078.6062 | AS5: =$AH5*BE$5 -> 3249.871 | AY5: =AY4/$AX$4 -> 0.12114551 | AZ5: =AZ4/$AX$4 -> 0.21447538 | BA5: =BA4/$AX$4 -> 0.2373999 | BB5: =BB4/$AX$4 -> 0.04566867 | BC5: =BC4/$AX$4 -> 0.057938429 | BD5: =BD4/$AX$4 -> 0.10786062 | BE5: =BE4/$AX$4 -> 0.3249871
B6: STORAGE_SUPS | E6: UP | F6: CAP_BND | H6: 0 | I6: 0 | J6: 5000 | K6: 0 | L6: 0 | M6: 0 | N6: 5000 | O6: 40000 | P6: 5000 | Q6: 0 | R6: 10000 | S6: 5000 | T6: 10000 | U6: 5000 | V6: 5000 | W6: 5000 | X6: 0 | Y6: 20000 | Z6: 0 | AA6: 0 | AB6: 0 | AC6: 0 | AD6: 5000 | AE6: 5000 | AF6: 10000 | AG6: 0 | AH6: 5000 | AI6: 5000 | AJ6: 0 | AK6: 2000 | AL6: 10000 | AM6: =$AH6*AY$5 -> 605.72757 | AN6: =$AH6*AZ$5 -> 1072.3769 | AO6: =$AH6*BA$5 -> 1186.9995 | AP6: =$AH6*BB$5 -> 228.34335 | AQ6: =$AH6*BC$5 -> 289.69214 | AR6: =$AH6*BD$5 -> 539.30308 | AS6: =$AH6*BE$5 -> 1624.9355
B7: STORAGE_COMS | E7: UP | F7: CAP_BND | H7: 0 | I7: 0 | J7: 0 | K7: 0 | L7: 0 | M7: 0 | N7: 0 | O7: 0 | P7: 0 | Q7: 0 | R7: 0 | S7: 0 | T7: 0 | U7: 0 | V7: 0 | W7: 0 | X7: 0 | Y7: 0 | Z7: 0 | AA7: 0 | AB7: 0 | AC7: 0 | AD7: 0 | AE7: 0 | AF7: 0 | AG7: 0 | AH7: 0 | AI7: 0 | AJ7: 0 | AK7: 0 | AL7: 0 | AM7: =$AH7*AY$5 -> 0 | AN7: =$AH7*AZ$5 -> 0 | AO7: =$AH7*BA$5 -> 0 | AP7: =$AH7*BB$5 -> 0 | AQ7: =$AH7*BC$5 -> 0 | AR7: =$AH7*BD$5 -> 0 | AS7: =$AH7*BE$5 -> 0
B8: STORAGE_AGRS | E8: UP | F8: CAP_BND | H8: 0 | I8: 0 | J8: 0 | K8: 0 | L8: 0 | M8: 0 | N8: 0 | O8: 0 | P8: 0 | Q8: 0 | R8: 0 | S8: 0 | T8: 0 | U8: 0 | V8: 0 | W8: 0 | X8: 0 | Y8: 0 | Z8: 0 | AA8: 0 | AB8: 0 | AC8: 0 | AD8: 0 | AE8: 0 | AF8: 0 | AG8: 0 | AH8: 0 | AI8: 0 | AJ8: 0 | AK8: 0 | AL8: 0 | AM8: =$AH8*AY$5 -> 0 | AN8: =$AH8*AZ$5 -> 0 | AO8: =$AH8*BA$5 -> 0 | AP8: =$AH8*BB$5 -> 0 | AQ8: =$AH8*BC$5 -> 0 | AR8: =$AH8*BD$5 -> 0 | AS8: =$AH8*BE$5 -> 0
B9: STORAGE_* | E9: UP | F9: CAP_BND | G9: 0 | H9: 5

Sheet CHPEmissions
A1: *assigning ELC sector emissions to CHP in commercial sector
B3: ~TFM_INS
B4: Attribute | C4: Year | D4: Other_Indexes | E4: PSET_CI | F4: Pset_PN | G4: Pset_PD | H4: Cset_CN | I4: AllRegions | K4: ELCCO2N is residual
B5: FLO_EMIS | D5: ELCWOO | E5: =D5 -> ELCWOO | F5: EU*,PU*,CO* | G5: *seq*,*CCS* | H5: ELCCO2N | I5: =I7-I6 -> -98.56
B6: FLO_EMIS | D6: ELCWOO | E6: =D6 -> ELCWOO | F6: EU*,PU*,CO* | G6: *seq*,*CCS* | H6: ELCSCO2N | I6: =0.88*112 -> 98.56
B7: FLO_EMIS | D7: ELCWOO | E7: =D7 -> ELCWOO | F7: EU*,PU*,H*,CO* | G7: -*seq*,-*CCS* | H7: ELCCO2N | I7: 0
B8: FLO_EMIS | D8: ELCBGS | E8: =D8 -> ELCBGS | F8: EU*,PU*,H*,CO* | G8: -*seq*,-*CCS* | H8: ELCCO2N | I8: 0
B9: FLO_EMIS | D9: ELCMUN | E9: =D9 -> ELCMUN | F9: EU*,PU*,H*,CO* | G9: -*seq*,-*CCS* | H9: ELCCO2N | I9: 85.85
B10: FLO_EMIS | D10: ELCSLU | E10: =D10 -> ELCSLU | F10: EU*,PU*,H*,CO* | G10: -*seq*,-*CCS* | H10: ELCCO2N | I10: 85.85
B12: \I: FLO_EMIS | D12: ELCBGS | E12: =D12 -> ELCBGS | F12: EU*,PU*,CO* | G12: *seq*,*CCS* | H12: ELCCO2N | I12: =I8-I15 -> -50.4
B13: \I: FLO_EMIS | D13: ELCMUN | E13: =D13 -> ELCMUN | F13: EU*,PU*,CO* | G13: *seq*,*CCS* | H13: ELCCO2N | I13: =0.12*I9 -> 10.302
B14: \I: FLO_EMIS | D14: ELCSLU | E14: =D14 -> ELCSLU | F14: EU*,PU*,CO* | G14: *seq*,*CCS* | H14: ELCCO2N | I14: =0.12*I10 -> 10.302
B15: \I: FLO_EMIS | D15: ELCBGS | E15: =D15 -> ELCBGS | F15: EU*,PU*,CO* | G15: *seq*,*CCS* | H15: ELCSCO2N | I15: =0.9*56 -> 50.4
B16: \I: FLO_EMIS | D16: ELCMUN | E16: =D16 -> ELCMUN | F16: EU*,PU*,CO* | G16: *seq*,*CCS* | H16: ELCSCO2N | I16: =0.88*I9 -> 75.548
B17: \I: FLO_EMIS | D17: ELCSLU | E17: =D17 -> ELCSLU | F17: EU*,PU*,CO* | G17: *seq*,*CCS* | H17: ELCSCO2N | I17: =0.88*I10 -> 75.548

Sheet CO2 Transport Data
A1: Reference: Joris Morbee (IET-JRC), October 2012
A2: This worksheet comes from Joris Morbee from:
A3: \s-jrcpttfs002p\home\InfraCCS\Results-20110201-1209_Bargaining_Individual_with_outside_option_NPV357\[InfraCCS v4.79.xls]Nodes'!$Y$2:$Y$95,D$2&"-"&$B4,'\\s-jrcpttfs002p\home\InfraCCS\Results-20110201-1209_Bargaining_Individual_with_outside_option_NPV357\[InfraCCS v4.79.xls]
A5: CO2 transport costs per country from the InfraCCS model
A6: Country | B6: Full name | C6: Domestic transport investment | D6: Maximum flow rate | G6: Domestic transport | H6: Domestic transport cost | I6: Comparable country | J6: Final domestic transport cost
C7: from InfraCCS | D7: Source | E7: Aquifer | F7: Hydrocarbon field | H7: 0.15 | I7: (for missing data)
C8: Millions EUR | D8: Mt/y | E8: Mt/y | F8: Mt/y | G8: Mt/y | H8: EUR/t | J8: EUR/t | K8: EUR/kg
A9: AT | B9: Austria | C9: 0 | D9: 8.0666099 | E9: 0 | F9: 0 | G9: =MIN(D9,E9+F9) -> 0 | H9: =IF(C9=0,0,C9*$H$7/G9) -> 0 | I9: Poland | J9: =IF(ISERROR(H9),INDEX($H$9:$H$35,MATCH(I9,$B$9:$B$35,0)),H9) -> 0 | K9: =J9/1000 -> 0
A10: BE | B10: Belgium | C10: 0 | D10: 30.247876 | E10: 0 | F10: 0 | G10: =MIN(D10,E10+F10) -> 0 | H10: =IF(C10=0,0,C10*$H$7/G10) -> 0 | I10: Netherlands | J10: =IF(ISERROR(H10),INDEX($H$9:$H$35,MATCH(I10,$B$9:$B$35,0)),H10) -> 0 | K10: =J10/1000 -> 0
A11: BG | B11: Bulgaria | C11: 0 | D11: 24.835728 | E11: 0 | F11: 0 | G11: =MIN(D11,E11+F11) -> 0 | H11: =IF(C11=0,0,C11*$H$7/G11) -> 0 | I11: Romania | J11: =IF(ISERROR(H11),INDEX($H$9:$H$35,MATCH(I11,$B$9:$B$35,0)),H11) -> 0 | K11: =J11/1000 -> 0
A12: CY | B12: Cyprus | C12: 0 | D12: 0 | E12: 0 | F12: 0 | G12: =MIN(D12,E12+F12) -> 0 | H12: =IF(C12=0,0,C12*$H$7/G12) -> 0 | I12: Denmark | J12: =IF(ISERROR(H12),INDEX($H$9:$H$35,MATCH(I12,$B$9:$B$35,0)),H12) -> 0 | K12: =J12/1000 -> 0
A13: CZ | B13: Czech Republic | C13: 0 | D13: 62.134985 | E13: 0 | F13: 0 | G13: =MIN(D13,E13+F13) -> 0 | H13: =IF(C13=0,0,C13*$H$7/G13) -> 0 | I13: Poland | J13: =IF(ISERROR(H13),INDEX($H$9:$H$35,MATCH(I13,$B$9:$B$35,0)),H13) -> 0 | K13: =J13/1000 -> 0
A14: DE | B14: Germany | C14: 981.14793 | D14: 336.70047 | E14: 63.479212 | F14: 47.702407 | G14: =MIN(D14,E14+F14) -> 111.18162 | H14: =IF(C14=0,0,C14*$H$7/G14) -> 1.3237097 | J14: =IF(ISERROR(H14),INDEX($H$9:$H$35,MATCH(I14,$B$9:$B$35,0)),H14) -> 1.3237097 | K14: =J14/1000 -> 0.0013237097
A15: DK | B15: Denmark | C15: 586.21074 | D15: 15.288753 | E15: 9.2247185 | F15: 4.4420131 | G15: =MIN(D15,E15+F15) -> 13.666732 | H15: =IF(C15=0,0,C15*$H$7/G15) -> 6.4339897 | J15: =IF(ISERROR(H15),INDEX($H$9:$H$35,MATCH(I15,$B$9:$B$35,0)),H15) -> 6.4339897 | K15: =J15/1000 -> 0.0064339897
A16: EE | B16: Estonia | C16: 0 | D16: 0 | E16: 0 | F16: 0 | G16: =MIN(D16,E16+F16) -> 0 | H16: =IF(C16=0,0,C16*$H$7/G16) -> 0 | I16: Denmark | J16: =IF(ISERROR(H16),INDEX($H$9:$H$35,MATCH(I16,$B$9:$B$35,0)),H16) -> 0 | K16: =J16/1000 -> 0
A17: ES | B17: Spain | C17: 1068.9724 | D17: 79.627507 | E17: 107.846 | F17: 0 | G17: =MIN(D17,E17+F17) -> 79.627507 | H17: =IF(C17=0,0,C17*$H$7/G17) -> 2.0136993 | J17: =IF(ISERROR(H17),INDEX($H$9:$H$35,MATCH(I17,$B$9:$B$35,0)),H17) -> 2.0136993 | K17: =J17/1000 -> 0.0020136993
A18: FI | B18: Finland | C18: 0 | D18: 0 | E18: 0 | F18: 0 | G18: =MIN(D18,E18+F18) -> 0 | H18: =IF(C18=0,0,C18*$H$7/G18) -> 0 | I18: Denmark | J18: =IF(ISERROR(H18),INDEX($H$9:$H$35,MATCH(I18,$B$9:$B$35,0)),H18) -> 0 | K18: =J18/1000 -> 0
A19: FR | B19: France | C19: 513.66916 | D19: 27.251039 | E19: 0 | F19: 16.845671 | G19: =MIN(D19,E19+F19) -> 16.845671 | H19: =IF(C19=0,0,C19*$H$7/G19) -> 4.5738976 | J19: =IF(ISERROR(H19),INDEX($H$9:$H$35,MATCH(I19,$B$9:$B$35,0)),H19) -> 4.5738976 | K19: =J19/1000 -> 0.0045738976
A20: GR | B20: Greece | C20: 0 | D20: 0 | E20: 0 | F20: 1.5317287 | G20: =MIN(D20,E20+F20) -> 0 | H20: =IF(C20=0,0,C20*$H$7/G20) -> 0 | I20: Netherlands | J20: =IF(ISERROR(H20),INDEX($H$9:$H$35,MATCH(I20,$B$9:$B$35,0)),H20) -> 0 | K20: =J20/1000 -> 0
A21: HU | B21: Hungary | C21: 56.219604 | D21: 17.427106 | E21: 0 | F21: 8.512035 | G21: =MIN(D21,E21+F21) -> 8.512035 | H21: =IF(C21=0,0,C21*$H$7/G21) -> 0.99070793 | J21: =IF(ISERROR(H21),INDEX($H$9:$H$35,MATCH(I21,$B$9:$B$35,0)),H21) -> 0.99070793 | K21: =J21/1000 -> 0.00099070793
A22: IE | B22: Ireland | C22: 0 | D22: 0 | E22: 0 | F22: 0 | G22: =MIN(D22,E22+F22) -> 0 | H22: =IF(C22=0,0,C22*$H$7/G22) -> 0 | I22: United Kingdom | J22: =IF(ISERROR(H22),INDEX($H$9:$H$35,MATCH(I22,$B$9:$B$35,0)),H22) -> 0 | K22: =J22/1000 -> 0
A23: IT | B23: Italy | C23: 594.38915 | D23: 89.163863 | E23: 21.892779 | F23: 39.606127 | G23: =MIN(D23,E23+F23) -> 61.498906 | H23: =IF(C23=0,0,C23*$H$7/G23) -> 1.4497554 | J23: =IF(ISERROR(H23),INDEX($H$9:$H$35,MATCH(I23,$B$9:$B$35,0)),H23) -> 1.4497554 | K23: =J23/1000 -> 0.0014497554
A24: LT | B24: Lithuania | C24: 0 | D24: 0 | E24: 0 | F24: 0 | G24: =MIN(D24,E24+F24) -> 0 | H24: =IF(C24=0,0,C24*$H$7/G24) -> 0 | I24: Denmark | J24: =IF(ISERROR(H24),INDEX($H$9:$H$35,MATCH(I24,$B$9:$B$35,0)),H24) -> 0 | K24: =J24/1000 -> 0
A25: LU | B25: Luxembourg | C25: 0 | D25: 0 | E25: 0 | F25: 0 | G25: =MIN(D25,E25+F25) -> 0 | H25: =IF(C25=0,0,C25*$H$7/G25) -> 0 | I25: Germany | J25: =IF(ISERROR(H25),INDEX($H$9:$H$35,MATCH(I25,$B$9:$B$35,0)),H25) -> 0 | K25: =J25/1000 -> 0
A26: LV | B26: Latvia | C26: 0 | D26: 0 | E26: 0 | F26: 0 | G26: =MIN(D26,E26+F26) -> 0 | H26: =IF(C26=0,0,C26*$H$7/G26) -> 0 | I26: Denmark | J26: =IF(ISERROR(H26),INDEX($H$9:$H$35,MATCH(I26,$B$9:$B$35,0)),H26) -> 0 | K26: =J26/1000 -> 0
A27: MT | B27: Malta | C27: 0 | D27: 0 | E27: 0 | F27: 0 | G27: =MIN(D27,E27+F27) -> 0 | H27: =IF(C27=0,0,C27*$H$7/G27) -> 0 | I27: Denmark | J27: =IF(ISERROR(H27),INDEX($H$9:$H$35,MATCH(I27,$B$9:$B$35,0)),H27) -> 0 | K27: =J27/1000 -> 0
A28: NL | B28: Netherlands | C28: 453.21612 | D28: 51.772429 | E28: 3.2326741 | F28: 37.199125 | G28: =MIN(D28,E28+F28) -> 40.431799 | H28: =IF(C28=0,0,C28*$H$7/G28) -> 1.6814097 | J28: =IF(ISERROR(H28),INDEX($H$9:$H$35,MATCH(I28,$B$9:$B$35,0)),H28) -> 1.6814097 | K28: =J28/1000 -> 0.0016814097
A29: PL | B29: Poland | C29: 288.87536 | D29: 147.19291 | E29: 0 | F29: 16.571772 | G29: =MIN(D29,E29+F29) -> 16.571772 | H29: =IF(C29=0,0,C29*$H$7/G29) -> 2.6147658 | J29: =IF(ISERROR(H29),INDEX($H$9:$H$35,MATCH(I29,$B$9:$B$35,0)),H29) -> 2.6147658 | K29: =J29/1000 -> 0.0026147658
A30: PT | B30: Portugal | C30: 0 | D30: 17.106395 | E30: 0 | F30: 0 | G30: =MIN(D30,E30+F30) -> 0 | H30: =IF(C30=0,0,C30*$H$7/G30) -> 0 | I30: Spain | J30: =IF(ISERROR(H30),INDEX($H$9:$H$35,MATCH(I30,$B$9:$B$35,0)),H30) -> 0 | K30: =J30/1000 -> 0
A31: RO | B31: Romania | C31: 280.11736 | D31: 43.21647 | E31: 0 | F31: 87.527352 | G31: =MIN(D31,E31+F31) -> 43.21647 | H31: =IF(C31=0,0,C31*$H$7/G31) -> 0.97225907 | J31: =IF(ISERROR(H31),INDEX($H$9:$H$35,MATCH(I31,$B$9:$B$35,0)),H31) -> 0.97225907 | K31: =J31/1000 -> 0.00097225907
A32: SE | B32: Sweden | C32: 0 | D32: 0 | E32: 0 | F32: 0 | G32: =MIN(D32,E32+F32) -> 0 | H32: =IF(C32=0,0,C32*$H$7/G32) -> 0 | I32: Denmark | J32: =IF(ISERROR(H32),INDEX($H$9:$H$35,MATCH(I32,$B$9:$B$35,0)),H32) -> 0 | K32: =J32/1000 -> 0
A33: SI | B33: Slovenia | C33: 0 | D33: 5.6767865 | E33: 0 | F33: 0 | G33: =MIN(D33,E33+F33) -> 0 | H33: =IF(C33=0,0,C33*$H$7/G33) -> 0 | I33: Poland | J33: =IF(ISERROR(H33),INDEX($H$9:$H$35,MATCH(I33,$B$9:$B$35,0)),H33) -> 0 | K33: =J33/1000 -> 0
A34: SK | B34: Slovakia | C34: 0 | D34: 16.205008 | E34: 0 | F34: 0 | G34: =MIN(D34,E34+F34) -> 0 | H34: =IF(C34=0,0,C34*$H$7/G34) -> 0 | I34: Poland | J34: =IF(ISERROR(H34),INDEX($H$9:$H$35,MATCH(I34,$B$9:$B$35,0)),H34) -> 0 | K34: =J34/1000 -> 0
A35: UK | B35: United Kingdom | C35: 1617.9977 | D35: 173.18107 | E35: 155.36105 | F35: 159.73742 | G35: =MIN(D35,E35+F35) -> 173.18107 | H35: =IF(C35=0,0,C35*$H$7/G35) -> 1.4014214 | J35: =IF(ISERROR(H35),INDEX($H$9:$H$35,MATCH(I35,$B$9:$B$35,0)),H35) -> 1.4014214 | K35: =J35/1000 -> 0.0014014214
A39: {=TRANSPOSE(A9:A35)} -> AT | B39: BE | C39: BG | D39: CY | E39: CZ | F39: DE | G39: DK | H39: EE | I39: ES | J39: FI | K39: FR | L39: GR | M39: HU | N39: IE | O39: IT | P39: LT | Q39: LU | R39: LV | S39: MT | T39: NL | U39: PL | V39: PT | W39: RO | X39: SE | Y39: SI | Z39: SK | AA39: UK
A40: {=TRANSPOSE(K9:K35)} -> 0 | B40: 0 | C40: 0 | D40: 0 | E40: 0 | F40: 0.0013237097 | G40: 0.0064339897 | H40: 0 | I40: 0.0020136993 | J40: 0 | K40: 0.0045738976 | L40: 0 | M40: 0.00099070793 | N40: 0 | O40: 0.0014497554 | P40: 0 | Q40: 0 | R40: 0 | S40: 0 | T40: 0.0016814097 | U40: 0.0026147658 | V40: 0 | W40: 0.00097225907 | X40: 0 | Y40: 0 | Z40: 0 | AA40: 0.0014014214

Sheet FillData
B2: ~TFM_Fill-R: w=Input; Hcol=Region
B3: TimeSlice | C3: LimType | D3: Attribute | E3: Year | F3: AllRegions | G3: Pset_CI | H3: Pset_PN | I3: Pset_CO | J3: Cset_CN
D4: INPUT | F4: 1 | G4: IND___ | J4: IND___, M*, I*HTH
B7: ~TFM_Fill-R: w=Output; Hcol=Region
B8: TimeSlice | C8: LimType | D8: Attribute | E8: Year | F8: AllRegions | G8: Pset_CI | H8: Pset_PN | I8: Pset_CO | J8: Cset_CN
D9: OUTPUT | F9: 1 | G9: IND___ | J9: I*,M*,G*

Sheet Input
A1: scenario | B1: attribute | C1: process | D1: commodity | E1: lim_type | F1: time_slice | G1: year | H1: commodity_group | I1: currency | J1: stage | K1: sow | L1: AL | M1: AT | N1: BA | O1: BE | P1: BG | Q1: CH | R1: CY | S1: CZ | T1: DE | U1: DK | V1: EE | W1: EL | X1: ES | Y1: FI | Z1: FR | AA1: HR | AB1: HU | AC1: IE | AD1: IS | AE1: IT | AF1: KS | AG1: LT | AH1: LU | AI1: LV | AJ1: ME | AK1: MK | AL1: MT | AM1: NL | AN1: NO | AO1: PL | AP1: PT | AQ1: RO | AR1: RS | AS1: SE | AT1: SI | AU1: SK | AV1: UK | AW1: year2
A2: BASE | B2: INPUT | C2: IALFINPRO00 | D2: IALHTH | E2: - | F2: ANNUAL | G2: 2010 | H2: - | I2: - | J2: - | K2: - | Y2: 5 | AW2: -
A3: BASE | B3: INPUT | C3: IALFINPRO00 | D3: INDELC | E3: - | F3: ANNUAL | G3: 2010 | H3: - | I3: - | J3: - | K3: - | L3: 10 | M3: 1.1496393 | N3: 10 | O3: 10 | P3: 10 | Q3: 8.5623392 | R3: 10 | S3: 10 | T3: 1.368 | U3: 10 | V3: 10 | W3: 15 | X3: 10 | Y3: 10 | Z3: 0.021171843 | AA3: 2.18 | AB3: 10 | AC3: 10 | AD3: 10 | AE3: 4 | AF3: 10 | AG3: 10 | AH3: 10 | AI3: 10 | AJ3: 10 | AK3: 10 | AL3: 10 | AM3: 10 | AN3: 10 | AO3: 10 | AP3: 10 | AQ3: 10 | AR3: 10 | AS3: 14.983497 | AT3: 10 | AU3: 10 | AV3: 10 | AW3: -
A4: BASE | B4: INPUT | C4: IALFINPRO00 | D4: INDGAS | E4: - | F4: ANNUAL | G4: 2010 | H4: - | I4: - | J4: - | K4: - | L4: 4.983497 | M4: 4.264562 | N4: 0 | O4: 4.983497 | P4: 4.983497 | Q4: 5.4402264 | R4: 4.983497 | S4: 8.1611958 | T4: 6.1 | U4: 4.983497 | V4: 4.983497 | W4: 10 | X4: 4.983497 | Y4: 0 | Z4: 0.10196973 | AA4: 0 | AB4: 4.983497 | AC4: 4.983497 | AD4: 0 | AE4: 4.4422105 | AF4: 4.983497 | AG4: 4.983497 | AH4: 4.983497 | AI4: 4.983497 | AJ4: 0 | AK4: 4.983497 | AL4: 4.983497 | AM4: 4.983497 | AN4: 0 | AO4: 4.983497 | AP4: 4.983497 | AQ4: 4.983497 | AR4: 4.983497 | AS4: 0 | AT4: 4.983497 | AU4: 3 | AV4: 4.983497 | AW4: -
A5: BASE | B5: INPUT | C5: IALFINPRO00 | D5: INDLFO | E5: - | F5: ANNUAL | G5: 2010 | H5: - | I5: - | J5: - | K5: - | L5: 0.034 | M5: 0 | N5: 0.034 | O5: 0.034 | P5: 0.034 | Q5: 0.034 | R5: 0.034 | S5: 0.034 | T5: 0.034 | U5: 0.034 | V5: 0.034 | W5: 0.034 | X5: 0.034 | Y5: 0.034 | Z5: 0.03427138 | AA5: 0.034 | AB5: 0.034 | AC5: 0.034 | AD5: 0.034 | AE5: 0.034 | AF5: 0.034 | AG5: 0.034 | AH5: 0.034 | AI5: 0.034 | AJ5: 0.034 | AK5: 0.034 | AL5: 0.034 | AM5: 0 | AN5: 0.034 | AO5: 0.034 | AP5: 0.034 | AQ5: 0.034 | AR5: 0.034 | AS5: 0.034 | AT5: 0.034 | AU5: 0 | AV5: 0.034 | AW5: -
A6: BASE | B6: INPUT | C6: IALFINPRO00 | D6: MALCAL | E6: - | F6: ANNUAL | G6: 2010 | H6: - | I6: - | J6: - | K6: - | L6: 1 | M6: 1 | N6: 1 | O6: 1 | P6: 1 | Q6: 1 | R6: 1 | S6: 1 | T6: 1 | U6: 1 | V6: 1 | W6: 1 | X6: 1 | Y6: 1 | Z6: 1 | AA6: 1 | AB6: 1 | AC6: 1 | AD6: 1 | AE6: 1 | AF6: 1 | AG6: 1 | AH6: 1 | AI6: 1 | AJ6: 1 | AK6: 1 | AL6: 1 | AM6: 1 | AN6: 1 | AO6: 1 | AP6: 1 | AQ6: 1 | AR6: 1 | AS6: 1 | AT6: 1 | AU6: 1 | AV6: 1 | AW6: -
A7: BASE | B7: INPUT | C7: IALHAHEPF00 | D7: INDELC | E7: - | F7: ANNUAL | G7: 2010 | H7: - | I7: - | J7: - | K7: - | L7: 35.2 | M7: 35.2 | N7: 35.2 | O7: 35.2 | P7: 35.2 | Q7: 35.2 | R7: 35.2 | S7: 35.2 | T7: 35.2 | U7: 35.2 | V7: 35.2 | W7: 35.2 | X7: 35.2 | Y7: 35.2 | Z7: 35.2 | AA7: 35.2 | AB7: 35.2 | AC7: 35.2 | AD7: 35.2 | AE7: 35.2 | AF7: 35.2 | AG7: 35.2 | AH7: 35.2 | AI7: 35.2 | AJ7: 35.2 | AK7: 35.2 | AL7: 35.2 | AM7: 35.2 | AN7: 35.2 | AO7: 35.2 | AP7: 35.2 | AQ7: 35.2 | AR7: 35.2 | AS7: 35.536 | AT7: 35.2 | AU7: 35.2 | AV7: 35.2 | AW7: -
A8: BASE | B8: INPUT | C8: IALHAHEPF00 | D8: INDGAS | E8: - | F8: ANNUAL | G8: 2010 | H8: - | I8: - | J8: - | K8: - | L8: 3.36 | M8: 3.36 | N8: 3.36 | O8: 3.36 | P8: 3.36 | Q8: 3.36 | R8: 3.36 | S8: 3.36 | T8: 3.36 | U8: 3.36 | V8: 3.36 | W8: 3.36 | X8: 3.36 | Y8: 3.36 | Z8: 3.36 | AA8: 3.36 | AB8: 3.36 | AC8: 3.36 | AD8: 3.36 | AE8: 3.36 | AF8: 3.36 | AG8: 3.36 | AH8: 3.36 | AI8: 3.36 | AJ8: 3.36 | AK8: 3.36 | AL8: 3.36 | AM8: 3.36 | AN8: 3.36 | AO8: 3.36 | AP8: 3.36 | AQ8: 3.36 | AR8: 3.36 | AS8: 3.024 | AT8: 3.36 | AU8: 3.36 | AV8: 3.36 | AW8: -
A9: BASE | B9: INPUT | C9: IALHAHEPF00 | D9: INDLFO | E9: - | F9: ANNUAL | G9: 2010 | H9: - | I9: - | J9: - | K9: - | L9: 8 | M9: 8 | N9: 8 | O9: 8 | P9: 8 | Q9: 8 | R9: 8 | S9: 8 | T9: 8 | U9: 8 | V9: 8 | W9: 8 | X9: 8 | Y9: 8 | Z9: 8 | AA9: 8 | AB9: 8 | AC9: 8 | AD9: 8 | AE9: 8 | AF9: 8 | AG9: 8 | AH9: 8 | AI9: 8 | AJ9: 8 | AK9: 8 | AL9: 8 | AM9: 8 | AN9: 8 | AO9: 8 | AP9: 8 | AQ9: 8 | AR9: 8 | AS9: 8 | AT9: 8 | AU9: 8 | AV9: 8 | AW9: -
A10: BASE | B10: INPUT | C10: IALHAHEPF00 | D10: MALBAU | E10: - | F10: ANNUAL | G10: 2010 | H10: - | I10: - | J10: - | K10: - | L10: 1.6 | M10: 1.6 | N10: 1.6 | O10: 1.6 | P10: 1.6 | Q10: 1.6 | R10: 1.6 | S10: 1.6 | T10: 1.6 | U10: 1.6 | V10: 1.6 | W10: 1.6 | X10: 1.6 | Y10: 1.6 | Z10: 1.6 | AA10: 1.6 | AB10: 1.6 | AC10: 1.6 | AD10: 1.6 | AE10: 1.6 | AF10: 1.6 | AG10: 1.6 | AH10: 1.6 | AI10: 1.6 | AJ10: 1.6 | AK10: 1.6 | AL10: 1.6 | AM10: 1.6 | AN10: 1.6 | AO10: 1.6 | AP10: 1.6 | AQ10: 1.6 | AR10: 1.6 | AS10: 1.6 | AT10: 1.6 | AU10: 1.6 | AV10: 1.6 | AW10: -
A11: BASE | B11: INPUT | C11: IALHAHEPF00 | D11: MALCAL | E11: - | F11: ANNUAL | G11: 2010 | H11: - | I11: - | J11: - | K11: - | L11: 1 | M11: 1 | N11: 1 | O11: 1 | P11: 1 | Q11: 1 | R11: 1 | S11: 1 | T11: 1 | U11: 1 | V11: 1 | W11: 1 | X11: 1 | Y11: 1 | Z11: 1 | AA11: 1 | AB11: 1 | AC11: 1 | AD11: 1 | AE11: 1 | AF11: 1 | AG11: 1 | AH11: 1 | AI11: 1 | AJ11: 1 | AK11: 1 | AL11: 1 | AM11: 1 | AN11: 1 | AO11: 1 | AP11: 1 | AQ11: 1 | AR11: 1 | AS11: 1 | AT11: 1 | AU11: 1 | AV11: 1 | AW11: -
A12: BASE | B12: INPUT | C12: IALHAHERG00 | D12: INDELC | E12: - | F12: ANNUAL | G12: 2010 | H12: - | I12: - | J12: - | K12: - | L12: 39.84 | M12: 39.84 | N12: 39.84 | O12: 39.84 | P12: 39.84 | Q12: 39.84 | R12: 39.84 | S12: 39.84 | T12: 39.84 | U12: 39.84 | V12: 39.84 | W12: 39.84 | X12: 39.84 | Y12: 39.84 | Z12: 39.84 | AA12: 39.84 | AB12: 39.84 | AC12: 39.84 | AD12: 39.84 | AE12: 39.84 | AF12: 39.84 | AG12: 39.84 | AH12: 39.84 | AI12: 39.84 | AJ12: 39.84 | AK12: 39.84 | AL12: 39.84 | AM12: 39.84 | AN12: 39.84 | AO12: 39.84 | AP12: 39.84 | AQ12: 39.84 | AR12: 39.84 | AS12: 40.176 | AT12: 39.84 | AU12: 39.84 | AV12: 39.84 | AW12: -
A13: BASE | B13: INPUT | C13: IALHAHERG00 | D13: INDGAS | E13: - | F13: ANNUAL | G13: 2010 | H13: - | I13: - | J13: - | K13: - | L13: 3.36 | M13: 3.36 | N13: 3.36 | O13: 3.36 | P13: 3.36 | Q13: 3.36 | R13: 3.36 | S13: 3.36 | T13: 3.36 | U13: 3.36 | V13: 3.36 | W13: 3.36 | X13: 3.36 | Y13: 3.36 | Z13: 3.36 | AA13: 3.36 | AB13: 3.36 | AC13: 3.36 | AD13: 3.36 | AE13: 3.36 | AF13: 3.36 | AG13: 3.36 | AH13: 3.36 | AI13: 3.36 | AJ13: 3.36 | AK13: 3.36 | AL13: 3.36 | AM13: 13.68 | AN13: 3.36 | AO13: 3.36 | AP13: 3.36 | AQ13: 3.36 | AR13: 3.36 | AS13: 3.024 | AT13: 3.36 | AU13: 3.36 | AV13: 3.36 | AW13: -
A14: BASE | B14: INPUT | C14: IALHAHERG00 | D14: INDLFO | E14: - | F14: ANNUAL | G14: 2010 | H14: - | I14: - | J14: - | K14: - | L14: 10.32 | M14: 10.32 | N14: 10.32 | O14: 10.32 | P14: 10.32 | Q14: 10.32 | R14: 10.32 | S14: 10.32 | T14: 10.32 | U14: 10.32 | V14: 10.32 | W14: 10.32 | X14: 10.32 | Y14: 10.32 | Z14: 10.32 | AA14: 10.32 | AB14: 10.32 | AC14: 10.32 | AD14: 10.32 | AE14: 10.32 | AF14: 10.32 | AG14: 10.32 | AH14: 10.32 | AI14: 10.32 | AJ14: 10.32 | AK14: 10.32 | AL14: 10.32 | AM14: 0 | AN14: 10.32 | AO14: 10.32 | AP14: 10.32 | AQ14: 10.32 | AR14: 10.32 | AS14: 10.32 | AT14: 10.32 | AU14: 10.32 | AV14: 10.32 | AW14: -
... A78: BASE | B78: INPUT | C78: ICMDRYPRD00 | D78: MCMCLK | E78: - | F78: ANNUAL | G78: 2010 | H78: - | I78: - | J78: - | K78: - | L78: 1 | M78: 1 | N78: 1 | O78: 1 | P78: 1 | Q78: 1 | R78: 1 | S78: 1 | T78: 1 | U78: 1 | V78: 1 | W78: 1 | X78: 1 | Y78: 1 | Z78: 1 | AA78: 1 | AB78: 1 | AC78: 1 | AD78: 1 | AE78: 1 | AF78: 1 | AG78: 1 | AH78: 1 | AI78: 1 | AJ78: 1 | AK78: 1 | AL78: 1 | AM78: 1 | AN78: 1 | AO78: 1 | AP78: 1 | AQ78: 1 | AR78: 1 | AS78: 1 | AT78: 1 | AU78: 1 | AV78: 1 | AW78: -
A79: BASE | B79: INPUT | C79: ICMFINPRO00 | D79: INDELC | E79: - | F79: ANNUAL | G79: 2010 | H79: - | I79: - | J79: - | K79: - | L79: 0.23801653 | M79: 1.4786536 | P79: 0.9624872 | Q79: 1 | R79: 0.17651073 | S79: 0.84664979 | T79: 0.7354 | U79: 0.89981569 | V79: 1 | W79: 0.12195141 | X79: 0.165 | Y79: 2.3107824 | Z79: 0.75328215 | AA79: 0.17 | AB79: 0.67049056 | AC79: 0.342 | AK79: 0.425 | AN79: 1.5 | AP79: 0.234 | AQ79: 0.814469 | AT79: 3.4 | AU79: 0.53939018 | AV79: 0.35864858 | AW79: -
A80: BASE | B80: INPUT | C80: ICMFINPRO00 | D80: INDLFO | E80: - | F80: ANNUAL | G80: 2010 | H80: - | I80: - | J80: - | K80: - | S80: 0.047 | U80: 0.047577273 | W80: 0.01004832 | AB80: 0.059811429 | AC80: 0.014276988 | AK80: 0.097 | AM80: 0.083333333 | AN80: 0.5 | AP80: 0.137 | AQ80: 0.049834352 | AV80: 0.65375404 | AW80: -
A81: BASE | B81: INPUT | C81: ICMFINPRO00 | D81: MCMCLK | E81: - | F81: ANNUAL | G81: 2010 | H81: - | I81: - | J81: - | K81: - | L81: 0.91632231 | M81: 0.38807121 | P81: 0.76685124 | Q81: 0.76685124 | R81: 0.76685124 | S81: 0.72374474 | T81: 0.77171384 | U81: 0.76685124 | V81: 0.76685124 | W81: 0.76685124 | X81: 0.76685124 | Y81: 0.5190686 | Z81: 0.76685124 | AA81: 0.76685124 | AB81: 0.90983417 | AC81: 0.76685124 | AK81: 0.76685124 | AM81: 0.48295335 | AN81: 0.76685124 | AP81: 0.7949401 | AQ81: 0.82899902 | AT81: 0.76685124 | AU81: 0.67243898 | AV81: 0.82711066 | AW81: -
A82: BASE | B82: INPUT | C82: ICMFINPRO00 | D82: MISBFS | E82: - | F82: ANNUAL | G82: 2010 | H82: - | I82: - | J82: - | K82: - | L82: 0.083677686 | M82: 0.61192879 | P82: 0.23314876 | Q82: 0.23314876 | R82: 0.23314876 | S82: 0.27625526 | T82: 0.22828616 | U82: 0.23314876 | V82: 0.23314876 | W82: 0.23314876 | X82: 0.015455276 | Y82: 0.4809314 | Z82: 0.0081646923 | AA82: 0.23314876 | AB82: 0.090165825 | AC82: 0.23314876 | AK82: 0.23314876 | AM82: 0.51704665 | AN82: 0.034749 | AP82: 0.23314876 | AQ82: 0.17100098 | AT82: 0.23314876 | AU82: 0.32756102 | AV82: 0.17288934 | AW82: -
A83: BASE | B83: INPUT | C83: ICMWETPRD00 | D83: INDELC | E83: - | F83: ANNUAL | G83: 2010 | H83: - | I83: - | J83: - | K83: - | L83: 0.3 | M83: 0.3 | N83: 0.3 | O83: 0.24 | P83: 0.3 | Q83: 0.3 | R83: 0.3 | S83: 0.3 | T83: 0.3 | U83: 0.3 | V83: 0.3 | W83: 0.3 | X83: 0.3 | Y83: 0.3 | Z83: 0.3 | AA83: 0.3 | AB83: 0.3 | AC83: 0.3 | AD83: 0.3 | AE83: 0.3 | AF83: 0.3 | AG83: 0.3 | AH83: 0.3 | AI83: 0.3 | AJ83: 0.3 | AK83: 0.3 | AL83: 0.3 | AM83: 0.3 | AN83: 0.3 | AO83: 0.3 | AP83: 0.3 | AQ83: 0.3 | AR83: 0.3 | AS83: 0.3 | AT83: 0.3 | AU83: 0.3 | AV83: 0.3 | AW83: -
A84: BASE | B84: INPUT | C84: ICMWETPRD00 | D84: INDHFO | E84: - | F84: ANNUAL | G84: 2010 | H84: - | I84: - | J84: - | K84: - | L84: 6 | M84: 6 | N84: 6 | O84: 4.8 | P84: 6 | Q84: 6 | R84: 6 | S84: 6 | T84: 6 | U84: 6 | V84: 6 | W84: 6 | X84: 6 | Y84: 6 | Z84: 6 | AA84: 6 | AB84: 6 | AC84: 6 | AD84: 6 | AE84: 6 | AF84: 6 | AG84: 6 | AH84: 6 | AI84: 6 | AJ84: 6 | AK84: 6 | AL84: 6 | AM84: 6 | AN84: 6 | AO84: 6 | AP84: 6 | AQ84: 6 | AR84: 6 | AS84: 6 | AT84: 6 | AU84: 6 | AV84: 6 | AW84: -
A85: BASE | B85: INPUT | C85: ICMWETPRD00 | D85: MCMCLK | E85: - | F85: ANNUAL | G85: 2010 | H85: - | I85: - | J85: - | K85: - | L85: 1 | M85: 1 | N85: 1 | O85: 1 | P85: 1 | Q85: 1 | R85: 1 | S85: 1 | T85: 1 | U85: 1 | V85: 1 | W85: 1 | X85: 1 | Y85: 1 | Z85: 1 | AA85: 1 | AB85: 1 | AC85: 1 | AD85: 1 | AE85: 1 | AF85: 1 | AG85: 1 | AH85: 1 | AI85: 1 | AJ85: 1 | AK85: 1 | AL85: 1 | AM85: 1 | AN85: 1 | AO85: 1 | AP85: 1 | AQ85: 1 | AR85: 1 | AS85: 1 | AT85: 1 | AU85: 1 | AV85: 1 | AW85: -
A86: BASE | B86: INPUT | C86: ICUFINPRO00 | D86: INDELC | E86: - | F86: ANNUAL | G86: 2010 | H86: - | I86: - | J86: - | K86: - | L86: 1.6 | M86: 1.6 | N86: 0 | O86: 1.6 | P86: 1.6 | Q86: 1.6 | R86: 1.6 | S86: 1.6 | T86: 1.6 | U86: 1.6 | V86: 1.6 | W86: 1.6 | X86: 1.6 | Y86: 1.6 | Z86: 1.6 | AA86: 1.6 | AB86: 1.6 | AC86: 1.6 | AD86: 1.6 | AE86: 1.6 | AF86: 1.6 | AG86: 1.6 | AH86: 1.6 | AI86: 1.6 | AJ86: 1.6 | AK86: 1.6 | AL86: 1.6 | AM86: 1.6 | AN86: 0 | AO86: 1.6 | AP86: 1.6 | AQ86: 1.6 | AR86: 1.6 | AS86: 1.6 | AT86: 1.6 | AU86: 1.6 | AV86: 1.6 | AW86: -
A87: BASE | B87: INPUT | C87: ICUFINPRO00 | D87: INDHFO | E87: - | F87: ANNUAL | G87: 2010 | H87: - | I87: - | J87: - | K87: - | L87: 2.8 | M87: 2.8 | N87: 2.8 | O87: 2.8 | P87: 2.8 | Q87: 2.8 | R87: 2.8 | S87: 2.8 | T87: 2.8 | U87: 2.8 | V87: 2.8 | W87: 2.8 | X87: 2.8 | Y87: 2.8 | Z87: 2.8 | AA87: 2.8 | AB87: 2.8 | AC87: 2.8 | AD87: 2.8 | AE87: 2.8 | AF87: 2.8 | AG87: 2.8 | AH87: 2.8 | AI87: 2.8 | AJ87: 2.8 | AK87: 2.8 | AL87: 2.8 | AM87: 2.8 | AN87: 2.8 | AO87: 2.52 | AP87: 2.8 | AQ87: 2.8 | AR87: 2.8 | AS87: 2.8 | AT87: 2.8 | AU87: 2.8 | AV87: 2.8 | AW87: -
A88: BASE | B88: INPUT | C88: ICUFINPRO00 | D88: INDLPG | E88: - | F88: ANNUAL | G88: 2010 | H88: - | I88: - | J88: - | K88: - | L88: 2.8 | M88: 2.8 | N88: 2.8 | O88: 2.8 | P88: 2.8 | Q88: 2.8 | R88: 2.8 | S88: 2.8 | T88: 2.8 | U88: 2.8 | V88: 2.8 | W88: 2.8 | X88: 2.8 | Y88: 2.8 | Z88: 2.8 | AA88: 2.8 | AB88: 2.8 | AC88: 2.8 | AD88: 2.8 | AE88: 2.8 | AF88: 2.8 | AG88: 2.8 | AH88: 2.8 | AI88: 2.8 | AJ88: 2.8 | AK88: 2.8 | AL88: 2.8 | AM88: 2.8 | AN88: 2.8 | AO88: 2.8 | AP88: 2.8 | AQ88: 2.8 | AR88: 2.8 | AS88: 2.8 | AT88: 2.8 | AU88: 2.8 | AV88: 2.8 | AW88: -
A89: BASE | B89: INPUT | C89: ICUFINPRO00 | D89: MCUSCR | E89: - | F89: ANNUAL | G89: 2010 | H89: - | I89: - | J89: - | K89: - | L89: 0.04 | M89: 0.04 | N89: 0.04 | O89: 0.04 | P89: 0.04 | Q89: 0.04 | R89: 0.04 | S89: 0.04 | T89: 0.04 | U89: 0.04 | V89: 0.04 | W89: 0.04 | X89: 0.04 | Y89: 0.04 | Z89: 0.04 | AA89: 0.04 | AB89: 0.04 | AC89: 0.04 | AD89: 0.04 | AE89: 0.04 | AF89: 0.04 | AG89: 0.04 | AH89: 0.04 | AI89: 0.04 | AJ89: 0.04 | AK89: 0.04 | AL89: 0.04 | AM89: 0.04 | AN89: 0.04 | AO89: 0.04 | AP89: 0.04 | AQ89: 0.04 | AR89: 0.04 | AS89: 0.04 | AT89: 0.04 | AU89: 0.04 | AV89: 0.04 | AW89: -
A90: BASE | B90: INPUT | C90: ICUFINPRO00 | D90: MCUSCU | E90: - | F90: ANNUAL | G90: 2010 | H90: - | I90: - | J90: - | K90: - | L90: 0.832 | M90: 0.832 | N90: 0.832 | O90: 0.832 | P90: 0.832 | Q90: 0.832 | R90: 0.832 | S90: 0.832 | T90: 0.832 | U90: 0.832 | V90: 0.832 | W90: 0.832 | X90: 0.832 | Y90: 0.832 | Z90: 0.832 | AA90: 0.832 | AB90: 0.832 | AC90: 0.832 | AD90: 0.832 | AE90: 0.832 | AF90: 0.832 | AG90: 0.832 | AH90: 0.832 | AI90: 0.832 | AJ90: 0.832 | AK90: 0.832 | AL90: 0.832 | AM90: 0.832 | AN90: 0.832 | AO90: 0.832 | AP90: 0.832 | AQ90: 0.832 | AR90: 0.832 | AS90: 0.832 | AT90: 0.832 | AU90: 0.832 | AV90: 0.832 | AW90: -
A91: BASE | B91: INPUT | C91: ICUOREPRD00 | D91: ICUHTH | E91: - | F91: ANNUAL | G91: 2010 | H91: - | I91: - | J91: - | K91: - | L91: 0.8 | M91: 0.8 | N91: 0.8 | O91: 0.8 | P91: 0.8 | Q91: 0.8 | R91: 0.8 | S91: 0.8 | T91: 0.8 | U91: 0.8 | V91: 0.8 | W91: 0.8 | X91: 0 | Y91: 3.36 | Z91: 0.8 | AA91: 0.8 | AB91: 0.8 | AC91: 0.8 | AD91: 0.8 | AE91: 0.8 | AF91: 0.8 | AG91: 0.8 | AH91: 0.8 | AI91: 0.8 | AJ91: 0.8 | AK91: 0.8 | AL91: 0.8 | AM91: 0.8 | AN91: 0 | AO91: 0.8 | AP91: 0.8 | AQ91: 0.8 | AR91: 0.8 | AS91: 0.8 | AT91: 0.8 | AU91: 0.8 | AV91: 0.8 | AW91: -
A92: BASE | B92: INPUT | C92: ICUOREPRD00 | D92: INDCOK | E92: - | F92: ANNUAL | G92: 2010 | H92: - | I92: - | J92: - | K92: - | L92: 1.52 | M92: 1.52 | N92: 1.52 | O92: 1.52 | P92: 1.52 | Q92: 1.52 | R92: 1.52 | S92: 1.52 | T92: 1.52 | U92: 1.52 | V92: 1.52 | W92: 1.52 | X92: 1.52 | Y92: 1.52 | Z92: 1.52 | AA92: 1.52 | AB92: 1.52 | AC92: 1.52 | AD92: 1.52 | AE92: 1.52 | AF92: 1.52 | AG92: 1.52 | AH92: 1.52 | AI92: 1.52 | AJ92: 1.52 | AK92: 1.52 | AL92: 1.52 | AM92: 1.52 | AN92: 1.52 | AO92: 1.52 | AP92: 1.52 | AQ92: 1.52 | AR92: 1.52 | AS92: 1.52 | AT92: 1.52 | AU92: 1.52 | AV92: 1.52 | AW92: -
A93: BASE | B93: INPUT | C93: ICUOREPRD00 | D93: INDELC | E93: - | F93: ANNUAL | G93: 2010 | H93: - | I93: - | J93: - | K93: - | L93: 8 | M93: 8 | N93: 8 | O93: 8 | P93: 8 | Q93: 8 | R93: 8 | S93: 8 | T93: 8 | U93: 8 | V93: 8 | W93: 8 | X93: 8 | Y93: 8 | Z93: 8 | AA93: 8 | AB93: 8 | AC93: 8 | AD93: 8 | AE93: 8 | AF93: 8 | AG93: 8 | AH93: 8 | AI93: 8 | AJ93: 8 | AK93: 8 | AL93: 8 | AM93: 8 | AN93: 8 | AO93: 8 | AP93: 8 | AQ93: 8 | AR93: 8 | AS93: 8 | AT93: 8 | AU93: 8 | AV93: 8 | AW93: -
A94: BASE | B94: INPUT | C94: ICUOREPRD00 | D94: INDGAS | E94: - | F94: ANNUAL | G94: 2010 | H94: - | I94: - | J94: - | K94: - | L94: 2.56 | M94: 2.56 | N94: 2.56 | O94: 2.56 | P94: 2.56 | Q94: 2.56 | R94: 2.56 | S94: 2.56 | T94: 2.56 | U94: 2.56 | V94: 2.56 | W94: 2.56 | X94: 3.36 | Y94: 0 | Z94: 2.56 | AA94: 2.56 | AB94: 2.56 | AC94: 2.56 | AD94: 2.56 | AE94: 2.56 | AF94: 2.56 | AG94: 2.56 | AH94: 2.56 | AI94: 2.56 | AJ94: 2.56 | AK94: 2.56 | AL94: 2.56 | AM94: 2.56 | AN94: 2.56 | AO94: 2.56 | AP94: 2.56 | AQ94: 2.56 | AR94: 2.56 | AS94: 2.56 | AT94: 2.56 | AU94: 2.56 | AV94: 2.56 | AW94: -
... A187: BASE | B187: INPUT | C187: IISFECRFR00 | D187: MISRFC | E187: - | F187: ANNUAL | G187: 2010 | H187: - | I187: - | J187: - | K187: - | L187: 1 | M187: 1 | N187: 1 | O187: 1 | P187: 1 | Q187: 1 | R187: 1 | S187: 1 | T187: 1 | U187: 1 | V187: 1 | W187: 1 | X187: 1 | Y187: 1 | Z187: 1 | AA187: 1 | AB187: 1 | AC187: 1 | AD187: 1 | AE187: 1 | AF187: 1 | AG187: 1 | AH187: 1 | AI187: 1 | AJ187: 1 | AK187: 1 | AL187: 1 | AM187: 1 | AN187: 1 | AO187: 1 | AP187: 1 | AQ187: 1 | AR187: 1 | AS187: 1 | AT187: 1 | AU187: 1 | AV187: 1 | AW187: -
A188: BASE | B188: INPUT | C188: IISFINPRO00 | D188: IISHTH | E188: - | F188: ANNUAL | G188: 2010 | H188: - | I188: - | J188: - | K188: - | M188: 0.115 | O188: 0.24 | S188: 0.92 | T188: 0.030574561 | U188: 0.54230769 | Y188: 0.645 | AA188: 0.010526316 | AB188: 0.43921335 | AE188: 0.052735951 | AG188: 0.1 | AK188: 0.63230241 | AN188: 1.29 | AO188: 1 | AQ188: 0.125 | AR188: 0.79904306 | AT188: 0.24422442 | AU188: 0.78 | AV188: 0.027333904 | AW188: -
A189: BASE | B189: INPUT | C189: IISFINPRO00 | D189: INDBFG | E189: - | F189: ANNUAL | G189: 2010 | H189: - | I189: - | J189: - | K189: - | M189: 0.77463658 | N189: 6.2294865 | O189: 0.86528858 | S189: 1.4316331 | T189: 1.0236834 | X189: 0.32537682 | Y189: 0.92 | Z189: 0.39921669 | AB189: 1.6278377 | AM189: 1.1539584 | AN189: 0.9085856 | AO189: 1.2471377 | AQ189: 1.5111639 | AR189: 1.843724 | AS189: 0.17260003 | AU189: 2.4986964 | AV189: 0.94992793 | AW189: -
A190: BASE | B190: INPUT | C190: IISFINPRO00 | D190: INDCOA | E190: - | F190: ANNUAL | G190: 2010 | H190: - | I190: - | J190: - | K190: - | M190: 0.0076325284 | Q190: 0.29 | S190: 0.185 | X190: 0.55 | Z190: 2.31 | AE190: 0.20912856 | AH190: 0.27 | AI190: 0.038 | AJ190: 0.66 | AK190: 12.95 | AN190: 7.6976152 | AO190: 0.22 | AP190: 0.128 | AQ190: 0.0088645549 | AS190: 0.33 | AU190: 0.235 | AV190: 1.1156171 | AW190: -
A191: BASE | B191: INPUT | C191: IISFINPRO00 | D191: INDCOG | E191: - | F191: ANNUAL | G191: 2010 | H191: - | I191: - | J191: - | K191: - | M191: 0.70482931 | O191: 0.78756394 | S191: 0.51022269 | T191: 0.37293441 | X191: 0.20908372 | Y191: 0.88 | Z191: 0.64182186 | AB191: 1.7640175 | AM191: 1.0495271 | AO191: 0.92827919 | AS191: 0.30799672 | AU191: 1.6318252 | AV191: 0.24297425 | AW191: -
A192: BASE | B192: INPUT | C192: IISFINPRO00 | D192: INDCOK | E192: - | F192: ANNUAL | G192: 2010 | H192: - | I192: - | J192: - | K192: - | M192: 2.2711676 | O192: 0.027197775 | Q192: 0.04224812 | S192: 2.2844392 | X192: 0.04524962 | Y192: 4.06 | Z192: 0.029504724 | AA192: 1.2 | AB192: 1.6104741 | AE192: 0.049987868 | AG192: 0.93333333 | AH192: 0.010989011 | AI192: 0.13129771 | AJ192: 0.21 | AK192: 2.5463918 | AN192: 10.55 | AQ192: 0.65 | AR192: 0.0851086 | AS192: 0.55798229 | AT192: 0.37623762 | AU192: 0.21952084 | AW192: -
A193: BASE | B193: INPUT | C193: IISFINPRO00 | D193: INDELC | E193: - | F193: ANNUAL | G193: 2010 | H193: - | I193: - | J193: - | K193: - | M193: 0.5154685 | N193: 2.2810165 | O193: 0.835 | P193: 1.9251075 | Q193: 1.9065714 | S193: 0.88952997 | T193: 1.0417823 | U193: 2.3230769 | W193: 0.39186052 | X193: 1.281418 | Y193: 0.089 | Z193: 0.68482284 | AA193: 5.6631579 | AB193: 0.066738403 | AE193: 0.8523234 | AF193: 11.6445 | AG193: 0.26666667 | AH193: 1.0123705 | AI193: 0.013740458 | AJ193: 0.605 | AK193: 14.058419 | AN193: 31.65 | AO193: 1.015 | AP193: 0.79430422 | AQ193: 4.7991534 | AR193: 0.555 | AS193: 0.21671813 | AT193: 2.3844884 | AU193: 0.42432464 | AW193: -
A194: BASE | B194: INPUT | C194: IISFINPRO00 | D194: INDGAS | E194: - | F194: ANNUAL | G194: 2010 | H194: - | I194: - | J194: - | K194: - | M194: 2.1567721 | N194: 1.6245912 | O194: 2.0302171 | P194: 2.141828 | Q194: 1.6864511 | S194: 2.291706 | T194: 2.1013541 | U194: 2.9653846 | W194: 0.14556672 | X194: 0.22877544 | Y194: 0.09 | Z194: 1.769003 | AA194: 7.7947368 | AB194: 1.4228427 | AE194: 1.9119481 | AH194: 1.8181633 | AI194: 4.098855 | AK194: 3.3934708 | AM194: 1.458355 | AO194: 1.7854979 | AP194: 0.76128793 | AQ194: 4.4413625 | AR194: 0.74007496 | AT194: 4.4686469 | AU194: 1.3785577 | AV194: 1.6543815 | AW194: -
A195: BASE | B195: INPUT | C195: IISFINPRO00 | D195: INDHFO | E195: - | F195: ANNUAL | G195: 2010 | H195: - | I195: - | J195: - | K195: - | L195: 1.1408205 | M195: 1.1566699 | Q195: 0.03006015 | S195: 0.14327255 | T195: 0.1327632 | U195: 0.15769231 | W195: 0.065897858 | X195: 0.84923939 | Y195: 2.485 | AA195: 0.32631579 | AE195: 0.0060299322 | AI195: 1.480916 | AJ195: 3.145 | AK195: 10.635739 | AN195: 0.068093385 | AP195: 0.029607698 | AS195: 0.81792841 | AW195: -
...

Sheet Output
A1: scenario | B1: attribute | C1: process | D1: commodity | E1: lim_type | F1: time_slice | G1: year | H1: commodity_group | I1: currency | J1: stage | K1: sow | L1: AL | M1: AT | N1: BA | O1: BE | P1: BG | Q1: CH | R1: CY | S1: CZ | T1: DE | U1: DK | V1: EE | W1: EL | X1: ES | Y1: FI | Z1: FR | AA1: HR | AB1: HU | AC1: IE | AD1: IS | AE1: IT | AF1: KS | AG1: LT | AH1: LU | AI1: LV | AJ1: ME | AK1: MK | AL1: MT | AM1: NL | AN1: NO | AO1: PL | AP1: PT | AQ1: RO | AR1: RS | AS1: SE | AT1: SI | AU1: SK | AV1: UK | AW1: year2
A2: BASE | B2: OUTPUT | C2: IALFINPRO00 | D2: IAL | E2: - | F2: ANNUAL | G2: 2010 | H2: - | I2: - | J2: - | K2: - | L2: 1 | M2: 1 | N2: 1 | O2: 1 | P2: 1 | Q2: 1 | R2: 1 | S2: 1 | T2: 1 | U2: 1 | V2: 1 | W2: 1 | X2: 1 | Y2: 1 | Z2: 1 | AA2: 1 | AB2: 1 | AC2: 1 | AD2: 1 | AE2: 1 | AF2: 1 | AG2: 1 | AH2: 1 | AI2: 1 | AJ2: 1 | AK2: 1 | AL2: 1 | AM2: 1 | AN2: 1 | AO2: 1 | AP2: 1 | AQ2: 1 | AR2: 1 | AS2: 1 | AT2: 1 | AU2: 1 | AV2: 1 | AW2: -
A3: BASE | B3: OUTPUT | C3: IALFINPRO00 | D3: IALHTH | E3: - | F3: ANNUAL | G3: 2010 | H3: - | I3: - | J3: - | K3: - | Y3: 5 | AW3: -
A4: BASE | B4: OUTPUT | C4: IALFINPRO00 | D4: INDELC | E4: - | F4: ANNUAL | G4: 2010 | H4: - | I4: - | J4: - | K4: - | L4: 10 | M4: 1.1496393 | N4: 10 | O4: 10 | P4: 10 | Q4: 8.5623392 | R4: 10 | S4: 10 | T4: 1.368 | U4: 10 | V4: 10 | W4: 15 | X4: 10 | Y4: 10 | Z4: 0.021171843 | AA4: 2.18 | AB4: 10 | AC4: 10 | AD4: 10 | AE4: 4 | AF4: 10 | AG4: 10 | AH4: 10 | AI4: 10 | AJ4: 10 | AK4: 10 | AL4: 10 | AM4: 10 | AN4: 10 | AO4: 10 | AP4: 10 | AQ4: 10 | AR4: 10 | AS4: 14.983497 | AT4: 10 | AU4: 10 | AV4: 10 | AW4: -
A5: BASE | B5: OUTPUT | C5: IALFINPRO00 | D5: INDGAS | E5: - | F5: ANNUAL | G5: 2010 | H5: - | I5: - | J5: - | K5: - | L5: 4.983497 | M5: 4.264562 | N5: 0 | O5: 4.983497 | P5: 4.983497 | Q5: 5.4402264 | R5: 4.983497 | S5: 8.1611958 | T5: 6.1 | U5: 4.983497 | V5: 4.983497 | W5: 10 | X5: 4.983497 | Y5: 0 | Z5: 0.10196973 | AA5: 0 | AB5: 4.983497 | AC5: 4.983497 | AD5: 0 | AE5: 4.4422105 | AF5: 4.983497 | AG5: 4.983497 | AH5: 4.983497 | AI5: 4.983497 | AJ5: 0 | AK5: 4.983497 | AL5: 4.983497 | AM5: 4.983497 | AN5: 0 | AO5: 4.983497 | AP5: 4.983497 | AQ5: 4.983497 | AR5: 4.983497 | AS5: 0 | AT5: 4.983497 | AU5: 3 | AV5: 4.983497 | AW5: -
A6: BASE | B6: OUTPUT | C6: IALFINPRO00 | D6: INDLFO | E6: - | F6: ANNUAL | G6: 2010 | H6: - | I6: - | J6: - | K6: - | L6: 0.034 | M6: 0 | N6: 0.034 | O6: 0.034 | P6: 0.034 | Q6: 0.034 | R6: 0.034 | S6: 0.034 | T6: 0.034 | U6: 0.034 | V6: 0.034 | W6: 0.034 | X6: 0.034 | Y6: 0.034 | Z6: 0.03427138 | AA6: 0.034 | AB6: 0.034 | AC6: 0.034 | AD6: 0.034 | AE6: 0.034 | AF6: 0.034 | AG6: 0.034 | AH6: 0.034 | AI6: 0.034 | AJ6: 0.034 | AK6: 0.034 | AL6: 0.034 | AM6: 0 | AN6: 0.034 | AO6: 0.034 | AP6: 0.034 | AQ6: 0.034 | AR6: 0.034 | AS6: 0.034 | AT6: 0.034 | AU6: 0 | AV6: 0.034 | AW6: -
A7: BASE | B7: OUTPUT | C7: IALFINPRO00 | D7: MALCAL | E7: - | F7: ANNUAL | G7: 2010 | H7: - | I7: - | J7: - | K7: - | L7: 1 | M7: 1 | N7: 1 | O7: 1 | P7: 1 | Q7: 1 | R7: 1 | S7: 1 | T7: 1 | U7: 1 | V7: 1 | W7: 1 | X7: 1 | Y7: 1 | Z7: 1 | AA7: 1 | AB7: 1 | AC7: 1 | AD7: 1 | AE7: 1 | AF7: 1 | AG7: 1 | AH7: 1 | AI7: 1 | AJ7: 1 | AK7: 1 | AL7: 1 | AM7: 1 | AN7: 1 | AO7: 1 | AP7: 1 | AQ7: 1 | AR7: 1 | AS7: 1 | AT7: 1 | AU7: 1 | AV7: 1 | AW7: -
A8: BASE | B8: OUTPUT | C8: IALHAHEPF00 | D8: INDELC | E8: - | F8: ANNUAL | G8: 2010 | H8: - | I8: - | J8: - | K8: - | L8: 35.2 | M8: 35.2 | N8: 35.2 | O8: 35.2 | P8: 35.2 | Q8: 35.2 | R8: 35.2 | S8: 35.2 | T8: 35.2 | U8: 35.2 | V8: 35.2 | W8: 35.2 | X8: 35.2 | Y8: 35.2 | Z8: 35.2 | AA8: 35.2 | AB8: 35.2 | AC8: 35.2 | AD8: 35.2 | AE8: 35.2 | AF8: 35.2 | AG8: 35.2 | AH8: 35.2 | AI8: 35.2 | AJ8: 35.2 | AK8: 35.2 | AL8: 35.2 | AM8: 35.2 | AN8: 35.2 | AO8: 35.2 | AP8: 35.2 | AQ8: 35.2 | AR8: 35.2 | AS8: 35.536 | AT8: 35.2 | AU8: 35.2 | AV8: 35.2 | AW8: -
A9: BASE | B9: OUTPUT | C9: IALHAHEPF00 | D9: INDGAS | E9: - | F9: ANNUAL | G9: 2010 | H9: - | I9: - | J9: - | K9: - | L9: 3.36 | M9: 3.36 | N9: 3.36 | O9: 3.36 | P9: 3.36 | Q9: 3.36 | R9: 3.36 | S9: 3.36 | T9: 3.36 | U9: 3.36 | V9: 3.36 | W9: 3.36 | X9: 3.36 | Y9: 3.36 | Z9: 3.36 | AA9: 3.36 | AB9: 3.36 | AC9: 3.36 | AD9: 3.36 | AE9: 3.36 | AF9: 3.36 | AG9: 3.36 | AH9: 3.36 | AI9: 3.36 | AJ9: 3.36 | AK9: 3.36 | AL9: 3.36 | AM9: 3.36 | AN9: 3.36 | AO9: 3.36 | AP9: 3.36 | AQ9: 3.36 | AR9: 3.36 | AS9: 3.024 | AT9: 3.36 | AU9: 3.36 | AV9: 3.36 | AW9: -
A10: BASE | B10: OUTPUT | C10: IALHAHEPF00 | D10: INDLFO | E10: - | F10: ANNUAL | G10: 2010 | H10: - | I10: - | J10: - | K10: - | L10: 8 | M10: 8 | N10: 8 | O10: 8 | P10: 8 | Q10: 8 | R10: 8 | S10: 8 | T10: 8 | U10: 8 | V10: 8 | W10: 8 | X10: 8 | Y10: 8 | Z10: 8 | AA10: 8 | AB10: 8 | AC10: 8 | AD10: 8 | AE10: 8 | AF10: 8 | AG10: 8 | AH10: 8 | AI10: 8 | AJ10: 8 | AK10: 8 | AL10: 8 | AM10: 8 | AN10: 8 | AO10: 8 | AP10: 8 | AQ10: 8 | AR10: 8 | AS10: 8 | AT10: 8 | AU10: 8 | AV10: 8 | AW10: -
A11: BASE | B11: OUTPUT | C11: IALHAHEPF00 | D11: MALBAU | E11: - | F11: ANNUAL | G11: 2010 | H11: - | I11: - | J11: - | K11: - | L11: 1.6 | M11: 1.6 | N11: 1.6 | O11: 1.6 | P11: 1.6 | Q11: 1.6 | R11: 1.6 | S11: 1.6 | T11: 1.6 | U11: 1.6 | V11: 1.6 | W11: 1.6 | X11: 1.6 | Y11: 1.6 | Z11: 1.6 | AA11: 1.6 | AB11: 1.6 | AC11: 1.6 | AD11: 1.6 | AE11: 1.6 | AF11: 1.6 | AG11: 1.6 | AH11: 1.6 | AI11: 1.6 | AJ11: 1.6 | AK11: 1.6 | AL11: 1.6 | AM11: 1.6 | AN11: 1.6 | AO11: 1.6 | AP11: 1.6 | AQ11: 1.6 | AR11: 1.6 | AS11: 1.6 | AT11: 1.6 | AU11: 1.6 | AV11: 1.6 | AW11: -
A12: BASE | B12: OUTPUT | C12: IALHAHEPF00 | D12: MALCAL | E12: - | F12: ANNUAL | G12: 2010 | H12: - | I12: - | J12: - | K12: - | L12: 1 | M12: 1 | N12: 1 | O12: 1 | P12: 1 | Q12: 1 | R12: 1 | S12: 1 | T12: 1 | U12: 1 | V12: 1 | W12: 1 | X12: 1 | Y12: 1 | Z12: 1 | AA12: 1 | AB12: 1 | AC12: 1 | AD12: 1 | AE12: 1 | AF12: 1 | AG12: 1 | AH12: 1 | AI12: 1 | AJ12: 1 | AK12: 1 | AL12: 1 | AM12: 1 | AN12: 1 | AO12: 1 | AP12: 1 | AQ12: 1 | AR12: 1 | AS12: 1 | AT12: 1 | AU12: 1 | AV12: 1 | AW12: -
A13: BASE | B13: OUTPUT | C13: IALHAHERG00 | D13: INDELC | E13: - | F13: ANNUAL | G13: 2010 | H13: - | I13: - | J13: - | K13: - | L13: 39.84 | M13: 39.84 | N13: 39.84 | O13: 39.84 | P13: 39.84 | Q13: 39.84 | R13: 39.84 | S13: 39.84 | T13: 39.84 | U13: 39.84 | V13: 39.84 | W13: 39.84 | X13: 39.84 | Y13: 39.84 | Z13: 39.84 | AA13: 39.84 | AB13: 39.84 | AC13: 39.84 | AD13: 39.84 | AE13: 39.84 | AF13: 39.84 | AG13: 39.84 | AH13: 39.84 | AI13: 39.84 | AJ13: 39.84 | AK13: 39.84 | AL13: 39.84 | AM13: 39.84 | AN13: 39.84 | AO13: 39.84 | AP13: 39.84 | AQ13: 39.84 | AR13: 39.84 | AS13: 40.176 | AT13: 39.84 | AU13: 39.84 | AV13: 39.84 | AW13: -
A14: BASE | B14: OUTPUT | C14: IALHAHERG00 | D14: INDGAS | E14: - | F14: ANNUAL | G14: 2010 | H14: - | I14: - | J14: - | K14: - | L14: 3.36 | M14: 3.36 | N14: 3.36 | O14: 3.36 | P14: 3.36 | Q14: 3.36 | R14: 3.36 | S14: 3.36 | T14: 3.36 | U14: 3.36 | V14: 3.36 | W14: 3.36 | X14: 3.36 | Y14: 3.36 | Z14: 3.36 | AA14: 3.36 | AB14: 3.36 | AC14: 3.36 | AD14: 3.36 | AE14: 3.36 | AF14: 3.36 | AG14: 3.36 | AH14: 3.36 | AI14: 3.36 | AJ14: 3.36 | AK14: 3.36 | AL14: 3.36 | AM14: 13.68 | AN14: 3.36 | AO14: 3.36 | AP14: 3.36 | AQ14: 3.36 | AR14: 3.36 | AS14: 3.024 | AT14: 3.36 | AU14: 3.36 | AV14: 3.36 | AW14: -
A15: BASE | B15: OUTPUT | C15: IALHAHERG00 | D15: INDLFO | E15: - | F15: ANNUAL | G15: 2010 | H15: - | I15: - | J15: - | K15: - | L15: 10.32 | M15: 10.32 | N15: 10.32 | O15: 10.32 | P15: 10.32 | Q15: 10.32 | R15: 10.32 | S15: 10.32 | T15: 10.32 | U15: 10.32 | V15: 10.32 | W15: 10.32 | X15: 10.32 | Y15: 10.32 | Z15: 10.32 | AA15: 10.32 | AB15: 10.32 | AC15: 10.32 | AD15: 10.32 | AE15: 10.32 | AF15: 10.32 | AG15: 10.32 | AH15: 10.32 | AI15: 10.32 | AJ15: 10.32 | AK15: 10.32 | AL15: 10.32 | AM15: 0 | AN15: 10.32 | AO15: 10.32 | AP15: 10.32 | AQ15: 10.32 | AR15: 10.32 | AS15: 10.32 | AT15: 10.32 | AU15: 10.32 | AV15: 10.32 | AW15: -
