Workbook
Name _.DMD.: #REF!
Name Cars_12: '[1]TechRep-Doc'!#REF!
Name Cars_12: '[1]TechRep-Doc'!#REF!
Name ddddd: [2]AGR_Fuels!$A$2
Name ddddd: [2]AGR_Fuels!$A$2
Name DISCRATE: '[1]TechRep-Doc'!#REF!
Name DISCRATE: '[1]TechRep-Doc'!#REF!
Name FID_1: [3]AGR_Fuels!$A$2
Name FID_1: [3]AGR_Fuels!$A$2
Name GROWTH: '[1]TechRep-Doc'!#REF!
Name GROWTH: '[1]TechRep-Doc'!#REF!
Name GROWTH_TID: '[1]TechRep-Doc'!#REF!
Name GROWTH_TID: '[1]TechRep-Doc'!#REF!
Name INVCOST: '[1]TechRep-Doc'!#REF!
Name INVCOST: '[1]TechRep-Doc'!#REF!
Name LIFE: '[1]TechRep-Doc'!#REF!
Name LIFE: '[1]TechRep-Doc'!#REF!
Name NAs_CCAR: '[1]TechRep-Doc'!#REF!
Name NAs_CCAR: '[1]TechRep-Doc'!#REF!
Name SETS: '[1]TechRep-Doc'!#REF!
Name SETS: '[1]TechRep-Doc'!#REF!
Name TRTGAB005: '[1]TechRep-Doc'!#REF!
Name TRTGAB005: '[1]TechRep-Doc'!#REF!
Name TRTGAC005: '[1]TechRep-Doc'!#REF!
Name TRTGAC005: '[1]TechRep-Doc'!#REF!
Name Trucks_15: '[1]TechRep-Doc'!#REF!
Name Trucks_15: '[1]TechRep-Doc'!#REF!
Name TSUB_COST: '[1]TechRep-Doc'!#REF!
Name TSUB_COST: '[1]TechRep-Doc'!#REF!
Name x: [1]AGR_Fuels!$A$2
Name x: [1]AGR_Fuels!$A$2

Sheet SUP_Fdstk
C2: ~FI_T | H2: ~FI_Process | Q2: Reason
A3: TechName | B3: Comm-IN | C3: Comm-OUT | D3: EFF | E3: ACTCOST | H3: Sets | I3: TechName | J3: TechDesc | K3: Tact | L3: Tcap | M3: Tslvl | N3: PrimaryCG | O3: Vintage
A4: GENOILCONVERTOR | B4: OILCRD | C4: OILOTH | D4: 1 | E4: 0.01 | H4: * | I4: DUMAFSCOM | J4: Dummy Process to make AFS Feasible | K4: PJ | L4: Pja
C5: OILNEU | H5: * | I5: DUMAFSRSD | J5: Dummy Process to make AFS Feasible | K5: PJ | L5: Pja
C6: OILRFG | H6: PRE | I6: GENOILCONVERTOR | J6: Converting CRD to OTH and NEU | K6: PJ | L6: Pja | Q6: dummy imports due to OILOTH/NEU as they are mainly produced by the refinery that is usually very tight.
C7: OILFDS | I7: GENCOALCONVERTOR | J7: Converting HAR to LIG and BRO | K7: PJ | L7: Pja | Q7: COAHAR trade includes all types of coal trade
H8: * | I8: CONSERVATION | J8: Dummy Process to account for Conservation | K8: PJ | L8: Pja
C9: ~FI_T | H9: * | I9: DUMMYDEMAND | J9: Dummy Process to Increase final energy consumption | K9: PJ | L9: Pja
A10: TechName | B10: Comm-IN | C10: Comm-OUT | D10: EFF | E10: ACTCOST
A11: =I7 -> GENCOALCONVERTOR | B11: COAHAR | C11: COALIG | D11: 1 | E11: 0.01
C12: COABRO | H12: *
H13: Csets | I13: CommName | J13: CommDesc | K13: Unit | L13: LimType | M13: CTSLvl | N13: PeakTS | O13: Ctype
H14: DEM | I14: DUMDEM | J14: Dummy Demand | K14: PJ

Sheet SUP_GasStorage
A3: BY_SubRES - FI_T
D4: ~FI_T: NCAP_BND~FX
B5: TechName | C5: Comm-IN | D5: Comm-Out | E5: S_EFF | F5: Stock | G5: LIFE | H5: INVCOST | I5: ='Storage Data'!N3 -> 2006 | J5: ='Storage Data'!O3 -> 2007 | K5: ='Storage Data'!P3 -> 2009 | L5: ='Storage Data'!Q3 -> 2010 | M5: ='Storage Data'!R3 -> 2011 | N5: ='Storage Data'!S3 -> 2012 | O5: ='Storage Data'!T3 -> 2013 | P5: ='Storage Data'!U3 -> 2014 | ... R5: ='Storage Data'!W3 -> 2016
B6: LNGSTOR-BE | C6: GASLNG | D6: GASLNG | E6: 0.98 | F6: ='Storage Data'!I4 -> 8.892 | G6: 50 | H6: ='Storage Data'!L4 -> 8.6708782 | I6: =IF('Storage Data'!N4="","",'Storage Data'!N4) | J6: =IF('Storage Data'!O4="","",'Storage Data'!O4) | K6: =IF('Storage Data'!P4="","",'Storage Data'!P4) | L6: =IF('Storage Data'!Q4="","",'Storage Data'!Q4) | M6: =IF('Storage Data'!R4="","",'Storage Data'!R4) | N6: =IF('Storage Data'!S4="","",'Storage Data'!S4) | O6: =IF('Storage Data'!T4="","",'Storage Data'!T4) | P6: =IF('Storage Data'!U4="","",'Storage Data'!U4) | ... R6: =IF('Storage Data'!W4="","",'Storage Data'!W4)
B7: LNGSTOR_A-FR | C7: GASLNG | D7: GASLNG | E7: 0.98 | F7: ='Storage Data'!I5 -> 8.424 | G7: 50 | H7: ='Storage Data'!L5 -> 8.6708782 | I7: =IF('Storage Data'!N5="","",'Storage Data'!N5) | J7: =IF('Storage Data'!O5="","",'Storage Data'!O5) | K7: =IF('Storage Data'!P5="","",'Storage Data'!P5) | L7: =IF('Storage Data'!Q5="","",'Storage Data'!Q5) | M7: =IF('Storage Data'!R5="","",'Storage Data'!R5) | N7: =IF('Storage Data'!S5="","",'Storage Data'!S5) | O7: =IF('Storage Data'!T5="","",'Storage Data'!T5) | P7: =IF('Storage Data'!U5="","",'Storage Data'!U5) | ... R7: =IF('Storage Data'!W5="","",'Storage Data'!W5)
B8: LNGSTOR_M-FR | C8: GASLNG | D8: GASLNG | E8: 0.98 | F8: ='Storage Data'!I6 -> 3.51 | G8: 50 | H8: ='Storage Data'!L6 -> 8.6708782 | I8: =IF('Storage Data'!N6="","",'Storage Data'!N6) | J8: =IF('Storage Data'!O6="","",'Storage Data'!O6) | K8: =IF('Storage Data'!P6="","",'Storage Data'!P6) -> 7.722 | L8: =IF('Storage Data'!Q6="","",'Storage Data'!Q6) | M8: =IF('Storage Data'!R6="","",'Storage Data'!R6) | N8: =IF('Storage Data'!S6="","",'Storage Data'!S6) | O8: =IF('Storage Data'!T6="","",'Storage Data'!T6) | P8: =IF('Storage Data'!U6="","",'Storage Data'!U6) | ... R8: =IF('Storage Data'!W6="","",'Storage Data'!W6)
B9: LNGSTOR_W-IT | C9: GASLNG | D9: GASLNG | E9: 0.98 | F9: ='Storage Data'!I7 -> 2.34 | G9: 50 | H9: ='Storage Data'!L7 -> 8.6708782 | I9: =IF('Storage Data'!N7="","",'Storage Data'!N7) | J9: =IF('Storage Data'!O7="","",'Storage Data'!O7) | K9: =IF('Storage Data'!P7="","",'Storage Data'!P7) | L9: =IF('Storage Data'!Q7="","",'Storage Data'!Q7) | M9: =IF('Storage Data'!R7="","",'Storage Data'!R7) -> 3.2058 | N9: =IF('Storage Data'!S7="","",'Storage Data'!S7) | O9: =IF('Storage Data'!T7="","",'Storage Data'!T7) | P9: =IF('Storage Data'!U7="","",'Storage Data'!U7) -> 0.936 | ... R9: =IF('Storage Data'!W7="","",'Storage Data'!W7)
B10: LNGSTOR_E-IT | C10: GASLNG | D10: GASLNG | E10: 0.98 | F10: ='Storage Data'!I8 -> 0 | G10: 50 | H10: ='Storage Data'!L8 -> 8.6708782 | I10: =IF('Storage Data'!N8="","",'Storage Data'!N8) | J10: =IF('Storage Data'!O8="","",'Storage Data'!O8) | K10: =IF('Storage Data'!P8="","",'Storage Data'!P8) | L10: =IF('Storage Data'!Q8="","",'Storage Data'!Q8) -> 7.488 | M10: =IF('Storage Data'!R8="","",'Storage Data'!R8) | N10: =IF('Storage Data'!S8="","",'Storage Data'!S8) -> 7.488 | O10: =IF('Storage Data'!T8="","",'Storage Data'!T8) | P10: =IF('Storage Data'!U8="","",'Storage Data'!U8) | ... R10: =IF('Storage Data'!W8="","",'Storage Data'!W8)
B11: LNGSTOR-GR | C11: GASLNG | D11: GASLNG | E11: 0.98 | F11: ='Storage Data'!I9 -> 3.042 | G11: 50 | H11: ='Storage Data'!L9 -> 8.6708782 | I11: =IF('Storage Data'!N9="","",'Storage Data'!N9) | J11: =IF('Storage Data'!O9="","",'Storage Data'!O9) | K11: =IF('Storage Data'!P9="","",'Storage Data'!P9) | L11: =IF('Storage Data'!Q9="","",'Storage Data'!Q9) | M11: =IF('Storage Data'!R9="","",'Storage Data'!R9) | N11: =IF('Storage Data'!S9="","",'Storage Data'!S9) | O11: =IF('Storage Data'!T9="","",'Storage Data'!T9) | P11: =IF('Storage Data'!U9="","",'Storage Data'!U9) | ... R11: =IF('Storage Data'!W9="","",'Storage Data'!W9)
B12: LNGSTOR-PT | C12: GASLNG | D12: GASLNG | E12: 0.98 | F12: ='Storage Data'!I10 -> 5.616 | G12: 50 | H12: ='Storage Data'!L10 -> 8.6708782 | I12: =IF('Storage Data'!N10="","",'Storage Data'!N10) | J12: =IF('Storage Data'!O10="","",'Storage Data'!O10) | K12: =IF('Storage Data'!P10="","",'Storage Data'!P10) | L12: =IF('Storage Data'!Q10="","",'Storage Data'!Q10) | M12: =IF('Storage Data'!R10="","",'Storage Data'!R10) | N12: =IF('Storage Data'!S10="","",'Storage Data'!S10) -> 3.51 | O12: =IF('Storage Data'!T10="","",'Storage Data'!T10) | P12: =IF('Storage Data'!U10="","",'Storage Data'!U10) | ... R12: =IF('Storage Data'!W10="","",'Storage Data'!W10)
B13: LNGSTOR_M-ES | C13: GASLNG | D13: GASLNG | E13: 0.98 | F13: ='Storage Data'!I11 -> 22.8618 | G13: 50 | H13: ='Storage Data'!L11 -> 8.6708782 | I13: =IF('Storage Data'!N11="","",'Storage Data'!N11) -> 7.02 | J13: =IF('Storage Data'!O11="","",'Storage Data'!O11) | K13: =IF('Storage Data'!P11="","",'Storage Data'!P11) -> 3.276 | L13: =IF('Storage Data'!Q11="","",'Storage Data'!Q11) | M13: =IF('Storage Data'!R11="","",'Storage Data'!R11) | N13: =IF('Storage Data'!S11="","",'Storage Data'!S11) | O13: =IF('Storage Data'!T11="","",'Storage Data'!T11) | P13: =IF('Storage Data'!U11="","",'Storage Data'!U11) -> 14.1102 | ... R13: =IF('Storage Data'!W11="","",'Storage Data'!W11)
B14: LNGSTOR_A-ES | C14: GASLNG | D14: GASLNG | E14: 0.98 | F14: ='Storage Data'!I12 -> 17.784 | G14: 50 | H14: ='Storage Data'!L12 -> 8.6708782 | I14: =IF('Storage Data'!N12="","",'Storage Data'!N12) | J14: =IF('Storage Data'!O12="","",'Storage Data'!O12) -> 7.02 | K14: =IF('Storage Data'!P12="","",'Storage Data'!P12) | L14: =IF('Storage Data'!Q12="","",'Storage Data'!Q12) | M14: =IF('Storage Data'!R12="","",'Storage Data'!R12) -> 10.5417 | N14: =IF('Storage Data'!S12="","",'Storage Data'!S12) -> 3.51 | O14: =IF('Storage Data'!T12="","",'Storage Data'!T12) | P14: =IF('Storage Data'!U12="","",'Storage Data'!U12) | ... R14: =IF('Storage Data'!W12="","",'Storage Data'!W12) -> 7.02
B15: LNGSTOR_W-UK | C15: GASLNG | D15: GASLNG | E15: 0.98 | F15: ='Storage Data'!I13 -> 0 | G15: 50 | H15: ='Storage Data'!L13 -> 8.6708782 | I15: =IF('Storage Data'!N13="","",'Storage Data'!N13) | J15: =IF('Storage Data'!O13="","",'Storage Data'!O13) | K15: =IF('Storage Data'!P13="","",'Storage Data'!P13) -> 30.771 | L15: =IF('Storage Data'!Q13="","",'Storage Data'!Q13) | M15: =IF('Storage Data'!R13="","",'Storage Data'!R13) | N15: =IF('Storage Data'!S13="","",'Storage Data'!S13) | O15: =IF('Storage Data'!T13="","",'Storage Data'!T13) | P15: =IF('Storage Data'!U13="","",'Storage Data'!U13) | ... R15: =IF('Storage Data'!W13="","",'Storage Data'!W13)
B16: LNGSTOR_E-UK | C16: GASLNG | D16: GASLNG | E16: 0.98 | F16: ='Storage Data'!I14 -> 18.72 | G16: 50 | H16: ='Storage Data'!L14 -> 8.6708782 | I16: =IF('Storage Data'!N14="","",'Storage Data'!N14) | J16: =IF('Storage Data'!O14="","",'Storage Data'!O14) | K16: =IF('Storage Data'!P14="","",'Storage Data'!P14) | L16: =IF('Storage Data'!Q14="","",'Storage Data'!Q14) -> 4.68 | M16: =IF('Storage Data'!R14="","",'Storage Data'!R14) | N16: =IF('Storage Data'!S14="","",'Storage Data'!S14) | O16: =IF('Storage Data'!T14="","",'Storage Data'!T14) | P16: =IF('Storage Data'!U14="","",'Storage Data'!U14) | ... R16: =IF('Storage Data'!W14="","",'Storage Data'!W14)
B17: LNGSTOR-NL | C17: GASLNG | D17: GASLNG | E17: 0.98 | F17: ='Storage Data'!I15 -> 0 | G17: 50 | H17: ='Storage Data'!L15 -> 8.6708782 | I17: =IF('Storage Data'!N15="","",'Storage Data'!N15) | J17: =IF('Storage Data'!O15="","",'Storage Data'!O15) | K17: =IF('Storage Data'!P15="","",'Storage Data'!P15) | L17: =IF('Storage Data'!Q15="","",'Storage Data'!Q15) | M17: =IF('Storage Data'!R15="","",'Storage Data'!R15) -> 12.636 | N17: =IF('Storage Data'!S15="","",'Storage Data'!S15) | O17: =IF('Storage Data'!T15="","",'Storage Data'!T15) | P17: =IF('Storage Data'!U15="","",'Storage Data'!U15) -> 4.212 | ... R17: =IF('Storage Data'!W15="","",'Storage Data'!W15)
D20: ~FI_T:
B21: TechName | C21: Comm-IN | D21: Comm-Out | E21: S_EFF | F21: Stock | G21: Stock~2050 | H21: INVCOST | I21: LIFE
B22: NGASTOR-AT | C22: GAS2ST | D22: GAS2ST | E22: 0.98 | F22: ='[4]Storage Data'!L22 -> 164.97 | G22: =F22 -> 164.97 | H22: 50 | I22: 50
B23: NGASTOR-BE | C23: GAS2ST | D23: GAS2ST | E23: 0.98 | F23: ='[4]Storage Data'!L23 -> 26.676 | G23: =F23 -> 26.676 | H23: 50 | I23: 50
B24: NGASTOR-BG | C24: GAS2ST | D24: GAS2ST | E24: 0.98 | F24: ='[4]Storage Data'!L24 -> 13.65 | G24: =F24 -> 13.65 | H24: 50 | I24: 50
B25: NGASTOR-CH | C25: GAS2ST | D25: GAS2ST | E25: 0.98 | F25: ='[4]Storage Data'!L25 -> 0 | G25: =F25 -> 0 | H25: 50 | I25: 50
B26: NGASTOR-CY | C26: GAS2ST | D26: GAS2ST | E26: 0.98 | F26: ='[4]Storage Data'!L26 -> 0 | G26: =F26 -> 0 | H26: 50 | I26: 50
B27: NGASTOR-CZ | C27: GAS2ST | D27: GAS2ST | E27: 0.98 | F27: ='[4]Storage Data'!L27 -> 120.003 | G27: =F27 -> 120.003 | H27: 50 | I27: 50
B28: NGASTOR-DE | C28: GAS2ST | D28: GAS2ST | E28: 0.98 | F28: ='[4]Storage Data'!L28 -> 764.2128 | G28: =F28 -> 764.2128 | H28: 50 | I28: 50
B29: NGASTOR-DK | C29: GAS2ST | D29: GAS2ST | E29: 0.98 | F29: ='[4]Storage Data'!L29 -> 39.039 | G29: =F29 -> 39.039 | H29: 50 | I29: 50
B30: NGASTOR-EE | C30: GAS2ST | D30: GAS2ST | E30: 0.98 | F30: ='[4]Storage Data'!L30 -> 0 | G30: =F30 -> 0 | H30: 50 | I30: 50
B31: NGASTOR-ES | C31: GAS2ST | D31: GAS2ST | E31: 0.98 | F31: ='[4]Storage Data'!L31 -> 161.46 | G31: =F31 -> 161.46 | H31: 50 | I31: 50
B32: NGASTOR-FI | C32: GAS2ST | D32: GAS2ST | E32: 0.98 | F32: ='[4]Storage Data'!L32 -> 0 | G32: =F32 -> 0 | H32: 50 | I32: 50
B33: NGASTOR-FR | C33: GAS2ST | D33: GAS2ST | E33: 0.98 | F33: ='[4]Storage Data'!L33 -> 477.945 | G33: =F33 -> 477.945 | H33: 50 | I33: 50
... B51: NGASTOR-UK | C51: GAS2ST | D51: GAS2ST | E51: 0.98 | F51: ='[4]Storage Data'!L51 -> 168.1017 | G51: =F51 -> 168.1017 | H51: 50 | I51: 50
D54: ~FI_T
B55: TechName | C55: Comm-IN | D55: Comm-OUT | E55: EFF
B56: NGASTOSTOR | C56: GASNAT | D56: GAS2ST | E56: 1
B57: NGASFRSTOR | C57: GAS2ST | D57: GASNAT | E57: 1
B62: BY_SubRES - Process
C63: ~FI_Process
C64: Sets | D64: TechName | E64: TechDesc | F64: Tact | G64: Tcap | H64: Tslvl | I64: PrimaryCG | J64: Vintage
C65: PRE,STGTSS | D65: =B6 -> LNGSTOR-BE | E65: LNG Storage | F65: PJ | G65: PJ-a | H65: SEASON
D66: =B7 -> LNGSTOR_A-FR | E66: LNG Storage | F66: PJ | G66: PJ-a | H66: SEASON
D67: =B8 -> LNGSTOR_M-FR | E67: LNG Storage | F67: PJ | G67: PJ-a | H67: SEASON
...

Sheet TRA_Biofuel
A1: Dummy electricity renewable, biofuel first and second generation import to satisfy the biofuel target
D3: ~FI_T
B4: TechName | C4: Comm-OUT | D4: Comm-IN | E4: ACT_COST
B5: \I:
B6: DUMELCR | C6: =$C$25 -> DUMBioFuelConstr
B7: DUMBIO1 | C7: =$C$25 -> DUMBioFuelConstr
B8: DUMBIO2 | C8: =$C$25 -> DUMBioFuelConstr
B9: DUMELCNR | C9: =$C$25 -> DUMBioFuelConstr
B10: =C20 -> EXPENVZ | D10: TOTCO2 | E10: 1.5
D11: NETSCO2
B14: ~FI_Process
B15: Sets | C15: TechName | D15: TechDesc | E15: Tact | F15: Tcap | G15: Tslvl | H15: PrimaryCG | I15: Vintage
B16: IMP | C16: =B6 -> DUMELCR | D16: Dummy Technology for ELC Renewable TRA road | E16: PJ
C17: =B7 -> DUMBIO1 | D17: Dummy Technology for Bio fuel first generation TRA sector | E17: PJ
C18: =B8 -> DUMBIO2 | D18: Dummy Technology for Bio fuel second generation TRA sector | E18: PJ
C19: =B9 -> DUMELCNR | D19: Dummy Technology for ELC Renewable TRA non-road | E19: PJ
B20: EXP | C20: EXPENVZ | D20: Dummy Export of constrained emissions (IS/NO/CH+BE) | E20: kt
B23: MovedToSysSettings
B24: Csets | C24: CommName | D24: CommDesc | E24: Unit | F24: LimType | G24: CTSLvl | H24: PeakTS | I24: Ctype
B25: NRG | C25: DUMBioFuelConstr | D25: Dummy commodity to model biofuel constraint | E25: PJ

Sheet Storage Data
B1: LNG Storage Capacities
N2: NCAP
A3: COM_CODE_in | B3: COMMODITY_in | C3: COMMODITY_out | D3: COM_CODE_out | E3: PROCESS_CODE | F3: PLANT_COUNTRY | G3: PLANT_NAME | H3: CAP_UNIT | I3: CAPACITY (year - 2005) | J3: PROD_LIFETIME | K3: CONSTR_TIME_yr | L3: CAP_Inv | M3: Availability factor | N3: 2006 | O3: 2007 | P3: 2009 | Q3: 2010 | R3: 2011 | S3: 2012 | T3: 2013 | U3: 2014 | V3: 2015 | W3: 2016
B4: LNG | C4: LNG | D4: LNGSBE | E4: LNGSTOR_BE | F4: Belgium | G4: Belgium | H4: PJ | I4: 8.892 | J4: 50 | L4: 8.6708782 | M4: 1
B5: LNG | C5: LNG | D5: LNGSFR-A | E5: LNGSTOR_FR-A | F5: France | G5: France-Atlantic | H5: PJ | I5: 8.424 | J5: 50 | L5: 8.6708782 | M5: 1
B6: LNG | C6: LNG | D6: LNGSFR-M | E6: LNGSTOR_FR-M | F6: Ffrance | G6: France- Mediterranean | H6: PJ | I6: 3.51 | J6: 50 | L6: 8.6708782 | M6: 1 | P6: 7.722
B7: LNG | C7: LNG | D7: LNGSIT-W | E7: LNGSTOR_IT-W | F7: Italy | G7: Italy-West | H7: PJ | I7: 2.34 | J7: 50 | L7: 8.6708782 | M7: 1 | R7: 3.2058 | U7: 0.936
B8: LNG | C8: LNG | D8: LNGSIT-E | E8: LNGSTOR_IT-E | F8: Italy | G8: Italy-East | H8: PJ | I8: 0 | J8: 50 | L8: 8.6708782 | M8: 1 | Q8: 7.488 | S8: 7.488
B9: LNG | C9: LNG | D9: LNGSGR | E9: LNGSTOR_GR | F9: Greece | G9: Greece | H9: PJ | I9: 3.042 | J9: 50 | L9: 8.6708782 | M9: 1
B10: LNG | C10: LNG | D10: LNGS-PT | E10: LNGSTOR_PT | F10: Portugal | G10: Portugal | H10: PJ | I10: 5.616 | J10: 50 | L10: 8.6708782 | M10: 1 | S10: 3.51
B11: LNG | C11: LNG | D11: LNGSES-M | E11: LNGSTOR_ES-M | F11: Spain | G11: Spain-Mediterranean | H11: PJ | I11: 22.8618 | J11: 50 | L11: 8.6708782 | M11: 1 | N11: 7.02 | P11: 3.276 | U11: 14.1102
B12: LNG | C12: LNG | D12: LNGSES-A | E12: LNGSTOR_ES-A | F12: Spain | G12: Spain-Atlantic | H12: PJ | I12: 17.784 | J12: 50 | L12: 8.6708782 | M12: 1 | O12: 7.02 | R12: 10.5417 | S12: 3.51 | V12: 21.0483 | W12: 7.02
B13: LNG | C13: LNG | D13: LNGSUK-W | E13: LNGSTOR_UK-W | F13: United Kingdom | G13: United Kingdom-West | H13: PJ | I13: 0 | J13: 50 | L13: 8.6708782 | M13: 1 | P13: 30.771
B14: LNG | C14: LNG | D14: LNGSUK-E | E14: LNGSTOR_UK-E | F14: United Kingdom | G14: United Kingdom-East | H14: PJ | I14: 18.72 | J14: 50 | L14: 8.6708782 | M14: 1 | Q14: 4.68
B15: LNG | C15: LNG | D15: LNGSNL | E15: LNGSTOR_NL | F15: Netherlands | G15: Netherlands | H15: PJ | I15: 0 | J15: 50 | L15: 8.6708782 | M15: 1 | R15: 12.636 | U15: 4.212
B19: Dry gas storage
A21: COM_CODE_in | B21: COMMODITY_in | C21: COMMODITY_out | D21: COM_CODE_out | E21: PROCESS_CODE | F21: PLANT_COUNTRY | G21: PLANT_NAME | H21: CAP_UNIT | I21: FLOW_UNIT | J21: STORE_CAPACITY (year - 2005) | K21: STORE_CAPACITY (year - 2007) | L21: STORE_CAPACITY (year - 2009) | M21: DELIV_CAPACITY (year - 2005) | N21: DELIV_CAPACITY (year - 2006) | O21: DELIV_CAPACITY (year - 2009)
A22: GASNAT | B22: Natural gas | C22: Natural gas | D22: GASNAT | E22: NGSTOR_AT | F22: Austria | G22: Austria | H22: PJ | I22: PJ | J22: 109.98 | K22: 159.9 | L22: 164.97 | M22: 469.755 | N22: 683.28 | O22: 695.8068
A23: GASNAT | B23: Natural gas | C23: Natural gas | D23: GASNAT | E23: NGSTOR_BE | F23: Belgium | G23: Belgium | H23: PJ | I23: PJ | J23: 24.765 | K23: 26.52 | L23: 26.676 | M23: 256.23 | N23: 341.64 | O23: 324.558
A24: GASNAT | B24: Natural gas | C24: Natural gas | D24: GASNAT | E24: NGSTOR_BG | F24: Bulgaria | G24: Bulgaria | H24: PJ | I24: PJ | J24: 0 | K24: 39 | L24: 13.65 | M24: 0 | N24: 113.88 | O24: 46.9755
A25: GASNAT | B25: Natural gas | C25: Natural gas | D25: GASNAT | E25: NGSTOR_CH | F25: Switzerland | G25: Switzerland | H25: PJ | I25: PJ | J25: 2.808 | K25: 2.808 | L25: 0 | M25: 28.47 | N25: 28.47 | O25: 0
A26: GASNAT | B26: Natural gas | C26: Natural gas | D26: GASNAT | E26: NGSTOR_CY | F26: Cyprus | G26: Cyprus | H26: PJ | I26: PJ | J26: 0 | K26: 0 | L26: 0 | M26: 0 | N26: 0 | O26: 0
A27: GASNAT | B27: Natural gas | C27: Natural gas | D27: GASNAT | E27: NGSTOR_CZ | F27: Czech Rep. | G27: Czech Rep. | H27: PJ | I27: PJ | J27: 131.664 | K27: 131.664 | L27: 120.003 | M27: 782.925 | N27: 782.925 | O27: 721.7145
A28: GASNAT | B28: Natural gas | C28: Natural gas | D28: GASNAT | E28: NGSTOR_DE | F28: Germany | G28: Germany | H28: PJ | I28: PJ | J28: 743.652 | K28: 776.802 | L28: 764.2128 | M28: 6775.86 | N28: 6690.45 | O28: 4673.0658
A29: GASNAT | B29: Natural gas | C29: Natural gas | D29: GASNAT | E29: NGSTOR_DK | F29: Denmark | G29: Denmark | H29: PJ | I29: PJ | J29: 29.64 | K29: 34.359 | L29: 39.039 | M29: 256.23 | N29: 313.17 | O29: 223.4895
A30: GASNAT | B30: Natural gas | C30: Natural gas | D30: GASNAT | E30: NGSTOR_EE | F30: Estonia | G30: Estonia | H30: PJ | I30: PJ | J30: 0 | K30: 0 | L30: 0 | M30: 0 | N30: 0 | O30: 0
A31: GASNAT | B31: Natural gas | C31: Natural gas | D31: GASNAT | E31: NGSTOR_ES | F31: Spain | G31: Spain | H31: PJ | I31: PJ | J31: 58.5 | K31: 64.701 | L31: 161.46 | M31: 170.82 | N31: 185.055 | O31: 2454.114
A32: GASNAT | B32: Natural gas | C32: Natural gas | D32: GASNAT | E32: NGSTOR_FI | F32: Finland | G32: Finland | H32: PJ | I32: PJ | J32: 0 | K32: 0 | L32: 0 | M32: 0 | N32: 0 | O32: 0
A33: GASNAT | B33: Natural gas | C33: Natural gas | D33: GASNAT | E33: NGSTOR_FR | F33: France | G33: France | H33: PJ | I33: PJ | J33: 456.3 | K33: 456.3 | L33: 477.945 | M33: 2847 | N33: 2847 | O33: 3779.3925
... A51: GASNAT | B51: Natural gas | C51: Natural gas | D51: GASNAT | E51: NGSTOR_UK | F51: United Kingdom | G51: United Kingdom | H51: PJ | I51: PJ | J51: 164.112 | K51: 170.196 | L51: 168.1017 | M51: 1765.14 | N51: 1807.845 | O51: 1365.9906

Sheet SUP
B2: ~COMAGG_R1C2 | E2: ~FI_Process
B3: CommName | C3: TOTCO2 | E3: Sets | F3: TechName | G3: TechDesc | H3: Tact | I3: Tcap | J3: Tslvl | K3: PrimaryCG | L3: Vintage
B4: RSDCO2N | C4: 1 | E4: PRE | F4: Penalty_RenELCQuota | G4: Penalty for not meeting the Renewable ELC production target under Quota system | H4: PJ | I4: PJ
B5: COMCO2N | C5: 1 | E5: PRE | F5: SUP2INDHTH | G5: Mapping SUP and REF HTH to INDHTH | H5: PJ | I5: PJ
B6: AGRCO2N | C6: 1 | E6: IMP | F6: IMPINDGASY | G6: Supply of Gas for IND in IS | H6: PJ | I6: PJ
B7: SE_TRACO2N | C7: 1
B8: INDCO2N | C8: 1
B9: INDCO2P | C9: 1
B10: ELCCO2N | C10: 1
B11: SUPCO2N | C11: 1
B12: SUPCO2P | C12: 1
B13: ELCCO2P | C13: 1
B14: ELCCO2I | C14: 1
I15: ~FI_T
B16: SNKCO2N | C16: -1 | G16: TechName | H16: Comm-IN | I16: Comm-OUT | J16: COST | K16: START | L16: EFF | M16: ACTCOST
G17: Penalty_RenELCQuota | I17: Penalty_REQ | K17: 2008
G18: =F5 -> SUP2INDHTH | H18: REFHTH | I18: INDHTH | K18: 2100 | L18: 1 | M18: 0.1
H19: SUPHTH
G20: =F6 -> IMPINDGASY | I20: INDGAS | J20: 20
B22: ~COMAGG_R1C2
B23: CommName | C23: ETSCO2
B24: INDCO2P | C24: 1
B25: INDSCO2P | C25: 1 | E25: MovedToSysSettings
E26: Csets | F26: CommName | G26: CommDesc | H26: Unit | I26: LimType | J26: CTSLvl | K26: PeakTS | L26: Ctype
E27: ENV | F27: Penalty_REQ | G27: Penalty for not meeting the Renewable ELC production target under Quota system | H27: PJ
E28: NRG | F28: GASLNG | G28: Liquified Natural Gas | H28: PJ
B30: ~COMAGG_R1C2
B31: CommName | C31: CO2WOT
B32: TOTCO2 | C32: 1
B33: SE_TRACO2N | C33: -1
B36: Industry Final Solid Fuels
B37: ~COMAGG_R1C2
B38: CommName | C38: INDFINSOLID
B39: INDCOA | C39: 1
B40: INDCOB | C40: 1
B41: INDCOK | C41: 1
B42: INDCOL | C42: 1
B45: Industry Final Petroleum Fuels
B46: ~COMAGG_R1C2
B47: CommName | C47: INDFINOIL
...

Sheet SUP_Feedin-Subs
D2: ~FI_T
B3: TechName | C3: Comm-IN | D3: Comm-OUT | E3: COST | F3: START | G3: EFF | H3: ACTCOST
B4: FeedInTariffGeo | C4: SUBS-REN_FeedInGeo | E4: 1 | F4: 2005
B5: FeedInTariffWindO | C5: SUBS-REN_FeedInWindO | E5: 1 | F5: 2005
B6: FeedInTariffWindN | C6: SUBS-REN_FeedInWindN | E6: 1 | F6: 2005
B7: FeedInTariffSmHyd | C7: SUBS-REN_FeedInSmHyd | E7: 1 | F7: 2005
B8: FeedInTariffLaHyd | C8: SUBS-REN_FeedInLaHyd | E8: 1 | F8: 2005
B9: FeedInTariffPV | C9: SUBS-REN_FeedInPV | E9: 1 | F9: 2005
B10: FeedInTariffSolTh | C10: SUBS-REN_FeedInSolTh | E10: 1 | F10: 2005
B11: FeedInTariffWaste | C11: SUBS-REN_FeedInWaste | E11: 1 | F11: 2005
B12: FeedInTariffBiom | C12: SUBS-REN_FeedInBiom | E12: 1 | F12: 2005
B13: FeedInTariffBiomCHP | C13: SUBS-REN_FeedInBiomCHP | E13: 1 | F13: 2005
B14: FeedInTariffBiog | C14: SUBS-REN_FeedInBiog | E14: 1 | F14: 2005
B15: FeedInTariffBiogCHP | C15: SUBS-REN_FeedInBiogCHP | E15: 1 | F15: 2005
B16: FeedInTariffOce | C16: SUBS-REN_FeedInOce | E16: 1 | F16: 2005
B19: ~FI_Process
B20: Sets | C20: TechName | D20: TechDesc | E20: Tact | F20: Tcap | G20: Tslvl | H20: PrimaryCG | I20: Vintage
B21: EXP | C21: FeedInTariffGeo | D21: Accounting for Feed-in Tariffs for REN ELC | E21: mEuro | F21: mEuro
B22: EXP | C22: FeedInTariffWindO | D22: Accounting for Feed-in Tariffs for REN ELC | E22: mEuro | F22: mEuro
B23: EXP | C23: FeedInTariffWindN | D23: Accounting for Feed-in Tariffs for REN ELC | E23: mEuro | F23: mEuro
B24: EXP | C24: FeedInTariffSmHyd | D24: Accounting for Feed-in Tariffs for REN ELC | E24: mEuro | F24: mEuro
B25: EXP | C25: FeedInTariffLaHyd | D25: Accounting for Feed-in Tariffs for REN ELC | E25: mEuro | F25: mEuro
B26: EXP | C26: FeedInTariffPV | D26: Accounting for Feed-in Tariffs for REN ELC | E26: mEuro | F26: mEuro
B27: EXP | C27: FeedInTariffSolTh | D27: Accounting for Feed-in Tariffs for REN ELC | E27: mEuro | F27: mEuro
B28: EXP | C28: FeedInTariffWaste | D28: Accounting for Feed-in Tariffs for REN ELC | E28: mEuro | F28: mEuro
B29: EXP | C29: FeedInTariffBiom | D29: Accounting for Feed-in Tariffs for REN ELC | E29: mEuro | F29: mEuro
B30: EXP | C30: FeedInTariffBiomCHP | D30: Accounting for Feed-in Tariffs for REN ELC | E30: mEuro | F30: mEuro
B31: EXP | C31: FeedInTariffBiog | D31: Accounting for Feed-in Tariffs for REN ELC | E31: mEuro | F31: mEuro
B32: EXP | C32: FeedInTariffBiogCHP | D32: Accounting for Feed-in Tariffs for REN ELC | E32: mEuro | F32: mEuro
B33: EXP | C33: FeedInTariffOce | D33: Accounting for Feed-in Tariffs for REN ELC | E33: mEuro | F33: mEuro
D36: ~FI_T
B37: TechName | C37: Comm-IN | D37: Comm-OUT | E37: COST | F37: START | G37: EFF | H37: ACTCOST
B38: RENInvSubsidyGeo | C38: SUBS-REN_INVGeo | E38: 1 | F38: 2005
B39: RENInvSubsidyWind | C39: SUBS-REN_INVWind | E39: 1 | F39: 2005
B40: RENInvSubsidySmHyd | C40: SUBS-REN_INVSmHyd | E40: 1 | F40: 2005
B41: RENInvSubsidyLaHyd | C41: SUBS-REN_INVLaHyd | E41: 1 | F41: 2005
B42: RENInvSubsidyPV | C42: SUBS-REN_INVPV | E42: 1 | F42: 2005
B43: RENInvSubsidySolTh | C43: SUBS-REN_INVSolTh | E43: 1 | F43: 2005
B44: RENInvSubsidyWaste | C44: SUBS-REN_INVWaste | E44: 1 | F44: 2005
B45: RENInvSubsidyBiom | C45: SUBS-REN_INVBiom | E45: 1 | F45: 2005
...

Sheet IND_CCS
B2: DeACTFI_Process
B3: Sets | C3: TechName | D3: TechDesc | E3: Tact | F3: Tcap | G3: Tslvl | H3: PrimaryCG | I3: Vintage
B4: PRE | C4: INDUPSCO2Cap | D4: CO2 capture from large industrial and upstream installations | E4: ktpa | F4: kt
E7: DeACTFI_T
C8: TechName | D8: Comm-OUT | E8: Attribute | F8: 2020 | H8: this process will be linked to the deserving emissions from IND and UPS via a UC in Base_Extra
C9: INDUPSCO2Cap | D9: SNKCO2N | E9: INVCOST | F9: 0.25
E10: FIXOM | F10: 0.0175
E11: LIFE | F11: 25
E12: START | F12: 2020
