Workbook
Name _Toc379539723: BioImport!#REF!

Sheet BIO
C1: =18/1000/1000 -> 1.8e-05 | D1: PJ/dry tonne | P1: BA | Z1: EL | AI1: Montenegro | AJ1: Macedonia | AQ1: CS | AY1: EU-28 | AZ1: in PJ | BE1: EU-27 | BF1: in PJ
C2: =60/1000/1000 -> 6e-05 | D2: M€/dry tonne | F2: =C2/C1 -> 3.3333333
E4: ~TFM_INS | AX4: 2010 | AY4: 2020 | AZ4: 2030 | BA4: 2040 | BB4: 2050 | BD4: 2010 | BE4: 2020 | BF4: 2030 | BG4: 2040 | BH4: 2050
E5: TimeSlice | F5: Curr | G5: LimType | H5: Attribute | I5: Year | J5: Pset_PN | K5: AllRegions | L5: AL | M5: AT | N5: BE | O5: BG | P5: BA | Q5: CH | R5: CY | S5: CZ | T5: DE | U5: DK | V5: EE | W5: ES | X5: FI | Y5: FR | Z5: EL | AA5: HR | AB5: HU | AC5: IE | AD5: IS | AE5: IT | AF5: LT | AG5: LU | AH5: LV | AI5: ME | AJ5: MK | AK5: MT | AL5: NL | AM5: NO | AN5: PL | AO5: PT | AP5: RO | AQ5: RS | AR5: SE | AS5: SI | AT5: SK | AU5: UK | AW5: *EU27 | AX5: =SUM(AX7:AX209) -> 5100.7379 | AY5: =SUM(AY7:AY209) -> 7288.6487 | AZ5: =SUM(AZ7:AZ209) -> 8384.7723 | BA5: =SUM(BA7:BA209) -> 8478.9497 | BB5: =SUM(BB7:BB209) -> 8556.8349 | BD5: =SUM(BD7:BD209) -> 4799.4808 | BE5: =SUM(BE7:BE209) -> 6916.3833 | BF5: =SUM(BF7:BF209) -> 7750.3733 | BG5: =SUM(BG7:BG209) -> 7916.7265 | BH5: =SUM(BH7:BH209) -> 8065.807
A6: Energy crop feedstock | B6: crops | C6: Bioethanol_sugarbeet | E6: ANNUAL | G6: UP | H6: ACT_BND | I6: 2005 | J6: MINBIOCRP21 | L6: 0 | M6: 13.880284 | N6: 4.5870892 | O6: 0 | P6: 0 | Q6: 0 | R6: 0 | S6: 9.6852713 | T6: 72.382004 | U6: 1.4394639 | V6: 0 | W6: 0 | X6: 0 | Y6: 230.31117 | Z6: 0 | AA6: 0 | AB6: 0 | AC6: 0 | AD6: 0 | AE6: 0 | AF6: 1.627066 | AG6: 0 | AH6: 0 | AI6: 0 | AJ6: 0 | AK6: 0 | AL6: 1.5812102 | AM6: 0 | AN6: 1.7885306 | AO6: 0 | AP6: 0 | AQ6: 0 | AR6: 4.8568285 | AS6: 0 | AT6: 1.467958 | AU6: 3.0246297
A7: Energy crop feedstock | B7: crops | C7: Bioethanol_sugarbeet | E7: ANNUAL | G7: UP | H7: ACT_BND | I7: 2010 | J7: MINBIOCRP21 | L7: 0 | M7: 13.880284 | N7: 4.5870892 | O7: 0 | P7: 0 | Q7: 0 | R7: 0 | S7: 9.6852713 | T7: 72.382004 | U7: 1.4394639 | V7: 0 | W7: 0 | X7: 0 | Y7: 230.31117 | Z7: 0 | AA7: 0 | AB7: 0 | AC7: 0 | AD7: 0 | AE7: 0 | AF7: 1.627066 | AG7: 0 | AH7: 0 | AI7: 0 | AJ7: 0 | AK7: 0 | AL7: 1.5812102 | AM7: 0 | AN7: 1.7885306 | AO7: 0 | AP7: 0 | AQ7: 0 | AR7: 4.8568285 | AS7: 0 | AT7: 1.467958 | AU7: 3.0246297 | AW7: =BD7 -> 343.60688 | AX7: =SUM(M7:O7,R7:AC7,AE7:AH7,AK7:AL7,AN7:AP7,AR7:AU7) -> 346.63151 | BD7: =AX7-AU7 -> 343.60688
A8: Energy crop feedstock | B8: crops | C8: Bioethanol_sugarbeet | E8: ANNUAL | G8: UP | H8: ACT_BND | I8: 2020 | J8: MINBIOCRP21 | L8: 0 | M8: 13.763614 | N8: 17.369174 | O8: 8.5780195 | P8: 0 | Q8: 0 | R8: 0 | S8: 14.641597 | T8: 48.939888 | U8: 0.6714715 | V8: 0 | W8: 106.07934 | X8: 0 | Y8: 228.259 | Z8: 14.722843 | AA8: 0 | AB8: 4.2584533 | AC8: 0 | AD8: 0 | AE8: 44.343331 | AF8: 24.295867 | AG8: 0 | AH8: 0 | AI8: 0 | AJ8: 0 | AK8: 0 | AL8: 14.17204 | AM8: 0 | AN8: 28.690385 | AO8: 0.20171668 | AP8: 9.898683 | AQ8: 0 | AR8: 4.5473747 | AS8: 0 | AT8: 1.6141066 | AU8: 18.166544 | AW8: =BE8 -> 585.0469 | AY8: =SUM(M8:O8,R8:AC8,AE8:AH8,AK8:AL8,AN8:AP8,AR8:AU8) -> 603.21344 | BE8: =AY8-AU8 -> 585.0469
A9: Energy crop feedstock | B9: crops | C9: Bioethanol_sugarbeet | E9: ANNUAL | G9: UP | H9: ACT_BND | I9: 2030 | J9: MINBIOCRP21 | L9: 0 | M9: 15.318843 | N9: 30.820799 | O9: 1.5152494 | P9: 0 | Q9: 0 | R9: 0 | S9: 25.03753 | T9: 45.7654 | U9: 1.3470716 | V9: 0 | W9: 136.66556 | X9: 0 | Y9: 251.35324 | Z9: 16.523798 | AA9: 0 | AB9: 9.1332542 | AC9: 0 | AD9: 0 | AE9: 110.97735 | AF9: 33.857988 | AG9: 0 | AH9: 0 | AI9: 0 | AJ9: 0 | AK9: 0 | AL9: 20.938521 | AM9: 0 | AN9: 47.667555 | AO9: 0.064776837 | AP9: 0.0061280271 | AQ9: 0 | AR9: 5.100919 | AS9: 0 | AT9: 4.2235842 | AU9: 126.16932 | AW9: =BF9 -> 756.31757 | AZ9: =SUM(M9:O9,R9:AC9,AE9:AH9,AK9:AL9,AN9:AP9,AR9:AU9) -> 882.48689 | BF9: =AZ9-AU9 -> 756.31757
A10: Energy crop feedstock | B10: crops | C10: Bioethanol_sugarbeet | E10: ANNUAL | G10: UP | H10: ACT_BND | I10: 2040 | J10: MINBIOCRP21 | L10: 0 | M10: 14.826541 | N10: 33.647113 | O10: 8.7856949 | P10: 0 | Q10: 0 | R10: 0 | S10: 29.672755 | T10: 44.590686 | U10: 2.1035948 | V10: 0 | W10: 154.33494 | X10: 0 | Y10: 241.64205 | Z10: 19.24158 | AA10: 0 | AB10: 12.800706 | AC10: 0 | AD10: 0 | AE10: 119.96625 | AF10: 37.81274 | AG10: 0 | AH10: 0 | AI10: 0 | AJ10: 0 | AK10: 0 | AL10: 17.587069 | AM10: 0 | AN10: 89.370987 | AO10: 0.222376 | AP10: 9.5818845 | AQ10: 0 | AR10: 5.270845 | AS10: 0 | AT10: 6.3034392 | AU10: 96.761883 | AW10: =BG10 -> 847.76125 | BA10: =SUM(M10:O10,R10:AC10,AE10:AH10,AK10:AL10,AN10:AP10,AR10:AU10) -> 944.52314 | BG10: =BA10-AU10 -> 847.76125
A11: Energy crop feedstock | B11: crops | C11: Bioethanol_sugarbeet | E11: ANNUAL | G11: UP | H11: ACT_BND | I11: 2050 | J11: MINBIOCRP21 | L11: 0 | M11: 14.335299 | N11: 36.400841 | O11: 11.674661 | P11: 0 | Q11: 0 | R11: 0 | S11: 34.388211 | T11: 43.513847 | U11: 2.699145 | V11: 0 | W11: 170.00479 | X11: 0 | Y11: 231.88143 | Z11: 21.774108 | AA11: 0 | AB11: 16.997487 | AC11: 0 | AD11: 0 | AE11: 130.29807 | AF11: 41.634753 | AG11: 0 | AH11: 0 | AI11: 0 | AJ11: 0 | AK11: 0 | AL11: 14.358482 | AM11: 0 | AN11: 133.03564 | AO11: 0.47666832 | AP11: 9.3721602 | AQ11: 0 | AR11: 5.4375972 | AS11: 0 | AT11: 8.7917622 | AU11: 67.979603 | AW11: =BH11 -> 927.07495 | BB11: =SUM(M11:O11,R11:AC11,AE11:AH11,AK11:AL11,AN11:AP11,AR11:AU11) -> 995.05456 | BH11: =BB11-AU11 -> 927.07495
A12: Energy crop feedstock | B12: crops | C12: sugar from sugarbeet | F12: EUR10 | H12: ACT_COST | I12: 2005 | J12: MINBIOCRP21 | L12: 4.3227006 | M12: 3.7313424 | N12: 3.7483714 | O12: 7.6957777 | P12: 5.0657973 | R12: 7.7652206 | S12: 3.6633594 | T12: 3.7304317 | U12: 5.2892618 | V12: 7.7257092 | W12: 3.710427 | X12: 3.7604922 | Y12: 3.7404682 | Z12: 3.6960762 | AA12: 4.3014237 | AB12: 3.651903 | AC12: 7.807495 | AE12: 3.753526 | AF12: 3.6398196 | AG12: 3.7483714 | AH12: 3.6513503 | AI12: 0 | AJ12: 4.9888629 | AK12: 7.7381441 | AL12: 3.7587972 | AM12: 3.8991766 | AN12: 3.6496214 | AO12: 3.6698932 | AP12: 3.6253669 | AQ12: 4.3227006 | AR12: 3.7850474 | AS12: 7.7449267 | AT12: 3.6623612 | AU12: 3.765706
A13: Energy crop feedstock | B13: crops | C13: sugar from sugarbeet | F13: EUR10 | H13: ACT_COST | I13: 2010 | J13: MINBIOCRP21 | L13: 4.3227006 | M13: 3.7313424 | N13: 3.7483714 | O13: 7.6957777 | P13: 5.0657973 | R13: 7.7652206 | S13: 3.6633594 | T13: 3.7304317 | U13: 5.2892618 | V13: 7.7257092 | W13: 3.710427 | X13: 3.7604922 | Y13: 3.7404682 | Z13: 3.6960762 | AA13: 4.3014237 | AB13: 3.651903 | AC13: 7.807495 | AE13: 3.753526 | AF13: 3.6398196 | AG13: 3.7483714 | AH13: 3.6513503 | AI13: 0 | AJ13: 4.9888629 | AK13: 7.7381441 | AL13: 3.7587972 | AM13: 3.8991766 | AN13: 3.6496214 | AO13: 3.6698932 | AP13: 3.6253669 | AQ13: 4.3227006 | AR13: 3.7850474 | AS13: 7.7449267 | AT13: 3.6623612 | AU13: 3.765706
A14: Energy crop feedstock | B14: crops | C14: sugar from sugarbeet | F14: EUR10 | H14: ACT_COST | I14: 2020 | J14: MINBIOCRP21 | L14: 4.5255392 | M14: 3.7764228 | N14: 3.7934518 | O14: 3.6715364 | P14: 4.5255392 | R14: 6.9156304 | S14: 3.7041532 | T14: 3.775512 | U14: 5.3552421 | V14: 6.876119 | W14: 3.7555074 | X14: 3.8055726 | Y14: 3.7855485 | Z14: 3.7411565 | AA14: 4.5042623 | AB14: 3.6926968 | AC14: 6.9579048 | AE14: 3.7986063 | AF14: 3.6806134 | AG14: 3.7934518 | AH14: 3.6921441 | AI14: 0 | AJ14: 4.3617963 | AK14: 6.8885539 | AL14: 3.8038776 | AM14: 3.5166582 | AN14: 3.6904152 | AO14: 3.7149735 | AP14: 3.6637655 | AQ14: 4.5255392 | AR14: 3.8301278 | AS14: 6.8953365 | AT14: 3.7031549 | AU14: 3.8107864
A15: Energy crop feedstock | B15: crops | C15: sugar from sugarbeet | F15: EUR10 | H15: ACT_COST | I15: 2030 | J15: MINBIOCRP21 | L15: 4.3253393 | M15: 4.0289005 | N15: 4.0459295 | O15: 3.9233865 | P15: 4.6588269 | R15: 7.4208289 | S15: 3.9575424 | T15: 4.0279897 | U15: 5.7247721 | V15: 7.3813176 | W15: 4.007985 | X15: 4.0580502 | Y15: 4.0380262 | Z15: 3.9936342 | AA15: 4.3040624 | AB15: 3.9460861 | AC15: 7.4631034 | AE15: 4.051084 | AF15: 3.9340027 | AG15: 4.0459295 | AH15: 3.9455334 | AI15: 0 | AJ15: 4.2484049 | AK15: 7.3937525 | AL15: 4.0563553 | AM15: 3.7441182 | AN15: 3.9438045 | AO15: 3.9674512 | AP15: 3.9156156 | AQ15: 4.3253393 | AR15: 4.0826054 | AS15: 7.4005351 | AT15: 3.9565442 | AU15: 4.0632641
A16: Energy crop feedstock | B16: crops | C16: sugar from sugarbeet | F16: EUR10 | H16: ACT_COST | I16: 2040 | J16: MINBIOCRP21 | L16: 4.3249492 | M16: 4.0540559 | N16: 4.0710849 | O16: 3.94831 | P16: 5.3327967 | R16: 8.3407476 | S16: 3.9820772 | T16: 4.0531451 | U16: 5.7615899 | V16: 8.3012362 | W16: 4.0331404 | X16: 4.0832056 | Y16: 4.0631816 | Z16: 4.0187896 | AA16: 4.3036723 | AB16: 3.9706208 | AC16: 8.383022 | AE16: 4.0762394 | AF16: 3.9585374 | AG16: 4.0710849 | AH16: 3.9700681 | AI16: 0 | AJ16: 4.2480148 | AK16: 8.3136711 | AL16: 4.0815107 | AM16: 4.1583011 | AN16: 3.9683392 | AO16: 3.9926066 | AP16: 3.9405391 | AQ16: 4.3249492 | AR16: 4.1077609 | AS16: 8.3204537 | AT16: 3.981079 | AU16: 4.0884195
A17: Energy crop feedstock | B17: crops | C17: sugar from sugarbeet | F17: EUR10 | H17: ACT_COST | I17: 2050 | J17: MINBIOCRP21 | L17: 4.3245591 | M17: 4.0792113 | N17: 4.0962403 | O17: 3.9732335 | P17: 6.0067665 | R17: 9.2606662 | S17: 4.0066119 | T17: 4.0783005 | U17: 5.7984078 | V17: 9.2211549 | W17: 4.0582959 | X17: 4.1083611 | Y17: 4.088337 | Z17: 4.043945 | AA17: 4.3032822 | AB17: 3.9951555 | AC17: 9.3029407 | AE17: 4.1013948 | AF17: 3.9830722 | AG17: 4.0962403 | AH17: 3.9946029 | AI17: 0 | AJ17: 4.2476246 | AK17: 9.2335898 | AL17: 4.1066661 | AM17: 4.5724841 | AN17: 3.992874 | AO17: 4.017762 | AP17: 3.9654626 | AQ17: 4.3245591 | AR17: 4.1329163 | AS17: 9.2403724 | AT17: 4.0056137 | AU17: 4.1135749
E18: \I:
A19: Energy crop feedstock | B19: crops | C19: Biodiesel_oil_crops | E19: ANNUAL | G19: UP | H19: ACT_BND | I19: 2005 | J19: MINBIORPS1 | L19: 0 | M19: 14.800632 | N19: 4.5870892 | O19: 0.88317895 | P19: 0 | Q19: 0 | R19: 0 | S19: 9.8423289 | T19: 72.382004 | U19: 1.4394639 | V19: 0 | W19: 6.952985 | X19: 0 | Y19: 238.35576 | Z19: 0.21723041 | AA19: 0 | AB19: 5.2399846 | AC19: 0 | AD19: 0 | AE19: 3.149265 | AF19: 1.627066 | AG19: 0 | AH19: 0 | AI19: 0 | AJ19: 0 | AK19: 0 | AL19: 1.5947529 | AM19: 0 | AN19: 1.8157662 | AO19: 0.098478791 | AP19: 0.85279283 | AQ19: 0 | AR19: 4.8568285 | AS19: 0.00036007831 | AT19: 1.8451006 | AU19: 3.0246297
A20: Energy crop feedstock | B20: crops | C20: Biodiesel_oil_crops | E20: ANNUAL | G20: UP | H20: ACT_BND | I20: 2010 | J20: MINBIORPS1 | L20: 0 | M20: 14.800632 | N20: 4.5870892 | O20: 0.88317895 | P20: 0 | Q20: 0 | R20: 0 | S20: 9.8423289 | T20: 72.382004 | U20: 1.4394639 | V20: 0 | W20: 6.952985 | X20: 0 | Y20: 238.35576 | Z20: 0.21723041 | AA20: 0 | AB20: 5.2399846 | AC20: 0 | AD20: 0 | AE20: 3.149265 | AF20: 1.627066 | AG20: 0 | AH20: 0 | AI20: 0 | AJ20: 0 | AK20: 0 | AL20: 1.5947529 | AM20: 0 | AN20: 1.8157662 | AO20: 0.098478791 | AP20: 0.85279283 | AQ20: 0 | AR20: 4.8568285 | AS20: 0.00036007831 | AT20: 1.8451006 | AU20: 3.0246297 | AW20: =BD20 -> 370.54107 | AX20: =SUM(M20:O20,R20:AC20,AE20:AH20,AK20:AL20,AN20:AP20,AR20:AU20) -> 373.5657 | BD20: =AX20-AU20 -> 370.54107
A21: Energy crop feedstock | B21: crops | C21: =C20 -> Biodiesel_oil_crops | E21: ANNUAL | G21: UP | H21: ACT_BND | I21: 2020 | J21: MINBIORPS1 | L21: 0 | M21: 14.567522 | N21: 17.369174 | O21: 14.329188 | P21: 0 | Q21: 0 | R21: 0 | S21: 15.282572 | T21: 48.939888 | U21: 0.6714715 | V21: 0 | W21: 115.36858 | X21: 0 | Y21: 260.32805 | Z21: 15.302884 | AA21: 0 | AB21: 11.745115 | AC21: 0 | AD21: 0 | AE21: 47.510161 | AF21: 24.295867 | AG21: 0 | AH21: 0 | AI21: 0 | AJ21: 0 | AK21: 0 | AL21: 14.18867 | AM21: 0 | AN21: 29.007484 | AO21: 1.2652394 | AP21: 14.891137 | AQ21: 0 | AR21: 4.5473747 | AS21: 0 | AT21: 2.6577313 | AU21: 18.166544 | AW21: =BE21 -> 652.2681 | AY21: =SUM(M21:O21,R21:AC21,AE21:AH21,AK21:AL21,AN21:AP21,AR21:AU21) -> 670.43465 | BE21: =AY21-AU21 -> 652.2681
A22: Energy crop feedstock | B22: crops | C22: =C21 -> Biodiesel_oil_crops | E22: ANNUAL | G22: UP | H22: ACT_BND | I22: 2030 | J22: MINBIORPS1 | L22: 0 | M22: 16.839363 | N22: 30.820799 | O22: 7.4500092 | P22: 0 | Q22: 0 | R22: 0 | S22: 25.883882 | T22: 45.7654 | U22: 1.3470716 | V22: 0 | W22: 143.33377 | X22: 0 | Y22: 278.30585 | Z22: 17.292575 | AA22: 0 | AB22: 18.133751 | AC22: 0 | AD22: 0 | AE22: 117.0223 | AF22: 33.857988 | AG22: 0 | AH22: 0 | AI22: 0 | AJ22: 0 | AK22: 0 | AL22: 21.05871 | AM22: 0 | AN22: 48.192338 | AO22: 0.79492886 | AP22: 7.0778429 | AQ22: 0 | AR22: 5.100919 | AS22: 0 | AT22: 4.965026 | AU22: 126.16932 | AW22: =BF22 -> 823.24252 | AZ22: =SUM(M22:O22,R22:AC22,AE22:AH22,AK22:AL22,AN22:AP22,AR22:AU22) -> 949.41184 | BF22: =AZ22-AU22 -> 823.24252
A23: Energy crop feedstock | B23: crops | C23: =C22 -> Biodiesel_oil_crops | E23: ANNUAL | G23: UP | H23: ACT_BND | I23: 2040 | J23: MINBIORPS1 | L23: 0 | M23: 16.359301 | N23: 33.647113 | O23: 14.386051 | P23: 0 | Q23: 0 | R23: 0 | S23: 30.238557 | T23: 44.590686 | U23: 2.1035948 | V23: 0 | W23: 158.77472 | X23: 0 | Y23: 257.75993 | Z23: 21.299417 | AA23: 0 | AB23: 20.8655 | AC23: 0 | AD23: 0 | AE23: 124.14554 | AF23: 37.81274 | AG23: 0 | AH23: 0 | AI23: 0 | AJ23: 0 | AK23: 0 | AL23: 17.641428 | AM23: 0 | AN23: 89.718983 | AO23: 0.81034904 | AP23: 16.908655 | AQ23: 0 | AR23: 5.270845 | AS23: 7.6734917e-19 | AT23: 6.6748248 | AU23: 96.761883 | AW23: =BG23 -> 899.00822 | BA23: =SUM(M23:O23,R23:AC23,AE23:AH23,AK23:AL23,AN23:AP23,AR23:AU23) -> 995.77011 | BG23: =BA23-AU23 -> 899.00822
A24: Energy crop feedstock | B24: crops | C24: =C23 -> Biodiesel_oil_crops | E24: ANNUAL | G24: UP | H24: ACT_BND | I24: 2050 | J24: MINBIORPS1 | L24: 0 | M24: 15.913269 | N24: 36.400841 | O24: 17.070374 | P24: 0 | Q24: 0 | R24: 0 | S24: 34.696633 | T24: 43.513847 | U24: 2.699145 | V24: 0 | W24: 172.62005 | X24: 0 | Y24: 239.5866 | Z24: 25.078765 | AA24: 0 | AB24: 24.165148 | AC24: 0 | AD24: 0 | AE24: 132.85097 | AF24: 41.634753 | AG24: 0 | AH24: 0 | AI24: 0 | AJ24: 0 | AK24: 0 | AL24: 14.361127 | AM24: 0 | AN24: 133.23321 | AO24: 0.84273485 | AP24: 16.481314 | AQ24: 0 | AR24: 5.4375972 | AS24: 0 | AT24: 8.865276 | AU24: 67.979603 | AW24: =BH24 -> 965.45166 | BB24: =SUM(M24:O24,R24:AC24,AE24:AH24,AK24:AL24,AN24:AP24,AR24:AU24) -> 1033.4313 | BH24: =BB24-AU24 -> 965.45166
A25: Energy crop feedstock | B25: crops | C25: oil_crops | F25: EUR10 | H25: ACT_COST | I25: 2005 | J25: MINBIORPS1 | L25: 0 | M25: 20.462754 | N25: 20.553174 | O25: 15.845068 | P25: 0 | Q25: 0 | R25: 0 | S25: 18.769237 | T25: 20.459094 | U25: 21.034385 | V25: 0 | W25: 20.859637 | X25: 0 | Y25: 20.516979 | Z25: 20.551231 | AA25: 0 | AB25: 19.859444 | AC25: 0 | AD25: 0 | AE25: 19.849471 | AF25: 18.632345 | AG25: 0 | AH25: 0 | AI25: 0 | AJ25: 0 | AK25: 0 | AL25: 20.612187 | AM25: 0 | AN25: 18.703484 | AO25: 20.64769 | AP25: 17.980433 | AQ25: 0 | AR25: 20.74551 | AS25: 19.102448 | AT25: 18.942189 | AU25: 20.64408
A26: Energy crop feedstock | B26: crops | C26: oil_crops | F26: EUR10 | H26: ACT_COST | I26: 2010 | J26: MINBIORPS1 | L26: 0 | M26: 20.462754 | N26: 20.553174 | O26: 15.845068 | P26: 0 | Q26: 0 | R26: 0 | S26: 18.769237 | T26: 20.459094 | U26: 21.034385 | V26: 0 | W26: 20.859637 | X26: 0 | Y26: 20.516979 | Z26: 20.551231 | AA26: 0 | AB26: 19.859444 | AC26: 0 | AD26: 0 | AE26: 19.849471 | AF26: 18.632345 | AG26: 0 | AH26: 0 | AI26: 0 | AJ26: 0 | AK26: 0 | AL26: 20.612187 | AM26: 0 | AN26: 18.703484 | AO26: 20.64769 | AP26: 17.980433 | AQ26: 0 | AR26: 20.74551 | AS26: 19.102448 | AT26: 18.942189 | AU26: 20.64408
A27: Energy crop feedstock | B27: crops | C27: oil_crops | F27: EUR10 | H27: ACT_COST | I27: 2020 | J27: MINBIORPS1 | L27: 0 | M27: 23.384451 | N27: 23.495838 | O27: 13.774834 | P27: 0 | Q27: 0 | R27: 0 | S27: 21.723245 | T27: 23.401758 | U27: 23.977049 | V27: 0 | W27: 23.277909 | X27: 0 | Y27: 23.309001 | Z27: 23.173512 | AA27: 0 | AB27: 22.28649 | AC27: 0 | AD27: 0 | AE27: 23.459173 | AF27: 21.627699 | AG27: 0 | AH27: 0 | AI27: 0 | AJ27: 0 | AK27: 0 | AL27: 23.551277 | AM27: 0 | AN27: 21.684458 | AO27: 23.628332 | AP27: 13.555535 | AQ27: 0 | AR27: 23.688174 | AS27: 0 | AT27: 22.02412 | AU27: 23.586744
A28: Energy crop feedstock | B28: crops | C28: oil_crops | F28: EUR10 | H28: ACT_COST | I28: 2030 | J28: MINBIORPS1 | L28: 0 | M28: 33.524576 | N28: 33.711144 | O28: 26.150041 | P28: 0 | Q28: 0 | R28: 0 | S28: 31.354825 | T28: 33.617064 | U28: 34.192355 | V28: 0 | W28: 33.537939 | X28: 0 | Y28: 33.554016 | Z28: 33.352127 | AA28: 0 | AB28: 31.531774 | AC28: 0 | AD28: 0 | AE28: 33.618586 | AF28: 31.313935 | AG28: 0 | AH28: 0 | AI28: 0 | AJ28: 0 | AK28: 0 | AL28: 33.769051 | AM28: 0 | AN28: 31.361936 | AO28: 33.815257 | AP28: 27.385492 | AQ28: 0 | AR28: 33.90348 | AS28: 0 | AT28: 31.318176 | AU28: 33.80205
A29: Energy crop feedstock | B29: crops | C29: oil_crops | F29: EUR10 | H29: ACT_COST | I29: 2040 | J29: MINBIORPS1 | L29: 0 | M29: 33.590663 | N29: 33.668456 | O29: 26.314095 | P29: 0 | Q29: 0 | R29: 0 | S29: 31.086182 | T29: 33.574376 | U29: 34.149667 | V29: 0 | W29: 33.489137 | X29: 0 | Y29: 33.611187 | Z29: 33.197066 | AA29: 0 | AB29: 31.500818 | AC29: 0 | AD29: 0 | AE29: 33.644079 | AF29: 30.970522 | AG29: 0 | AH29: 0 | AI29: 0 | AJ29: 0 | AK29: 0 | AL29: 33.72532 | AM29: 0 | AN29: 31.024304 | AO29: 33.768751 | AP29: 27.466196 | AQ29: 0 | AR29: 33.860792 | AS29: 29.801632 | AT29: 31.103927 | AU29: 33.759362
A30: Energy crop feedstock | B30: crops | C30: oil_crops | F30: EUR10 | H30: ACT_COST | I30: 2050 | J30: MINBIORPS1 | L30: 0 | M30: 33.607336 | N30: 33.625768 | O30: 26.144816 | P30: 0 | Q30: 0 | R30: 0 | S30: 30.763826 | T30: 33.531688 | U30: 34.106979 | V30: 0 | W30: 33.439683 | X30: 0 | Y30: 33.604162 | Z30: 33.177167 | AA30: 0 | AB30: 31.29252 | AC30: 0 | AD30: 0 | AE30: 33.638349 | AF30: 30.627109 | AG30: 0 | AH30: 0 | AI30: 0 | AJ30: 0 | AK30: 0 | AL30: 33.6806 | AM30: 0 | AN30: 30.681058 | AO30: 33.583199 | AP30: 27.928763 | AQ30: 0 | AR30: 33.818104 | AS30: 0 | AT30: 30.754556 | AU30: 33.716674
E31: \I:
A32: Energy crop feedstock | B32: crops | C32: starchy grops | E32: ANNUAL | G32: UP | H32: ACT_BND | I32: 2005 | J32: MINBIOCRP11 | L32: 0 | M32: 3.3394367 | N32: 4.859286 | O32: 2.9695707 | P32: 0 | Q32: 0 | R32: 0 | S32: 3.7135344 | T32: 12.469523 | U32: 0.4434902 | V32: 0.010223422 | W32: 13.440987 | X32: 0 | Y32: 34.164009 | Z32: 9.0321379 | AA32: 30.150919 | AB32: 9.9642599 | AC32: 0.046531844 | AD32: 0 | AE32: 4.4976957 | AF32: 1.4906609 | AG32: 0.41430963 | AH32: 0.8283496 | AI32: 0 | AJ32: 0 | AK32: 0 | AL32: 0.58981918 | AM32: 0 | AN32: 7.8814979 | AO32: 0 | AP32: 3.4996211 | AQ32: 0 | AR32: 8.7534768 | AS32: 0 | AT32: 5.8044894 | AU32: 13.937596
A33: Energy crop feedstock | B33: crops | C33: starchy grops | E33: ANNUAL | G33: UP | H33: ACT_BND | I33: 2010 | J33: MINBIOCRP11 | L33: 0 | M33: 3.3394367 | N33: 4.859286 | O33: 2.9695707 | P33: 0 | Q33: 0 | R33: 0 | S33: 3.7135344 | T33: 12.469523 | U33: 0.4434902 | V33: 0.010223422 | W33: 13.440987 | X33: 0 | Y33: 34.164009 | Z33: 9.0321379 | AA33: 30.150919 | AB33: 9.9642599 | AC33: 0.046531844 | AD33: 0 | AE33: 4.4976957 | AF33: 1.4906609 | AG33: 0.41430963 | AH33: 0.8283496 | AI33: 0 | AJ33: 0 | AK33: 0 | AL33: 0.58981918 | AM33: 0 | AN33: 7.8814979 | AO33: 0 | AP33: 3.4996211 | AQ33: 0 | AR33: 8.7534768 | AS33: 0 | AT33: 5.8044894 | AU33: 13.937596 | AW33: =BD33 -> 158.36383 | AX33: =SUM(M33:O33,R33:AC33,AE33:AH33,AK33:AL33,AN33:AP33,AR33:AU33) -> 172.30143 | BD33: =AX33-AU33 -> 158.36383
A34: Energy crop feedstock | B34: crops | C34: starchy grops | E34: ANNUAL | G34: UP | H34: ACT_BND | I34: 2020 | J34: MINBIOCRP11 | L34: 0 | M34: 1.0696175 | N34: 4.7354622 | O34: 8.5624636 | P34: 0 | Q34: 0 | R34: 0 | S34: 3.3145743 | T34: 2.5178927 | U34: 1.6082219 | V34: 0.35890929 | W34: 25.865499 | X34: 0 | Y34: 27.062315 | Z34: 5.7418704 | AA34: 26.515819 | AB34: 15.100428 | AC34: 0.23210082 | AD34: 0 | AE34: 19.511394 | AF34: 2.3564664 | AG34: 0.35088535 | AH34: 0.74437049 | AI34: 0 | AJ34: 0 | AK34: 0 | AL34: 0.6902328 | AM34: 0 | AN34: 11.164789 | AO34: 0.1637198 | AP34: 17.805635 | AQ34: 0 | AR34: 0.82380616 | AS34: 0.044361191 | AT34: 3.4395421 | AU34: 18.084441 | AW34: =BE34 -> 179.78037 | AY34: =SUM(M34:O34,R34:AC34,AE34:AH34,AK34:AL34,AN34:AP34,AR34:AU34) -> 197.86482 | BE34: =AY34-AU34 -> 179.78037
A35: Energy crop feedstock | B35: crops | C35: starchy grops | E35: ANNUAL | G35: UP | H35: ACT_BND | I35: 2030 | J35: MINBIOCRP11 | L35: 0 | M35: 1.7958196 | N35: 5.0049586 | O35: 10.79822 | P35: 0 | Q35: 0 | R35: 0 | S35: 6.4399656 | T35: 3.6878377 | U35: 2.1193233 | V35: 4.5203506 | W35: 30.553001 | X35: 0 | Y35: 37.249134 | Z35: 8.8374091 | AA35: 40.340454 | AB35: 21.760031 | AC35: 0.25780214 | AD35: 0 | AE35: 18.480186 | AF35: 7.1200226 | AG35: 0.35942217 | AH35: 3.2025328 | AI35: 0 | AJ35: 0 | AK35: 0 | AL35: 0.79204453 | AM35: 0 | AN35: 15.828578 | AO35: 0.14198229 | AP35: 24.161946 | AQ35: 0 | AR35: 0.63753754 | AS35: 0.19166908 | AT35: 5.1908696 | AU35: 37.680508 | AW35: =BF35 -> 249.4711 | AZ35: =SUM(M35:O35,R35:AC35,AE35:AH35,AK35:AL35,AN35:AP35,AR35:AU35) -> 287.15161 | BF35: =AZ35-AU35 -> 249.4711
A36: Energy crop feedstock | B36: crops | C36: starchy grops | E36: ANNUAL | G36: UP | H36: ACT_BND | I36: 2040 | J36: MINBIOCRP11 | L36: 0 | M36: 1.8287084 | N36: 5.2943371 | O36: 10.230877 | P36: 0 | Q36: 0 | R36: 0 | S36: 4.6856336 | T36: 5.8547718 | U36: 1.8981987 | V36: 9.4740259 | W36: 32.474304 | X36: 0 | Y36: 32.210667 | Z36: 8.0813377 | AA36: 40.950979 | AB36: 22.397418 | AC36: 0.23871891 | AD36: 0 | AE36: 16.999325 | AF36: 9.8024732 | AG36: 0.39421719 | AH36: 5.4482646 | AI36: 0 | AJ36: 0 | AK36: 0 | AL36: 0.8852445 | AM36: 0 | AN36: 17.488204 | AO36: 0.10610033 | AP36: 25.953489 | AQ36: 0 | AR36: 0.5136139 | AS36: 0.16800615 | AT36: 4.0333149 | AU36: 29.942134 | AW36: =BG36 -> 257.41223 | BA36: =SUM(M36:O36,R36:AC36,AE36:AH36,AK36:AL36,AN36:AP36,AR36:AU36) -> 287.35436 | BG36: =BA36-AU36 -> 257.41223
A37: Energy crop feedstock | B37: crops | C37: starchy grops | E37: ANNUAL | G37: UP | H37: ACT_BND | I37: 2050 | J37: MINBIOCRP11 | L37: 0 | M37: 1.9571041 | N37: 5.5985522 | O37: 9.6993416 | P37: 0 | Q37: 0 | R37: 0 | S37: 2.9690616 | T37: 8.2977941 | U37: 1.7216738 | V37: 14.119216 | W37: 33.190016 | X37: 0 | Y37: 26.60522 | Z37: 6.9083159 | AA37: 41.295444 | AB37: 22.352912 | AC37: 0.21710644 | AD37: 0 | AE37: 16.232567 | AF37: 12.42139 | AG37: 0.43051834 | AH37: 7.6800158 | AI37: 0 | AJ37: 0 | AK37: 0 | AL37: 0.9926474 | AM37: 0 | AN37: 18.466306 | AO37: 0.064116942 | AP37: 26.67172 | AQ37: 0 | AR37: 0.45682486 | AS37: 0.13858066 | AT37: 2.7043099 | AU37: 22.261169 | AW37: =BH37 -> 261.19075 | BB37: =SUM(M37:O37,R37:AC37,AE37:AH37,AK37:AL37,AN37:AP37,AR37:AU37) -> 283.45192 | BH37: =BB37-AU37 -> 261.19075
A38: Energy crop feedstock | B38: crops | C38: starchy grops | F38: EUR10 | H38: ACT_COST | I38: 2005 | J38: MINBIOCRP11 | L38: 15.678711 | M38: 12.504855 | N38: 12.146388 | O38: 11.431297 | P38: 15.442558 | R38: 33.613648 | S38: 11.28182 | T38: 13.568641 | U38: 13.304464 | V38: 11.64517 | W38: 14.162825 | X38: 12.533129 | Y38: 13.476189 | Z38: 19.35308 | AA38: 13.32185 | AB38: 11.720201 | AC38: 10.964759 | AE38: 17.219837 | AF38: 10.493758 | AG38: 12.146388 | AH38: 11.052243 | AJ38: 14.74812 | AK38: 16.801736 | AL38: 12.909546 | AM38: 22.266462 | AN38: 10.806966 | AO38: 14.491827 | AP38: 16.912351 | AQ38: 14.155104 | AR38: 13.281993 | AS38: 13.258654 | AT38: 11.266041 | AU38: 13.357131
A39: Energy crop feedstock | B39: crops | C39: starchy grops | F39: EUR10 | H39: ACT_COST | I39: 2010 | J39: MINBIOCRP11 | L39: 15.678711 | M39: 12.504855 | N39: 12.146388 | O39: 11.431297 | P39: 15.442558 | R39: 33.613648 | S39: 11.28182 | T39: 13.568641 | U39: 13.304464 | V39: 11.64517 | W39: 14.162825 | X39: 12.533129 | Y39: 13.476189 | Z39: 19.35308 | AA39: 13.32185 | AB39: 11.720201 | AC39: 10.964759 | AE39: 17.219837 | AF39: 10.493758 | AG39: 12.146388 | AH39: 11.052243 | AJ39: 14.74812 | AK39: 16.801736 | AL39: 12.909546 | AM39: 22.266462 | AN39: 10.806966 | AO39: 14.491827 | AP39: 16.912351 | AQ39: 14.155104 | AR39: 13.281993 | AS39: 13.258654 | AT39: 11.266041 | AU39: 13.357131
A40: Energy crop feedstock | B40: crops | C40: starchy grops | F40: EUR10 | H40: ACT_COST | I40: 2020 | J40: MINBIOCRP11 | L40: 15.161186 | M40: 13.560737 | N40: 12.804879 | O40: 12.628009 | P40: 14.934986 | R40: 41.548327 | S40: 12.553542 | T40: 14.844193 | U40: 14.69949 | V40: 12.051497 | W40: 15.320955 | X40: 13.689422 | Y40: 14.743839 | Z40: 20.03838 | AA40: 14.66288 | AB40: 12.846581 | AC40: 12.287634 | AE40: 18.27155 | AF40: 11.83314 | AG40: 12.804879 | AH40: 12.311652 | AJ40: 14.176839 | AK40: 15.773569 | AL40: 14.080741 | AM40: 21.178182 | AN40: 11.93858 | AO40: 15.05148 | AP40: 18.193503 | AQ40: 13.641248 | AR40: 13.977328 | AS40: 12.013897 | AT40: 12.476418 | AU40: 14.798379
A41: Energy crop feedstock | B41: crops | C41: starchy grops | F41: EUR10 | H41: ACT_COST | I41: 2030 | J41: MINBIOCRP11 | L41: 16.897686 | M41: 18.316323 | N41: 17.550508 | O41: 17.272364 | P41: 16.63809 | R41: 65.237099 | S41: 16.923709 | T41: 19.667553 | U41: 19.930218 | V41: 16.312234 | W41: 21.297161 | X41: 18.360748 | Y41: 20.169027 | Z41: 28.81744 | AA41: 13.373515 | AB41: 17.442311 | AC41: 16.703974 | AE41: 25.175 | AF41: 16.184478 | AG41: 17.550508 | AH41: 16.826893 | AJ41: 16.126871 | AK41: 21.473177 | AL41: 18.867917 | AM41: 22.6717 | AN41: 16.16802 | AO41: 20.629202 | AP41: 25.605735 | AQ41: 14.616679 | AR41: 18.389001 | AS41: 16.002543 | AT41: 16.88665 | AU41: 20.29427
...

Sheet shares
A1: COUNTRY SHARES
B3: EU27 shares | D3: AL | E3: AT | F3: BE | G3: BG | H3: BA | I3: CH | J3: CY | K3: CZ | L3: DE | M3: DK | N3: EE | O3: ES | P3: FI | Q3: FR | R3: EL | S3: HR | T3: HU | U3: IE | V3: IS | W3: IT | X3: LT | Y3: LU | Z3: LV | AA3: ME | AB3: MK | AC3: MT | AD3: NL | AE3: NO | AF3: PL | AG3: PT | AH3: RO | AI3: RS | AJ3: SE | AK3: SI | AL3: SK | AM3: UK
B4: waste | C4: 2005 | E4: =BIO!M263/BIO!$AX263 -> 0.0086618521 | F4: =BIO!N263/BIO!$AX263 -> 0.048321226 | G4: =BIO!O263/BIO!$AX263 -> 0.0059439492 | J4: =BIO!R263/BIO!$AX263 -> 0.0035968673 | K4: =BIO!S263/BIO!$AX263 -> 0.040220879 | L4: =BIO!T263/BIO!$AX263 -> 0.1455032 | M4: =BIO!U263/BIO!$AX263 -> 0.042110766 | N4: =BIO!V263/BIO!$AX263 -> 0.0072322955 | O4: =BIO!W263/BIO!$AX263 -> 0.076268726 | P4: =BIO!X263/BIO!$AX263 -> 0.0074794181 | Q4: =BIO!Y263/BIO!$AX263 -> 0.22068116 | ... U4: =BIO!AC263/BIO!$AX263 -> 0.013076126 | W4: =BIO!AE263/BIO!$AX263 -> 0.097807446 | X4: =BIO!AF263/BIO!$AX263 -> 0.0080623319 | Y4: =BIO!AG263/BIO!$AX263 -> 0.001597355 | Z4: =BIO!AH263/BIO!$AX263 -> 0.0053010564 | AC4: =BIO!AK263/BIO!$AX263 -> 0.0069966057 | AD4: =BIO!AL263/BIO!$AX263 -> 0.060141452 | AF4: =BIO!AN263/BIO!$AX263 -> 0.055780727 | AG4: =BIO!AO263/BIO!$AX263 -> 0.021613311 | AH4: =BIO!AP263/BIO!$AX263 -> 0.019060921 | AJ4: =BIO!AR263/BIO!$AX263 -> 0.026875106 | AK4: =BIO!AS263/BIO!$AX263 -> 0.001581099 | AL4: =BIO!AT263/BIO!$AX263 -> 0.01286112 | AO4: =SUM(D4:AM4) -> 1
B5: waste | C5: 2010 | E5: =BIO!M264/BIO!$AX264 -> 0.0086600694 | F5: =BIO!N264/BIO!$AX264 -> 0.048311281 | G5: =BIO!O264/BIO!$AX264 -> 0.0059427258 | J5: =BIO!R264/BIO!$AX264 -> 0.0035961271 | K5: =BIO!S264/BIO!$AX264 -> 0.040212601 | L5: =BIO!T264/BIO!$AX264 -> 0.14547325 | M5: =BIO!U264/BIO!$AX264 -> 0.042102099 | N5: =BIO!V264/BIO!$AX264 -> 0.007230807 | O5: =BIO!W264/BIO!$AX264 -> 0.076253029 | P5: =BIO!X264/BIO!$AX264 -> 0.0076836919 | Q5: =BIO!Y264/BIO!$AX264 -> 0.22063574 | ... U5: =BIO!AC264/BIO!$AX264 -> 0.013073435 | W5: =BIO!AE264/BIO!$AX264 -> 0.097787316 | X5: =BIO!AF264/BIO!$AX264 -> 0.0080606726 | Y5: =BIO!AG264/BIO!$AX264 -> 0.0015970263 | Z5: =BIO!AH264/BIO!$AX264 -> 0.0052999654 | AC5: =BIO!AK264/BIO!$AX264 -> 0.0069951657 | AD5: =BIO!AL264/BIO!$AX264 -> 0.060129074 | AF5: =BIO!AN264/BIO!$AX264 -> 0.055769247 | AG5: =BIO!AO264/BIO!$AX264 -> 0.021608863 | AH5: =BIO!AP264/BIO!$AX264 -> 0.019056998 | AJ5: =BIO!AR264/BIO!$AX264 -> 0.026869575 | AK5: =BIO!AS264/BIO!$AX264 -> 0.0015807736 | AL5: =BIO!AT264/BIO!$AX264 -> 0.012858473 | AO5: =SUM(D5:AM5) -> 1
B6: waste | C6: 2020 | E6: =BIO!M265/BIO!$AX265 -> 0.0092460567 | F6: =BIO!N265/BIO!$AX265 -> 0.050164919 | G6: =BIO!O265/BIO!$AX265 -> 0.0054211892 | J6: =BIO!R265/BIO!$AX265 -> 0.0037160135 | K6: =BIO!S265/BIO!$AX265 -> 0.035168908 | L6: =BIO!T265/BIO!$AX265 -> 0.14443228 | M6: =BIO!U265/BIO!$AX265 -> 0.042365838 | N6: =BIO!V265/BIO!$AX265 -> 0.0068880154 | O6: =BIO!W265/BIO!$AX265 -> 0.083247203 | P6: =BIO!X265/BIO!$AX265 -> 0.008625731 | Q6: =BIO!Y265/BIO!$AX265 -> 0.22033402 | ... U6: =BIO!AC265/BIO!$AX265 -> 0.013077468 | W6: =BIO!AE265/BIO!$AX265 -> 0.098509838 | X6: =BIO!AF265/BIO!$AX265 -> 0.0092190854 | Y6: =BIO!AG265/BIO!$AX265 -> 0.0010925845 | Z6: =BIO!AH265/BIO!$AX265 -> 0.0053592069 | AC6: =BIO!AK265/BIO!$AX265 -> 0.0025363186 | AD6: =BIO!AL265/BIO!$AX265 -> 0.061420588 | AF6: =BIO!AN265/BIO!$AX265 -> 0.0608528 | AG6: =BIO!AO265/BIO!$AX265 -> 0.021393382 | AH6: =BIO!AP265/BIO!$AX265 -> 0.020162291 | AJ6: =BIO!AR265/BIO!$AX265 -> 0.028146561 | AK6: =BIO!AS265/BIO!$AX265 -> 0.0016100538 | AL6: =BIO!AT265/BIO!$AX265 -> 0.011107017 | AO6: =SUM(D6:AM6) -> 1
B7: waste | C7: 2030 | E7: =BIO!M266/BIO!$AX266 -> 0.0099117852 | F7: =BIO!N266/BIO!$AX266 -> 0.053763409 | G7: =BIO!O266/BIO!$AX266 -> 0.0056164153 | J7: =BIO!R266/BIO!$AX266 -> 0.003765994 | K7: =BIO!S266/BIO!$AX266 -> 0.030749463 | L7: =BIO!T266/BIO!$AX266 -> 0.14304162 | M7: =BIO!U266/BIO!$AX266 -> 0.041862531 | N7: =BIO!V266/BIO!$AX266 -> 0.0068546363 | O7: =BIO!W266/BIO!$AX266 -> 0.084477097 | P7: =BIO!X266/BIO!$AX266 -> 0.01069104 | Q7: =BIO!Y266/BIO!$AX266 -> 0.21583473 | ... U7: =BIO!AC266/BIO!$AX266 -> 0.012696235 | W7: =BIO!AE266/BIO!$AX266 -> 0.095902924 | X7: =BIO!AF266/BIO!$AX266 -> 0.00982266 | Y7: =BIO!AG266/BIO!$AX266 -> 0.0010381561 | Z7: =BIO!AH266/BIO!$AX266 -> 0.0054638225 | AC7: =BIO!AK266/BIO!$AX266 -> 0.0028207423 | AD7: =BIO!AL266/BIO!$AX266 -> 0.062940526 | AF7: =BIO!AN266/BIO!$AX266 -> 0.065311909 | AG7: =BIO!AO266/BIO!$AX266 -> 0.022473912 | AH7: =BIO!AP266/BIO!$AX266 -> 0.020177277 | AJ7: =BIO!AR266/BIO!$AX266 -> 0.028813277 | AK7: =BIO!AS266/BIO!$AX266 -> 0.001617592 | AL7: =BIO!AT266/BIO!$AX266 -> 0.010949804 | AO7: =SUM(D7:AM7) -> 1
B8: waste | C8: 2040 | E8: =BIO!M267/BIO!$AX267 -> 0.010404599 | F8: =BIO!N267/BIO!$AX267 -> 0.057952204 | G8: =BIO!O267/BIO!$AX267 -> 0.005446744 | J8: =BIO!R267/BIO!$AX267 -> 0.0038849285 | K8: =BIO!S267/BIO!$AX267 -> 0.02847157 | L8: =BIO!T267/BIO!$AX267 -> 0.14158758 | M8: =BIO!U267/BIO!$AX267 -> 0.041155682 | N8: =BIO!V267/BIO!$AX267 -> 0.0067621746 | O8: =BIO!W267/BIO!$AX267 -> 0.084427274 | P8: =BIO!X267/BIO!$AX267 -> 0.01402933 | Q8: =BIO!Y267/BIO!$AX267 -> 0.21216173 | ... U8: =BIO!AC267/BIO!$AX267 -> 0.012227941 | W8: =BIO!AE267/BIO!$AX267 -> 0.092420019 | X8: =BIO!AF267/BIO!$AX267 -> 0.010165864 | Y8: =BIO!AG267/BIO!$AX267 -> 0.00099278442 | Z8: =BIO!AH267/BIO!$AX267 -> 0.0053647776 | AC8: =BIO!AK267/BIO!$AX267 -> 0.003022754 | AD8: =BIO!AL267/BIO!$AX267 -> 0.064348911 | AF8: =BIO!AN267/BIO!$AX267 -> 0.069047795 | AG8: =BIO!AO267/BIO!$AX267 -> 0.023046116 | AH8: =BIO!AP267/BIO!$AX267 -> 0.018835381 | AJ8: =BIO!AR267/BIO!$AX267 -> 0.029887861 | AK8: =BIO!AS267/BIO!$AX267 -> 0.0015877861 | AL8: =BIO!AT267/BIO!$AX267 -> 0.010365554 | AO8: =SUM(D8:AM8) -> 1
B9: waste | C9: 2050 | E9: =BIO!M268/BIO!$AX268 -> 0.010944807 | F9: =BIO!N268/BIO!$AX268 -> 0.062992268 | G9: =BIO!O268/BIO!$AX268 -> 0.0053004759 | J9: =BIO!R268/BIO!$AX268 -> 0.0040212655 | K9: =BIO!S268/BIO!$AX268 -> 0.026364693 | L9: =BIO!T268/BIO!$AX268 -> 0.13983084 | M9: =BIO!U268/BIO!$AX268 -> 0.040625242 | N9: =BIO!V268/BIO!$AX268 -> 0.0066862854 | O9: =BIO!W268/BIO!$AX268 -> 0.084277417 | P9: =BIO!X268/BIO!$AX268 -> 0.015526635 | Q9: =BIO!Y268/BIO!$AX268 -> 0.20919634 | ... U9: =BIO!AC268/BIO!$AX268 -> 0.011811119 | W9: =BIO!AE268/BIO!$AX268 -> 0.089284706 | X9: =BIO!AF268/BIO!$AX268 -> 0.010442364 | Y9: =BIO!AG268/BIO!$AX268 -> 0.00095009624 | Z9: =BIO!AH268/BIO!$AX268 -> 0.0052571445 | AC9: =BIO!AK268/BIO!$AX268 -> 0.0032391176 | AD9: =BIO!AL268/BIO!$AX268 -> 0.065991698 | AF9: =BIO!AN268/BIO!$AX268 -> 0.072408941 | AG9: =BIO!AO268/BIO!$AX268 -> 0.023672652 | AH9: =BIO!AP268/BIO!$AX268 -> 0.01760864 | AJ9: =BIO!AR268/BIO!$AX268 -> 0.030731635 | AK9: =BIO!AS268/BIO!$AX268 -> 0.0015618142 | AL9: =BIO!AT268/BIO!$AX268 -> 0.0098357944 | AO9: =SUM(D9:AM9) -> 1
B11: crops | C11: 2005 | E11: =BIO!M270/BIO!$AX270 -> 0.036699049 | F11: =BIO!N270/BIO!$AX270 -> 0.016083983 | G11: =BIO!O270/BIO!$AX270 -> 0.0044156993 | J11: =BIO!R270/BIO!$AX270 -> 0 | K11: =BIO!S270/BIO!$AX270 -> 0.026637044 | L11: =BIO!T270/BIO!$AX270 -> 0.18020792 | M11: =BIO!U270/BIO!$AX270 -> 0.0038078775 | N11: =BIO!V270/BIO!$AX270 -> 1.1717231e-05 | O11: =BIO!W270/BIO!$AX270 -> 0.023373865 | P11: =BIO!X270/BIO!$AX270 -> 0 | Q11: =BIO!Y270/BIO!$AX270 -> 0.57630275 | ... U11: =BIO!AC270/BIO!$AX270 -> 5.3330907e-05 | W11: =BIO!AE270/BIO!$AX270 -> 0.0087643066 | X11: =BIO!AF270/BIO!$AX270 -> 0.0054380847 | Y11: =BIO!AG270/BIO!$AX270 -> 0.00047484704 | Z11: =BIO!AH270/BIO!$AX270 -> 0.00094938501 | AC11: =BIO!AK270/BIO!$AX270 -> 0 | AD11: =BIO!AL270/BIO!$AX270 -> 0.0043160245 | AF11: =BIO!AN270/BIO!$AX270 -> 0.013164057 | AG11: =BIO!AO270/BIO!$AX270 -> 0.00011286815 | AH11: =BIO!AP270/BIO!$AX270 -> 0.0049883727 | AJ11: =BIO!AR270/BIO!$AX270 -> 0.021165484 | AK11: =BIO!AS270/BIO!$AX270 -> 4.1269163e-07 | AL11: =BIO!AT270/BIO!$AX270 -> 0.010449771 | AO11: =SUM(D11:AM11) -> 1
B12: crops | C12: 2010 | E12: =BIO!M271/BIO!$AX271 -> 0.036699049 | F12: =BIO!N271/BIO!$AX271 -> 0.016083983 | G12: =BIO!O271/BIO!$AX271 -> 0.0044156993 | J12: =BIO!R271/BIO!$AX271 -> 0 | K12: =BIO!S271/BIO!$AX271 -> 0.026637044 | L12: =BIO!T271/BIO!$AX271 -> 0.18020792 | M12: =BIO!U271/BIO!$AX271 -> 0.0038078775 | N12: =BIO!V271/BIO!$AX271 -> 1.1717231e-05 | O12: =BIO!W271/BIO!$AX271 -> 0.023373865 | P12: =BIO!X271/BIO!$AX271 -> 0 | Q12: =BIO!Y271/BIO!$AX271 -> 0.57630275 | ... U12: =BIO!AC271/BIO!$AX271 -> 5.3330907e-05 | W12: =BIO!AE271/BIO!$AX271 -> 0.0087643066 | X12: =BIO!AF271/BIO!$AX271 -> 0.0054380847 | Y12: =BIO!AG271/BIO!$AX271 -> 0.00047484704 | Z12: =BIO!AH271/BIO!$AX271 -> 0.00094938501 | AC12: =BIO!AK271/BIO!$AX271 -> 0 | AD12: =BIO!AL271/BIO!$AX271 -> 0.0043160245 | AF12: =BIO!AN271/BIO!$AX271 -> 0.013164057 | AG12: =BIO!AO271/BIO!$AX271 -> 0.00011286815 | AH12: =BIO!AP271/BIO!$AX271 -> 0.0049883727 | AJ12: =BIO!AR271/BIO!$AX271 -> 0.021165484 | AK12: =BIO!AS271/BIO!$AX271 -> 4.1269163e-07 | AL12: =BIO!AT271/BIO!$AX271 -> 0.010449771 | AO12: =SUM(D12:AM12) -> 1
B13: crops | C13: 2020 | E13: =BIO!M272/BIO!$AX272 -> 0.015093093 | F13: =BIO!N272/BIO!$AX272 -> 0.018722305 | G13: =BIO!O272/BIO!$AX272 -> 0.029293003 | J13: =BIO!R272/BIO!$AX272 -> 0.00028775482 | K13: =BIO!S272/BIO!$AX272 -> 0.019520509 | L13: =BIO!T272/BIO!$AX272 -> 0.062384518 | M13: =BIO!U272/BIO!$AX272 -> 0.0009679988 | N13: =BIO!V272/BIO!$AX272 -> 0.0029722907 | O13: =BIO!W272/BIO!$AX272 -> 0.16223287 | P13: =BIO!X272/BIO!$AX272 -> 0.0011431194 | Q13: =BIO!Y272/BIO!$AX272 -> 0.23227822 | ... U13: =BIO!AC272/BIO!$AX272 -> 0.0062459196 | W13: =BIO!AE272/BIO!$AX272 -> 0.091543447 | X13: =BIO!AF272/BIO!$AX272 -> 0.031324142 | Y13: =BIO!AG272/BIO!$AX272 -> 0.0001146011 | Z13: =BIO!AH272/BIO!$AX272 -> 0.0031264618 | AC13: =BIO!AK272/BIO!$AX272 -> 0 | AD13: =BIO!AL272/BIO!$AX272 -> 0.013728788 | AF13: =BIO!AN272/BIO!$AX272 -> 0.094796423 | AG13: =BIO!AO272/BIO!$AX272 -> 0.0073366433 | AH13: =BIO!AP272/BIO!$AX272 -> 0.12140906 | AJ13: =BIO!AR272/BIO!$AX272 -> 0.0079249541 | AK13: =BIO!AS272/BIO!$AX272 -> 0.00036055874 | AL13: =BIO!AT272/BIO!$AX272 -> 0.0067876148 | AO13: =SUM(D13:AM13) -> 1
B14: crops | C14: 2030 | E14: =BIO!M273/BIO!$AX273 -> 0.013736814 | F14: =BIO!N273/BIO!$AX273 -> 0.024621162 | G14: =BIO!O273/BIO!$AX273 -> 0.019003696 | J14: =BIO!R273/BIO!$AX273 -> 0.00025430145 | K14: =BIO!S273/BIO!$AX273 -> 0.02340162 | L14: =BIO!T273/BIO!$AX273 -> 0.069781839 | M14: =BIO!U273/BIO!$AX273 -> 0.0012826735 | N14: =BIO!V273/BIO!$AX273 -> 0.0034710301 | O14: =BIO!W273/BIO!$AX273 -> 0.15866862 | P14: =BIO!X273/BIO!$AX273 -> 0.001118036 | Q14: =BIO!Y273/BIO!$AX273 -> 0.22465844 | ... U14: =BIO!AC273/BIO!$AX273 -> 0.0047440421 | W14: =BIO!AE273/BIO!$AX273 -> 0.10726562 | X14: =BIO!AF273/BIO!$AX273 -> 0.033381476 | Y14: =BIO!AG273/BIO!$AX273 -> 9.5677841e-05 | Z14: =BIO!AH273/BIO!$AX273 -> 0.0038244777 | AC14: =BIO!AK273/BIO!$AX273 -> 0 | AD14: =BIO!AL273/BIO!$AX273 -> 0.017840284 | AF14: =BIO!AN273/BIO!$AX273 -> 0.10185227 | AG14: =BIO!AO273/BIO!$AX273 -> 0.0061464891 | AH14: =BIO!AP273/BIO!$AX273 -> 0.10031621 | AJ14: =BIO!AR273/BIO!$AX273 -> 0.0075191803 | AK14: =BIO!AS273/BIO!$AX273 -> 0.00081051283 | AL14: =BIO!AT273/BIO!$AX273 -> 0.0080229428 | AO14: =SUM(D14:AM14) -> 1
B15: crops | C15: 2040 | E15: =BIO!M274/BIO!$AX274 -> 0.012401895 | F15: =BIO!N274/BIO!$AX274 -> 0.022689723 | G15: =BIO!O274/BIO!$AX274 -> 0.022345279 | J15: =BIO!R274/BIO!$AX274 -> 0.00023138485 | K15: =BIO!S274/BIO!$AX274 -> 0.025556192 | L15: =BIO!T274/BIO!$AX274 -> 0.069094659 | M15: =BIO!U274/BIO!$AX274 -> 0.0015764405 | N15: =BIO!V274/BIO!$AX274 -> 0.0039798757 | O15: =BIO!W274/BIO!$AX274 -> 0.16745255 | P15: =BIO!X274/BIO!$AX274 -> 0.0015485647 | Q15: =BIO!Y274/BIO!$AX274 -> 0.20662553 | ... U15: =BIO!AC274/BIO!$AX274 -> 0.0033363279 | W15: =BIO!AE274/BIO!$AX274 -> 0.10503819 | X15: =BIO!AF274/BIO!$AX274 -> 0.031401887 | Y15: =BIO!AG274/BIO!$AX274 -> 0.00010174514 | Z15: =BIO!AH274/BIO!$AX274 -> 0.0033846433 | AC15: =BIO!AK274/BIO!$AX274 -> 0 | AD15: =BIO!AL274/BIO!$AX274 -> 0.01492053 | AF15: =BIO!AN274/BIO!$AX274 -> 0.11893979 | AG15: =BIO!AO274/BIO!$AX274 -> 0.0062403857 | AH15: =BIO!AP274/BIO!$AX274 -> 0.09731869 | AJ15: =BIO!AR274/BIO!$AX274 -> 0.0069860067 | AK15: =BIO!AS274/BIO!$AX274 -> 0.00067410146 | AL15: =BIO!AT274/BIO!$AX274 -> 0.0070403202 | AO15: =SUM(D15:AM15) -> 1
B16: crops | C16: 2050 | E16: =BIO!M275/BIO!$AX275 -> 0.011200518 | F16: =BIO!N275/BIO!$AX275 -> 0.020763591 | G16: =BIO!O275/BIO!$AX275 -> 0.0245258 | J16: =BIO!R275/BIO!$AX275 -> 0.00020939686 | K16: =BIO!S275/BIO!$AX275 -> 0.027933199 | L16: =BIO!T275/BIO!$AX275 -> 0.069120655 | M16: =BIO!U275/BIO!$AX275 -> 0.0017987917 | N16: =BIO!V275/BIO!$AX275 -> 0.0043543626 | O16: =BIO!W275/BIO!$AX275 -> 0.17624324 | P16: =BIO!X275/BIO!$AX275 -> 0.0018695402 | Q16: =BIO!Y275/BIO!$AX275 -> 0.19129297 | ... U16: =BIO!AC275/BIO!$AX275 -> 0.0019039643 | W16: =BIO!AE275/BIO!$AX275 -> 0.10436538 | X16: =BIO!AF275/BIO!$AX275 -> 0.029347195 | Y16: =BIO!AG275/BIO!$AX275 -> 0.0001087664 | Z16: =BIO!AH275/BIO!$AX275 -> 0.0029050247 | AC16: =BIO!AK275/BIO!$AX275 -> 0 | AD16: =BIO!AL275/BIO!$AX275 -> 0.012268305 | AF16: =BIO!AN275/BIO!$AX275 -> 0.13659703 | AG16: =BIO!AO275/BIO!$AX275 -> 0.0064096512 | AH16: =BIO!AP275/BIO!$AX275 -> 0.08917697 | AJ16: =BIO!AR275/BIO!$AX275 -> 0.0065079175 | AK16: =BIO!AS275/BIO!$AX275 -> 0.00053718911 | AL16: =BIO!AT275/BIO!$AX275 -> 0.0062137145 | AO16: =SUM(D16:AM16) -> 1
... B37: forest residues | C37: 2050 | E37: =BIO!M296/BIO!$AX296 -> 0.036342748 | F37: =BIO!N296/BIO!$AX296 -> 0.017918614 | G37: =BIO!O296/BIO!$AX296 -> 0.0076775494 | J37: =BIO!R296/BIO!$AX296 -> 0 | K37: =BIO!S296/BIO!$AX296 -> 0.0135593 | L37: =BIO!T296/BIO!$AX296 -> 0.086639335 | M37: =BIO!U296/BIO!$AX296 -> 0.0053684854 | N37: =BIO!V296/BIO!$AX296 -> 0.010735746 | O37: =BIO!W296/BIO!$AX296 -> 0.050722905 | P37: =BIO!X296/BIO!$AX296 -> 0.20033809 | Q37: =BIO!Y296/BIO!$AX296 -> 0.1178137 | ... U37: =BIO!AC296/BIO!$AX296 -> 0.0072413317 | W37: =BIO!AE296/BIO!$AX296 -> 0.030240948 | X37: =BIO!AF296/BIO!$AX296 -> 0.0083582921 | Y37: =BIO!AG296/BIO!$AX296 -> 0.0016515178 | Z37: =BIO!AH296/BIO!$AX296 -> 0.026777965 | AC37: =BIO!AK296/BIO!$AX296 -> 4.270983e-05 | AD37: =BIO!AL296/BIO!$AX296 -> 0.0053631163 | AF37: =BIO!AN296/BIO!$AX296 -> 0.051292834 | AG37: =BIO!AO296/BIO!$AX296 -> 0.018709812 | AH37: =BIO!AP296/BIO!$AX296 -> 0.05244294 | AJ37: =BIO!AR296/BIO!$AX296 -> 0.21858866 | AK37: =BIO!AS296/BIO!$AX296 -> 0.0014954026 | AL37: =BIO!AT296/BIO!$AX296 -> 0.006621559 | AO37: =SUM(D37:AM37) -> 1
B39: crops: subcategories | C39: share of all crops | D39: AL | E39: AT | F39: BE | G39: BG | H39: BA | I39: CH | J39: CY | K39: CZ | L39: DE | M39: DK | N39: EE | O39: ES | P39: FI | Q39: FR | R39: EL | S39: HR | T39: HU | U39: IE | V39: IS | W39: IT | X39: LT | Y39: LU | Z39: LV | AA39: ME | AB39: MK | AC39: MT | AD39: NL | AE39: NO | AF39: PL | AG39: PT | AH39: RO | AI39: RS | AJ39: SE | AK39: SI | AL39: SK | AM39: UK
B40: MINBIOCRP21 | C40: 2005 | D40: =IFERROR(BIO!L6/BIO!L270,0) -> 0 | E40: =IFERROR(BIO!M6/BIO!M270,0) -> 0.43348316 | F40: =IFERROR(BIO!N6/BIO!N270,0) -> 0.32686791 | G40: =IFERROR(BIO!O6/BIO!O270,0) -> 0 | H40: =IFERROR(BIO!P6/BIO!P270,0) -> 0 | I40: =IFERROR(BIO!Q6/BIO!Q270,0) -> 0 | J40: =IFERROR(BIO!R6/BIO!R270,0) -> 0 | K40: =IFERROR(BIO!S6/BIO!S270,0) -> 0.41672971 | ... AM40: =IFERROR(BIO!AU6/BIO!AU270,0) -> 0.15133094
B41: MINBIOCRP21 | C41: 2010 | D41: =IFERROR(BIO!L7/BIO!L271,0) -> 0 | E41: =IFERROR(BIO!M7/BIO!M271,0) -> 0.43348316 | F41: =IFERROR(BIO!N7/BIO!N271,0) -> 0.32686791 | G41: =IFERROR(BIO!O7/BIO!O271,0) -> 0 | H41: =IFERROR(BIO!P7/BIO!P271,0) -> 0 | I41: =IFERROR(BIO!Q7/BIO!Q271,0) -> 0 | J41: =IFERROR(BIO!R7/BIO!R271,0) -> 0 | K41: =IFERROR(BIO!S7/BIO!S271,0) -> 0.41672971 | ... AM41: =IFERROR(BIO!AU7/BIO!AU271,0) -> 0.15133094
B42: MINBIOCRP21 | C42: 2020 | D42: =IFERROR(BIO!L8/BIO!L272,0) -> 0 | E42: =IFERROR(BIO!M8/BIO!M272,0) -> 0.29783641 | F42: =IFERROR(BIO!N8/BIO!N272,0) -> 0.30300054 | G42: =IFERROR(BIO!O8/BIO!O272,0) -> 0.09564157 | H42: =IFERROR(BIO!P8/BIO!P272,0) -> 0 | I42: =IFERROR(BIO!Q8/BIO!Q272,0) -> 0 | J42: =IFERROR(BIO!R8/BIO!R272,0) -> 0 | K42: =IFERROR(BIO!S8/BIO!S272,0) -> 0.2449745 | ... AM42: =IFERROR(BIO!AU8/BIO!AU272,0) -> 0.16505882
B43: MINBIOCRP21 | C43: 2030 | D43: =IFERROR(BIO!L9/BIO!L273,0) -> 0 | E43: =IFERROR(BIO!M9/BIO!M273,0) -> 0.29685643 | F43: =IFERROR(BIO!N9/BIO!N273,0) -> 0.33322829 | G43: =IFERROR(BIO!O9/BIO!O273,0) -> 0.021225237 | H43: =IFERROR(BIO!P9/BIO!P273,0) -> 0 | I43: =IFERROR(BIO!Q9/BIO!Q273,0) -> 0 | J43: =IFERROR(BIO!R9/BIO!R273,0) -> 0 | K43: =IFERROR(BIO!S9/BIO!S273,0) -> 0.28480792 | ... AM43: =IFERROR(BIO!AU9/BIO!AU273,0) -> 0.34857668
B44: MINBIOCRP21 | C44: 2040 | D44: =IFERROR(BIO!L10/BIO!L274,0) -> 0 | E44: =IFERROR(BIO!M10/BIO!M274,0) -> 0.3085531 | F44: =IFERROR(BIO!N10/BIO!N274,0) -> 0.38273371 | G44: =IFERROR(BIO!O10/BIO!O274,0) -> 0.10147719 | H44: =IFERROR(BIO!P10/BIO!P274,0) -> 0 | I44: =IFERROR(BIO!Q10/BIO!Q274,0) -> 0 | J44: =IFERROR(BIO!R10/BIO!R274,0) -> 0 | K44: =IFERROR(BIO!S10/BIO!S274,0) -> 0.29966763 | ... AM44: =IFERROR(BIO!AU10/BIO!AU274,0) -> 0.33642971
B45: MINBIOCRP21 | C45: 2050 | D45: =IFERROR(BIO!L11/BIO!L275,0) -> 0 | E45: =IFERROR(BIO!M11/BIO!M275,0) -> 0.32334917 | F45: =IFERROR(BIO!N11/BIO!N275,0) -> 0.4429065 | G45: =IFERROR(BIO!O11/BIO!O275,0) -> 0.12026082 | H45: =IFERROR(BIO!P11/BIO!P275,0) -> 0 | I45: =IFERROR(BIO!Q11/BIO!Q275,0) -> 0 | J45: =IFERROR(BIO!R11/BIO!R275,0) -> 0 | K45: =IFERROR(BIO!S11/BIO!S275,0) -> 0.31102264 | ... AM45: =IFERROR(BIO!AU11/BIO!AU275,0) -> 0.31822922
B46: MINBIORPS1 | C46: 2005 | D46: =IFERROR(BIO!L19/BIO!L270,0) -> 0 | E46: =IFERROR(BIO!M19/BIO!M270,0) -> 0.46222577 | F46: =IFERROR(BIO!N19/BIO!N270,0) -> 0.32686791 | G46: =IFERROR(BIO!O19/BIO!O270,0) -> 0.22923341 | H46: =IFERROR(BIO!P19/BIO!P270,0) -> 0 | I46: =IFERROR(BIO!Q19/BIO!Q270,0) -> 0 | J46: =IFERROR(BIO!R19/BIO!R270,0) -> 0 | K46: =IFERROR(BIO!S19/BIO!S270,0) -> 0.42348745 | ... AM46: =IFERROR(BIO!AU19/BIO!AU270,0) -> 0.15133094
B47: MINBIORPS1 | C47: 2010 | D47: =IFERROR(BIO!L20/BIO!L271,0) -> 0 | E47: =IFERROR(BIO!M20/BIO!M271,0) -> 0.46222577 | F47: =IFERROR(BIO!N20/BIO!N271,0) -> 0.32686791 | G47: =IFERROR(BIO!O20/BIO!O271,0) -> 0.22923341 | H47: =IFERROR(BIO!P20/BIO!P271,0) -> 0 | I47: =IFERROR(BIO!Q20/BIO!Q271,0) -> 0 | J47: =IFERROR(BIO!R20/BIO!R271,0) -> 0 | K47: =IFERROR(BIO!S20/BIO!S271,0) -> 0.42348745 | ... AM47: =IFERROR(BIO!AU20/BIO!AU271,0) -> 0.15133094
B48: MINBIORPS1 | C48: 2020 | D48: =IFERROR(BIO!L21/BIO!L272,0) -> 0 | E48: =IFERROR(BIO!M21/BIO!M272,0) -> 0.3152325 | F48: =IFERROR(BIO!N21/BIO!N272,0) -> 0.30300054 | G48: =IFERROR(BIO!O21/BIO!O272,0) -> 0.15976485 | H48: =IFERROR(BIO!P21/BIO!P272,0) -> 0 | I48: =IFERROR(BIO!Q21/BIO!Q272,0) -> 0 | J48: =IFERROR(BIO!R21/BIO!R272,0) -> 0 | K48: =IFERROR(BIO!S21/BIO!S272,0) -> 0.25569891 | ... AM48: =IFERROR(BIO!AU21/BIO!AU272,0) -> 0.16505882
B49: MINBIORPS1 | C49: 2030 | D49: =IFERROR(BIO!L22/BIO!L273,0) -> 0 | E49: =IFERROR(BIO!M22/BIO!M273,0) -> 0.32632185 | F49: =IFERROR(BIO!N22/BIO!N273,0) -> 0.33322829 | G49: =IFERROR(BIO!O22/BIO!O273,0) -> 0.10435788 | H49: =IFERROR(BIO!P22/BIO!P273,0) -> 0 | I49: =IFERROR(BIO!Q22/BIO!Q273,0) -> 0 | J49: =IFERROR(BIO!R22/BIO!R273,0) -> 0 | K49: =IFERROR(BIO!S22/BIO!S273,0) -> 0.29443538 | ... AM49: =IFERROR(BIO!AU22/BIO!AU273,0) -> 0.34857668
B50: MINBIORPS1 | C50: 2040 | D50: =IFERROR(BIO!L23/BIO!L274,0) -> 0 | E50: =IFERROR(BIO!M23/BIO!M274,0) -> 0.34045115 | F50: =IFERROR(BIO!N23/BIO!N274,0) -> 0.38273371 | G50: =IFERROR(BIO!O23/BIO!O274,0) -> 0.16616284 | H50: =IFERROR(BIO!P23/BIO!P274,0) -> 0 | I50: =IFERROR(BIO!Q23/BIO!Q274,0) -> 0 | J50: =IFERROR(BIO!R23/BIO!R274,0) -> 0 | K50: =IFERROR(BIO!S23/BIO!S274,0) -> 0.30538172 | ... AM50: =IFERROR(BIO!AU23/BIO!AU274,0) -> 0.33642971
B51: MINBIORPS1 | C51: 2050 | D51: =IFERROR(BIO!L24/BIO!L275,0) -> 0 | E51: =IFERROR(BIO!M24/BIO!M275,0) -> 0.3589421 | F51: =IFERROR(BIO!N24/BIO!N275,0) -> 0.4429065 | G51: =IFERROR(BIO!O24/BIO!O275,0) -> 0.17584213 | H51: =IFERROR(BIO!P24/BIO!P275,0) -> 0 | I51: =IFERROR(BIO!Q24/BIO!Q275,0) -> 0 | J51: =IFERROR(BIO!R24/BIO!R275,0) -> 0 | K51: =IFERROR(BIO!S24/BIO!S275,0) -> 0.31381215 | ... AM51: =IFERROR(BIO!AU24/BIO!AU275,0) -> 0.31822922
B52: MINBIOCRP11 | C52: 2005 | D52: =IFERROR(BIO!L32/BIO!L270,0) -> 0 | E52: =IFERROR(BIO!M32/BIO!M270,0) -> 0.10429107 | F52: =IFERROR(BIO!N32/BIO!N270,0) -> 0.34626417 | G52: =IFERROR(BIO!O32/BIO!O270,0) -> 0.77076659 | H52: =IFERROR(BIO!P32/BIO!P270,0) -> 0 | I52: =IFERROR(BIO!Q32/BIO!Q270,0) -> 0 | J52: =IFERROR(BIO!R32/BIO!R270,0) -> 0 | K52: =IFERROR(BIO!S32/BIO!S270,0) -> 0.15978284 | ... AM52: =IFERROR(BIO!AU32/BIO!AU270,0) -> 0.69733811
B53: MINBIOCRP11 | C53: 2010 | D53: =IFERROR(BIO!L33/BIO!L271,0) -> 0 | E53: =IFERROR(BIO!M33/BIO!M271,0) -> 0.10429107 | F53: =IFERROR(BIO!N33/BIO!N271,0) -> 0.34626417 | G53: =IFERROR(BIO!O33/BIO!O271,0) -> 0.77076659 | H53: =IFERROR(BIO!P33/BIO!P271,0) -> 0 | I53: =IFERROR(BIO!Q33/BIO!Q271,0) -> 0 | J53: =IFERROR(BIO!R33/BIO!R271,0) -> 0 | K53: =IFERROR(BIO!S33/BIO!S271,0) -> 0.15978284 | ... AM53: =IFERROR(BIO!AU33/BIO!AU271,0) -> 0.69733811
B54: MINBIOCRP11 | C54: 2020 | D54: =IFERROR(BIO!L34/BIO!L272,0) -> 0 | E54: =IFERROR(BIO!M34/BIO!M272,0) -> 0.023145887 | F54: =IFERROR(BIO!N34/BIO!N272,0) -> 0.082608857 | G54: =IFERROR(BIO!O34/BIO!O272,0) -> 0.095468128 | H54: =IFERROR(BIO!P34/BIO!P272,0) -> 0 | I54: =IFERROR(BIO!Q34/BIO!Q272,0) -> 0 | J54: =IFERROR(BIO!R34/BIO!R272,0) -> 0 | K54: =IFERROR(BIO!S34/BIO!S272,0) -> 0.055457486 | ... AM54: =IFERROR(BIO!AU34/BIO!AU272,0) -> 0.16431284
B55: MINBIOCRP11 | C55: 2030 | D55: =IFERROR(BIO!L35/BIO!L273,0) -> 0 | E55: =IFERROR(BIO!M35/BIO!M273,0) -> 0.034800317 | F55: =IFERROR(BIO!N35/BIO!N273,0) -> 0.054112608 | G55: =IFERROR(BIO!O35/BIO!O273,0) -> 0.15125879 | H55: =IFERROR(BIO!P35/BIO!P273,0) -> 0 | I55: =IFERROR(BIO!Q35/BIO!Q273,0) -> 0 | J55: =IFERROR(BIO!R35/BIO!R273,0) -> 0 | K55: =IFERROR(BIO!S35/BIO!S273,0) -> 0.073256158 | ... AM55: =IFERROR(BIO!AU35/BIO!AU273,0) -> 0.10410254
B56: MINBIOCRP11 | C56: 2040 | D56: =IFERROR(BIO!L36/BIO!L274,0) -> 0 | E56: =IFERROR(BIO!M36/BIO!M274,0) -> 0.038056999 | F56: =IFERROR(BIO!N36/BIO!N274,0) -> 0.060222739 | G56: =IFERROR(BIO!O36/BIO!O274,0) -> 0.11816944 | H56: =IFERROR(BIO!P36/BIO!P274,0) -> 0 | I56: =IFERROR(BIO!Q36/BIO!Q274,0) -> 0 | J56: =IFERROR(BIO!R36/BIO!R274,0) -> 0 | K56: =IFERROR(BIO!S36/BIO!S274,0) -> 0.047320605 | ... AM56: =IFERROR(BIO!AU36/BIO!AU274,0) -> 0.10410528
B57: MINBIOCRP11 | C57: 2050 | D57: =IFERROR(BIO!L37/BIO!L275,0) -> 0 | E57: =IFERROR(BIO!M37/BIO!M275,0) -> 0.044144736 | F57: =IFERROR(BIO!N37/BIO!N275,0) -> 0.06812027 | G57: =IFERROR(BIO!O37/BIO!O275,0) -> 0.099913038 | H57: =IFERROR(BIO!P37/BIO!P275,0) -> 0 | I57: =IFERROR(BIO!Q37/BIO!Q275,0) -> 0 | J57: =IFERROR(BIO!R37/BIO!R275,0) -> 0 | K57: =IFERROR(BIO!S37/BIO!S275,0) -> 0.026853545 | ... AM57: =IFERROR(BIO!AU37/BIO!AU275,0) -> 0.10421
B58: MINBIOCRP31 | C58: 2005 | D58: =IFERROR(BIO!L45/BIO!L270,0) -> 0 | E58: =IFERROR(BIO!M45/BIO!M270,0) -> 0 | F58: =IFERROR(BIO!N45/BIO!N270,0) -> 0 | G58: =IFERROR(BIO!O45/BIO!O270,0) -> 0 | H58: =IFERROR(BIO!P45/BIO!P270,0) -> 0 | I58: =IFERROR(BIO!Q45/BIO!Q270,0) -> 0 | J58: =IFERROR(BIO!R45/BIO!R270,0) -> 0 | K58: =IFERROR(BIO!S45/BIO!S270,0) -> 0 | ... AM58: =IFERROR(BIO!AU45/BIO!AU270,0) -> 0
B59: MINBIOCRP31 | C59: 2010 | D59: =IFERROR(BIO!L46/BIO!L271,0) -> 0 | E59: =IFERROR(BIO!M46/BIO!M271,0) -> 0 | F59: =IFERROR(BIO!N46/BIO!N271,0) -> 0 | G59: =IFERROR(BIO!O46/BIO!O271,0) -> 0 | H59: =IFERROR(BIO!P46/BIO!P271,0) -> 0 | I59: =IFERROR(BIO!Q46/BIO!Q271,0) -> 0 | J59: =IFERROR(BIO!R46/BIO!R271,0) -> 0 | K59: =IFERROR(BIO!S46/BIO!S271,0) -> 0 | ... AM59: =IFERROR(BIO!AU46/BIO!AU271,0) -> 0
B60: MINBIOCRP31 | C60: 2020 | D60: =IFERROR(BIO!L47/BIO!L272,0) -> 0.8213368 | E60: =IFERROR(BIO!M47/BIO!M272,0) -> 0.31326822 | F60: =IFERROR(BIO!N47/BIO!N272,0) -> 0.24770809 | G60: =IFERROR(BIO!O47/BIO!O272,0) -> 0.57429563 | H60: =IFERROR(BIO!P47/BIO!P272,0) -> 0.8213368 | I60: =IFERROR(BIO!Q47/BIO!Q272,0) -> 0 | J60: =IFERROR(BIO!R47/BIO!R272,0) -> 0.69807067 | K60: =IFERROR(BIO!S47/BIO!S272,0) -> 0.37619662 | ... AM60: =IFERROR(BIO!AU47/BIO!AU272,0) -> 0.25480769
B61: MINBIOCRP31 | C61: 2030 | D61: =IFERROR(BIO!L48/BIO!L273,0) -> 0.8213368 | E61: =IFERROR(BIO!M48/BIO!M273,0) -> 0.29391736 | F61: =IFERROR(BIO!N48/BIO!N273,0) -> 0.22344547 | G61: =IFERROR(BIO!O48/BIO!O273,0) -> 0.65595683 | H61: =IFERROR(BIO!P48/BIO!P273,0) -> 0.8213368 | I61: =IFERROR(BIO!Q48/BIO!Q273,0) -> 0 | J61: =IFERROR(BIO!R48/BIO!R273,0) -> 0.69807067 | K61: =IFERROR(BIO!S48/BIO!S273,0) -> 0.28985387 | ... AM61: =IFERROR(BIO!AU48/BIO!AU273,0) -> 0.099535114
B62: MINBIOCRP31 | C62: 2040 | D62: =IFERROR(BIO!L49/BIO!L274,0) -> 0.8213368 | E62: =IFERROR(BIO!M49/BIO!M274,0) -> 0.26844776 | F62: =IFERROR(BIO!N49/BIO!N274,0) -> 0.13943431 | G62: =IFERROR(BIO!O49/BIO!O274,0) -> 0.54920605 | H62: =IFERROR(BIO!P49/BIO!P274,0) -> 0.8213368 | I62: =IFERROR(BIO!Q49/BIO!Q274,0) -> 0 | J62: =IFERROR(BIO!R49/BIO!R274,0) -> 0.69807067 | K62: =IFERROR(BIO!S49/BIO!S274,0) -> 0.27082294 | ... AM62: =IFERROR(BIO!AU49/BIO!AU274,0) -> 0.11149783
B63: MINBIOCRP31 | C63: 2050 | D63: =IFERROR(BIO!L50/BIO!L275,0) -> 0.8213368 | E63: =IFERROR(BIO!M50/BIO!M275,0) -> 0.23400855 | F63: =IFERROR(BIO!N50/BIO!N275,0) -> 0.036944868 | G63: =IFERROR(BIO!O50/BIO!O275,0) -> 0.53694371 | H63: =IFERROR(BIO!P50/BIO!P275,0) -> 0.8213368 | I63: =IFERROR(BIO!Q50/BIO!Q275,0) -> 0 | J63: =IFERROR(BIO!R50/BIO!R275,0) -> 0.69807067 | K63: =IFERROR(BIO!S50/BIO!S275,0) -> 0.25475936 | ... AM63: =IFERROR(BIO!AU50/BIO!AU275,0) -> 0.12930866
...

Sheet BioImport
A1: reference
B2: ~UC_SETS: R_S: AT,BE,BG,CH,CY,CZ,DE,DK,EE,ES,FI,FR,EL,HU,IE,IT,IS,LT,LU,LV,MT,NL,NO,PL,PT,RO,SE,SI,SK,HR,UK
H3: ~UC_T
B4: UC_N | C4: Pset_PN | D4: Pset_CI | E4: Cset_CN | F4: Attribute | G4: Year | H4: LimType | I4: UC_COMPRD | J4: UC_FLO | K4: UC_ACT | L4: UC_RHST~2005 | M4: UC_RHST~2010 | N4: UC_RHST~2020 | O4: UC_RHST~2030 | P4: UC_RHST~2040 | Q4: UC_RHST~2050 | R4: UC_RHST~0 | S4: UC_Desc
B5: AU_EU-IMP_ETH | C5: IMPBIOETH* | G5: 2020,2030,2040,2050 | H5: UP | K5: 1 | L5: 6573.7052 | M5: 6573.7052 | N5: 6573.7052 | O5: 22788.845 | P5: 22788.845 | Q5: 22788.845 | R5: 15 | S5: AU_EU-IMP_ETH
B6: AU_EU-IMP_EMHV | C6: IMPBIOEMHV* | G6: 2020,2030,2040,2050 | H6: UP | K6: 1 | L6: 7012.987 | M6: 7012.987 | N6: 7012.987 | O6: 12181.818 | P6: 12181.818 | Q6: 12181.818 | R6: 15 | S6: AU_EU-IMP_EMHV
B7: AU_EU-IMP_WOO | C7: IMPBIOWOO | G7: 2020,2030,2040,2050 | H7: UP | K7: 1 | L7: 283 | M7: 283 | N7: 283 | O7: 517 | P7: 517 | Q7: 517 | R7: 15 | S7: AU_EU-IMP_WOO
B9: ~TFM_INS
B10: TimeSlice | C10: Curr | D10: LimType | E10: Attribute | F10: Year | G10: Pset_PN | H10: AllRegions | K10: EUR/GJ | L10: MJ/kg | M10: EUR/GJ
C11: EUR10 | E11: ACT_COST | F11: 2005,2020 | G11: IMPBIOETH* | H11: 0.88260727 | K11: 35.163636 | L11: 26.8 | M11: =H11/L11*1000 -> 32.933107
C12: EUR10 | E12: ACT_COST | F12: 2030,2040,2050 | G12: IMPBIOETH* | H12: 0.67010857 | K12: 92.551515 | L12: 26.8 | M12: =H12/L12*1000 -> 25.004051
C13: EUR10 | E13: ACT_COST | F13: 2005,2020 | G13: IMPBIOEMHV* | H13: =0.531813333333333*1.2 -> 0.638176 | K13: 13.813333 | L13: 37.4 | M13: =H13/L13*1000 -> 17.063529
C14: EUR10 | E14: ACT_COST | F14: 2030,2040,2050 | G14: IMPBIOEMHV* | H14: =0.472146268656716*1.22 -> 0.57601845 | K14: 21.302222 | L14: 37.4 | M14: =H14/L14*1000 -> 15.401563
C15: EUR10 | E15: ACT_COST | F15: 2005,2020 | G15: IMPBIOWOO | H15: 7.0939929 | K15: 7.0939929
C16: EUR10 | E16: ACT_COST | F16: 2030,2040,2050 | G16: IMPBIOWOO | H16: 7.0123791 | K16: 12.810601
B19: Nordic export limits within EU
B21: ~TFM_INS
B22: Attribute | C22: LimType | D22: Year | E22: FI | F22: SE | G22: Pset_PN | H22: Pset_Set | J22: =J23/1000/1000 -> 4.604523
B23: ACT_BND | C23: UP | D23: 2025 | E23: 15 | F23: 40 | G23: TB_BIOWOO-G26 | J23: =J25*J24 -> 4604523 | K23: GJ
B24: ACT_BND | C24: UP | D24: 2035 | E24: 10 | F24: 40 | G24: TB_BIOWOO-G26 | J24: 42 | K24: GJ/toe
B25: ACT_BND | C25: UP | D25: 0 | E25: 5 | F25: 40 | G25: TB_BIOWOO-G26 | J25: =J26*J27 -> 109631.5 | K25: toe
J26: 0.3215 | K26: toe/t
J27: =J28*1000 -> 341000 | K27: t
J28: 341 | K28: kt
B30: ~TFM_INS
B31: TimeSlice | C31: Curr | D31: LimType | E31: Attribute | F31: Year | G31: Pset_PN | H31: AllRegions | I31: AT | J31: BE | K31: BG | L31: HR | M31: CY | N31: CZ | O31: DK | P31: EE | Q31: FI | R31: FR | S31: DE | T31: EL | U31: HU | V31: IE | W31: IT | X31: LV | Y31: LT | Z31: LU | AA31: MT | AB31: NL | AC31: PL | AD31: PT | AE31: RO | AF31: SK | AG31: SI | AH31: ES | AI31: SE | AJ31: UK | AL31: EU31 | AM31: EU27
B32: ANNUAL | D32: UP | E32: ACT_BND | F32: 2010 | G32: =BioImport!$C$7 -> IMPBIOWOO | H32: 0 | I32: 0 | J32: 9.5 | K32: 0 | L32: 5 | M32: 0 | N32: 0 | O32: 30 | P32: 0 | Q32: 0 | R32: 0 | S32: 0 | T32: 0 | U32: 0 | V32: 1 | W32: 30 | X32: 0 | Y32: 0 | Z32: 0 | AA32: 0 | AB32: 3 | AC32: 0 | AD32: 0 | AE32: 0 | AF32: 0 | AG32: 1 | AH32: 0 | AI32: 4 | AJ32: 73 | AL32: =SUM(I32:AJ32) -> 156.5 | AM32: =AL32-AJ32 -> 83.5
B33: ANNUAL | D33: UP | E33: ACT_BND | F33: 2015 | G33: =BioImport!$C$7 -> IMPBIOWOO | H33: 0 | I33: 0 | J33: 9.5 | K33: 0 | L33: 5 | M33: 0 | N33: 0 | O33: 30 | P33: 0 | Q33: 0 | R33: 0 | S33: 0 | T33: 0 | U33: 0 | V33: 1 | W33: 30 | X33: 0 | Y33: 0 | Z33: 0 | AA33: 0 | AB33: 3 | AC33: 0 | AD33: 0 | AE33: 0 | AF33: 0 | AG33: 1 | AH33: 0 | AI33: 4 | AJ33: 73 | AL33: =SUM(I33:AJ33) -> 156.5 | AM33: =AL33-AJ33 -> 83.5
B34: ANNUAL | D34: UP | E34: ACT_BND | F34: 2020 | G34: =BioImport!$C$7 -> IMPBIOWOO | H34: 0 | I34: 0 | J34: 10 | K34: 0 | L34: 5 | M34: 0 | N34: 0 | O34: 32 | P34: 0 | Q34: 0 | R34: 0 | S34: 0 | T34: 0 | U34: 0 | V34: 1 | W34: 32 | X34: 0 | Y34: 0 | Z34: 0 | AA34: 0 | AB34: 3 | AC34: 0 | AD34: 0 | AE34: 0 | AF34: 0 | AG34: 1 | AH34: 0 | AI34: 4 | AJ34: 76 | AL34: =SUM(I34:AJ34) -> 164 | AM34: =AL34-AJ34 -> 88
B35: ANNUAL | D35: UP | E35: ACT_BND | F35: 2025 | G35: =BioImport!$C$7 -> IMPBIOWOO | H35: 0 | I35: 0 | J35: 11 | K35: 0 | L35: 5 | M35: 0 | N35: 0 | O35: 34 | P35: 0 | Q35: 0 | R35: 0 | S35: 0 | T35: 0 | U35: 0 | V35: 1 | W35: 34 | X35: 0 | Y35: 0 | Z35: 0 | AA35: 0 | AB35: 4 | AC35: 0 | AD35: 0 | AE35: 0 | AF35: 0 | AG35: 1 | AH35: 0 | AI35: 4 | AJ35: 79 | AL35: =SUM(I35:AJ35) -> 173 | AM35: =AL35-AJ35 -> 94
B36: ANNUAL | D36: UP | E36: ACT_BND | F36: 2030 | G36: =BioImport!$C$7 -> IMPBIOWOO | H36: 0 | I36: 0 | J36: 12 | K36: 0 | L36: 5 | M36: 0 | N36: 0 | O36: 36 | P36: 0 | Q36: 0 | R36: 0 | S36: 0 | T36: 1 | U36: 0 | V36: 1 | W36: 36 | X36: 0 | Y36: 0 | Z36: 0 | AA36: 0 | AB36: 4 | AC36: 0 | AD36: 0 | AE36: 0 | AF36: 0 | AG36: 1 | AH36: 0 | AI36: 4 | AJ36: 83 | AL36: =SUM(I36:AJ36) -> 183 | AM36: =AL36-AJ36 -> 100
B37: ANNUAL | D37: UP | E37: ACT_BND | F37: 0 | G37: IMPBIOWOO | H37: 5
B39: ~TFM_MIG
B40: Attribute | C40: Year | D40: Attribute2 | E40: AllRegions | F40: Pset_PN | G40: Cset_CN2 | H40: Timeslice2 | I40: SourceScen
B41: ACT_COST | C41: 2015 | D41: FLO_DELIV | E41: *-1 | F41: MINBIOCRP11 | G41: BIOWOO | H41: ANNUAL | I41: biopot_biom16_forestbau
B42: ACT_COST | C42: 2030 | D42: FLO_DELIV | E42: *-1 | F42: MINBIOCRP11 | G42: BIOWOO | H42: ANNUAL | I42: biopot_biom16_forestbau
B43: ACT_COST | C43: 2040 | D43: FLO_DELIV | E43: *-1 | F43: MINBIOCRP11 | G43: BIOWOO | H43: ANNUAL | I43: biopot_biom16_forestbau
B44: ACT_COST | C44: 2015 | D44: FLO_DELIV | E44: *-1 | F44: MINBIORPS1 | G44: BIOWOO | H44: ANNUAL | I44: biopot_biom16_forestbau
B45: ACT_COST | C45: 2030 | D45: FLO_DELIV | E45: *-1 | F45: MINBIORPS1 | G45: BIOWOO | H45: ANNUAL | I45: biopot_biom16_forestbau
B46: ACT_COST | C46: 2040 | D46: FLO_DELIV | E46: *-1 | F46: MINBIORPS1 | G46: BIOWOO | H46: ANNUAL | I46: biopot_biom16_forestbau
...
