Workbook

Sheet ETS1CO2bound
B1: EU ETS1 2010-2020 | N1: UK ETS 2021-
B4: ~UC_SETS: R_S: AT,BE,BG,CY,CH,CZ,DE,DK,EE,ES,FI,FR,EL,HR,HU,IE,IT,IS,LT,LU,LV,MT,NL,NO,PL,PT,RO,SE,SI,SK,UK | N4: DeAct~UC_SETS: R_S: UK
E6: ~UC_T: UP | Q6: DeAct~UC_T: UP
B7: UC_N | C7: Pset_PN | D7: Cset_CN | E7: Year | F7: UC_FLO | G7: UC_COMNET | H7: UC_RHSTS | I7: UC_COMPRD | N7: UC_N | O7: Pset_PN | P7: Cset_CN | Q7: Year | R7: UC_COMNET | S7: UC_RHSTS | T7: UC_COMPRD | V7: CO2 from extra-EU flights
B8: CO2CapETSold | D8: ETSCO2 | E8: 2010 | G8: 1 | H8: =1971657.255+K8 -> 1971657.3 | N8: CO2CapUKETS | P8: ETSCO2 | Q8: 2021 | R8: 1 | S8: =155671.581+V8 -> 180582 | V8: 24910.424
D9: ETSCO2 | E9: 2015 | H9: =1856001.3825+K9 -> 1856001.4 | Q9: 2025 | S9: =69000+V9 -> 95837.172 | V9: 26837.172
D10: ETSCO2 | E10: 2020 | H10: ='Cap trajectories'!E5*1000+K10 -> 1615000 | Q10: 2030 | S10: =69000+V10 -> 97601.581 | V10: 28601.581
D11: ETSCO2 | E11: 0 | H11: 1 | Q11: 0 | S11: 5
C12: TRAHFO00,TRALFO00 | D12: ETSCO2 | E12: 2010 | F12: -1
C13: TRAHFO00,TRALFO00 | D13: ETSCO2 | E13: 2020 | F13: -1
C14: TRAHFO00,TRALFO00 | D14: ETSCO2 | E14: 0 | F14: 1
B17: NOTE!
B18: ETS Covers CH4 and N2O from 2026 onwards. How to include in calculation?
B20: EU ETS1 2021- | D20: deactivated, using regional limits
B22: DeAct**UC_SETS: R_S: AT,BE,BG,CY,CH,CZ,DE,DK,EE,ES,FI,FR,EL,HR,HU,IE,IT,IS,LT,LU,LV,MT,NL,NO,PL,PT,RO,SE,SI,SK
E24: DeAct**UC_T: UP
B25: UC_N | C25: Pset_PN | D25: Cset_CN | E25: Year | F25: UC_COMNET | G25: UC_RHSTS | H25: UC_COMPRD
B26: CO2CapETS1UP | D26: ETSCO2 | E26: 2021 | F26: 1 | G26: ='Cap trajectories'!E6*1000+K26 -> 1572000
D27: ETSCO2 | E27: 2025 | G27: ='Cap trajectories'!D10*1000+K27 -> 1299684.1
D28: ETSCO2 | E28: 2030 | G28: ='Cap trajectories'!D15*1000+K28 -> 830318.18
D29: ETSCO2 | E29: 2035 | G29: ='Cap trajectories'!D20*1000+ETS1CO2bound!K29 -> 490000
D30: ETSCO2 | E30: 2040 | G30: ='Cap trajectories'!D25*1000+ETS1CO2bound!K30 -> 150000
D31: ETSCO2 | E31: 2045 | G31: ='Cap trajectories'!D30*1000+ETS1CO2bound!K31 -> 110000
D32: ETSCO2 | E32: 2050 | G32: ='Cap trajectories'!D35*1000+ETS1CO2bound!K32 -> 72000
D33: ETSCO2 | E33: 0 | G33: 5
E37: DeAct**UC_T: LO
B38: UC_N | C38: Pset_PN | D38: Cset_CN | E38: Year | F38: UC_COMNET | G38: UC_RHSTS | H38: UC_COMPRD
B39: CO2CapETS1LO | D39: ETSCO2 | E39: 2025 | F39: 1 | G39: =G27*0.99 -> 1286687.3
D40: ETSCO2 | E40: 2030 | G40: =G28*0.98 -> 813711.82
E41: 0 | G41: 1
B44: COUNTRY-SPECIFIC-LIMITS | G44: values from S1 model run 14.10.2025 for year 2035: the year until union-wide ETS emissions decreased, before starting to increase again
G45: =G63 -> 24312.788 | H45: =H63 -> 18033.912 | I45: =I63 -> 2795.9235 | J45: =J63 -> 16741.21 | K45: =K63 -> 1319.3512 | L45: =L63 -> 14604.345 | M45: =M63 -> 120496.39 | N45: =N63 -> 7688.1183 | ... AK45: =AK63 -> 122975.21
B46: ~TFM_INS
B47: TimeSlice | C47: LimType | D47: Year | E47: Attribute | F47: Cset_CN | G47: AT | H47: BE | I47: BG | J47: CH | K47: CY | L47: CZ | M47: DE | N47: DK | O47: EE | P47: EL | Q47: ES | R47: FI | S47: FR | T47: HR | U47: HU | V47: IE | W47: IS | X47: IT | Y47: LT | Z47: LU | AA47: LV | AB47: MT | AC47: NL | AD47: NO | AE47: PL | AF47: PT | AG47: RO | AH47: SE | AI47: SI | AJ47: SK | AK47: UK | AN47: multiplicator | AP47: EU27+NO
B48: ANNUAL | C48: UP | D48: 2035 | E48: COM_BNDNET | F48: ETSCO2 | G48: =G$45*$AN48 -> 24337.101 | H48: =H$45*$AN48 -> 18051.946 | I48: =I$45*$AN48 -> 2798.7194 | J48: =J$45*$AN48 -> 16757.952 | K48: =K$45*$AN48 -> 1320.6705 | L48: =L$45*$AN48 -> 14618.949 | M48: =M$45*$AN48 -> 120616.89 | N48: =N$45*$AN48 -> 7695.8064 | ... AK48: =AK$45*$AN48 -> 123098.19 | AN48: 1.001 | AP48: =SUM(G48:AK48)-AK48-J48-W48 -> 565071.27
B49: ANNUAL | C49: UP | D49: 2040 | E49: COM_BNDNET | F49: ETSCO2 | G49: =G$45*$AN49 -> 21881.509 | H49: =H$45*$AN49 -> 16230.521 | I49: =I$45*$AN49 -> 2516.3311 | J49: =J$45*$AN49 -> 15067.089 | K49: =K$45*$AN49 -> 1187.4161 | L49: =L$45*$AN49 -> 13143.911 | M49: =M$45*$AN49 -> 108446.75 | N49: =N$45*$AN49 -> 6919.3065 | ... AK49: =AK$45*$AN49 -> 110677.69 | AN49: 0.9 | AP49: =SUM(G49:AK49)-AK49-J49-W49 -> 508056.09
B50: ANNUAL | C50: UP | D50: 2045 | E50: COM_BNDNET | F50: ETSCO2 | G50: =G$45*$AN50 -> 16557.008 | H50: =H$45*$AN50 -> 12281.094 | I50: =I$45*$AN50 -> 1904.0239 | J50: =J$45*$AN50 -> 11400.764 | K50: =K$45*$AN50 -> 898.47815 | L50: =L$45*$AN50 -> 9945.559 | M50: =M$45*$AN50 -> 82058.041 | N50: =N$45*$AN50 -> 5235.6086 | ... AK50: =AK$45*$AN50 -> 83746.121 | AN50: 0.681 | AP50: =SUM(G50:AK50)-AK50-J50-W50 -> 384429.11
B51: ANNUAL | C51: UP | D51: 2050 | E51: COM_BNDNET | F51: ETSCO2 | G51: =G$45*$AN51 -> 11159.57 | H51: =H$45*$AN51 -> 8277.5655 | I51: =I$45*$AN51 -> 1283.3289 | J51: =J$45*$AN51 -> 7684.2156 | K51: =K$45*$AN51 -> 605.58219 | L51: =L$45*$AN51 -> 6703.3944 | M51: =M$45*$AN51 -> 55307.843 | N51: =N$45*$AN51 -> 3528.8463 | ... AK51: =AK$45*$AN51 -> 56445.623 | AN51: 0.459 | AP51: =SUM(G51:AK51)-AK51-J51-W51 -> 259108.61
B52: ANNUAL | C52: UP | D52: 2055 | E52: COM_BNDNET | F52: ETSCO2 | G52: =G$45*$AN52 -> 7208.7416 | H52: =H$45*$AN52 -> 5347.0549 | I52: =I$45*$AN52 -> 828.99132 | J52: =J$45*$AN52 -> 4963.7689 | K52: =K$45*$AN52 -> 391.18762 | L52: =L$45*$AN52 -> 4330.1883 | M52: =M$45*$AN52 -> 35727.18 | N52: =N$45*$AN52 -> 2279.5271 | ... AK52: =AK$45*$AN52 -> 36462.151 | AN52: 0.2965 | AP52: =SUM(G52:AK52)-AK52-J52-W52 -> 167376.26
B53: ANNUAL | C53: UP | D53: 2060 | E53: COM_BNDNET | F53: ETSCO2 | G53: =G$45*$AN53 -> 2431.2788 | H53: =H$45*$AN53 -> 1803.3912 | I53: =I$45*$AN53 -> 279.59235 | J53: =J$45*$AN53 -> 1674.121 | K53: =K$45*$AN53 -> 131.93512 | L53: =L$45*$AN53 -> 1460.4345 | M53: =M$45*$AN53 -> 12049.639 | N53: =N$45*$AN53 -> 768.81183 | ... AK53: =AK$45*$AN53 -> 12297.521 | AN53: 0.1 | AP53: =SUM(G53:AK53)-AK53-J53-W53 -> 56450.677
...

Sheet ETS1CO2price
C1: Harmonised trajectory for the carbon price/value (EUR2020/tCO2)
C2: updated 08/2025 | E2: EUR23->EUR20 | F2: 1.1941
C3: WEM-trajectory
C5: ~TFM_INS
C6: Attribute | D6: Year | E6: Other_indexes | F6: AllRegions | G6: UK | H6: Pset_PN | I6: Pset_Set | J6: Cset_CN | K6: Curr | N6: Values used in NEGEM
A7: Energy sector (CDR excluded) | C7: COM_TAXPRD | D7: 2010 | F7: 0 | G7: =F7 -> 0 | J7: ELCCO2N,INDCO2N,SUPCO2N,INDCO2P,-*SCO2P,-*SCO2N | K7: EUR10
C8: COM_TAXPRD | D8: 2020 | F8: =29/1000 -> 0.029 | G8: =F8 -> 0.029 | J8: =J7 -> ELCCO2N,INDCO2N,SUPCO2N,INDCO2P,-*SCO2P,-*SCO2N | K8: EUR20 | N8: 0.03 | O8: EUR15
C9: COM_TAXPRD | D9: 2025 | F9: =0.095/F2 -> 0.079557826 | G9: =F9 -> 0.079557826 | J9: =J8 -> ELCCO2N,INDCO2N,SUPCO2N,INDCO2P,-*SCO2P,-*SCO2N | K9: EUR20
C10: COM_TAXPRD | D10: 2030 | F10: =0.095/F2 -> 0.079557826 | G10: =F10 -> 0.079557826 | J10: =J9 -> ELCCO2N,INDCO2N,SUPCO2N,INDCO2P,-*SCO2P,-*SCO2N | K10: EUR20 | N10: 0.06 | O10: EUR15
C11: COM_TAXPRD | D11: 2035 | F11: =0.1/F2 -> 0.08374508 | G11: =F11 -> 0.08374508 | J11: =J10 -> ELCCO2N,INDCO2N,SUPCO2N,INDCO2P,-*SCO2P,-*SCO2N | K11: EUR20 | N11: 0.073 | O11: EUR15
C12: COM_TAXPRD | D12: 2040 | F12: =0.105/F2 -> 0.087932334 | G12: =F12 -> 0.087932334 | J12: =J11 -> ELCCO2N,INDCO2N,SUPCO2N,INDCO2P,-*SCO2P,-*SCO2N | K12: EUR20 | N12: 0.082 | O12: EUR15
C13: COM_TAXPRD | D13: 2045 | F13: =0.16/F2 -> 0.13399213 | G13: =F13 -> 0.13399213 | J13: =J12 -> ELCCO2N,INDCO2N,SUPCO2N,INDCO2P,-*SCO2P,-*SCO2N | K13: EUR20 | N13: 0.124 | O13: EUR15
C14: COM_TAXPRD | D14: 2050 | F14: =0.19/F2 -> 0.15911565 | G14: =F14 -> 0.15911565 | J14: =J13 -> ELCCO2N,INDCO2N,SUPCO2N,INDCO2P,-*SCO2P,-*SCO2N | K14: EUR20 | N14: 0.153 | O14: EUR15
C15: COM_TAXPRD | D15: 2055 | F15: =0.22/F2 -> 0.18423918 | G15: =F15 -> 0.18423918 | J15: =J14 -> ELCCO2N,INDCO2N,SUPCO2N,INDCO2P,-*SCO2P,-*SCO2N | K15: EUR20 | N15: 0.153 | O15: EUR15
C16: COM_TAXPRD | D16: 0 | F16: 5 | G16: =F16 -> 5 | J16: =J15 -> ELCCO2N,INDCO2N,SUPCO2N,INDCO2P,-*SCO2P,-*SCO2N | K16: EUR20
A17: Aviation | C17: COM_TAXPRD | D17: 2012 | F17: 0.001 | G17: =F17 -> 0.001 | H17: BLDJET,BLD_RFNBO_JET | J17: SE_TRACO2N | K17: EUR10
C18: COM_TAXPRD | D18: 2020 | F18: 0.002 | G18: =F18 -> 0.002 | H18: =H17 -> BLDJET,BLD_RFNBO_JET | J18: SE_TRACO2N | K18: =K8 -> EUR20
C19: COM_TAXPRD | D19: 2027 | F19: =F9 -> 0.079557826 | G19: =F19 -> 0.079557826 | H19: =H18 -> BLDJET,BLD_RFNBO_JET | J19: SE_TRACO2N | K19: =K9 -> EUR20
C20: COM_TAXPRD | D20: 2030 | F20: =F10 -> 0.079557826 | G20: =F20 -> 0.079557826 | H20: =H19 -> BLDJET,BLD_RFNBO_JET | J20: SE_TRACO2N | K20: =K10 -> EUR20
C21: COM_TAXPRD | D21: 2035 | F21: =F11 -> 0.08374508 | G21: =F21 -> 0.08374508 | H21: =H20 -> BLDJET,BLD_RFNBO_JET | J21: SE_TRACO2N | K21: =K11 -> EUR20
C22: COM_TAXPRD | D22: 2040 | F22: =F12 -> 0.087932334 | G22: =F22 -> 0.087932334 | H22: =H21 -> BLDJET,BLD_RFNBO_JET | J22: SE_TRACO2N | K22: =K12 -> EUR20
C23: COM_TAXPRD | D23: 2045 | F23: =F13 -> 0.13399213 | G23: =F23 -> 0.13399213 | H23: =H22 -> BLDJET,BLD_RFNBO_JET | J23: SE_TRACO2N | K23: =K13 -> EUR20
C24: COM_TAXPRD | D24: 2050 | F24: =F14 -> 0.15911565 | G24: =F24 -> 0.15911565 | H24: =H23 -> BLDJET,BLD_RFNBO_JET | J24: SE_TRACO2N | K24: =K14 -> EUR20
C25: COM_TAXPRD | D25: 2055 | F25: =F15 -> 0.18423918 | G25: =F25 -> 0.18423918 | H25: =H24 -> BLDJET,BLD_RFNBO_JET | J25: SE_TRACO2N | K25: =K15 -> EUR20
C26: COM_TAXPRD | D26: 0 | F26: =F16 -> 5 | G26: =F26 -> 5 | H26: =H25 -> BLDJET,BLD_RFNBO_JET | J26: SE_TRACO2N | K26: =K16 -> EUR20
A27: Maritime transport: HFO | C27: COM_TAXPRD | D27: 2024 | F27: =F19*0.4 -> 0.03182313 | G27: =F27 -> 0.03182313 | H27: TRAHFO00,BLD_RFNBO_NAV | J27: SE_TRACO2N | K27: =K18 -> EUR20
C28: COM_TAXPRD | D28: 2025 | F28: =F19*0.7 -> 0.055690478 | G28: =F28 -> 0.055690478 | H28: =H27 -> TRAHFO00,BLD_RFNBO_NAV | J28: SE_TRACO2N | K28: =K19 -> EUR20
C29: COM_TAXPRD | D29: 2026 | F29: =F19 -> 0.079557826 | G29: =F29 -> 0.079557826 | H29: =H28 -> TRAHFO00,BLD_RFNBO_NAV | J29: SE_TRACO2N | K29: =K20 -> EUR20
C30: COM_TAXPRD | D30: 2030 | F30: =F20 -> 0.079557826 | G30: =F30 -> 0.079557826 | H30: =H29 -> TRAHFO00,BLD_RFNBO_NAV | J30: SE_TRACO2N | K30: =K21 -> EUR20
C31: COM_TAXPRD | D31: 2035 | F31: =F21 -> 0.08374508 | G31: =F31 -> 0.08374508 | H31: =H30 -> TRAHFO00,BLD_RFNBO_NAV | J31: SE_TRACO2N | K31: =K22 -> EUR20
C32: COM_TAXPRD | D32: 2040 | F32: =F22 -> 0.087932334 | G32: =F32 -> 0.087932334 | H32: =H31 -> TRAHFO00,BLD_RFNBO_NAV | J32: SE_TRACO2N | K32: =K23 -> EUR20
C33: COM_TAXPRD | D33: 2045 | F33: =F23 -> 0.13399213 | G33: =F33 -> 0.13399213 | H33: =H32 -> TRAHFO00,BLD_RFNBO_NAV | J33: SE_TRACO2N | K33: =K24 -> EUR20
C34: COM_TAXPRD | D34: 2050 | F34: =F24 -> 0.15911565 | G34: =F34 -> 0.15911565 | H34: =H33 -> TRAHFO00,BLD_RFNBO_NAV | J34: SE_TRACO2N | K34: =K25 -> EUR20
C35: COM_TAXPRD | D35: 2055 | F35: =F25 -> 0.18423918 | G35: =F35 -> 0.18423918 | H35: =H34 -> TRAHFO00,BLD_RFNBO_NAV | J35: SE_TRACO2N | K35: =K26 -> EUR20
C36: COM_TAXPRD | D36: 0 | F36: =F26 -> 5 | G36: =F36 -> 5 | H36: =H35 -> TRAHFO00,BLD_RFNBO_NAV | J36: SE_TRACO2N | K36: =K27 -> EUR20
A37: Maritime transport: LFO | C37: COM_TAXPRD | D37: 2024 | F37: =F19 -> 0.079557826 | G37: =F37 -> 0.079557826 | H37: TRALFO00 | J37: SE_TRACO2N | K37: =K28 -> EUR20
C38: COM_TAXPRD | D38: 2030 | F38: =F30 -> 0.079557826 | G38: =F38 -> 0.079557826 | H38: TRALFO00 | J38: SE_TRACO2N | K38: =K29 -> EUR20
C39: COM_TAXPRD | D39: 2035 | F39: =F31 -> 0.08374508 | G39: =F39 -> 0.08374508 | H39: TRALFO00 | J39: SE_TRACO2N | K39: =K30 -> EUR20
C40: COM_TAXPRD | D40: 2040 | F40: =F32 -> 0.087932334 | G40: =F40 -> 0.087932334 | H40: TRALFO00 | J40: SE_TRACO2N | K40: =K31 -> EUR20
C41: COM_TAXPRD | D41: 2045 | F41: =F33 -> 0.13399213 | G41: =F41 -> 0.13399213 | H41: TRALFO00 | J41: SE_TRACO2N | K41: =K32 -> EUR20
...

Sheet Cap trajectories
A1: https://www.umweltbundesamt.de/sites/default/files/medien/11850/publikationen/factsheet_cap_msr_2023_en_v2.pdf | F1: 1954.5455 | N1: =-O10/N10 -> 1835.2222
A2: https://climate.ec.europa.eu/news-your-voice/news/emissions-trading-system-buildings-road-transport-and-small-industry-ets2-cap-adopted-2027-2024-12-03_en | C2: Sum of ETS1 and ETS2 | D2: ETS1 Total Cap (new) | E2: Cap according to previous directive (without UK) | F2: LFR | G2: Annual cap reduction through LRFs (stationary) | H2: Rebasing the cap | I2: Cap stationary installations (new) | J2: Cap maritime transport | K2: Maritime cap reduction | M2: ETS2 Total Cap | N2: LFR | O2: Annual cap reduction through LFRs
B3: 2018 | F3: 0.0174
B4: 2019 | F4: 0.0174
B5: 2020 | E5: =1615 -> 1615 | F5: 0.0174 | G5: =-$F$1*F5 -> -34.009091 | H5: 34
B6: 2021 | E6: =1572 -> 1572 | F6: 0.022 | G6: =-$F$1*F6 -> -43 | H6: 43
B7: 2022 | E7: =1529 -> 1529 | F7: 0.022 | G7: =-$F$1*F7 -> -43
B8: 2023 | E8: =1486 -> 1486 | F8: 0.022 | G8: =-$F$1*F8 -> -43
B9: 2024 | D9: =I9+J9 -> 1386.9545 | E9: 1443 | F9: 0.043 | G9: =-$F$1*F9 -> -84.045455 | H9: -90 | I9: =E8+G9+H9 -> 1311.9545 | J9: 75 | K9: =-$J$9*F9 -> -3.225
B10: 2025 | D10: =I10+J10 -> 1299.6841 | E10: 1400 | F10: 0.043 | G10: =-$F$1*F10 -> -84.045455 | I10: =I9+G10+H10 -> 1227.9091 | J10: =J9+K9 -> 71.775 | K10: =-$J$9*F10 -> -3.225 | M10: =1223481445/1000/1000 -> 1223.4814 | N10: 0.051 | O10: =-(M10-M12)/2 -> -93.596331
B11: 2026 | D11: =I11+J11 -> 1185.4136 | E11: 1357 | F11: 0.043 | G11: =-$F$1*F11 -> -84.045455 | H11: -27 | I11: =I10+G11+H11 -> 1116.8636 | J11: =J10+K10 -> 68.55 | K11: =-$J$9*F11 -> -3.225 | M11: =M10+O11 -> 1129.8851 | N11: 0.051 | O11: =O10 -> -93.596331
B12: 2027 | D12: =I12+J12 -> 1098.1432 | E12: 1314 | F12: 0.043 | G12: =-$F$1*F12 -> -84.045455 | I12: =I11+G12+H12 -> 1032.8182 | J12: =J11+K11 -> 65.325 | K12: =-$J$9*F12 -> -3.225 | M12: =1036288784/1000/1000 -> 1036.2888 | N12: =N11 -> 0.051 | O12: =-N12*$N$1 -> -93.596331
B13: 2028 | D13: =I13+J13 -> 1008.9182 | E13: 1271 | F13: 0.044 | G13: =-$F$1*F13 -> -86 | I13: =I12+G13+H13 -> 946.81818 | J13: =J12+K12 -> 62.1 | K13: =-$J$9*F13 -> -3.3 | M13: =M12+O13 -> 937.55383 | N13: 0.0538 | O13: =-N13*$N$1 -> -98.734953
B14: 2029 | D14: =I14+J14 -> 919.61818 | E14: 1228 | F14: 0.044 | G14: =-$F$1*F14 -> -86 | I14: =I13+G14+H14 -> 860.81818 | J14: =J13+K13 -> 58.8 | K14: =-$J$9*F14 -> -3.3 | M14: =M13+O14 -> 838.81888 | N14: =N13 -> 0.0538 | O14: =-N14*$N$1 -> -98.734953
B15: 2030 | D15: =I15+J15 -> 830.31818 | E15: 1184 | F15: 0.044 | G15: =-$F$1*F15 -> -86 | I15: =I14+G15+H15 -> 774.81818 | J15: =J14+K14 -> 55.5 | K15: =-$J$9*F15 -> -3.3 | M15: =M14+O15 -> 740.08393 | N15: =N14 -> 0.0538 | O15: =-N15*$N$1 -> -98.734953
B16: 2031 | D16: =I16+J16 -> 741.01818 | F16: =F15 -> 0.044 | G16: =-$F$1*F16 -> -86 | I16: =I15+G16+H16 -> 688.81818 | J16: =J15+K15 -> 52.2 | K16: =-$J$9*F16 -> -3.3 | M16: =M15+O16 -> 641.34897 | N16: =N15 -> 0.0538 | O16: =-N16*$N$1 -> -98.734953
B17: 2032 | D17: =I17+J17 -> 651.71818 | F17: =F16 -> 0.044 | G17: =-$F$1*F17 -> -86 | I17: =I16+G17+H17 -> 602.81818 | J17: =J16+K16 -> 48.9 | K17: =-$J$9*F17 -> -3.3 | M17: =M16+O17 -> 542.61402 | N17: =N16 -> 0.0538 | O17: =-N17*$N$1 -> -98.734953
B18: 2033 | D18: =I18+J18 -> 562.41818 | F18: =F17 -> 0.044 | G18: =-$F$1*F18 -> -86 | I18: =I17+G18+H18 -> 516.81818 | J18: =J17+K17 -> 45.6 | K18: =-$J$9*F18 -> -3.3 | M18: =M17+O18 -> 443.87907 | N18: =N17 -> 0.0538 | O18: =-N18*$N$1 -> -98.734953
B19: 2034 | D19: =I19+J19 -> 473.11818 | F19: =F18 -> 0.044 | G19: =-$F$1*F19 -> -86 | I19: =I18+G19+H19 -> 430.81818 | J19: =J18+K18 -> 42.3 | K19: =-$J$9*F19 -> -3.3 | M19: =M18+O19 -> 345.14412 | N19: =N18 -> 0.0538 | O19: =-N19*$N$1 -> -98.734953
A20: ETS1 and 2 merge in 2035? | B20: 2035 | C20: =D20+M20 -> 736.40916 | D20: 490 | F20: =F19 -> 0.044 | G20: =-$F$1*F20 -> -86 | I20: =I19+G20+H20 -> 344.81818 | J20: =J19+K19 -> 39 | K20: =-$J$9*F20 -> -3.3 | M20: =M19+O20 -> 246.40916 | N20: =N19 -> 0.0538 | O20: =-N20*$N$1 -> -98.734953
B21: 2036 | C21: =D21+M21 -> 147.67421 | F21: =F20 -> 0.044 | G21: =-$F$1*F21 -> -86 | I21: =I20+G21+H21 -> 258.81818 | J21: =J20+K20 -> 35.7 | K21: =-$J$9*F21 -> -3.3 | M21: =M20+O21 -> 147.67421 | N21: =N20 -> 0.0538 | O21: =-N21*$N$1 -> -98.734953
B22: 2037 | C22: =D22+M22 -> 48.939258 | F22: =F21 -> 0.044 | G22: =-$F$1*F22 -> -86 | I22: =I21+G22+H22 -> 172.81818 | J22: =J21+K21 -> 32.4 | K22: =-$J$9*F22 -> -3.3 | M22: =M21+O22 -> 48.939258 | N22: =N21 -> 0.0538 | O22: =-N22*$N$1 -> -98.734953
A23: With these assumptions | B23: 2038 | C23: =D23+M23 -> -49.795694 | F23: =F22 -> 0.044 | G23: =-$F$1*F23 -> -86 | I23: =I22+G23+H23 -> 86.818182 | J23: =J22+K22 -> 29.1 | K23: =-$J$9*F23 -> -3.3 | M23: =M22+O23 -> -49.795694 | N23: =N22 -> 0.0538 | O23: =-N23*$N$1 -> -98.734953
A24: the emission cap becomes negative before 2040 | B24: 2039 | C24: =D24+M24 -> -148.53065 | F24: =F23 -> 0.044 | G24: =-$F$1*F24 -> -86 | I24: =I23+G24+H24 -> 0.81818182 | J24: =J23+K23 -> 25.8 | K24: =-$J$9*F24 -> -3.3 | M24: =M23+O24 -> -148.53065 | N24: =N23 -> 0.0538 | O24: =-N24*$N$1 -> -98.734953
A25: We cannot really implement an emission cap that far | B25: 2040 | C25: =D25+M25 -> -97.265599 | D25: 150 | F25: =F24 -> 0.044 | G25: =-$F$1*F25 -> -86 | I25: =I24+G25+H25 -> -85.181818 | J25: =J24+K24 -> 22.5 | K25: =-$J$9*F25 -> -3.3 | M25: =M24+O25 -> -247.2656 | N25: =N24 -> 0.0538 | O25: =-N25*$N$1 -> -98.734953
A26: We have the price mechanism in place | B26: 2041 | C26: =D26+M26 -> -346.00055 | F26: =F25 -> 0.044 | G26: =-$F$1*F26 -> -86 | I26: =I25+G26+H26 -> -171.18182 | J26: =J25+K25 -> 19.2 | K26: =-$J$9*F26 -> -3.3 | M26: =M25+O26 -> -346.00055 | N26: =N25 -> 0.0538 | O26: =-N26*$N$1 -> -98.734953
A27: we can first try to set emission cap to 2030 | B27: 2042 | C27: =D27+M27 -> -444.7355 | F27: =F26 -> 0.044 | G27: =-$F$1*F27 -> -86 | I27: =I26+G27+H27 -> -257.18182 | J27: =J26+K26 -> 15.9 | K27: =-$J$9*F27 -> -3.3 | M27: =M26+O27 -> -444.7355 | N27: =N26 -> 0.0538 | O27: =-N27*$N$1 -> -98.734953
B28: 2043 | C28: =D28+M28 -> -543.47046 | F28: =F27 -> 0.044 | G28: =-$F$1*F28 -> -86 | I28: =I27+G28+H28 -> -343.18182 | J28: =J27+K27 -> 12.6 | K28: =-$J$9*F28 -> -3.3 | M28: =M27+O28 -> -543.47046 | N28: =N27 -> 0.0538 | O28: =-N28*$N$1 -> -98.734953
B29: 2044 | C29: =D29+M29 -> -642.20541 | F29: =F28 -> 0.044 | G29: =-$F$1*F29 -> -86 | I29: =I28+G29+H29 -> -429.18182 | J29: =J28+K28 -> 9.3 | K29: =-$J$9*F29 -> -3.3 | M29: =M28+O29 -> -642.20541 | N29: =N28 -> 0.0538 | O29: =-N29*$N$1 -> -98.734953
B30: 2045 | C30: =D30+M30 -> -630.94036 | D30: 110 | F30: =F29 -> 0.044 | G30: =-$F$1*F30 -> -86 | I30: =I29+G30+H30 -> -515.18182 | J30: =J29+K29 -> 6 | K30: =-$J$9*F30 -> -3.3 | M30: =M29+O30 -> -740.94036 | N30: =N29 -> 0.0538 | O30: =-N30*$N$1 -> -98.734953
B31: 2046 | C31: =D31+M31 -> 0 | F31: =F30 -> 0.044 | G31: =-$F$1*F31 -> -86 | I31: =I30+G31+H31 -> -601.18182 | J31: =J30+K30 -> 2.7 | K31: =-$J$9*F31 -> -3.3 | N31: =N30 -> 0.0538
B32: 2047 | F32: =F31 -> 0.044 | G32: =-$F$1*F32 -> -86 | N32: =N31 -> 0.0538
B33: 2048 | F33: =F32 -> 0.044 | G33: =-$F$1*F33 -> -86 | N33: =N32 -> 0.0538
B34: 2049 | F34: =F33 -> 0.044 | G34: =-$F$1*F34 -> -86 | N34: =N33 -> 0.0538
B35: 2050 | D35: 72 | F35: =F34 -> 0.044 | G35: =-$F$1*F35 -> -86 | N35: =N34 -> 0.0538
B36: 2051 | F36: =F35 -> 0.044 | G36: =-$F$1*F36 -> -86 | N36: =N35 -> 0.0538
B37: 2052 | F37: =F36 -> 0.044 | G37: =-$F$1*F37 -> -86 | N37: =N36 -> 0.0538
B38: 2053 | F38: =F37 -> 0.044 | G38: =-$F$1*F38 -> -86 | N38: =N37 -> 0.0538
B39: 2054 | F39: =F38 -> 0.044 | G39: =-$F$1*F39 -> -86 | N39: =N38 -> 0.0538
B40: 2055 | F40: =F39 -> 0.044 | G40: =-$F$1*F40 -> -86 | N40: =N39 -> 0.0538
...
