Workbook

Sheet FillTable
B2: ~TFM_Fill-R: w=Rdw_Stock; Hcol=Region
B3: TimeSlice | C3: LimType | D3: Attribute | E3: Year | F3: AllRegions | G3: Pset_CI | H3: Pset_PN | I3: Pset_CO | J3: Cset_CN
D4: COM_PROJ | F4: 1 | J4: R_DetH
D5: COM_PROJ | F5: 1 | J5: R_Flat
D6: COM_PROJ | F6: 1 | J6: R_SDetH

Sheet Rdw_Stock
A1: scenario | B1: attribute | C1: process | D1: commodity | E1: lim_type | F1: time_slice | G1: year | H1: commodity_group | I1: currency | J1: stage | K1: sow | L1: AL | M1: AT | N1: BA | O1: BE | P1: BG | Q1: CH | R1: CY | S1: CZ | T1: DE | U1: DK | V1: EE | W1: EL | X1: ES | Y1: FI | Z1: FR | AA1: HR | AB1: HU | AC1: IE | AD1: IS | AE1: IT | AF1: KS | AG1: LT | AH1: LU | AI1: LV | AJ1: ME | AK1: MK | AL1: MT | AM1: NL | AN1: NO | AO1: PL | AP1: PT | AQ1: RO | AR1: RS | AS1: SE | AT1: SI | AU1: SK | AV1: UK | AW1: year2
A2: NewHouses_and_retrofits | B2: COM_PROJ | C2: - | D2: R_DetH | E2: - | F2: - | G2: 2010 | H2: - | I2: - | J2: - | K2: - | L2: 85.365659 | M2: 1015.1617 | N2: 223.10096 | O2: 950.38722 | P2: 617.01235 | Q2: 841.55024 | R2: 105.85211 | S2: 1027.0584 | T2: 7733.6446 | U2: 997.38129 | V2: 111.66794 | W2: 728.81258 | X2: 972.98462 | Y2: 792.12147 | Z2: 6298.8611 | AA2: 636.08385 | AB2: 1536.6621 | AC2: 465.49382 | AD2: 43.582504 | AE2: 2111.8077 | AF2: 131.32823 | AG2: 260.62604 | AH2: 52.311377 | AI2: 184.32886 | AJ2: 42.777195 | AK2: 116.45012 | AL2: 3.5681226 | AM2: 635.78908 | AN2: 463.6125 | AO2: 3324.8676 | AP2: 409.81536 | AQ2: 2103.4798 | AR2: 659.19651 | AS2: 1178.7306 | AT2: 195.06476 | AU2: 431.50301 | AV2: 3810.9775 | AW2: -
A3: NewHouses_and_retrofits | B3: COM_PROJ | C3: - | D3: R_DetH | E3: - | F3: - | G3: 2050 | H3: - | I3: - | J3: - | K3: - | L3: 258.23468 | M3: 1278.7031 | N3: 439.0482 | O3: 1419.0733 | P3: 697.64544 | Q3: 1133.0116 | R3: 141.67291 | S3: 1340.5414 | T3: 7300.6379 | U3: 1166.0184 | V3: 93.796135 | W3: 760.24589 | X3: 1231.1466 | Y3: 888.69436 | Z3: 7484.8276 | AA3: 737.07716 | AB3: 1393.1474 | AC3: 611.30833 | AD3: 56.214271 | AE3: 2292.3115 | AF3: 281.71077 | AG3: 155.42907 | AH3: 126.4903 | AI3: 124.33872 | AJ3: 52.12417 | AK3: 218.03879 | AL3: 7.3838203 | AM3: 789.93269 | AN3: 628.81044 | AO3: 3790.1063 | AP3: 909.18284 | AQ3: 2527.5219 | AR3: 932.18797 | AS3: 1663.7538 | AT3: 231.37676 | AU3: 556.71653 | AV3: 5282.2968 | AW3: -
A4: NewHouses_and_retrofits | B4: COM_PROJ | C4: - | D4: R_DetH | E4: - | F4: - | G4: 2060 | H4: - | I4: - | J4: - | K4: - | L4: 258.23468 | M4: 1278.7031 | N4: 439.0482 | O4: 1419.0733 | P4: 697.64544 | Q4: 1133.0116 | R4: 141.67291 | S4: 1340.5414 | T4: 7300.6379 | U4: 1166.0184 | V4: 93.796135 | W4: 760.24589 | X4: 1231.1466 | Y4: 888.69436 | Z4: 7484.8276 | AA4: 737.07716 | AB4: 1393.1474 | AC4: 611.30833 | AD4: 56.214271 | AE4: 2292.3115 | AF4: 281.71077 | AG4: 155.42907 | AH4: 126.4903 | AI4: 124.33872 | AJ4: 52.12417 | AK4: 218.03879 | AL4: 7.3838203 | AM4: 789.93269 | AN4: 628.81044 | AO4: 3790.1063 | AP4: 909.18284 | AQ4: 2527.5219 | AR4: 932.18797 | AS4: 1663.7538 | AT4: 231.37676 | AU4: 556.71653 | AV4: 5282.2968 | AW4: -
A5: NewHouses_and_retrofits | B5: COM_PROJ | C5: - | D5: R_Flat | E5: - | F5: - | G5: 2010 | H5: - | I5: - | J5: - | K5: - | L5: 196.66972 | M5: 1468.1931 | N5: 271.1874 | O5: 905.52301 | P5: 777.21771 | Q5: 1648.2852 | R5: 83.544874 | S5: 2208.0312 | T5: 18507.479 | U5: 1066.6763 | V5: 488.14638 | W5: 1679.0753 | X5: 7433.1088 | Y5: 1108.1723 | Z5: 9195.3527 | AA5: 505.02473 | AB5: 1314.8023 | AC5: 148.11827 | AD5: 67.162135 | AE5: 17047.884 | AF5: 159.63428 | AG5: 725.54347 | AH5: 68 | AI5: 576.16017 | AJ5: 98.552265 | AK5: 160.89709 | AL5: 16.335462 | AM5: 1728.7006 | AN5: 1151.6628 | AO5: 6734.1392 | AP5: 514.68577 | AQ5: 2050.9073 | AR5: 801.27752 | AS5: 2426.7815 | AT5: 461.41891 | AU5: 580.36075 | AV5: 3928.2271 | AW5: -
A6: NewHouses_and_retrofits | B6: COM_PROJ | C6: - | D6: R_Flat | E6: - | F6: - | G6: 2050 | H6: - | I6: - | J6: - | K6: - | L6: 594.93412 | M6: 1849.3438 | N6: 533.67918 | O6: 1352.0842 | P6: 878.78693 | Q6: 2219.1502 | R6: 111.81681 | S6: 2881.9756 | T6: 17471.245 | U6: 1247.0297 | V6: 410.02138 | W6: 1751.493 | X6: 9405.3351 | Y6: 1243.2771 | Z6: 10926.678 | AA6: 585.20931 | AB6: 1192.008 | AC6: 194.51586 | AD6: 86.628122 | AE6: 18505.028 | AF6: 342.42976 | AG6: 432.69102 | AH6: 164.42581 | AI6: 388.64785 | AJ6: 120.0863 | AK6: 301.26037 | AL6: 33.804365 | AM6: 2147.8146 | AN6: 1562.0321 | AO6: 7676.427 | AP6: 1141.8398 | AQ6: 2464.3513 | AR6: 1133.1087 | AS6: 3425.3517 | AT6: 547.3137 | AU6: 748.76981 | AV6: 5444.8134 | AW6: -
A7: NewHouses_and_retrofits | B7: COM_PROJ | C7: - | D7: R_Flat | E7: - | F7: - | G7: 2060 | H7: - | I7: - | J7: - | K7: - | L7: 594.93412 | M7: 1849.3438 | N7: 533.67918 | O7: 1352.0842 | P7: 878.78693 | Q7: 2219.1502 | R7: 111.81681 | S7: 2881.9756 | T7: 17471.245 | U7: 1247.0297 | V7: 410.02138 | W7: 1751.493 | X7: 9405.3351 | Y7: 1243.2771 | Z7: 10926.678 | AA7: 585.20931 | AB7: 1192.008 | AC7: 194.51586 | AD7: 86.628122 | AE7: 18505.028 | AF7: 342.42976 | AG7: 432.69102 | AH7: 164.42581 | AI7: 388.64785 | AJ7: 120.0863 | AK7: 301.26037 | AL7: 33.804365 | AM7: 2147.8146 | AN7: 1562.0321 | AO7: 7676.427 | AP7: 1141.8398 | AQ7: 2464.3513 | AR7: 1133.1087 | AS7: 3425.3517 | AT7: 547.3137 | AU7: 748.76981 | AV7: 5444.8134 | AW7: -
A8: NewHouses_and_retrofits | B8: COM_PROJ | C8: - | D8: R_SDetH | E8: - | F8: - | G8: 2010 | H8: - | I8: - | J8: - | K8: - | L8: 48.267499 | M8: 470.44081 | N8: 79.84264 | O8: 1585.6865 | P8: 335.3328 | Q8: 944.09207 | R8: 108.10428 | S8: 608.78058 | T8: 8085.1739 | U8: 531.0051 | V8: 51.805681 | W8: 412.08562 | X8: 2157.021 | Y8: 598.70622 | Z8: 5600.5711 | AA8: 227.6396 | AB8: 567.5309 | AC8: 700.17967 | AD8: 40.710304 | AE8: 3755.6581 | AF8: 46.999316 | AG8: 131.79385 | AH8: 67.688622 | AI8: 73.615616 | AJ8: 24.187105 | AK8: 63.288109 | AL8: 45.592678 | AM8: 3357.5158 | AN8: 364.13058 | AO8: 1247.6753 | AP8: 330.83001 | AQ8: 604.09855 | AR8: 235.91108 | AS8: 565.48787 | AT8: 64.875141 | AU8: 128.41322 | AV8: 13230.789 | AW8: -
A9: NewHouses_and_retrofits | B9: COM_PROJ | C9: - | D9: R_SDetH | E9: - | F9: - | G9: 2050 | H9: - | I9: - | J9: - | K9: - | L9: 146.0112 | M9: 592.56971 | N9: 157.12513 | O9: 2367.6722 | P9: 379.15513 | Q9: 1271.0677 | R9: 144.68723 | S9: 794.59511 | T9: 7632.485 | U9: 620.78736 | V9: 43.514482 | W9: 429.85866 | X9: 2729.3433 | Y9: 671.69854 | Z9: 6655.0616 | AA9: 263.78275 | AB9: 514.52707 | AC9: 919.5088 | AD9: 52.509606 | AE9: 4076.6676 | AF9: 100.81772 | AG9: 78.597656 | AH9: 163.67289 | AI9: 49.657287 | AJ9: 29.472077 | AK9: 118.49934 | AL9: 94.348815 | AM9: 4171.5273 | AN9: 493.88036 | AO9: 1422.2587 | AP9: 733.95241 | AQ9: 725.87923 | AR9: 333.60837 | AS9: 798.1744 | AT9: 76.951882 | AU9: 165.67616 | AV9: 18338.853 | AW9: -
A10: NewHouses_and_retrofits | B10: COM_PROJ | C10: - | D10: R_SDetH | E10: - | F10: - | G10: 2060 | H10: - | I10: - | J10: - | K10: - | L10: 146.0112 | M10: 592.56971 | N10: 157.12513 | O10: 2367.6722 | P10: 379.15513 | Q10: 1271.0677 | R10: 144.68723 | S10: 794.59511 | T10: 7632.485 | U10: 620.78736 | V10: 43.514482 | W10: 429.85866 | X10: 2729.3433 | Y10: 671.69854 | Z10: 6655.0616 | AA10: 263.78275 | AB10: 514.52707 | AC10: 919.5088 | AD10: 52.509606 | AE10: 4076.6676 | AF10: 100.81772 | AG10: 78.597656 | AH10: 163.67289 | AI10: 49.657287 | AJ10: 29.472077 | AK10: 118.49934 | AL10: 94.348815 | AM10: 4171.5273 | AN10: 493.88036 | AO10: 1422.2587 | AP10: 733.95241 | AQ10: 725.87923 | AR10: 333.60837 | AS10: 798.1744 | AT10: 76.951882 | AU10: 165.67616 | AV10: 18338.853 | AW10: -

Sheet VDA_table
B2: ~UC_Sets: R_E: AllRegions
E3: ~UC_T: UC_RHSRTS~UP
B4: UC_N | C4: UC_Desc | D4: Pset_PN | E4: Year | F4: UC_CAP | G4: UC_RHSRTS~UP~0 | H4: =H34 -> AL | I4: =I34 -> AT | J4: =J34 -> BA | K4: =K34 -> BE | L4: =L34 -> BG | M4: =M34 -> CH | N4: =N34 -> CY | O4: =O34 -> CZ | ... AR4: =AR34 -> UK
B5: UC_RSD_HPCAP-DH_Max | C5: Maximum STOCK Heat Pumps-DH | D5: R_ES-SH-DH*ELC*, -*ELC01, -*ELC-R, -*spl | E5: =G35 -> 2010 | F5: 1 | G5: 5 | H5: =IF(H35*H$48>SUM(H$28:H$29,H$31)/1000,H35*H$48,SUM(H$28:H$29,H$31)/1000*1.1) -> 42.682829 | I5: =IF(I35*I$48>SUM(I$28:I$29,I$31)/1000,I35*I$48,SUM(I$28:I$29,I$31)/1000*1.1) -> 507.58087 | J5: =IF(J35*J$48>SUM(J$28:J$29,J$31)/1000,J35*J$48,SUM(J$28:J$29,J$31)/1000*1.1) -> 111.55048 | K5: =IF(K35*K$48>SUM(K$28:K$29,K$31)/1000,K35*K$48,SUM(K$28:K$29,K$31)/1000*1.1) -> 475.19361 | L5: =IF(L35*L$48>SUM(L$28:L$29,L$31)/1000,L35*L$48,SUM(L$28:L$29,L$31)/1000*1.1) -> 308.50618 | M5: =IF(M35*M$48>SUM(M$28:M$29,M$31)/1000,M35*M$48,SUM(M$28:M$29,M$31)/1000*1.1) -> 420.77512 | N5: =IF(N35*N$48>SUM(N$28:N$29,N$31)/1000,N35*N$48,SUM(N$28:N$29,N$31)/1000*1.1) -> 52.926053 | O5: =IF(O35*O$48>SUM(O$28:O$29,O$31)/1000,O35*O$48,SUM(O$28:O$29,O$31)/1000*1.1) -> 513.5292 | ... AR5: =IF(AR35*AR$48>SUM(AR$28:AR$29,AR$31)/1000,AR35*AR$48,SUM(AR$28:AR$29,AR$31)/1000*1.1) -> 1905.4888
D6: R_ES-SH-DH*ELC*, -*ELC01, -*ELC-R, -*spl | E6: =G36 -> 2050 | F6: 1 | H6: =IF(H36*H$48>SUM(H$28:H$29,H$31)/1000,H36*H$48,SUM(H$28:H$29,H$31)/1000*1.1) -> 129.11734 | I6: =IF(I36*I$48>SUM(I$28:I$29,I$31)/1000,I36*I$48,SUM(I$28:I$29,I$31)/1000*1.1) -> 639.35153 | J6: =IF(J36*J$48>SUM(J$28:J$29,J$31)/1000,J36*J$48,SUM(J$28:J$29,J$31)/1000*1.1) -> 219.5241 | K6: =IF(K36*K$48>SUM(K$28:K$29,K$31)/1000,K36*K$48,SUM(K$28:K$29,K$31)/1000*1.1) -> 709.53666 | L6: =IF(L36*L$48>SUM(L$28:L$29,L$31)/1000,L36*L$48,SUM(L$28:L$29,L$31)/1000*1.1) -> 348.82272 | M6: =IF(M36*M$48>SUM(M$28:M$29,M$31)/1000,M36*M$48,SUM(M$28:M$29,M$31)/1000*1.1) -> 566.50582 | N6: =IF(N36*N$48>SUM(N$28:N$29,N$31)/1000,N36*N$48,SUM(N$28:N$29,N$31)/1000*1.1) -> 70.836455 | O6: =IF(O36*O$48>SUM(O$28:O$29,O$31)/1000,O36*O$48,SUM(O$28:O$29,O$31)/1000*1.1) -> 670.27071 | ... AR6: =IF(AR36*AR$48>SUM(AR$28:AR$29,AR$31)/1000,AR36*AR$48,SUM(AR$28:AR$29,AR$31)/1000*1.1) -> 2641.1484
D7: R_ES-SH-DH*ELC*, -*ELC01, -*ELC-R, -*spl | E7: =G37 -> 2060 | F7: 1 | H7: =IF(H37*H$48>SUM(H$28:H$29,H$31)/1000,H37*H$48,SUM(H$28:H$29,H$31)/1000*1.1) -> 129.11734 | I7: =IF(I37*I$48>SUM(I$28:I$29,I$31)/1000,I37*I$48,SUM(I$28:I$29,I$31)/1000*1.1) -> 639.35153 | J7: =IF(J37*J$48>SUM(J$28:J$29,J$31)/1000,J37*J$48,SUM(J$28:J$29,J$31)/1000*1.1) -> 219.5241 | K7: =IF(K37*K$48>SUM(K$28:K$29,K$31)/1000,K37*K$48,SUM(K$28:K$29,K$31)/1000*1.1) -> 709.53666 | L7: =IF(L37*L$48>SUM(L$28:L$29,L$31)/1000,L37*L$48,SUM(L$28:L$29,L$31)/1000*1.1) -> 348.82272 | M7: =IF(M37*M$48>SUM(M$28:M$29,M$31)/1000,M37*M$48,SUM(M$28:M$29,M$31)/1000*1.1) -> 566.50582 | N7: =IF(N37*N$48>SUM(N$28:N$29,N$31)/1000,N37*N$48,SUM(N$28:N$29,N$31)/1000*1.1) -> 70.836455 | O7: =IF(O37*O$48>SUM(O$28:O$29,O$31)/1000,O37*O$48,SUM(O$28:O$29,O$31)/1000*1.1) -> 670.27071 | ... AR7: =IF(AR37*AR$48>SUM(AR$28:AR$29,AR$31)/1000,AR37*AR$48,SUM(AR$28:AR$29,AR$31)/1000*1.1) -> 2641.1484
B8: UC_RSD_HPCAP-FL_Max | C8: Maximum STOCK Heat Pumps-FL | D8: R_ES-SH-FL*ELC*, -*ELC01, -*ELC-R, -*spl | E8: =G38 -> 2010 | F8: 1 | G8: 5 | H8: =IF(H38*H$48>SUM(H$28:H$29,H$31)/1000,H38*H$48,SUM(H$28:H$29,H$31)/1000*1.1) -> 98.334862 | I8: =IF(I38*I$48>SUM(I$28:I$29,I$31)/1000,I38*I$48,SUM(I$28:I$29,I$31)/1000*1.1) -> 734.09657 | J8: =IF(J38*J$48>SUM(J$28:J$29,J$31)/1000,J38*J$48,SUM(J$28:J$29,J$31)/1000*1.1) -> 135.5937 | K8: =IF(K38*K$48>SUM(K$28:K$29,K$31)/1000,K38*K$48,SUM(K$28:K$29,K$31)/1000*1.1) -> 452.76151 | L8: =IF(L38*L$48>SUM(L$28:L$29,L$31)/1000,L38*L$48,SUM(L$28:L$29,L$31)/1000*1.1) -> 388.60885 | M8: =IF(M38*M$48>SUM(M$28:M$29,M$31)/1000,M38*M$48,SUM(M$28:M$29,M$31)/1000*1.1) -> 824.14261 | N8: =IF(N38*N$48>SUM(N$28:N$29,N$31)/1000,N38*N$48,SUM(N$28:N$29,N$31)/1000*1.1) -> 41.772437 | O8: =IF(O38*O$48>SUM(O$28:O$29,O$31)/1000,O38*O$48,SUM(O$28:O$29,O$31)/1000*1.1) -> 1104.0156 | ... AR8: =IF(AR38*AR$48>SUM(AR$28:AR$29,AR$31)/1000,AR38*AR$48,SUM(AR$28:AR$29,AR$31)/1000*1.1) -> 1964.1135
D9: R_ES-SH-FL*ELC*, -*ELC01, -*ELC-R, -*spl | E9: =G39 -> 2050 | F9: 1 | H9: =IF(H39*H$48>SUM(H$28:H$29,H$31)/1000,H39*H$48,SUM(H$28:H$29,H$31)/1000*1.1) -> 297.46706 | I9: =IF(I39*I$48>SUM(I$28:I$29,I$31)/1000,I39*I$48,SUM(I$28:I$29,I$31)/1000*1.1) -> 924.6719 | J9: =IF(J39*J$48>SUM(J$28:J$29,J$31)/1000,J39*J$48,SUM(J$28:J$29,J$31)/1000*1.1) -> 266.83959 | K9: =IF(K39*K$48>SUM(K$28:K$29,K$31)/1000,K39*K$48,SUM(K$28:K$29,K$31)/1000*1.1) -> 676.0421 | L9: =IF(L39*L$48>SUM(L$28:L$29,L$31)/1000,L39*L$48,SUM(L$28:L$29,L$31)/1000*1.1) -> 439.39346 | M9: =IF(M39*M$48>SUM(M$28:M$29,M$31)/1000,M39*M$48,SUM(M$28:M$29,M$31)/1000*1.1) -> 1109.5751 | N9: =IF(N39*N$48>SUM(N$28:N$29,N$31)/1000,N39*N$48,SUM(N$28:N$29,N$31)/1000*1.1) -> 55.908407 | O9: =IF(O39*O$48>SUM(O$28:O$29,O$31)/1000,O39*O$48,SUM(O$28:O$29,O$31)/1000*1.1) -> 1440.9878 | ... AR9: =IF(AR39*AR$48>SUM(AR$28:AR$29,AR$31)/1000,AR39*AR$48,SUM(AR$28:AR$29,AR$31)/1000*1.1) -> 2722.4067
D10: R_ES-SH-FL*ELC*, -*ELC01, -*ELC-R, -*spl | E10: =G40 -> 2060 | F10: 1 | H10: =IF(H40*H$48>SUM(H$28:H$29,H$31)/1000,H40*H$48,SUM(H$28:H$29,H$31)/1000*1.1) -> 297.46706 | I10: =IF(I40*I$48>SUM(I$28:I$29,I$31)/1000,I40*I$48,SUM(I$28:I$29,I$31)/1000*1.1) -> 924.6719 | J10: =IF(J40*J$48>SUM(J$28:J$29,J$31)/1000,J40*J$48,SUM(J$28:J$29,J$31)/1000*1.1) -> 266.83959 | K10: =IF(K40*K$48>SUM(K$28:K$29,K$31)/1000,K40*K$48,SUM(K$28:K$29,K$31)/1000*1.1) -> 676.0421 | L10: =IF(L40*L$48>SUM(L$28:L$29,L$31)/1000,L40*L$48,SUM(L$28:L$29,L$31)/1000*1.1) -> 439.39346 | M10: =IF(M40*M$48>SUM(M$28:M$29,M$31)/1000,M40*M$48,SUM(M$28:M$29,M$31)/1000*1.1) -> 1109.5751 | N10: =IF(N40*N$48>SUM(N$28:N$29,N$31)/1000,N40*N$48,SUM(N$28:N$29,N$31)/1000*1.1) -> 55.908407 | O10: =IF(O40*O$48>SUM(O$28:O$29,O$31)/1000,O40*O$48,SUM(O$28:O$29,O$31)/1000*1.1) -> 1440.9878 | ... AR10: =IF(AR40*AR$48>SUM(AR$28:AR$29,AR$31)/1000,AR40*AR$48,SUM(AR$28:AR$29,AR$31)/1000*1.1) -> 2722.4067
B11: UC_RSD_HPCAP-SD_Max | C11: Maximum STOCK Heat Pumps-SD | D11: R_ES-SH-SD*ELC*, -*ELC01, -*ELC-R, -*spl | E11: =G41 -> 2010 | F11: 1 | G11: 5 | H11: =IF(H41*H$48>SUM(H$28:H$29,H$31)/1000,H41*H$48,SUM(H$28:H$29,H$31)/1000*1.1) -> 24.133749 | I11: =IF(I41*I$48>SUM(I$28:I$29,I$31)/1000,I41*I$48,SUM(I$28:I$29,I$31)/1000*1.1) -> 235.2204 | J11: =IF(J41*J$48>SUM(J$28:J$29,J$31)/1000,J41*J$48,SUM(J$28:J$29,J$31)/1000*1.1) -> 39.92132 | K11: =IF(K41*K$48>SUM(K$28:K$29,K$31)/1000,K41*K$48,SUM(K$28:K$29,K$31)/1000*1.1) -> 792.84324 | L11: =IF(L41*L$48>SUM(L$28:L$29,L$31)/1000,L41*L$48,SUM(L$28:L$29,L$31)/1000*1.1) -> 167.6664 | M11: =IF(M41*M$48>SUM(M$28:M$29,M$31)/1000,M41*M$48,SUM(M$28:M$29,M$31)/1000*1.1) -> 472.04604 | N11: =IF(N41*N$48>SUM(N$28:N$29,N$31)/1000,N41*N$48,SUM(N$28:N$29,N$31)/1000*1.1) -> 54.052139 | O11: =IF(O41*O$48>SUM(O$28:O$29,O$31)/1000,O41*O$48,SUM(O$28:O$29,O$31)/1000*1.1) -> 304.39029 | ... AR11: =IF(AR41*AR$48>SUM(AR$28:AR$29,AR$31)/1000,AR41*AR$48,SUM(AR$28:AR$29,AR$31)/1000*1.1) -> 6615.3946
D12: R_ES-SH-SD*ELC*, -*ELC01, -*ELC-R, -*spl | E12: =G42 -> 2050 | F12: 1 | H12: =IF(H42*H$48>SUM(H$28:H$29,H$31)/1000,H42*H$48,SUM(H$28:H$29,H$31)/1000*1.1) -> 73.005599 | I12: =IF(I42*I$48>SUM(I$28:I$29,I$31)/1000,I42*I$48,SUM(I$28:I$29,I$31)/1000*1.1) -> 296.28486 | J12: =IF(J42*J$48>SUM(J$28:J$29,J$31)/1000,J42*J$48,SUM(J$28:J$29,J$31)/1000*1.1) -> 78.562563 | K12: =IF(K42*K$48>SUM(K$28:K$29,K$31)/1000,K42*K$48,SUM(K$28:K$29,K$31)/1000*1.1) -> 1183.8361 | L12: =IF(L42*L$48>SUM(L$28:L$29,L$31)/1000,L42*L$48,SUM(L$28:L$29,L$31)/1000*1.1) -> 189.57757 | M12: =IF(M42*M$48>SUM(M$28:M$29,M$31)/1000,M42*M$48,SUM(M$28:M$29,M$31)/1000*1.1) -> 635.53384 | N12: =IF(N42*N$48>SUM(N$28:N$29,N$31)/1000,N42*N$48,SUM(N$28:N$29,N$31)/1000*1.1) -> 72.343613 | O12: =IF(O42*O$48>SUM(O$28:O$29,O$31)/1000,O42*O$48,SUM(O$28:O$29,O$31)/1000*1.1) -> 397.29756 | ... AR12: =IF(AR42*AR$48>SUM(AR$28:AR$29,AR$31)/1000,AR42*AR$48,SUM(AR$28:AR$29,AR$31)/1000*1.1) -> 9169.4264
D13: R_ES-SH-SD*ELC*, -*ELC01, -*ELC-R, -*spl | E13: =G43 -> 2060 | F13: 1 | H13: =IF(H43*H$48>SUM(H$28:H$29,H$31)/1000,H43*H$48,SUM(H$28:H$29,H$31)/1000*1.1) -> 73.005599 | I13: =IF(I43*I$48>SUM(I$28:I$29,I$31)/1000,I43*I$48,SUM(I$28:I$29,I$31)/1000*1.1) -> 296.28486 | J13: =IF(J43*J$48>SUM(J$28:J$29,J$31)/1000,J43*J$48,SUM(J$28:J$29,J$31)/1000*1.1) -> 78.562563 | K13: =IF(K43*K$48>SUM(K$28:K$29,K$31)/1000,K43*K$48,SUM(K$28:K$29,K$31)/1000*1.1) -> 1183.8361 | L13: =IF(L43*L$48>SUM(L$28:L$29,L$31)/1000,L43*L$48,SUM(L$28:L$29,L$31)/1000*1.1) -> 189.57757 | M13: =IF(M43*M$48>SUM(M$28:M$29,M$31)/1000,M43*M$48,SUM(M$28:M$29,M$31)/1000*1.1) -> 635.53384 | N13: =IF(N43*N$48>SUM(N$28:N$29,N$31)/1000,N43*N$48,SUM(N$28:N$29,N$31)/1000*1.1) -> 72.343613 | O13: =IF(O43*O$48>SUM(O$28:O$29,O$31)/1000,O43*O$48,SUM(O$28:O$29,O$31)/1000*1.1) -> 397.29756 | ... AR13: =IF(AR43*AR$48>SUM(AR$28:AR$29,AR$31)/1000,AR43*AR$48,SUM(AR$28:AR$29,AR$31)/1000*1.1) -> 9169.4264
B14: UC_RSD_GHPCAP-DH_Max | C14: Maximum STOCK Ground Heat Pumps-DH | D14: R_ES-SH-DH*ELC06, R_ES-SH-DH*ELC07, R_ES-SH-DH*ELC08, R_ES-SH-DH*ELC09, R_ES-SH-DH*ELC10, R_ES-SH-DH*ELC11, R_ES-SH-DH*ELC-HPG | E14: =G35 -> 2010 | F14: 1 | G14: 5 | H14: =IF(H35*H$49>H$31/1000,H35*H$49,H$31/1000*1.1) -> 42.682829 | I14: =IF(I35*I$49>I$31/1000,I35*I$49,I$31/1000*1.1) -> 507.58087 | J14: =IF(J35*J$49>J$31/1000,J35*J$49,J$31/1000*1.1) -> 111.55048 | K14: =IF(K35*K$49>K$31/1000,K35*K$49,K$31/1000*1.1) -> 475.19361 | L14: =IF(L35*L$49>L$31/1000,L35*L$49,L$31/1000*1.1) -> 308.50618 | M14: =IF(M35*M$49>M$31/1000,M35*M$49,M$31/1000*1.1) -> 420.77512 | N14: =IF(N35*N$49>N$31/1000,N35*N$49,N$31/1000*1.1) -> 52.926053 | O14: =IF(O35*O$49>O$31/1000,O35*O$49,O$31/1000*1.1) -> 513.5292 | ... AR14: =IF(AR35*AR$49>AR$31/1000,AR35*AR$49,AR$31/1000*1.1) -> 1905.4888
D15: R_ES-SH-DH*ELC06, R_ES-SH-DH*ELC07, R_ES-SH-DH*ELC08, R_ES-SH-DH*ELC09, R_ES-SH-DH*ELC10, R_ES-SH-DH*ELC11, R_ES-SH-DH*ELC-HPG | E15: =G36 -> 2050 | F15: 1 | H15: =IF(H36*H$49>H$31/1000,H36*H$49,H$31/1000*1.1) -> 129.11734 | I15: =IF(I36*I$49>I$31/1000,I36*I$49,I$31/1000*1.1) -> 639.35153 | J15: =IF(J36*J$49>J$31/1000,J36*J$49,J$31/1000*1.1) -> 219.5241 | K15: =IF(K36*K$49>K$31/1000,K36*K$49,K$31/1000*1.1) -> 709.53666 | L15: =IF(L36*L$49>L$31/1000,L36*L$49,L$31/1000*1.1) -> 348.82272 | M15: =IF(M36*M$49>M$31/1000,M36*M$49,M$31/1000*1.1) -> 566.50582 | N15: =IF(N36*N$49>N$31/1000,N36*N$49,N$31/1000*1.1) -> 70.836455 | O15: =IF(O36*O$49>O$31/1000,O36*O$49,O$31/1000*1.1) -> 670.27071 | ... AR15: =IF(AR36*AR$49>AR$31/1000,AR36*AR$49,AR$31/1000*1.1) -> 2641.1484
D16: R_ES-SH-DH*ELC06, R_ES-SH-DH*ELC07, R_ES-SH-DH*ELC08, R_ES-SH-DH*ELC09, R_ES-SH-DH*ELC10, R_ES-SH-DH*ELC11, R_ES-SH-DH*ELC-HPG | E16: =G37 -> 2060 | F16: 1 | H16: =IF(H37*H$49>H$31/1000,H37*H$49,H$31/1000*1.1) -> 129.11734 | I16: =IF(I37*I$49>I$31/1000,I37*I$49,I$31/1000*1.1) -> 639.35153 | J16: =IF(J37*J$49>J$31/1000,J37*J$49,J$31/1000*1.1) -> 219.5241 | K16: =IF(K37*K$49>K$31/1000,K37*K$49,K$31/1000*1.1) -> 709.53666 | L16: =IF(L37*L$49>L$31/1000,L37*L$49,L$31/1000*1.1) -> 348.82272 | M16: =IF(M37*M$49>M$31/1000,M37*M$49,M$31/1000*1.1) -> 566.50582 | N16: =IF(N37*N$49>N$31/1000,N37*N$49,N$31/1000*1.1) -> 70.836455 | O16: =IF(O37*O$49>O$31/1000,O37*O$49,O$31/1000*1.1) -> 670.27071 | ... AR16: =IF(AR37*AR$49>AR$31/1000,AR37*AR$49,AR$31/1000*1.1) -> 2641.1484
B17: UC_RSD_GHPCAP-FL_Max | C17: Maximum STOCK Ground Heat Pumps-FL | D17: R_ES-SH-FL*ELC06, R_ES-SH-FL*ELC07, R_ES-SH-FL*ELC08, R_ES-SH-FL*ELC09, R_ES-SH-FL*ELC10, R_ES-SH-FL*ELC11, R_ES-SH-FL*ELC-HPG | E17: =G38 -> 2010 | F17: 1 | G17: 5 | H17: =IF(H38*H$50>H$31/1000,H38*H$50,H$31/1000*1.1) -> 39.333945 | I17: =IF(I38*I$50>I$31/1000,I38*I$50,I$31/1000*1.1) -> 293.63863 | J17: =IF(J38*J$50>J$31/1000,J38*J$50,J$31/1000*1.1) -> 54.23748 | K17: =IF(K38*K$50>K$31/1000,K38*K$50,K$31/1000*1.1) -> 181.1046 | L17: =IF(L38*L$50>L$31/1000,L38*L$50,L$31/1000*1.1) -> 155.44354 | M17: =IF(M38*M$50>M$31/1000,M38*M$50,M$31/1000*1.1) -> 329.65704 | N17: =IF(N38*N$50>N$31/1000,N38*N$50,N$31/1000*1.1) -> 16.708975 | O17: =IF(O38*O$50>O$31/1000,O38*O$50,O$31/1000*1.1) -> 441.60624 | ... AR17: =IF(AR38*AR$50>AR$31/1000,AR38*AR$50,AR$31/1000*1.1) -> 785.64542
D18: R_ES-SH-FL*ELC06, R_ES-SH-FL*ELC07, R_ES-SH-FL*ELC08, R_ES-SH-FL*ELC09, R_ES-SH-FL*ELC10, R_ES-SH-FL*ELC11, R_ES-SH-FL*ELC-HPG | E18: =G39 -> 2050 | F18: 1 | H18: =IF(H39*H$50>H$31/1000,H39*H$50,H$31/1000*1.1) -> 118.98682 | I18: =IF(I39*I$50>I$31/1000,I39*I$50,I$31/1000*1.1) -> 369.86876 | J18: =IF(J39*J$50>J$31/1000,J39*J$50,J$31/1000*1.1) -> 106.73584 | K18: =IF(K39*K$50>K$31/1000,K39*K$50,K$31/1000*1.1) -> 270.41684 | L18: =IF(L39*L$50>L$31/1000,L39*L$50,L$31/1000*1.1) -> 175.75739 | M18: =IF(M39*M$50>M$31/1000,M39*M$50,M$31/1000*1.1) -> 443.83003 | N18: =IF(N39*N$50>N$31/1000,N39*N$50,N$31/1000*1.1) -> 22.363363 | O18: =IF(O39*O$50>O$31/1000,O39*O$50,O$31/1000*1.1) -> 576.39513 | ... AR18: =IF(AR39*AR$50>AR$31/1000,AR39*AR$50,AR$31/1000*1.1) -> 1088.9627
D19: R_ES-SH-FL*ELC06, R_ES-SH-FL*ELC07, R_ES-SH-FL*ELC08, R_ES-SH-FL*ELC09, R_ES-SH-FL*ELC10, R_ES-SH-FL*ELC11, R_ES-SH-FL*ELC-HPG | E19: =G40 -> 2060 | F19: 1 | H19: =IF(H40*H$50>H$31/1000,H40*H$50,H$31/1000*1.1) -> 118.98682 | I19: =IF(I40*I$50>I$31/1000,I40*I$50,I$31/1000*1.1) -> 369.86876 | J19: =IF(J40*J$50>J$31/1000,J40*J$50,J$31/1000*1.1) -> 106.73584 | K19: =IF(K40*K$50>K$31/1000,K40*K$50,K$31/1000*1.1) -> 270.41684 | L19: =IF(L40*L$50>L$31/1000,L40*L$50,L$31/1000*1.1) -> 175.75739 | M19: =IF(M40*M$50>M$31/1000,M40*M$50,M$31/1000*1.1) -> 443.83003 | N19: =IF(N40*N$50>N$31/1000,N40*N$50,N$31/1000*1.1) -> 22.363363 | O19: =IF(O40*O$50>O$31/1000,O40*O$50,O$31/1000*1.1) -> 576.39513 | ... AR19: =IF(AR40*AR$50>AR$31/1000,AR40*AR$50,AR$31/1000*1.1) -> 1088.9627
B20: UC_RSD_GHPCAP-SD_Max | C20: Maximum STOCK Ground Heat Pumps-SD | D20: R_ES-SH-SD*ELC06, R_ES-SH-SD*ELC07, R_ES-SH-SD*ELC08, R_ES-SH-SD*ELC09, R_ES-SH-SD*ELC10, R_ES-SH-SD*ELC11, R_ES-SH-SD*ELC-HPG | E20: =G41 -> 2010 | F20: 1 | G20: 5 | H20: =IF(H41*H$51>H$31/1000,H41*H$51,H$31/1000*1.1) -> 4.8267499 | I20: =IF(I41*I$51>I$31/1000,I41*I$51,I$31/1000*1.1) -> 98.8372 | J20: =IF(J41*J$51>J$31/1000,J41*J$51,J$31/1000*1.1) -> 7.984264 | K20: =IF(K41*K$51>K$31/1000,K41*K$51,K$31/1000*1.1) -> 158.56865 | L20: =IF(L41*L$51>L$31/1000,L41*L$51,L$31/1000*1.1) -> 33.53328 | M20: =IF(M41*M$51>M$31/1000,M41*M$51,M$31/1000*1.1) -> 94.409207 | N20: =IF(N41*N$51>N$31/1000,N41*N$51,N$31/1000*1.1) -> 10.810428 | O20: =IF(O41*O$51>O$31/1000,O41*O$51,O$31/1000*1.1) -> 60.878058 | ... AR20: =IF(AR41*AR$51>AR$31/1000,AR41*AR$51,AR$31/1000*1.1) -> 1323.0789
D21: R_ES-SH-SD*ELC06, R_ES-SH-SD*ELC07, R_ES-SH-SD*ELC08, R_ES-SH-SD*ELC09, R_ES-SH-SD*ELC10, R_ES-SH-SD*ELC11, R_ES-SH-SD*ELC-HPG | E21: =G42 -> 2050 | F21: 1 | H21: =IF(H42*H$51>H$31/1000,H42*H$51,H$31/1000*1.1) -> 14.60112 | I21: =IF(I42*I$51>I$31/1000,I42*I$51,I$31/1000*1.1) -> 98.8372 | J21: =IF(J42*J$51>J$31/1000,J42*J$51,J$31/1000*1.1) -> 15.712513 | K21: =IF(K42*K$51>K$31/1000,K42*K$51,K$31/1000*1.1) -> 236.76722 | L21: =IF(L42*L$51>L$31/1000,L42*L$51,L$31/1000*1.1) -> 37.915513 | M21: =IF(M42*M$51>M$31/1000,M42*M$51,M$31/1000*1.1) -> 127.10677 | N21: =IF(N42*N$51>N$31/1000,N42*N$51,N$31/1000*1.1) -> 14.468723 | O21: =IF(O42*O$51>O$31/1000,O42*O$51,O$31/1000*1.1) -> 79.459511 | ... AR21: =IF(AR42*AR$51>AR$31/1000,AR42*AR$51,AR$31/1000*1.1) -> 1833.8853
D22: R_ES-SH-SD*ELC06, R_ES-SH-SD*ELC07, R_ES-SH-SD*ELC08, R_ES-SH-SD*ELC09, R_ES-SH-SD*ELC10, R_ES-SH-SD*ELC11, R_ES-SH-SD*ELC-HPG | E22: =G43 -> 2060 | F22: 1 | H22: =IF(H43*H$51>H$31/1000,H43*H$51,H$31/1000*1.1) -> 14.60112 | I22: =IF(I43*I$51>I$31/1000,I43*I$51,I$31/1000*1.1) -> 98.8372 | J22: =IF(J43*J$51>J$31/1000,J43*J$51,J$31/1000*1.1) -> 15.712513 | K22: =IF(K43*K$51>K$31/1000,K43*K$51,K$31/1000*1.1) -> 236.76722 | L22: =IF(L43*L$51>L$31/1000,L43*L$51,L$31/1000*1.1) -> 37.915513 | M22: =IF(M43*M$51>M$31/1000,M43*M$51,M$31/1000*1.1) -> 127.10677 | N22: =IF(N43*N$51>N$31/1000,N43*N$51,N$31/1000*1.1) -> 14.468723 | O22: =IF(O43*O$51>O$31/1000,O43*O$51,O$31/1000*1.1) -> 79.459511 | ... AR22: =IF(AR43*AR$51>AR$31/1000,AR43*AR$51,AR$31/1000*1.1) -> 1833.8853
B26: New ELC Techs | F26: HP Stock 2014 (n. of units)
B27: R_ES-SH-DH_ELC01 | C27: Electric boiler_SH-WH (DH) | D27: R_ES-DH-SpHeat, R_ES-DH-WatHeat | F27: Tech | G27: Year | H27: AL | I27: ='STOCK 2014'!K18 -> AT | J27: BA | K27: ='STOCK 2014'!K9 -> BE | L27: BG | M27: ='STOCK 2014'!K17 -> CH | N27: CY | O27: ='STOCK 2014'!K10 -> CZ | P27: ='STOCK 2014'!K21 -> DE | Q27: ='STOCK 2014'!K16 -> DK | R27: ='STOCK 2014'!K13 -> EE | S27: EL | T27: ='STOCK 2014'!K19 -> ES | U27: ='STOCK 2014'!K20 -> FI | V27: ='STOCK 2014'!K24 -> FR | W27: HR | X27: ='STOCK 2014'!K6 -> HU | Y27: ='STOCK 2014'!K8 -> IE | Z27: IS | AA27: ='STOCK 2014'!K23 -> IT | AB27: KS | AC27: ='STOCK 2014'!K5 -> LT | AD27: LU | AE27: LV | AF27: ME | AG27: MK | AH27: MT | AI27: ='STOCK 2014'!K12 -> NL | AJ27: ='STOCK 2014'!K22 -> NO | AK27: ='STOCK 2014'!K11 -> PL | AL27: ='STOCK 2014'!K14 -> PT | AM27: RO | AN27: RS | AO27: ='STOCK 2014'!K25 -> SE | AP27: SI | AQ27: ='STOCK 2014'!K7 -> SK | AR27: ='STOCK 2014'!K15 -> UK
B28: R_ES-SH-DH_ELC02 | C28: Heat Pump Air-to-Air_SH (DH) | D28: R_ES-DH-SpHeat, R_ES-DH-SpCool | F28: ='STOCK 2014'!L4 -> AIR | G28: 2014 | I28: ='STOCK 2014'!L18 -> 49974 | K28: ='STOCK 2014'!L9 -> 19544 | M28: ='STOCK 2014'!L17 -> 105523 | O28: ='STOCK 2014'!L10 -> 28948 | P28: ='STOCK 2014'!L21 -> 277894 | Q28: ='STOCK 2014'!L16 -> 14122 | R28: ='STOCK 2014'!L13 -> 4820 | T28: ='STOCK 2014'!L19 -> 2090 | U28: ='STOCK 2014'!L20 -> 11055 | V28: ='STOCK 2014'!L24 -> 507040 | X28: ='STOCK 2014'!L6 -> 552 | Y28: ='STOCK 2014'!L8 -> 5432 | AA28: ='STOCK 2014'!L23 -> 2889 | AC28: ='STOCK 2014'!L5 -> 1175 | AI28: ='STOCK 2014'!L12 -> 23527.265 | AJ28: ='STOCK 2014'!L22 -> 32157 | AK28: ='STOCK 2014'!L11 -> 6533 | AL28: ='STOCK 2014'!L14 -> 202 | AO28: ='STOCK 2014'!L25 -> 124437 | AQ28: ='STOCK 2014'!L7 -> 1499 | AR28: ='STOCK 2014'!L15 -> 84481
B29: R_ES-SH-DH_ELC02-ELCspl | C29: Backup for Heat Pump Air-to-Air - Electric_SH-WH (DH) | D29: R_ES-DH-SpHeat, R_ES-DH-WatHeat | F29: ='STOCK 2014'!M4 -> AIR REVERSIBLE | G29: 2014 | I29: ='STOCK 2014'!M18 -> 0 | K29: ='STOCK 2014'!M9 -> 1819.8 | M29: ='STOCK 2014'!M17 -> 0 | O29: ='STOCK 2014'!M10 -> 0 | P29: ='STOCK 2014'!M21 -> 1371.6 | Q29: ='STOCK 2014'!M16 -> 115755 | R29: ='STOCK 2014'!M13 -> 81520 | T29: ='STOCK 2014'!M19 -> 278896.07 | U29: ='STOCK 2014'!M20 -> 496910 | V29: ='STOCK 2014'!M24 -> 405640.01 | X29: ='STOCK 2014'!M6 -> 613.62 | Y29: ='STOCK 2014'!M8 -> 0 | AA29: ='STOCK 2014'!M23 -> 1103936.5 | AC29: ='STOCK 2014'!M5 -> 0 | AI29: ='STOCK 2014'!M12 -> 130.5 | AJ29: ='STOCK 2014'!M22 -> 749025.1 | AK29: ='STOCK 2014'!M11 -> 2685.6 | AL29: ='STOCK 2014'!M14 -> 85780.105 | AO29: ='STOCK 2014'!M25 -> 619234 | AQ29: ='STOCK 2014'!M7 -> 169.2 | AR29: ='STOCK 2014'!M15 -> 0
B30: R_ES-SH-DH_ELC02-GASspl | C30: Backup for Heat Pump Air-to-Air - Natural Gas boiler_SH-WH (DH) | D30: R_ES-DH-SpHeat, R_ES-DH-WatHeat | F30: ='STOCK 2014'!N4 -> AIR Sanitary Hot Water | G30: 2014 | I30: ='STOCK 2014'!N18 -> 75277 | K30: ='STOCK 2014'!N9 -> 12489 | M30: ='STOCK 2014'!N17 -> 12446 | O30: ='STOCK 2014'!N10 -> 20 | P30: ='STOCK 2014'!N21 -> 144174 | Q30: ='STOCK 2014'!N16 -> 15463 | R30: ='STOCK 2014'!N13 -> 0 | T30: ='STOCK 2014'!N19 -> 2187 | U30: ='STOCK 2014'!N20 -> 0 | V30: ='STOCK 2014'!N24 -> 209089 | X30: ='STOCK 2014'!N6 -> 71 | Y30: ='STOCK 2014'!N8 -> 15 | AA30: ='STOCK 2014'!N23 -> 1551 | AC30: ='STOCK 2014'!N5 -> 0 | AI30: ='STOCK 2014'!N12 -> 7155 | AJ30: ='STOCK 2014'!N22 -> 0 | AK30: ='STOCK 2014'!N11 -> 28457 | AL30: ='STOCK 2014'!N14 -> 2772 | AO30: ='STOCK 2014'!N25 -> 0 | AQ30: ='STOCK 2014'!N7 -> 72 | AR30: ='STOCK 2014'!N15 -> 230
B31: R_ES-SH-DH_ELC02-BIOspl | C31: Backup for Heat Pump Air-to-Air - Biomass boiler_SH-WH (DH) | D31: R_ES-DH-SpHeat, R_ES-DH-WatHeat | F31: ='STOCK 2014'!O4 -> GROUND | G31: 2014 | I31: ='STOCK 2014'!O18 -> 89852 | K31: ='STOCK 2014'!O9 -> 6996 | M31: ='STOCK 2014'!O17 -> 75879 | O31: ='STOCK 2014'!O10 -> 17469 | P31: ='STOCK 2014'!O21 -> 296129 | Q31: ='STOCK 2014'!O16 -> 25814 | R31: ='STOCK 2014'!O13 -> 8875 | T31: ='STOCK 2014'!O19 -> 1144 | U31: ='STOCK 2014'!O20 -> 85294 | V31: ='STOCK 2014'!O24 -> 103409 | X31: ='STOCK 2014'!O6 -> 1845 | Y31: ='STOCK 2014'!O8 -> 3119 | AA31: ='STOCK 2014'!O23 -> 2759 | AC31: ='STOCK 2014'!O5 -> 2868 | AI31: ='STOCK 2014'!O12 -> 35860.735 | AJ31: ='STOCK 2014'!O22 -> 38104 | AK31: ='STOCK 2014'!O11 -> 22750 | AL31: ='STOCK 2014'!O14 -> 54 | AO31: ='STOCK 2014'!O25 -> 474079 | AQ31: ='STOCK 2014'!O7 -> 1426 | AR31: ='STOCK 2014'!O15 -> 24875
B32: R_ES-SH-DH_ELC02-SOLspl | C32: Backup for Heat Pump Air-to-Air - Solar thermal_SH-WH (DH) | D32: R_ES-DH-SpHeat, R_ES-DH-WatHeat
B33: R_ES-SH-DH_ELC04 | C33: Heat Pump Air-to-Water_SH-WH (DH) | D33: R_ES-DH-SpHeat, R_ES-DH-WatHeat | F33: Dwelling stock projections ('000units)
B34: R_ES-SH-DH_ELC05 | C34: Heat Pump Air-to-Water_SH-WH-SC (DH) | D34: R_ES-DH-SpHeat, R_ES-DH-WatHeat, R_ES-DH-SpCool | F34: Dwelling type | G34: Year | H34: AL | I34: AT | J34: BA | K34: BE | L34: BG | M34: CH | N34: CY | O34: CZ | P34: DE | Q34: DK | R34: EE | S34: EL | T34: ES | U34: FI | V34: FR | W34: HR | X34: HU | Y34: IE | Z34: IS | AA34: IT | AB34: KS | AC34: LT | AD34: LU | AE34: LV | AF34: ME | AG34: MK | AH34: MT | AI34: NL | AJ34: NO | AK34: PL | AL34: PT | AM34: RO | AN34: RS | AO34: SE | AP34: SI | AQ34: SK | AR34: UK
B35: R_ES-SH-DH_ELC06 | C35: Heat Pump Ground Source Horizontal_SH-WH (DH) | D35: R_ES-DH-SpHeat, R_ES-DH-WatHeat | F35: =Rdw_Stock!D2 -> R_DetH | G35: =Rdw_Stock!G2 -> 2010 | H35: =AVERAGEIFS(Rdw_Stock!L$2:L$29,Rdw_Stock!$D$2:$D$29,VDA_table!$F35,Rdw_Stock!$G$2:$G$29,VDA_table!$G35) -> 85.365659 | I35: =AVERAGEIFS(Rdw_Stock!M$2:M$29,Rdw_Stock!$D$2:$D$29,VDA_table!$F35,Rdw_Stock!$G$2:$G$29,VDA_table!$G35) -> 1015.1617 | J35: =AVERAGEIFS(Rdw_Stock!N$2:N$29,Rdw_Stock!$D$2:$D$29,VDA_table!$F35,Rdw_Stock!$G$2:$G$29,VDA_table!$G35) -> 223.10096 | K35: =AVERAGEIFS(Rdw_Stock!O$2:O$29,Rdw_Stock!$D$2:$D$29,VDA_table!$F35,Rdw_Stock!$G$2:$G$29,VDA_table!$G35) -> 950.38722 | L35: =AVERAGEIFS(Rdw_Stock!P$2:P$29,Rdw_Stock!$D$2:$D$29,VDA_table!$F35,Rdw_Stock!$G$2:$G$29,VDA_table!$G35) -> 617.01235 | M35: =AVERAGEIFS(Rdw_Stock!Q$2:Q$29,Rdw_Stock!$D$2:$D$29,VDA_table!$F35,Rdw_Stock!$G$2:$G$29,VDA_table!$G35) -> 841.55024 | N35: =AVERAGEIFS(Rdw_Stock!R$2:R$29,Rdw_Stock!$D$2:$D$29,VDA_table!$F35,Rdw_Stock!$G$2:$G$29,VDA_table!$G35) -> 105.85211 | O35: =AVERAGEIFS(Rdw_Stock!S$2:S$29,Rdw_Stock!$D$2:$D$29,VDA_table!$F35,Rdw_Stock!$G$2:$G$29,VDA_table!$G35) -> 1027.0584 | ... AR35: =AVERAGEIFS(Rdw_Stock!AV$2:AV$29,Rdw_Stock!$D$2:$D$29,VDA_table!$F35,Rdw_Stock!$G$2:$G$29,VDA_table!$G35) -> 3810.9775
B36: R_ES-SH-DH_ELC07 | C36: Heat Pump Ground Source Horizontal_SH-WH-SC (DH) | D36: R_ES-DH-SpHeat,R_ES-DH-WatHeat,R_ES-DH-SpCool | F36: =Rdw_Stock!D3 -> R_DetH | G36: =Rdw_Stock!G3 -> 2050 | H36: =AVERAGEIFS(Rdw_Stock!L$2:L$29,Rdw_Stock!$D$2:$D$29,VDA_table!$F36,Rdw_Stock!$G$2:$G$29,VDA_table!$G36) -> 258.23468 | I36: =AVERAGEIFS(Rdw_Stock!M$2:M$29,Rdw_Stock!$D$2:$D$29,VDA_table!$F36,Rdw_Stock!$G$2:$G$29,VDA_table!$G36) -> 1278.7031 | J36: =AVERAGEIFS(Rdw_Stock!N$2:N$29,Rdw_Stock!$D$2:$D$29,VDA_table!$F36,Rdw_Stock!$G$2:$G$29,VDA_table!$G36) -> 439.0482 | K36: =AVERAGEIFS(Rdw_Stock!O$2:O$29,Rdw_Stock!$D$2:$D$29,VDA_table!$F36,Rdw_Stock!$G$2:$G$29,VDA_table!$G36) -> 1419.0733 | L36: =AVERAGEIFS(Rdw_Stock!P$2:P$29,Rdw_Stock!$D$2:$D$29,VDA_table!$F36,Rdw_Stock!$G$2:$G$29,VDA_table!$G36) -> 697.64544 | M36: =AVERAGEIFS(Rdw_Stock!Q$2:Q$29,Rdw_Stock!$D$2:$D$29,VDA_table!$F36,Rdw_Stock!$G$2:$G$29,VDA_table!$G36) -> 1133.0116 | N36: =AVERAGEIFS(Rdw_Stock!R$2:R$29,Rdw_Stock!$D$2:$D$29,VDA_table!$F36,Rdw_Stock!$G$2:$G$29,VDA_table!$G36) -> 141.67291 | O36: =AVERAGEIFS(Rdw_Stock!S$2:S$29,Rdw_Stock!$D$2:$D$29,VDA_table!$F36,Rdw_Stock!$G$2:$G$29,VDA_table!$G36) -> 1340.5414 | ... AR36: =AVERAGEIFS(Rdw_Stock!AV$2:AV$29,Rdw_Stock!$D$2:$D$29,VDA_table!$F36,Rdw_Stock!$G$2:$G$29,VDA_table!$G36) -> 5282.2968
B37: R_ES-SH-DH_ELC08 | C37: Heat Pump Ground Source Vertical_SH-WH (DH) | D37: R_ES-DH-SpHeat, R_ES-DH-WatHeat | F37: =Rdw_Stock!D4 -> R_DetH | G37: =Rdw_Stock!G4 -> 2060 | H37: =AVERAGEIFS(Rdw_Stock!L$2:L$29,Rdw_Stock!$D$2:$D$29,VDA_table!$F37,Rdw_Stock!$G$2:$G$29,VDA_table!$G37) -> 258.23468 | I37: =AVERAGEIFS(Rdw_Stock!M$2:M$29,Rdw_Stock!$D$2:$D$29,VDA_table!$F37,Rdw_Stock!$G$2:$G$29,VDA_table!$G37) -> 1278.7031 | J37: =AVERAGEIFS(Rdw_Stock!N$2:N$29,Rdw_Stock!$D$2:$D$29,VDA_table!$F37,Rdw_Stock!$G$2:$G$29,VDA_table!$G37) -> 439.0482 | K37: =AVERAGEIFS(Rdw_Stock!O$2:O$29,Rdw_Stock!$D$2:$D$29,VDA_table!$F37,Rdw_Stock!$G$2:$G$29,VDA_table!$G37) -> 1419.0733 | L37: =AVERAGEIFS(Rdw_Stock!P$2:P$29,Rdw_Stock!$D$2:$D$29,VDA_table!$F37,Rdw_Stock!$G$2:$G$29,VDA_table!$G37) -> 697.64544 | M37: =AVERAGEIFS(Rdw_Stock!Q$2:Q$29,Rdw_Stock!$D$2:$D$29,VDA_table!$F37,Rdw_Stock!$G$2:$G$29,VDA_table!$G37) -> 1133.0116 | N37: =AVERAGEIFS(Rdw_Stock!R$2:R$29,Rdw_Stock!$D$2:$D$29,VDA_table!$F37,Rdw_Stock!$G$2:$G$29,VDA_table!$G37) -> 141.67291 | O37: =AVERAGEIFS(Rdw_Stock!S$2:S$29,Rdw_Stock!$D$2:$D$29,VDA_table!$F37,Rdw_Stock!$G$2:$G$29,VDA_table!$G37) -> 1340.5414 | ... AR37: =AVERAGEIFS(Rdw_Stock!AV$2:AV$29,Rdw_Stock!$D$2:$D$29,VDA_table!$F37,Rdw_Stock!$G$2:$G$29,VDA_table!$G37) -> 5282.2968
B38: R_ES-SH-DH_ELC09 | C38: Heat Pump Ground Source Vertical_SH-WH-SC (DH) | D38: R_ES-DH-SpHeat, R_ES-DH-WatHeat, R_ES-DH-SpCool | F38: =Rdw_Stock!D5 -> R_Flat | G38: =Rdw_Stock!G5 -> 2010 | H38: =AVERAGEIFS(Rdw_Stock!L$2:L$29,Rdw_Stock!$D$2:$D$29,VDA_table!$F38,Rdw_Stock!$G$2:$G$29,VDA_table!$G38) -> 196.66972 | I38: =AVERAGEIFS(Rdw_Stock!M$2:M$29,Rdw_Stock!$D$2:$D$29,VDA_table!$F38,Rdw_Stock!$G$2:$G$29,VDA_table!$G38) -> 1468.1931 | J38: =AVERAGEIFS(Rdw_Stock!N$2:N$29,Rdw_Stock!$D$2:$D$29,VDA_table!$F38,Rdw_Stock!$G$2:$G$29,VDA_table!$G38) -> 271.1874 | K38: =AVERAGEIFS(Rdw_Stock!O$2:O$29,Rdw_Stock!$D$2:$D$29,VDA_table!$F38,Rdw_Stock!$G$2:$G$29,VDA_table!$G38) -> 905.52301 | L38: =AVERAGEIFS(Rdw_Stock!P$2:P$29,Rdw_Stock!$D$2:$D$29,VDA_table!$F38,Rdw_Stock!$G$2:$G$29,VDA_table!$G38) -> 777.21771 | M38: =AVERAGEIFS(Rdw_Stock!Q$2:Q$29,Rdw_Stock!$D$2:$D$29,VDA_table!$F38,Rdw_Stock!$G$2:$G$29,VDA_table!$G38) -> 1648.2852 | N38: =AVERAGEIFS(Rdw_Stock!R$2:R$29,Rdw_Stock!$D$2:$D$29,VDA_table!$F38,Rdw_Stock!$G$2:$G$29,VDA_table!$G38) -> 83.544874 | O38: =AVERAGEIFS(Rdw_Stock!S$2:S$29,Rdw_Stock!$D$2:$D$29,VDA_table!$F38,Rdw_Stock!$G$2:$G$29,VDA_table!$G38) -> 2208.0312 | ... AR38: =AVERAGEIFS(Rdw_Stock!AV$2:AV$29,Rdw_Stock!$D$2:$D$29,VDA_table!$F38,Rdw_Stock!$G$2:$G$29,VDA_table!$G38) -> 3928.2271
B39: R_ES-SH-DH_ELC10 | C39: Heat Pump Groundwater_SH-WH (DH) | D39: R_ES-DH-SpHeat, R_ES-DH-WatHeat | F39: =Rdw_Stock!D6 -> R_Flat | G39: =Rdw_Stock!G6 -> 2050 | H39: =AVERAGEIFS(Rdw_Stock!L$2:L$29,Rdw_Stock!$D$2:$D$29,VDA_table!$F39,Rdw_Stock!$G$2:$G$29,VDA_table!$G39) -> 594.93412 | I39: =AVERAGEIFS(Rdw_Stock!M$2:M$29,Rdw_Stock!$D$2:$D$29,VDA_table!$F39,Rdw_Stock!$G$2:$G$29,VDA_table!$G39) -> 1849.3438 | J39: =AVERAGEIFS(Rdw_Stock!N$2:N$29,Rdw_Stock!$D$2:$D$29,VDA_table!$F39,Rdw_Stock!$G$2:$G$29,VDA_table!$G39) -> 533.67918 | K39: =AVERAGEIFS(Rdw_Stock!O$2:O$29,Rdw_Stock!$D$2:$D$29,VDA_table!$F39,Rdw_Stock!$G$2:$G$29,VDA_table!$G39) -> 1352.0842 | L39: =AVERAGEIFS(Rdw_Stock!P$2:P$29,Rdw_Stock!$D$2:$D$29,VDA_table!$F39,Rdw_Stock!$G$2:$G$29,VDA_table!$G39) -> 878.78693 | M39: =AVERAGEIFS(Rdw_Stock!Q$2:Q$29,Rdw_Stock!$D$2:$D$29,VDA_table!$F39,Rdw_Stock!$G$2:$G$29,VDA_table!$G39) -> 2219.1502 | N39: =AVERAGEIFS(Rdw_Stock!R$2:R$29,Rdw_Stock!$D$2:$D$29,VDA_table!$F39,Rdw_Stock!$G$2:$G$29,VDA_table!$G39) -> 111.81681 | O39: =AVERAGEIFS(Rdw_Stock!S$2:S$29,Rdw_Stock!$D$2:$D$29,VDA_table!$F39,Rdw_Stock!$G$2:$G$29,VDA_table!$G39) -> 2881.9756 | ... AR39: =AVERAGEIFS(Rdw_Stock!AV$2:AV$29,Rdw_Stock!$D$2:$D$29,VDA_table!$F39,Rdw_Stock!$G$2:$G$29,VDA_table!$G39) -> 5444.8134
B40: R_ES-SH-DH_ELC11 | C40: Heat Pump Groundwater_SH-WH-SC (DH) | D40: R_ES-DH-SpHeat, R_ES-DH-WatHeat, R_ES-DH-SpCool | F40: =Rdw_Stock!D7 -> R_Flat | G40: =Rdw_Stock!G7 -> 2060 | H40: =AVERAGEIFS(Rdw_Stock!L$2:L$29,Rdw_Stock!$D$2:$D$29,VDA_table!$F40,Rdw_Stock!$G$2:$G$29,VDA_table!$G40) -> 594.93412 | I40: =AVERAGEIFS(Rdw_Stock!M$2:M$29,Rdw_Stock!$D$2:$D$29,VDA_table!$F40,Rdw_Stock!$G$2:$G$29,VDA_table!$G40) -> 1849.3438 | J40: =AVERAGEIFS(Rdw_Stock!N$2:N$29,Rdw_Stock!$D$2:$D$29,VDA_table!$F40,Rdw_Stock!$G$2:$G$29,VDA_table!$G40) -> 533.67918 | K40: =AVERAGEIFS(Rdw_Stock!O$2:O$29,Rdw_Stock!$D$2:$D$29,VDA_table!$F40,Rdw_Stock!$G$2:$G$29,VDA_table!$G40) -> 1352.0842 | L40: =AVERAGEIFS(Rdw_Stock!P$2:P$29,Rdw_Stock!$D$2:$D$29,VDA_table!$F40,Rdw_Stock!$G$2:$G$29,VDA_table!$G40) -> 878.78693 | M40: =AVERAGEIFS(Rdw_Stock!Q$2:Q$29,Rdw_Stock!$D$2:$D$29,VDA_table!$F40,Rdw_Stock!$G$2:$G$29,VDA_table!$G40) -> 2219.1502 | N40: =AVERAGEIFS(Rdw_Stock!R$2:R$29,Rdw_Stock!$D$2:$D$29,VDA_table!$F40,Rdw_Stock!$G$2:$G$29,VDA_table!$G40) -> 111.81681 | O40: =AVERAGEIFS(Rdw_Stock!S$2:S$29,Rdw_Stock!$D$2:$D$29,VDA_table!$F40,Rdw_Stock!$G$2:$G$29,VDA_table!$G40) -> 2881.9756 | ... AR40: =AVERAGEIFS(Rdw_Stock!AV$2:AV$29,Rdw_Stock!$D$2:$D$29,VDA_table!$F40,Rdw_Stock!$G$2:$G$29,VDA_table!$G40) -> 5444.8134
F41: =Rdw_Stock!D8 -> R_SDetH | G41: =Rdw_Stock!G8 -> 2010 | H41: =AVERAGEIFS(Rdw_Stock!L$2:L$29,Rdw_Stock!$D$2:$D$29,VDA_table!$F41,Rdw_Stock!$G$2:$G$29,VDA_table!$G41) -> 48.267499 | I41: =AVERAGEIFS(Rdw_Stock!M$2:M$29,Rdw_Stock!$D$2:$D$29,VDA_table!$F41,Rdw_Stock!$G$2:$G$29,VDA_table!$G41) -> 470.44081 | J41: =AVERAGEIFS(Rdw_Stock!N$2:N$29,Rdw_Stock!$D$2:$D$29,VDA_table!$F41,Rdw_Stock!$G$2:$G$29,VDA_table!$G41) -> 79.84264 | K41: =AVERAGEIFS(Rdw_Stock!O$2:O$29,Rdw_Stock!$D$2:$D$29,VDA_table!$F41,Rdw_Stock!$G$2:$G$29,VDA_table!$G41) -> 1585.6865 | L41: =AVERAGEIFS(Rdw_Stock!P$2:P$29,Rdw_Stock!$D$2:$D$29,VDA_table!$F41,Rdw_Stock!$G$2:$G$29,VDA_table!$G41) -> 335.3328 | M41: =AVERAGEIFS(Rdw_Stock!Q$2:Q$29,Rdw_Stock!$D$2:$D$29,VDA_table!$F41,Rdw_Stock!$G$2:$G$29,VDA_table!$G41) -> 944.09207 | N41: =AVERAGEIFS(Rdw_Stock!R$2:R$29,Rdw_Stock!$D$2:$D$29,VDA_table!$F41,Rdw_Stock!$G$2:$G$29,VDA_table!$G41) -> 108.10428 | O41: =AVERAGEIFS(Rdw_Stock!S$2:S$29,Rdw_Stock!$D$2:$D$29,VDA_table!$F41,Rdw_Stock!$G$2:$G$29,VDA_table!$G41) -> 608.78058 | ... AR41: =AVERAGEIFS(Rdw_Stock!AV$2:AV$29,Rdw_Stock!$D$2:$D$29,VDA_table!$F41,Rdw_Stock!$G$2:$G$29,VDA_table!$G41) -> 13230.789
F42: =Rdw_Stock!D9 -> R_SDetH | G42: =Rdw_Stock!G9 -> 2050 | H42: =AVERAGEIFS(Rdw_Stock!L$2:L$29,Rdw_Stock!$D$2:$D$29,VDA_table!$F42,Rdw_Stock!$G$2:$G$29,VDA_table!$G42) -> 146.0112 | I42: =AVERAGEIFS(Rdw_Stock!M$2:M$29,Rdw_Stock!$D$2:$D$29,VDA_table!$F42,Rdw_Stock!$G$2:$G$29,VDA_table!$G42) -> 592.56971 | J42: =AVERAGEIFS(Rdw_Stock!N$2:N$29,Rdw_Stock!$D$2:$D$29,VDA_table!$F42,Rdw_Stock!$G$2:$G$29,VDA_table!$G42) -> 157.12513 | K42: =AVERAGEIFS(Rdw_Stock!O$2:O$29,Rdw_Stock!$D$2:$D$29,VDA_table!$F42,Rdw_Stock!$G$2:$G$29,VDA_table!$G42) -> 2367.6722 | L42: =AVERAGEIFS(Rdw_Stock!P$2:P$29,Rdw_Stock!$D$2:$D$29,VDA_table!$F42,Rdw_Stock!$G$2:$G$29,VDA_table!$G42) -> 379.15513 | M42: =AVERAGEIFS(Rdw_Stock!Q$2:Q$29,Rdw_Stock!$D$2:$D$29,VDA_table!$F42,Rdw_Stock!$G$2:$G$29,VDA_table!$G42) -> 1271.0677 | N42: =AVERAGEIFS(Rdw_Stock!R$2:R$29,Rdw_Stock!$D$2:$D$29,VDA_table!$F42,Rdw_Stock!$G$2:$G$29,VDA_table!$G42) -> 144.68723 | O42: =AVERAGEIFS(Rdw_Stock!S$2:S$29,Rdw_Stock!$D$2:$D$29,VDA_table!$F42,Rdw_Stock!$G$2:$G$29,VDA_table!$G42) -> 794.59511 | ... AR42: =AVERAGEIFS(Rdw_Stock!AV$2:AV$29,Rdw_Stock!$D$2:$D$29,VDA_table!$F42,Rdw_Stock!$G$2:$G$29,VDA_table!$G42) -> 18338.853
F43: =Rdw_Stock!D10 -> R_SDetH | G43: =Rdw_Stock!G10 -> 2060 | H43: =AVERAGEIFS(Rdw_Stock!L$2:L$29,Rdw_Stock!$D$2:$D$29,VDA_table!$F43,Rdw_Stock!$G$2:$G$29,VDA_table!$G43) -> 146.0112 | I43: =AVERAGEIFS(Rdw_Stock!M$2:M$29,Rdw_Stock!$D$2:$D$29,VDA_table!$F43,Rdw_Stock!$G$2:$G$29,VDA_table!$G43) -> 592.56971 | J43: =AVERAGEIFS(Rdw_Stock!N$2:N$29,Rdw_Stock!$D$2:$D$29,VDA_table!$F43,Rdw_Stock!$G$2:$G$29,VDA_table!$G43) -> 157.12513 | K43: =AVERAGEIFS(Rdw_Stock!O$2:O$29,Rdw_Stock!$D$2:$D$29,VDA_table!$F43,Rdw_Stock!$G$2:$G$29,VDA_table!$G43) -> 2367.6722 | L43: =AVERAGEIFS(Rdw_Stock!P$2:P$29,Rdw_Stock!$D$2:$D$29,VDA_table!$F43,Rdw_Stock!$G$2:$G$29,VDA_table!$G43) -> 379.15513 | M43: =AVERAGEIFS(Rdw_Stock!Q$2:Q$29,Rdw_Stock!$D$2:$D$29,VDA_table!$F43,Rdw_Stock!$G$2:$G$29,VDA_table!$G43) -> 1271.0677 | N43: =AVERAGEIFS(Rdw_Stock!R$2:R$29,Rdw_Stock!$D$2:$D$29,VDA_table!$F43,Rdw_Stock!$G$2:$G$29,VDA_table!$G43) -> 144.68723 | O43: =AVERAGEIFS(Rdw_Stock!S$2:S$29,Rdw_Stock!$D$2:$D$29,VDA_table!$F43,Rdw_Stock!$G$2:$G$29,VDA_table!$G43) -> 794.59511 | ... AR43: =AVERAGEIFS(Rdw_Stock!AV$2:AV$29,Rdw_Stock!$D$2:$D$29,VDA_table!$F43,Rdw_Stock!$G$2:$G$29,VDA_table!$G43) -> 18338.853
F44: All dwellings | G44: =G35 -> 2010 | H44: =SUM(H35,H38,H41) -> 330.30288 | I44: =SUM(I35,I38,I41) -> 2953.7957 | J44: =SUM(J35,J38,J41) -> 574.13101 | K44: =SUM(K35,K38,K41) -> 3441.5967 | L44: =SUM(L35,L38,L41) -> 1729.5629 | M44: =SUM(M35,M38,M41) -> 3433.9275 | N44: =SUM(N35,N38,N41) -> 297.50126 | O44: =SUM(O35,O38,O41) -> 3843.8702 | ... AR44: =SUM(AR35,AR38,AR41) -> 20969.994
...

Sheet STOCK 2010
B2: Source: http://stats.ehpa.org/hp_sales/cockpit/ | K2: Simplification
C4: Exhaust air | D4: H-air/water | E4: H-ground/water | F4: Reversible air-air w/heating | G4: Reversible other | H4: Sanitary hot water | L4: AIR | M4: AIR REVERSIBLE | N4: AIR Sanitary Hot Water | O4: GROUND | R4: AT | S4: BE | T4: CH | U4: CZ | V4: DE | W4: DK | X4: EE | Y4: ES | Z4: FI | AA4: FR | AB4: HU | AC4: IE | AD4: IT | AE4: LT | AF4: NL | AG4: NO | AH4: PL | AI4: PT | AJ4: SE | AK4: SK | AL4: UK
B5: LT | C5: 0 | D5: 302 | E5: 769 | F5: 0 | G5: 0 | H5: 0 | K5: LT | L5: =D5 -> 302 | M5: =F5 -> 0 | N5: =H5 -> 0 | O5: =E5 -> 769 | Q5: =L4 -> AIR | R5: =L5 -> 302 | S5: =L6 -> 164 | T5: =L7 -> 650 | U5: =L8 -> 927 | V5: =L9 -> 2879 | W5: =L10 -> 9724 | X5: =L11 -> 1200 | Y5: =L12 -> 9070.265 | Z5: =L13 -> 1520 | AA5: =L14 -> 0 | AB5: =L15 -> 25245 | AC5: =L16 -> 4226 | AD5: =L17 -> 59579 | AE5: =L18 -> 21063 | AF5: =L19 -> 0 | AG5: =L20 -> 6326 | AH5: =L21 -> 130781 | AI5: =L22 -> 20941 | AJ5: =L23 -> 1240 | AK5: =L24 -> 366053 | AL5: =L25 -> 96565
B6: HU | C6: 71 | D6: 164 | E6: 520 | F6: 268.02 | G6: 663.8 | H6: 38 | K6: HU | L6: =D6 -> 164 | M6: =F6 -> 268.02 | N6: =H6 -> 38 | O6: =E6 -> 520 | Q6: =M4 -> AIR REVERSIBLE | R6: =M5 -> 0 | S6: =M6 -> 268.02 | T6: =M7 -> 58.5 | U6: =M8 -> 0 | V6: =M9 -> 0 | W6: =M10 -> 0 | X6: =M11 -> 0 | Y6: =M12 -> 130.5 | Z6: =M13 -> 34320 | AA6: =M14 -> 49669.255 | AB6: =M15 -> 0 | AC6: =M16 -> 42163 | AD6: =M17 -> 0 | AE6: =M18 -> 0 | AF6: =M19 -> 67229.95 | AG6: =M20 -> 297948 | AH6: =M21 -> 1371.6 | AI6: =M22 -> 504182 | AJ6: =M23 -> 715200.73 | AK6: =M24 -> 217550.71 | AL6: =M25 -> 402543
B7: SK | C7: 71 | D7: 650 | E7: 500 | F7: 58.5 | G7: 100 | H7: 0 | K7: SK | L7: =D7 -> 650 | M7: =F7 -> 58.5 | N7: =H7 -> 0 | O7: =E7 -> 500 | Q7: =N4 -> AIR Sanitary Hot Water | R7: =N5 -> 0 | S7: =N6 -> 38 | T7: =N7 -> 0 | U7: =N8 -> 3 | V7: =N9 -> 1611 | W7: =N10 -> 10 | X7: =N11 -> 2060 | Y7: =N12 -> 5901 | Z7: =N13 -> 0 | AA7: =N14 -> 427 | AB7: =N15 -> 0 | AC7: =N16 -> 6580 | AD7: =N17 -> 1487 | AE7: =N18 -> 80685 | AF7: =N19 -> 0 | AG7: =N20 -> 0 | AH7: =N21 -> 102515 | AI7: =N22 -> 0 | AJ7: =N23 -> 0 | AK7: =N24 -> 29000 | AL7: =N25 -> 0
B8: IE | C8: 90 | D8: 927 | E8: 1279 | F8: 0 | G8: 0 | H8: 3 | K8: IE | L8: =D8 -> 927 | M8: =F8 -> 0 | N8: =H8 -> 3 | O8: =E8 -> 1279 | Q8: =O4 -> GROUND | R8: =O5 -> 769 | S8: =O6 -> 520 | T8: =O7 -> 500 | U8: =O8 -> 1279 | V8: =O9 -> 1954 | W8: =O10 -> 8747 | X8: =O11 -> 4120 | Y8: =O12 -> 18652.735 | Z8: =O13 -> 3735 | AA8: =O14 -> 0 | AB8: =O15 -> 16160 | AC8: =O16 -> 13528 | AD8: =O17 -> 45733 | AE8: =O18 -> 69213 | AF8: =O19 -> 0 | AG8: =O20 -> 34934 | AH8: =O21 -> 216821 | AI8: =O22 -> 25248 | AJ8: =O23 -> 357 | AK8: =O24 -> 84737 | AL8: =O25 -> 372685
B9: BE | C9: 135 | D9: 2879 | E9: 1954 | F9: 0 | G9: 0 | H9: 1611 | K9: BE | L9: =D9 -> 2879 | M9: =F9 -> 0 | N9: =H9 -> 1611 | O9: =E9 -> 1954
B10: CZ | C10: 0 | D10: 9724 | E10: 8747 | F10: 0 | G10: 55 | H10: 10 | K10: CZ | L10: =D10 -> 9724 | M10: =F10 -> 0 | N10: =H10 -> 10 | O10: =E10 -> 8747
B11: PL | C11: 95 | D11: 1200 | E11: 4120 | F11: 0 | G11: 770 | H11: 2060 | K11: PL | L11: =D11 -> 1200 | M11: =F11 -> 0 | N11: =H11 -> 2060 | O11: =E11 -> 4120
B12: NL | C12: 922 | D12: 9070.265 | E12: 18652.735 | F12: 130.5 | G12: 361 | H12: 5901 | K12: NL | L12: =D12 -> 9070.265 | M12: =F12 -> 130.5 | N12: =H12 -> 5901 | O12: =E12 -> 18652.735 | Q12: Stock 2010 | R12: AT | S12: BE | T12: BG | U12: CH | V12: CY | W12: CZ | X12: DE | Y12: DK | Z12: EE | AA12: ES | AB12: FI | AC12: FR | AD12: EL | AE12: HR | AF12: HU | AG12: IE | AH12: IS | AI12: IT | AJ12: LT | AK12: LU | AL12: LV | AM12: MT | AN12: NL | AO12: NO | AP12: PL | AQ12: PT | AR12: RO | AS12: SE | AT12: SI | AU12: SK | AV12: UK | AW12: AL | AX12: BA | AY12: ME | AZ12: MK | BA12: RS | BB12: KS
B13: EE | C13: 176 | D13: 1520 | E13: 3735 | F13: 34320 | G13: 0 | H13: 0 | K13: EE | L13: =D13 -> 1520 | M13: =F13 -> 34320 | N13: =H13 -> 0 | O13: =E13 -> 3735 | Q13: Air | R13: =SUM(R5:R7) -> 302 | S13: =SUM(S5:S7) -> 470.02 | U13: =SUM(T5:T7) -> 708.5 | W13: =SUM(U5:U7) -> 930 | X13: =SUM(V5:V7) -> 4490 | Y13: =SUM(W5:W7) -> 9734 | Z13: =SUM(X5:X7) -> 3260 | AA13: =SUM(Y5:Y7) -> 15101.765 | AB13: =SUM(Z5:Z7) -> 35840 | AC13: =SUM(AA5:AA7) -> 50096.255 | AF13: =SUM(AB5:AB7) -> 25245 | AG13: =SUM(AC5:AC7) -> 52969 | AI13: =SUM(AD5:AD7) -> 61066 | AJ13: =SUM(AE5:AE7) -> 101748 | AN13: =SUM(AF5:AF7) -> 67229.95 | AO13: =SUM(AG5:AG7) -> 304274 | AP13: =SUM(AH5:AH7) -> 234667.6 | AQ13: =SUM(AI5:AI7) -> 525123 | AS13: =SUM(AJ5:AJ7) -> 716440.73 | AU13: =SUM(AK5:AK7) -> 612603.71 | AV13: =SUM(AL5:AL7) -> 499108
B14: PT | C14: 0 | D14: 0 | E14: 0 | F14: 49669.255 | G14: 4588.6 | H14: 427 | K14: PT | L14: =D14 -> 0 | M14: =F14 -> 49669.255 | N14: =H14 -> 427 | O14: =E14 -> 0 | Q14: Ground | R14: =R8 -> 769 | S14: =S8 -> 520 | U14: =T8 -> 500 | W14: =U8 -> 1279 | X14: =V8 -> 1954 | Y14: =W8 -> 8747 | Z14: =X8 -> 4120 | AA14: =Y8 -> 18652.735 | AB14: =Z8 -> 3735 | AC14: =AA8 -> 0 | AF14: =AB8 -> 16160 | AG14: =AC8 -> 13528 | AI14: =AD8 -> 45733 | AJ14: =AE8 -> 69213 | AN14: =AF8 -> 0 | AO14: =AG8 -> 34934 | AP14: =AH8 -> 216821 | AQ14: =AI8 -> 25248 | AS14: =AJ8 -> 357 | AU14: =AK8 -> 84737 | AV14: =AL8 -> 372685
B15: UK | C15: 8770 | D15: 25245 | E15: 16160 | F15: 0 | G15: 0 | H15: 0 | K15: UK | L15: =D15 -> 25245 | M15: =F15 -> 0 | N15: =H15 -> 0 | O15: =E15 -> 16160
B16: DK | C16: 4224 | D16: 4226 | E16: 13528 | F16: 42163 | G16: 0 | H16: 6580 | K16: DK | L16: =D16 -> 4226 | M16: =F16 -> 42163 | N16: =H16 -> 6580 | O16: =E16 -> 13528
B17: CH | C17: 478 | D17: 59579 | E17: 45733 | F17: 0 | G17: 0 | H17: 1487 | K17: CH | L17: =D17 -> 59579 | M17: =F17 -> 0 | N17: =H17 -> 1487 | O17: =E17 -> 45733
B18: AT | C18: 4036 | D18: 21063 | E18: 69213 | F18: 0 | G18: 0 | H18: 80685 | K18: AT | L18: =D18 -> 21063 | M18: =F18 -> 0 | N18: =H18 -> 80685 | O18: =E18 -> 69213
B19: ES | C19: 0 | D19: 0 | E19: 0 | F19: 67229.95 | G19: 3259 | H19: 0 | K19: ES | L19: =D19 -> 0 | M19: =F19 -> 67229.95 | N19: =H19 -> 0 | O19: =E19 -> 0
B20: FI | C20: 12707 | D20: 6326 | E20: 34934 | F20: 297948 | G20: 0 | H20: 0 | K20: FI | L20: =D20 -> 6326 | M20: =F20 -> 297948 | N20: =H20 -> 0 | O20: =E20 -> 34934
B21: DE | C21: 0 | D21: 130781 | E21: 216821 | F21: 1371.6 | G21: 3313 | H21: 102515 | K21: DE | L21: =D21 -> 130781 | M21: =F21 -> 1371.6 | N21: =H21 -> 102515 | O21: =E21 -> 216821
B22: NO | C22: 7632 | D22: 20941 | E22: 25248 | F22: 504182 | G22: 0 | H22: 0 | K22: NO | L22: =D22 -> 20941 | M22: =F22 -> 504182 | N22: =H22 -> 0 | O22: =E22 -> 25248
B23: IT | C23: 0 | D23: 1240 | E23: 357 | F23: 715200.73 | G23: 62038 | H23: 0 | K23: IT | L23: =D23 -> 1240 | M23: =F23 -> 715200.73 | N23: =H23 -> 0 | O23: =E23 -> 357
B24: FR | C24: 0 | D24: 366053 | E24: 84737 | F24: 217550.71 | G24: 33122 | H24: 29000 | K24: FR | L24: =D24 -> 366053 | M24: =F24 -> 217550.71 | N24: =H24 -> 29000 | O24: =E24 -> 84737
B25: SE | C25: 176180 | D25: 96565 | E25: 372685 | F25: 402543 | G25: 0 | H25: 0 | K25: SE | L25: =D25 -> 96565 | M25: =F25 -> 402543 | N25: =H25 -> 0 | O25: =E25 -> 372685

Sheet STOCK 2014
R1: MARKET
B2: Source: http://stats.ehpa.org/hp_sales/cockpit/ | K2: Simplification | R2: Absolute growth per year
C4: Exhaust air | D4: H-air/water | E4: H-ground/water | F4: Reversible air-air w/heating | G4: Reversible other | H4: Sanitary hot water | L4: AIR | M4: AIR REVERSIBLE | N4: AIR Sanitary Hot Water | O4: GROUND | Q4: AIR TOT | R4: AIR | S4: AIR REVERSIBLE | T4: AIR Sanitary Hot Water | U4: GROUND
B5: LT | D5: 1175 | E5: 2868 | G5: 45 | K5: LT | L5: =D5 -> 1175 | M5: =F5 -> 0 | N5: =H5 -> 0 | O5: =E5 -> 2868 | Q5: =R5+S5 -> 218.25 | R5: =(L5-'STOCK 2010'!L5)/4 -> 218.25 | S5: =(M5-'STOCK 2010'!M5)/4 -> 0 | T5: =(N5-'STOCK 2010'!N5)/4 -> 0 | U5: =(O5-'STOCK 2010'!O5)/4 -> 524.75 | V5: =SUM(R5:U5) -> 743
B6: HU | C6: 195 | D6: 552 | E6: 1845 | F6: 613.62 | G6: 1180.8 | H6: 71 | K6: HU | L6: =D6 -> 552 | M6: =F6 -> 613.62 | N6: =H6 -> 71 | O6: =E6 -> 1845 | Q6: =R6+S6 -> 183.4 | R6: =(L6-'STOCK 2010'!L6)/4 -> 97 | S6: =(M6-'STOCK 2010'!M6)/4 -> 86.4 | T6: =(N6-'STOCK 2010'!N6)/4 -> 8.25 | U6: =(O6-'STOCK 2010'!O6)/4 -> 331.25 | V6: =SUM(R6:U6) -> 522.9
B7: SK | C7: 105 | D7: 1499 | E7: 1426 | F7: 169.2 | G7: 1090 | H7: 72 | K7: SK | L7: =D7 -> 1499 | M7: =F7 -> 169.2 | N7: =H7 -> 72 | O7: =E7 -> 1426 | Q7: =R7+S7 -> 239.925 | R7: =(L7-'STOCK 2010'!L7)/4 -> 212.25 | S7: =(M7-'STOCK 2010'!M7)/4 -> 27.675 | T7: =(N7-'STOCK 2010'!N7)/4 -> 18 | U7: =(O7-'STOCK 2010'!O7)/4 -> 231.5 | V7: =SUM(R7:U7) -> 489.425
B8: IE | C8: 142 | D8: 5432 | E8: 3119 | H8: 15 | K8: IE | L8: =D8 -> 5432 | M8: =F8 -> 0 | N8: =H8 -> 15 | O8: =E8 -> 3119 | Q8: =R8+S8 -> 1126.25 | R8: =(L8-'STOCK 2010'!L8)/4 -> 1126.25 | S8: =(M8-'STOCK 2010'!M8)/4 -> 0 | T8: =(N8-'STOCK 2010'!N8)/4 -> 3 | U8: =(O8-'STOCK 2010'!O8)/4 -> 460 | V8: =SUM(R8:U8) -> 1589.25
B9: BE | C9: 135 | D9: 19544 | E9: 6996 | F9: 1819.8 | H9: 12489 | K9: BE | L9: =D9 -> 19544 | M9: =F9 -> 1819.8 | N9: =H9 -> 12489 | O9: =E9 -> 6996 | Q9: =R9+S9 -> 4621.2 | R9: =(L9-'STOCK 2010'!L9)/4 -> 4166.25 | S9: =(M9-'STOCK 2010'!M9)/4 -> 454.95 | T9: =(N9-'STOCK 2010'!N9)/4 -> 2719.5 | U9: =(O9-'STOCK 2010'!O9)/4 -> 1260.5 | V9: =SUM(R9:U9) -> 8601.2
B10: CZ | C10: 675 | D10: 28948 | E10: 17469 | F10: 0 | G10: 55 | H10: 20 | K10: CZ | L10: =D10 -> 28948 | M10: =F10 -> 0 | N10: =H10 -> 20 | O10: =E10 -> 17469 | Q10: =R10+S10 -> 4806 | R10: =(L10-'STOCK 2010'!L10)/4 -> 4806 | S10: =(M10-'STOCK 2010'!M10)/4 -> 0 | T10: =(N10-'STOCK 2010'!N10)/4 -> 2.5 | U10: =(O10-'STOCK 2010'!O10)/4 -> 2180.5 | V10: =SUM(R10:U10) -> 6989
B11: PL | C11: 361 | D11: 6533 | E11: 22750 | F11: 2685.6 | G11: 4450 | H11: 28457 | K11: PL | L11: =D11 -> 6533 | M11: =F11 -> 2685.6 | N11: =H11 -> 28457 | O11: =E11 -> 22750 | Q11: =R11+S11 -> 2004.65 | R11: =(L11-'STOCK 2010'!L11)/4 -> 1333.25 | S11: =(M11-'STOCK 2010'!M11)/4 -> 671.4 | T11: =(N11-'STOCK 2010'!N11)/4 -> 6599.25 | U11: =(O11-'STOCK 2010'!O11)/4 -> 4657.5 | V11: =SUM(R11:U11) -> 13261.4
B12: NL | C12: 922 | D12: 23527.265 | E12: 35860.735 | F12: 130.5 | G12: 361 | H12: 7155 | K12: NL | L12: =D12 -> 23527.265 | M12: =F12 -> 130.5 | N12: =H12 -> 7155 | O12: =E12 -> 35860.735 | Q12: =R12+S12 -> 3614.25 | R12: =(L12-'STOCK 2010'!L12)/4 -> 3614.25 | S12: =(M12-'STOCK 2010'!M12)/4 -> 0 | T12: =(N12-'STOCK 2010'!N12)/4 -> 313.5 | U12: =(O12-'STOCK 2010'!O12)/4 -> 4302 | V12: =SUM(R12:U12) -> 8229.75
B13: EE | C13: 357 | D13: 4820 | E13: 8875 | F13: 81520 | K13: EE | L13: =D13 -> 4820 | M13: =F13 -> 81520 | N13: =H13 -> 0 | O13: =E13 -> 8875 | Q13: =R13+S13 -> 12625 | R13: =(L13-'STOCK 2010'!L13)/4 -> 825 | S13: =(M13-'STOCK 2010'!M13)/4 -> 11800 | T13: =(N13-'STOCK 2010'!N13)/4 -> 0 | U13: =(O13-'STOCK 2010'!O13)/4 -> 1285 | V13: =SUM(R13:U13) -> 13910
B14: PT | D14: 202 | E14: 54 | F14: 85780.105 | G14: 6468.6 | H14: 2772 | K14: PT | L14: =D14 -> 202 | M14: =F14 -> 85780.105 | N14: =H14 -> 2772 | O14: =E14 -> 54 | Q14: =R14+S14 -> 9078.2125 | R14: =(L14-'STOCK 2010'!L14)/4 -> 50.5 | S14: =(M14-'STOCK 2010'!M14)/4 -> 9027.7125 | T14: =(N14-'STOCK 2010'!N14)/4 -> 586.25 | U14: =(O14-'STOCK 2010'!O14)/4 -> 13.5 | V14: =SUM(R14:U14) -> 9677.9625
B15: UK | C15: 13300 | D15: 84481 | E15: 24875 | H15: 230 | K15: UK | L15: =D15 -> 84481 | M15: =F15 -> 0 | N15: =H15 -> 230 | O15: =E15 -> 24875 | Q15: =R15+S15 -> 14809 | R15: =(L15-'STOCK 2010'!L15)/4 -> 14809 | S15: =(M15-'STOCK 2010'!M15)/4 -> 0 | T15: =(N15-'STOCK 2010'!N15)/4 -> 57.5 | U15: =(O15-'STOCK 2010'!O15)/4 -> 2178.75 | V15: =SUM(R15:U15) -> 17045.25
B16: DK | C16: 8934 | D16: 14122 | E16: 25814 | F16: 115755 | H16: 15463 | K16: DK | L16: =D16 -> 14122 | M16: =F16 -> 115755 | N16: =H16 -> 15463 | O16: =E16 -> 25814 | Q16: =R16+S16 -> 20872 | R16: =(L16-'STOCK 2010'!L16)/4 -> 2474 | S16: =(M16-'STOCK 2010'!M16)/4 -> 18398 | T16: =(N16-'STOCK 2010'!N16)/4 -> 2220.75 | U16: =(O16-'STOCK 2010'!O16)/4 -> 3071.5 | V16: =SUM(R16:U16) -> 26164.25
B17: CH | C17: 549 | D17: 105523 | E17: 75879 | F17: 0 | H17: 12446 | K17: CH | L17: =D17 -> 105523 | M17: =F17 -> 0 | N17: =H17 -> 12446 | O17: =E17 -> 75879 | Q17: =R17+S17 -> 11486 | R17: =(L17-'STOCK 2010'!L17)/4 -> 11486 | S17: =(M17-'STOCK 2010'!M17)/4 -> 0 | T17: =(N17-'STOCK 2010'!N17)/4 -> 2739.75 | U17: =(O17-'STOCK 2010'!O17)/4 -> 7536.5 | V17: =SUM(R17:U17) -> 21762.25
B18: AT | C18: 4938 | D18: 49974 | E18: 89852 | H18: 75277 | K18: AT | L18: =D18 -> 49974 | M18: =F18 -> 0 | N18: =H18 -> 75277 | O18: =E18 -> 89852 | Q18: =R18+S18 -> 7227.75 | R18: =(L18-'STOCK 2010'!L18)/4 -> 7227.75 | S18: =(M18-'STOCK 2010'!M18)/4 -> 0 | T18: =(N18-'STOCK 2010'!N18)/4 -> -1352 | U18: =(O18-'STOCK 2010'!O18)/4 -> 5159.75 | V18: =SUM(R18:U18) -> 11035.5
B19: ES | D19: 2090 | E19: 1144 | F19: 278896.07 | G19: 18722 | H19: 2187 | K19: ES | L19: =D19 -> 2090 | M19: =F19 -> 278896.07 | N19: =H19 -> 2187 | O19: =E19 -> 1144 | Q19: =R19+S19 -> 53439.029 | R19: =(L19-'STOCK 2010'!L19)/4 -> 522.5 | S19: =(M19-'STOCK 2010'!M19)/4 -> 52916.529 | T19: =(N19-'STOCK 2010'!N19)/4 -> 546.75 | U19: =(O19-'STOCK 2010'!O19)/4 -> 286 | V19: =SUM(R19:U19) -> 54271.779
B20: FI | C20: 20308 | D20: 11055 | E20: 85294 | F20: 496910 | K20: FI | L20: =D20 -> 11055 | M20: =F20 -> 496910 | N20: =H20 -> 0 | O20: =E20 -> 85294 | Q20: =R20+S20 -> 50922.75 | R20: =(L20-'STOCK 2010'!L20)/4 -> 1182.25 | S20: =(M20-'STOCK 2010'!M20)/4 -> 49740.5 | T20: =(N20-'STOCK 2010'!N20)/4 -> 0 | U20: =(O20-'STOCK 2010'!O20)/4 -> 12590 | V20: =SUM(R20:U20) -> 63512.75
B21: DE | D21: 277894 | E21: 296129 | F21: 1371.6 | G21: 3313 | H21: 144174 | K21: DE | L21: =D21 -> 277894 | M21: =F21 -> 1371.6 | N21: =H21 -> 144174 | O21: =E21 -> 296129 | Q21: =R21+S21 -> 36778.25 | R21: =(L21-'STOCK 2010'!L21)/4 -> 36778.25 | S21: =(M21-'STOCK 2010'!M21)/4 -> 0 | T21: =(N21-'STOCK 2010'!N21)/4 -> 10414.75 | U21: =(O21-'STOCK 2010'!O21)/4 -> 19827 | V21: =SUM(R21:U21) -> 67020
B22: NO | C22: 9496 | D22: 32157 | E22: 38104 | F22: 749025.1 | K22: NO | L22: =D22 -> 32157 | M22: =F22 -> 749025.1 | N22: =H22 -> 0 | O22: =E22 -> 38104 | Q22: =R22+S22 -> 64014.775 | R22: =(L22-'STOCK 2010'!L22)/4 -> 2804 | S22: =(M22-'STOCK 2010'!M22)/4 -> 61210.775 | T22: =(N22-'STOCK 2010'!N22)/4 -> 0 | U22: =(O22-'STOCK 2010'!O22)/4 -> 3214 | V22: =SUM(R22:U22) -> 67228.775
B23: IT | D23: 2889 | E23: 2759 | F23: 1103936.5 | G23: 122677 | H23: 1551 | K23: IT | L23: =D23 -> 2889 | M23: =F23 -> 1103936.5 | N23: =H23 -> 1551 | O23: =E23 -> 2759 | Q23: =R23+S23 -> 97596.185 | R23: =(L23-'STOCK 2010'!L23)/4 -> 412.25 | S23: =(M23-'STOCK 2010'!M23)/4 -> 97183.935 | T23: =(N23-'STOCK 2010'!N23)/4 -> 387.75 | U23: =(O23-'STOCK 2010'!O23)/4 -> 600.5 | V23: =SUM(R23:U23) -> 98584.435
B24: FR | D24: 507040 | E24: 103409 | F24: 405640.01 | G24: 128929 | H24: 209089 | K24: FR | L24: =D24 -> 507040 | M24: =F24 -> 405640.01 | N24: =H24 -> 209089 | O24: =E24 -> 103409 | Q24: =R24+S24 -> 82269.074 | R24: =(L24-'STOCK 2010'!L24)/4 -> 35246.75 | S24: =(M24-'STOCK 2010'!M24)/4 -> 47022.324 | T24: =(N24-'STOCK 2010'!N24)/4 -> 45022.25 | U24: =(O24-'STOCK 2010'!O24)/4 -> 4668 | V24: =SUM(R24:U24) -> 131959.32
B25: SE | C25: 214136 | D25: 124437 | E25: 474079 | F25: 619234 | K25: SE | L25: =D25 -> 124437 | M25: =F25 -> 619234 | N25: =H25 -> 0 | O25: =E25 -> 474079 | Q25: =R25+S25 -> 61140.75 | R25: =(L25-'STOCK 2010'!L25)/4 -> 6968 | S25: =(M25-'STOCK 2010'!M25)/4 -> 54172.75 | T25: =(N25-'STOCK 2010'!N25)/4 -> 0 | U25: =(O25-'STOCK 2010'!O25)/4 -> 25348.5 | V25: =SUM(R25:U25) -> 86489.25
