Workbook

Sheet fill data
A3: ~TFM_Fill-R: w=Stock; Hcol=Region
A4: TimeSlice | B4: LimType | C4: Attribute | D4: Year | E4: AllRegions | F4: Pset_CO
C5: Stock | E5: 1 | F5: TB??,TC??,TM??,TH??,TL??

Sheet Stock
A1: scenario | B1: attribute | C1: process | D1: commodity | E1: lim_type | F1: time_slice | G1: year | H1: commodity_group | I1: currency | J1: stage | K1: sow | L1: AL | M1: AT | N1: BA | O1: BE | P1: BG | Q1: CH | R1: CY | S1: CZ | T1: DE | U1: DK | V1: EE | W1: EL | X1: ES | Y1: FI | Z1: FR | AA1: HR | AB1: HU | AC1: IE | AD1: IS | AE1: IT | AF1: KS | AG1: LT | AH1: LU | AI1: LV | AJ1: ME | AK1: MK | AL1: MT | AM1: NL | AN1: NO | AO1: PL | AP1: PT | AQ1: RO | AR1: RS | AS1: SE | AT1: SI | AU1: SK | AV1: UK | AW1: year2
A2: BASE | B2: Stock | C2: TRA_Bus_Cng_Coa | D2: - | E2: - | F2: - | G2: 2010 | H2: - | I2: - | J2: - | K2: - | L2: 0 | M2: 0 | N2: 0 | O2: 0 | P2: 0 | Q2: 0 | R2: 0 | S2: 0 | T2: 0 | U2: 0 | V2: 0 | W2: 0 | X2: 0 | Y2: 0 | Z2: 0 | AA2: 0 | AB2: 0 | AC2: 0 | AD2: 0 | AE2: 0 | AF2: 0 | AG2: 0 | AH2: 0 | AI2: 0 | AJ2: 0 | AK2: 0 | AL2: 0 | AM2: 0 | AN2: 0 | AO2: 0 | AP2: 0 | AQ2: 0 | AR2: 0 | AS2: 0.27 | AT2: 0 | AU2: 0 | AV2: 0 | AW2: -
A3: BASE | B3: Stock | C3: TRA_Bus_Cng_Urb | D3: - | E3: - | F3: - | G3: 2010 | H3: - | I3: - | J3: - | K3: - | L3: 0 | M3: 0 | N3: 0 | O3: 0 | P3: 0 | Q3: 0.18 | R3: 0 | S3: 0 | T3: 1.53 | U3: 0 | V3: 0 | W3: 0 | X3: 0 | Y3: 0 | Z3: 0 | AA3: 0.06 | AB3: 0 | AC3: 0 | AD3: 0 | AE3: 3.55 | AF3: 0 | AG3: 0 | AH3: 0 | AI3: 0 | AJ3: 0 | AK3: 0 | AL3: 0 | AM3: 0.478 | AN3: 0 | AO3: 0 | AP3: 0 | AQ3: 0 | AR3: 0.038559753 | AS3: 1.2 | AT3: 0 | AU3: 0 | AV3: 0 | AW3: -
A4: BASE | B4: Stock | C4: TRA_Bus_Dis_Coa | D4: - | E4: - | F4: - | G4: 2010 | H4: - | I4: - | J4: - | K4: - | L4: 3.8439259 | M4: 7.29 | N4: 2.8242478 | O4: 9.46 | P4: 11.69 | Q4: 2.47 | R4: 2.36 | S4: 12.55 | T4: 29.51 | U4: 8.35 | V4: 3.29 | W4: 16.9 | X4: 39.65 | Y4: 5.93 | Z4: 61.69 | AA4: 3.78 | AB4: 12.16 | AC4: 4.95 | AD4: 0.87 | AE4: 78.1 | AF4: 0.76589735 | AG4: 4.05 | AH4: 0.85 | AI4: 1.83 | AJ4: 1.0775337 | AK4: 1.11 | AL4: 0.21 | AM4: 6.27 | AN4: 6.81 | AO4: 35.81 | AP4: 10.02 | AQ4: 13.09 | AR4: 3.5094836 | AS4: 5.77 | AT4: 1.22 | AU4: 3.82 | AV4: 119.9 | AW4: -
A5: BASE | B5: Stock | C5: TRA_Bus_Dis_Urb | D5: - | E5: - | F5: - | G5: 2010 | H5: - | I5: - | J5: - | K5: - | L5: 2.3677673 | M5: 2.14 | N5: 0.79945639 | O5: 6.52 | P5: 12.16 | Q5: 4.72 | R5: 3.14 | S5: 5.07 | T5: 44.69 | U5: 5.17 | V5: 0 | W5: 10.41 | X5: 21.35 | Y5: 7.72 | Z5: 21.2 | AA5: 1.07 | AB5: 4.91 | AC5: 4.95 | AD5: 0.91 | AE5: 15.59 | AF5: 0.21680163 | AG5: 9.86 | AH5: 0.79 | AI5: 1.76 | AJ5: 0.66373526 | AK5: 1.15 | AL5: 1.62 | AM5: 4.32 | AN5: 7.67 | AO5: 56.08 | AP5: 5.4 | AQ5: 15.06 | AR5: 0.99342526 | AS5: 6.66 | AT5: 1.21 | AU5: 5.53 | AV5: 44.35 | AW5: -
A6: BASE | B6: Stock | C6: TRA_Bus_Gas_Coa | D6: - | E6: - | F6: - | G6: 2010 | H6: - | I6: - | J6: - | K6: - | L6: 0 | M6: 0 | N6: 0 | O6: 0 | P6: 0 | Q6: 0 | R6: 0 | S6: 1.45 | T6: 0 | U6: 1.05 | V6: 0 | W6: 0 | X6: 0 | Y6: 0 | Z6: 0 | AA6: 0 | AB6: 0 | AC6: 0 | AD6: 0 | AE6: 0 | AF6: 0 | AG6: 0 | AH6: 0 | AI6: 0 | AJ6: 0 | AK6: 0 | AL6: 0 | AM6: 0 | AN6: 0 | AO6: 0 | AP6: 0 | AQ6: 0 | AR6: 0 | AS6: 0 | AT6: 0 | AU6: 0 | AV6: 1.98 | AW6: -
A7: BASE | B7: Stock | C7: TRA_Bus_Gas_Urb | D7: - | E7: - | F7: - | G7: 2010 | H7: - | I7: - | J7: - | K7: - | L7: 0 | M7: 0 | N7: 0 | O7: 0 | P7: 0 | Q7: 0 | R7: 0 | S7: 0.58 | T7: 0 | U7: 0.01 | V7: 0 | W7: 0 | X7: 0 | Y7: 0 | Z7: 0 | AA7: 0 | AB7: 0 | AC7: 0 | AD7: 0.12 | AE7: 0 | AF7: 0 | AG7: 0 | AH7: 0 | AI7: 0 | AJ7: 0 | AK7: 0.39 | AL7: 0 | AM7: 0.03 | AN7: 0 | AO7: 4.38 | AP7: 0.006 | AQ7: 0 | AR7: 0 | AS7: 0 | AT7: 0 | AU7: 0 | AV7: 4.62 | AW7: -
A8: BASE | B8: Stock | C8: TRA_Bus_Lpg_Coa | D8: - | E8: - | F8: - | G8: 2010 | H8: - | I8: - | J8: - | K8: - | L8: 0 | M8: 0 | N8: 0 | O8: 0 | P8: 0 | Q8: 0 | R8: 0 | S8: 0 | T8: 0 | U8: 0 | V8: 0 | W8: 0 | X8: 0 | Y8: 0 | Z8: 0 | AA8: 0 | AB8: 0 | AC8: 0 | AD8: 0 | AE8: 0 | AF8: 0 | AG8: 0 | AH8: 0 | AI8: 0 | AJ8: 0 | AK8: 0 | AL8: 0 | AM8: 0 | AN8: 0 | AO8: 0 | AP8: 0 | AQ8: 0 | AR8: 0 | AS8: 0 | AT8: 0 | AU8: 0 | AV8: 0.03 | AW8: -
A9: BASE | B9: Stock | C9: TRA_Bus_Lpg_Urb | D9: - | E9: - | F9: - | G9: 2010 | H9: - | I9: - | J9: - | K9: - | L9: 0 | M9: 0 | N9: 0 | O9: 0 | P9: 0 | Q9: 0 | R9: 0 | S9: 0 | T9: 0 | U9: 0 | V9: 0 | W9: 0 | X9: 0 | Y9: 0 | Z9: 0 | AA9: 0 | AB9: 0 | AC9: 0 | AD9: 0 | AE9: 0 | AF9: 0 | AG9: 0 | AH9: 0 | AI9: 0.013 | AJ9: 0 | AK9: 0.05 | AL9: 0 | AM9: 0.08 | AN9: 0 | AO9: 0.77 | AP9: 0.003 | AQ9: 0 | AR9: 0 | AS9: 0 | AT9: 0 | AU9: 0 | AV9: 0.23 | AW9: -
A10: BASE | B10: Stock | C10: TRA_Car_Cng_Exe | D10: - | E10: - | F10: - | G10: 2010 | H10: - | I10: - | J10: - | K10: - | L10: 0 | M10: 0 | N10: 0 | O10: 0 | P10: 0 | Q10: 0.9 | R10: 0 | S10: 0 | T10: 9.2 | U10: 0 | V10: 0 | W10: 0 | X10: 0 | Y10: 0 | Z10: 0 | AA10: 0 | AB10: 0 | AC10: 0 | AD10: 0 | AE10: 97.21 | AF10: 0 | AG10: 0 | AH10: 0 | AI10: 0 | AJ10: 0 | AK10: 0 | AL10: 0 | AM10: 0.12 | AN10: 0 | AO10: 0 | AP10: 0 | AQ10: 0 | AR10: 1.0558825 | AS10: 2.42 | AT10: 0 | AU10: 0 | AV10: 0.18 | AW10: -
A11: BASE | B11: Stock | C11: TRA_Car_Cng_Lom | D11: - | E11: - | F11: - | G11: 2010 | H11: - | I11: - | J11: - | K11: - | L11: 0 | M11: 0 | N11: 0 | O11: 0 | P11: 0 | Q11: 2.34 | R11: 0 | S11: 0 | T11: 23.9 | U11: 0 | V11: 0 | W11: 0 | X11: 0 | Y11: 0 | Z11: 0 | AA11: 0 | AB11: 0 | AC11: 0 | AD11: 0 | AE11: 252.71 | AF11: 0 | AG11: 0 | AH11: 0 | AI11: 0 | AJ11: 0 | AK11: 0 | AL11: 0 | AM11: 0.32 | AN11: 0 | AO11: 0 | AP11: 0 | AQ11: 0 | AR11: 2.7449036 | AS11: 8.9 | AT11: 0 | AU11: 0 | AV11: 0.48 | AW11: -
A12: BASE | B12: Stock | C12: TRA_Car_Cng_Sma | D12: - | E12: - | F12: - | G12: 2010 | H12: - | I12: - | J12: - | K12: - | L12: 0 | M12: 0 | N12: 0 | O12: 0 | P12: 0 | Q12: 2.29 | R12: 0 | S12: 0 | T12: 23.34 | U12: 0 | V12: 0 | W12: 0 | X12: 0 | Y12: 0 | Z12: 0 | AA12: 0 | AB12: 0 | AC12: 0 | AD12: 0 | AE12: 246.79 | AF12: 0 | AG12: 0 | AH12: 0 | AI12: 0 | AJ12: 0 | AK12: 0 | AL12: 0 | AM12: 0.32 | AN12: 0 | AO12: 0 | AP12: 0 | AQ12: 0 | AR12: 2.6806013 | AS12: 8.94 | AT12: 0 | AU12: 0 | AV12: 0.47 | AW12: -
A13: BASE | B13: Stock | C13: TRA_Car_Cng_Upm | D13: - | E13: - | F13: - | G13: 2010 | H13: - | I13: - | J13: - | K13: - | L13: 0 | M13: 0 | N13: 0 | O13: 0 | P13: 0 | Q13: 1.05 | R13: 0 | S13: 0 | T13: 10.72 | U13: 0 | V13: 0 | W13: 0 | X13: 0 | Y13: 0 | Z13: 0 | AA13: 0 | AB13: 0 | AC13: 0 | AD13: 0 | AE13: 113.31 | AF13: 0 | AG13: 0 | AH13: 0 | AI13: 0 | AJ13: 0 | AK13: 0 | AL13: 0 | AM13: 0.15 | AN13: 0 | AO13: 0 | AP13: 0 | AQ13: 0 | AR13: 1.2307587 | AS13: 4.74 | AT13: 0 | AU13: 0 | AV13: 0.21 | AW13: -
... A41: BASE | B41: Stock | C41: TRA_Mot_Gas | D41: - | E41: - | F41: - | G41: 2010 | H41: - | I41: - | J41: - | K41: - | L41: 47.984096 | M41: 360.97546 | N41: 43.4917 | O41: 396.169 | P41: 70.387 | Q41: 587.33496 | R41: 29.385 | S41: 446.107 | T41: 2685.7305 | U41: 148.766 | V41: 7.4059039 | W41: 1499.133 | X41: 2703.754 | Y41: 225.504 | Z41: 1994.518 | AA41: 107.502 | AB41: 139.084 | AC41: 35.286 | AD41: 11.112 | AE41: 6570.977 | AF41: 11.830979 | AG41: 26.849794 | AH41: 15.753 | AI41: 8.61 | AJ41: 23.492939 | AK41: 7.761 | AL41: 15.391 | AM41: 681.843 | AN41: 129.62848 | AO41: 1013.014 | AP41: 216.004 | AQ41: 89.933 | AR41: 78.723476 | AS41: 303.14279 | AT41: 43.68 | AU41: 59.6 | AV41: 1234.4 | AW41: -
A42: TRA_FleetUpdates | B42: Stock | C42: TRA_Car_Cng_Exe | D42: - | E42: - | F42: - | G42: 2015 | H42: - | I42: - | J42: - | K42: - | L42: 0 | M42: 0.75883037 | N42: 0.33519459 | O42: 2.493399 | P42: 1.3762205 | Q42: 3.6281743 | R42: 0 | S42: 0 | T42: 12.686403 | U42: 0.0052104918 | V42: 0.097038129 | W42: 0 | X42: 0.057890255 | Y42: 0.30201489 | Z42: 18.002819 | AA42: 3.9910484 | AB42: 1.6681466 | AC42: 0 | AD42: 0 | AE42: 77.125231 | AG42: 0.0073359785 | AH42: 0.036029185 | AI42: 0 | AL42: 0.032586062 | AM42: 1.3058766 | AN42: 0.04537558 | AO42: 0 | AP42: 0.015651442 | AQ42: 0.058995628 | AR42: 0 | AS42: 17.554002 | AT42: 0.012116905 | AU42: 0.12587184 | AW42: -
A43: TRA_FleetUpdates | B43: Stock | C43: TRA_Car_Cng_Exe | D43: - | E43: - | F43: - | G43: 2020 | H43: - | I43: - | J43: - | K43: - | L43: 0 | M43: 0.90430021 | N43: 3.3280542 | O43: 3.9941104 | P43: 4.3294112 | Q43: 3.7769082 | R43: 0 | S43: 1.5523147 | T43: 13.172768 | U43: 0.012127869 | V43: 0.52268841 | W43: 0 | X43: 13.919116 | Y43: 2.4300264 | Z43: 16.052251 | AA43: 4.4295082 | AB43: 1.9120481 | AC43: 0 | AD43: 0.047526194 | AE43: 85.477241 | AG43: 0.013320593 | AH43: 0.099580663 | AI43: 0.0788778 | AL43: 0.074277733 | AM43: 1.6496297 | AN43: 0.075323463 | AO43: 0 | AP43: 0.052810995 | AQ43: 1.8315283 | AR43: 19.488274 | AS43: 16.888504 | AT43: 0.026964379 | AU43: 0.19299254 | AW43: -
A44: TRA_FleetUpdates | B44: Stock | C44: TRA_Car_Cng_Exe | D44: - | E44: - | F44: - | G44: 2025 | H44: - | I44: - | J44: - | K44: - | L44: 0 | M44: 0.76285876 | N44: 3.0757257 | O44: 4.6111897 | P44: 3.6591111 | Q44: 3.2822514 | R44: 0 | S44: 1.7903836 | T44: 12.277426 | U44: 0.008175082 | V44: 0.66330502 | W44: 0 | X44: 23.376027 | Y44: 3.3159618 | Z44: 30.338216 | AA44: 4.32044 | AB44: 1.9124277 | AC44: 0.015863157 | AD44: 0 | AE44: 83.003128 | AG44: 0.022780144 | AH44: 0.10508512 | AI44: 0.099804563 | AL44: 0.088282806 | AM44: 1.3247795 | AN44: 0.053845688 | AO44: 0 | AP44: 0.1086513 | AQ44: 5.6713367 | AR44: 16.718144 | AS44: 15.029061 | AT44: 0.037801329 | AU44: 0.2610979 | AW44: -
A45: TRA_FleetUpdates | B45: Stock | C45: TRA_Car_Cng_Lom | D45: - | E45: - | F45: - | G45: 2015 | H45: - | I45: - | J45: - | K45: - | L45: 0 | M45: 1.4709954 | N45: 1.0009974 | O45: 5.9112972 | P45: 3.5097122 | Q45: 4.3188195 | R45: 0 | S45: 0 | T45: 24.093788 | U45: 0.020972479 | V45: 0.13840262 | W45: 0 | X45: 0.14601497 | Y45: 0.59242089 | Z45: 49.749104 | AA45: 13.408092 | AB45: 5.5782754 | AC45: 0 | AD45: 0 | AE45: 193.76189 | AG45: 0.011068066 | AH45: 0.041680821 | AI45: 0 | AL45: 0.13106838 | AM45: 2.0381269 | AN45: 0.0398815 | AO45: 0 | AP45: 0.030776013 | AQ45: 0.15931326 | AR45: 0 | AS45: 11.546724 | AT45: 0.038284014 | AU45: 0.35074696 | AW45: -
A46: TRA_FleetUpdates | B46: Stock | C46: TRA_Car_Cng_Lom | D46: - | E46: - | F46: - | G46: 2020 | H46: - | I46: - | J46: - | K46: - | L46: 0 | M46: 1.7529892 | N46: 9.9386257 | O46: 9.4691519 | P46: 11.0411 | Q46: 4.4958658 | R46: 0 | S46: 4.6385097 | T46: 25.017484 | U46: 0.048815253 | V46: 0.74549505 | W46: 0 | X46: 35.107795 | Y46: 4.7666472 | Z46: 44.358891 | AA46: 14.881116 | AB46: 6.3938808 | AC46: 0 | AD46: 0.077718484 | AE46: 214.74467 | AG46: 0.020097278 | AH46: 0.11520116 | AI46: 0.1070386 | AL46: 0.29876155 | AM46: 2.5746343 | AN46: 0.06620329 | AO46: 0 | AP46: 0.10384422 | AQ46: 4.9459046 | AR46: 59.518097 | AS46: 11.10897 | AT46: 0.085195411 | AU46: 0.53778152 | AW46: -
A47: TRA_FleetUpdates | B47: Stock | C47: TRA_Car_Cng_Lom | D47: - | E47: - | F47: - | G47: 2025 | H47: - | I47: - | J47: - | K47: - | L47: 0 | M47: 1.4788045 | N47: 9.1850926 | O47: 10.932111 | P47: 9.331664 | Q47: 3.907048 | R47: 0 | S47: 5.3498891 | T47: 23.317065 | U47: 0.032905097 | V47: 0.94605237 | W47: 0 | X47: 58.960697 | Y47: 6.5044643 | Z47: 83.836816 | AA47: 14.514697 | AB47: 6.3951502 | AC47: 0.056738233 | AD47: 0 | AE47: 208.52895 | AG47: 0.034369257 | AH47: 0.12156906 | AI47: 0.13543659 | AL47: 0.35509307 | AM47: 2.0676294 | AN47: 0.047326047 | AO47: 0 | AP47: 0.2136451 | AQ47: 15.315019 | AR47: 51.057991 | AS47: 9.8858601 | AT47: 0.11943534 | AU47: 0.72755986 | AW47: -
A48: TRA_FleetUpdates | B48: Stock | C48: TRA_Car_Cng_Sma | D48: - | E48: - | F48: - | G48: 2015 | H48: - | I48: - | J48: - | K48: - | L48: 0 | M48: 2.1966212 | N48: 1.9889716 | O48: 9.2248193 | P48: 6.4833707 | Q48: 4.1185674 | R48: 0 | S48: 0 | T48: 32.4168 | U48: 0.022413388 | V48: 0.085508025 | W48: 0 | X48: 0.13299793 | Y48: 0.4469413 | Z48: 82.367962 | AA48: 31.330682 | AB48: 16.618408 | AC48: 0 | AD48: 0 | AE48: 525.42544 | AG48: 0.014633356 | AH48: 0.047194569 | AI48: 0 | AL48: 0.48257478 | AM48: 3.2028819 | AN48: 0.042525203 | AO48: 0 | AP48: 0.094773491 | AQ48: 0.46326022 | AR48: 0 | AS48: 8.3792123 | AT48: 0.07443325 | AU48: 0.90010965 | AW48: -
A49: TRA_FleetUpdates | B49: Stock | C49: TRA_Car_Cng_Sma | D49: - | E49: - | F49: - | G49: 2020 | H49: - | I49: - | J49: - | K49: - | L49: 0 | M49: 2.6177194 | N49: 19.747948 | O49: 14.776996 | P49: 20.395844 | Q49: 4.2874045 | R49: 0 | S49: 11.662415 | T49: 33.659579 | U49: 0.052169092 | V49: 0.46058239 | W49: 0 | X49: 31.977982 | Y49: 3.5961114 | Z49: 73.443564 | AA49: 34.772696 | AB49: 19.048202 | AC49: 0 | AD49: 0.045838323 | AE49: 582.32457 | AG49: 0.026571094 | AH49: 0.13044054 | AI49: 0.060082762 | AL49: 1.0999967 | AM49: 4.045994 | AN49: 0.070591837 | AO49: 0 | AP49: 0.3197841 | AQ49: 14.381984 | AR49: 115.88299 | AS49: 8.061544 | AT49: 0.16564019 | AU49: 1.3800899 | AW49: -
A50: TRA_FleetUpdates | B50: Stock | C50: TRA_Car_Cng_Sma | D50: - | E50: - | F50: - | G50: 2025 | H50: - | I50: - | J50: - | K50: - | L50: 0 | M50: 2.2082824 | N50: 18.250685 | O50: 17.060002 | P50: 17.238062 | Q50: 3.7258887 | R50: 0 | S50: 13.451007 | T50: 31.371763 | U50: 0.035165832 | V50: 0.58449089 | W50: 0 | X50: 53.704429 | Y50: 4.9071763 | Z50: 138.80587 | AA50: 33.916485 | AB50: 19.051984 | AC50: 0.040056642 | AD50: 0 | AE50: 565.46936 | AG50: 0.045440422 | AH50: 0.13765082 | AI50: 0.076023087 | AL50: 1.3074012 | AM50: 3.2492444 | AN50: 0.050463241 | AO50: 0 | AP50: 0.65791146 | AQ50: 44.533888 | AR50: 99.410981 | AS50: 7.1739589 | AT50: 0.23221077 | AU50: 1.8671114 | AW50: -
A51: TRA_FleetUpdates | B51: Stock | C51: TRA_Car_Cng_Upm | D51: - | E51: - | F51: - | G51: 2015 | H51: - | I51: - | J51: - | K51: - | L51: 0 | M51: 0.65955304 | N51: 0.44883642 | O51: 2.6504845 | P51: 1.5736966 | Q51: 1.9364388 | R51: 0 | S51: 0 | T51: 10.803008 | U51: 0.0094036415 | V51: 0.062051226 | W51: 0 | X51: 0.061096851 | Y51: 0.26562292 | Z51: 22.306115 | AA51: 6.0121772 | AB51: 2.5011703 | AC51: 0 | AD51: 0 | AE51: 86.877433 | AG51: 0.0049625993 | AH51: 0.019095426 | AI51: 0 | AL51: 0.058770773 | AM51: 0.91411459 | AN51: 0.022217717 | AO51: 0 | AP51: 0.013799053 | AQ51: 0.071430891 | AR51: 0 | AS51: 5.1720618 | AT51: 0.017165831 | AU51: 0.15727156 | AW51: -
A52: TRA_FleetUpdates | B52: Stock | C52: TRA_Car_Cng_Upm | D52: - | E52: - | F52: - | G52: 2020 | H52: - | I52: - | J52: - | K52: - | L52: 0 | M52: 0.78599115 | N52: 4.4563724 | O52: 4.2457416 | P52: 4.9506456 | Q52: 2.0158215 | R52: 0 | S52: 2.0797603 | T52: 11.217168 | U52: 0.021887786 | V52: 0.33423415 | W52: 0 | X52: 14.690108 | Y52: 2.1372149 | Z52: 19.889294 | AA52: 6.6726798 | AB52: 2.866869 | AC52: 0 | AD52: 0.034917 | AE52: 96.285524 | AG52: 0.0090110356 | AH52: 0.052777634 | AI52: 0.048000839 | AL52: 0.13396402 | AM52: 1.154742 | AN52: 0.03688141 | AO52: 0 | AP52: 0.046560677 | AQ52: 2.2175829 | AR52: 26.689642 | AS52: 4.9759814 | AT52: 0.038200019 | AU52: 0.24113605 | AW52: -
A53: TRA_FleetUpdates | B53: Stock | C53: TRA_Car_Cng_Upm | D53: - | E53: - | F53: - | G53: 2025 | H53: - | I53: - | J53: - | K53: - | L53: 0 | M53: 0.6630544 | N53: 4.1184963 | O53: 4.9016973 | P53: 4.184163 | Q53: 1.7518119 | R53: 0 | S53: 2.3987201 | T53: 10.454746 | U53: 0.014753989 | V53: 0.42415172 | W53: 0 | X53: 24.670847 | Y53: 2.9163975 | Z53: 37.590098 | AA53: 6.5083778 | AB53: 2.8674381 | AC53: 0.027341969 | AD53: 0 | AE53: 93.498568 | AG53: 0.015410177 | AH53: 0.055694991 | AI53: 0.060735756 | AL53: 0.15922295 | AM53: 0.92734665 | AN53: 0.026365024 | AO53: 0 | AP53: 0.095792138 | AQ53: 6.8667569 | AR53: 22.895884 | AS53: 4.4281202 | AT53: 0.053552559 | AU53: 0.32623083 | AW53: -
... A89: TRA_FleetUpdates | B89: Stock | C89: TRA_Car_Lpg_Upm | D89: - | E89: - | F89: - | G89: 2025 | H89: - | I89: - | J89: - | K89: - | L89: 0.058840246 | M89: 0.00012968011 | N89: 0.0013082143 | O89: 0.003659446 | P89: 45.556834 | Q89: 0.014521217 | R89: 0 | S89: 12.301501 | T89: 42.364401 | U89: 0.001297054 | V89: 0.011178942 | W89: 0 | X89: 2.8204333 | Y89: 0.00016529118 | Z89: 0.017593818 | AA89: 0.0058208577 | AB89: 0.0035099484 | AC89: 0 | AD89: 0 | AE89: 298.32939 | AG89: 0.012537093 | AH89: 0 | AI89: 3.4694484 | AL89: 0.00041681399 | AM89: 11.422083 | AN89: 0.00014811811 | AO89: 0 | AP89: 6.7219195 | AQ89: 0.0023715435 | AR89: 0.0034931091 | AS89: 0.024616162 | AT89: 1.0888214 | AU89: 4.8611674 | AW89: -

Sheet TypeShares
A1: mode | B1: type | C1: fuel
D2: TYPE Shares
E3: =Stock!L1 -> AL | F3: =Stock!M1 -> AT | G3: =Stock!N1 -> BA | H3: =Stock!O1 -> BE | I3: =Stock!P1 -> BG | J3: =Stock!Q1 -> CH | K3: =Stock!R1 -> CY | L3: =Stock!S1 -> CZ | ... AO3: =Stock!AV1 -> UK
A4: =LEFT(Stock!C2,7)&"*" -> TRA_Bus* | B4: ="*"&RIGHT(Stock!C2,3)&"*" -> *Coa* | C4: ="*"&MID(Stock!C2,9,3) -> *Cng | E4: =SUMIF(Stock!$C$2:$C$41,TypeShares!$B4,Stock!L$2:L$41)/SUMIF(Stock!$C$2:$C$41,TypeShares!$A4,Stock!L$2:L$41) -> 0.61882094 | F4: =SUMIF(Stock!$C$2:$C$41,TypeShares!$B4,Stock!M$2:M$41)/SUMIF(Stock!$C$2:$C$41,TypeShares!$A4,Stock!M$2:M$41) -> 0.77306469 | G4: =SUMIF(Stock!$C$2:$C$41,TypeShares!$B4,Stock!N$2:N$41)/SUMIF(Stock!$C$2:$C$41,TypeShares!$A4,Stock!N$2:N$41) -> 0.77938144 | H4: =SUMIF(Stock!$C$2:$C$41,TypeShares!$B4,Stock!O$2:O$41)/SUMIF(Stock!$C$2:$C$41,TypeShares!$A4,Stock!O$2:O$41) -> 0.59198999 | I4: =SUMIF(Stock!$C$2:$C$41,TypeShares!$B4,Stock!P$2:P$41)/SUMIF(Stock!$C$2:$C$41,TypeShares!$A4,Stock!P$2:P$41) -> 0.49014675 | J4: =SUMIF(Stock!$C$2:$C$41,TypeShares!$B4,Stock!Q$2:Q$41)/SUMIF(Stock!$C$2:$C$41,TypeShares!$A4,Stock!Q$2:Q$41) -> 0.33514247 | K4: =SUMIF(Stock!$C$2:$C$41,TypeShares!$B4,Stock!R$2:R$41)/SUMIF(Stock!$C$2:$C$41,TypeShares!$A4,Stock!R$2:R$41) -> 0.42909091 | L4: =SUMIF(Stock!$C$2:$C$41,TypeShares!$B4,Stock!S$2:S$41)/SUMIF(Stock!$C$2:$C$41,TypeShares!$A4,Stock!S$2:S$41) -> 0.71246819 | ... AO4: =SUMIF(Stock!$C$2:$C$41,TypeShares!$B4,Stock!AV$2:AV$41)/SUMIF(Stock!$C$2:$C$41,TypeShares!$A4,Stock!AV$2:AV$41) -> 0.71246567
A5: =LEFT(Stock!C3,7)&"*" -> TRA_Bus* | B5: ="*"&RIGHT(Stock!C3,3)&"*" -> *Urb* | C5: ="*"&MID(Stock!C3,9,3) -> *Cng | E5: =SUMIF(Stock!$C$2:$C$41,TypeShares!$B5,Stock!L$2:L$41)/SUMIF(Stock!$C$2:$C$41,TypeShares!$A5,Stock!L$2:L$41) -> 0.38117906 | F5: =SUMIF(Stock!$C$2:$C$41,TypeShares!$B5,Stock!M$2:M$41)/SUMIF(Stock!$C$2:$C$41,TypeShares!$A5,Stock!M$2:M$41) -> 0.22693531 | G5: =SUMIF(Stock!$C$2:$C$41,TypeShares!$B5,Stock!N$2:N$41)/SUMIF(Stock!$C$2:$C$41,TypeShares!$A5,Stock!N$2:N$41) -> 0.22061856 | H5: =SUMIF(Stock!$C$2:$C$41,TypeShares!$B5,Stock!O$2:O$41)/SUMIF(Stock!$C$2:$C$41,TypeShares!$A5,Stock!O$2:O$41) -> 0.40801001 | I5: =SUMIF(Stock!$C$2:$C$41,TypeShares!$B5,Stock!P$2:P$41)/SUMIF(Stock!$C$2:$C$41,TypeShares!$A5,Stock!P$2:P$41) -> 0.50985325 | J5: =SUMIF(Stock!$C$2:$C$41,TypeShares!$B5,Stock!Q$2:Q$41)/SUMIF(Stock!$C$2:$C$41,TypeShares!$A5,Stock!Q$2:Q$41) -> 0.66485753 | K5: =SUMIF(Stock!$C$2:$C$41,TypeShares!$B5,Stock!R$2:R$41)/SUMIF(Stock!$C$2:$C$41,TypeShares!$A5,Stock!R$2:R$41) -> 0.57090909 | L5: =SUMIF(Stock!$C$2:$C$41,TypeShares!$B5,Stock!S$2:S$41)/SUMIF(Stock!$C$2:$C$41,TypeShares!$A5,Stock!S$2:S$41) -> 0.28753181 | ... AO5: =SUMIF(Stock!$C$2:$C$41,TypeShares!$B5,Stock!AV$2:AV$41)/SUMIF(Stock!$C$2:$C$41,TypeShares!$A5,Stock!AV$2:AV$41) -> 0.28753433
A6: =LEFT(Stock!C4,7)&"*" -> TRA_Bus* | B6: ="*"&RIGHT(Stock!C4,3)&"*" -> *Coa* | C6: ="*"&MID(Stock!C4,9,3) -> *Dis
A7: =LEFT(Stock!C5,7)&"*" -> TRA_Bus* | B7: ="*"&RIGHT(Stock!C5,3)&"*" -> *Urb* | C7: ="*"&MID(Stock!C5,9,3) -> *Dis
A8: =LEFT(Stock!C6,7)&"*" -> TRA_Bus* | B8: ="*"&RIGHT(Stock!C6,3)&"*" -> *Coa* | C8: ="*"&MID(Stock!C6,9,3) -> *Gas
A9: =LEFT(Stock!C7,7)&"*" -> TRA_Bus* | B9: ="*"&RIGHT(Stock!C7,3)&"*" -> *Urb* | C9: ="*"&MID(Stock!C7,9,3) -> *Gas
A10: =LEFT(Stock!C8,7)&"*" -> TRA_Bus* | B10: ="*"&RIGHT(Stock!C8,3)&"*" -> *Coa* | C10: ="*"&MID(Stock!C8,9,3) -> *Lpg
A11: =LEFT(Stock!C9,7)&"*" -> TRA_Bus* | B11: ="*"&RIGHT(Stock!C9,3)&"*" -> *Urb* | C11: ="*"&MID(Stock!C9,9,3) -> *Lpg
A12: =LEFT(Stock!C10,7)&"*" -> TRA_Car* | B12: ="*"&RIGHT(Stock!C10,3)&"*" -> *Exe* | C12: ="*"&MID(Stock!C10,9,3) -> *Cng | E12: =SUMIF(Stock!$C$2:$C$41,TypeShares!$B12,Stock!L$2:L$41)/SUMIF(Stock!$C$2:$C$41,TypeShares!$A12,Stock!L$2:L$41) -> 0.087336159 | F12: =SUMIF(Stock!$C$2:$C$41,TypeShares!$B12,Stock!M$2:M$41)/SUMIF(Stock!$C$2:$C$41,TypeShares!$A12,Stock!M$2:M$41) -> 0.1507069 | G12: =SUMIF(Stock!$C$2:$C$41,TypeShares!$B12,Stock!N$2:N$41)/SUMIF(Stock!$C$2:$C$41,TypeShares!$A12,Stock!N$2:N$41) -> 0.089713936 | H12: =SUMIF(Stock!$C$2:$C$41,TypeShares!$B12,Stock!O$2:O$41)/SUMIF(Stock!$C$2:$C$41,TypeShares!$A12,Stock!O$2:O$41) -> 0.12419057 | I12: =SUMIF(Stock!$C$2:$C$41,TypeShares!$B12,Stock!P$2:P$41)/SUMIF(Stock!$C$2:$C$41,TypeShares!$A12,Stock!P$2:P$41) -> 0.10740336 | J12: =SUMIF(Stock!$C$2:$C$41,TypeShares!$B12,Stock!Q$2:Q$41)/SUMIF(Stock!$C$2:$C$41,TypeShares!$A12,Stock!Q$2:Q$41) -> 0.26173565 | K12: =SUMIF(Stock!$C$2:$C$41,TypeShares!$B12,Stock!R$2:R$41)/SUMIF(Stock!$C$2:$C$41,TypeShares!$A12,Stock!R$2:R$41) -> 0.10840828 | L12: =SUMIF(Stock!$C$2:$C$41,TypeShares!$B12,Stock!S$2:S$41)/SUMIF(Stock!$C$2:$C$41,TypeShares!$A12,Stock!S$2:S$41) -> 0.078663256 | ... AO12: =SUMIF(Stock!$C$2:$C$41,TypeShares!$B12,Stock!AV$2:AV$41)/SUMIF(Stock!$C$2:$C$41,TypeShares!$A12,Stock!AV$2:AV$41) -> 0.14481674
A13: =LEFT(Stock!C11,7)&"*" -> TRA_Car* | B13: ="*"&RIGHT(Stock!C11,3)&"*" -> *Lom* | C13: ="*"&MID(Stock!C11,9,3) -> *Cng | E13: =SUMIF(Stock!$C$2:$C$41,TypeShares!$B13,Stock!L$2:L$41)/SUMIF(Stock!$C$2:$C$41,TypeShares!$A13,Stock!L$2:L$41) -> 0.26488084 | F13: =SUMIF(Stock!$C$2:$C$41,TypeShares!$B13,Stock!M$2:M$41)/SUMIF(Stock!$C$2:$C$41,TypeShares!$A13,Stock!M$2:M$41) -> 0.29214588 | G13: =SUMIF(Stock!$C$2:$C$41,TypeShares!$B13,Stock!N$2:N$41)/SUMIF(Stock!$C$2:$C$41,TypeShares!$A13,Stock!N$2:N$41) -> 0.26791428 | H13: =SUMIF(Stock!$C$2:$C$41,TypeShares!$B13,Stock!O$2:O$41)/SUMIF(Stock!$C$2:$C$41,TypeShares!$A13,Stock!O$2:O$41) -> 0.29442837 | I13: =SUMIF(Stock!$C$2:$C$41,TypeShares!$B13,Stock!P$2:P$41)/SUMIF(Stock!$C$2:$C$41,TypeShares!$A13,Stock!P$2:P$41) -> 0.27390588 | J13: =SUMIF(Stock!$C$2:$C$41,TypeShares!$B13,Stock!Q$2:Q$41)/SUMIF(Stock!$C$2:$C$41,TypeShares!$A13,Stock!Q$2:Q$41) -> 0.31155863 | K13: =SUMIF(Stock!$C$2:$C$41,TypeShares!$B13,Stock!R$2:R$41)/SUMIF(Stock!$C$2:$C$41,TypeShares!$A13,Stock!R$2:R$41) -> 0.35173794 | L13: =SUMIF(Stock!$C$2:$C$41,TypeShares!$B13,Stock!S$2:S$41)/SUMIF(Stock!$C$2:$C$41,TypeShares!$A13,Stock!S$2:S$41) -> 0.2350556 | ... AO13: =SUMIF(Stock!$C$2:$C$41,TypeShares!$B13,Stock!AV$2:AV$41)/SUMIF(Stock!$C$2:$C$41,TypeShares!$A13,Stock!AV$2:AV$41) -> 0.29740328
A14: =LEFT(Stock!C12,7)&"*" -> TRA_Car* | B14: ="*"&RIGHT(Stock!C12,3)&"*" -> *Sma* | C14: ="*"&MID(Stock!C12,9,3) -> *Cng | E14: =SUMIF(Stock!$C$2:$C$41,TypeShares!$B14,Stock!L$2:L$41)/SUMIF(Stock!$C$2:$C$41,TypeShares!$A14,Stock!L$2:L$41) -> 0.54221535 | F14: =SUMIF(Stock!$C$2:$C$41,TypeShares!$B14,Stock!M$2:M$41)/SUMIF(Stock!$C$2:$C$41,TypeShares!$A14,Stock!M$2:M$41) -> 0.4261572 | G14: =SUMIF(Stock!$C$2:$C$41,TypeShares!$B14,Stock!N$2:N$41)/SUMIF(Stock!$C$2:$C$41,TypeShares!$A14,Stock!N$2:N$41) -> 0.52224192 | H14: =SUMIF(Stock!$C$2:$C$41,TypeShares!$B14,Stock!O$2:O$41)/SUMIF(Stock!$C$2:$C$41,TypeShares!$A14,Stock!O$2:O$41) -> 0.44936641 | I14: =SUMIF(Stock!$C$2:$C$41,TypeShares!$B14,Stock!P$2:P$41)/SUMIF(Stock!$C$2:$C$41,TypeShares!$A14,Stock!P$2:P$41) -> 0.49587591 | J14: =SUMIF(Stock!$C$2:$C$41,TypeShares!$B14,Stock!Q$2:Q$41)/SUMIF(Stock!$C$2:$C$41,TypeShares!$A14,Stock!Q$2:Q$41) -> 0.28701148 | K14: =SUMIF(Stock!$C$2:$C$41,TypeShares!$B14,Stock!R$2:R$41)/SUMIF(Stock!$C$2:$C$41,TypeShares!$A14,Stock!R$2:R$41) -> 0.38214012 | L14: =SUMIF(Stock!$C$2:$C$41,TypeShares!$B14,Stock!S$2:S$41)/SUMIF(Stock!$C$2:$C$41,TypeShares!$A14,Stock!S$2:S$41) -> 0.58088968 | ... AO14: =SUMIF(Stock!$C$2:$C$41,TypeShares!$B14,Stock!AV$2:AV$41)/SUMIF(Stock!$C$2:$C$41,TypeShares!$A14,Stock!AV$2:AV$41) -> 0.42443268
A15: =LEFT(Stock!C13,7)&"*" -> TRA_Car* | B15: ="*"&RIGHT(Stock!C13,3)&"*" -> *Upm* | C15: ="*"&MID(Stock!C13,9,3) -> *Cng | E15: =SUMIF(Stock!$C$2:$C$41,TypeShares!$B15,Stock!L$2:L$41)/SUMIF(Stock!$C$2:$C$41,TypeShares!$A15,Stock!L$2:L$41) -> 0.10556766 | F15: =SUMIF(Stock!$C$2:$C$41,TypeShares!$B15,Stock!M$2:M$41)/SUMIF(Stock!$C$2:$C$41,TypeShares!$A15,Stock!M$2:M$41) -> 0.13099001 | G15: =SUMIF(Stock!$C$2:$C$41,TypeShares!$B15,Stock!N$2:N$41)/SUMIF(Stock!$C$2:$C$41,TypeShares!$A15,Stock!N$2:N$41) -> 0.12012987 | H15: =SUMIF(Stock!$C$2:$C$41,TypeShares!$B15,Stock!O$2:O$41)/SUMIF(Stock!$C$2:$C$41,TypeShares!$A15,Stock!O$2:O$41) -> 0.13201465 | I15: =SUMIF(Stock!$C$2:$C$41,TypeShares!$B15,Stock!P$2:P$41)/SUMIF(Stock!$C$2:$C$41,TypeShares!$A15,Stock!P$2:P$41) -> 0.12281485 | J15: =SUMIF(Stock!$C$2:$C$41,TypeShares!$B15,Stock!Q$2:Q$41)/SUMIF(Stock!$C$2:$C$41,TypeShares!$A15,Stock!Q$2:Q$41) -> 0.13969425 | K15: =SUMIF(Stock!$C$2:$C$41,TypeShares!$B15,Stock!R$2:R$41)/SUMIF(Stock!$C$2:$C$41,TypeShares!$A15,Stock!R$2:R$41) -> 0.15771367 | L15: =SUMIF(Stock!$C$2:$C$41,TypeShares!$B15,Stock!S$2:S$41)/SUMIF(Stock!$C$2:$C$41,TypeShares!$A15,Stock!S$2:S$41) -> 0.10539146 | ... AO15: =SUMIF(Stock!$C$2:$C$41,TypeShares!$B15,Stock!AV$2:AV$41)/SUMIF(Stock!$C$2:$C$41,TypeShares!$A15,Stock!AV$2:AV$41) -> 0.13334731
A16: =LEFT(Stock!C14,7)&"*" -> TRA_Car* | B16: ="*"&RIGHT(Stock!C14,3)&"*" -> *Exe* | C16: ="*"&MID(Stock!C14,9,3) -> *Dis
A17: =LEFT(Stock!C15,7)&"*" -> TRA_Car* | B17: ="*"&RIGHT(Stock!C15,3)&"*" -> *Lom* | C17: ="*"&MID(Stock!C15,9,3) -> *Dis
A18: =LEFT(Stock!C16,7)&"*" -> TRA_Car* | B18: ="*"&RIGHT(Stock!C16,3)&"*" -> *Sma* | C18: ="*"&MID(Stock!C16,9,3) -> *Dis
A19: =LEFT(Stock!C17,7)&"*" -> TRA_Car* | B19: ="*"&RIGHT(Stock!C17,3)&"*" -> *Upm* | C19: ="*"&MID(Stock!C17,9,3) -> *Dis
A20: =LEFT(Stock!C18,7)&"*" -> TRA_Car* | B20: ="*"&RIGHT(Stock!C18,3)&"*" -> *Exe* | C20: ="*"&MID(Stock!C18,9,3) -> *Fle
A21: =LEFT(Stock!C19,7)&"*" -> TRA_Car* | B21: ="*"&RIGHT(Stock!C19,3)&"*" -> *Lom* | C21: ="*"&MID(Stock!C19,9,3) -> *Fle
A22: =LEFT(Stock!C20,7)&"*" -> TRA_Car* | B22: ="*"&RIGHT(Stock!C20,3)&"*" -> *Sma* | C22: ="*"&MID(Stock!C20,9,3) -> *Fle
A23: =LEFT(Stock!C21,7)&"*" -> TRA_Car* | B23: ="*"&RIGHT(Stock!C21,3)&"*" -> *Upm* | C23: ="*"&MID(Stock!C21,9,3) -> *Fle
A24: =LEFT(Stock!C22,7)&"*" -> TRA_Car* | B24: ="*"&RIGHT(Stock!C22,3)&"*" -> *Exe* | C24: ="*"&MID(Stock!C22,9,3) -> *Gas
A25: =LEFT(Stock!C23,7)&"*" -> TRA_Car* | B25: ="*"&RIGHT(Stock!C23,3)&"*" -> *Lom* | C25: ="*"&MID(Stock!C23,9,3) -> *Gas
A26: =LEFT(Stock!C24,7)&"*" -> TRA_Car* | B26: ="*"&RIGHT(Stock!C24,3)&"*" -> *Sma* | C26: ="*"&MID(Stock!C24,9,3) -> *Gas
A27: =LEFT(Stock!C25,7)&"*" -> TRA_Car* | B27: ="*"&RIGHT(Stock!C25,3)&"*" -> *Upm* | C27: ="*"&MID(Stock!C25,9,3) -> *Gas
... A41: =LEFT(Stock!C39,7)&"*" -> TRA_Lcv* | B41: ="*"&RIGHT(Stock!C39,3)&"*" -> *Lpg* | C41: ="*"&MID(Stock!C39,9,3) -> *Lpg

Sheet TypeUC
H1: 0.99
B2: ~UC_Sets: R_E: AllRegions
F3: ~UC_T: UC_COMPRD~LO~2011
C4: UC_N | D4: PSET_PN | E4: PSET_CO | F4: CSET_CN | G4: UC_FLO | H4: =TypeShares!E$3 -> AL | I4: =TypeShares!F$3 -> AT | J4: =TypeShares!G$3 -> BA | K4: =TypeShares!H$3 -> BE | L4: =TypeShares!I$3 -> BG | M4: =TypeShares!J$3 -> CH | N4: =TypeShares!K$3 -> CY | O4: =TypeShares!L$3 -> CZ | ... AR4: =TypeShares!AO$3 -> UK | AS4: UC_RHSRT | AT4: UC_RHSRT~0
C5: ="TUC_"&LEFT(Stock!C10,8)&RIGHT(Stock!C10,3) -> TUC_TRA_Car_Exe | D5: =TypeShares!B12 -> *Exe* | E5: Tcar | F5: =E5 -> Tcar | G5: 1 | H5: =-TypeShares!E12*TypeUC!$H$1 -> -0.086462797 | I5: =-TypeShares!F12*TypeUC!$H$1 -> -0.14919984 | J5: =-TypeShares!G12*TypeUC!$H$1 -> -0.088816796 | K5: =-TypeShares!H12*TypeUC!$H$1 -> -0.12294867 | L5: =-TypeShares!I12*TypeUC!$H$1 -> -0.10632933 | M5: =-TypeShares!J12*TypeUC!$H$1 -> -0.25911829 | N5: =-TypeShares!K12*TypeUC!$H$1 -> -0.1073242 | O5: =-TypeShares!L12*TypeUC!$H$1 -> -0.077876624 | ... AR5: =-TypeShares!AO12*TypeUC!$H$1 -> -0.14336857 | AS5: 0 | AT5: 5
C6: ="TUC_"&LEFT(Stock!C11,8)&RIGHT(Stock!C11,3) -> TUC_TRA_Car_Lom | D6: =TypeShares!B13 -> *Lom* | E6: Tcar | F6: =E6 -> Tcar | G6: 1 | H6: =-TypeShares!E13*TypeUC!$H$1 -> -0.26223203 | I6: =-TypeShares!F13*TypeUC!$H$1 -> -0.28922442 | J6: =-TypeShares!G13*TypeUC!$H$1 -> -0.26523513 | K6: =-TypeShares!H13*TypeUC!$H$1 -> -0.29148408 | L6: =-TypeShares!I13*TypeUC!$H$1 -> -0.27116683 | M6: =-TypeShares!J13*TypeUC!$H$1 -> -0.30844304 | N6: =-TypeShares!K13*TypeUC!$H$1 -> -0.34822056 | O6: =-TypeShares!L13*TypeUC!$H$1 -> -0.23270505 | ... AR6: =-TypeShares!AO13*TypeUC!$H$1 -> -0.29442924 | AS6: 0 | AT6: 5
C7: ="TUC_"&LEFT(Stock!C12,8)&RIGHT(Stock!C12,3) -> TUC_TRA_Car_Sma | D7: =TypeShares!B14 -> *Sma* | E7: Tcar | F7: =E7 -> Tcar | G7: 1 | H7: =-TypeShares!E14*TypeUC!$H$1 -> -0.53679319 | I7: =-TypeShares!F14*TypeUC!$H$1 -> -0.42189563 | J7: =-TypeShares!G14*TypeUC!$H$1 -> -0.5170195 | K7: =-TypeShares!H14*TypeUC!$H$1 -> -0.44487275 | L7: =-TypeShares!I14*TypeUC!$H$1 -> -0.49091715 | M7: =-TypeShares!J14*TypeUC!$H$1 -> -0.28414137 | N7: =-TypeShares!K14*TypeUC!$H$1 -> -0.37831872 | O7: =-TypeShares!L14*TypeUC!$H$1 -> -0.57508078 | ... AR7: =-TypeShares!AO14*TypeUC!$H$1 -> -0.42018835 | AS7: 0 | AT7: 5
C8: ="TUC_"&LEFT(Stock!C13,8)&RIGHT(Stock!C13,3) -> TUC_TRA_Car_Upm | D8: =TypeShares!B15 -> *Upm* | E8: Tcar | F8: =E8 -> Tcar | G8: 1 | H8: =-TypeShares!E15*TypeUC!$H$1 -> -0.10451198 | I8: =-TypeShares!F15*TypeUC!$H$1 -> -0.12968011 | J8: =-TypeShares!G15*TypeUC!$H$1 -> -0.11892857 | K8: =-TypeShares!H15*TypeUC!$H$1 -> -0.1306945 | L8: =-TypeShares!I15*TypeUC!$H$1 -> -0.1215867 | M8: =-TypeShares!J15*TypeUC!$H$1 -> -0.1382973 | N8: =-TypeShares!K15*TypeUC!$H$1 -> -0.15613653 | O8: =-TypeShares!L15*TypeUC!$H$1 -> -0.10433754 | ... AR8: =-TypeShares!AO15*TypeUC!$H$1 -> -0.13201384 | AS8: 0 | AT8: 5
H11: 0.99
F13: ~UC_T: UC_COMPRD~LO~2025
C14: UC_N | D14: PSET_PN | E14: PSET_CO | F14: CSET_CN | G14: UC_FLO | H14: =TypeShares!E$3 -> AL | I14: =TypeShares!F$3 -> AT | J14: =TypeShares!G$3 -> BA | K14: =TypeShares!H$3 -> BE | L14: =TypeShares!I$3 -> BG | M14: =TypeShares!J$3 -> CH | N14: =TypeShares!K$3 -> CY | O14: =TypeShares!L$3 -> CZ | ... AR14: =TypeShares!AO$3 -> UK
C15: =C5 -> TUC_TRA_Car_Exe | F15: =F5 -> Tcar | H15: =-TypeShares!E12*TypeUC!$H$11 -> -0.086462797 | I15: =-TypeShares!F12*TypeUC!$H$11 -> -0.14919984 | J15: =-TypeShares!G12*TypeUC!$H$11 -> -0.088816796 | K15: =-TypeShares!H12*TypeUC!$H$11 -> -0.12294867 | L15: =-TypeShares!I12*TypeUC!$H$11 -> -0.10632933 | M15: =-TypeShares!J12*TypeUC!$H$11 -> -0.25911829 | N15: =-TypeShares!K12*TypeUC!$H$11 -> -0.1073242 | O15: =-TypeShares!L12*TypeUC!$H$11 -> -0.077876624 | ... AR15: =-TypeShares!AO12*TypeUC!$H$11 -> -0.14336857
C16: =C6 -> TUC_TRA_Car_Lom | F16: =F6 -> Tcar | H16: =-TypeShares!E13*TypeUC!$H$11 -> -0.26223203 | I16: =-TypeShares!F13*TypeUC!$H$11 -> -0.28922442 | J16: =-TypeShares!G13*TypeUC!$H$11 -> -0.26523513 | K16: =-TypeShares!H13*TypeUC!$H$11 -> -0.29148408 | L16: =-TypeShares!I13*TypeUC!$H$11 -> -0.27116683 | M16: =-TypeShares!J13*TypeUC!$H$11 -> -0.30844304 | N16: =-TypeShares!K13*TypeUC!$H$11 -> -0.34822056 | O16: =-TypeShares!L13*TypeUC!$H$11 -> -0.23270505 | ... AR16: =-TypeShares!AO13*TypeUC!$H$11 -> -0.29442924
C17: =C7 -> TUC_TRA_Car_Sma | F17: =F7 -> Tcar | H17: =-TypeShares!E14*TypeUC!$H$11 -> -0.53679319 | I17: =-TypeShares!F14*TypeUC!$H$11 -> -0.42189563 | J17: =-TypeShares!G14*TypeUC!$H$11 -> -0.5170195 | K17: =-TypeShares!H14*TypeUC!$H$11 -> -0.44487275 | L17: =-TypeShares!I14*TypeUC!$H$11 -> -0.49091715 | M17: =-TypeShares!J14*TypeUC!$H$11 -> -0.28414137 | N17: =-TypeShares!K14*TypeUC!$H$11 -> -0.37831872 | O17: =-TypeShares!L14*TypeUC!$H$11 -> -0.57508078 | ... AR17: =-TypeShares!AO14*TypeUC!$H$11 -> -0.42018835
C18: =C8 -> TUC_TRA_Car_Upm | F18: =F8 -> Tcar | H18: =-TypeShares!E15*TypeUC!$H$11 -> -0.10451198 | I18: =-TypeShares!F15*TypeUC!$H$11 -> -0.12968011 | J18: =-TypeShares!G15*TypeUC!$H$11 -> -0.11892857 | K18: =-TypeShares!H15*TypeUC!$H$11 -> -0.1306945 | L18: =-TypeShares!I15*TypeUC!$H$11 -> -0.1215867 | M18: =-TypeShares!J15*TypeUC!$H$11 -> -0.1382973 | N18: =-TypeShares!K15*TypeUC!$H$11 -> -0.15613653 | O18: =-TypeShares!L15*TypeUC!$H$11 -> -0.10433754 | ... AR18: =-TypeShares!AO15*TypeUC!$H$11 -> -0.13201384
H21: 0.99
F23: ~UC_T: UC_COMPRD~LO~2050
C24: UC_N | D24: PSET_PN | E24: PSET_CO | F24: CSET_CN | G24: UC_FLO | H24: =TypeShares!E$3 -> AL | I24: =TypeShares!F$3 -> AT | J24: =TypeShares!G$3 -> BA | K24: =TypeShares!H$3 -> BE | L24: =TypeShares!I$3 -> BG | M24: =TypeShares!J$3 -> CH | N24: =TypeShares!K$3 -> CY | O24: =TypeShares!L$3 -> CZ | ... AR24: =TypeShares!AO$3 -> UK
C25: =C15 -> TUC_TRA_Car_Exe | F25: =F15 -> Tcar | H25: =-TypeShares!E12*TypeUC!$H$21 -> -0.086462797 | I25: =-TypeShares!F12*TypeUC!$H$21 -> -0.14919984 | J25: =-TypeShares!G12*TypeUC!$H$21 -> -0.088816796 | K25: =-TypeShares!H12*TypeUC!$H$21 -> -0.12294867 | L25: =-TypeShares!I12*TypeUC!$H$21 -> -0.10632933 | M25: =-TypeShares!J12*TypeUC!$H$21 -> -0.25911829 | N25: =-TypeShares!K12*TypeUC!$H$21 -> -0.1073242 | O25: =-TypeShares!L12*TypeUC!$H$21 -> -0.077876624 | ... AR25: =-TypeShares!AO12*TypeUC!$H$21 -> -0.14336857
C26: =C16 -> TUC_TRA_Car_Lom | F26: =F16 -> Tcar | H26: =-TypeShares!E13*TypeUC!$H$21 -> -0.26223203 | I26: =-TypeShares!F13*TypeUC!$H$21 -> -0.28922442 | J26: =-TypeShares!G13*TypeUC!$H$21 -> -0.26523513 | K26: =-TypeShares!H13*TypeUC!$H$21 -> -0.29148408 | L26: =-TypeShares!I13*TypeUC!$H$21 -> -0.27116683 | M26: =-TypeShares!J13*TypeUC!$H$21 -> -0.30844304 | N26: =-TypeShares!K13*TypeUC!$H$21 -> -0.34822056 | O26: =-TypeShares!L13*TypeUC!$H$21 -> -0.23270505 | ... AR26: =-TypeShares!AO13*TypeUC!$H$21 -> -0.29442924
C27: =C17 -> TUC_TRA_Car_Sma | F27: =F17 -> Tcar | H27: =-TypeShares!E14*TypeUC!$H$21 -> -0.53679319 | I27: =-TypeShares!F14*TypeUC!$H$21 -> -0.42189563 | J27: =-TypeShares!G14*TypeUC!$H$21 -> -0.5170195 | K27: =-TypeShares!H14*TypeUC!$H$21 -> -0.44487275 | L27: =-TypeShares!I14*TypeUC!$H$21 -> -0.49091715 | M27: =-TypeShares!J14*TypeUC!$H$21 -> -0.28414137 | N27: =-TypeShares!K14*TypeUC!$H$21 -> -0.37831872 | O27: =-TypeShares!L14*TypeUC!$H$21 -> -0.57508078 | ... AR27: =-TypeShares!AO14*TypeUC!$H$21 -> -0.42018835
C28: =C18 -> TUC_TRA_Car_Upm | F28: =F18 -> Tcar | H28: =-TypeShares!E15*TypeUC!$H$21 -> -0.10451198 | I28: =-TypeShares!F15*TypeUC!$H$21 -> -0.12968011 | J28: =-TypeShares!G15*TypeUC!$H$21 -> -0.11892857 | K28: =-TypeShares!H15*TypeUC!$H$21 -> -0.1306945 | L28: =-TypeShares!I15*TypeUC!$H$21 -> -0.1215867 | M28: =-TypeShares!J15*TypeUC!$H$21 -> -0.1382973 | N28: =-TypeShares!K15*TypeUC!$H$21 -> -0.15613653 | O28: =-TypeShares!L15*TypeUC!$H$21 -> -0.10433754 | ... AR28: =-TypeShares!AO15*TypeUC!$H$21 -> -0.13201384

Sheet FuelShares
A1: mode | B1: type | C1: fuel
D2: Fuel Shares
E3: =Stock!L$1 -> AL | F3: =Stock!M$1 -> AT | G3: =Stock!N$1 -> BA | H3: =Stock!O$1 -> BE | I3: =Stock!P$1 -> BG | J3: =Stock!Q$1 -> CH | K3: =Stock!R$1 -> CY | L3: =Stock!S$1 -> CZ | ... AO3: =Stock!AV$1 -> UK
A4: =LEFT(Stock!C2,7)&"*" -> TRA_Bus* | B4: ="*"&RIGHT(Stock!C2,3)&"*" -> *Coa* | C4: ="*"&MID(Stock!C2,9,3)&"*" -> *Cng* | E4: =SUMIFS(Stock!L$2:L$41,Stock!$C$2:$C$41,FuelShares!$A4,Stock!$C$2:$C$41,FuelShares!$C4)/SUMIF(Stock!$C$2:$C$41,FuelShares!$A4,Stock!L$2:L$41) -> 0 | F4: =SUMIFS(Stock!M$2:M$41,Stock!$C$2:$C$41,FuelShares!$A4,Stock!$C$2:$C$41,FuelShares!$C4)/SUMIF(Stock!$C$2:$C$41,FuelShares!$A4,Stock!M$2:M$41) -> 0 | G4: =SUMIFS(Stock!N$2:N$41,Stock!$C$2:$C$41,FuelShares!$A4,Stock!$C$2:$C$41,FuelShares!$C4)/SUMIF(Stock!$C$2:$C$41,FuelShares!$A4,Stock!N$2:N$41) -> 0 | H4: =SUMIFS(Stock!O$2:O$41,Stock!$C$2:$C$41,FuelShares!$A4,Stock!$C$2:$C$41,FuelShares!$C4)/SUMIF(Stock!$C$2:$C$41,FuelShares!$A4,Stock!O$2:O$41) -> 0 | I4: =SUMIFS(Stock!P$2:P$41,Stock!$C$2:$C$41,FuelShares!$A4,Stock!$C$2:$C$41,FuelShares!$C4)/SUMIF(Stock!$C$2:$C$41,FuelShares!$A4,Stock!P$2:P$41) -> 0 | J4: =SUMIFS(Stock!Q$2:Q$41,Stock!$C$2:$C$41,FuelShares!$A4,Stock!$C$2:$C$41,FuelShares!$C4)/SUMIF(Stock!$C$2:$C$41,FuelShares!$A4,Stock!Q$2:Q$41) -> 0.024423338 | K4: =SUMIFS(Stock!R$2:R$41,Stock!$C$2:$C$41,FuelShares!$A4,Stock!$C$2:$C$41,FuelShares!$C4)/SUMIF(Stock!$C$2:$C$41,FuelShares!$A4,Stock!R$2:R$41) -> 0 | L4: =SUMIFS(Stock!S$2:S$41,Stock!$C$2:$C$41,FuelShares!$A4,Stock!$C$2:$C$41,FuelShares!$C4)/SUMIF(Stock!$C$2:$C$41,FuelShares!$A4,Stock!S$2:S$41) -> 0 | ... AO4: =SUMIFS(Stock!AV$2:AV$41,Stock!$C$2:$C$41,FuelShares!$A4,Stock!$C$2:$C$41,FuelShares!$C4)/SUMIF(Stock!$C$2:$C$41,FuelShares!$A4,Stock!AV$2:AV$41) -> 0
A5: =LEFT(Stock!C3,7)&"*" -> TRA_Bus* | B5: ="*"&RIGHT(Stock!C3,3)&"*" -> *Urb* | C5: ="*"&MID(Stock!C3,9,3)&"*" -> *Cng* | E5: =SUMIFS(Stock!L$2:L$41,Stock!$C$2:$C$41,FuelShares!$A5,Stock!$C$2:$C$41,FuelShares!$C5)/SUMIF(Stock!$C$2:$C$41,FuelShares!$A5,Stock!L$2:L$41) -> 0 | F5: =SUMIFS(Stock!M$2:M$41,Stock!$C$2:$C$41,FuelShares!$A5,Stock!$C$2:$C$41,FuelShares!$C5)/SUMIF(Stock!$C$2:$C$41,FuelShares!$A5,Stock!M$2:M$41) -> 0 | G5: =SUMIFS(Stock!N$2:N$41,Stock!$C$2:$C$41,FuelShares!$A5,Stock!$C$2:$C$41,FuelShares!$C5)/SUMIF(Stock!$C$2:$C$41,FuelShares!$A5,Stock!N$2:N$41) -> 0 | H5: =SUMIFS(Stock!O$2:O$41,Stock!$C$2:$C$41,FuelShares!$A5,Stock!$C$2:$C$41,FuelShares!$C5)/SUMIF(Stock!$C$2:$C$41,FuelShares!$A5,Stock!O$2:O$41) -> 0 | I5: =SUMIFS(Stock!P$2:P$41,Stock!$C$2:$C$41,FuelShares!$A5,Stock!$C$2:$C$41,FuelShares!$C5)/SUMIF(Stock!$C$2:$C$41,FuelShares!$A5,Stock!P$2:P$41) -> 0 | J5: =SUMIFS(Stock!Q$2:Q$41,Stock!$C$2:$C$41,FuelShares!$A5,Stock!$C$2:$C$41,FuelShares!$C5)/SUMIF(Stock!$C$2:$C$41,FuelShares!$A5,Stock!Q$2:Q$41) -> 0.024423338 | K5: =SUMIFS(Stock!R$2:R$41,Stock!$C$2:$C$41,FuelShares!$A5,Stock!$C$2:$C$41,FuelShares!$C5)/SUMIF(Stock!$C$2:$C$41,FuelShares!$A5,Stock!R$2:R$41) -> 0 | L5: =SUMIFS(Stock!S$2:S$41,Stock!$C$2:$C$41,FuelShares!$A5,Stock!$C$2:$C$41,FuelShares!$C5)/SUMIF(Stock!$C$2:$C$41,FuelShares!$A5,Stock!S$2:S$41) -> 0 | ... AO5: =SUMIFS(Stock!AV$2:AV$41,Stock!$C$2:$C$41,FuelShares!$A5,Stock!$C$2:$C$41,FuelShares!$C5)/SUMIF(Stock!$C$2:$C$41,FuelShares!$A5,Stock!AV$2:AV$41) -> 0
A6: =LEFT(Stock!C4,7)&"*" -> TRA_Bus* | B6: ="*"&RIGHT(Stock!C4,3)&"*" -> *Coa* | C6: ="*"&MID(Stock!C4,9,3)&"*" -> *Dis* | E6: =SUMIFS(Stock!L$2:L$41,Stock!$C$2:$C$41,FuelShares!$A6,Stock!$C$2:$C$41,FuelShares!$C6)/SUMIF(Stock!$C$2:$C$41,FuelShares!$A6,Stock!L$2:L$41) -> 1 | F6: =SUMIFS(Stock!M$2:M$41,Stock!$C$2:$C$41,FuelShares!$A6,Stock!$C$2:$C$41,FuelShares!$C6)/SUMIF(Stock!$C$2:$C$41,FuelShares!$A6,Stock!M$2:M$41) -> 1 | G6: =SUMIFS(Stock!N$2:N$41,Stock!$C$2:$C$41,FuelShares!$A6,Stock!$C$2:$C$41,FuelShares!$C6)/SUMIF(Stock!$C$2:$C$41,FuelShares!$A6,Stock!N$2:N$41) -> 1 | H6: =SUMIFS(Stock!O$2:O$41,Stock!$C$2:$C$41,FuelShares!$A6,Stock!$C$2:$C$41,FuelShares!$C6)/SUMIF(Stock!$C$2:$C$41,FuelShares!$A6,Stock!O$2:O$41) -> 1 | I6: =SUMIFS(Stock!P$2:P$41,Stock!$C$2:$C$41,FuelShares!$A6,Stock!$C$2:$C$41,FuelShares!$C6)/SUMIF(Stock!$C$2:$C$41,FuelShares!$A6,Stock!P$2:P$41) -> 1 | J6: =SUMIFS(Stock!Q$2:Q$41,Stock!$C$2:$C$41,FuelShares!$A6,Stock!$C$2:$C$41,FuelShares!$C6)/SUMIF(Stock!$C$2:$C$41,FuelShares!$A6,Stock!Q$2:Q$41) -> 0.97557666 | K6: =SUMIFS(Stock!R$2:R$41,Stock!$C$2:$C$41,FuelShares!$A6,Stock!$C$2:$C$41,FuelShares!$C6)/SUMIF(Stock!$C$2:$C$41,FuelShares!$A6,Stock!R$2:R$41) -> 1 | L6: =SUMIFS(Stock!S$2:S$41,Stock!$C$2:$C$41,FuelShares!$A6,Stock!$C$2:$C$41,FuelShares!$C6)/SUMIF(Stock!$C$2:$C$41,FuelShares!$A6,Stock!S$2:S$41) -> 0.89669211 | ... AO6: =SUMIFS(Stock!AV$2:AV$41,Stock!$C$2:$C$41,FuelShares!$A6,Stock!$C$2:$C$41,FuelShares!$C6)/SUMIF(Stock!$C$2:$C$41,FuelShares!$A6,Stock!AV$2:AV$41) -> 0.95990883
A7: =LEFT(Stock!C5,7)&"*" -> TRA_Bus* | B7: ="*"&RIGHT(Stock!C5,3)&"*" -> *Urb* | C7: ="*"&MID(Stock!C5,9,3)&"*" -> *Dis* | E7: =SUMIFS(Stock!L$2:L$41,Stock!$C$2:$C$41,FuelShares!$A7,Stock!$C$2:$C$41,FuelShares!$C7)/SUMIF(Stock!$C$2:$C$41,FuelShares!$A7,Stock!L$2:L$41) -> 1 | F7: =SUMIFS(Stock!M$2:M$41,Stock!$C$2:$C$41,FuelShares!$A7,Stock!$C$2:$C$41,FuelShares!$C7)/SUMIF(Stock!$C$2:$C$41,FuelShares!$A7,Stock!M$2:M$41) -> 1 | G7: =SUMIFS(Stock!N$2:N$41,Stock!$C$2:$C$41,FuelShares!$A7,Stock!$C$2:$C$41,FuelShares!$C7)/SUMIF(Stock!$C$2:$C$41,FuelShares!$A7,Stock!N$2:N$41) -> 1 | H7: =SUMIFS(Stock!O$2:O$41,Stock!$C$2:$C$41,FuelShares!$A7,Stock!$C$2:$C$41,FuelShares!$C7)/SUMIF(Stock!$C$2:$C$41,FuelShares!$A7,Stock!O$2:O$41) -> 1 | I7: =SUMIFS(Stock!P$2:P$41,Stock!$C$2:$C$41,FuelShares!$A7,Stock!$C$2:$C$41,FuelShares!$C7)/SUMIF(Stock!$C$2:$C$41,FuelShares!$A7,Stock!P$2:P$41) -> 1 | J7: =SUMIFS(Stock!Q$2:Q$41,Stock!$C$2:$C$41,FuelShares!$A7,Stock!$C$2:$C$41,FuelShares!$C7)/SUMIF(Stock!$C$2:$C$41,FuelShares!$A7,Stock!Q$2:Q$41) -> 0.97557666 | K7: =SUMIFS(Stock!R$2:R$41,Stock!$C$2:$C$41,FuelShares!$A7,Stock!$C$2:$C$41,FuelShares!$C7)/SUMIF(Stock!$C$2:$C$41,FuelShares!$A7,Stock!R$2:R$41) -> 1 | L7: =SUMIFS(Stock!S$2:S$41,Stock!$C$2:$C$41,FuelShares!$A7,Stock!$C$2:$C$41,FuelShares!$C7)/SUMIF(Stock!$C$2:$C$41,FuelShares!$A7,Stock!S$2:S$41) -> 0.89669211 | ... AO7: =SUMIFS(Stock!AV$2:AV$41,Stock!$C$2:$C$41,FuelShares!$A7,Stock!$C$2:$C$41,FuelShares!$C7)/SUMIF(Stock!$C$2:$C$41,FuelShares!$A7,Stock!AV$2:AV$41) -> 0.95990883
A8: =LEFT(Stock!C6,7)&"*" -> TRA_Bus* | B8: ="*"&RIGHT(Stock!C6,3)&"*" -> *Coa* | C8: ="*"&MID(Stock!C6,9,3)&"*" -> *Gas* | E8: =SUMIFS(Stock!L$2:L$41,Stock!$C$2:$C$41,FuelShares!$A8,Stock!$C$2:$C$41,FuelShares!$C8)/SUMIF(Stock!$C$2:$C$41,FuelShares!$A8,Stock!L$2:L$41) -> 0 | F8: =SUMIFS(Stock!M$2:M$41,Stock!$C$2:$C$41,FuelShares!$A8,Stock!$C$2:$C$41,FuelShares!$C8)/SUMIF(Stock!$C$2:$C$41,FuelShares!$A8,Stock!M$2:M$41) -> 0 | G8: =SUMIFS(Stock!N$2:N$41,Stock!$C$2:$C$41,FuelShares!$A8,Stock!$C$2:$C$41,FuelShares!$C8)/SUMIF(Stock!$C$2:$C$41,FuelShares!$A8,Stock!N$2:N$41) -> 0 | H8: =SUMIFS(Stock!O$2:O$41,Stock!$C$2:$C$41,FuelShares!$A8,Stock!$C$2:$C$41,FuelShares!$C8)/SUMIF(Stock!$C$2:$C$41,FuelShares!$A8,Stock!O$2:O$41) -> 0 | I8: =SUMIFS(Stock!P$2:P$41,Stock!$C$2:$C$41,FuelShares!$A8,Stock!$C$2:$C$41,FuelShares!$C8)/SUMIF(Stock!$C$2:$C$41,FuelShares!$A8,Stock!P$2:P$41) -> 0 | J8: =SUMIFS(Stock!Q$2:Q$41,Stock!$C$2:$C$41,FuelShares!$A8,Stock!$C$2:$C$41,FuelShares!$C8)/SUMIF(Stock!$C$2:$C$41,FuelShares!$A8,Stock!Q$2:Q$41) -> 0 | K8: =SUMIFS(Stock!R$2:R$41,Stock!$C$2:$C$41,FuelShares!$A8,Stock!$C$2:$C$41,FuelShares!$C8)/SUMIF(Stock!$C$2:$C$41,FuelShares!$A8,Stock!R$2:R$41) -> 0 | L8: =SUMIFS(Stock!S$2:S$41,Stock!$C$2:$C$41,FuelShares!$A8,Stock!$C$2:$C$41,FuelShares!$C8)/SUMIF(Stock!$C$2:$C$41,FuelShares!$A8,Stock!S$2:S$41) -> 0.10330789 | ... AO8: =SUMIFS(Stock!AV$2:AV$41,Stock!$C$2:$C$41,FuelShares!$A8,Stock!$C$2:$C$41,FuelShares!$C8)/SUMIF(Stock!$C$2:$C$41,FuelShares!$A8,Stock!AV$2:AV$41) -> 0.038571679
A9: =LEFT(Stock!C7,7)&"*" -> TRA_Bus* | B9: ="*"&RIGHT(Stock!C7,3)&"*" -> *Urb* | C9: ="*"&MID(Stock!C7,9,3)&"*" -> *Gas* | E9: =SUMIFS(Stock!L$2:L$41,Stock!$C$2:$C$41,FuelShares!$A9,Stock!$C$2:$C$41,FuelShares!$C9)/SUMIF(Stock!$C$2:$C$41,FuelShares!$A9,Stock!L$2:L$41) -> 0 | F9: =SUMIFS(Stock!M$2:M$41,Stock!$C$2:$C$41,FuelShares!$A9,Stock!$C$2:$C$41,FuelShares!$C9)/SUMIF(Stock!$C$2:$C$41,FuelShares!$A9,Stock!M$2:M$41) -> 0 | G9: =SUMIFS(Stock!N$2:N$41,Stock!$C$2:$C$41,FuelShares!$A9,Stock!$C$2:$C$41,FuelShares!$C9)/SUMIF(Stock!$C$2:$C$41,FuelShares!$A9,Stock!N$2:N$41) -> 0 | H9: =SUMIFS(Stock!O$2:O$41,Stock!$C$2:$C$41,FuelShares!$A9,Stock!$C$2:$C$41,FuelShares!$C9)/SUMIF(Stock!$C$2:$C$41,FuelShares!$A9,Stock!O$2:O$41) -> 0 | I9: =SUMIFS(Stock!P$2:P$41,Stock!$C$2:$C$41,FuelShares!$A9,Stock!$C$2:$C$41,FuelShares!$C9)/SUMIF(Stock!$C$2:$C$41,FuelShares!$A9,Stock!P$2:P$41) -> 0 | J9: =SUMIFS(Stock!Q$2:Q$41,Stock!$C$2:$C$41,FuelShares!$A9,Stock!$C$2:$C$41,FuelShares!$C9)/SUMIF(Stock!$C$2:$C$41,FuelShares!$A9,Stock!Q$2:Q$41) -> 0 | K9: =SUMIFS(Stock!R$2:R$41,Stock!$C$2:$C$41,FuelShares!$A9,Stock!$C$2:$C$41,FuelShares!$C9)/SUMIF(Stock!$C$2:$C$41,FuelShares!$A9,Stock!R$2:R$41) -> 0 | L9: =SUMIFS(Stock!S$2:S$41,Stock!$C$2:$C$41,FuelShares!$A9,Stock!$C$2:$C$41,FuelShares!$C9)/SUMIF(Stock!$C$2:$C$41,FuelShares!$A9,Stock!S$2:S$41) -> 0.10330789 | ... AO9: =SUMIFS(Stock!AV$2:AV$41,Stock!$C$2:$C$41,FuelShares!$A9,Stock!$C$2:$C$41,FuelShares!$C9)/SUMIF(Stock!$C$2:$C$41,FuelShares!$A9,Stock!AV$2:AV$41) -> 0.038571679
A10: =LEFT(Stock!C8,7)&"*" -> TRA_Bus* | B10: ="*"&RIGHT(Stock!C8,3)&"*" -> *Coa* | C10: ="*"&MID(Stock!C8,9,3)&"*" -> *Lpg* | E10: =SUMIFS(Stock!L$2:L$41,Stock!$C$2:$C$41,FuelShares!$A10,Stock!$C$2:$C$41,FuelShares!$C10)/SUMIF(Stock!$C$2:$C$41,FuelShares!$A10,Stock!L$2:L$41) -> 0 | F10: =SUMIFS(Stock!M$2:M$41,Stock!$C$2:$C$41,FuelShares!$A10,Stock!$C$2:$C$41,FuelShares!$C10)/SUMIF(Stock!$C$2:$C$41,FuelShares!$A10,Stock!M$2:M$41) -> 0 | G10: =SUMIFS(Stock!N$2:N$41,Stock!$C$2:$C$41,FuelShares!$A10,Stock!$C$2:$C$41,FuelShares!$C10)/SUMIF(Stock!$C$2:$C$41,FuelShares!$A10,Stock!N$2:N$41) -> 0 | H10: =SUMIFS(Stock!O$2:O$41,Stock!$C$2:$C$41,FuelShares!$A10,Stock!$C$2:$C$41,FuelShares!$C10)/SUMIF(Stock!$C$2:$C$41,FuelShares!$A10,Stock!O$2:O$41) -> 0 | I10: =SUMIFS(Stock!P$2:P$41,Stock!$C$2:$C$41,FuelShares!$A10,Stock!$C$2:$C$41,FuelShares!$C10)/SUMIF(Stock!$C$2:$C$41,FuelShares!$A10,Stock!P$2:P$41) -> 0 | J10: =SUMIFS(Stock!Q$2:Q$41,Stock!$C$2:$C$41,FuelShares!$A10,Stock!$C$2:$C$41,FuelShares!$C10)/SUMIF(Stock!$C$2:$C$41,FuelShares!$A10,Stock!Q$2:Q$41) -> 0 | K10: =SUMIFS(Stock!R$2:R$41,Stock!$C$2:$C$41,FuelShares!$A10,Stock!$C$2:$C$41,FuelShares!$C10)/SUMIF(Stock!$C$2:$C$41,FuelShares!$A10,Stock!R$2:R$41) -> 0 | L10: =SUMIFS(Stock!S$2:S$41,Stock!$C$2:$C$41,FuelShares!$A10,Stock!$C$2:$C$41,FuelShares!$C10)/SUMIF(Stock!$C$2:$C$41,FuelShares!$A10,Stock!S$2:S$41) -> 0 | ... AO10: =SUMIFS(Stock!AV$2:AV$41,Stock!$C$2:$C$41,FuelShares!$A10,Stock!$C$2:$C$41,FuelShares!$C10)/SUMIF(Stock!$C$2:$C$41,FuelShares!$A10,Stock!AV$2:AV$41) -> 0.0015194904
A11: =LEFT(Stock!C9,7)&"*" -> TRA_Bus* | B11: ="*"&RIGHT(Stock!C9,3)&"*" -> *Urb* | C11: ="*"&MID(Stock!C9,9,3)&"*" -> *Lpg* | E11: =SUMIFS(Stock!L$2:L$41,Stock!$C$2:$C$41,FuelShares!$A11,Stock!$C$2:$C$41,FuelShares!$C11)/SUMIF(Stock!$C$2:$C$41,FuelShares!$A11,Stock!L$2:L$41) -> 0 | F11: =SUMIFS(Stock!M$2:M$41,Stock!$C$2:$C$41,FuelShares!$A11,Stock!$C$2:$C$41,FuelShares!$C11)/SUMIF(Stock!$C$2:$C$41,FuelShares!$A11,Stock!M$2:M$41) -> 0 | G11: =SUMIFS(Stock!N$2:N$41,Stock!$C$2:$C$41,FuelShares!$A11,Stock!$C$2:$C$41,FuelShares!$C11)/SUMIF(Stock!$C$2:$C$41,FuelShares!$A11,Stock!N$2:N$41) -> 0 | H11: =SUMIFS(Stock!O$2:O$41,Stock!$C$2:$C$41,FuelShares!$A11,Stock!$C$2:$C$41,FuelShares!$C11)/SUMIF(Stock!$C$2:$C$41,FuelShares!$A11,Stock!O$2:O$41) -> 0 | I11: =SUMIFS(Stock!P$2:P$41,Stock!$C$2:$C$41,FuelShares!$A11,Stock!$C$2:$C$41,FuelShares!$C11)/SUMIF(Stock!$C$2:$C$41,FuelShares!$A11,Stock!P$2:P$41) -> 0 | J11: =SUMIFS(Stock!Q$2:Q$41,Stock!$C$2:$C$41,FuelShares!$A11,Stock!$C$2:$C$41,FuelShares!$C11)/SUMIF(Stock!$C$2:$C$41,FuelShares!$A11,Stock!Q$2:Q$41) -> 0 | K11: =SUMIFS(Stock!R$2:R$41,Stock!$C$2:$C$41,FuelShares!$A11,Stock!$C$2:$C$41,FuelShares!$C11)/SUMIF(Stock!$C$2:$C$41,FuelShares!$A11,Stock!R$2:R$41) -> 0 | L11: =SUMIFS(Stock!S$2:S$41,Stock!$C$2:$C$41,FuelShares!$A11,Stock!$C$2:$C$41,FuelShares!$C11)/SUMIF(Stock!$C$2:$C$41,FuelShares!$A11,Stock!S$2:S$41) -> 0 | ... AO11: =SUMIFS(Stock!AV$2:AV$41,Stock!$C$2:$C$41,FuelShares!$A11,Stock!$C$2:$C$41,FuelShares!$C11)/SUMIF(Stock!$C$2:$C$41,FuelShares!$A11,Stock!AV$2:AV$41) -> 0.0015194904
A12: =LEFT(Stock!C10,7)&"*" -> TRA_Car* | B12: ="*"&RIGHT(Stock!C10,3)&"*" -> *Exe* | C12: ="*"&MID(Stock!C10,9,3)&"*" -> *Cng* | E12: =SUMIFS(Stock!L$2:L$41,Stock!$C$2:$C$41,FuelShares!$A12,Stock!$C$2:$C$41,FuelShares!$C12)/SUMIF(Stock!$C$2:$C$41,FuelShares!$A12,Stock!L$2:L$41) -> 0 | F12: =SUMIFS(Stock!M$2:M$41,Stock!$C$2:$C$41,FuelShares!$A12,Stock!$C$2:$C$41,FuelShares!$C12)/SUMIF(Stock!$C$2:$C$41,FuelShares!$A12,Stock!M$2:M$41) -> 0 | G12: =SUMIFS(Stock!N$2:N$41,Stock!$C$2:$C$41,FuelShares!$A12,Stock!$C$2:$C$41,FuelShares!$C12)/SUMIF(Stock!$C$2:$C$41,FuelShares!$A12,Stock!N$2:N$41) -> 0 | H12: =SUMIFS(Stock!O$2:O$41,Stock!$C$2:$C$41,FuelShares!$A12,Stock!$C$2:$C$41,FuelShares!$C12)/SUMIF(Stock!$C$2:$C$41,FuelShares!$A12,Stock!O$2:O$41) -> 0 | I12: =SUMIFS(Stock!P$2:P$41,Stock!$C$2:$C$41,FuelShares!$A12,Stock!$C$2:$C$41,FuelShares!$C12)/SUMIF(Stock!$C$2:$C$41,FuelShares!$A12,Stock!P$2:P$41) -> 0 | J12: =SUMIFS(Stock!Q$2:Q$41,Stock!$C$2:$C$41,FuelShares!$A12,Stock!$C$2:$C$41,FuelShares!$C12)/SUMIF(Stock!$C$2:$C$41,FuelShares!$A12,Stock!Q$2:Q$41) -> 0.0016143951 | K12: =SUMIFS(Stock!R$2:R$41,Stock!$C$2:$C$41,FuelShares!$A12,Stock!$C$2:$C$41,FuelShares!$C12)/SUMIF(Stock!$C$2:$C$41,FuelShares!$A12,Stock!R$2:R$41) -> 0 | L12: =SUMIFS(Stock!S$2:S$41,Stock!$C$2:$C$41,FuelShares!$A12,Stock!$C$2:$C$41,FuelShares!$C12)/SUMIF(Stock!$C$2:$C$41,FuelShares!$A12,Stock!S$2:S$41) -> 0 | ... AO12: =SUMIFS(Stock!AV$2:AV$41,Stock!$C$2:$C$41,FuelShares!$A12,Stock!$C$2:$C$41,FuelShares!$C12)/SUMIF(Stock!$C$2:$C$41,FuelShares!$A12,Stock!AV$2:AV$41) -> 4.7290785e-05
A13: =LEFT(Stock!C11,7)&"*" -> TRA_Car* | B13: ="*"&RIGHT(Stock!C11,3)&"*" -> *Lom* | C13: ="*"&MID(Stock!C11,9,3)&"*" -> *Cng* | E13: =SUMIFS(Stock!L$2:L$41,Stock!$C$2:$C$41,FuelShares!$A13,Stock!$C$2:$C$41,FuelShares!$C13)/SUMIF(Stock!$C$2:$C$41,FuelShares!$A13,Stock!L$2:L$41) -> 0 | F13: =SUMIFS(Stock!M$2:M$41,Stock!$C$2:$C$41,FuelShares!$A13,Stock!$C$2:$C$41,FuelShares!$C13)/SUMIF(Stock!$C$2:$C$41,FuelShares!$A13,Stock!M$2:M$41) -> 0 | G13: =SUMIFS(Stock!N$2:N$41,Stock!$C$2:$C$41,FuelShares!$A13,Stock!$C$2:$C$41,FuelShares!$C13)/SUMIF(Stock!$C$2:$C$41,FuelShares!$A13,Stock!N$2:N$41) -> 0 | H13: =SUMIFS(Stock!O$2:O$41,Stock!$C$2:$C$41,FuelShares!$A13,Stock!$C$2:$C$41,FuelShares!$C13)/SUMIF(Stock!$C$2:$C$41,FuelShares!$A13,Stock!O$2:O$41) -> 0 | I13: =SUMIFS(Stock!P$2:P$41,Stock!$C$2:$C$41,FuelShares!$A13,Stock!$C$2:$C$41,FuelShares!$C13)/SUMIF(Stock!$C$2:$C$41,FuelShares!$A13,Stock!P$2:P$41) -> 0 | J13: =SUMIFS(Stock!Q$2:Q$41,Stock!$C$2:$C$41,FuelShares!$A13,Stock!$C$2:$C$41,FuelShares!$C13)/SUMIF(Stock!$C$2:$C$41,FuelShares!$A13,Stock!Q$2:Q$41) -> 0.0016143951 | K13: =SUMIFS(Stock!R$2:R$41,Stock!$C$2:$C$41,FuelShares!$A13,Stock!$C$2:$C$41,FuelShares!$C13)/SUMIF(Stock!$C$2:$C$41,FuelShares!$A13,Stock!R$2:R$41) -> 0 | L13: =SUMIFS(Stock!S$2:S$41,Stock!$C$2:$C$41,FuelShares!$A13,Stock!$C$2:$C$41,FuelShares!$C13)/SUMIF(Stock!$C$2:$C$41,FuelShares!$A13,Stock!S$2:S$41) -> 0 | ... AO13: =SUMIFS(Stock!AV$2:AV$41,Stock!$C$2:$C$41,FuelShares!$A13,Stock!$C$2:$C$41,FuelShares!$C13)/SUMIF(Stock!$C$2:$C$41,FuelShares!$A13,Stock!AV$2:AV$41) -> 4.7290785e-05
A14: =LEFT(Stock!C12,7)&"*" -> TRA_Car* | B14: ="*"&RIGHT(Stock!C12,3)&"*" -> *Sma* | C14: ="*"&MID(Stock!C12,9,3)&"*" -> *Cng* | E14: =SUMIFS(Stock!L$2:L$41,Stock!$C$2:$C$41,FuelShares!$A14,Stock!$C$2:$C$41,FuelShares!$C14)/SUMIF(Stock!$C$2:$C$41,FuelShares!$A14,Stock!L$2:L$41) -> 0 | F14: =SUMIFS(Stock!M$2:M$41,Stock!$C$2:$C$41,FuelShares!$A14,Stock!$C$2:$C$41,FuelShares!$C14)/SUMIF(Stock!$C$2:$C$41,FuelShares!$A14,Stock!M$2:M$41) -> 0 | G14: =SUMIFS(Stock!N$2:N$41,Stock!$C$2:$C$41,FuelShares!$A14,Stock!$C$2:$C$41,FuelShares!$C14)/SUMIF(Stock!$C$2:$C$41,FuelShares!$A14,Stock!N$2:N$41) -> 0 | H14: =SUMIFS(Stock!O$2:O$41,Stock!$C$2:$C$41,FuelShares!$A14,Stock!$C$2:$C$41,FuelShares!$C14)/SUMIF(Stock!$C$2:$C$41,FuelShares!$A14,Stock!O$2:O$41) -> 0 | I14: =SUMIFS(Stock!P$2:P$41,Stock!$C$2:$C$41,FuelShares!$A14,Stock!$C$2:$C$41,FuelShares!$C14)/SUMIF(Stock!$C$2:$C$41,FuelShares!$A14,Stock!P$2:P$41) -> 0 | J14: =SUMIFS(Stock!Q$2:Q$41,Stock!$C$2:$C$41,FuelShares!$A14,Stock!$C$2:$C$41,FuelShares!$C14)/SUMIF(Stock!$C$2:$C$41,FuelShares!$A14,Stock!Q$2:Q$41) -> 0.0016143951 | K14: =SUMIFS(Stock!R$2:R$41,Stock!$C$2:$C$41,FuelShares!$A14,Stock!$C$2:$C$41,FuelShares!$C14)/SUMIF(Stock!$C$2:$C$41,FuelShares!$A14,Stock!R$2:R$41) -> 0 | L14: =SUMIFS(Stock!S$2:S$41,Stock!$C$2:$C$41,FuelShares!$A14,Stock!$C$2:$C$41,FuelShares!$C14)/SUMIF(Stock!$C$2:$C$41,FuelShares!$A14,Stock!S$2:S$41) -> 0 | ... AO14: =SUMIFS(Stock!AV$2:AV$41,Stock!$C$2:$C$41,FuelShares!$A14,Stock!$C$2:$C$41,FuelShares!$C14)/SUMIF(Stock!$C$2:$C$41,FuelShares!$A14,Stock!AV$2:AV$41) -> 4.7290785e-05
A15: =LEFT(Stock!C13,7)&"*" -> TRA_Car* | B15: ="*"&RIGHT(Stock!C13,3)&"*" -> *Upm* | C15: ="*"&MID(Stock!C13,9,3)&"*" -> *Cng* | E15: =SUMIFS(Stock!L$2:L$41,Stock!$C$2:$C$41,FuelShares!$A15,Stock!$C$2:$C$41,FuelShares!$C15)/SUMIF(Stock!$C$2:$C$41,FuelShares!$A15,Stock!L$2:L$41) -> 0 | F15: =SUMIFS(Stock!M$2:M$41,Stock!$C$2:$C$41,FuelShares!$A15,Stock!$C$2:$C$41,FuelShares!$C15)/SUMIF(Stock!$C$2:$C$41,FuelShares!$A15,Stock!M$2:M$41) -> 0 | G15: =SUMIFS(Stock!N$2:N$41,Stock!$C$2:$C$41,FuelShares!$A15,Stock!$C$2:$C$41,FuelShares!$C15)/SUMIF(Stock!$C$2:$C$41,FuelShares!$A15,Stock!N$2:N$41) -> 0 | H15: =SUMIFS(Stock!O$2:O$41,Stock!$C$2:$C$41,FuelShares!$A15,Stock!$C$2:$C$41,FuelShares!$C15)/SUMIF(Stock!$C$2:$C$41,FuelShares!$A15,Stock!O$2:O$41) -> 0 | I15: =SUMIFS(Stock!P$2:P$41,Stock!$C$2:$C$41,FuelShares!$A15,Stock!$C$2:$C$41,FuelShares!$C15)/SUMIF(Stock!$C$2:$C$41,FuelShares!$A15,Stock!P$2:P$41) -> 0 | J15: =SUMIFS(Stock!Q$2:Q$41,Stock!$C$2:$C$41,FuelShares!$A15,Stock!$C$2:$C$41,FuelShares!$C15)/SUMIF(Stock!$C$2:$C$41,FuelShares!$A15,Stock!Q$2:Q$41) -> 0.0016143951 | K15: =SUMIFS(Stock!R$2:R$41,Stock!$C$2:$C$41,FuelShares!$A15,Stock!$C$2:$C$41,FuelShares!$C15)/SUMIF(Stock!$C$2:$C$41,FuelShares!$A15,Stock!R$2:R$41) -> 0 | L15: =SUMIFS(Stock!S$2:S$41,Stock!$C$2:$C$41,FuelShares!$A15,Stock!$C$2:$C$41,FuelShares!$C15)/SUMIF(Stock!$C$2:$C$41,FuelShares!$A15,Stock!S$2:S$41) -> 0 | ... AO15: =SUMIFS(Stock!AV$2:AV$41,Stock!$C$2:$C$41,FuelShares!$A15,Stock!$C$2:$C$41,FuelShares!$C15)/SUMIF(Stock!$C$2:$C$41,FuelShares!$A15,Stock!AV$2:AV$41) -> 4.7290785e-05
... A41: =LEFT(Stock!C39,7)&"*" -> TRA_Lcv* | B41: ="*"&RIGHT(Stock!C39,3)&"*" -> *Lpg* | C41: ="*"&MID(Stock!C39,9,3)&"*" -> *Lpg* | E41: =SUMIFS(Stock!L$2:L$41,Stock!$C$2:$C$41,FuelShares!$A41,Stock!$C$2:$C$41,FuelShares!$C41)/SUMIF(Stock!$C$2:$C$41,FuelShares!$A41,Stock!L$2:L$41) -> 0 | F41: =SUMIFS(Stock!M$2:M$41,Stock!$C$2:$C$41,FuelShares!$A41,Stock!$C$2:$C$41,FuelShares!$C41)/SUMIF(Stock!$C$2:$C$41,FuelShares!$A41,Stock!M$2:M$41) -> 0 | G41: =SUMIFS(Stock!N$2:N$41,Stock!$C$2:$C$41,FuelShares!$A41,Stock!$C$2:$C$41,FuelShares!$C41)/SUMIF(Stock!$C$2:$C$41,FuelShares!$A41,Stock!N$2:N$41) -> 0 | H41: =SUMIFS(Stock!O$2:O$41,Stock!$C$2:$C$41,FuelShares!$A41,Stock!$C$2:$C$41,FuelShares!$C41)/SUMIF(Stock!$C$2:$C$41,FuelShares!$A41,Stock!O$2:O$41) -> 0 | I41: =SUMIFS(Stock!P$2:P$41,Stock!$C$2:$C$41,FuelShares!$A41,Stock!$C$2:$C$41,FuelShares!$C41)/SUMIF(Stock!$C$2:$C$41,FuelShares!$A41,Stock!P$2:P$41) -> 0 | J41: =SUMIFS(Stock!Q$2:Q$41,Stock!$C$2:$C$41,FuelShares!$A41,Stock!$C$2:$C$41,FuelShares!$C41)/SUMIF(Stock!$C$2:$C$41,FuelShares!$A41,Stock!Q$2:Q$41) -> 0 | K41: =SUMIFS(Stock!R$2:R$41,Stock!$C$2:$C$41,FuelShares!$A41,Stock!$C$2:$C$41,FuelShares!$C41)/SUMIF(Stock!$C$2:$C$41,FuelShares!$A41,Stock!R$2:R$41) -> 0 | L41: =SUMIFS(Stock!S$2:S$41,Stock!$C$2:$C$41,FuelShares!$A41,Stock!$C$2:$C$41,FuelShares!$C41)/SUMIF(Stock!$C$2:$C$41,FuelShares!$A41,Stock!S$2:S$41) -> 0 | ... AO41: =SUMIFS(Stock!AV$2:AV$41,Stock!$C$2:$C$41,FuelShares!$A41,Stock!$C$2:$C$41,FuelShares!$C41)/SUMIF(Stock!$C$2:$C$41,FuelShares!$A41,Stock!AV$2:AV$41) -> 0.0037630576
E45: =Stock!L$1 -> AL | F45: =Stock!M$1 -> AT | G45: =Stock!N$1 -> BA | H45: =Stock!O$1 -> BE | I45: =Stock!P$1 -> BG | J45: =Stock!Q$1 -> CH | K45: =Stock!R$1 -> CY | L45: =Stock!S$1 -> CZ | ... AO45: =Stock!AV$1 -> UK
A46: TRA_Bus* | C46: *Cng* | E46: =SUMIFS(Stock!L$2:L$41,Stock!$C$2:$C$41,FuelShares!$A46,Stock!$C$2:$C$41,FuelShares!$C46)/SUMIF(Stock!$C$2:$C$41,FuelShares!$A46,Stock!L$2:L$41) -> 0 | F46: =SUMIFS(Stock!M$2:M$41,Stock!$C$2:$C$41,FuelShares!$A46,Stock!$C$2:$C$41,FuelShares!$C46)/SUMIF(Stock!$C$2:$C$41,FuelShares!$A46,Stock!M$2:M$41) -> 0 | G46: =SUMIFS(Stock!N$2:N$41,Stock!$C$2:$C$41,FuelShares!$A46,Stock!$C$2:$C$41,FuelShares!$C46)/SUMIF(Stock!$C$2:$C$41,FuelShares!$A46,Stock!N$2:N$41) -> 0 | H46: =SUMIFS(Stock!O$2:O$41,Stock!$C$2:$C$41,FuelShares!$A46,Stock!$C$2:$C$41,FuelShares!$C46)/SUMIF(Stock!$C$2:$C$41,FuelShares!$A46,Stock!O$2:O$41) -> 0 | I46: =SUMIFS(Stock!P$2:P$41,Stock!$C$2:$C$41,FuelShares!$A46,Stock!$C$2:$C$41,FuelShares!$C46)/SUMIF(Stock!$C$2:$C$41,FuelShares!$A46,Stock!P$2:P$41) -> 0 | J46: =SUMIFS(Stock!Q$2:Q$41,Stock!$C$2:$C$41,FuelShares!$A46,Stock!$C$2:$C$41,FuelShares!$C46)/SUMIF(Stock!$C$2:$C$41,FuelShares!$A46,Stock!Q$2:Q$41) -> 0.024423338 | K46: =SUMIFS(Stock!R$2:R$41,Stock!$C$2:$C$41,FuelShares!$A46,Stock!$C$2:$C$41,FuelShares!$C46)/SUMIF(Stock!$C$2:$C$41,FuelShares!$A46,Stock!R$2:R$41) -> 0 | L46: =SUMIFS(Stock!S$2:S$41,Stock!$C$2:$C$41,FuelShares!$A46,Stock!$C$2:$C$41,FuelShares!$C46)/SUMIF(Stock!$C$2:$C$41,FuelShares!$A46,Stock!S$2:S$41) -> 0 | ... AO46: =SUMIFS(Stock!AV$2:AV$41,Stock!$C$2:$C$41,FuelShares!$A46,Stock!$C$2:$C$41,FuelShares!$C46)/SUMIF(Stock!$C$2:$C$41,FuelShares!$A46,Stock!AV$2:AV$41) -> 0
A47: TRA_Bus* | C47: *Dis* | E47: =SUMIFS(Stock!L$2:L$41,Stock!$C$2:$C$41,FuelShares!$A47,Stock!$C$2:$C$41,FuelShares!$C47)/SUMIF(Stock!$C$2:$C$41,FuelShares!$A47,Stock!L$2:L$41) -> 1 | F47: =SUMIFS(Stock!M$2:M$41,Stock!$C$2:$C$41,FuelShares!$A47,Stock!$C$2:$C$41,FuelShares!$C47)/SUMIF(Stock!$C$2:$C$41,FuelShares!$A47,Stock!M$2:M$41) -> 1 | G47: =SUMIFS(Stock!N$2:N$41,Stock!$C$2:$C$41,FuelShares!$A47,Stock!$C$2:$C$41,FuelShares!$C47)/SUMIF(Stock!$C$2:$C$41,FuelShares!$A47,Stock!N$2:N$41) -> 1 | H47: =SUMIFS(Stock!O$2:O$41,Stock!$C$2:$C$41,FuelShares!$A47,Stock!$C$2:$C$41,FuelShares!$C47)/SUMIF(Stock!$C$2:$C$41,FuelShares!$A47,Stock!O$2:O$41) -> 1 | I47: =SUMIFS(Stock!P$2:P$41,Stock!$C$2:$C$41,FuelShares!$A47,Stock!$C$2:$C$41,FuelShares!$C47)/SUMIF(Stock!$C$2:$C$41,FuelShares!$A47,Stock!P$2:P$41) -> 1 | J47: =SUMIFS(Stock!Q$2:Q$41,Stock!$C$2:$C$41,FuelShares!$A47,Stock!$C$2:$C$41,FuelShares!$C47)/SUMIF(Stock!$C$2:$C$41,FuelShares!$A47,Stock!Q$2:Q$41) -> 0.97557666 | K47: =SUMIFS(Stock!R$2:R$41,Stock!$C$2:$C$41,FuelShares!$A47,Stock!$C$2:$C$41,FuelShares!$C47)/SUMIF(Stock!$C$2:$C$41,FuelShares!$A47,Stock!R$2:R$41) -> 1 | L47: =SUMIFS(Stock!S$2:S$41,Stock!$C$2:$C$41,FuelShares!$A47,Stock!$C$2:$C$41,FuelShares!$C47)/SUMIF(Stock!$C$2:$C$41,FuelShares!$A47,Stock!S$2:S$41) -> 0.89669211 | ... AO47: =SUMIFS(Stock!AV$2:AV$41,Stock!$C$2:$C$41,FuelShares!$A47,Stock!$C$2:$C$41,FuelShares!$C47)/SUMIF(Stock!$C$2:$C$41,FuelShares!$A47,Stock!AV$2:AV$41) -> 0.95990883
A48: TRA_Bus* | C48: *Gas* | E48: =SUMIFS(Stock!L$2:L$41,Stock!$C$2:$C$41,FuelShares!$A48,Stock!$C$2:$C$41,FuelShares!$C48)/SUMIF(Stock!$C$2:$C$41,FuelShares!$A48,Stock!L$2:L$41) -> 0 | F48: =SUMIFS(Stock!M$2:M$41,Stock!$C$2:$C$41,FuelShares!$A48,Stock!$C$2:$C$41,FuelShares!$C48)/SUMIF(Stock!$C$2:$C$41,FuelShares!$A48,Stock!M$2:M$41) -> 0 | G48: =SUMIFS(Stock!N$2:N$41,Stock!$C$2:$C$41,FuelShares!$A48,Stock!$C$2:$C$41,FuelShares!$C48)/SUMIF(Stock!$C$2:$C$41,FuelShares!$A48,Stock!N$2:N$41) -> 0 | H48: =SUMIFS(Stock!O$2:O$41,Stock!$C$2:$C$41,FuelShares!$A48,Stock!$C$2:$C$41,FuelShares!$C48)/SUMIF(Stock!$C$2:$C$41,FuelShares!$A48,Stock!O$2:O$41) -> 0 | I48: =SUMIFS(Stock!P$2:P$41,Stock!$C$2:$C$41,FuelShares!$A48,Stock!$C$2:$C$41,FuelShares!$C48)/SUMIF(Stock!$C$2:$C$41,FuelShares!$A48,Stock!P$2:P$41) -> 0 | J48: =SUMIFS(Stock!Q$2:Q$41,Stock!$C$2:$C$41,FuelShares!$A48,Stock!$C$2:$C$41,FuelShares!$C48)/SUMIF(Stock!$C$2:$C$41,FuelShares!$A48,Stock!Q$2:Q$41) -> 0 | K48: =SUMIFS(Stock!R$2:R$41,Stock!$C$2:$C$41,FuelShares!$A48,Stock!$C$2:$C$41,FuelShares!$C48)/SUMIF(Stock!$C$2:$C$41,FuelShares!$A48,Stock!R$2:R$41) -> 0 | L48: =SUMIFS(Stock!S$2:S$41,Stock!$C$2:$C$41,FuelShares!$A48,Stock!$C$2:$C$41,FuelShares!$C48)/SUMIF(Stock!$C$2:$C$41,FuelShares!$A48,Stock!S$2:S$41) -> 0.10330789 | ... AO48: =SUMIFS(Stock!AV$2:AV$41,Stock!$C$2:$C$41,FuelShares!$A48,Stock!$C$2:$C$41,FuelShares!$C48)/SUMIF(Stock!$C$2:$C$41,FuelShares!$A48,Stock!AV$2:AV$41) -> 0.038571679
