Workbook
Name BE: #REF!
Name bel: #REF!
Name dsg: #REF!
Name Scenario: #REF!
Name Summer: #REF!
Name Summer1: #REF!
Name ToeTJ: #REF!
Name TSeg: #REF!
Name TSEG1: #REF!
Name TSEG2: #REF!
Name TSEG3: #REF!
Name TSEG4: #REF!
Name TSEG5: #REF!
Name Winter: #REF!

Sheet ETS2CO2bound
A1: EU ESR until 2010-2020, with UK, EU-wide cap
B3: ~UC_SETS: R_E: AT,BE,BG,CY,CZ,DE,DK,EE,ES,FI,FR,EL,HR,HU,IE,IT,IS,LT,LU,LV,MT,NL,NO,PL,PT,RO,SE,SI,SK,UK
E5: ~UC_T: UP
B6: UC_N | C6: Pset_PN | D6: Cset_CN | E6: Year | F6: UC_FLO | G6: UC_COMNET | H6: UC_RHSTS | I6: UC_COMPRD | K6: compare to the sum of regions incl UK
B7: CO2TargetESR2020 | D7: RSDCO2N,COMCO2N,AGRCO2N,SE_TRACO2N,NETSCO2 | E7: 2010 | G7: 1 | H7: =SUM(M58:AQ58) -> 2411921.7 | K7: =SUM(M58:AQ58) -> 2411921.7 | L7: =K7-H7 -> 0
D8: RSDCO2N,COMCO2N,AGRCO2N,SE_TRACO2N,NETSCO2 | E8: 2015 | K8: =SUM(M59:AQ59) -> 1776815.2 | L8: =K8-H8 -> 1776815.2
D9: RSDCO2N,COMCO2N,AGRCO2N,SE_TRACO2N,NETSCO2 | E9: 2020 | H9: =SUM(M60:AQ60) -> 1765609.8 | K9: =SUM(M60:AQ60) -> 1765609.8 | L9: =K9-H9 -> 0
D10: RSDCO2N,COMCO2N,AGRCO2N,SE_TRACO2N,NETSCO2 | E10: 0 | H10: 1
C11: =C29 -> TRAHFO00,TRALFO00,BLD_RFNBO_NAV | D11: SE_TRACO2N | E11: 2010 | F11: -1
C12: =C30 -> TRAHFO00,TRALFO00,BLD_RFNBO_NAV | D12: SE_TRACO2N | E12: 2020 | F12: -1
C13: =C31 -> TRAHFO00,TRALFO00,BLD_RFNBO_NAV | D13: SE_TRACO2N | E13: 0 | F13: 1
C14: =C32 -> BLDJET,BLD_RFNBO_JET | D14: SE_TRACO2N | E14: 2010 | F14: -1
C15: =C33 -> BLDJET,BLD_RFNBO_JET | D15: SE_TRACO2N | E15: 2020 | F15: -1
C16: =C34 -> BLDJET,BLD_RFNBO_JET | D16: SE_TRACO2N | E16: 0 | F16: 1
A20: EU ESR 2021-2026, EU ETS2 2027- without UK, CH, EU-wide cap
B22: ~UC_SETS: R_E: AT,BE,BG,CY,CZ,DE,DK,EE,ES,FI,FR,EL,HR,HU,IE,IS,IT,LT,LU,LV,MT,NL,NO,PL,PT,RO,SE,SI,SK
E24: ~UC_T: UP | K24: relax
B25: UC_N | C25: Pset_PN | D25: Cset_CN | E25: Year | F25: UC_FLO | G25: UC_COMNET | H25: UC_RHSTS | I25: UC_COMPRD | K25: 1.1
B26: CO2TargetETS2upper | D26: RSDCO2N,COMCO2N,AGRCO2N,SE_TRACO2N,NETSCO2 | E26: 2030 | G26: 1 | H26: ='Cap trajectories'!M15*1000*K25 -> 814092.32 | K26: Estimated cap for 2030 with 10% relaxation
D27: RSDCO2N,COMCO2N,AGRCO2N,SE_TRACO2N,NETSCO2 | E27: 2060 | H27: =H26 -> 814092.32
D28: RSDCO2N,COMCO2N,AGRCO2N,SE_TRACO2N,NETSCO2 | E28: 0 | H28: 5
C29: TRAHFO00,TRALFO00,BLD_RFNBO_NAV | D29: SE_TRACO2N | E29: 2021 | F29: -1
C30: TRAHFO00,TRALFO00,BLD_RFNBO_NAV | D30: SE_TRACO2N | E30: 2060 | F30: -1
C31: TRAHFO00,TRALFO00,BLD_RFNBO_NAV | D31: SE_TRACO2N | E31: 0 | F31: 1 | K31: DIFFERENCES
C32: BLDJET,BLD_RFNBO_JET | D32: SE_TRACO2N | E32: 2021 | F32: -1 | K32: ETS2 applies only to CO2 from RSD, COM, AGR, TRA, small industry
C33: BLDJET,BLD_RFNBO_JET | D33: SE_TRACO2N | E33: 2060 | F33: -1 | K33: ESR includes all GHGs, and additionally the agriculture (NFR 3) and waste sectors (NFR 5)
C34: BLDJET,BLD_RFNBO_JET | D34: SE_TRACO2N | E34: 0 | F34: 1
B37: **UC_SETS: R_E: AT,BE,BG,CY,CZ,DE,DK,EE,ES,FI,FR,EL,HR,HU,IE,IS,IT,LT,LU,LV,MT,NL,NO,PL,PT,RO,SE,SI,SK
E39: **UC_T: LO
B40: UC_N | C40: Pset_PN | D40: Cset_CN | E40: Year | F40: UC_FLO | G40: UC_COMNET | H40: UC_RHSTS | I40: UC_COMPRD
B41: CO2TargetETS2lower | D41: RSDCO2N,COMCO2N,AGRCO2N,SE_TRACO2N,NETSCO2 | E41: 2025 | G41: 1 | H41: =H26 -> 814092.32 | K41: 0.95
D42: RSDCO2N,COMCO2N,AGRCO2N,SE_TRACO2N,NETSCO2 | E42: 2030 | H42: =H26*K41 -> 773387.7
D43: RSDCO2N,COMCO2N,AGRCO2N,SE_TRACO2N,NETSCO2 | E43: 0 | H43: 1
C44: =C29 -> TRAHFO00,TRALFO00,BLD_RFNBO_NAV | D44: SE_TRACO2N | E44: 2021 | F44: -1
C45: =C30 -> TRAHFO00,TRALFO00,BLD_RFNBO_NAV | D45: SE_TRACO2N | E45: 2060 | F45: -1
C46: =C31 -> TRAHFO00,TRALFO00,BLD_RFNBO_NAV | D46: SE_TRACO2N | E46: 0 | F46: 1
C47: =C32 -> BLDJET,BLD_RFNBO_JET | D47: SE_TRACO2N | E47: 2021 | F47: -1
C48: =C33 -> BLDJET,BLD_RFNBO_JET | D48: SE_TRACO2N | E48: 2060 | F48: -1
C49: =C34 -> BLDJET,BLD_RFNBO_JET | D49: SE_TRACO2N | E49: 0 | F49: 1
A52: Effort sharing regulation 2010-2027 country-specific caps
...

Sheet ETS2CO2price
C1: Harmonised trajectory for the carbon price/value (EUR2020/tCO2)
C2: updated 08/2025 | E2: conversion EUR23->EUR20 | F2: 1.1941
C3: WEM-trajectory
C5: ~TFM_INS
C6: Attribute | D6: Year | E6: Other_indexes | F6: AllRegions | G6: UK | H6: Pset_PN | I6: Pset_Set | J6: Cset_CN | K6: Curr | N6: Values used in NEGEM
A7: Residential, commercial, agri, small industry | C7: COM_TAXPRD | D7: 2026 | F7: 0 | J7: RSDCO2N,COMCO2N,AGRCO2N,NETSCO2 | K7: EUR20
C8: COM_TAXPRD | D8: 2027 | F8: =0.03/F2 -> 0.025123524 | J8: RSDCO2N,COMCO2N,AGRCO2N,NETSCO2 | K8: EUR20
C9: COM_TAXPRD | D9: 2028 | F9: =0.05/F2 -> 0.04187254 | J9: =J8 -> RSDCO2N,COMCO2N,AGRCO2N,NETSCO2 | K9: =K8 -> EUR20
C10: COM_TAXPRD | D10: 2030 | F10: =0.06/F2 -> 0.050247048 | J10: RSDCO2N,COMCO2N,AGRCO2N,NETSCO2 | K10: EUR20 | N10: 0.06 | O10: EUR15
C11: COM_TAXPRD | D11: 2035 | F11: =0.1/F2 -> 0.08374508 | J11: RSDCO2N,COMCO2N,AGRCO2N,NETSCO2 | K11: EUR20 | N11: 0.073 | O11: EUR15
C12: COM_TAXPRD | D12: 2040 | F12: =0.105/F2 -> 0.087932334 | J12: RSDCO2N,COMCO2N,AGRCO2N,NETSCO2 | K12: EUR20 | N12: 0.082 | O12: EUR15
C13: COM_TAXPRD | D13: 2045 | F13: =0.16/F2 -> 0.13399213 | J13: RSDCO2N,COMCO2N,AGRCO2N,NETSCO2 | K13: EUR20 | N13: 0.124 | O13: EUR15
C14: COM_TAXPRD | D14: 2050 | F14: =0.19/F2 -> 0.15911565 | J14: RSDCO2N,COMCO2N,AGRCO2N,NETSCO2 | K14: EUR20 | N14: 0.153 | O14: EUR15
C15: COM_TAXPRD | D15: 2055 | F15: =0.22/F2 -> 0.18423918 | J15: RSDCO2N,COMCO2N,AGRCO2N,NETSCO2 | K15: EUR20 | N15: 0.153 | O15: EUR15
C16: COM_TAXPRD | D16: 0 | F16: 5 | J16: RSDCO2N,COMCO2N,AGRCO2N,NETSCO2 | K16: EUR20
A17: Transport excl. maritime, aviation | C17: COM_TAXPRD | D17: 2026 | F17: 0 | H17: BLDDSL,BLDDSL_RAI,BLDGSLE85,BLDGSLSP95,BLDGSLSP95E10,TRAGAS00,TRAGASH2C01,TRALPG00,BLD_RFNBO_DSL,BLD_RFNBO_RAI,BLD_RFNBO_GSL,BLD_RFNBO_GAS,-BLDJET,-TRAHFO00,-TRALFO00,-BLD_RFNBO_JET,-BLD_RFNBO_NAV | J17: SE_TRACO2N | K17: =K7 -> EUR20
C18: COM_TAXPRD | D18: 2027 | F18: =F8 -> 0.025123524 | H18: =H17 -> BLDDSL,BLDDSL_RAI,BLDGSLE85,BLDGSLSP95,BLDGSLSP95E10,TRAGAS00,TRAGASH2C01,TRALPG00,BLD_RFNBO_DSL,BLD_RFNBO_RAI,BLD_RFNBO_GSL,BLD_RFNBO_GAS,-BLDJET,-TRAHFO00,-TRALFO00,-BLD_RFNBO_JET,-BLD_RFNBO_NAV | J18: SE_TRACO2N | K18: =K8 -> EUR20
C19: COM_TAXPRD | D19: 2030 | F19: =F10 -> 0.050247048 | H19: =H18 -> BLDDSL,BLDDSL_RAI,BLDGSLE85,BLDGSLSP95,BLDGSLSP95E10,TRAGAS00,TRAGASH2C01,TRALPG00,BLD_RFNBO_DSL,BLD_RFNBO_RAI,BLD_RFNBO_GSL,BLD_RFNBO_GAS,-BLDJET,-TRAHFO00,-TRALFO00,-BLD_RFNBO_JET,-BLD_RFNBO_NAV | J19: SE_TRACO2N | K19: =K10 -> EUR20
C20: COM_TAXPRD | D20: 2035 | F20: =F11 -> 0.08374508 | H20: =H19 -> BLDDSL,BLDDSL_RAI,BLDGSLE85,BLDGSLSP95,BLDGSLSP95E10,TRAGAS00,TRAGASH2C01,TRALPG00,BLD_RFNBO_DSL,BLD_RFNBO_RAI,BLD_RFNBO_GSL,BLD_RFNBO_GAS,-BLDJET,-TRAHFO00,-TRALFO00,-BLD_RFNBO_JET,-BLD_RFNBO_NAV | J20: SE_TRACO2N | K20: =K11 -> EUR20
C21: COM_TAXPRD | D21: 2040 | F21: =F12 -> 0.087932334 | H21: =H20 -> BLDDSL,BLDDSL_RAI,BLDGSLE85,BLDGSLSP95,BLDGSLSP95E10,TRAGAS00,TRAGASH2C01,TRALPG00,BLD_RFNBO_DSL,BLD_RFNBO_RAI,BLD_RFNBO_GSL,BLD_RFNBO_GAS,-BLDJET,-TRAHFO00,-TRALFO00,-BLD_RFNBO_JET,-BLD_RFNBO_NAV | J21: SE_TRACO2N | K21: =K12 -> EUR20
C22: COM_TAXPRD | D22: 2045 | F22: =F13 -> 0.13399213 | H22: =H21 -> BLDDSL,BLDDSL_RAI,BLDGSLE85,BLDGSLSP95,BLDGSLSP95E10,TRAGAS00,TRAGASH2C01,TRALPG00,BLD_RFNBO_DSL,BLD_RFNBO_RAI,BLD_RFNBO_GSL,BLD_RFNBO_GAS,-BLDJET,-TRAHFO00,-TRALFO00,-BLD_RFNBO_JET,-BLD_RFNBO_NAV | J22: SE_TRACO2N | K22: =K13 -> EUR20
C23: COM_TAXPRD | D23: 2050 | F23: =F14 -> 0.15911565 | H23: =H22 -> BLDDSL,BLDDSL_RAI,BLDGSLE85,BLDGSLSP95,BLDGSLSP95E10,TRAGAS00,TRAGASH2C01,TRALPG00,BLD_RFNBO_DSL,BLD_RFNBO_RAI,BLD_RFNBO_GSL,BLD_RFNBO_GAS,-BLDJET,-TRAHFO00,-TRALFO00,-BLD_RFNBO_JET,-BLD_RFNBO_NAV | J23: SE_TRACO2N | K23: =K14 -> EUR20
C24: COM_TAXPRD | D24: 2055 | F24: =F15 -> 0.18423918 | H24: =H23 -> BLDDSL,BLDDSL_RAI,BLDGSLE85,BLDGSLSP95,BLDGSLSP95E10,TRAGAS00,TRAGASH2C01,TRALPG00,BLD_RFNBO_DSL,BLD_RFNBO_RAI,BLD_RFNBO_GSL,BLD_RFNBO_GAS,-BLDJET,-TRAHFO00,-TRALFO00,-BLD_RFNBO_JET,-BLD_RFNBO_NAV | J24: SE_TRACO2N | K24: =K15 -> EUR20
C25: COM_TAXPRD | D25: 0 | F25: =F16 -> 5 | H25: =H24 -> BLDDSL,BLDDSL_RAI,BLDGSLE85,BLDGSLSP95,BLDGSLSP95E10,TRAGAS00,TRAGASH2C01,TRALPG00,BLD_RFNBO_DSL,BLD_RFNBO_RAI,BLD_RFNBO_GSL,BLD_RFNBO_GAS,-BLDJET,-TRAHFO00,-TRALFO00,-BLD_RFNBO_JET,-BLD_RFNBO_NAV | J25: SE_TRACO2N | K25: =K16 -> EUR20
C29: WAM-trajectory
C31: DeActTFM_INS
C32: Attribute | D32: Year | E32: Other_indexes | F32: AllRegions | G32: UK | H32: Pset_PN | I32: Pset_Set | J32: Cset_CN | K32: Curr
A33: Residential, commercial, agri, small industry | C33: COM_TAXPRD | D33: 2026 | F33: =F7 -> 0 | J33: RSDCO2N,COMCO2N,AGRCO2N,NETSCO2 | K33: EUR20
C34: COM_TAXPRD | D34: 2027 | F34: =F8 -> 0.025123524 | J34: RSDCO2N,COMCO2N,AGRCO2N,NETSCO2 | K34: EUR20
C35: COM_TAXPRD | D35: 2030 | F35: =F10 -> 0.050247048 | J35: RSDCO2N,COMCO2N,AGRCO2N,NETSCO2 | K35: EUR20
C36: COM_TAXPRD | D36: 2035 | F36: =120/1000 -> 0.12 | J36: RSDCO2N,COMCO2N,AGRCO2N,NETSCO2 | K36: EUR20
C37: COM_TAXPRD | D37: 2040 | F37: =250/1000 -> 0.25 | J37: RSDCO2N,COMCO2N,AGRCO2N,NETSCO2 | K37: EUR20
C38: COM_TAXPRD | D38: 2045 | F38: =360/1000 -> 0.36 | J38: RSDCO2N,COMCO2N,AGRCO2N,NETSCO2 | K38: EUR20
C39: COM_TAXPRD | D39: 2050 | F39: =410/1000 -> 0.41 | J39: RSDCO2N,COMCO2N,AGRCO2N,NETSCO2 | K39: EUR20
C40: COM_TAXPRD | D40: 2060 | F40: =F39 -> 0.41 | J40: RSDCO2N,COMCO2N,AGRCO2N,NETSCO2 | K40: EUR20
C41: COM_TAXPRD | D41: 0 | F41: 5 | J41: RSDCO2N,COMCO2N,AGRCO2N,NETSCO2 | K41: EUR20
A42: Transport excl. maritime, aviation | C42: COM_TAXPRD | D42: 2026 | F42: 0 | H42: =H17 -> BLDDSL,BLDDSL_RAI,BLDGSLE85,BLDGSLSP95,BLDGSLSP95E10,TRAGAS00,TRAGASH2C01,TRALPG00,BLD_RFNBO_DSL,BLD_RFNBO_RAI,BLD_RFNBO_GSL,BLD_RFNBO_GAS,-BLDJET,-TRAHFO00,-TRALFO00,-BLD_RFNBO_JET,-BLD_RFNBO_NAV | J42: SE_TRACO2N | K42: EUR20
C43: COM_TAXPRD | D43: 2027 | F43: =F34 -> 0.025123524 | H43: =H42 -> BLDDSL,BLDDSL_RAI,BLDGSLE85,BLDGSLSP95,BLDGSLSP95E10,TRAGAS00,TRAGASH2C01,TRALPG00,BLD_RFNBO_DSL,BLD_RFNBO_RAI,BLD_RFNBO_GSL,BLD_RFNBO_GAS,-BLDJET,-TRAHFO00,-TRALFO00,-BLD_RFNBO_JET,-BLD_RFNBO_NAV | J43: SE_TRACO2N | K43: EUR20
C44: COM_TAXPRD | D44: 2030 | F44: =F35 -> 0.050247048 | H44: =H43 -> BLDDSL,BLDDSL_RAI,BLDGSLE85,BLDGSLSP95,BLDGSLSP95E10,TRAGAS00,TRAGASH2C01,TRALPG00,BLD_RFNBO_DSL,BLD_RFNBO_RAI,BLD_RFNBO_GSL,BLD_RFNBO_GAS,-BLDJET,-TRAHFO00,-TRALFO00,-BLD_RFNBO_JET,-BLD_RFNBO_NAV | J44: SE_TRACO2N | K44: EUR20
C45: COM_TAXPRD | D45: 2035 | F45: =F36 -> 0.12 | H45: =H44 -> BLDDSL,BLDDSL_RAI,BLDGSLE85,BLDGSLSP95,BLDGSLSP95E10,TRAGAS00,TRAGASH2C01,TRALPG00,BLD_RFNBO_DSL,BLD_RFNBO_RAI,BLD_RFNBO_GSL,BLD_RFNBO_GAS,-BLDJET,-TRAHFO00,-TRALFO00,-BLD_RFNBO_JET,-BLD_RFNBO_NAV | J45: SE_TRACO2N | K45: EUR20
...

Sheet Cap trajectories
A1: https://www.umweltbundesamt.de/sites/default/files/medien/11850/publikationen/factsheet_cap_msr_2023_en_v2.pdf | F1: 1954.5455 | N1: =-O10/N10 -> 1835.2222 | P1: https://climate.ec.europa.eu/eu-action/eu-emissions-trading-system-eu-ets/ets2-buildings-road-transport-and-additional-sectors_en
A2: https://climate.ec.europa.eu/news-your-voice/news/emissions-trading-system-buildings-road-transport-and-small-industry-ets2-cap-adopted-2027-2024-12-03_en | C2: Sum of ETS1 and ETS2 | D2: ETS1 Total Cap (new) | E2: Cap according to previous directive (without UK) | F2: LFR | G2: Annual cap reduction through LRFs (stationary) | H2: Rebasing the cap | I2: Cap stationary installations (new) | J2: Cap maritime transport | K2: Maritime cap reduction | M2: ETS2 Total Cap | N2: LFR | O2: Annual cap reduction through LFRs
A3: https://climate.ec.europa.eu/eu-action/eu-emissions-trading-system-eu-ets/about-eu-ets_en#our-climate-ambition-for-2030 | B3: 2018 | F3: 0.0174
B4: 2019 | F4: 0.0174
B5: 2020 | E5: =1615 -> 1615 | F5: 0.0174 | G5: =-$F$1*F5 -> -34.009091 | H5: 34
B6: 2021 | E6: =1572 -> 1572 | F6: 0.022 | G6: =-$F$1*F6 -> -43 | H6: 43
B7: 2022 | E7: =1529 -> 1529 | F7: 0.022 | G7: =-$F$1*F7 -> -43
B8: 2023 | E8: =1486 -> 1486 | F8: 0.022 | G8: =-$F$1*F8 -> -43
B9: 2024 | D9: =I9+J9 -> 1386.9545 | E9: 1443 | F9: 0.043 | G9: =-$F$1*F9 -> -84.045455 | H9: -90 | I9: =E8+G9+H9 -> 1311.9545 | J9: 75 | K9: =-$J$9*F9 -> -3.225
B10: 2025 | D10: =I10+J10 -> 1299.6841 | E10: 1400 | F10: 0.043 | G10: =-$F$1*F10 -> -84.045455 | I10: =I9+G10+H10 -> 1227.9091 | J10: =J9+K9 -> 71.775 | K10: =-$J$9*F10 -> -3.225 | M10: =1223481445/1000/1000 -> 1223.4814 | N10: 0.051 | O10: =-(M10-M12)/2 -> -93.596331 | P10: 1057014.6 | Q10: TRA | R10: AGR | S10: NETS | T10: others
B11: 2026 | D11: =I11+J11 -> 1185.4136 | E11: 1357 | F11: 0.043 | G11: =-$F$1*F11 -> -84.045455 | H11: -27 | I11: =I10+G11+H11 -> 1116.8636 | J11: =J10+K10 -> 68.55 | K11: =-$J$9*F11 -> -3.225 | M11: =M10+O11 -> 1129.8851 | N11: 0.051 | O11: =O10 -> -93.596331 | S11: 180000
B12: 2027 | D12: =I12+J12 -> 1098.1432 | E12: 1314 | F12: 0.043 | G12: =-$F$1*F12 -> -84.045455 | I12: =I11+G12+H12 -> 1032.8182 | J12: =J11+K11 -> 65.325 | K12: =-$J$9*F12 -> -3.225 | M12: =1036288784/1000/1000 -> 1036.2888 | N12: =N11 -> 0.051 | O12: =-N12*$N$1 -> -93.596331
B13: 2028 | D13: =I13+J13 -> 1008.9182 | E13: 1271 | F13: 0.044 | G13: =-$F$1*F13 -> -86 | I13: =I12+G13+H13 -> 946.81818 | J13: =J12+K12 -> 62.1 | K13: =-$J$9*F13 -> -3.3 | M13: =M12+O13 -> 937.55383 | N13: 0.0538 | O13: =-N13*$N$1 -> -98.734953
B14: 2029 | D14: =I14+J14 -> 919.61818 | E14: 1228 | F14: 0.044 | G14: =-$F$1*F14 -> -86 | I14: =I13+G14+H14 -> 860.81818 | J14: =J13+K13 -> 58.8 | K14: =-$J$9*F14 -> -3.3 | M14: =M13+O14 -> 838.81888 | N14: =N13 -> 0.0538 | O14: =-N14*$N$1 -> -98.734953
B15: 2030 | D15: =I15+J15 -> 830.31818 | E15: 1184 | F15: 0.044 | G15: =-$F$1*F15 -> -86 | I15: =I14+G15+H15 -> 774.81818 | J15: =J14+K14 -> 55.5 | K15: =-$J$9*F15 -> -3.3 | M15: =M14+O15 -> 740.08393 | N15: =N14 -> 0.0538 | O15: =-N15*$N$1 -> -98.734953 | P15: 1004163.8 | Q15: 500000 | R15: 16000 | S15: 100000 | T15: =P15-Q15-R15-S15 -> 388163.83
B16: 2031 | D16: =I16+J16 -> 741.01818 | F16: =F15 -> 0.044 | G16: =-$F$1*F16 -> -86 | I16: =I15+G16+H16 -> 688.81818 | J16: =J15+K15 -> 52.2 | K16: =-$J$9*F16 -> -3.3 | M16: =M15+O16 -> 641.34897 | N16: =N15 -> 0.0538 | O16: =-N16*$N$1 -> -98.734953 | P16: 1004163.8 | R16: =(R$20-R$15)/5+R15 -> 15800 | S16: =(S$20-S$15)/5+S15 -> 96000 | T16: =P16-Q16-R16-S16 -> 892363.83
B17: 2032 | D17: =I17+J17 -> 651.71818 | F17: =F16 -> 0.044 | G17: =-$F$1*F17 -> -86 | I17: =I16+G17+H17 -> 602.81818 | J17: =J16+K16 -> 48.9 | K17: =-$J$9*F17 -> -3.3 | M17: =M16+O17 -> 542.61402 | N17: =N16 -> 0.0538 | O17: =-N17*$N$1 -> -98.734953 | P17: 1004163.8 | R17: =(R$20-R$15)/5+R16 -> 15600 | S17: =(S$20-S$15)/5+S16 -> 92000 | T17: =P17-Q17-R17-S17 -> 896563.83
B18: 2033 | D18: =I18+J18 -> 562.41818 | F18: =F17 -> 0.044 | G18: =-$F$1*F18 -> -86 | I18: =I17+G18+H18 -> 516.81818 | J18: =J17+K17 -> 45.6 | K18: =-$J$9*F18 -> -3.3 | M18: =M17+O18 -> 443.87907 | N18: =N17 -> 0.0538 | O18: =-N18*$N$1 -> -98.734953 | P18: 1004163.8 | R18: =(R$20-R$15)/5+R17 -> 15400 | S18: =(S$20-S$15)/5+S17 -> 88000 | T18: =P18-Q18-R18-S18 -> 900763.83
B19: 2034 | D19: =I19+J19 -> 473.11818 | F19: =F18 -> 0.044 | G19: =-$F$1*F19 -> -86 | I19: =I18+G19+H19 -> 430.81818 | J19: =J18+K18 -> 42.3 | K19: =-$J$9*F19 -> -3.3 | M19: =M18+O19 -> 345.14412 | N19: =N18 -> 0.0538 | O19: =-N19*$N$1 -> -98.734953 | P19: 1004163.8 | R19: =(R$20-R$15)/5+R18 -> 15200 | S19: =(S$20-S$15)/5+S18 -> 84000 | T19: =P19-Q19-R19-S19 -> 904963.83
A20: ETS1 and 2 prices converge in 2035 | B20: 2035 | C20: =D20+M20 -> 630.22735 | D20: =I20+J20 -> 383.81818 | F20: =F19 -> 0.044 | G20: =-$F$1*F20 -> -86 | I20: =I19+G20+H20 -> 344.81818 | J20: =J19+K19 -> 39 | K20: =-$J$9*F20 -> -3.3 | M20: =M19+O20 -> 246.40916 | N20: =N19 -> 0.0538 | O20: =-N20*$N$1 -> -98.734953 | P20: 1004163.8 | R20: 15000 | S20: 80000 | T20: =P20-Q20-R20-S20 -> 909163.83
B21: 2036 | C21: =D21+M21 -> 442.19239 | D21: =I21+J21 -> 294.51818 | F21: =F20 -> 0.044 | G21: =-$F$1*F21 -> -86 | I21: =I20+G21+H21 -> 258.81818 | J21: =J20+K20 -> 35.7 | K21: =-$J$9*F21 -> -3.3 | M21: =M20+O21 -> 147.67421 | N21: =N20 -> 0.0538 | O21: =-N21*$N$1 -> -98.734953 | P21: 1004163.8 | R21: =(R$25-R$20)/5+R20 -> 14700 | S21: =(S$25-S$20)/5+S20 -> 76000 | T21: =P21-Q21-R21-S21 -> 913463.83
B22: 2037 | C22: =D22+M22 -> 254.15744 | D22: =I22+J22 -> 205.21818 | F22: =F21 -> 0.044 | G22: =-$F$1*F22 -> -86 | I22: =I21+G22+H22 -> 172.81818 | J22: =J21+K21 -> 32.4 | K22: =-$J$9*F22 -> -3.3 | M22: =M21+O22 -> 48.939258 | N22: =N21 -> 0.0538 | O22: =-N22*$N$1 -> -98.734953 | P22: 1004163.8 | R22: =(R$25-R$20)/5+R21 -> 14400 | S22: =(S$25-S$20)/5+S21 -> 72000 | T22: =P22-Q22-R22-S22 -> 917763.83
A23: With these assumptions | B23: 2038 | C23: =D23+M23 -> 66.122488 | D23: =I23+J23 -> 115.91818 | F23: =F22 -> 0.044 | G23: =-$F$1*F23 -> -86 | I23: =I22+G23+H23 -> 86.818182 | J23: =J22+K22 -> 29.1 | K23: =-$J$9*F23 -> -3.3 | M23: =M22+O23 -> -49.795694 | N23: =N22 -> 0.0538 | O23: =-N23*$N$1 -> -98.734953 | P23: 1004163.8 | R23: =(R$25-R$20)/5+R22 -> 14100 | S23: =(S$25-S$20)/5+S22 -> 68000 | T23: =P23-Q23-R23-S23 -> 922063.83
A24: the emission cap becomes negative before 2040 | B24: 2039 | C24: =D24+M24 -> -121.91246 | D24: =I24+J24 -> 26.618182 | F24: =F23 -> 0.044 | G24: =-$F$1*F24 -> -86 | I24: =I23+G24+H24 -> 0.81818182 | J24: =J23+K23 -> 25.8 | K24: =-$J$9*F24 -> -3.3 | M24: =M23+O24 -> -148.53065 | N24: =N23 -> 0.0538 | O24: =-N24*$N$1 -> -98.734953 | P24: 1004163.8 | R24: =(R$25-R$20)/5+R23 -> 13800 | S24: =(S$25-S$20)/5+S23 -> 64000 | T24: =P24-Q24-R24-S24 -> 926363.83
A25: We cannot really implement an emission cap that far | B25: 2040 | C25: =D25+M25 -> -309.94742 | D25: =I25+J25 -> -62.681818 | F25: =F24 -> 0.044 | G25: =-$F$1*F25 -> -86 | I25: =I24+G25+H25 -> -85.181818 | J25: =J24+K24 -> 22.5 | K25: =-$J$9*F25 -> -3.3 | M25: =M24+O25 -> -247.2656 | N25: =N24 -> 0.0538 | O25: =-N25*$N$1 -> -98.734953 | P25: 1004163.8 | R25: 13500 | S25: 60000 | T25: =P25-Q25-R25-S25 -> 930663.83
A26: We have the price mechanism in place | B26: 2041 | C26: =D26+M26 -> -497.98237 | D26: =I26+J26 -> -151.98182 | F26: =F25 -> 0.044 | G26: =-$F$1*F26 -> -86 | I26: =I25+G26+H26 -> -171.18182 | J26: =J25+K25 -> 19.2 | K26: =-$J$9*F26 -> -3.3 | M26: =M25+O26 -> -346.00055 | N26: =N25 -> 0.0538 | O26: =-N26*$N$1 -> -98.734953 | P26: 1004163.8 | R26: =(R$30-R$25)/5+R25 -> 13400 | S26: =(S$30-S$25)/5+S25 -> 59000 | T26: =P26-Q26-R26-S26 -> 931763.83
A27: we can first try to set emission cap to 2030 | B27: 2042 | C27: =D27+M27 -> -686.01732 | D27: =I27+J27 -> -241.28182 | F27: =F26 -> 0.044 | G27: =-$F$1*F27 -> -86 | I27: =I26+G27+H27 -> -257.18182 | J27: =J26+K26 -> 15.9 | K27: =-$J$9*F27 -> -3.3 | M27: =M26+O27 -> -444.7355 | N27: =N26 -> 0.0538 | O27: =-N27*$N$1 -> -98.734953 | P27: 1004163.8 | R27: =(R$30-R$25)/5+R26 -> 13300 | S27: =(S$30-S$25)/5+S26 -> 58000 | T27: =P27-Q27-R27-S27 -> 932863.83
B28: 2043 | C28: =D28+M28 -> -874.05228 | D28: =I28+J28 -> -330.58182 | F28: =F27 -> 0.044 | G28: =-$F$1*F28 -> -86 | I28: =I27+G28+H28 -> -343.18182 | J28: =J27+K27 -> 12.6 | K28: =-$J$9*F28 -> -3.3 | M28: =M27+O28 -> -543.47046 | N28: =N27 -> 0.0538 | O28: =-N28*$N$1 -> -98.734953 | P28: 1004163.8 | R28: =(R$30-R$25)/5+R27 -> 13200 | S28: =(S$30-S$25)/5+S27 -> 57000 | T28: =P28-Q28-R28-S28 -> 933963.83
B29: 2044 | C29: =D29+M29 -> -1062.0872 | D29: =I29+J29 -> -419.88182 | F29: =F28 -> 0.044 | G29: =-$F$1*F29 -> -86 | I29: =I28+G29+H29 -> -429.18182 | J29: =J28+K28 -> 9.3 | K29: =-$J$9*F29 -> -3.3 | M29: =M28+O29 -> -642.20541 | N29: =N28 -> 0.0538 | O29: =-N29*$N$1 -> -98.734953 | P29: 1004163.8 | R29: =(R$30-R$25)/5+R28 -> 13100 | S29: =(S$30-S$25)/5+S28 -> 56000 | T29: =P29-Q29-R29-S29 -> 935063.83
B30: 2045 | C30: =D30+M30 -> -1250.1222 | D30: =I30+J30 -> -509.18182 | F30: =F29 -> 0.044 | G30: =-$F$1*F30 -> -86 | I30: =I29+G30+H30 -> -515.18182 | J30: =J29+K29 -> 6 | K30: =-$J$9*F30 -> -3.3 | M30: =M29+O30 -> -740.94036 | N30: =N29 -> 0.0538 | O30: =-N30*$N$1 -> -98.734953 | P30: 1004163.8 | R30: 13000 | S30: 55000 | T30: =P30-Q30-R30-S30 -> 936163.83
B31: 2046 | C31: =D31+M31 -> -598.48182 | D31: =I31+J31 -> -598.48182 | F31: =F30 -> 0.044 | G31: =-$F$1*F31 -> -86 | I31: =I30+G31+H31 -> -601.18182 | J31: =J30+K30 -> 2.7 | K31: =-$J$9*F31 -> -3.3 | N31: =N30 -> 0.0538 | P31: 1004163.8 | R31: =(R$35-R$30)/5+R30 -> 12700 | S31: =(S$35-S$30)/5+S30 -> 54000 | T31: =P31-Q31-R31-S31 -> 937463.83
B32: 2047 | F32: =F31 -> 0.044 | G32: =-$F$1*F32 -> -86 | N32: =N31 -> 0.0538 | P32: 1004163.8 | R32: =(R$35-R$30)/5+R31 -> 12400 | S32: =(S$35-S$30)/5+S31 -> 53000 | T32: =P32-Q32-R32-S32 -> 938763.83
B33: 2048 | F33: =F32 -> 0.044 | G33: =-$F$1*F33 -> -86 | N33: =N32 -> 0.0538 | P33: 1004163.8 | R33: =(R$35-R$30)/5+R32 -> 12100 | S33: =(S$35-S$30)/5+S32 -> 52000 | T33: =P33-Q33-R33-S33 -> 940063.83
B34: 2049 | F34: =F33 -> 0.044 | G34: =-$F$1*F34 -> -86 | N34: =N33 -> 0.0538 | P34: 1004163.8 | R34: =(R$35-R$30)/5+R33 -> 11800 | S34: =(S$35-S$30)/5+S33 -> 51000 | T34: =P34-Q34-R34-S34 -> 941363.83
B35: 2050 | F35: =F34 -> 0.044 | G35: =-$F$1*F35 -> -86 | N35: =N34 -> 0.0538 | P35: 1004163.8 | R35: 11500 | S35: 50000 | T35: =P35-Q35-R35-S35 -> 942663.83
B36: 2051 | F36: =F35 -> 0.044 | G36: =-$F$1*F36 -> -86 | N36: =N35 -> 0.0538
B37: 2052 | F37: =F36 -> 0.044 | G37: =-$F$1*F37 -> -86 | N37: =N36 -> 0.0538
B38: 2053 | F38: =F37 -> 0.044 | G38: =-$F$1*F38 -> -86 | N38: =N37 -> 0.0538
B39: 2054 | F39: =F38 -> 0.044 | G39: =-$F$1*F39 -> -86 | N39: =N38 -> 0.0538
B40: 2055 | F40: =F39 -> 0.044 | G40: =-$F$1*F40 -> -86 | N40: =N39 -> 0.0538
...

Sheet esr2023
A1: Country-specific emissions from sectors regulated under Effort Sharing Regulation (ESR) | L1: source: UNFCCC, national CRF-tables from 2023 submission
A2: nfr_code | B2: nfr_category | C2: period | D2: emission | E2: AT | F2: BE | G2: BG | H2: CH | I2: CY | J2: CZ | K2: DE | L2: DK | M2: EE | N2: EL | O2: ES | P2: FI | Q2: FR | R2: HR | S2: HU | T2: IE | U2: IS | V2: IT | W2: LT | X2: LU | Y2: LV | Z2: MT | AA2: NL | AB2: NO | AC2: PL | AD2: PT | AE2: RO | AF2: SE | AG2: SI | AH2: SK
A3: 1A2 | B3: manufacturing and construction | C3: 2005 | D3: co2 | E3: 11210.77 | F3: 18765.899 | G3: 7045.4144 | H3: 6000.1132 | I3: 908.28368 | J3: 18715.291 | K3: 112500.13 | L3: 5615.2854 | M3: 1031.1009 | N3: 10134.373 | O3: 68319.412 | P3: 11186.178 | Q3: 67022.669 | R3: 3724.0224 | S3: 4564.972 | T3: 5411.4128 | U3: 287.03489 | V3: 90785.927 | W3: 1468.6653 | X3: 1357.685 | Y3: 1143.5875 | Z3: 27.7609 | AA3: 28673.868 | AB3: 3201.2666 | AC3: 33669.648 | AD3: 10406.65 | AE3: 17387.024 | AF3: 9913.133 | AG3: 2432.7456 | AH3: 8530.1712
A4: 1A2 | B4: manufacturing and construction | C4: 2010 | D4: co2 | E4: 11039.268 | F4: 15752.003 | G4: 3128.4849 | H4: 5820.3791 | I4: 696.57832 | J4: 12021.164 | K4: 123316.96 | L4: 4548.0704 | M4: 788.16452 | N4: 6813.2422 | O4: 48780.971 | P4: 9890.891 | Q4: 58156.801 | R4: 3015.7996 | S4: 3343.7316 | T4: 4176.8384 | U4: 132.83086 | V4: 68899.428 | W4: 1273.6604 | X4: 1257.2431 | Y4: 1073.7097 | Z4: 30.7538 | AA4: 28348.437 | AB4: 3319.2843 | AC4: 29402.607 | AD4: 9030.9547 | AE4: 14958.162 | AF4: 8459.0328 | AG4: 1910.1106 | AH4: 7612.5109
A5: 1A2 | B5: manufacturing and construction | C5: 2015 | D5: co2 | E5: 10066.037 | F5: 13601.027 | G5: 2819.7098 | H5: 4939.6188 | I5: 600.15824 | J5: 9770.6661 | K5: 125161.59 | L5: 3909.9611 | M5: 653.27812 | N5: 5166.2808 | O5: 41127.242 | P5: 6594.9574 | Q5: 50544.263 | R5: 2222.7049 | S5: 4114.9848 | T5: 4289.0236 | U5: 111.54866 | V5: 54552.43 | W5: 1167.4249 | X5: 1132.8741 | Y5: 640.33502 | Z5: 59.7014 | AA5: 25414.113 | AB5: 2870.5025 | AC5: 27703.778 | AD5: 7681.7595 | AE5: 12979.525 | AF5: 6887.024 | AG5: 1584.3376 | AH5: 6713.2272
A6: 1A2 | B6: manufacturing and construction | C6: 2019 | D6: co2 | E6: 10687.497 | F6: 13757.108 | G6: 4144.7757 | H6: 4664.3678 | I6: 559.8812 | J6: 9673.4924 | K6: 121411.41 | L6: 3865.3886 | M6: 711.73633 | N6: 4568.5001 | O6: 45648.958 | P6: 6415.0236 | Q6: 48143.575 | R6: 2421.1092 | S6: 5102.4258 | T6: 4604.1388 | U6: 67.411306 | V6: 48972.331 | W6: 1277.6707 | X6: 1218.8898 | Y6: 625.85299 | Z6: 47.1169 | AA6: 26826.925 | AB6: 2871.6025 | AC6: 30876.566 | AD6: 7676.64 | AE6: 13285.769 | AF6: 6714.2124 | AG6: 1724.9512 | AH6: 6278.5491
A7: 1A2 | B7: manufacturing and construction | C7: 2021 | D7: co2 | E7: 10791.715 | F7: 13841.213 | G7: 4526.9116 | H7: 4553.8686 | I7: 522.07011 | J7: 12770.409 | K7: 124987.07 | L7: 3841.4293 | M7: 393.76103 | N7: 4779.7906 | O7: 45392.126 | P7: 6248.5201 | Q7: 46852.479 | R7: 2418.0554 | S7: 5160.2044 | T7: 4603.5374 | U7: 73.092722 | V7: 52790.841 | W7: 1256.5682 | X7: 1170.7087 | Y7: 604.43721 | Z7: 54.256068 | AA7: 27715.638 | AB7: 2806.4473 | AC7: 29829.41 | AD7: 7165.5326 | AE7: 14439.109 | AF7: 6170.3863 | AG7: 1709.6852 | AH7: 6983.4361
A8: 1A2 | B8: manufacturing and construction | C8: 2005 | D8: ghg | E8: 11361.375 | F8: 18932.735 | G8: 7080.9271 | H8: 6038.6832 | I8: 911.90385 | J8: 18842.922 | K8: 113411.35 | L8: 5695.1067 | M8: 1036.6403 | N8: 10228.094 | O8: 69884.339 | P8: 11349.848 | Q8: 67707.448 | R8: 3738.8895 | S8: 4585.48 | T8: 5441.004 | U8: 298.43638 | V8: 92297.892 | W8: 1489.1234 | X8: 1373.4924 | Y8: 1168.498 | Z8: 27.841896 | AA8: 28774.71 | AB8: 3248.6739 | AC8: 33872.335 | AD8: 10612.917 | AE8: 17462.906 | AF8: 10042.182 | AG8: 2461.1035 | AH8: 8576.3822
A9: 1A2 | B9: manufacturing and construction | C9: 2010 | D9: ghg | E9: 11188.458 | F9: 15956.984 | G9: 3156.8398 | H9: 5860.0855 | I9: 699.92058 | J9: 12112.491 | K9: 124357.93 | L9: 4618.5999 | M9: 792.99728 | N9: 6891.8964 | O9: 49845.088 | P9: 10029.705 | Q9: 58669.965 | R9: 3029.7243 | S9: 3361.7574 | T9: 4198.7829 | U9: 138.32381 | V9: 70057.554 | W9: 1287.7835 | X9: 1270.1062 | Y9: 1107.0342 | Z9: 30.838032 | AA9: 28453.774 | AB9: 3369.1768 | AC9: 29615.727 | AD9: 9228.5784 | AE9: 15029.909 | AF9: 8601.2185 | AG9: 1932.3035 | AH9: 7664.1834
A10: 1A2 | B10: manufacturing and construction | C10: 2015 | D10: ghg | E10: 10203.683 | F10: 13839.838 | G10: 2857.0207 | H10: 4976.0807 | I10: 603.57747 | J10: 9869.8514 | K10: 126220.25 | L10: 3968.7463 | M10: 658.4329 | N10: 5242.5359 | O10: 42193.862 | P10: 6742.0462 | Q10: 51122.431 | R10: 2231.7607 | S10: 4139.3748 | T10: 4309.6296 | U10: 117.08849 | V10: 55579.189 | W10: 1182.2653 | X10: 1144.719 | Y10: 687.38949 | Z10: 59.881994 | AA10: 25517.634 | AB10: 2916.1112 | AC10: 27954.155 | AD10: 7836.3949 | AE10: 13044.102 | AF10: 7019.7615 | AG10: 1604.6914 | AH10: 6768.9927
A11: 1A2 | B11: manufacturing and construction | C11: 2019 | D11: ghg | E11: 10817.816 | F11: 13894.027 | G11: 4194.8993 | H11: 4702.1748 | I11: 566.08827 | J11: 9780.4198 | K11: 122454.9 | L11: 3942.7876 | M11: 717.90551 | N11: 4615.86 | O11: 46924.812 | P11: 6576.5296 | Q11: 48746.362 | R11: 2431.8295 | S11: 5145.7818 | T11: 4624.7925 | U11: 71.622222 | V11: 49957.988 | W11: 1296.1108 | X11: 1237.3157 | Y11: 674.09403 | Z11: 47.244026 | AA11: 26933.847 | AB11: 2917.2478 | AC11: 31186.789 | AD11: 7833.4929 | AE11: 13344.463 | AF11: 6851.419 | AG11: 1747.2447 | AH11: 6327.4906
A12: 1A2 | B12: manufacturing and construction | C12: 2021 | D12: ghg | E12: 10923.187 | F12: 13994.971 | G12: 4573.3307 | H12: 4593.9091 | I12: 530.62289 | J12: 12892.674 | K12: 126071.77 | L12: 3919.9702 | M12: 398.81916 | N12: 4825.4358 | O12: 46696.838 | P12: 6408.6057 | Q12: 47444.318 | R12: 2430.3557 | S12: 5210.7796 | T12: 4624.4737 | U12: 76.640332 | V12: 53863.41 | W12: 1275.0044 | X12: 1193.9013 | Y12: 655.60003 | Z12: 54.411881 | AA12: 27830.43 | AB12: 2853.1677 | AC12: 30106.351 | AD12: 7335.2541 | AE12: 14511.482 | AF12: 6300.6508 | AG12: 1732.555 | AH12: 7032.3162
A13: 1A2 | B13: manufacturing and construction | C13: 2005 | D13: nonco2 | E13: 150.60578 | F13: 166.83599 | G13: 35.512779 | H13: 38.570085 | I13: 3.6201684 | J13: 127.63124 | K13: 911.21749 | L13: 79.821267 | M13: 5.5393499 | N13: 93.72065 | O13: 1564.9275 | P13: 163.67004 | Q13: 684.77943 | R13: 14.867092 | S13: 20.507932 | T13: 29.591276 | U13: 11.401488 | V13: 1511.9644 | W13: 20.458096 | X13: 15.807387 | Y13: 24.910487 | Z13: 0.080996 | AA13: 100.84149 | AB13: 47.407326 | AC13: 202.68709 | AD13: 206.26718 | AE13: 75.881992 | AF13: 129.04937 | AG13: 28.357838 | AH13: 46.21109
A14: 1A2 | B14: manufacturing and construction | C14: 2010 | D14: nonco2 | E14: 149.19004 | F14: 204.98056 | G14: 28.354908 | H14: 39.706391 | I14: 3.3422619 | J14: 91.327356 | K14: 1040.973 | L14: 70.529454 | M14: 4.832753 | N14: 78.654238 | O14: 1064.1174 | P14: 138.81406 | Q14: 513.16428 | R14: 13.924682 | S14: 18.025837 | T14: 21.944443 | U14: 5.4929502 | V14: 1158.1264 | W14: 14.123085 | X14: 12.863171 | Y14: 33.324497 | Z14: 0.084232 | AA14: 105.33677 | AB14: 49.892459 | AC14: 213.11971 | AD14: 197.6237 | AE14: 71.747088 | AF14: 142.18569 | AG14: 22.192983 | AH14: 51.672568
... A152: total (3,5) | B152: nonmodelled ESR sectors | C152: 2021 | D152: nonco2 | E152: 8280.3986 | F152: 10210.14 | G152: 8875.0019 | H152: 6985.1244 | I152: 1219.5125 | J152: 13128.026 | K152: 58238.926 | L152: 13131.34 | M152: 1871.878 | N152: 13861.365 | O152: 48279.205 | P152: 7919.7262 | Q152: 81325.047 | R152: 4475.3321 | S152: 10674.411 | T152: 23163.184 | U152: 872.74525 | V152: 52360.155 | W152: 5103.7352 | X152: 771.98929 | Y152: 2734.5826 | Z152: 288.21223 | AA152: 21401.774 | AB152: 5852.012 | AC152: 37023.302 | AD152: 12198.132 | AE152: 25532.771 | AF152: 7415.4719 | AG152: 2198.5802 | AH152: 4244.0001
