Workbook
Name conv: 'common data'!#REF!
Name conv: 'common data'!#REF!
Name discount: 'common data'!#REF!
Name discount: 'common data'!#REF!
Name period: #REF!

Sheet common data
A2: Conversion factors
G5: Tc | H5: 1100
A6: 1 year = | B6: =24*365 -> 8760 | C6: hours | G6: Tf | H6: 30
A7: 1kWh e = | B7: 7 | C7: kWh th | G7: Carnot | H7: =(H5+273-H6-273)/(H5+273) -> 0.77931537
A9: Conversion energy units
B10: 1 | C10: PJ | D10: = | F10: GWh
B11: 1 | C11: GJ | E11: 277.8 | F11: kWh
B12: 1 | C12: MJ | E12: =B12/3600*1000 -> 0.27777778 | F12: kWh
B13: =1000000000000000 -> 1e+15 | C13: Ws
B14: =B13/3600 -> 2.7777778e+11 | C14: wh
B15: =B14/1000000000 -> 277.77778 | C15: GWh
J17: =416/C29 -> 11162.779
A18: Basic Unit Conversion Factors
A19: 1BOE | B19: 6.1 | C19: GJ
A20: 1 MBTU GAS | B20: 1.054 | C20: GJ
A21: 1 TOE | B21: 41.868 | C21: GJ
A22: 1 Kwh | B22: 0.0036 | C22: GJ | E22: 1PJ = | F22: =1/B22 -> 277.77778 | G22: GWh | H22: =F22*1000000 -> 2.7777778e+08 | I22: kWh
A23: 1 t coal | B23: 28.1 | C23: GJ
A24: 10e7kcal | B24: 41.84 | C24: GJ
A25: GW | B25: 31.536 | C25: PJ
A27: IEA source | C27: GJ/L | D27: TOE/TON | E27: KG/L | F27: L/TOE
B28: Gasoline | C28: =$B$21/F28 -> 0.034943033 | D28: 1.07 | E28: 0.78 | F28: =1000/(D28*E28) -> 1198.1788
B29: Diesel | C29: =$B$21/F29 -> 0.037266707 | D29: 1.035 | E29: 0.86 | F29: =1000/(D29*E29) -> 1123.4693
C30: GJ/1000l | D30: TOE/TON | E30: KG/L | F30: L/TOE | G30: GJ/ton
B31: Light fuel | C31: =(B21/F31)*1000 -> 36.375421 | D31: 1.0343 | E31: 0.84 | F31: =1000/(D31*E31) -> 1150.997 | G31: =D31*B21 -> 43.304072
C32: GJ/ton | D32: TOE/TON | E32: KG/L | F32: L/TOE
B33: Heavy Fuel Oil | C33: =D33*B21 -> 40.19328 | D33: 0.96 | E33: 0.95 | F33: =1000/(D33*E33) -> 1096.4912
A37: Exchange Rates
B38: NC/EURO | C38: Conversion Factor for IEA prices in EURO
B39: 2000 | C39: 2000 | D39: 2005
A40: EX_AT | B40: 13.7603 | C40: =1 -> 1
A41: EX_BE | B41: 40.3399 | C41: =1 -> 1
A42: EX_DE | B42: 1.95583 | C42: =1 -> 1
A43: EX_DK | B43: 7.4621835 | C43: =1/B43 -> 0.13400903
A44: EX_FI | B44: 5.94573 | C44: =1 -> 1
A45: EX_FR | B45: 6.55957 | C45: =1 -> 1
A46: EX_EL | B46: 340.75 | C46: =1 -> 1
A47: EX_IE | B47: 0.787564 | C47: =1 -> 1
A48: EX_IT | B48: 1.93627 | C48: =1 -> 1
A49: EX_NL | B49: 2.20371 | C49: =1 -> 1
...

Sheet REF2016 Prices
A1: Energy Trends Reference Scenario 2015
A4: USD of 2010 per boe
B5: 2010 | C5: 2020 | D5: 2030 | E5: 2040 | F5: 2050
A6: Oil
A7: Reference | B7: 79.5 | C7: 84.7 | D7: 106.7 | E7: 117.9 | F7: 123.4
A8: High prices
A9: Low Prices
A10: Gas
A11: Reference | B11: 50.2 | C11: 54.8 | D11: 64.6 | E11: 71.3 | F11: 73.9
A12: High prices
A13: Low Prices
A14: Coal
A15: Reference | B15: 21.2 | C15: 16.2 | D15: 23.3 | E15: 25.8 | F15: 27.4
A16: High prices
A17: Low Prices
B19: 2010 | C19: 2020 | D19: 2030 | E19: 2040 | F19: 2050
A20: Oil P Ref | B20: =B7 -> 79.5 | C20: =C7 -> 84.7 | D20: =D7 -> 106.7 | E20: =E7 -> 117.9 | F20: =F7 -> 123.4
A21: Oil P High | B21: =B8 -> 0 | C21: =C8 -> 0 | D21: =D8 -> 0 | E21: =E8 -> 0 | F21: =F8 -> 0
A22: Oil P Low | B22: =B9 -> 0 | C22: =C9 -> 0 | D22: =D9 -> 0 | E22: =E9 -> 0 | F22: =F9 -> 0
A23: Oil T Ref | B23: =[1]POLES!E33 -> 73.831733 | C23: =[1]POLES!G33 -> 84.358357 | D23: =[1]POLES!I33 -> 98.131828 | E23: =[1]POLES!L33 -> 111.98185 | F23: =[1]POLES!M33 -> 114.64982
A24: Oil T Base | B24: =[1]POLES!E36 -> 73.831733 | C24: =[1]POLES!G36 -> 90.109361 | D24: =[1]POLES!I36 -> 112.99791 | E24: =[1]POLES!L36 -> 153.88672 | F24: =[1]POLES!M36 -> 165.75298
A25: Gas P Ref | B25: =B11 -> 50.2 | C25: =C11 -> 54.8 | D25: =D11 -> 64.6 | E25: =E11 -> 71.3 | F25: =F11 -> 73.9
A26: Gas P High | B26: =B12 -> 0 | C26: =C12 -> 0 | D26: =D12 -> 0 | E26: =E12 -> 0 | F26: =F12 -> 0
A27: Gas P Low | B27: =B13 -> 0 | C27: =C13 -> 0 | D27: =D13 -> 0 | E27: =E13 -> 0 | F27: =F13 -> 0
A28: Gas T Ref | B28: =[1]POLES!E34 -> 23.142718 | C28: =[1]POLES!G34 -> 30.903103 | D28: =[1]POLES!I34 -> 34.341529 | E28: =[1]POLES!L34 -> 40.063973 | F28: =[1]POLES!M34 -> 41.104371
A29: Gas T Base | B29: =[1]POLES!E37 -> 23.212543 | C29: =[1]POLES!G37 -> 32.526848 | D29: =[1]POLES!I37 -> 39.069219 | E29: =[1]POLES!L37 -> 53.876146 | F29: =[1]POLES!M37 -> 60.097385
A30: Coal P Ref | B30: =B15 -> 21.2 | C30: =C15 -> 16.2 | D30: =D15 -> 23.3 | E30: =E15 -> 25.8 | F30: =F15 -> 27.4
A31: Coal P High | B31: =B16 -> 0 | C31: =C16 -> 0 | D31: =D16 -> 0 | E31: =E16 -> 0 | F31: =F16 -> 0
A32: Coal P Low | B32: =B17 -> 0 | C32: =C17 -> 0 | D32: =D17 -> 0 | E32: =E17 -> 0 | F32: =F17 -> 0
A33: Coal T Ref | B33: =[1]POLES!E35 -> 14.942496 | C33: =[1]POLES!G35 -> 16.37357 | D33: =[1]POLES!I35 -> 17.667871 | E33: =[1]POLES!L35 -> 19.549739 | F33: =[1]POLES!M35 -> 20.141291
A34: Coal T Base | B34: =[1]POLES!E38 -> 14.943538 | C34: =[1]POLES!G38 -> 16.961579 | D34: =[1]POLES!I38 -> 18.480519 | E34: =[1]POLES!L38 -> 20.618706 | F34: =[1]POLES!M38 -> 21.306766
A36: Updated from EU 2024
A37: PRIMES in eur 2010/GJ
B38: 2010 | C38: 2020 | D38: 2030 | E38: 2040 | F38: 2050
A39: Oil
A40: Reference | B40: =B53/'common data'!$B$19 -> 9.8196721 | C40: 9.31 | D40: 13.65 | E40: 14.45 | F40: 17.47
A41: High prices
A42: Low Prices
A43: Gas
A44: Reference | B44: =B54/'common data'!$B$19 -> 6.1967213 | C44: 13.39 | D44: 7 | E44: 7 | F44: 7
...

Sheet PRIMESprices SEC 2011
A1: Energy 2050 Roadmap. Impact assessment 1 - including Part 1 of Annex 1 "Scenarios - assumptions and results" [SEC(2011)1565/1]
A2: http://ec.europa.eu/energy/energy2020/roadmap/doc/sec_2011_1565_part1.pdf
A3: Annex 1 Table 3: Energy import prices in the Reference scenario and low and high price variants
A4: USD of 2008 per boe
B5: 2010 | C5: 2020 | D5: 2030 | E5: 2040 | F5: 2050
A6: Oil
A7: Reference | B7: 84.6 | C7: 88.4 | D7: 105.9 | E7: 116.2 | F7: 126.8
A8: High prices | B8: 84.6 | C8: 132.2 | D8: 149.3 | E8: 148.8 | F8: 162.3
A9: Low Prices | B9: 84.6 | C9: 78.8 | D9: 91.5 | E9: 87.9 | F9: 83.9
A10: Gas
A11: Reference | B11: 53.5 | C11: 62.1 | D11: 76.6 | E11: 86.8 | F11: 98.4
A12: High prices | B12: 53.5 | C12: 85.5 | D12: 101.5 | E12: 111.6 | F12: 129
A13: Low Prices | B13: 53.5 | C13: 43.7 | D13: 50.9 | E13: 49.9 | F13: 54.1
A14: Coal
A15: Reference | B15: 22.6 | C15: 28.7 | D15: 32.6 | E15: 32.6 | F15: 33.5
A16: High prices | B16: 22.6 | C16: 39.3 | D16: 45.7 | E16: 42 | F16: 40
A17: Low Prices | B17: 22.6 | C17: 21.9 | D17: 23.8 | E17: 22.2 | F17: 23.1
B19: 2010 | C19: 2020 | D19: 2030 | E19: 2040 | F19: 2050
A20: Oil P Ref | B20: =B7 -> 84.6 | C20: =C7 -> 88.4 | D20: =D7 -> 105.9 | E20: =E7 -> 116.2 | F20: =F7 -> 126.8
A21: Oil P High | B21: =B8 -> 84.6 | C21: =C8 -> 132.2 | D21: =D8 -> 149.3 | E21: =E8 -> 148.8 | F21: =F8 -> 162.3
A22: Oil P Low | B22: =B9 -> 84.6 | C22: =C9 -> 78.8 | D22: =D9 -> 91.5 | E22: =E9 -> 87.9 | F22: =F9 -> 83.9
A23: Oil T Ref | B23: =[1]POLES!E33 -> 73.831733 | C23: =[1]POLES!G33 -> 84.358357 | D23: =[1]POLES!I33 -> 98.131828 | E23: =[1]POLES!L33 -> 111.98185 | F23: =[1]POLES!M33 -> 114.64982
A24: Oil T Base | B24: =[1]POLES!E36 -> 73.831733 | C24: =[1]POLES!G36 -> 90.109361 | D24: =[1]POLES!I36 -> 112.99791 | E24: =[1]POLES!L36 -> 153.88672 | F24: =[1]POLES!M36 -> 165.75298
A25: Gas P Ref | B25: =B11 -> 53.5 | C25: =C11 -> 62.1 | D25: =D11 -> 76.6 | E25: =E11 -> 86.8 | F25: =F11 -> 98.4
A26: Gas P High | B26: =B12 -> 53.5 | C26: =C12 -> 85.5 | D26: =D12 -> 101.5 | E26: =E12 -> 111.6 | F26: =F12 -> 129
A27: Gas P Low | B27: =B13 -> 53.5 | C27: =C13 -> 43.7 | D27: =D13 -> 50.9 | E27: =E13 -> 49.9 | F27: =F13 -> 54.1
A28: Gas T Ref | B28: =[1]POLES!E34 -> 23.142718 | C28: =[1]POLES!G34 -> 30.903103 | D28: =[1]POLES!I34 -> 34.341529 | E28: =[1]POLES!L34 -> 40.063973 | F28: =[1]POLES!M34 -> 41.104371
A29: Gas T Base | B29: =[1]POLES!E37 -> 23.212543 | C29: =[1]POLES!G37 -> 32.526848 | D29: =[1]POLES!I37 -> 39.069219 | E29: =[1]POLES!L37 -> 53.876146 | F29: =[1]POLES!M37 -> 60.097385
A30: Coal P Ref | B30: =B15 -> 22.6 | C30: =C15 -> 28.7 | D30: =D15 -> 32.6 | E30: =E15 -> 32.6 | F30: =F15 -> 33.5
A31: Coal P High | B31: =B16 -> 22.6 | C31: =C16 -> 39.3 | D31: =D16 -> 45.7 | E31: =E16 -> 42 | F31: =F16 -> 40
A32: Coal P Low | B32: =B17 -> 22.6 | C32: =C17 -> 21.9 | D32: =D17 -> 23.8 | E32: =E17 -> 22.2 | F32: =F17 -> 23.1
A33: Coal T Ref | B33: =[1]POLES!E35 -> 14.942496 | C33: =[1]POLES!G35 -> 16.37357 | D33: =[1]POLES!I35 -> 17.667871 | E33: =[1]POLES!L35 -> 19.549739 | F33: =[1]POLES!M35 -> 20.141291
A34: Coal T Base | B34: =[1]POLES!E38 -> 14.943538 | C34: =[1]POLES!G38 -> 16.961579 | D34: =[1]POLES!I38 -> 18.480519 | E34: =[1]POLES!L38 -> 20.618706 | F34: =[1]POLES!M38 -> 21.306766
A37: PRIMES in eur 2000/GJ
B38: 2010 | C38: 2020 | D38: 2030 | E38: 2040 | F38: 2050
A39: Oil
A40: Reference | B40: =B7*[1]Price_conversion!$C$25*[1]Price_conversion!$C$31/[1]Price_conversion!$B$46 -> 12.188662 | C40: =C7*[1]Price_conversion!$C$25*[1]Price_conversion!$C$31/[1]Price_conversion!$B$46 -> 12.736144 | D40: =D7*[1]Price_conversion!$C$25*[1]Price_conversion!$C$31/[1]Price_conversion!$B$46 -> 15.257439 | E40: =E7*[1]Price_conversion!$C$25*[1]Price_conversion!$C$31/[1]Price_conversion!$B$46 -> 16.741402 | F40: =F7*[1]Price_conversion!$C$25*[1]Price_conversion!$C$31/[1]Price_conversion!$B$46 -> 18.268586
A41: High prices | B41: =B8*[1]Price_conversion!$C$25*[1]Price_conversion!$C$31/[1]Price_conversion!$B$46 -> 12.188662 | C41: =C8*[1]Price_conversion!$C$25*[1]Price_conversion!$C$31/[1]Price_conversion!$B$46 -> 19.046586 | D41: =D8*[1]Price_conversion!$C$25*[1]Price_conversion!$C$31/[1]Price_conversion!$B$46 -> 21.510252 | E41: =E8*[1]Price_conversion!$C$25*[1]Price_conversion!$C$31/[1]Price_conversion!$B$46 -> 21.438215 | F41: =F8*[1]Price_conversion!$C$25*[1]Price_conversion!$C$31/[1]Price_conversion!$B$46 -> 23.383214
A42: Low Prices | B42: =B9*[1]Price_conversion!$C$25*[1]Price_conversion!$C$31/[1]Price_conversion!$B$46 -> 12.188662 | C42: =C9*[1]Price_conversion!$C$25*[1]Price_conversion!$C$31/[1]Price_conversion!$B$46 -> 11.353033 | D42: =D9*[1]Price_conversion!$C$25*[1]Price_conversion!$C$31/[1]Price_conversion!$B$46 -> 13.182773 | E42: =E9*[1]Price_conversion!$C$25*[1]Price_conversion!$C$31/[1]Price_conversion!$B$46 -> 12.664107 | F42: =F9*[1]Price_conversion!$C$25*[1]Price_conversion!$C$31/[1]Price_conversion!$B$46 -> 12.087811
A43: Gas
...

Sheet Worldprices
A1: Source: Energy 2050 Roadmap. Impact assessment 1 - including Part 1 of Annex 1 "Scenarios - assumptions and results" [SEC(2011)1565/1]
C3: (IEA Europe E15 Import Costs) | D3: PRIMES (euro2000/GJ)
C4: 2000 | D4: 2000 | E4: 2001 | F4: 2005 | G4: 2010 | H4: 2015 | I4: 2020 | J4: 2025 | K4: 2030 | L4: =K4+5 -> 2035 | M4: =L4+5 -> 2040 | N4: =M4+5 -> 2045 | O4: =N4+5 -> 2050
A5: ($/boe) | B5: oil | C5: 27.89 | D5: 3.5163711 | E5: 2.9455134 | F5: 5.967172 | G5: ='REF2016 Prices'!B40 -> 9.8196721 | H5: =AVERAGE(G5,I5) -> 9.5648361 | I5: ='REF2016 Prices'!C40 -> 9.31 | J5: =AVERAGE(I5,K5) -> 11.48 | K5: ='REF2016 Prices'!D40 -> 13.65 | L5: =AVERAGE(K5,M5) -> 14.05 | M5: ='REF2016 Prices'!E40 -> 14.45 | N5: =AVERAGE(M5,O5) -> 15.96 | O5: ='REF2016 Prices'!F40 -> 17.47
A6: ($/MBTU) | B6: gas | C6: 2.78 | D6: 2.450666 | E6: 3.182487 | F6: 4.063408 | G6: ='REF2016 Prices'!B44 -> 6.1967213 | H6: =AVERAGE(G6,I6) -> 9.7933607 | I6: ='REF2016 Prices'!C44 -> 13.39 | J6: =AVERAGE(I6,K6) -> 10.195 | K6: ='REF2016 Prices'!D44 -> 7 | L6: =AVERAGE(K6,M6) -> 7 | M6: ='REF2016 Prices'!E44 -> 7 | N6: =AVERAGE(M6,O6) -> 7 | O6: ='REF2016 Prices'!F44 -> 7
A7: ($/ton) | B7: coal | C7: 34.93 | D7: 0.97036858 | E7: 1.0380398 | F7: 1.4745067 | G7: ='REF2016 Prices'!B48 -> 2.6229508 | H7: =AVERAGE(G7,I7) -> 2.9964754 | I7: ='REF2016 Prices'!C48 -> 3.37 | J7: =AVERAGE(I7,K7) -> 3.06 | K7: ='REF2016 Prices'!D48 -> 2.75 | L7: =AVERAGE(K7,M7) -> 2.84 | M7: ='REF2016 Prices'!E48 -> 2.93 | N7: =AVERAGE(M7,O7) -> 3.105 | O7: ='REF2016 Prices'!F48 -> 3.28
B8: coking coal | C8: 47.85 | D8: These in yellow are still from POLES as we do not have these prices in EU2050 Roadmap
A10: Conversion to EURO per GJ for 2000
A11: in EURO2000/GJ
A12: conversion factor | C12: 2000 | D12: 2001 | E12: 2005 | F12: 2010 | G12: 2015 | H12: 2020 | I12: 2025 | J12: 2030 | K12: =J12+5 -> 2035 | L12: =K12+5 -> 2040 | M12: =L12+5 -> 2045 | N12: =M12+5 -> 2050
A13: ='common data'!B19 -> 6.1 | B13: oil | C13: =C5/A13/'common data'!B54 -> 4.9503369 | D13: =C13*E5/D5 -> 4.1466851 | E13: =D13*F5/E5 -> 8.4005671 | F13: =G5 -> 9.8196721 | G13: =H5 -> 9.5648361 | H13: =I5 -> 9.31 | I13: =J5 -> 11.48 | J13: =K5 -> 13.65 | K13: =L5 -> 14.05 | L13: =M5 -> 14.45 | M13: =N5 -> 15.96 | N13: =O5 -> 17.47
A14: ='common data'!B20 -> 1.054 | B14: gas | C14: =C6/A14/'common data'!B54 -> 2.8557505 | D14: =C14*E6/D6 -> 3.7085383 | E14: =D14*F6/E6 -> 4.7350718 | F14: =G6 -> 6.1967213 | G14: =H6 -> 9.7933607 | H14: =I6 -> 13.39 | I14: =J6 -> 10.195 | J14: =K6 -> 7 | K14: =L6 -> 7 | L14: =M6 -> 7 | M14: =N6 -> 7 | N14: =O6 -> 7
A15: ='common data'!B23 -> 28.1 | B15: coal | C15: =C7/A15/'common data'!B54 -> 1.3458862 | D15: =C15*E7/D7 -> 1.4397452 | E15: =D15*F7/E7 -> 2.045118 | F15: =G7 -> 2.6229508 | G15: =H7 -> 2.9964754 | H15: =I7 -> 3.37 | I15: =J7 -> 3.06 | J15: =K7 -> 2.75 | K15: =L7 -> 2.84 | L15: =M7 -> 2.93 | M15: =N7 -> 3.105 | N15: =O7 -> 3.28
C16: The prices in yellow are estimated from 2000 real prices from an unclear source and assuming the same growth rate as from the POLES prices from 2000-2005. SSimoes ESE-IET 09/April 2013
A18: Going from Crude/Coal to Refined Products
A19: Coal to coke | B19: 1.27
A20: Coal to brown coal | B20: 0.95
A21: Coal to Lignite | B21: =B20 -> 0.95
A22: Crude to Heavy Fuel | B22: 0.81 | D22: =B22*$C$13-$C$13 -> -0.94056401
A23: Crude to Light Distillate | B23: 1.3 | D23: =B23*$C$13-$C$13 -> 1.4851011
A24: Crude to LPG | B24: 1.1 | D24: =B24*$C$13-$C$13 -> 0.49503369
A25: Crude to Gasoline | B25: 1.4 | D25: =B25*$C$13-$C$13 -> 1.9801348
A26: Crude to Naphta, Fdst & NEU | B26: 1 | D26: =B26*$C$13-$C$13 -> 0
A29: Prices for TIMES
A31: Price for Import of Fuels (basic import price to which to add the delivery cost to have the final consumer price without taxes)
A32: EURO/GJ
C33: 2000 | D33: 2001 | E33: 2005 | F33: 2010 | G33: 2015 | H33: 2020 | I33: 2025 | J33: 2030 | K33: =J33+5 -> 2035 | L33: =K33+5 -> 2040 | M33: =L33+5 -> 2045 | N33: =M33+5 -> 2050
A34: Coal | C34: =C15 -> 1.3458862 | D34: =C34*D15/C15 -> 1.4397452 | E34: =D34*E15/D15 -> 2.045118 | F34: =E34*F15/E15 -> 2.6229508 | G34: =F34*G15/F15 -> 2.9964754 | H34: =G34*H15/G15 -> 3.37 | I34: =H34*I15/H15 -> 3.06 | J34: =I34*J15/I15 -> 2.75 | K34: =J34*K15/J15 -> 2.84 | ... N34: =M34*N15/M15 -> 3.28
A35: Coke (rel coal) | C35: =$B19*C34 -> 1.7092755 | D35: =$B19*D34 -> 1.8284764 | E35: =$B19*E34 -> 2.5972998 | F35: =$B19*F34 -> 3.3311475 | G35: =$B19*G34 -> 3.8055238 | H35: =$B19*H34 -> 4.2799 | I35: =$B19*I34 -> 3.8862 | J35: =$B19*J34 -> 3.4925 | ... N35: =$B19*N34 -> 4.1656
A36: Brown coal | C36: =$B20*C34 -> 1.2785919 | D36: =$B20*D34 -> 1.3677579 | E36: =$B20*E34 -> 1.9428621 | F36: =$B20*F34 -> 2.4918033 | G36: =$B20*G34 -> 2.8466516 | H36: =$B20*H34 -> 3.2015 | I36: =$B20*I34 -> 2.907 | J36: =$B20*J34 -> 2.6125 | ... N36: =$B20*N34 -> 3.116
A37: Lignite | C37: =$B21*C34 -> 1.2785919 | D37: =$B21*D34 -> 1.3677579 | E37: =$B21*E34 -> 1.9428621 | F37: =$B21*F34 -> 2.4918033 | G37: =$B21*G34 -> 2.8466516 | H37: =$B21*H34 -> 3.2015 | I37: =$B21*I34 -> 2.907 | J37: =$B21*J34 -> 2.6125 | ... N37: =$B21*N34 -> 3.116
A38: Crude | C38: =C13 -> 4.9503369 | D38: =C38*D13/C13 -> 4.1466851 | E38: =D38*E13/D13 -> 8.4005671 | F38: =E38*F13/E13 -> 9.8196721 | G38: =F38*G13/F13 -> 9.5648361 | H38: =G38*H13/G13 -> 9.31 | I38: =H38*I13/H13 -> 11.48 | J38: =I38*J13/I13 -> 13.65 | K38: =J38*K13/J13 -> 14.05 | ... N38: =M38*N13/M13 -> 17.47
A39: Heavy Distillate Oil | C39: =$B22*C38 -> 4.0097729 | D39: =$B22*D38 -> 3.358815 | E39: =$B22*E38 -> 6.8044594 | F39: =$B22*F38 -> 7.9539344 | G39: =$B22*G38 -> 7.7475172 | H39: =$B22*H38 -> 7.5411 | I39: =$B22*I38 -> 9.2988 | J39: =$B22*J38 -> 11.0565 | ... N39: =$B22*N38 -> 14.1507
A40: Light Distilate Oil | C40: =$B23*C38 -> 6.435438 | D40: =$B23*D38 -> 5.3906907 | E40: =$B23*E38 -> 10.920737 | F40: =$B23*F38 -> 12.765574 | G40: =$B23*G38 -> 12.434287 | H40: =$B23*H38 -> 12.103 | I40: =$B23*I38 -> 14.924 | J40: =$B23*J38 -> 17.745 | ... N40: =$B23*N38 -> 22.711
A41: LPG | C41: =$B24*C38 -> 5.4453706 | D41: =$B24*D38 -> 4.5613537 | E41: =$B24*E38 -> 9.2406239 | F41: =$B24*F38 -> 10.801639 | G41: =$B24*G38 -> 10.52132 | H41: =$B24*H38 -> 10.241 | I41: =$B24*I38 -> 12.628 | J41: =$B24*J38 -> 15.015 | ... N41: =$B24*N38 -> 19.217
A42: Gasoline | C42: =$B25*C38 -> 6.9304716 | D42: =$B25*D38 -> 5.8053592 | E42: =$B25*E38 -> 11.760794 | F42: =$B25*F38 -> 13.747541 | G42: =$B25*G38 -> 13.39077 | H42: =$B25*H38 -> 13.034 | I42: =$B25*I38 -> 16.072 | J42: =$B25*J38 -> 19.11 | ... N42: =$B25*N38 -> 24.458
A43: Kerosene | C43: =C42 -> 6.9304716 | D43: =D42 -> 5.8053592 | E43: =E42 -> 11.760794 | F43: =F42 -> 13.747541 | G43: =G42 -> 13.39077 | H43: =H42 -> 13.034 | I43: =I42 -> 16.072 | J43: =J42 -> 19.11 | ... N43: =N42 -> 24.458
A44: other oil products | C44: =$B$26*C$38 -> 4.9503369 | D44: =$B$26*D$38 -> 4.1466851 | E44: =$B$26*E$38 -> 8.4005671 | F44: =$B$26*F$38 -> 9.8196721 | G44: =$B$26*G$38 -> 9.5648361 | H44: =$B$26*H$38 -> 9.31 | I44: =$B$26*I$38 -> 11.48 | J44: =$B$26*J$38 -> 13.65 | ... N44: =$B$26*N$38 -> 17.47
A45: Naphta | C45: =$B$26*C$38 -> 4.9503369 | D45: =$B$26*D$38 -> 4.1466851 | E45: =$B$26*E$38 -> 8.4005671 | F45: =$B$26*F$38 -> 9.8196721 | G45: =$B$26*G$38 -> 9.5648361 | H45: =$B$26*H$38 -> 9.31 | I45: =$B$26*I$38 -> 11.48 | J45: =$B$26*J$38 -> 13.65 | ... N45: =$B$26*N$38 -> 17.47
A46: Feedstock | C46: =$B$26*C$38 -> 4.9503369 | D46: =$B$26*D$38 -> 4.1466851 | E46: =$B$26*E$38 -> 8.4005671 | F46: =$B$26*F$38 -> 9.8196721 | G46: =$B$26*G$38 -> 9.5648361 | H46: =$B$26*H$38 -> 9.31 | I46: =$B$26*I$38 -> 11.48 | J46: =$B$26*J$38 -> 13.65 | ... N46: =$B$26*N$38 -> 17.47
...

Sheet MaterialPrices
A1: Materials which need prices are those which have an influence on technology choices
A3: The materials in TIMES are
B5: tech | C5: mat | F5: M€/Mt
A6: MAT | B6: MINMISORE1 | C6: MISORE | D6: Iron and Steel: Ore | F6: 80 | G6: =F6 -> 80 | H6: prices 2007, google
B7: MINMISSCR1 | C7: MISSCR | D7: Iron and Steel: Scrap Iron | F7: =390/3 -> 130 | G7: =F7 -> 130 | H7: one third of steel price
B8: MINMISOXY1 | C8: MISOXY | D8: Iron and Steel: Oxygen | F8: 10 | G8: =F8 -> 10 | H8: (density is about 1.4 kg/Nm3)
B9: MINMISQLI1 | C9: MISQLI | D9: Iron and Steel: Quick Lime | F9: 70 | G9: =F9 -> 70
B10: MINMLMSTN1 | C10: MLMSTN | D10: Lime: Limestone | F10: 50 | G10: =F10 -> 50
B11: MINMGHRYC1 | C11: MGHRYC | D11: Glass: Recycled | F11: 10 | G11: =F11 -> 10
B12: MINMPPWOO1 | C12: MPPWOO | D12: Paper: Wood | F12: 81 | G12: 200 | H12: Stookwaarde: 15GJ/ton, geeft dus ongeveer 2 €/GJ | M12: from IER | N12: (BE = 30)
B13: MINMPPRYC1 | C13: MPPRYC | D13: Paper: Recycled | F13: =450/3 -> 150 | G13: =F13 -> 150 | H13: one third of paper price
B14: MINMPPNOH1 | C14: MPPNOH | D14: Paper: Sodium Hydraxide
B15: MINMPPOXY1 | C15: MPPOXY | D15: Paper: Oxygen | F15: 10 | G15: =F15 -> 10
B16: MINMPPKAO1 | C16: MPPKAO | D16: Paper: Kaolin | F16: 150 | G16: =F16 -> 150
B17: MINMPPGYP1 | C17: MPPGYP | D17: Paper: Gypsum | F17: 20 | G17: =F17 -> 20
B18: MINMALBAU1 | C18: MALBAU | F18: =0.1191*1000 -> 119.1
B19: MINMALSCR1 | C19: MALSCR | F19: =1.1645*1000 -> 1164.5
B20: MINMCUORE1 | C20: MCUORE | F20: =0.743*1000 -> 743
B21: MINMCUSCR1 | C21: MCUSCR | F21: =0.9839*1000 -> 983.9
A24: Voor biomass heb ik | C24: EURO/GJ
C25: 2000 | D25: 2005 | E25: 2010 | F25: 2015 | G25: 2020 | H25: 2025 | I25: 2030 | J25: 2035 | K25: 2040 | L25: 2045 | M25: 2050
A26: Municipal Waste | B26: BIOMUN | C26: 1.9831482 | D26: 1.9831482 | E26: 1.9831482 | F26: 1.9831482 | G26: 1.9831482 | H26: 1.9831482 | I26: 1.9831482 | J26: 1.9831482 | K26: 1.9831482 | L26: 1.9831482 | M26: 1.9831482
A27: Bio Wood nat | B27: BIOWOO | C27: 2.7558824 | D27: 3.013003 | E27: 3.2941127 | F27: 3.6014496 | G27: 3.9374607 | H27: 4.3048213 | I27: 4.7064561 | J27: 5.145563 | K27: 5.6256381 | L27: 6.1505037 | M27: 6.7243386 | O27: 0.018
A28: Wood residue | B28: BIOWOO | C28: 1.1 | D28: 1.2144889 | E28: 1.3408939 | F28: 1.4804552 | G28: 1.6345421 | H28: 1.8046666 | I28: 1.9924977 | J28: 2.1998785 | K28: 2.4288436 | L28: 2.6816396 | M28: 2.9607468 | O28: 0.02
A30: BioWood imp | B30: BIOWOO | C30: 3.0314706 | D30: 3.3143033 | E30: 3.623524 | F30: 3.9615946 | G30: 4.3312068 | H30: 4.7353034 | I30: 5.1771017 | J30: 5.6601194 | K30: 6.188202 | L30: 6.7655541 | M30: 7.3967725
A31: BioWoodImpB | B31: BIOWOO | C31: 3.6377647 | D31: 3.977164 | E31: 4.3482288 | F31: 4.7539135 | G31: 5.1974481 | H31: 5.6823641 | I31: 6.2125221 | J31: 6.7921432 | K31: 7.4258424 | L31: 8.1186649 | M31: 8.876127
B35: IISBOXFUR00 | C35: IIS.Blast Oxygen Furnace BOF.Regular.00. | G35: Simplified material cost
B36: MISRIR | D36: 0.85 | G36: =D36*D47*D61*F6 -> 104.72 | H36: €/ton
B37: MISSCR | D37: 0.25 | G37: =D37*F7 -> 32.5
B38: MISQLI | D38: 0.05 | G38: =SUM(G36:G37) -> 137.22
B39: MISOXY | D39: 0.05 | G39: 150 | H39: energy cost from Veda
B40: INDGAS | D40: 0.2
C41: MISCST | E41: 1
C42: GASBFG
B45: IISBLAFUR00 | C45: IIS.Iron Blast Furnace.00.
B46: MISPLT | D46: 0.04
B47: MISSNT | D47: 1.54
B48: MISOXY | D48: 0.05
B49: INDCOK | D49: =8.75-1.3 -> 7.45
B50: INDCOA | D50: 5.5
...

Sheet INPUTtoVEDAMatPrices
A2: ~TFM_INS
A3: TimeSlice | B3: LimType | C3: Attribute | D3: Year | E3: AllRegions | F3: Pset_CO | G3: Pset_PN | H3: Cset_CN
A4: ANNUAL | C4: COST | E4: =MaterialPrices!G6 -> 80 | F4: =MaterialPrices!C6 -> MISORE | G4: =MaterialPrices!B6 -> MINMISORE1 | H4: =F4 -> MISORE
A5: ANNUAL | C5: COST | E5: =MaterialPrices!G7 -> 130 | F5: =MaterialPrices!C7 -> MISSCR | G5: =MaterialPrices!B7 -> MINMISSCR1 | H5: =F5 -> MISSCR
A6: ANNUAL | C6: COST | E6: =MaterialPrices!G8 -> 10 | F6: =MaterialPrices!C8 -> MISOXY | G6: =MaterialPrices!B8 -> MINMISOXY1 | H6: =F6 -> MISOXY
A7: ANNUAL | C7: COST | E7: =MaterialPrices!G9 -> 70 | F7: =MaterialPrices!C9 -> MISQLI | G7: =MaterialPrices!B9 -> MINMISQLI1 | H7: =F7 -> MISQLI
A8: ANNUAL | C8: COST | E8: =MaterialPrices!G10 -> 50 | F8: =MaterialPrices!C10 -> MLMSTN | G8: =MaterialPrices!B10 -> MINMLMSTN1 | H8: =F8 -> MLMSTN
A9: ANNUAL | C9: COST | E9: =MaterialPrices!G11 -> 10 | F9: =MaterialPrices!C11 -> MGHRYC | G9: =MaterialPrices!B11 -> MINMGHRYC1 | H9: =F9 -> MGHRYC
A10: ANNUAL | C10: COST | E10: =MaterialPrices!G12 -> 200 | F10: =MaterialPrices!C12 -> MPPWOO | G10: =MaterialPrices!B12 -> MINMPPWOO1 | H10: =F10 -> MPPWOO
A11: ANNUAL | C11: COST | E11: =MaterialPrices!G13 -> 150 | F11: =MaterialPrices!C13 -> MPPRYC | G11: =MaterialPrices!B13 -> MINMPPRYC1 | H11: =F11 -> MPPRYC
A12: ANNUAL | C12: COST | E12: =MaterialPrices!G14 -> 0 | F12: =MaterialPrices!C14 -> MPPNOH | G12: =MaterialPrices!B14 -> MINMPPNOH1 | H12: =F12 -> MPPNOH
A13: ANNUAL | C13: COST | E13: =MaterialPrices!G15 -> 10 | F13: =MaterialPrices!C15 -> MPPOXY | G13: =MaterialPrices!B15 -> MINMPPOXY1 | H13: =F13 -> MPPOXY
A14: ANNUAL | C14: COST | E14: =MaterialPrices!G16 -> 150 | F14: =MaterialPrices!C16 -> MPPKAO | G14: =MaterialPrices!B16 -> MINMPPKAO1 | H14: =F14 -> MPPKAO
A15: ANNUAL | C15: COST | E15: =MaterialPrices!G17 -> 20 | F15: =MaterialPrices!C17 -> MPPGYP | G15: =MaterialPrices!B17 -> MINMPPGYP1 | H15: =F15 -> MPPGYP
... A19: ANNUAL | C19: COST | E19: =MaterialPrices!G21 -> 0 | F19: =MaterialPrices!C21 -> MCUSCR | G19: =MaterialPrices!B21 -> MINMCUSCR1 | H19: =F19 -> MCUSCR

Sheet INPUTtoVEDA_importprice TR
A1: Adjustment factors derived from the computation of the delivery cost
H3: AT | I3: BE | K3: DE | L3: DK | M3: FI | N3: FR | O3: EL | P3: IE | Q3: IT | R3: NL | S3: PT | T3: ES | U3: SE | V3: UK | W3: HU | X3: PL | Y3: CZ | Z3: SK | AA3: CH | AB3: CY | AC3: EE | AD3: IS | AE3: LT | AF3: LU | AG3: LV | AH3: MT | AI3: RO | AJ3: SI | AK3: NO | AL3: AL | AM3: BH | AN3: HR | AO3: ME | AP3: MK | AQ3: RS | AR3: KS
D4: Coal | H4: 1 | I4: 0.935 | K4: 1 | L4: 1 | M4: 1 | N4: 1 | O4: 1 | P4: 0.85 | Q4: 0.95 | R4: 1 | S4: 0.85 | T4: 1 | U4: 1 | V4: 1 | W4: 1 | X4: 1 | Y4: 1 | Z4: 1 | AA4: 1 | AB4: 1 | AC4: 1 | AD4: 1 | AE4: 1 | AF4: 1 | AG4: 1 | AH4: 1 | AI4: 1 | AJ4: 1 | AK4: 1 | AL4: 1 | AM4: 1 | AN4: 1 | AO4: 1 | AP4: 1 | AQ4: 1 | AR4: 1
D5: Heavy Distillate Oil | H5: 0.9 | I5: 1 | K5: 1 | L5: 1 | M5: 1 | N5: 1 | O5: 1 | P5: 0.85 | Q5: 1 | R5: 1 | S5: 1 | T5: 1 | U5: 0.9 | V5: 0.9 | W5: 1 | X5: 1 | Y5: 1 | Z5: 1 | AA5: 1 | AB5: 1 | AC5: 1 | AD5: 1 | AE5: 1 | AF5: 1 | AG5: 1 | AH5: 1 | AI5: 1 | AJ5: 1 | AK5: 1 | AL5: 1 | AM5: 1 | AN5: 1 | AO5: 1 | AP5: 1 | AQ5: 1 | AR5: 1
D6: Light Distilate Oil | H6: 1 | I6: 1 | K6: 1 | L6: 1 | M6: 1 | N6: 1 | O6: 1 | P6: 1 | Q6: 1 | R6: 1 | S6: 1 | T6: 1 | U6: 1 | V6: 0.95 | W6: 1 | X6: 1 | Y6: 1 | Z6: 1 | AA6: 1 | AB6: 1 | AC6: 1 | AD6: 1 | AE6: 1 | AF6: 1 | AG6: 1 | AH6: 1 | AI6: 1 | AJ6: 1 | AK6: 1 | AL6: 1 | AM6: 1 | AN6: 1 | AO6: 1 | AP6: 1 | AQ6: 1 | AR6: 1
D7: Gasoline | H7: 1 | I7: 1 | K7: 1 | L7: 1 | M7: 1 | N7: 1 | O7: 1 | P7: 1 | Q7: 1 | R7: 1 | S7: 1 | T7: 1 | U7: 1 | V7: 0.95 | W7: 1 | X7: 1 | Y7: 1 | Z7: 1 | AA7: 1 | AB7: 1 | AC7: 1 | AD7: 1 | AE7: 1 | AF7: 1 | AG7: 1 | AH7: 1 | AI7: 1 | AJ7: 1 | AK7: 1 | AL7: 1 | AM7: 1 | AN7: 1 | AO7: 1 | AP7: 1 | AQ7: 1 | AR7: 1
D8: Natural Gas | H8: 1 | I8: 1 | K8: 1 | L8: 1 | M8: 1 | N8: 1 | O8: 1 | P8: 0.85 | Q8: 0.9 | R8: 1 | S8: 1 | T8: 1 | U8: 1 | V8: 0.9 | W8: 1 | X8: 1 | Y8: 1 | Z8: 1 | AA8: 1 | AB8: 1 | AC8: 1 | AD8: 1 | AE8: 1 | AF8: 1 | AG8: 1 | AH8: 1 | AI8: 1 | AJ8: 1 | AK8: 1 | AL8: 1 | AM8: 1 | AN8: 1 | AO8: 1 | AP8: 1 | AQ8: 1 | AR8: 1
A11: ~TFM_DINS
A12: TimeSlice | B12: Curr | C12: LimType | D12: Attribute | E12: Year | F12: Pset_PN | G12: Cset_CN | H12: AT | I12: BE | J12: BG | K12: DE | L12: DK | M12: FI | N12: FR | O12: EL | P12: IE | Q12: IT | R12: NL | S12: PT | T12: ES | U12: SE | V12: UK | W12: HU | X12: PL | Y12: CZ | Z12: SK | AA12: CH | AB12: CY | AC12: EE | AD12: IS | AE12: LT | AF12: LU | AG12: LV | AH12: MT | AI12: RO | AJ12: SI | AK12: NO | AL12: AL | AM12: BA | AN12: HR | AO12: ME | AP12: MK | AQ12: RS | AR12: KS
A13: ANNUAL | B13: EUR10 | D13: =IF(RIGHT(F13,6)="GASNAT","*","COST") -> COST | E13: 2010 | F13: =Worldprices!$G$62 -> IMPOILCRD | G13: =Worldprices!$G$63 -> OILCRD | H13: =Worldprices!$G$67*H$5 -> 8.8377049 | I13: =Worldprices!$G$67*I$5 -> 9.8196721 | J13: =AI13 -> 9.8196721 | K13: =Worldprices!$G$67*K$5 -> 9.8196721 | L13: =Worldprices!$G$67*L$5 -> 9.8196721 | M13: =Worldprices!$G$67*M$5 -> 9.8196721 | N13: =Worldprices!$G$67*N$5 -> 9.8196721 | O13: =Worldprices!$G$67*O$5 -> 9.8196721 | P13: =Worldprices!$G$67*P$5 -> 8.3467213 | Q13: =Worldprices!$G$67*Q$5 -> 9.8196721 | R13: =Worldprices!$G$67*R$5 -> 9.8196721 | ... AQ13: =Worldprices!$G$67*AQ$5 -> 9.8196721 | AR13: =AQ13 -> 9.8196721
A14: ANNUAL | B14: EUR10 | D14: =IF(RIGHT(F14,6)="GASNAT","*","COST") -> COST | E14: 2010 | F14: =Worldprices!$H$62 -> IMPOILHFO | G14: =Worldprices!$H$63 -> OILHFO | H14: =Worldprices!$H$67*H$5 -> 7.158541 | I14: =Worldprices!$H$67*I$5 -> 7.9539344 | J14: =AI14 -> 7.9539344 | K14: =Worldprices!$H$67*K$5 -> 7.9539344 | L14: =Worldprices!$H$67*L$5 -> 7.9539344 | M14: =Worldprices!$H$67*M$5 -> 7.9539344 | N14: =Worldprices!$H$67*N$5 -> 7.9539344 | O14: =Worldprices!$H$67*O$5 -> 7.9539344 | P14: =Worldprices!$H$67*P$5 -> 6.7608443 | Q14: =Worldprices!$H$67*Q$5 -> 7.9539344 | R14: =Worldprices!$H$67*R$5 -> 7.9539344 | ... AQ14: =Worldprices!$H$67*AQ$5 -> 7.9539344 | AR14: =AQ14 -> 7.9539344
A15: ANNUAL | B15: EUR10 | D15: =IF(RIGHT(F15,6)="GASNAT","*","COST") -> COST | E15: 2010 | F15: =Worldprices!$I$62 -> IMPOILDST | G15: =Worldprices!$I$63 -> OILDST | H15: =Worldprices!$I$67*H$6 -> 12.765574 | I15: =Worldprices!$I$67*I$6 -> 12.765574 | J15: =AI15 -> 12.765574 | K15: =Worldprices!$I$67*K$6 -> 12.765574 | L15: =Worldprices!$I$67*L$6 -> 12.765574 | M15: =Worldprices!$I$67*M$6 -> 12.765574 | N15: =Worldprices!$I$67*N$6 -> 12.765574 | O15: =Worldprices!$I$67*O$6 -> 12.765574 | P15: =Worldprices!$I$67*P$6 -> 12.765574 | Q15: =Worldprices!$I$67*Q$6 -> 12.765574 | R15: =Worldprices!$I$67*R$6 -> 12.765574 | ... AQ15: =Worldprices!$I$67*AQ$6 -> 12.765574 | AR15: =AQ15 -> 12.765574
A16: ANNUAL | B16: EUR10 | D16: =IF(RIGHT(F16,6)="GASNAT","*","COST") -> COST | E16: 2010 | F16: =Worldprices!$J$62 -> IMPOILLPG | G16: =Worldprices!$J$63 -> OILLPG | H16: =Worldprices!$J$67*H$7 -> 10.801639 | I16: =Worldprices!$J$67*I$7 -> 10.801639 | J16: =AI16 -> 10.801639 | K16: =Worldprices!$J$67*K$7 -> 10.801639 | L16: =Worldprices!$J$67*L$7 -> 10.801639 | M16: =Worldprices!$J$67*M$7 -> 10.801639 | N16: =Worldprices!$J$67*N$7 -> 10.801639 | O16: =Worldprices!$J$67*O$7 -> 10.801639 | P16: =Worldprices!$J$67*P$7 -> 10.801639 | Q16: =Worldprices!$J$67*Q$7 -> 10.801639 | R16: =Worldprices!$J$67*R$7 -> 10.801639 | ... AQ16: =Worldprices!$J$67*AQ$7 -> 10.801639 | AR16: =AQ16 -> 10.801639
A17: ANNUAL | B17: EUR10 | D17: =IF(RIGHT(F17,6)="GASNAT","*","COST") -> COST | E17: 2010 | F17: =Worldprices!$K$62 -> IMPOILGSL | G17: =Worldprices!$K$63 -> OILGSL | H17: =Worldprices!$K$67*H$7 -> 13.747541 | I17: =Worldprices!$K$67*I$7 -> 13.747541 | J17: =AI17 -> 13.747541 | K17: =Worldprices!$K$67*K$7 -> 13.747541 | L17: =Worldprices!$K$67*L$7 -> 13.747541 | M17: =Worldprices!$K$67*M$7 -> 13.747541 | N17: =Worldprices!$K$67*N$7 -> 13.747541 | O17: =Worldprices!$K$67*O$7 -> 13.747541 | P17: =Worldprices!$K$67*P$7 -> 13.747541 | Q17: =Worldprices!$K$67*Q$7 -> 13.747541 | R17: =Worldprices!$K$67*R$7 -> 13.747541 | ... AQ17: =Worldprices!$K$67*AQ$7 -> 13.747541 | AR17: =AQ17 -> 13.747541
A18: ANNUAL | B18: EUR10 | D18: =IF(RIGHT(F18,6)="GASNAT","*","COST") -> COST | E18: 2010 | F18: =Worldprices!$L$62 -> IMPOILKER | G18: =Worldprices!$L$63 -> OILKER | H18: =Worldprices!$L$67*H$7 -> 13.747541 | I18: =Worldprices!$L$67*I$7 -> 13.747541 | J18: =AI18 -> 13.747541 | K18: =Worldprices!$L$67*K$7 -> 13.747541 | L18: =Worldprices!$L$67*L$7 -> 13.747541 | M18: =Worldprices!$L$67*M$7 -> 13.747541 | N18: =Worldprices!$L$67*N$7 -> 13.747541 | O18: =Worldprices!$L$67*O$7 -> 13.747541 | P18: =Worldprices!$L$67*P$7 -> 13.747541 | Q18: =Worldprices!$L$67*Q$7 -> 13.747541 | R18: =Worldprices!$L$67*R$7 -> 13.747541 | ... AQ18: =Worldprices!$L$67*AQ$7 -> 13.747541 | AR18: =AQ18 -> 13.747541
A19: ANNUAL | B19: EUR10 | D19: =IF(RIGHT(F19,6)="GASNAT","*","COST") -> * | E19: 2010 | F19: =Worldprices!$Q$62 -> IMPGASNAT | G19: =Worldprices!$Q$63 -> GASNAT | H19: =Worldprices!$Q$67*H$8 -> 6.1967213 | I19: =Worldprices!$Q$67*I$8 -> 6.1967213 | J19: =AI19 -> 6.1967213 | K19: =Worldprices!$Q$67*K$8 -> 6.1967213 | L19: =Worldprices!$Q$67*L$8 -> 6.1967213 | M19: =Worldprices!$Q$67*M$8 -> 6.1967213 | N19: =Worldprices!$Q$67*N$8 -> 6.1967213 | O19: =Worldprices!$Q$67*O$8 -> 6.1967213 | P19: =Worldprices!$Q$67*P$8 -> 5.2672131 | Q19: =Worldprices!$Q$67*Q$8 -> 5.5770492 | R19: =Worldprices!$Q$67*R$8 -> 6.1967213 | ... AQ19: =Worldprices!$Q$67*AQ$8 -> 6.1967213 | AR19: =AQ19 -> 6.1967213
A20: ANNUAL | B20: EUR10 | D20: =IF(RIGHT(F20,6)="GASNAT","*","COST") -> COST | E20: 2015 | F20: =Worldprices!$G$62 -> IMPOILCRD | G20: =Worldprices!$G$63 -> OILCRD | H20: =Worldprices!$G$68*H$5 -> 8.6083525 | I20: =Worldprices!$G$68*I$5 -> 9.5648361 | J20: =AI20 -> 9.5648361 | K20: =Worldprices!$G$68*K$5 -> 9.5648361 | L20: =Worldprices!$G$68*L$5 -> 9.5648361 | M20: =Worldprices!$G$68*M$5 -> 9.5648361 | N20: =Worldprices!$G$68*N$5 -> 9.5648361 | O20: =Worldprices!$G$68*O$5 -> 9.5648361 | P20: =Worldprices!$G$68*P$5 -> 8.1301107 | Q20: =Worldprices!$G$68*Q$5 -> 9.5648361 | R20: =Worldprices!$G$68*R$5 -> 9.5648361 | ... AQ20: =Worldprices!$G$68*AQ$5 -> 9.5648361 | AR20: =AQ20 -> 9.5648361
A21: ANNUAL | B21: EUR10 | D21: =IF(RIGHT(F21,6)="GASNAT","*","COST") -> COST | E21: 2015 | F21: =Worldprices!$H$62 -> IMPOILHFO | G21: =Worldprices!$H$63 -> OILHFO | H21: =Worldprices!$H$68*H$5 -> 6.9727655 | I21: =Worldprices!$H$68*I$5 -> 7.7475172 | J21: =AI21 -> 7.7475172 | K21: =Worldprices!$H$68*K$5 -> 7.7475172 | L21: =Worldprices!$H$68*L$5 -> 7.7475172 | M21: =Worldprices!$H$68*M$5 -> 7.7475172 | N21: =Worldprices!$H$68*N$5 -> 7.7475172 | O21: =Worldprices!$H$68*O$5 -> 7.7475172 | P21: =Worldprices!$H$68*P$5 -> 6.5853896 | Q21: =Worldprices!$H$68*Q$5 -> 7.7475172 | R21: =Worldprices!$H$68*R$5 -> 7.7475172 | ... AQ21: =Worldprices!$H$68*AQ$5 -> 7.7475172 | AR21: =AQ21 -> 7.7475172
A22: ANNUAL | B22: EUR10 | D22: =IF(RIGHT(F22,6)="GASNAT","*","COST") -> COST | E22: 2015 | F22: =Worldprices!$I$62 -> IMPOILDST | G22: =Worldprices!$I$63 -> OILDST | H22: =Worldprices!$I$68*H$6 -> 12.434287 | I22: =Worldprices!$I$68*I$6 -> 12.434287 | J22: =AI22 -> 12.434287 | K22: =Worldprices!$I$68*K$6 -> 12.434287 | L22: =Worldprices!$I$68*L$6 -> 12.434287 | M22: =Worldprices!$I$68*M$6 -> 12.434287 | N22: =Worldprices!$I$68*N$6 -> 12.434287 | O22: =Worldprices!$I$68*O$6 -> 12.434287 | P22: =Worldprices!$I$68*P$6 -> 12.434287 | Q22: =Worldprices!$I$68*Q$6 -> 12.434287 | R22: =Worldprices!$I$68*R$6 -> 12.434287 | ... AQ22: =Worldprices!$I$68*AQ$6 -> 12.434287 | AR22: =AQ22 -> 12.434287
A23: ANNUAL | B23: EUR10 | D23: =IF(RIGHT(F23,6)="GASNAT","*","COST") -> COST | E23: 2015 | F23: =Worldprices!$J$62 -> IMPOILLPG | G23: =Worldprices!$J$63 -> OILLPG | H23: =Worldprices!$J$68*H$7 -> 10.52132 | I23: =Worldprices!$J$68*I$7 -> 10.52132 | J23: =AI23 -> 10.52132 | K23: =Worldprices!$J$68*K$7 -> 10.52132 | L23: =Worldprices!$J$68*L$7 -> 10.52132 | M23: =Worldprices!$J$68*M$7 -> 10.52132 | N23: =Worldprices!$J$68*N$7 -> 10.52132 | O23: =Worldprices!$J$68*O$7 -> 10.52132 | P23: =Worldprices!$J$68*P$7 -> 10.52132 | Q23: =Worldprices!$J$68*Q$7 -> 10.52132 | R23: =Worldprices!$J$68*R$7 -> 10.52132 | ... AQ23: =Worldprices!$J$68*AQ$7 -> 10.52132 | AR23: =AQ23 -> 10.52132
A24: ANNUAL | B24: EUR10 | D24: =IF(RIGHT(F24,6)="GASNAT","*","COST") -> COST | E24: 2015 | F24: =Worldprices!$K$62 -> IMPOILGSL | G24: =Worldprices!$K$63 -> OILGSL | H24: =Worldprices!$K$68*H$7 -> 13.39077 | I24: =Worldprices!$K$68*I$7 -> 13.39077 | J24: =AI24 -> 13.39077 | K24: =Worldprices!$K$68*K$7 -> 13.39077 | L24: =Worldprices!$K$68*L$7 -> 13.39077 | M24: =Worldprices!$K$68*M$7 -> 13.39077 | N24: =Worldprices!$K$68*N$7 -> 13.39077 | O24: =Worldprices!$K$68*O$7 -> 13.39077 | P24: =Worldprices!$K$68*P$7 -> 13.39077 | Q24: =Worldprices!$K$68*Q$7 -> 13.39077 | R24: =Worldprices!$K$68*R$7 -> 13.39077 | ... AQ24: =Worldprices!$K$68*AQ$7 -> 13.39077 | AR24: =AQ24 -> 13.39077
A25: ANNUAL | B25: EUR10 | D25: =IF(RIGHT(F25,6)="GASNAT","*","COST") -> COST | E25: 2015 | F25: =Worldprices!$L$62 -> IMPOILKER | G25: =Worldprices!$L$63 -> OILKER | H25: =Worldprices!$L$68*H$7 -> 13.39077 | I25: =Worldprices!$L$68*I$7 -> 13.39077 | J25: =AI25 -> 13.39077 | K25: =Worldprices!$L$68*K$7 -> 13.39077 | L25: =Worldprices!$L$68*L$7 -> 13.39077 | M25: =Worldprices!$L$68*M$7 -> 13.39077 | N25: =Worldprices!$L$68*N$7 -> 13.39077 | O25: =Worldprices!$L$68*O$7 -> 13.39077 | P25: =Worldprices!$L$68*P$7 -> 13.39077 | Q25: =Worldprices!$L$68*Q$7 -> 13.39077 | R25: =Worldprices!$L$68*R$7 -> 13.39077 | ... AQ25: =Worldprices!$L$68*AQ$7 -> 13.39077 | AR25: =AQ25 -> 13.39077
A26: ANNUAL | B26: EUR10 | D26: =IF(RIGHT(F26,6)="GASNAT","*","COST") -> * | E26: 2015 | F26: =Worldprices!$Q$62 -> IMPGASNAT | G26: =Worldprices!$Q$63 -> GASNAT | H26: =Worldprices!$Q$68*H$8 -> 9.7933607 | I26: =Worldprices!$Q$68*I$8 -> 9.7933607 | J26: =AI26 -> 9.7933607 | K26: =Worldprices!$Q$68*K$8 -> 9.7933607 | L26: =Worldprices!$Q$68*L$8 -> 9.7933607 | M26: =Worldprices!$Q$68*M$8 -> 9.7933607 | N26: =Worldprices!$Q$68*N$8 -> 9.7933607 | O26: =Worldprices!$Q$68*O$8 -> 9.7933607 | P26: =Worldprices!$Q$68*P$8 -> 8.3243566 | Q26: =Worldprices!$Q$68*Q$8 -> 8.8140246 | R26: =Worldprices!$Q$68*R$8 -> 9.7933607 | ... AQ26: =Worldprices!$Q$68*AQ$8 -> 9.7933607 | AR26: =AQ26 -> 9.7933607
A27: ANNUAL | B27: EUR10 | D27: =IF(RIGHT(F27,6)="GASNAT","*","COST") -> COST | E27: 2020 | F27: =Worldprices!$G$62 -> IMPOILCRD | G27: =Worldprices!$G$63 -> OILCRD | H27: =Worldprices!$G$69*H$5 -> 8.379 | I27: =Worldprices!$G$69*I$5 -> 9.31 | J27: =AI27 -> 9.31 | K27: =Worldprices!$G$69*K$5 -> 9.31 | L27: =Worldprices!$G$69*L$5 -> 9.31 | M27: =Worldprices!$G$69*M$5 -> 9.31 | N27: =Worldprices!$G$69*N$5 -> 9.31 | O27: =Worldprices!$G$69*O$5 -> 9.31 | P27: =Worldprices!$G$69*P$5 -> 7.9135 | Q27: =Worldprices!$G$69*Q$5 -> 9.31 | R27: =Worldprices!$G$69*R$5 -> 9.31 | ... AQ27: =Worldprices!$G$69*AQ$5 -> 9.31 | AR27: =AQ27 -> 9.31
A28: ANNUAL | B28: EUR10 | D28: =IF(RIGHT(F28,6)="GASNAT","*","COST") -> COST | E28: 2020 | F28: =Worldprices!$H$62 -> IMPOILHFO | G28: =Worldprices!$H$63 -> OILHFO | H28: =Worldprices!$H$69*H$5 -> 6.78699 | I28: =Worldprices!$H$69*I$5 -> 7.5411 | J28: =AI28 -> 7.5411 | K28: =Worldprices!$H$69*K$5 -> 7.5411 | L28: =Worldprices!$H$69*L$5 -> 7.5411 | M28: =Worldprices!$H$69*M$5 -> 7.5411 | N28: =Worldprices!$H$69*N$5 -> 7.5411 | O28: =Worldprices!$H$69*O$5 -> 7.5411 | P28: =Worldprices!$H$69*P$5 -> 6.409935 | Q28: =Worldprices!$H$69*Q$5 -> 7.5411 | R28: =Worldprices!$H$69*R$5 -> 7.5411 | ... AQ28: =Worldprices!$H$69*AQ$5 -> 7.5411 | AR28: =AQ28 -> 7.5411
A29: ANNUAL | B29: EUR10 | D29: =IF(RIGHT(F29,6)="GASNAT","*","COST") -> COST | E29: 2020 | F29: =Worldprices!$I$62 -> IMPOILDST | G29: =Worldprices!$I$63 -> OILDST | H29: =Worldprices!$I$69*H$6 -> 12.103 | I29: =Worldprices!$I$69*I$6 -> 12.103 | J29: =AI29 -> 12.103 | K29: =Worldprices!$I$69*K$6 -> 12.103 | L29: =Worldprices!$I$69*L$6 -> 12.103 | M29: =Worldprices!$I$69*M$6 -> 12.103 | N29: =Worldprices!$I$69*N$6 -> 12.103 | O29: =Worldprices!$I$69*O$6 -> 12.103 | P29: =Worldprices!$I$69*P$6 -> 12.103 | Q29: =Worldprices!$I$69*Q$6 -> 12.103 | R29: =Worldprices!$I$69*R$6 -> 12.103 | ... AQ29: =Worldprices!$I$69*AQ$6 -> 12.103 | AR29: =AQ29 -> 12.103
A30: ANNUAL | B30: EUR10 | D30: =IF(RIGHT(F30,6)="GASNAT","*","COST") -> COST | E30: 2020 | F30: =Worldprices!$J$62 -> IMPOILLPG | G30: =Worldprices!$J$63 -> OILLPG | H30: =Worldprices!$J$69*H$7 -> 10.241 | I30: =Worldprices!$J$69*I$7 -> 10.241 | J30: =AI30 -> 10.241 | K30: =Worldprices!$J$69*K$7 -> 10.241 | L30: =Worldprices!$J$69*L$7 -> 10.241 | M30: =Worldprices!$J$69*M$7 -> 10.241 | N30: =Worldprices!$J$69*N$7 -> 10.241 | O30: =Worldprices!$J$69*O$7 -> 10.241 | P30: =Worldprices!$J$69*P$7 -> 10.241 | Q30: =Worldprices!$J$69*Q$7 -> 10.241 | R30: =Worldprices!$J$69*R$7 -> 10.241 | ... AQ30: =Worldprices!$J$69*AQ$7 -> 10.241 | AR30: =AQ30 -> 10.241
A31: ANNUAL | B31: EUR10 | D31: =IF(RIGHT(F31,6)="GASNAT","*","COST") -> COST | E31: 2020 | F31: =Worldprices!$K$62 -> IMPOILGSL | G31: =Worldprices!$K$63 -> OILGSL | H31: =Worldprices!$K$69*H$7 -> 13.034 | I31: =Worldprices!$K$69*I$7 -> 13.034 | J31: =AI31 -> 13.034 | K31: =Worldprices!$K$69*K$7 -> 13.034 | L31: =Worldprices!$K$69*L$7 -> 13.034 | M31: =Worldprices!$K$69*M$7 -> 13.034 | N31: =Worldprices!$K$69*N$7 -> 13.034 | O31: =Worldprices!$K$69*O$7 -> 13.034 | P31: =Worldprices!$K$69*P$7 -> 13.034 | Q31: =Worldprices!$K$69*Q$7 -> 13.034 | R31: =Worldprices!$K$69*R$7 -> 13.034 | ... AQ31: =Worldprices!$K$69*AQ$7 -> 13.034 | AR31: =AQ31 -> 13.034
A32: ANNUAL | B32: EUR10 | D32: =IF(RIGHT(F32,6)="GASNAT","*","COST") -> COST | E32: 2020 | F32: =Worldprices!$L$62 -> IMPOILKER | G32: =Worldprices!$L$63 -> OILKER | H32: =Worldprices!$L$69*H$7 -> 13.034 | I32: =Worldprices!$L$69*I$7 -> 13.034 | J32: =AI32 -> 13.034 | K32: =Worldprices!$L$69*K$7 -> 13.034 | L32: =Worldprices!$L$69*L$7 -> 13.034 | M32: =Worldprices!$L$69*M$7 -> 13.034 | N32: =Worldprices!$L$69*N$7 -> 13.034 | O32: =Worldprices!$L$69*O$7 -> 13.034 | P32: =Worldprices!$L$69*P$7 -> 13.034 | Q32: =Worldprices!$L$69*Q$7 -> 13.034 | R32: =Worldprices!$L$69*R$7 -> 13.034 | ... AQ32: =Worldprices!$L$69*AQ$7 -> 13.034 | AR32: =AQ32 -> 13.034
A33: ANNUAL | B33: EUR10 | D33: =IF(RIGHT(F33,6)="GASNAT","*","COST") -> * | E33: 2020 | F33: =Worldprices!$Q$62 -> IMPGASNAT | G33: =Worldprices!$Q$63 -> GASNAT | H33: =Worldprices!$Q$69*H$8 -> 13.39 | I33: =Worldprices!$Q$69*I$8 -> 13.39 | J33: =AI33 -> 13.39 | K33: =Worldprices!$Q$69*K$8 -> 13.39 | L33: =Worldprices!$Q$69*L$8 -> 13.39 | M33: =Worldprices!$Q$69*M$8 -> 13.39 | N33: =Worldprices!$Q$69*N$8 -> 13.39 | O33: =Worldprices!$Q$69*O$8 -> 13.39 | P33: =Worldprices!$Q$69*P$8 -> 11.3815 | Q33: =Worldprices!$Q$69*Q$8 -> 12.051 | R33: =Worldprices!$Q$69*R$8 -> 13.39 | ... AQ33: =Worldprices!$Q$69*AQ$8 -> 13.39 | AR33: =AQ33 -> 13.39
A34: ANNUAL | B34: EUR10 | D34: =IF(RIGHT(F34,6)="GASNAT","*","COST") -> COST | E34: 2025 | F34: =Worldprices!$G$62 -> IMPOILCRD | G34: =Worldprices!$G$63 -> OILCRD | H34: =Worldprices!$G$70*H$5 -> 10.332 | I34: =Worldprices!$G$70*I$5 -> 11.48 | J34: =AI34 -> 11.48 | K34: =Worldprices!$G$70*K$5 -> 11.48 | L34: =Worldprices!$G$70*L$5 -> 11.48 | M34: =Worldprices!$G$70*M$5 -> 11.48 | N34: =Worldprices!$G$70*N$5 -> 11.48 | O34: =Worldprices!$G$70*O$5 -> 11.48 | P34: =Worldprices!$G$70*P$5 -> 9.758 | Q34: =Worldprices!$G$70*Q$5 -> 11.48 | R34: =Worldprices!$G$70*R$5 -> 11.48 | ... AQ34: =Worldprices!$G$70*AQ$5 -> 11.48 | AR34: =AQ34 -> 11.48
A35: ANNUAL | B35: EUR10 | D35: =IF(RIGHT(F35,6)="GASNAT","*","COST") -> COST | E35: 2025 | F35: =Worldprices!$H$62 -> IMPOILHFO | G35: =Worldprices!$H$63 -> OILHFO | H35: =Worldprices!$H$70*H$5 -> 8.36892 | I35: =Worldprices!$H$70*I$5 -> 9.2988 | J35: =AI35 -> 9.2988 | K35: =Worldprices!$H$70*K$5 -> 9.2988 | L35: =Worldprices!$H$70*L$5 -> 9.2988 | M35: =Worldprices!$H$70*M$5 -> 9.2988 | N35: =Worldprices!$H$70*N$5 -> 9.2988 | O35: =Worldprices!$H$70*O$5 -> 9.2988 | P35: =Worldprices!$H$70*P$5 -> 7.90398 | Q35: =Worldprices!$H$70*Q$5 -> 9.2988 | R35: =Worldprices!$H$70*R$5 -> 9.2988 | ... AQ35: =Worldprices!$H$70*AQ$5 -> 9.2988 | AR35: =AQ35 -> 9.2988
A36: ANNUAL | B36: EUR10 | D36: =IF(RIGHT(F36,6)="GASNAT","*","COST") -> COST | E36: 2025 | F36: =Worldprices!$I$62 -> IMPOILDST | G36: =Worldprices!$I$63 -> OILDST | H36: =Worldprices!$I$70*H$6 -> 14.924 | I36: =Worldprices!$I$70*I$6 -> 14.924 | J36: =AI36 -> 14.924 | K36: =Worldprices!$I$70*K$6 -> 14.924 | L36: =Worldprices!$I$70*L$6 -> 14.924 | M36: =Worldprices!$I$70*M$6 -> 14.924 | N36: =Worldprices!$I$70*N$6 -> 14.924 | O36: =Worldprices!$I$70*O$6 -> 14.924 | P36: =Worldprices!$I$70*P$6 -> 14.924 | Q36: =Worldprices!$I$70*Q$6 -> 14.924 | R36: =Worldprices!$I$70*R$6 -> 14.924 | ... AQ36: =Worldprices!$I$70*AQ$6 -> 14.924 | AR36: =AQ36 -> 14.924
A37: ANNUAL | B37: EUR10 | D37: =IF(RIGHT(F37,6)="GASNAT","*","COST") -> COST | E37: 2025 | F37: =Worldprices!$J$62 -> IMPOILLPG | G37: =Worldprices!$J$63 -> OILLPG | H37: =Worldprices!$J$70*H$7 -> 12.628 | I37: =Worldprices!$J$70*I$7 -> 12.628 | J37: =AI37 -> 12.628 | K37: =Worldprices!$J$70*K$7 -> 12.628 | L37: =Worldprices!$J$70*L$7 -> 12.628 | M37: =Worldprices!$J$70*M$7 -> 12.628 | N37: =Worldprices!$J$70*N$7 -> 12.628 | O37: =Worldprices!$J$70*O$7 -> 12.628 | P37: =Worldprices!$J$70*P$7 -> 12.628 | Q37: =Worldprices!$J$70*Q$7 -> 12.628 | R37: =Worldprices!$J$70*R$7 -> 12.628 | ... AQ37: =Worldprices!$J$70*AQ$7 -> 12.628 | AR37: =AQ37 -> 12.628
A38: ANNUAL | B38: EUR10 | D38: =IF(RIGHT(F38,6)="GASNAT","*","COST") -> COST | E38: 2025 | F38: =Worldprices!$K$62 -> IMPOILGSL | G38: =Worldprices!$K$63 -> OILGSL | H38: =Worldprices!$K$70*H$7 -> 16.072 | I38: =Worldprices!$K$70*I$7 -> 16.072 | J38: =AI38 -> 16.072 | K38: =Worldprices!$K$70*K$7 -> 16.072 | L38: =Worldprices!$K$70*L$7 -> 16.072 | M38: =Worldprices!$K$70*M$7 -> 16.072 | N38: =Worldprices!$K$70*N$7 -> 16.072 | O38: =Worldprices!$K$70*O$7 -> 16.072 | P38: =Worldprices!$K$70*P$7 -> 16.072 | Q38: =Worldprices!$K$70*Q$7 -> 16.072 | R38: =Worldprices!$K$70*R$7 -> 16.072 | ... AQ38: =Worldprices!$K$70*AQ$7 -> 16.072 | AR38: =AQ38 -> 16.072
A39: ANNUAL | B39: EUR10 | D39: =IF(RIGHT(F39,6)="GASNAT","*","COST") -> COST | E39: 2025 | F39: =Worldprices!$L$62 -> IMPOILKER | G39: =Worldprices!$L$63 -> OILKER | H39: =Worldprices!$L$70*H$7 -> 16.072 | I39: =Worldprices!$L$70*I$7 -> 16.072 | J39: =AI39 -> 16.072 | K39: =Worldprices!$L$70*K$7 -> 16.072 | L39: =Worldprices!$L$70*L$7 -> 16.072 | M39: =Worldprices!$L$70*M$7 -> 16.072 | N39: =Worldprices!$L$70*N$7 -> 16.072 | O39: =Worldprices!$L$70*O$7 -> 16.072 | P39: =Worldprices!$L$70*P$7 -> 16.072 | Q39: =Worldprices!$L$70*Q$7 -> 16.072 | R39: =Worldprices!$L$70*R$7 -> 16.072 | ... AQ39: =Worldprices!$L$70*AQ$7 -> 16.072 | AR39: =AQ39 -> 16.072
A40: ANNUAL | B40: EUR10 | D40: =IF(RIGHT(F40,6)="GASNAT","*","COST") -> * | E40: 2025 | F40: =Worldprices!$Q$62 -> IMPGASNAT | G40: =Worldprices!$Q$63 -> GASNAT | H40: =Worldprices!$Q$70*H$8 -> 10.195 | I40: =Worldprices!$Q$70*I$8 -> 10.195 | J40: =AI40 -> 10.195 | K40: =Worldprices!$Q$70*K$8 -> 10.195 | L40: =Worldprices!$Q$70*L$8 -> 10.195 | M40: =Worldprices!$Q$70*M$8 -> 10.195 | N40: =Worldprices!$Q$70*N$8 -> 10.195 | O40: =Worldprices!$Q$70*O$8 -> 10.195 | P40: =Worldprices!$Q$70*P$8 -> 8.66575 | Q40: =Worldprices!$Q$70*Q$8 -> 9.1755 | R40: =Worldprices!$Q$70*R$8 -> 10.195 | ... AQ40: =Worldprices!$Q$70*AQ$8 -> 10.195 | AR40: =AQ40 -> 10.195
A41: ANNUAL | B41: EUR10 | D41: =IF(RIGHT(F41,6)="GASNAT","*","COST") -> COST | E41: 2030 | F41: =Worldprices!$G$62 -> IMPOILCRD | G41: =Worldprices!$G$63 -> OILCRD | H41: =Worldprices!$G$71*H$5 -> 12.285 | I41: =Worldprices!$G$71*I$5 -> 13.65 | J41: =AI41 -> 13.65 | K41: =Worldprices!$G$71*K$5 -> 13.65 | L41: =Worldprices!$G$71*L$5 -> 13.65 | M41: =Worldprices!$G$71*M$5 -> 13.65 | N41: =Worldprices!$G$71*N$5 -> 13.65 | O41: =Worldprices!$G$71*O$5 -> 13.65 | P41: =Worldprices!$G$71*P$5 -> 11.6025 | Q41: =Worldprices!$G$71*Q$5 -> 13.65 | R41: =Worldprices!$G$71*R$5 -> 13.65 | ... AQ41: =Worldprices!$G$71*AQ$5 -> 13.65 | AR41: =AQ41 -> 13.65
A42: ANNUAL | B42: EUR10 | D42: =IF(RIGHT(F42,6)="GASNAT","*","COST") -> COST | E42: 2030 | F42: =Worldprices!$H$62 -> IMPOILHFO | G42: =Worldprices!$H$63 -> OILHFO | H42: =Worldprices!$H$71*H$5 -> 9.95085 | I42: =Worldprices!$H$71*I$5 -> 11.0565 | J42: =AI42 -> 11.0565 | K42: =Worldprices!$H$71*K$5 -> 11.0565 | L42: =Worldprices!$H$71*L$5 -> 11.0565 | M42: =Worldprices!$H$71*M$5 -> 11.0565 | N42: =Worldprices!$H$71*N$5 -> 11.0565 | O42: =Worldprices!$H$71*O$5 -> 11.0565 | P42: =Worldprices!$H$71*P$5 -> 9.398025 | Q42: =Worldprices!$H$71*Q$5 -> 11.0565 | R42: =Worldprices!$H$71*R$5 -> 11.0565 | ... AQ42: =Worldprices!$H$71*AQ$5 -> 11.0565 | AR42: =AQ42 -> 11.0565
A43: ANNUAL | B43: EUR10 | D43: =IF(RIGHT(F43,6)="GASNAT","*","COST") -> COST | E43: 2030 | F43: =Worldprices!$I$62 -> IMPOILDST | G43: =Worldprices!$I$63 -> OILDST | H43: =Worldprices!$I$71*H$6 -> 17.745 | I43: =Worldprices!$I$71*I$6 -> 17.745 | J43: =AI43 -> 17.745 | K43: =Worldprices!$I$71*K$6 -> 17.745 | L43: =Worldprices!$I$71*L$6 -> 17.745 | M43: =Worldprices!$I$71*M$6 -> 17.745 | N43: =Worldprices!$I$71*N$6 -> 17.745 | O43: =Worldprices!$I$71*O$6 -> 17.745 | P43: =Worldprices!$I$71*P$6 -> 17.745 | Q43: =Worldprices!$I$71*Q$6 -> 17.745 | R43: =Worldprices!$I$71*R$6 -> 17.745 | ... AQ43: =Worldprices!$I$71*AQ$6 -> 17.745 | AR43: =AQ43 -> 17.745
...

Sheet INPUTtoVEDA_miningprice
B2: ~TFM_FILL
B3: Operation_Sum_Avg_Count | C3: Scenario Name | D3: TimeSlice | E3: LimType | F3: Attribute | G3: Year | H3: Other_Indexes | I3: Pset_PN | J3: AllRegions | K3: AT | L3: BE | M3: BG | N3: CH | O3: CY | P3: CZ | Q3: DE | R3: DK | S3: EE | T3: ES | U3: FI | V3: FR | W3: EL | X3: HU | Y3: IE | Z3: IS | AA3: IT | AB3: LT | AC3: LU | AD3: LV | AE3: MT | AF3: NL | AG3: NO | AH3: PL | AI3: PT | AJ3: RO | AK3: SE | AL3: SI | AM3: SK | AN3: UK | AO3: AL | AP3: BA | AQ3: HR | AR3: KS | AS3: ME | AT3: MK | AU3: RS
B4: A | C4: BASE | F4: COST | I4: MINCOHRSV1 | M4: 1.85 | P4: 1.39775 | Q4: 1.85 | T4: 1.85 | V4: 2.64495 | X4: 2.64495 | Z4: 1.2 | AA4: 1.85 | AH4: 1.39775 | AJ4: 1.39775 | AL4: 1.85 | AN4: 1.365 | AU4: 1.85
B5: A | C5: BASE | F5: COST | I5: MINCOHRSV2 | P5: 1.85 | Q5: 2.64495 | T5: 2.775 | AA5: 2.64495 | AG5: 1.39775 | AH5: 1.85 | AJ5: 1.39775 | AL5: 2.64495 | AN5: 1.39775
B6: A | C6: BASE | F6: COST | I6: MINCOHRSV3 | T6: 2.64495 | AA6: 2.64495 | AJ6: 1.85
B7: A | C7: BASE | F7: COST | I7: MINCOLRSV1 | K7: 1.097 | M7: 1.29865 | P7: 1.097 | Q7: 1.22 | S7: 1.097 | T7: 1.5 | U7: 0.994 | W7: 1.5 | X7: 1.2 | Y7: 1.097 | AA7: 1.22 | AB7: 1.097 | AD7: 1.097 | AH7: 1.097 | AJ7: 1.097 | AK7: 1.22 | AL7: 1.22 | AM7: 1.22 | AO7: 1.22 | AP7: 1.22 | AR7: 1.22 | AS7: 1.22 | AT7: 1.22 | AU7: 1.22
B8: A | C8: BASE | F8: COST | I8: MINCOLRSV2 | P8: 1.22 | Q8: 1.5 | S8: 1.22 | T8: 2.25 | U8: 0.994 | W8: 1.5 | Y8: 1.097 | AA8: 1.5 | AH8: 1.22 | AJ8: 1.22 | AL8: 1.4973 | AP8: 1.5
B9: A | C9: BASE | F9: COST | I9: MINCOLRSV3 | S9: 1.22 | T9: 1.5 | U9: 1.22 | AA9: 1.5 | AJ9: 1.22
B10: A | C10: BASE | F10: COST | I10: MINGASRSV1 | K10: 1.825 | M10: 1.825 | P10: 1.825 | Q10: 1.825 | R10: 1.0504166 | T10: 1.825 | V10: 1.825 | W10: 2.6 | X10: 1.825 | Y10: 1.0504166 | AF10: 1.0504166 | AG10: 1.0504166 | AH10: 1.825 | AI10: 1.825 | AJ10: 1.825 | AK10: 1.825 | AM10: 1.825 | AN10: 1.0504166 | AO10: 1.825 | AQ10: 1.825 | AU10: 1.825
B11: A | C11: BASE | F11: \I: | I11: MINGASRSV2
B12: A | C12: BASE | F12: \I: | I12: MINGASRSV3
B13: A | C13: BASE | F13: COST | I13: MINGASRSV4 | K13: 2.6 | M13: 2.6 | P13: 2.6 | Q13: 2.6 | R13: 1.825 | T13: 2.6 | V13: 2.6 | W13: 2.6 | X13: 2.6 | Y13: 1.8717496 | AF13: 1.0504166 | AG13: 1.0504166 | AH13: 2.6 | AI13: 1.825 | AJ13: 2.6 | AK13: 1.825 | AM13: 2.6 | AN13: 1.825
B14: A | C14: BASE | F14: \I: | I14: MINGASRSV5
B15: A | C15: BASE | F15: \I: | I15: MINGASRSV6
B16: A | C16: BASE | F16: COST | I16: MINGASRSV7 | K16: 2.6 | P16: 2.6 | Q16: 2.6 | R16: 1.825 | T16: 2.6 | V16: 2.6 | X16: 2.6 | AF16: 1.825 | AG16: 1.0504166 | AH16: 2.6 | AJ16: 2.6 | AL16: 1.825 | AN16: 1.825
B17: A | C17: BASE | F17: \I: | I17: MINGASRSV8
B18: A | C18: BASE | F18: \I: | I18: MINGASRSV9
B19: A | C19: BASE | F19: COST | I19: MINOILRSV1 | K19: 3 | M19: 1.8046779 | P19: 3 | Q19: 3 | R19: 1.8046779 | T19: 3 | V19: 3 | W19: 3 | X19: 3 | AB19: 3 | AF19: 1.8046779 | AG19: 1.8046779 | AH19: 3 | AJ19: 3 | AM19: 3 | AN19: 1.8046779 | AO19: 3 | AQ19: 3 | AU19: 3
B20: A | C20: BASE | F20: COST | I20: MINOILRSV2 | AB20: 3
B21: A | C21: BASE | F21: \I: | I21: MINOILRSV3
B22: A | C22: BASE | F22: COST | I22: MINOILRSV4 | K22: 3 | M22: 3 | P22: 3 | Q22: 3 | R22: 3 | T22: 4.5 | V22: 3.3 | W22: 3.3 | X22: 3.3 | AF22: 2.7070168 | AG22: 2.7070168 | AH22: 3 | AJ22: 4.5 | AM22: 3 | AN22: 2.7070168
B23: A | C23: BASE | F23: \I: | I23: MINOILRSV5
B24: A | C24: BASE | F24: \I: | I24: MINOILRSV6
B25: A | C25: BASE | F25: COST | I25: MINOILRSV7 | M25: 3.3 | P25: 3.3 | Q25: 3.3 | R25: 3 | T25: 5.25 | V25: 3.3 | X25: 3.3 | AF25: 3.1581863 | AG25: 3.1581863 | AH25: 3 | AJ25: 5.25 | AM25: 3.3 | AN25: 3.1581863
B26: A | C26: BASE | F26: \I: | I26: MINOILRSV8
B27: A | C27: BASE | F27: \I: | I27: MINOILRSV9
A31: Growth rate Import GASNAT and Crude oil
B32: GASNAT | C32: CRUDE
A33: =Worldprices!B65 -> 2001 | B33: =Worldprices!Q65/Worldprices!Q64 -> 1.2986213 | C33: =Worldprices!G65/Worldprices!G64 -> 0.83765716
A34: =Worldprices!B66 -> 2005 | B34: =Worldprices!Q66/Worldprices!Q65 -> 1.2768027 | C34: =Worldprices!G66/Worldprices!G65 -> 2.0258512
A35: =Worldprices!B67 -> 2010 | B35: =Worldprices!Q67/Worldprices!Q66 -> 1.3086858 | C35: =Worldprices!G67/Worldprices!G66 -> 1.1689297
A36: =Worldprices!B68 -> 2015 | B36: =Worldprices!Q68/Worldprices!Q67 -> 1.5804101 | C36: =Worldprices!G68/Worldprices!G67 -> 0.97404841
A37: =Worldprices!B69 -> 2020 | B37: =Worldprices!Q69/Worldprices!Q68 -> 1.3672528 | C37: =Worldprices!G69/Worldprices!G68 -> 0.97335699
A38: =Worldprices!B70 -> 2025 | B38: =Worldprices!Q70/Worldprices!Q69 -> 0.7613891 | C38: =Worldprices!G70/Worldprices!G69 -> 1.2330827
A39: =Worldprices!B71 -> 2030 | B39: =Worldprices!Q71/Worldprices!Q70 -> 0.68661108 | C39: =Worldprices!G71/Worldprices!G70 -> 1.1890244
A40: =Worldprices!B72 -> 2035 | B40: =Worldprices!Q72/Worldprices!Q71 -> 1 | C40: =Worldprices!G72/Worldprices!G71 -> 1.029304
A41: =Worldprices!B73 -> 2040 | B41: =Worldprices!Q73/Worldprices!Q72 -> 1 | C41: =Worldprices!G73/Worldprices!G72 -> 1.0284698
A42: =Worldprices!B74 -> 2045 | B42: =Worldprices!Q74/Worldprices!Q73 -> 1 | C42: =Worldprices!G74/Worldprices!G73 -> 1.1044983
A43: =Worldprices!B75 -> 2050 | B43: =Worldprices!Q75/Worldprices!Q74 -> 1 | C43: =Worldprices!G75/Worldprices!G74 -> 1.0946115
E45: ~TFM_INS
...

Sheet INPUTtoVEDA_importpriceNT
A1: ='INPUTtoVEDA_importprice TR'!A1 -> Adjustment factors derived from the computation of the delivery cost
G3: ='INPUTtoVEDA_importprice TR'!H3 -> AT | H3: ='INPUTtoVEDA_importprice TR'!I3 -> BE | I3: BG | J3: ='INPUTtoVEDA_importprice TR'!K3 -> DE | K3: ='INPUTtoVEDA_importprice TR'!L3 -> DK | L3: ='INPUTtoVEDA_importprice TR'!M3 -> FI | M3: ='INPUTtoVEDA_importprice TR'!N3 -> FR | N3: ='INPUTtoVEDA_importprice TR'!O3 -> EL | O3: ='INPUTtoVEDA_importprice TR'!P3 -> IE | P3: ='INPUTtoVEDA_importprice TR'!Q3 -> IT | Q3: ='INPUTtoVEDA_importprice TR'!R3 -> NL | ... AJ3: ='INPUTtoVEDA_importprice TR'!AK3 -> NO | AK3: AL | AL3: BA | AM3: HR | AN3: ME | AO3: MK | AP3: RS | AQ3: KS
C4: ='INPUTtoVEDA_importprice TR'!D4 -> Coal | G4: ='INPUTtoVEDA_importprice TR'!H4 -> 1 | H4: ='INPUTtoVEDA_importprice TR'!I4 -> 0.935 | I4: 1 | J4: ='INPUTtoVEDA_importprice TR'!K4 -> 1 | K4: ='INPUTtoVEDA_importprice TR'!L4 -> 1 | L4: ='INPUTtoVEDA_importprice TR'!M4 -> 1 | M4: ='INPUTtoVEDA_importprice TR'!N4 -> 1 | N4: ='INPUTtoVEDA_importprice TR'!O4 -> 1 | O4: ='INPUTtoVEDA_importprice TR'!P4 -> 0.85 | P4: ='INPUTtoVEDA_importprice TR'!Q4 -> 0.95 | Q4: ='INPUTtoVEDA_importprice TR'!R4 -> 1 | ... AP4: ='INPUTtoVEDA_importprice TR'!AQ4 -> 1 | AQ4: 1
C5: ='INPUTtoVEDA_importprice TR'!D5 -> Heavy Distillate Oil | G5: ='INPUTtoVEDA_importprice TR'!H5 -> 0.9 | H5: ='INPUTtoVEDA_importprice TR'!I5 -> 1 | I5: 1 | J5: ='INPUTtoVEDA_importprice TR'!K5 -> 1 | K5: ='INPUTtoVEDA_importprice TR'!L5 -> 1 | L5: ='INPUTtoVEDA_importprice TR'!M5 -> 1 | M5: ='INPUTtoVEDA_importprice TR'!N5 -> 1 | N5: ='INPUTtoVEDA_importprice TR'!O5 -> 1 | O5: ='INPUTtoVEDA_importprice TR'!P5 -> 0.85 | P5: ='INPUTtoVEDA_importprice TR'!Q5 -> 1 | Q5: ='INPUTtoVEDA_importprice TR'!R5 -> 1 | ... AP5: ='INPUTtoVEDA_importprice TR'!AQ5 -> 1 | AQ5: 1
C6: ='INPUTtoVEDA_importprice TR'!D6 -> Light Distilate Oil | G6: ='INPUTtoVEDA_importprice TR'!H6 -> 1 | H6: ='INPUTtoVEDA_importprice TR'!I6 -> 1 | I6: 1 | J6: ='INPUTtoVEDA_importprice TR'!K6 -> 1 | K6: ='INPUTtoVEDA_importprice TR'!L6 -> 1 | L6: ='INPUTtoVEDA_importprice TR'!M6 -> 1 | M6: ='INPUTtoVEDA_importprice TR'!N6 -> 1 | N6: ='INPUTtoVEDA_importprice TR'!O6 -> 1 | O6: ='INPUTtoVEDA_importprice TR'!P6 -> 1 | P6: ='INPUTtoVEDA_importprice TR'!Q6 -> 1 | Q6: ='INPUTtoVEDA_importprice TR'!R6 -> 1 | ... AP6: ='INPUTtoVEDA_importprice TR'!AQ6 -> 1 | AQ6: 1
C7: ='INPUTtoVEDA_importprice TR'!D7 -> Gasoline | G7: ='INPUTtoVEDA_importprice TR'!H7 -> 1 | H7: ='INPUTtoVEDA_importprice TR'!I7 -> 1 | I7: 1 | J7: ='INPUTtoVEDA_importprice TR'!K7 -> 1 | K7: ='INPUTtoVEDA_importprice TR'!L7 -> 1 | L7: ='INPUTtoVEDA_importprice TR'!M7 -> 1 | M7: ='INPUTtoVEDA_importprice TR'!N7 -> 1 | N7: ='INPUTtoVEDA_importprice TR'!O7 -> 1 | O7: ='INPUTtoVEDA_importprice TR'!P7 -> 1 | P7: ='INPUTtoVEDA_importprice TR'!Q7 -> 1 | Q7: ='INPUTtoVEDA_importprice TR'!R7 -> 1 | ... AP7: ='INPUTtoVEDA_importprice TR'!AQ7 -> 1 | AQ7: 1
C8: Wood Imp. | G8: 1 | H8: 1 | I8: 1 | J8: 1 | K8: 1 | L8: 1 | M8: 1 | N8: 1 | O8: 1 | P8: 1 | Q8: 1 | R8: 1 | S8: 1 | T8: 1 | U8: 1 | V8: 1 | W8: 1 | X8: 1 | Y8: 1 | Z8: 1 | AA8: 1 | AB8: 1 | AC8: 1 | AD8: 1 | AE8: 1 | AF8: 1 | AG8: 1 | AH8: 1 | AI8: 1 | AJ8: 1 | AK8: 1 | AL8: 1 | AM8: 1 | AN8: 1 | AO8: 1 | AP8: 1 | AQ8: 1
C9: Wood Dom. | G9: 1 | H9: 1 | I9: 1 | J9: 1 | K9: 1 | L9: 1 | M9: 1 | N9: 1 | O9: 1 | P9: 1 | Q9: 1 | R9: 1 | S9: 1.5 | T9: 1 | U9: 1 | V9: 1 | W9: 1 | X9: 1 | Y9: 1 | Z9: 1 | AA9: 1 | AB9: 1 | AC9: 1 | AD9: 1 | AE9: 1 | AF9: 1 | AG9: 1 | AH9: 1 | AI9: 1 | AJ9: 1 | AK9: 1 | AL9: 1 | AM9: 1 | AN9: 1 | AO9: 1 | AP9: 1 | AQ9: 1
C10: Mun Waste | G10: 1 | H10: 1 | I10: 1 | J10: 1 | K10: 1 | L10: 1 | M10: 1 | N10: 1 | O10: 1 | P10: 1 | Q10: 1 | R10: 1 | S10: 1 | T10: 1 | U10: 1 | V10: 1 | W10: 1 | X10: 1 | Y10: 1 | Z10: 1 | AA10: 1 | AB10: 1 | AC10: 1 | AD10: 1 | AE10: 1 | AF10: 1 | AG10: 1 | AH10: 1 | AI10: 1 | AJ10: 1 | AK10: 1 | AL10: 1 | AM10: 1 | AN10: 1 | AO10: 1 | AP10: 1 | AQ10: 1
C11: GASNAT | G11: ='INPUTtoVEDA_importprice TR'!H8 -> 1 | H11: ='INPUTtoVEDA_importprice TR'!I8 -> 1 | I11: ='INPUTtoVEDA_importprice TR'!J8 -> 0 | J11: ='INPUTtoVEDA_importprice TR'!K8 -> 1 | K11: ='INPUTtoVEDA_importprice TR'!L8 -> 1 | L11: ='INPUTtoVEDA_importprice TR'!M8 -> 1 | M11: ='INPUTtoVEDA_importprice TR'!N8 -> 1 | N11: ='INPUTtoVEDA_importprice TR'!O8 -> 1 | ... AP11: ='INPUTtoVEDA_importprice TR'!AQ8 -> 1 | AQ11: 11
A12: ~TFM_INS
A13: TimeSlice | B13: Curr | C13: Attribute | D13: Year | E13: Pset_PN | F13: Cset_CN | G13: AT | H13: BE | I13: BG | J13: DE | K13: DK | L13: FI | M13: FR | N13: EL | O13: IE | P13: IT | Q13: NL | R13: PT | S13: ES | T13: SE | U13: UK | V13: HU | W13: PL | X13: CZ | Y13: SK | Z13: CH | AA13: CY | AB13: EE | AC13: IS | AD13: LT | AE13: LU | AF13: LV | AG13: MT | AH13: RO | AI13: SI | AJ13: NO | AK13: AL | AL13: BA | AM13: HR | AN13: ME | AO13: MK | AP13: RS | AQ13: KS
A14: ANNUAL | B14: EUR10 | C14: COST | D14: 2010 | E14: =Worldprices!$C$62 -> IMPCOAHAR* | F14: =Worldprices!$C$63 -> COAHAR | G14: =Worldprices!$C$67*G$4 -> 2.6229508 | H14: =Worldprices!$C$67*H$4 -> 2.452459 | I14: =AH14 -> 2.6229508 | J14: =Worldprices!$C$67*J$4 -> 2.6229508 | K14: =Worldprices!$C$67*K$4 -> 2.6229508 | L14: =Worldprices!$C$67*L$4 -> 2.6229508 | M14: =Worldprices!$C$67*M$4 -> 2.6229508 | N14: =Worldprices!$C$67*N$4 -> 2.6229508 | O14: =Worldprices!$C$67*O$4 -> 2.2295082 | P14: =Worldprices!$C$67*P$4 -> 2.4918033 | Q14: =Worldprices!$C$67*Q$4 -> 2.6229508 | ... AP14: =Worldprices!$C$67*AP$4 -> 2.6229508 | AQ14: =AP14 -> 2.6229508
A15: ANNUAL | B15: EUR10 | C15: COST | D15: 2010 | E15: =Worldprices!$D$62 -> IMPCOACOK* | F15: =Worldprices!$D$63 -> COACOK | G15: =Worldprices!$D$67*G$4 -> 3.3311475 | H15: =Worldprices!$D$67*H$4 -> 3.114623 | I15: =AH15 -> 3.3311475 | J15: =Worldprices!$D$67*J$4 -> 3.3311475 | K15: =Worldprices!$D$67*K$4 -> 3.3311475 | L15: =Worldprices!$D$67*L$4 -> 3.3311475 | M15: =Worldprices!$D$67*M$4 -> 3.3311475 | N15: =Worldprices!$D$67*N$4 -> 3.3311475 | O15: =Worldprices!$D$67*O$4 -> 2.8314754 | P15: =Worldprices!$D$67*P$4 -> 3.1645902 | Q15: =Worldprices!$D$67*Q$4 -> 3.3311475 | ... AP15: =Worldprices!$D$67*AP$4 -> 3.3311475 | AQ15: =AP15 -> 3.3311475
A16: ANNUAL | B16: EUR10 | C16: COST | D16: 2010 | E16: =Worldprices!$E$62 -> IMPCOABRO* | F16: =Worldprices!$E$63 -> COABRO | G16: =Worldprices!$E$67*G$4 -> 2.4918033 | H16: =Worldprices!$E$67*H$4 -> 2.3298361 | I16: =AH16 -> 2.4918033 | J16: =Worldprices!$E$67*J$4 -> 2.4918033 | K16: =Worldprices!$E$67*K$4 -> 2.4918033 | L16: =Worldprices!$E$67*L$4 -> 2.4918033 | M16: =Worldprices!$E$67*M$4 -> 2.4918033 | N16: =Worldprices!$E$67*N$4 -> 2.4918033 | O16: =Worldprices!$E$67*O$4 -> 2.1180328 | P16: =Worldprices!$E$67*P$4 -> 2.3672131 | Q16: =Worldprices!$E$67*Q$4 -> 2.4918033 | ... AP16: =Worldprices!$E$67*AP$4 -> 2.4918033 | AQ16: =AP16 -> 2.4918033
A17: ANNUAL | B17: EUR10 | C17: COST | D17: 2010 | E17: =Worldprices!$F$62 -> IMPCOALIG* | F17: =Worldprices!$F$63 -> COALIG | G17: =Worldprices!$F$67*G$4 -> 2.4918033 | H17: =Worldprices!$F$67*H$4 -> 2.3298361 | I17: =AH17 -> 2.4918033 | J17: =Worldprices!$F$67*J$4 -> 2.4918033 | K17: =Worldprices!$F$67*K$4 -> 2.4918033 | L17: =Worldprices!$F$67*L$4 -> 2.4918033 | M17: =Worldprices!$F$67*M$4 -> 2.4918033 | N17: =Worldprices!$F$67*N$4 -> 2.4918033 | O17: =Worldprices!$F$67*O$4 -> 2.1180328 | P17: =Worldprices!$F$67*P$4 -> 2.3672131 | Q17: =Worldprices!$F$67*Q$4 -> 2.4918033 | ... AP17: =Worldprices!$F$67*AP$4 -> 2.4918033 | AQ17: =AP17 -> 2.4918033
