Workbook
Name BE: #REF!
Name BE: #REF!
Name bel: #REF!
Name bel: #REF!
Name dsg: #REF!
Name dsg: #REF!
Name Scenario: [1]BioCrops!$G$1
Name Scenario: #REF!
Name Summer: #REF!
Name Summer: #REF!
Name Summer1: #REF!
Name Summer1: #REF!
Name ToeTJ: #REF!
Name ToeTJ: #REF!
Name TSeg: #REF!
Name TSeg: #REF!
Name TSEG1: #REF!
Name TSEG1: #REF!
Name TSEG2: #REF!
Name TSEG2: #REF!
Name TSEG3: #REF!
Name TSEG3: #REF!
Name TSEG4: #REF!
Name TSEG4: #REF!
Name TSEG5: #REF!
Name TSEG5: #REF!
Name Winter: #REF!
Name Winter: #REF!

Sheet POLICY
A1: EU Climate Targets
B3: ~UC_SETS: R_S: AT,BE,BG,CY,CZ,DE,DK,EE,ES,FI,FR,EL,HU,IE,IT,LT,LU,LV,MT,NL,PL,PT,RO,SE,SI,SK,HR
D5: ~UC_T: UP
B6: UC_N | C6: Cset_CN | D6: Year | E6: UC_COMNET | F6: UC_RHSTS
B7: CO2TargetEU27 | C7: TOTCO2 | D7: 2010 | E7: 1 | F7: =scenassumptions!I6 -> 3663881.1
C8: TOTCO2 | D8: 2015 | F8: =scenassumptions!I7 -> 3310547.7
C9: TOTCO2 | D9: 2020 | F9: =scenassumptions!I8 -> 3156134.2
C10: TOTCO2 | D10: 2030 | F10: =scenassumptions!I10 -> 1546975.8
C11: TOTCO2 | D11: 2035 | F11: =scenassumptions!I11 -> 945374.1
C12: TOTCO2 | D12: 2040 | F12: =scenassumptions!I12 -> 343772.4
C13: TOTCO2 | D13: 2045 | F13: =scenassumptions!I13 -> 171886.2
C14: TOTCO2 | D14: 2050 | F14: =scenassumptions!I14 -> 0
C15: TOTCO2 | D15: 2060 | F15: =-F12 -> -343772.4
C16: TOTCO2 | D16: 0 | F16: 5 | I16: Climate targets for CH, IS, NO and UK are set in the table below as regional target
A20: Regional modelled CO2 bounds | K20: flexibility for the model | M20: up | N20: =1+0.01 -> 1.01 | O20: low | P20: =1-0.01 -> 0.99
B22: ~UC_Sets: R_E: AllRegions
B23: ~UC_Sets: T_E:
I24: ~UC_T: UC_RHSRT~UP
B25: UC_N | C25: UC_Desc | D25: Pset_Set | E25: Pset_PN | F25: Cset_CN | G25: Attribute | H25: Year | I25: UC_COMNET | J25: UC_RHSRT~UP~0 | K25: AT | L25: BE | M25: BG | N25: CH | O25: CY | P25: CZ | Q25: DE | R25: DK | S25: EE | T25: EL | U25: ES | V25: FI | W25: FR | X25: HR | Y25: HU | Z25: IE | AA25: IS | AB25: IT | AC25: LT | AD25: LU | AE25: LV | AF25: MT | AG25: NL | AH25: NO | AI25: PL | AJ25: PT | AK25: RO | AL25: SE | AM25: SI | AN25: SK | AO25: UK | AQ25: EU27 | AR25: EU31
B26: CO2TargetRegionsUp | C26: CO2TargetRegionalUpper | F26: TOTCO2 | H26: 2010 | I26: 1 | J26: 5 | K26: =SUMIFS(historicalGHG!E:E,historicalGHG!$C:$C,POLICY!$H26,historicalGHG!$D:$D,"co2",historicalGHG!$B:$B,"modelled sectors")*$N$20 -> 74572.631 | L26: =SUMIFS(historicalGHG!F:F,historicalGHG!$C:$C,POLICY!$H26,historicalGHG!$D:$D,"co2",historicalGHG!$B:$B,"modelled sectors")*$N$20 -> 144102.02 | M26: =SUMIFS(historicalGHG!G:G,historicalGHG!$C:$C,POLICY!$H26,historicalGHG!$D:$D,"co2",historicalGHG!$B:$B,"modelled sectors")*$N$20 -> 48667.751 | N26: =SUMIFS(historicalGHG!H:H,historicalGHG!$C:$C,POLICY!$H26,historicalGHG!$D:$D,"co2",historicalGHG!$B:$B,"modelled sectors")*$N$20 -> 49705.296 | O26: =SUMIFS(historicalGHG!I:I,historicalGHG!$C:$C,POLICY!$H26,historicalGHG!$D:$D,"co2",historicalGHG!$B:$B,"modelled sectors")*$N$20 -> 9611.5697 | P26: =SUMIFS(historicalGHG!J:J,historicalGHG!$C:$C,POLICY!$H26,historicalGHG!$D:$D,"co2",historicalGHG!$B:$B,"modelled sectors")*$N$20 -> 119018.55 | Q26: =SUMIFS(historicalGHG!K:K,historicalGHG!$C:$C,POLICY!$H26,historicalGHG!$D:$D,"co2",historicalGHG!$B:$B,"modelled sectors")*$N$20 -> 867189.27 | R26: =SUMIFS(historicalGHG!L:L,historicalGHG!$C:$C,POLICY!$H26,historicalGHG!$D:$D,"co2",historicalGHG!$B:$B,"modelled sectors")*$N$20 -> 55369.075 | S26: =SUMIFS(historicalGHG!M:M,historicalGHG!$C:$C,POLICY!$H26,historicalGHG!$D:$D,"co2",historicalGHG!$B:$B,"modelled sectors")*$N$20 -> 19959.824 | T26: =SUMIFS(historicalGHG!N:N,historicalGHG!$C:$C,POLICY!$H26,historicalGHG!$D:$D,"co2",historicalGHG!$B:$B,"modelled sectors")*$N$20 -> 109771.34 | U26: =SUMIFS(historicalGHG!O:O,historicalGHG!$C:$C,POLICY!$H26,historicalGHG!$D:$D,"co2",historicalGHG!$B:$B,"modelled sectors")*$N$20 -> 323293.67 | V26: =SUMIFS(historicalGHG!P:P,historicalGHG!$C:$C,POLICY!$H26,historicalGHG!$D:$D,"co2",historicalGHG!$B:$B,"modelled sectors")*$N$20 -> 66674.423 | W26: =SUMIFS(historicalGHG!Q:Q,historicalGHG!$C:$C,POLICY!$H26,historicalGHG!$D:$D,"co2",historicalGHG!$B:$B,"modelled sectors")*$N$20 -> 411220.69 | X26: =SUMIFS(historicalGHG!R:R,historicalGHG!$C:$C,POLICY!$H26,historicalGHG!$D:$D,"co2",historicalGHG!$B:$B,"modelled sectors")*$N$20 -> 20910.688 | Y26: =SUMIFS(historicalGHG!S:S,historicalGHG!$C:$C,POLICY!$H26,historicalGHG!$D:$D,"co2",historicalGHG!$B:$B,"modelled sectors")*$N$20 -> 52928.3 | Z26: =SUMIFS(historicalGHG!T:T,historicalGHG!$C:$C,POLICY!$H26,historicalGHG!$D:$D,"co2",historicalGHG!$B:$B,"modelled sectors")*$N$20 -> 44341.698 | AA26: =SUMIFS(historicalGHG!U:U,historicalGHG!$C:$C,POLICY!$H26,historicalGHG!$D:$D,"co2",historicalGHG!$B:$B,"modelled sectors")*$N$20 -> 3842.6597 | AB26: =SUMIFS(historicalGHG!V:V,historicalGHG!$C:$C,POLICY!$H26,historicalGHG!$D:$D,"co2",historicalGHG!$B:$B,"modelled sectors")*$N$20 -> 455048.1 | AC26: =SUMIFS(historicalGHG!W:W,historicalGHG!$C:$C,POLICY!$H26,historicalGHG!$D:$D,"co2",historicalGHG!$B:$B,"modelled sectors")*$N$20 -> 14237.181 | AD26: =SUMIFS(historicalGHG!X:X,historicalGHG!$C:$C,POLICY!$H26,historicalGHG!$D:$D,"co2",historicalGHG!$B:$B,"modelled sectors")*$N$20 -> 12605.071 | AE26: =SUMIFS(historicalGHG!Y:Y,historicalGHG!$C:$C,POLICY!$H26,historicalGHG!$D:$D,"co2",historicalGHG!$B:$B,"modelled sectors")*$N$20 -> 9809.2207 | AF26: =SUMIFS(historicalGHG!Z:Z,historicalGHG!$C:$C,POLICY!$H26,historicalGHG!$D:$D,"co2",historicalGHG!$B:$B,"modelled sectors")*$N$20 -> 7630.4963 | AG26: =SUMIFS(historicalGHG!AA:AA,historicalGHG!$C:$C,POLICY!$H26,historicalGHG!$D:$D,"co2",historicalGHG!$B:$B,"modelled sectors")*$N$20 -> 238279.39 | AH26: =SUMIFS(historicalGHG!AB:AB,historicalGHG!$C:$C,POLICY!$H26,historicalGHG!$D:$D,"co2",historicalGHG!$B:$B,"modelled sectors")*$N$20 -> 45889.076 | AI26: =SUMIFS(historicalGHG!AC:AC,historicalGHG!$C:$C,POLICY!$H26,historicalGHG!$D:$D,"co2",historicalGHG!$B:$B,"modelled sectors")*$N$20 -> 334862.67 | AJ26: =SUMIFS(historicalGHG!AD:AD,historicalGHG!$C:$C,POLICY!$H26,historicalGHG!$D:$D,"co2",historicalGHG!$B:$B,"modelled sectors")*$N$20 -> 57142.251 | AK26: =SUMIFS(historicalGHG!AE:AE,historicalGHG!$C:$C,POLICY!$H26,historicalGHG!$D:$D,"co2",historicalGHG!$B:$B,"modelled sectors")*$N$20 -> 86221.441 | AL26: =SUMIFS(historicalGHG!AF:AF,historicalGHG!$C:$C,POLICY!$H26,historicalGHG!$D:$D,"co2",historicalGHG!$B:$B,"modelled sectors")*$N$20 -> 61613.074 | AM26: =SUMIFS(historicalGHG!AG:AG,historicalGHG!$C:$C,POLICY!$H26,historicalGHG!$D:$D,"co2",historicalGHG!$B:$B,"modelled sectors")*$N$20 -> 16546.505 | AN26: =SUMIFS(historicalGHG!AH:AH,historicalGHG!$C:$C,POLICY!$H26,historicalGHG!$D:$D,"co2",historicalGHG!$B:$B,"modelled sectors")*$N$20 -> 38893.024 | AO26: 444289.03 | AQ26: =AR26-AO26-AH26-AA26-N26 -> 3700519.9 | AR26: =SUM(K26:AO26) -> 4244246
F27: TOTCO2 | H27: 2015 | K27: =SUMIFS(historicalGHG!E:E,historicalGHG!$C:$C,POLICY!$H27,historicalGHG!$D:$D,"co2",historicalGHG!$B:$B,"modelled sectors")*$N$20 -> 68913.617 | L27: =SUMIFS(historicalGHG!F:F,historicalGHG!$C:$C,POLICY!$H27,historicalGHG!$D:$D,"co2",historicalGHG!$B:$B,"modelled sectors")*$N$20 -> 125053.26 | M27: =SUMIFS(historicalGHG!G:G,historicalGHG!$C:$C,POLICY!$H27,historicalGHG!$D:$D,"co2",historicalGHG!$B:$B,"modelled sectors")*$N$20 -> 48736.614 | N27: =SUMIFS(historicalGHG!H:H,historicalGHG!$C:$C,POLICY!$H27,historicalGHG!$D:$D,"co2",historicalGHG!$B:$B,"modelled sectors")*$N$20 -> 43991.838 | O27: =SUMIFS(historicalGHG!I:I,historicalGHG!$C:$C,POLICY!$H27,historicalGHG!$D:$D,"co2",historicalGHG!$B:$B,"modelled sectors")*$N$20 -> 8574.3881 | P27: =SUMIFS(historicalGHG!J:J,historicalGHG!$C:$C,POLICY!$H27,historicalGHG!$D:$D,"co2",historicalGHG!$B:$B,"modelled sectors")*$N$20 -> 106239.19 | Q27: =SUMIFS(historicalGHG!K:K,historicalGHG!$C:$C,POLICY!$H27,historicalGHG!$D:$D,"co2",historicalGHG!$B:$B,"modelled sectors")*$N$20 -> 832448.3 | R27: =SUMIFS(historicalGHG!L:L,historicalGHG!$C:$C,POLICY!$H27,historicalGHG!$D:$D,"co2",historicalGHG!$B:$B,"modelled sectors")*$N$20 -> 41345.274 | S27: =SUMIFS(historicalGHG!M:M,historicalGHG!$C:$C,POLICY!$H27,historicalGHG!$D:$D,"co2",historicalGHG!$B:$B,"modelled sectors")*$N$20 -> 17040.816 | T27: =SUMIFS(historicalGHG!N:N,historicalGHG!$C:$C,POLICY!$H27,historicalGHG!$D:$D,"co2",historicalGHG!$B:$B,"modelled sectors")*$N$20 -> 84387.925 | U27: =SUMIFS(historicalGHG!O:O,historicalGHG!$C:$C,POLICY!$H27,historicalGHG!$D:$D,"co2",historicalGHG!$B:$B,"modelled sectors")*$N$20 -> 308395.61 | V27: =SUMIFS(historicalGHG!P:P,historicalGHG!$C:$C,POLICY!$H27,historicalGHG!$D:$D,"co2",historicalGHG!$B:$B,"modelled sectors")*$N$20 -> 47259.982 | W27: =SUMIFS(historicalGHG!Q:Q,historicalGHG!$C:$C,POLICY!$H27,historicalGHG!$D:$D,"co2",historicalGHG!$B:$B,"modelled sectors")*$N$20 -> 367178.19 | X27: =SUMIFS(historicalGHG!R:R,historicalGHG!$C:$C,POLICY!$H27,historicalGHG!$D:$D,"co2",historicalGHG!$B:$B,"modelled sectors")*$N$20 -> 18049.542 | Y27: =SUMIFS(historicalGHG!S:S,historicalGHG!$C:$C,POLICY!$H27,historicalGHG!$D:$D,"co2",historicalGHG!$B:$B,"modelled sectors")*$N$20 -> 47376.132 | Z27: =SUMIFS(historicalGHG!T:T,historicalGHG!$C:$C,POLICY!$H27,historicalGHG!$D:$D,"co2",historicalGHG!$B:$B,"modelled sectors")*$N$20 -> 41586.249 | AA27: =SUMIFS(historicalGHG!U:U,historicalGHG!$C:$C,POLICY!$H27,historicalGHG!$D:$D,"co2",historicalGHG!$B:$B,"modelled sectors")*$N$20 -> 4231.8679 | AB27: =SUMIFS(historicalGHG!V:V,historicalGHG!$C:$C,POLICY!$H27,historicalGHG!$D:$D,"co2",historicalGHG!$B:$B,"modelled sectors")*$N$20 -> 377068.9 | AC27: =SUMIFS(historicalGHG!W:W,historicalGHG!$C:$C,POLICY!$H27,historicalGHG!$D:$D,"co2",historicalGHG!$B:$B,"modelled sectors")*$N$20 -> 13399.479 | AD27: =SUMIFS(historicalGHG!X:X,historicalGHG!$C:$C,POLICY!$H27,historicalGHG!$D:$D,"co2",historicalGHG!$B:$B,"modelled sectors")*$N$20 -> 10817.004 | AE27: =SUMIFS(historicalGHG!Y:Y,historicalGHG!$C:$C,POLICY!$H27,historicalGHG!$D:$D,"co2",historicalGHG!$B:$B,"modelled sectors")*$N$20 -> 8459.7029 | AF27: =SUMIFS(historicalGHG!Z:Z,historicalGHG!$C:$C,POLICY!$H27,historicalGHG!$D:$D,"co2",historicalGHG!$B:$B,"modelled sectors")*$N$20 -> 7034.9903 | AG27: =SUMIFS(historicalGHG!AA:AA,historicalGHG!$C:$C,POLICY!$H27,historicalGHG!$D:$D,"co2",historicalGHG!$B:$B,"modelled sectors")*$N$20 -> 217027.6 | AH27: =SUMIFS(historicalGHG!AB:AB,historicalGHG!$C:$C,POLICY!$H27,historicalGHG!$D:$D,"co2",historicalGHG!$B:$B,"modelled sectors")*$N$20 -> 45557.414 | AI27: =SUMIFS(historicalGHG!AC:AC,historicalGHG!$C:$C,POLICY!$H27,historicalGHG!$D:$D,"co2",historicalGHG!$B:$B,"modelled sectors")*$N$20 -> 312229.76 | AJ27: =SUMIFS(historicalGHG!AD:AD,historicalGHG!$C:$C,POLICY!$H27,historicalGHG!$D:$D,"co2",historicalGHG!$B:$B,"modelled sectors")*$N$20 -> 56701.257 | AK27: =SUMIFS(historicalGHG!AE:AE,historicalGHG!$C:$C,POLICY!$H27,historicalGHG!$D:$D,"co2",historicalGHG!$B:$B,"modelled sectors")*$N$20 -> 78783.821 | AL27: =SUMIFS(historicalGHG!AF:AF,historicalGHG!$C:$C,POLICY!$H27,historicalGHG!$D:$D,"co2",historicalGHG!$B:$B,"modelled sectors")*$N$20 -> 50765.899 | AM27: =SUMIFS(historicalGHG!AG:AG,historicalGHG!$C:$C,POLICY!$H27,historicalGHG!$D:$D,"co2",historicalGHG!$B:$B,"modelled sectors")*$N$20 -> 13895.227 | AN27: =SUMIFS(historicalGHG!AH:AH,historicalGHG!$C:$C,POLICY!$H27,historicalGHG!$D:$D,"co2",historicalGHG!$B:$B,"modelled sectors")*$N$20 -> 34884.423 | AO27: 412800 | AQ27: =AR27-AO27-AH27-AA27-N27 -> 3343653.1 | AR27: =SUM(K27:AO27) -> 3850234.3
F28: TOTCO2 | H28: 2020 | K28: =K29 -> 67743.075 | L28: =L29 -> 126448.13 | M28: =M29 -> 42834.273 | N28: =N29 -> 38415.291 | O28: =O29 -> 8468.2586 | P28: =P29 -> 97531.648 | Q28: =Q29 -> 703238.26 | R28: =R29 -> 33939.941 | ... AN28: =AN29 -> 35515.165
F29: TOTCO2 | H29: 2021 | K29: =SUMIFS(historicalGHG!E:E,historicalGHG!$C:$C,POLICY!$H29,historicalGHG!$D:$D,"co2",historicalGHG!$B:$B,"modelled sectors")*$N$20 -> 67743.075 | L29: =SUMIFS(historicalGHG!F:F,historicalGHG!$C:$C,POLICY!$H29,historicalGHG!$D:$D,"co2",historicalGHG!$B:$B,"modelled sectors")*$N$20 -> 126448.13 | M29: =SUMIFS(historicalGHG!G:G,historicalGHG!$C:$C,POLICY!$H29,historicalGHG!$D:$D,"co2",historicalGHG!$B:$B,"modelled sectors")*$N$20 -> 42834.273 | N29: =SUMIFS(historicalGHG!H:H,historicalGHG!$C:$C,POLICY!$H29,historicalGHG!$D:$D,"co2",historicalGHG!$B:$B,"modelled sectors")*$N$20 -> 38415.291 | O29: =SUMIFS(historicalGHG!I:I,historicalGHG!$C:$C,POLICY!$H29,historicalGHG!$D:$D,"co2",historicalGHG!$B:$B,"modelled sectors")*$N$20 -> 8468.2586 | P29: =SUMIFS(historicalGHG!J:J,historicalGHG!$C:$C,POLICY!$H29,historicalGHG!$D:$D,"co2",historicalGHG!$B:$B,"modelled sectors")*$N$20 -> 97531.648 | Q29: =SUMIFS(historicalGHG!K:K,historicalGHG!$C:$C,POLICY!$H29,historicalGHG!$D:$D,"co2",historicalGHG!$B:$B,"modelled sectors")*$N$20 -> 703238.26 | R29: =SUMIFS(historicalGHG!L:L,historicalGHG!$C:$C,POLICY!$H29,historicalGHG!$D:$D,"co2",historicalGHG!$B:$B,"modelled sectors")*$N$20 -> 33939.941 | S29: =SUMIFS(historicalGHG!M:M,historicalGHG!$C:$C,POLICY!$H29,historicalGHG!$D:$D,"co2",historicalGHG!$B:$B,"modelled sectors")*$N$20 -> 11575.55 | T29: =SUMIFS(historicalGHG!N:N,historicalGHG!$C:$C,POLICY!$H29,historicalGHG!$D:$D,"co2",historicalGHG!$B:$B,"modelled sectors")*$N$20 -> 66611.915 | U29: =SUMIFS(historicalGHG!O:O,historicalGHG!$C:$C,POLICY!$H29,historicalGHG!$D:$D,"co2",historicalGHG!$B:$B,"modelled sectors")*$N$20 -> 260705.52 | V29: =SUMIFS(historicalGHG!P:P,historicalGHG!$C:$C,POLICY!$H29,historicalGHG!$D:$D,"co2",historicalGHG!$B:$B,"modelled sectors")*$N$20 -> 39773.152 | W29: =SUMIFS(historicalGHG!Q:Q,historicalGHG!$C:$C,POLICY!$H29,historicalGHG!$D:$D,"co2",historicalGHG!$B:$B,"modelled sectors")*$N$20 -> 330940.16 | X29: =SUMIFS(historicalGHG!R:R,historicalGHG!$C:$C,POLICY!$H29,historicalGHG!$D:$D,"co2",historicalGHG!$B:$B,"modelled sectors")*$N$20 -> 17570.585 | Y29: =SUMIFS(historicalGHG!S:S,historicalGHG!$C:$C,POLICY!$H29,historicalGHG!$D:$D,"co2",historicalGHG!$B:$B,"modelled sectors")*$N$20 -> 49024.652 | Z29: =SUMIFS(historicalGHG!T:T,historicalGHG!$C:$C,POLICY!$H29,historicalGHG!$D:$D,"co2",historicalGHG!$B:$B,"modelled sectors")*$N$20 -> 38976.556 | AA29: =SUMIFS(historicalGHG!U:U,historicalGHG!$C:$C,POLICY!$H29,historicalGHG!$D:$D,"co2",historicalGHG!$B:$B,"modelled sectors")*$N$20 -> 3891.7839 | AB29: =SUMIFS(historicalGHG!V:V,historicalGHG!$C:$C,POLICY!$H29,historicalGHG!$D:$D,"co2",historicalGHG!$B:$B,"modelled sectors")*$N$20 -> 348916.29 | AC29: =SUMIFS(historicalGHG!W:W,historicalGHG!$C:$C,POLICY!$H29,historicalGHG!$D:$D,"co2",historicalGHG!$B:$B,"modelled sectors")*$N$20 -> 14415.785 | AD29: =SUMIFS(historicalGHG!X:X,historicalGHG!$C:$C,POLICY!$H29,historicalGHG!$D:$D,"co2",historicalGHG!$B:$B,"modelled sectors")*$N$20 -> 10385.85 | AE29: =SUMIFS(historicalGHG!Y:Y,historicalGHG!$C:$C,POLICY!$H29,historicalGHG!$D:$D,"co2",historicalGHG!$B:$B,"modelled sectors")*$N$20 -> 8149.0001 | AF29: =SUMIFS(historicalGHG!Z:Z,historicalGHG!$C:$C,POLICY!$H29,historicalGHG!$D:$D,"co2",historicalGHG!$B:$B,"modelled sectors")*$N$20 -> 8165.4285 | AG29: =SUMIFS(historicalGHG!AA:AA,historicalGHG!$C:$C,POLICY!$H29,historicalGHG!$D:$D,"co2",historicalGHG!$B:$B,"modelled sectors")*$N$20 -> 183488.2 | AH29: =SUMIFS(historicalGHG!AB:AB,historicalGHG!$C:$C,POLICY!$H29,historicalGHG!$D:$D,"co2",historicalGHG!$B:$B,"modelled sectors")*$N$20 -> 40592.543 | AI29: =SUMIFS(historicalGHG!AC:AC,historicalGHG!$C:$C,POLICY!$H29,historicalGHG!$D:$D,"co2",historicalGHG!$B:$B,"modelled sectors")*$N$20 -> 331238.92 | AJ29: =SUMIFS(historicalGHG!AD:AD,historicalGHG!$C:$C,POLICY!$H29,historicalGHG!$D:$D,"co2",historicalGHG!$B:$B,"modelled sectors")*$N$20 -> 43499.299 | AK29: =SUMIFS(historicalGHG!AE:AE,historicalGHG!$C:$C,POLICY!$H29,historicalGHG!$D:$D,"co2",historicalGHG!$B:$B,"modelled sectors")*$N$20 -> 77388.625 | AL29: =SUMIFS(historicalGHG!AF:AF,historicalGHG!$C:$C,POLICY!$H29,historicalGHG!$D:$D,"co2",historicalGHG!$B:$B,"modelled sectors")*$N$20 -> 47655.328 | AM29: =SUMIFS(historicalGHG!AG:AG,historicalGHG!$C:$C,POLICY!$H29,historicalGHG!$D:$D,"co2",historicalGHG!$B:$B,"modelled sectors")*$N$20 -> 13342.357 | AN29: =SUMIFS(historicalGHG!AH:AH,historicalGHG!$C:$C,POLICY!$H29,historicalGHG!$D:$D,"co2",historicalGHG!$B:$B,"modelled sectors")*$N$20 -> 35515.165 | AQ29: =AR29-AO29-AH29-AA29-N29 -> 3017541.9 | AR29: =SUM(K29:AO29) -> 3100441.5
F30: TOTCO2 | H30: 2025
F31: TOTCO2 | H31: 2030 | N31: =SUMIFS(historicalGHG!H:H,historicalGHG!$C:$C,1990,historicalGHG!$D:$D,"co2",historicalGHG!$B:$B,"modelled sectors")*0.5 -> 23579.827 | AH31: =SUMIFS(historicalGHG!AB:AB,historicalGHG!$C:$C,1990,historicalGHG!$D:$D,"co2",historicalGHG!$B:$B,"modelled sectors")*0.5 -> 17342.531 | AO31: =(-0.68*AR31+AR31)*AR32 -> 209788.72 | AQ31: UK 1990 total | AR31: =799*1000 -> 799000 | AS31: ktCO2eq
F32: TOTCO2 | H32: 2040 | AA32: 0 | AQ32: share of CO2s | AR32: =(412.8/503.1) -> 0.82051282
F33: TOTCO2 | H33: 2050 | N33: 0 | AH33: =SUMIFS(historicalGHG!AB:AB,historicalGHG!$C:$C,1990,historicalGHG!$D:$D,"co2",historicalGHG!$B:$B,"modelled sectors")*0.1 -> 3468.5063 | AO33: 0
B36: ~UC_Sets: R_E: AllRegions
B37: ~UC_Sets: T_E:
I38: ~UC_T: UC_RHSRT~LO
B39: UC_N | C39: UC_Desc | D39: Pset_Set | E39: Pset_PN | F39: Cset_CN | G39: Attribute | H39: Year | I39: UC_COMNET | J39: UC_RHSRT~LO~0 | K39: AT | L39: BE | M39: BG | N39: CH | O39: CY | P39: CZ | Q39: DE | R39: DK | S39: EE | T39: EL | U39: ES | V39: FI | W39: FR | X39: HR | Y39: HU | Z39: IE | AA39: IS | AB39: IT | AC39: LT | AD39: LU | AE39: LV | AF39: MT | AG39: NL | AH39: NO | AI39: PL | AJ39: PT | AK39: RO | AL39: SE | AM39: SI | AN39: SK | AO39: UK | AQ39: EU27 | AR39: EU31
B40: CO2TargetRegionsLo | C40: CO2TargetRegionalLower | F40: TOTCO2 | H40: 2010 | I40: 1 | J40: 1 | K40: =SUMIFS(historicalGHG!E:E,historicalGHG!$C:$C,POLICY!$H40,historicalGHG!$D:$D,"co2",historicalGHG!$B:$B,"modelled sectors")*$P$20 -> 73095.945 | L40: =SUMIFS(historicalGHG!F:F,historicalGHG!$C:$C,POLICY!$H40,historicalGHG!$D:$D,"co2",historicalGHG!$B:$B,"modelled sectors")*$P$20 -> 141248.51 | M40: =SUMIFS(historicalGHG!G:G,historicalGHG!$C:$C,POLICY!$H40,historicalGHG!$D:$D,"co2",historicalGHG!$B:$B,"modelled sectors")*$P$20 -> 47704.033 | N40: =SUMIFS(historicalGHG!H:H,historicalGHG!$C:$C,POLICY!$H40,historicalGHG!$D:$D,"co2",historicalGHG!$B:$B,"modelled sectors")*$P$20 -> 48721.033 | O40: =SUMIFS(historicalGHG!I:I,historicalGHG!$C:$C,POLICY!$H40,historicalGHG!$D:$D,"co2",historicalGHG!$B:$B,"modelled sectors")*$P$20 -> 9421.2416 | P40: =SUMIFS(historicalGHG!J:J,historicalGHG!$C:$C,POLICY!$H40,historicalGHG!$D:$D,"co2",historicalGHG!$B:$B,"modelled sectors")*$P$20 -> 116661.75 | Q40: =SUMIFS(historicalGHG!K:K,historicalGHG!$C:$C,POLICY!$H40,historicalGHG!$D:$D,"co2",historicalGHG!$B:$B,"modelled sectors")*$P$20 -> 850017.2 | R40: =SUMIFS(historicalGHG!L:L,historicalGHG!$C:$C,POLICY!$H40,historicalGHG!$D:$D,"co2",historicalGHG!$B:$B,"modelled sectors")*$P$20 -> 54272.658 | S40: =SUMIFS(historicalGHG!M:M,historicalGHG!$C:$C,POLICY!$H40,historicalGHG!$D:$D,"co2",historicalGHG!$B:$B,"modelled sectors")*$P$20 -> 19564.58 | T40: =SUMIFS(historicalGHG!N:N,historicalGHG!$C:$C,POLICY!$H40,historicalGHG!$D:$D,"co2",historicalGHG!$B:$B,"modelled sectors")*$P$20 -> 107597.65 | U40: =SUMIFS(historicalGHG!O:O,historicalGHG!$C:$C,POLICY!$H40,historicalGHG!$D:$D,"co2",historicalGHG!$B:$B,"modelled sectors")*$P$20 -> 316891.81 | V40: =SUMIFS(historicalGHG!P:P,historicalGHG!$C:$C,POLICY!$H40,historicalGHG!$D:$D,"co2",historicalGHG!$B:$B,"modelled sectors")*$P$20 -> 65354.137 | W40: =SUMIFS(historicalGHG!Q:Q,historicalGHG!$C:$C,POLICY!$H40,historicalGHG!$D:$D,"co2",historicalGHG!$B:$B,"modelled sectors")*$P$20 -> 403077.7 | X40: =SUMIFS(historicalGHG!R:R,historicalGHG!$C:$C,POLICY!$H40,historicalGHG!$D:$D,"co2",historicalGHG!$B:$B,"modelled sectors")*$P$20 -> 20496.615 | Y40: =SUMIFS(historicalGHG!S:S,historicalGHG!$C:$C,POLICY!$H40,historicalGHG!$D:$D,"co2",historicalGHG!$B:$B,"modelled sectors")*$P$20 -> 51880.215 | Z40: =SUMIFS(historicalGHG!T:T,historicalGHG!$C:$C,POLICY!$H40,historicalGHG!$D:$D,"co2",historicalGHG!$B:$B,"modelled sectors")*$P$20 -> 43463.645 | AA40: =SUMIFS(historicalGHG!U:U,historicalGHG!$C:$C,POLICY!$H40,historicalGHG!$D:$D,"co2",historicalGHG!$B:$B,"modelled sectors")*$P$20 -> 3766.5674 | AB40: =SUMIFS(historicalGHG!V:V,historicalGHG!$C:$C,POLICY!$H40,historicalGHG!$D:$D,"co2",historicalGHG!$B:$B,"modelled sectors")*$P$20 -> 446037.25 | AC40: =SUMIFS(historicalGHG!W:W,historicalGHG!$C:$C,POLICY!$H40,historicalGHG!$D:$D,"co2",historicalGHG!$B:$B,"modelled sectors")*$P$20 -> 13955.257 | AD40: =SUMIFS(historicalGHG!X:X,historicalGHG!$C:$C,POLICY!$H40,historicalGHG!$D:$D,"co2",historicalGHG!$B:$B,"modelled sectors")*$P$20 -> 12355.465 | AE40: =SUMIFS(historicalGHG!Y:Y,historicalGHG!$C:$C,POLICY!$H40,historicalGHG!$D:$D,"co2",historicalGHG!$B:$B,"modelled sectors")*$P$20 -> 9614.9787 | AF40: =SUMIFS(historicalGHG!Z:Z,historicalGHG!$C:$C,POLICY!$H40,historicalGHG!$D:$D,"co2",historicalGHG!$B:$B,"modelled sectors")*$P$20 -> 7479.3973 | AG40: =SUMIFS(historicalGHG!AA:AA,historicalGHG!$C:$C,POLICY!$H40,historicalGHG!$D:$D,"co2",historicalGHG!$B:$B,"modelled sectors")*$P$20 -> 233560.99 | AH40: =SUMIFS(historicalGHG!AB:AB,historicalGHG!$C:$C,POLICY!$H40,historicalGHG!$D:$D,"co2",historicalGHG!$B:$B,"modelled sectors")*$P$20 -> 44980.382 | AI40: =SUMIFS(historicalGHG!AC:AC,historicalGHG!$C:$C,POLICY!$H40,historicalGHG!$D:$D,"co2",historicalGHG!$B:$B,"modelled sectors")*$P$20 -> 328231.73 | AJ40: =SUMIFS(historicalGHG!AD:AD,historicalGHG!$C:$C,POLICY!$H40,historicalGHG!$D:$D,"co2",historicalGHG!$B:$B,"modelled sectors")*$P$20 -> 56010.721 | AK40: =SUMIFS(historicalGHG!AE:AE,historicalGHG!$C:$C,POLICY!$H40,historicalGHG!$D:$D,"co2",historicalGHG!$B:$B,"modelled sectors")*$P$20 -> 84514.086 | AL40: =SUMIFS(historicalGHG!AF:AF,historicalGHG!$C:$C,POLICY!$H40,historicalGHG!$D:$D,"co2",historicalGHG!$B:$B,"modelled sectors")*$P$20 -> 60393.013 | AM40: =SUMIFS(historicalGHG!AG:AG,historicalGHG!$C:$C,POLICY!$H40,historicalGHG!$D:$D,"co2",historicalGHG!$B:$B,"modelled sectors")*$P$20 -> 16218.852 | AN40: =SUMIFS(historicalGHG!AH:AH,historicalGHG!$C:$C,POLICY!$H40,historicalGHG!$D:$D,"co2",historicalGHG!$B:$B,"modelled sectors")*$P$20 -> 38122.865 | AO40: 444289.03 | AQ40: =AR40-AO40-AH40-AA40-N40 -> 3627242.3 | AR40: =SUM(K40:AO40) -> 4168999.3
F41: TOTCO2 | H41: 2015 | K41: =SUMIFS(historicalGHG!E:E,historicalGHG!$C:$C,POLICY!$H41,historicalGHG!$D:$D,"co2",historicalGHG!$B:$B,"modelled sectors")*$P$20 -> 67548.991 | L41: =SUMIFS(historicalGHG!F:F,historicalGHG!$C:$C,POLICY!$H41,historicalGHG!$D:$D,"co2",historicalGHG!$B:$B,"modelled sectors")*$P$20 -> 122576.96 | M41: =SUMIFS(historicalGHG!G:G,historicalGHG!$C:$C,POLICY!$H41,historicalGHG!$D:$D,"co2",historicalGHG!$B:$B,"modelled sectors")*$P$20 -> 47771.532 | N41: =SUMIFS(historicalGHG!H:H,historicalGHG!$C:$C,POLICY!$H41,historicalGHG!$D:$D,"co2",historicalGHG!$B:$B,"modelled sectors")*$P$20 -> 43120.712 | O41: =SUMIFS(historicalGHG!I:I,historicalGHG!$C:$C,POLICY!$H41,historicalGHG!$D:$D,"co2",historicalGHG!$B:$B,"modelled sectors")*$P$20 -> 8404.5983 | P41: =SUMIFS(historicalGHG!J:J,historicalGHG!$C:$C,POLICY!$H41,historicalGHG!$D:$D,"co2",historicalGHG!$B:$B,"modelled sectors")*$P$20 -> 104135.44 | Q41: =SUMIFS(historicalGHG!K:K,historicalGHG!$C:$C,POLICY!$H41,historicalGHG!$D:$D,"co2",historicalGHG!$B:$B,"modelled sectors")*$P$20 -> 815964.18 | R41: =SUMIFS(historicalGHG!L:L,historicalGHG!$C:$C,POLICY!$H41,historicalGHG!$D:$D,"co2",historicalGHG!$B:$B,"modelled sectors")*$P$20 -> 40526.556 | S41: =SUMIFS(historicalGHG!M:M,historicalGHG!$C:$C,POLICY!$H41,historicalGHG!$D:$D,"co2",historicalGHG!$B:$B,"modelled sectors")*$P$20 -> 16703.374 | T41: =SUMIFS(historicalGHG!N:N,historicalGHG!$C:$C,POLICY!$H41,historicalGHG!$D:$D,"co2",historicalGHG!$B:$B,"modelled sectors")*$P$20 -> 82716.877 | U41: =SUMIFS(historicalGHG!O:O,historicalGHG!$C:$C,POLICY!$H41,historicalGHG!$D:$D,"co2",historicalGHG!$B:$B,"modelled sectors")*$P$20 -> 302288.77 | V41: =SUMIFS(historicalGHG!P:P,historicalGHG!$C:$C,POLICY!$H41,historicalGHG!$D:$D,"co2",historicalGHG!$B:$B,"modelled sectors")*$P$20 -> 46324.141 | W41: =SUMIFS(historicalGHG!Q:Q,historicalGHG!$C:$C,POLICY!$H41,historicalGHG!$D:$D,"co2",historicalGHG!$B:$B,"modelled sectors")*$P$20 -> 359907.33 | X41: =SUMIFS(historicalGHG!R:R,historicalGHG!$C:$C,POLICY!$H41,historicalGHG!$D:$D,"co2",historicalGHG!$B:$B,"modelled sectors")*$P$20 -> 17692.125 | Y41: =SUMIFS(historicalGHG!S:S,historicalGHG!$C:$C,POLICY!$H41,historicalGHG!$D:$D,"co2",historicalGHG!$B:$B,"modelled sectors")*$P$20 -> 46437.991 | Z41: =SUMIFS(historicalGHG!T:T,historicalGHG!$C:$C,POLICY!$H41,historicalGHG!$D:$D,"co2",historicalGHG!$B:$B,"modelled sectors")*$P$20 -> 40762.759 | AA41: =SUMIFS(historicalGHG!U:U,historicalGHG!$C:$C,POLICY!$H41,historicalGHG!$D:$D,"co2",historicalGHG!$B:$B,"modelled sectors")*$P$20 -> 4148.0686 | AB41: =SUMIFS(historicalGHG!V:V,historicalGHG!$C:$C,POLICY!$H41,historicalGHG!$D:$D,"co2",historicalGHG!$B:$B,"modelled sectors")*$P$20 -> 369602.18 | AC41: =SUMIFS(historicalGHG!W:W,historicalGHG!$C:$C,POLICY!$H41,historicalGHG!$D:$D,"co2",historicalGHG!$B:$B,"modelled sectors")*$P$20 -> 13134.143 | AD41: =SUMIFS(historicalGHG!X:X,historicalGHG!$C:$C,POLICY!$H41,historicalGHG!$D:$D,"co2",historicalGHG!$B:$B,"modelled sectors")*$P$20 -> 10602.806 | AE41: =SUMIFS(historicalGHG!Y:Y,historicalGHG!$C:$C,POLICY!$H41,historicalGHG!$D:$D,"co2",historicalGHG!$B:$B,"modelled sectors")*$P$20 -> 8292.184 | AF41: =SUMIFS(historicalGHG!Z:Z,historicalGHG!$C:$C,POLICY!$H41,historicalGHG!$D:$D,"co2",historicalGHG!$B:$B,"modelled sectors")*$P$20 -> 6895.6836 | AG41: =SUMIFS(historicalGHG!AA:AA,historicalGHG!$C:$C,POLICY!$H41,historicalGHG!$D:$D,"co2",historicalGHG!$B:$B,"modelled sectors")*$P$20 -> 212730.02 | AH41: =SUMIFS(historicalGHG!AB:AB,historicalGHG!$C:$C,POLICY!$H41,historicalGHG!$D:$D,"co2",historicalGHG!$B:$B,"modelled sectors")*$P$20 -> 44655.287 | AI41: =SUMIFS(historicalGHG!AC:AC,historicalGHG!$C:$C,POLICY!$H41,historicalGHG!$D:$D,"co2",historicalGHG!$B:$B,"modelled sectors")*$P$20 -> 306047 | AJ41: =SUMIFS(historicalGHG!AD:AD,historicalGHG!$C:$C,POLICY!$H41,historicalGHG!$D:$D,"co2",historicalGHG!$B:$B,"modelled sectors")*$P$20 -> 55578.46 | AK41: =SUMIFS(historicalGHG!AE:AE,historicalGHG!$C:$C,POLICY!$H41,historicalGHG!$D:$D,"co2",historicalGHG!$B:$B,"modelled sectors")*$P$20 -> 77223.745 | AL41: =SUMIFS(historicalGHG!AF:AF,historicalGHG!$C:$C,POLICY!$H41,historicalGHG!$D:$D,"co2",historicalGHG!$B:$B,"modelled sectors")*$P$20 -> 49760.634 | AM41: =SUMIFS(historicalGHG!AG:AG,historicalGHG!$C:$C,POLICY!$H41,historicalGHG!$D:$D,"co2",historicalGHG!$B:$B,"modelled sectors")*$P$20 -> 13620.074 | AN41: =SUMIFS(historicalGHG!AH:AH,historicalGHG!$C:$C,POLICY!$H41,historicalGHG!$D:$D,"co2",historicalGHG!$B:$B,"modelled sectors")*$P$20 -> 34193.642 | AQ41: =AR41-AO41-AH41-AA41-N41 -> 3277442.2 | AR41: =SUM(K41:AO41) -> 3369366.3
F42: TOTCO2 | H42: 2021 | K42: =SUMIFS(historicalGHG!E:E,historicalGHG!$C:$C,POLICY!$H42,historicalGHG!$D:$D,"co2",historicalGHG!$B:$B,"modelled sectors")*$P$20 -> 66401.628 | L42: =SUMIFS(historicalGHG!F:F,historicalGHG!$C:$C,POLICY!$H42,historicalGHG!$D:$D,"co2",historicalGHG!$B:$B,"modelled sectors")*$P$20 -> 123944.2 | M42: =SUMIFS(historicalGHG!G:G,historicalGHG!$C:$C,POLICY!$H42,historicalGHG!$D:$D,"co2",historicalGHG!$B:$B,"modelled sectors")*$P$20 -> 41986.07 | N42: =SUMIFS(historicalGHG!H:H,historicalGHG!$C:$C,POLICY!$H42,historicalGHG!$D:$D,"co2",historicalGHG!$B:$B,"modelled sectors")*$P$20 -> 37654.592 | O42: =SUMIFS(historicalGHG!I:I,historicalGHG!$C:$C,POLICY!$H42,historicalGHG!$D:$D,"co2",historicalGHG!$B:$B,"modelled sectors")*$P$20 -> 8300.5703 | P42: =SUMIFS(historicalGHG!J:J,historicalGHG!$C:$C,POLICY!$H42,historicalGHG!$D:$D,"co2",historicalGHG!$B:$B,"modelled sectors")*$P$20 -> 95600.328 | Q42: =SUMIFS(historicalGHG!K:K,historicalGHG!$C:$C,POLICY!$H42,historicalGHG!$D:$D,"co2",historicalGHG!$B:$B,"modelled sectors")*$P$20 -> 689312.75 | R42: =SUMIFS(historicalGHG!L:L,historicalGHG!$C:$C,POLICY!$H42,historicalGHG!$D:$D,"co2",historicalGHG!$B:$B,"modelled sectors")*$P$20 -> 33267.863 | S42: =SUMIFS(historicalGHG!M:M,historicalGHG!$C:$C,POLICY!$H42,historicalGHG!$D:$D,"co2",historicalGHG!$B:$B,"modelled sectors")*$P$20 -> 11346.332 | T42: =SUMIFS(historicalGHG!N:N,historicalGHG!$C:$C,POLICY!$H42,historicalGHG!$D:$D,"co2",historicalGHG!$B:$B,"modelled sectors")*$P$20 -> 65292.867 | U42: =SUMIFS(historicalGHG!O:O,historicalGHG!$C:$C,POLICY!$H42,historicalGHG!$D:$D,"co2",historicalGHG!$B:$B,"modelled sectors")*$P$20 -> 255543.03 | V42: =SUMIFS(historicalGHG!P:P,historicalGHG!$C:$C,POLICY!$H42,historicalGHG!$D:$D,"co2",historicalGHG!$B:$B,"modelled sectors")*$P$20 -> 38985.565 | W42: =SUMIFS(historicalGHG!Q:Q,historicalGHG!$C:$C,POLICY!$H42,historicalGHG!$D:$D,"co2",historicalGHG!$B:$B,"modelled sectors")*$P$20 -> 324386.89 | X42: =SUMIFS(historicalGHG!R:R,historicalGHG!$C:$C,POLICY!$H42,historicalGHG!$D:$D,"co2",historicalGHG!$B:$B,"modelled sectors")*$P$20 -> 17222.652 | Y42: =SUMIFS(historicalGHG!S:S,historicalGHG!$C:$C,POLICY!$H42,historicalGHG!$D:$D,"co2",historicalGHG!$B:$B,"modelled sectors")*$P$20 -> 48053.867 | Z42: =SUMIFS(historicalGHG!T:T,historicalGHG!$C:$C,POLICY!$H42,historicalGHG!$D:$D,"co2",historicalGHG!$B:$B,"modelled sectors")*$P$20 -> 38204.743 | AA42: =SUMIFS(historicalGHG!U:U,historicalGHG!$C:$C,POLICY!$H42,historicalGHG!$D:$D,"co2",historicalGHG!$B:$B,"modelled sectors")*$P$20 -> 3814.7189 | AB42: =SUMIFS(historicalGHG!V:V,historicalGHG!$C:$C,POLICY!$H42,historicalGHG!$D:$D,"co2",historicalGHG!$B:$B,"modelled sectors")*$P$20 -> 342007.06 | AC42: =SUMIFS(historicalGHG!W:W,historicalGHG!$C:$C,POLICY!$H42,historicalGHG!$D:$D,"co2",historicalGHG!$B:$B,"modelled sectors")*$P$20 -> 14130.324 | AD42: =SUMIFS(historicalGHG!X:X,historicalGHG!$C:$C,POLICY!$H42,historicalGHG!$D:$D,"co2",historicalGHG!$B:$B,"modelled sectors")*$P$20 -> 10180.19 | AE42: =SUMIFS(historicalGHG!Y:Y,historicalGHG!$C:$C,POLICY!$H42,historicalGHG!$D:$D,"co2",historicalGHG!$B:$B,"modelled sectors")*$P$20 -> 7987.6338 | AF42: =SUMIFS(historicalGHG!Z:Z,historicalGHG!$C:$C,POLICY!$H42,historicalGHG!$D:$D,"co2",historicalGHG!$B:$B,"modelled sectors")*$P$20 -> 8003.7369 | AG42: =SUMIFS(historicalGHG!AA:AA,historicalGHG!$C:$C,POLICY!$H42,historicalGHG!$D:$D,"co2",historicalGHG!$B:$B,"modelled sectors")*$P$20 -> 179854.77 | AH42: =SUMIFS(historicalGHG!AB:AB,historicalGHG!$C:$C,POLICY!$H42,historicalGHG!$D:$D,"co2",historicalGHG!$B:$B,"modelled sectors")*$P$20 -> 39788.731 | AI42: =SUMIFS(historicalGHG!AC:AC,historicalGHG!$C:$C,POLICY!$H42,historicalGHG!$D:$D,"co2",historicalGHG!$B:$B,"modelled sectors")*$P$20 -> 324679.74 | AJ42: =SUMIFS(historicalGHG!AD:AD,historicalGHG!$C:$C,POLICY!$H42,historicalGHG!$D:$D,"co2",historicalGHG!$B:$B,"modelled sectors")*$P$20 -> 42637.926 | AK42: =SUMIFS(historicalGHG!AE:AE,historicalGHG!$C:$C,POLICY!$H42,historicalGHG!$D:$D,"co2",historicalGHG!$B:$B,"modelled sectors")*$P$20 -> 75856.177 | AL42: =SUMIFS(historicalGHG!AF:AF,historicalGHG!$C:$C,POLICY!$H42,historicalGHG!$D:$D,"co2",historicalGHG!$B:$B,"modelled sectors")*$P$20 -> 46711.658 | AM42: =SUMIFS(historicalGHG!AG:AG,historicalGHG!$C:$C,POLICY!$H42,historicalGHG!$D:$D,"co2",historicalGHG!$B:$B,"modelled sectors")*$P$20 -> 13078.152 | AN42: =SUMIFS(historicalGHG!AH:AH,historicalGHG!$C:$C,POLICY!$H42,historicalGHG!$D:$D,"co2",historicalGHG!$B:$B,"modelled sectors")*$P$20 -> 34811.894 | AQ42: =AR42-AO42-AH42-AA42-N42 -> 2957788.6 | AR42: =SUM(K42:AO42) -> 3039046.7
F43: TOTCO2 | H43: 2025 | K43: =K42*0.8 -> 53121.302 | L43: =L42*0.8 -> 99155.362 | M43: =M42*0.8 -> 33588.856 | N43: =N42*0.8 -> 30123.673 | O43: =O42*0.8 -> 6640.4562 | P43: =P42*0.8 -> 76480.262 | Q43: =Q42*0.8 -> 551450.2 | R43: =R42*0.8 -> 26614.29 | ... AN43: =AN42*0.8 -> 27849.515 | AQ43: =AR43-AO43-AH43-AA43-N43 -> 2366230.9 | AR43: =SUM(K43:AO43) -> 2431237.3
F47: factor
F48: 1.5
B51: ~UC_SETS: R_S: AT,BE,BG,CY,CZ,DE,DK,EE,ES,FI,FR,EL,HU,IE,IT,LT,LU,LV,MT,NL,PL,PT,RO,SE,SI,SK,UK,CH,IS,NO,HR
D53: ~UC_T: UP
B54: UC_N | C54: Pset_PN | D54: Year | E54: UC_ACT | F54: UC_RHSTS
...

Sheet historicalGHG
A1: nfr_code | B1: nfr_category | C1: period | D1: emission | E1: AT | F1: BE | G1: BG | H1: CH | I1: CY | J1: CZ | K1: DE | L1: DK | M1: EE | N1: EL | O1: ES | P1: FI | Q1: FR | R1: HR | S1: HU | T1: IE | U1: IS | V1: IT | W1: LT | X1: LU | Y1: LV | Z1: MT | AA1: NL | AB1: NO | AC1: PL | AD1: PT | AE1: RO | AF1: SE | AG1: SI | AH1: SK | AI1: EU27
A2: 1A | B2: fuel combustion | C2: 1990 | D2: co2 | E2: 50828.113 | F2: 101525.75 | G2: 68148.241 | H2: 40881.486 | I2: 3921.7822 | J2: 146640.72 | K2: 988065.64 | L2: 52621.159 | M2: 35945.856 | N2: 74634.329 | O2: 206729.85 | P2: 52473.235 | Q2: 349231.39 | R2: 19780.379 | S2: 64296.063 | T2: 30148.208 | U2: 1745.8361 | V2: 404531.54 | W2: 32216.465 | X2: 10211.016 | Y2: 18645.258 | Z2: 2421.8837 | AA2: 155340.71 | AB2: 24626.885 | AC2: 350635.52 | AD2: 39397.712 | AE2: 149627.66 | AF2: 51023.294 | AG2: 13806.955 | AH2: 53155.873 | AI2: =SUM(E2:AH2)-H2-U2-AB2 -> 3526004.6
A3: 1A | B3: fuel combustion | C3: 2010 | D3: co2 | E3: 57787.332 | F3: 97550.097 | G3: 43979.368 | H3: 42559.036 | I3: 7506.8736 | J3: 105193.42 | K3: 780112.3 | L3: 49172.694 | M3: 18608.726 | N3: 90712.544 | O3: 258268.12 | P3: 59128.708 | Q3: 350511.66 | R3: 18265.121 | S3: 46783.421 | T3: 39778.738 | U3: 1804.1295 | V3: 411945.07 | W3: 12250.867 | X3: 10596.178 | Y3: 8024.5109 | Z3: 2598.6545 | AA3: 174947.99 | AB3: 35310.403 | AC3: 313363.43 | AD3: 47296.121 | AE3: 73092.001 | AF3: 45667.242 | AG3: 15554.374 | AH3: 30509.533 | AI3: =SUM(E3:AH3)-H3-U3-AB3 -> 3169205.1
A4: 1A | B4: fuel combustion | C4: 2015 | D4: co2 | E4: 51664.964 | F4: 85147.165 | G4: 43143.324 | H4: 36545.685 | I4: 6080.5866 | J4: 92898.917 | K4: 749200.93 | L4: 34752.433 | M4: 15527.255 | N4: 69213.622 | O4: 246084.58 | P4: 39753.692 | Q4: 309676.52 | R4: 15549.112 | S4: 41563.27 | T4: 36239.747 | U4: 1660.5384 | V4: 343765.85 | W4: 10391.904 | X4: 8795.5472 | Y4: 6714.0314 | Z4: 1655.0954 | AA4: 156921.37 | AB4: 34888.564 | AC4: 288748.81 | AD4: 46298.503 | AE4: 66759.416 | AF4: 36469.478 | AG4: 12746.382 | AH4: 26257.568 | AI4: =SUM(E4:AH4)-H4-U4-AB4 -> 2842020.1
A5: 1A | B5: fuel combustion | C5: 2019 | D5: co2 | E5: 53627.429 | F5: 83664.775 | G5: 37640.151 | H5: 34531.858 | I5: 6522.7422 | J5: 89264.379 | K5: 657793.17 | L5: 30776.125 | M5: 11919.179 | N5: 59774.338 | O5: 228049.32 | P5: 38058.494 | Q5: 294549.22 | R5: 15477.34 | S5: 43737.526 | T5: 34629.525 | U5: 1664.1864 | V5: 322119.66 | W5: 11003.841 | X5: 9155.6731 | Y5: 6975.6974 | Z5: 1643.4841 | AA5: 145253.14 | AB5: 32929.448 | AC5: 292920.12 | AD5: 42301.625 | AE5: 65255.942 | AF5: 33593.992 | AG5: 13029.577 | AH5: 25893.12 | AI5: =SUM(E5:AH5)-H5-U5-AB5 -> 2654629.6
A6: 1A | B6: fuel combustion | C6: 2021 | D6: co2 | E6: 50848.506 | F6: 80264.081 | G6: 37959.214 | H6: 33597.885 | I6: 6127.0402 | J6: 84267.386 | K6: 629640.24 | L6: 29354.22 | M6: 10290.397 | N6: 52444.935 | O6: 208494.56 | P6: 33445.253 | Q6: 285210.68 | R6: 15189.976 | S6: 43281.631 | T6: 34376.405 | U6: 1566.7397 | V6: 319646.2 | W6: 11405.976 | X6: 7908.5843 | Y6: 6554.1637 | Z6: 1601.5397 | AA6: 133190.11 | AB6: 30912.04 | AC6: 306225.28 | AD6: 35093.921 | AE6: 65533.107 | AF6: 32381.455 | AG6: 12114.095 | AH6: 26399.18 | AI6: =SUM(E6:AH6)-H6-U6-AB6 -> 2559248.1
A7: 1A | B7: fuel combustion | C7: 1990 | D7: ghg | E7: 51890.981 | F7: 102530.24 | G7: 69030.069 | H7: 41496.126 | I7: 3953.8928 | J7: 149368.96 | K7: 1001632.6 | L7: 53209.667 | M7: 36112.779 | N7: 75784.168 | O7: 209424.49 | P7: 53295.41 | Q7: 358769.94 | R7: 20460.033 | S7: 65638.554 | T7: 30949.05 | U7: 1778.4129 | V7: 411345.15 | W7: 32824.453 | X7: 10274.335 | Y7: 19253.477 | Z7: 2434.9404 | AA7: 156663.1 | AB7: 25396.248 | AC7: 355986.4 | AD7: 40473.54 | AE7: 150851.38 | AF7: 51845.543 | AG7: 14144.161 | AH7: 53892.714 | AI7: =SUM(E7:AH7)-H7-U7-AB7 -> 3582040
A8: 1A | B8: fuel combustion | C8: 2010 | D8: ghg | E8: 58778.984 | F8: 98778.607 | G8: 44622.565 | H8: 42922.557 | I8: 7546.6956 | J8: 106782.4 | K8: 788482.34 | L8: 50124.174 | M8: 18706.733 | N8: 91766.269 | O8: 262572.34 | P8: 60053.073 | Q8: 357824.18 | R8: 18934.97 | S8: 47781.559 | T8: 40357.971 | U8: 1831.3783 | V8: 420227.42 | W8: 12606.754 | X8: 10671.931 | Y8: 8429.7857 | Z8: 2611.8486 | AA8: 177841.92 | AB8: 36173.365 | AC8: 320243.46 | AD8: 48200.737 | AE8: 75043.522 | AF8: 46447.586 | AG8: 15890.614 | AH8: 31043.228 | AI8: =SUM(E8:AH8)-H8-U8-AB8 -> 3222371.7
A9: 1A | B9: fuel combustion | C9: 2015 | D9: ghg | E9: 52607.622 | F9: 86375.823 | G9: 43788.703 | H9: 36857.729 | I9: 6117.2276 | J9: 94541.405 | K9: 758237.91 | L9: 35378.792 | M9: 15612.772 | N9: 70067.951 | O9: 249986.12 | P9: 40527.823 | Q9: 315696.96 | R9: 16174.25 | S9: 42618.652 | T9: 36756.77 | U9: 1685.5145 | V9: 351289.04 | W9: 10739.089 | X9: 8882.1421 | Y9: 7080.7775 | Z9: 1664.2388 | AA9: 159290.51 | AB9: 35653.051 | AC9: 294804.48 | AD9: 47146.347 | AE9: 68505.788 | AF9: 37191.495 | AG9: 13061.762 | AH9: 26781.561 | AI9: =SUM(E9:AH9)-H9-U9-AB9 -> 2890926
A10: 1A | B10: fuel combustion | C10: 2019 | D10: ghg | E10: 54563.032 | F10: 84823.583 | G10: 38330.406 | H10: 34852.126 | I10: 6566.7142 | J10: 90941.209 | K10: 666601.28 | L10: 31415.615 | M10: 12013.452 | N10: 60509.423 | O10: 231955.3 | P10: 38876.399 | Q10: 300080.21 | R10: 16062.535 | S10: 44619.045 | T10: 35156.314 | U10: 1686.6453 | V10: 329426.75 | W10: 11364.692 | X10: 9257.4555 | Y10: 7366.6182 | Z10: 1652.1546 | AA10: 147778.68 | AB10: 33626.256 | AC10: 299844.68 | AD10: 43158.273 | AE10: 67078.83 | AF10: 34338.694 | AG10: 13309.568 | AH10: 26375.03 | AI10: =SUM(E10:AH10)-H10-U10-AB10 -> 2703465.9
A11: 1A | B11: fuel combustion | C11: 2021 | D11: ghg | E11: 51810.61 | F11: 81445.975 | G11: 38694.011 | H11: 33919.004 | I11: 6172.3985 | J11: 86046.758 | K11: 638525.34 | L11: 29976.921 | M11: 10394.977 | N11: 53133.85 | O11: 212321.76 | P11: 34236.337 | Q11: 290584.73 | R11: 15823.351 | S11: 44173.464 | T11: 34868.515 | U11: 1586.6349 | V11: 327124.18 | W11: 11785.999 | X11: 8005.2813 | Y11: 6928.4574 | Z11: 1609.1424 | AA11: 135856.38 | AB11: 31629.112 | AC11: 313101.04 | AD11: 35935.851 | AE11: 67470.168 | AF11: 33123.859 | AG11: 12394.407 | AH11: 26928.369 | AI11: =SUM(E11:AH11)-H11-U11-AB11 -> 2608472.1
A12: 1A | B12: fuel combustion | C12: 1990 | D12: nonco2 | E12: 1062.868 | F12: 1004.4862 | G12: 881.82821 | H12: 614.63973 | I12: 32.110514 | J12: 2728.244 | K12: 13566.979 | L12: 588.50785 | M12: 166.92347 | N12: 1149.8386 | O12: 2694.6423 | P12: 822.17577 | Q12: 9538.5515 | R12: 679.65333 | S12: 1342.4906 | T12: 800.84208 | U12: 32.576775 | V12: 6813.6082 | W12: 607.98782 | X12: 63.318651 | Y12: 608.21872 | Z12: 13.056721 | AA12: 1322.3932 | AB12: 769.36293 | AC12: 5350.885 | AD12: 1075.8271 | AE12: 1223.7182 | AF12: 822.24884 | AG12: 337.20542 | AH12: 736.84051 | AI12: =SUM(E12:AH12)-H12-U12-AB12 -> 56035.45
A13: 1A | B13: fuel combustion | C13: 2010 | D13: nonco2 | E13: 991.65259 | F13: 1228.51 | G13: 643.19751 | H13: 363.52103 | I13: 39.822056 | J13: 1588.9734 | K13: 8370.0376 | L13: 951.48016 | M13: 98.006976 | N13: 1053.7246 | O13: 4304.2236 | P13: 924.36486 | Q13: 7312.5167 | R13: 669.84911 | S13: 998.13834 | T13: 579.23336 | U13: 27.248728 | V13: 8282.3485 | W13: 355.88736 | X13: 75.752927 | Y13: 405.2748 | Z13: 13.194112 | AA13: 2893.9365 | AB13: 862.96249 | AC13: 6880.0276 | AD13: 904.61597 | AE13: 1951.5205 | AF13: 780.34342 | AG13: 336.24031 | AH13: 533.69559 | AI13: =SUM(E13:AH13)-H13-U13-AB13 -> 53166.569
... A286: total (1B,1C,2F,2H,3,4,5) | B286: nonmodelled sectors | C286: 2021 | D286: nonco2 | E286: 10149.602 | F286: 13156.779 | G286: 11250.802 | H286: 8481.8899 | I286: 1582.3968 | J286: 19414.959 | K286: 76123.867 | L286: 13879.884 | M286: 2432.6216 | N286: 19201.111 | O286: 53941.674 | P286: 11427.463 | Q286: 94523.84 | R286: 6461.0429 | S286: 14402.762 | T286: 24993.09 | U286: 4790.2516 | V286: 73077.8 | W286: 6034.3374 | X286: 854.47229 | Y286: 4533.2059 | Z286: 517.60489 | AA286: 23075.425 | AB286: 7475.0826 | AC286: 62506.811 | AD286: 16317.828 | AE286: 36199.328 | AF286: 9966.3731 | AG286: 2748.0944 | AH286: 5443.0164 | AI286: =SUM(E286:AH286)-H286-U286-AB286 -> 614216.19
C289: modelled sectors | D289: nonco2 | E289: ghg
C290: 1990 | D290: =SUM(E267:AH267) -> 202261.75 | E290: =SUM(E262:AH262) -> 4277701.9 | F290: =D290/E290 -> 0.047282806 | H290: =(H277+H267)/H247 -> 0.17209276 | U290: =(U277+U267)/U247 -> 0.83811424 | AB290: =(AB277+AB267)/AB247 -> 0.22580682
C291: 2010 | D291: =SUM(E268:AH268) -> 88334.854 | E291: =SUM(E263:AH263) -> 3850668.5 | F291: =D291/E291 -> 0.022940135 | H291: =(H278+H268)/H248 -> 0.14459158 | U291: =(U278+U268)/U248 -> 0.7638623 | AB291: =(AB278+AB268)/AB248 -> -0.364776
C292: 2015 | D292: =SUM(E269:AH269) -> 74673.777 | E292: =SUM(E264:AH264) -> 3478074 | F292: =D292/E292 -> 0.021469864 | H292: =(H279+H269)/H249 -> 0.17773371 | U292: =(U279+U269)/U249 -> 0.76455986 | AB292: =(AB279+AB269)/AB249 -> -0.03208356
C293: 2019 | D293: =SUM(E270:AH270) -> 73534.328 | E293: =SUM(E265:AH265) -> 3319831.3 | F293: =D293/E293 -> 0.02215002 | H293: =(H280+H270)/H250 -> 0.18138284 | U293: =(U280+U270)/U250 -> 0.76178996 | AB293: =(AB280+AB270)/AB250 -> -0.13306845
C294: 2021 | D294: =SUM(E271:AH271) -> 69441.186 | E294: =SUM(E266:AH266) -> 3139185.3 | F294: =D294/E294 -> 0.022120767 | H294: =(H281+H271)/H251 -> 0.1749016 | U294: =(U281+U271)/U251 -> 0.76428653 | AB294: =(AB281+AB271)/AB251 -> -0.1559069

Sheet scenassumptions
E1: Do the same for swiss, uk and is. They have now no country targets.. | N1: bunkers | Q1: bunkers | W1: ok | Y1: ok
I2: =R4 -> v0 no non-modelled in scope | K2: Modelled | U2: Nonmodelled GHGs
D3: Scope of EU Climate Law | I3: co2 | J3: co2 | K3: co2 | L3: co2 | O3: co2 | R3: ghg | S3: ghg | T3: ghg | U3: ghg | V3: nonco2 | W3: ghg | X3: ghg | Y3: ghg | Z3: ghg | AA3: ghg | AB3: ghg | AC3: ghg | AE3: ghg
A4: Target | B4: EU27 | C4: Total GHG emissions (UNFCCC) (ktCO2eq) | D4: Total net GHG emissions (UNFCCC) (kt CO2eq) | E4: Total CO2 emissions (UNFCCC) (kt CO2) | F4: Total net CO2 emissions (UNFCCC) (kt CO2) | I4: target for the model | J4: national total net GHG | K4: modelled sectors | L4: international aviation | M4: domestic + intra-EU aviation | N4: extra-EU-aviation | O4: international navigation | P4: intra-EU-maritime | Q4: extra-eu-maritime | R4: v0 no non-modelled in scope | S4: v1 all but LULUCF non-modelled | T4: v2 only fossil non-modelled | U4: v3 all non-modelled | V4: modelled sectors | W4: agriculture | X4: LULUCF | Y4: waste | Z4: fugitive emissions | AA4: CO2 transport, storage | AB4: f-gases | AC4: other | AE4: LULUCF (old version) | AG4: sum check | AI4: modelled sectors | AJ4: nonco2 | AK4: ghg | AL4: share of non-co2 from modelled sectors
B5: 1990 | C5: 4867242 | D5: 4649770 | E5: =3880978 -> 3880978 | F5: 3300908 | H5: 1990 | I5: =K5 -> 3991194.6 | J5: =SUMIFS(historicalGHG!$AI:$AI,historicalGHG!$B:$B,J$4,historicalGHG!$C:$C,$H5,historicalGHG!$D:$D,J$3) -> 3643060 | K5: =SUMIFS(historicalGHG!$AI:$AI,historicalGHG!$B:$B,K$4,historicalGHG!$C:$C,$H5,historicalGHG!$D:$D,K$3) -> 3991194.6 | L5: =SUMIFS(historicalGHG!$AI:$AI,historicalGHG!$B:$B,L$4,historicalGHG!$C:$C,$H5,historicalGHG!$D:$D,L$3) -> 53966.823 | O5: =SUMIFS(historicalGHG!$AI:$AI,historicalGHG!$B:$B,O$4,historicalGHG!$C:$C,$H5,historicalGHG!$D:$D,O$3) -> 101077.41 | R5: 0 | S5: =SUM(V5,W5,Y5,Z5,AA5,AB5,AC5) -> 1030542.3 | T5: =SUM(V5,Z5,AA5,AB5,AC5) -> 361090.62 | U5: =SUM(V5:AC5) -> 821979.96 | V5: =SUMIFS(historicalGHG!$AI:$AI,historicalGHG!$B:$B,V$4,historicalGHG!$C:$C,$H5,historicalGHG!$D:$D,V$3) -> 191900.87 | W5: =SUMIFS(historicalGHG!$AI:$AI,historicalGHG!$B:$B,W$4,historicalGHG!$C:$C,$H5,historicalGHG!$D:$D,W$3) -> 485094.01 | X5: =SUMIFS(historicalGHG!$AI:$AI,historicalGHG!$B:$B,X$4,historicalGHG!$C:$C,$H5,historicalGHG!$D:$D,X$3) -> -208562.3 | Y5: =SUMIFS(historicalGHG!$AI:$AI,historicalGHG!$B:$B,Y$4,historicalGHG!$C:$C,$H5,historicalGHG!$D:$D,Y$3) -> 184357.63 | Z5: =SUMIFS(historicalGHG!$AI:$AI,historicalGHG!$B:$B,Z$4,historicalGHG!$C:$C,$H5,historicalGHG!$D:$D,Z$3) -> 168709.33 | AA5: =SUMIFS(historicalGHG!$AI:$AI,historicalGHG!$B:$B,AA$4,historicalGHG!$C:$C,$H5,historicalGHG!$D:$D,AA$3) -> 0 | AB5: =SUMIFS(historicalGHG!$AI:$AI,historicalGHG!$B:$B,AB$4,historicalGHG!$C:$C,$H5,historicalGHG!$D:$D,AB$3) -> 6.1275051 | AC5: =SUMIFS(historicalGHG!$AI:$AI,historicalGHG!$B:$B,AC$4,historicalGHG!$C:$C,$H5,historicalGHG!$D:$D,AC$3) -> 474.29138 | AG5: =J5-SUM(V5:AC5)-(K5-L5-O5) -> -1015070.3 | AI5: 1990 | AJ5: 202261.75 | AK5: 4277701.9 | AL5: 0.047282806
B6: 2010 | C6: 4171763 | D6: 3820496 | E6: 3437724 | F6: 3061101 | H6: 2010 | I6: =K6 -> 3663881.1 | J6: =SUMIFS(historicalGHG!$AI:$AI,historicalGHG!$B:$B,J$4,historicalGHG!$C:$C,$H6,historicalGHG!$D:$D,J$3) -> 3071371.1 | K6: =SUMIFS(historicalGHG!$AI:$AI,historicalGHG!$B:$B,K$4,historicalGHG!$C:$C,$H6,historicalGHG!$D:$D,K$3) -> 3663881.1 | L6: =SUMIFS(historicalGHG!$AI:$AI,historicalGHG!$B:$B,L$4,historicalGHG!$C:$C,$H6,historicalGHG!$D:$D,L$3) -> 99855.942 | O6: =SUMIFS(historicalGHG!$AI:$AI,historicalGHG!$B:$B,O$4,historicalGHG!$C:$C,$H6,historicalGHG!$D:$D,O$3) -> 150340.14 | R6: 0 | S6: =SUM(V6,W6,Y6,Z6,AA6,AB6,AC6) -> 772394.55 | T6: =SUM(V6,Z6,AA6,AB6,AC6) -> 258431.5 | U6: =SUM(V6:AC6) -> 419615.04 | V6: =SUMIFS(historicalGHG!$AI:$AI,historicalGHG!$B:$B,V$4,historicalGHG!$C:$C,$H6,historicalGHG!$D:$D,V$3) -> 85232.211 | W6: =SUMIFS(historicalGHG!$AI:$AI,historicalGHG!$B:$B,W$4,historicalGHG!$C:$C,$H6,historicalGHG!$D:$D,W$3) -> 376631.95 | X6: =SUMIFS(historicalGHG!$AI:$AI,historicalGHG!$B:$B,X$4,historicalGHG!$C:$C,$H6,historicalGHG!$D:$D,X$3) -> -352779.51 | Y6: =SUMIFS(historicalGHG!$AI:$AI,historicalGHG!$B:$B,Y$4,historicalGHG!$C:$C,$H6,historicalGHG!$D:$D,Y$3) -> 137331.11 | Z6: =SUMIFS(historicalGHG!$AI:$AI,historicalGHG!$B:$B,Z$4,historicalGHG!$C:$C,$H6,historicalGHG!$D:$D,Z$3) -> 88942.118 | AA6: =SUMIFS(historicalGHG!$AI:$AI,historicalGHG!$B:$B,AA$4,historicalGHG!$C:$C,$H6,historicalGHG!$D:$D,AA$3) -> 0 | AB6: =SUMIFS(historicalGHG!$AI:$AI,historicalGHG!$B:$B,AB$4,historicalGHG!$C:$C,$H6,historicalGHG!$D:$D,AB$3) -> 83749.866 | AC6: =SUMIFS(historicalGHG!$AI:$AI,historicalGHG!$B:$B,AC$4,historicalGHG!$C:$C,$H6,historicalGHG!$D:$D,AC$3) -> 507.30221 | AG6: =J6-SUM(V6:AC6)-(K6-L6-O6) -> -761929 | AI6: 2010 | AJ6: 88334.854 | AK6: 3850668.5 | AL6: 0.022940135
B7: 2015 | C7: 3810555 | D7: 3486016 | E7: 3107670 | F7: 2758750 | H7: 2015 | I7: =K7 -> 3310547.7 | J7: =SUMIFS(historicalGHG!$AI:$AI,historicalGHG!$B:$B,J$4,historicalGHG!$C:$C,$H7,historicalGHG!$D:$D,J$3) -> 2764652.1 | K7: =SUMIFS(historicalGHG!$AI:$AI,historicalGHG!$B:$B,K$4,historicalGHG!$C:$C,$H7,historicalGHG!$D:$D,K$3) -> 3310547.7 | L7: =SUMIFS(historicalGHG!$AI:$AI,historicalGHG!$B:$B,L$4,historicalGHG!$C:$C,$H7,historicalGHG!$D:$D,L$3) -> 107954.93 | O7: =SUMIFS(historicalGHG!$AI:$AI,historicalGHG!$B:$B,O$4,historicalGHG!$C:$C,$H7,historicalGHG!$D:$D,O$3) -> 127985.67 | R7: 0 | S7: =SUM(V7,W7,Y7,Z7,AA7,AB7,AC7) -> 744728.84 | T7: =SUM(V7,Z7,AA7,AB7,AC7) -> 241593.58 | U7: =SUM(V7:AC7) -> 422643.26 | V7: =SUMIFS(historicalGHG!$AI:$AI,historicalGHG!$B:$B,V$4,historicalGHG!$C:$C,$H7,historicalGHG!$D:$D,V$3) -> 71903.015 | W7: =SUMIFS(historicalGHG!$AI:$AI,historicalGHG!$B:$B,W$4,historicalGHG!$C:$C,$H7,historicalGHG!$D:$D,W$3) -> 384630.67 | X7: =SUMIFS(historicalGHG!$AI:$AI,historicalGHG!$B:$B,X$4,historicalGHG!$C:$C,$H7,historicalGHG!$D:$D,X$3) -> -322085.57 | Y7: =SUMIFS(historicalGHG!$AI:$AI,historicalGHG!$B:$B,Y$4,historicalGHG!$C:$C,$H7,historicalGHG!$D:$D,Y$3) -> 118504.59 | Z7: =SUMIFS(historicalGHG!$AI:$AI,historicalGHG!$B:$B,Z$4,historicalGHG!$C:$C,$H7,historicalGHG!$D:$D,Z$3) -> 82722.176 | AA7: =SUMIFS(historicalGHG!$AI:$AI,historicalGHG!$B:$B,AA$4,historicalGHG!$C:$C,$H7,historicalGHG!$D:$D,AA$3) -> 0 | AB7: =SUMIFS(historicalGHG!$AI:$AI,historicalGHG!$B:$B,AB$4,historicalGHG!$C:$C,$H7,historicalGHG!$D:$D,AB$3) -> 86590.345 | AC7: =SUMIFS(historicalGHG!$AI:$AI,historicalGHG!$B:$B,AC$4,historicalGHG!$C:$C,$H7,historicalGHG!$D:$D,AC$3) -> 378.04745 | AG7: =J7-SUM(V7:AC7)-(K7-L7-O7) -> -732598.2 | AI7: 2015 | AJ7: 74673.777 | AK7: 3478074 | AL7: 0.021469864
B8: 2019 | C8: 3584404 | D8: 3343420 | E8: 2917621 | F8: 2651404 | H8: 2019 | I8: =K8 -> 3156134.2 | J8: =SUMIFS(historicalGHG!$AI:$AI,historicalGHG!$B:$B,J$4,historicalGHG!$C:$C,$H8,historicalGHG!$D:$D,J$3) -> 2654313.6 | K8: =SUMIFS(historicalGHG!$AI:$AI,historicalGHG!$B:$B,K$4,historicalGHG!$C:$C,$H8,historicalGHG!$D:$D,K$3) -> 3156134.2 | L8: =SUMIFS(historicalGHG!$AI:$AI,historicalGHG!$B:$B,L$4,historicalGHG!$C:$C,$H8,historicalGHG!$D:$D,L$3) -> 132240.64 | O8: =SUMIFS(historicalGHG!$AI:$AI,historicalGHG!$B:$B,O$4,historicalGHG!$C:$C,$H8,historicalGHG!$D:$D,O$3) -> 135327.32 | R8: 0 | S8: =SUM(V8,W8,Y8,Z8,AA8,AB8,AC8) -> 711414.5 | T8: =SUM(V8,Z8,AA8,AB8,AC8) -> 217999.46 | U8: =SUM(V8:AC8) -> 466331.44 | V8: =SUMIFS(historicalGHG!$AI:$AI,historicalGHG!$B:$B,V$4,historicalGHG!$C:$C,$H8,historicalGHG!$D:$D,V$3) -> 70899.778 | W8: =SUMIFS(historicalGHG!$AI:$AI,historicalGHG!$B:$B,W$4,historicalGHG!$C:$C,$H8,historicalGHG!$D:$D,W$3) -> 380591.69 | X8: =SUMIFS(historicalGHG!$AI:$AI,historicalGHG!$B:$B,X$4,historicalGHG!$C:$C,$H8,historicalGHG!$D:$D,X$3) -> -245083.06 | Y8: =SUMIFS(historicalGHG!$AI:$AI,historicalGHG!$B:$B,Y$4,historicalGHG!$C:$C,$H8,historicalGHG!$D:$D,Y$3) -> 112823.35 | Z8: =SUMIFS(historicalGHG!$AI:$AI,historicalGHG!$B:$B,Z$4,historicalGHG!$C:$C,$H8,historicalGHG!$D:$D,Z$3) -> 68470.869 | AA8: =SUMIFS(historicalGHG!$AI:$AI,historicalGHG!$B:$B,AA$4,historicalGHG!$C:$C,$H8,historicalGHG!$D:$D,AA$3) -> 0 | AB8: =SUMIFS(historicalGHG!$AI:$AI,historicalGHG!$B:$B,AB$4,historicalGHG!$C:$C,$H8,historicalGHG!$D:$D,AB$3) -> 78255.127 | AC8: =SUMIFS(historicalGHG!$AI:$AI,historicalGHG!$B:$B,AC$4,historicalGHG!$C:$C,$H8,historicalGHG!$D:$D,AC$3) -> 373.68444 | AG8: =J8-SUM(V8:AC8)-(K8-L8-O8) -> -700584.11 | AI8: 2019 | AJ8: 73534.328 | AK8: 3319831.3 | AL8: 0.02215002
B9: 2025 | C9: 3374743 | D9: 3138341 | E9: 2748554 | F9: 2485814 | H9: 2025 | K9: this part will be modelled | L9: =M9+N9 -> 74058.417 | M9: 74058.417 | O9: =P9+Q9 -> 34043.317 | P9: 34043.317 | R9: 0 | S9: =SUM(V9,W9,Y9,Z9,AA9,AB9,AC9) -> 641966.24 | T9: =SUM(V9,Z9,AA9,AB9,AC9) -> 170669.78 | U9: =SUM(V9:AC9) -> 364424.71 | V9: =V8-($V$8/($H$14-$H$8))*6 -> 57177.24 | W9: =W8+(W$12-W$8)/($H$12-$H$8)*($H9-$H8) -> 372136.92 | X9: =AVERAGE(X8,X10) -> -277541.53 | Y9: =Y8+(Y$12-Y$8)/($H$12-$H$8)*($H9-$H8) -> 99159.537 | Z9: =Z8-($V$8/($H$14-$H$8))*6 -> 54748.331 | AA9: =AA8 -> 0 | AB9: =AB8+(AB$12-AB$8)/($H$12-$H$8)*($H9-$H8) -> 58370.529 | AC9: =AC8 -> 373.68444 | AI9: 2021 | AJ9: 69441.186 | AK9: 3139185.3 | AL9: 0.022120767
A10: -0.55 | B10: 2030 | C10: =C$6*$A10+C$6 -> 1877293.3 | D10: =D$6*$A10+D$6 -> 1719223.2 | E10: =E$6*$A10+E$6 -> 1546975.8 | F10: =F$6*$A10+F$6 -> 1377495.4 | H10: 2030 | I10: =J10-R10+N10+(Q10*0.5) -> 1546975.8 | J10: =E10 -> 1546975.8 | L10: =M10+N10 -> 74500.311 | M10: 74500.311 | O10: =P10+Q10 -> 8728.9052 | P10: 8728.9052 | R10: 0 | S10: =SUM(V10,W10,Y10,Z10,AA10,AB10,AC10) -> 584092.7 | T10: =SUM(V10,Z10,AA10,AB10,AC10) -> 131228.39 | U10: =SUM(V10:AC10) -> 274092.7 | V10: =V9-($V$8/($H$14-$H$8))*5 -> 45741.792 | W10: =W9+(W$12-W$8)/($H$12-$H$8)*($H10-$H9) -> 365091.28 | X10: =L26*1000 -> -310000 | Y10: =Y9+(Y$12-Y$8)/($H$12-$H$8)*($H10-$H9) -> 87773.025 | Z10: =Z9-($V$8/($H$14-$H$8))*5 -> 43312.883 | AA10: =AA9 -> 0 | AB10: =AB9+(AB$12-AB$8)/($H$12-$H$8)*($H10-$H9) -> 41800.031 | AC10: =AC9 -> 373.68444 | AL10: assume this approaches zero as the use of fossil fuels decreases
A11: =AVERAGE(A10,A12) -> -0.725 | B11: 2035 | C11: =C$6*$A11+C$6 -> 1147234.8 | D11: =D$6*$A11+D$6 -> 1050636.4 | E11: =E$6*$A11+E$6 -> 945374.1 | F11: =F$6*$A11+F$6 -> 841802.77 | H11: 2035 | I11: =J11-R11+N11+(Q11*0.5) -> 945374.1 | J11: =E11 -> 945374.1 | L11: =M11+N11 -> 88866.563 | M11: 88866.563 | O11: =P11+Q11 -> 12721.546 | P11: 12721.546 | R11: 0 | S11: =SUM(V11,W11,Y11,Z11,AA11,AB11,AC11) -> 526219.15 | T11: =SUM(V11,Z11,AA11,AB11,AC11) -> 91786.996 | U11: =SUM(V11:AC11) -> 216219.15 | V11: =V10-($V$8/($H$14-$H$8))*5 -> 34306.344 | W11: =W10+(W$12-W$8)/($H$12-$H$8)*($H11-$H10) -> 358045.64 | X11: =AVERAGE(X10,X12) -> -310000 | Y11: =Y10+(Y$12-Y$8)/($H$12-$H$8)*($H11-$H10) -> 76386.512 | Z11: =Z10-($V$8/($H$14-$H$8))*5 -> 31877.435 | AA11: =AA10 -> 0 | AB11: =AB10+(AB$12-AB$8)/($H$12-$H$8)*($H11-$H10) -> 25229.533 | AC11: =AC10 -> 373.68444 | AL11: creates a margin of error of 0-2 % to the TOTCO2 estimations
A12: -0.9 | B12: 2040 | C12: =C$6*$A12+C$6 -> 417176.3 | D12: =D$6*$A12+D$6 -> 382049.6 | E12: =E$6*$A12+E$6 -> 343772.4 | F12: =F$6*$A12+F$6 -> 306110.1 | H12: 2040 | I12: =J12-R12+N12+(Q12*0.5) -> 343772.4 | J12: =E12 -> 343772.4 | L12: =M12+N12 -> 97530.32 | M12: 97530.32 | O12: =P12+Q12 -> 11196.172 | P12: 11196.172 | R12: 0 | S12: =SUM(V12,W12,Y12,Z12,AA12,AB12,AC12) -> 468345.6 | T12: =SUM(V12,Z12,AA12,AB12,AC12) -> 52345.602 | U12: =SUM(V12:AC12) -> 158345.6 | V12: =V11-($V$8/($H$14-$H$8))*5 -> 22870.896 | W12: =351*1000 -> 351000 | X12: =X10 -> -310000 | Y12: =65*1000 -> 65000 | Z12: =Z11-($V$8/($H$14-$H$8))*5 -> 20441.987 | AA12: =AA11 -> 0 | AB12: =AB7+AB7*-0.9 -> 8659.0345 | AC12: =AC11 -> 373.68444
A13: =AVERAGE(A12,A14) -> -0.95 | B13: 2045 | C13: =C$6*$A13+C$6 -> 208588.15 | D13: =D$6*$A13+D$6 -> 191024.8 | E13: =E$6*$A13+E$6 -> 171886.2 | F13: =F$6*$A13+F$6 -> 153055.05 | H13: 2045 | I13: =J13-R13+N13+(Q13*0.5) -> 171886.2 | J13: =E13 -> 171886.2 | L13: =M13+N13 -> 102786.49 | M13: 102786.49 | O13: =P13+Q13 -> 12405.175 | P13: 12405.175 | R13: 0 | S13: =SUM(V13,W13,Y13,Z13,AA13,AB13,AC13) -> 371645.19 | T13: =SUM(V13,Z13,AA13,AB13,AC13) -> 25145.188 | U13: =SUM(V13:AC13) -> 61645.188 | V13: =V12-($V$8/($H$14-$H$8))*5 -> 11435.448 | W13: =AVERAGE(W12,W14) -> 300000 | X13: =AVERAGE(X12,X14) -> -310000 | Y13: =AVERAGE(Y12,Y14) -> 46500 | Z13: =Z12-($V$8/($H$14-$H$8))*5 -> 9006.5387 | AA13: =AA12 -> 0 | AB13: =AVERAGE(AB12,AB14) -> 4329.5173 | AC13: =AC12 -> 373.68444
A14: -1 | B14: 2050 | C14: =C$6*$A14+C$6 -> 0 | D14: =D$6*$A14+D$6 -> 0 | E14: =E$6*$A14+E$6 -> 0 | F14: =F$6*$A14+F$6 -> 0 | H14: 2050 | I14: =J14-R14+N14+(Q14*0.5) -> 0 | J14: =E14 -> 0 | L14: =M14+N14 -> 108770.86 | M14: 108770.86 | O14: =P14+Q14 -> 13904.414 | P14: 13904.414 | R14: 0 | S14: =SUM(V14,W14,Y14,Z14,AA14,AB14,AC14) -> 277373.68 | T14: =SUM(V14,Z14,AA14,AB14,AC14) -> 373.68444 | U14: =SUM(V14:AC14) -> -32626.316 | V14: 0 | W14: =249*1000 -> 249000 | X14: =X12 -> -310000 | Y14: =28*1000 -> 28000 | Z14: 0 | AA14: =AA13 -> 0 | AB14: 0 | AC14: =AC13 -> 373.68444
L15: sum column | M15: included | N15: excluded | O15: sum column | P15: included | Q15: 50% excluded | V15: assumption | W15: S1-scenario EU 2040 IA | X15: Stays at 2030 levels | Y15: S1-scenario EU 2040 IA | Z15: assumption | AA15: should we assume something here? | AB15: S1-scenario EU 2040 IA | AC15: assumption
W16: "pessimistic" | X16: "rather optimistic"
X17: "highly uncertain"
W18: S1 scenario considers mitigation due to current policies (but no more),
J19: from EU 2040 Impact assessment
K21: LULUCF net sink estimates (Mt CO2eq)
J22: Model | K22: GLOBIOM-model | L22: GLOBIOM-model | M22: FSCM-model | N22: GLOBIOM-model | O22: GLOBIOM-model
J23: Scenario | K23: S1 | L23: S2 | M23: S2 | N23: S3 | O23: S3*BIO+ | P23: LIFE
J24: CO2-price | K24: 0 | L24: 50 | M24: =L24 -> 50 | N24: 50 | O24: =N24 -> 50 | P24: =O24 -> 50 | T24: €(2020)/tCO2eq
J25: 2015 | K25: -330 | L25: =K25 -> -330 | M25: =L25 -> -330 | N25: =L25 -> -330 | O25: =N25 -> -330 | P25: =N25 -> -330
J26: 2030 | K26: -310 | L26: =K26 -> -310 | M26: -334 | N26: =K26 -> -310 | O26: =N26 -> -310 | P26: =L26 -> -310
J27: 2040 | K27: -220 | L27: -330 | M27: -331 | N27: -330 | O27: =N27+100 -> -230 | P27: -360
J28: 2050 | K28: -330 | L28: -340 | M28: -347 | N28: -340 | O28: =N28+65 -> -275 | P28: -380
J38: Climate change impacts on net LULUCF sink have not been considered. See fig below
