Workbook

Sheet FR_UPD
A1: Trans - Update
B5: ~TFM_UPD
B6: TimeSlice | C6: LimType | D6: Attribute | E6: Year | F6: Attrib_Cond | G6: Val_Cond | H6: AllRegions | I6: Pset_Set | J6: Pset_PN | K6: Pset_PD | L6: Pset_CI | M6: Pset_CO | N6: Cset_Set | O6: Cset_CN | P6: Cset_CD
D7: LIFE | H7: +10 | J7: =C74 -> ENFR_PHENIX_00 | R7: Following the feedback of Dominique Lafond (EDF) during the JET validation in Nov 2013, an extension of 10 years of all existing nuclear plants in FR should be tested
D8: LIFE | H8: +10 | J8: =C75 -> ENFR_BELLEVILLE-1_00
D9: LIFE | H9: +10 | J9: =C76 -> ENFR_BELLEVILLE-2_00
D10: LIFE | H10: +10 | J10: =C77 -> ENFR_BLAYAIS-1_00
D11: LIFE | H11: +10 | J11: =C78 -> ENFR_BLAYAIS-2_00
D12: LIFE | H12: +10 | J12: =C79 -> ENFR_BLAYAIS-3_00
D13: LIFE | H13: +10 | J13: =C80 -> ENFR_BLAYAIS-4_00
D14: LIFE | H14: +10 | J14: =C81 -> ENFR_BUGEY-2_00_00
D15: LIFE | H15: +10 | J15: =C82 -> ENFR_BUGEY-3_00_00
D16: LIFE | H16: +10 | J16: =C83 -> ENFR_BUGEY-4_00_00
D17: LIFE | H17: +10 | J17: =C84 -> ENFR_BUGEY-5_00_00
D18: LIFE | H18: +10 | J18: =C85 -> ENFR_CATTENOM-1_00
D19: LIFE | H19: +10 | J19: =C86 -> ENFR_CATTENOM-2_00
... D65: LIFE | H65: +10 | J65: =C132 -> ENFR_TRICASTIN-4_00
C71: Life time of nuclear power plants in FR as in IAEA data base
C72: TechName | D72: Comm-IN | E72: Comm-OUT | F72: Year | G72: * | H72: * | I72: AFA | J72: AFA~2005 | K72: AFA~2010 | L72: NCAP_PASTI | M72: NCAP_BND~UP | N72: NCAP_BND~FX | O72: START | P72: END | Q72: VAROM | R72: INVCOST | S72: * | T72: Life | U72: EFF | V72: Peak | W72: Cap2Act
D73: *Comment row | G73: GW | H73: GW | L73: GW | M73: GW | N73: GW | P73: Euro/kW | Q73: Euro/GJ | R73: Euro/kW | T73: Years | U73: % | W73: PJ/GW
C74: ENFR_PHENIX_00 | D74: ELCNUC | E74: ELCHIG | F74: 1973 | G74: 0.13 | H74: 0.14 | I74: 0.7056 | J74: 0.7056 | K74: 0.7102 | L74: 0.13 | S74: 2009 | T74: 36 | U74: 2.85 | V74: 1 | W74: 31.536
C75: ENFR_BELLEVILLE-1_00 | D75: ELCNUC | E75: ELCHIG | F75: 1987 | G75: 1.31 | H75: 1.363 | I75: 0.763 | J75: 0.8919 | K75: 0.5795 | L75: 1.31 | S75: 2017 | T75: 30 | U75: 1.0181256 | V75: 1 | W75: 31.536
C76: ENFR_BELLEVILLE-2_00 | D76: ELCNUC | E76: ELCHIG | F76: 1988 | G76: 1.31 | H76: 1.363 | I76: 0.797 | J76: 0.8053 | K76: 0.6858 | L76: 1.31 | S76: 2018 | T76: 30 | U76: 1.0181256 | V76: 1 | W76: 31.536
C77: ENFR_BLAYAIS-1_00 | D77: ELCNUC | E77: ELCHIG | F77: 1981 | G77: 0.91 | H77: 0.951 | I77: 0.796 | J77: 0.8634 | K77: 0.8323 | L77: 0.91 | S77: 2021 | T77: 40 | U77: 0.99529031 | V77: 1 | W77: 31.536
C78: ENFR_BLAYAIS-2_00 | D78: ELCNUC | E78: ELCHIG | F78: 1982 | G78: 0.91 | H78: 0.951 | I78: 0.824 | J78: 0.8678 | K78: 0.7955 | L78: 0.91 | S78: 2022 | T78: 40 | U78: 0.99529031 | V78: 1 | W78: 31.536
C79: ENFR_BLAYAIS-3_00 | D79: ELCNUC | E79: ELCHIG | F79: 1983 | G79: 0.91 | H79: 0.951 | I79: 0.829 | J79: 0.7361 | K79: 0.8379 | L79: 0.91 | S79: 2023 | T79: 40 | U79: 0.99529031 | V79: 1 | W79: 31.536
C80: ENFR_BLAYAIS-4_00 | D80: ELCNUC | E80: ELCHIG | F80: 1983 | G80: 0.91 | H80: 0.951 | I80: 0.82 | J80: 0.6843 | K80: 0.8435 | L80: 0.91 | S80: 2023 | T80: 40 | U80: 0.99529031 | V80: 1 | W80: 31.536
C81: ENFR_BUGEY-2_00_00 | D81: ELCNUC | E81: ELCHIG | F81: 1978 | G81: 0.91 | H81: 0.945 | I81: 0.739 | J81: 0.7996 | K81: 0.2782 | L81: 0.91 | S81: 2018 | T81: 40 | U81: 0.98901087 | V81: 1 | W81: 31.536
C82: ENFR_BUGEY-3_00_00 | D82: ELCNUC | E82: ELCHIG | F82: 1978 | G82: 0.91 | H82: 0.945 | I82: 0.728 | J82: 0.7283 | K82: 0.7283 | L82: 0.91 | S82: 2018 | T82: 40 | U82: 0.98901087 | V82: 1 | W82: 31.536
C83: ENFR_BUGEY-4_00_00 | D83: ELCNUC | E83: ELCHIG | F83: 1979 | G83: 0.88 | H83: 0.917 | I83: 0.754 | J83: 0.7878 | K83: 0.9566 | L83: 0.88 | S83: 2019 | T83: 40 | U83: 0.95970685 | V83: 1 | W83: 31.536
C84: ENFR_BUGEY-5_00_00 | D84: ELCNUC | E84: ELCHIG | F84: 1979 | G84: 0.88 | H84: 0.917 | I84: 0.776 | J84: 0.9109 | K84: 0.7689 | L84: 0.88 | S84: 2019 | T84: 40 | U84: 0.95970685 | V84: 1 | W84: 31.536
C85: ENFR_CATTENOM-1_00 | D85: ELCNUC | E85: ELCHIG | F85: 1986 | G85: 1.3 | H85: 1.362 | I85: 0.758 | J85: 0.8186 | K85: 0.8662 | L85: 1.3 | S85: 2016 | T85: 30 | U85: 1.0173787 | V85: 1 | W85: 31.536
... C132: ENFR_TRICASTIN-4_00 | D132: ELCNUC | E132: ELCHIG | F132: 1981 | G132: 0.915 | H132: 0.955 | I132: 0.822 | J132: 0.811 | K132: 0.7815 | L132: 0.915 | S132: 2021 | T132: 40 | U132: 0.9994766 | V132: 1 | W132: 31.536
C133: ENFR_FLAMANVILLE-3 | D133: ELCNUC | E133: ELCHIG | F133: 2016 | G133: 1.63 | H133: 1.75 | I133: 0.85 | J133: 0.85 | N133: 1.63 | O133: 2016 | P133: 2016 | S133: 2066 | T133: 50 | U133: 1.85328 | V133: 1 | W133: 31.536
C134: ENFR_PENLY-3 | D134: ELCNUC | E134: ELCHIG | F134: 2017 | G134: 1.63 | H134: 1.75 | I134: 0.85 | J134: 0.85 | N134: 1.63 | O134: 2017 | P134: 2017 | S134: 2067 | T134: 50 | U134: 1.85328 | V134: 1 | W134: 31.536

Sheet Background info
B2: LimType | C2: FX | D2: N | E2: UP | H2: Member State | I2: Plant name | J2: Capacity (GW) | K2: Comment | M2: From NUCEU_Trans
A3: TODO | B3: Process\Attribute | C3: NCAP_BND | D3: NCAP_BND | E3: CAP_BND | H3: Bulgaria | I3: ENBG_BELENE-1 | K3: cancelled | M3: ENBG_BELENE-1 | N3: 2013
A4: x with N | B4: ENBG_BELENE-1 | C4: 1.06 | D4: 2012 | H4: Bulgaria | I4: ENBG_BELENE-2 | K4: cancelled | M4: ENBG_BELENE-2 | N4: 2014
A5: x with N | B5: ENBG_BELENE-2 | C5: 1.06 | D5: 2013 | H5: Bulgaria | I5: ENBG_KOZLODUY-7 | J5: 1 | M5: ENCZ_TEMELIN-3 | N5: 2023
B6: ENBG_KOZLODUY-7 | E6: 1 | H6: Czech Rep. | I6: ENCZ_DUKOVANY-5 | J6: 1.14 | M6: ENCZ_TEMELIN-4 | N6: 2024
B7: ENCZ_DUKOVANY-5 | E7: 1.14077 | H7: Czech Rep. | I7: ENCZ_TEMELIN-3 | J7: 1.14 | M7: ENFI_OLKILUOTO-3 | N7: 2013
B8: ENCZ_TEMELIN-3 | C8: 1.14077 | D8: 2022 | H8: Czech Rep. | I8: ENCZ_TEMELIN-4 | J8: 1.14 | M8: ENFR_FLAMANVILLE-3 | N8: 2016
B9: ENCZ_TEMELIN-4 | C9: 1.14077 | D9: 2023 | H9: Finland | I9: ENFI_OLKILUOTO-3 | J9: 1.6 | M9: ENFR_PENLY-3 | N9: 2017
B10: ENFI_OLKILUOTO-3 | C10: 1.6 | D10: 2012 | H10: Finland | I10: ENFI_OLKILUOTO-4 | J10: 1.5 | K10: cancelled? | M10: ENHU_PAKS-5 | N10: 2026
B11: ENFR_FLAMANVILLE-3 | C11: 1.63 | D11: 2015 | H11: Finland | I11: ENFI_PYHA-YOKI | J11: 1.5 | M11: ENHU_PAKS-6 | N11: 2031
B12: ENHU_PAKS-5 | C12: 1.39535 | D12: 2025 | H12: France | I12: ENFR_FLAMANVILLE-3 | J12: 1.63 | M12: ENRO_CERNAVODA-3 | N12: 2016
A13: x | B13: ENHU_PAKS-6 | C13: 1.39535 | D13: 2030 | H13: France | I13: ENFR_PENLY-3 | K13: cancelled | M13: ENRO_CERNAVODA-4 | N13: 2017
B14: ENLT_VISAGINAS-1 | E14: 1.35 | H14: Hungary | I14: ENHU_PAKS-5 | J14: 1.39 | M14: ENSK_MOCHOVCE-3 | N14: 2012
B15: ENNL_BORSSELE-2 | E15: 1.2 | H15: Hungary | I15: ENHU_PAKS-6 | J15: 1.39 | M15: ENSK_MOCHOVCE-4 | N15: 2013
B16: ENPL_POLAND-1 | E16: 3 | H16: Lithuania | I16: ENLT_VISAGINAS | J16: 1.35 | M16: ENUK_HINKLEYPOINT-C1 | N16: 2018
B17: ENPL_POLAND-2 | E17: 3 | H17: The Netherlands | I17: ENNL_BORSSELE-2 | K17: cancelled | M17: ENUK_HINKLEYPOINT-C2 | N17: 2019
B18: ENRO_CERNAVODA-3 | D18: 2015 | E18: 0.72 | H18: Poland | I18: ENPL_POLAND-1 | J18: 3 | M18: ENUK_SIZEWELL-C1 | N18: 2020
B19: ENRO_CERNAVODA-4 | D19: 2016 | E19: 0.72 | H19: Poland | I19: ENPL_POLAND-2 | J19: 3 | M19: ENUK_SIZEWELL-C2 | N19: 2022
B20: ENRO_CERNAVODA-5 | E20: 1 | H20: Romania | I20: ENRO_CERNAVODA-3 | J20: 0.72
A21: x | B21: ENSI_KRSKO-2 | E21: 1.6 | H21: Romania | I21: ENRO_CERNAVODA-4 | J21: 0.72
B22: ENSK_BOHUNICE-NEWBLOCK | E22: 1 | H22: Slovenia | I22: ENSI_KRSKO-2 | J22: 1.6
B23: ENSK_KECEROVCE | E23: 1.2 | H23: Slovakia | I23: ENSK_BOHUNICE-NEWBLOCK | J23: 1
B24: ENSK_MOCHOVCE-3 | C24: 0.391 | D24: 2011 | H24: Slovakia | I24: ENSK_KECEROVCE | J24: 1.2
B25: ENSK_MOCHOVCE-4 | C25: 0.391 | D25: 2012 | H25: Slovakia | I25: ENSK_MOCHOVCE-3 | J25: 0.39 | K25: under construction
A26: x | B26: ENUK_HINKLEYPOINT-C1 | C26: 1.5153704 | D26: 2017 | H26: Slovakia | I26: ENSK_MOCHOVCE-4 | J26: 0.39 | K26: under construction
B27: ENUK_HINKLEYPOINT-C2 | C27: 1.5153704 | D27: 2018 | H27: United Kingdom | I27: ENUK_HINKLEYPOINT-C1 | J27: 1.52
B28: ENUK_MOORSIDE | E28: 3.6 | H28: United Kingdom | I28: ENUK_HINKLEYPOINT-C2 | J28: 1.52
B29: ENUK_OLDBURY-B | E29: 3.5 | H29: United Kingdom | I29: ENUK_MOORSIDE | J29: 3.6
B30: ENUK_SIZEWELL-C1 | C30: 1.5153704 | D30: 2019 | H30: United Kingdom | I30: ENUK_OLDBURY-B | J30: 3.5
B31: ENUK_SIZEWELL-C2 | C31: 1.5153704 | D31: 2021 | H31: United Kingdom | I31: ENUK_SIZEWELL-C1 | J31: 1.52
B32: ENUK_WYLFA-B | E32: 5 | H32: United Kingdom | I32: ENUK_SIZEWELL-C2 | J32: 1.52
H33: United Kingdom | I33: ENUK_WYLFA-B | J33: 5

Sheet Nuclear plans killing
B2: ~TFM_INS
B3: TimeSlice | C3: LimType | D3: Attribute | E3: Year | F3: Other_Indexes | G3: Attrib_COND | H3: Val_COND | I3: Pset_PN | J3: Allregions
D4: OFFEPS | J4: 1
B8: ~TFM_UPD | I8: Ask Andreas which are killed for ever or which come as optional in long term future
B9: TimeSlice | C9: LimType | D9: Attribute | E9: AllRegions | F9: Pset_PN
D10: START | E10: 2100 | F10: ENRO_CERNAVODA-5
B15: ~TFM_INS | H15: From VEDA FE
B16: PSET_PN | C16: Attribute | D16: Year | E16: LimType | F16: Allregions | H16: Region | I16: Process | J16: Attribute | K16: Year | L16: LimType\Scenario | M16: Nuc-EU
B17: =I17 -> ENBG_BELENE-1 | C17: =J17 -> NCAP_BND | D17: =K17 -> 2013 | E17: =L17 -> FX | F17: 0 | H17: BG | I17: ENBG_BELENE-1 | J17: NCAP_BND | K17: 2013 | L17: FX | M17: 1.06
B18: =I18 -> ENBG_BELENE-1 | C18: =J18 -> NCAP_BND | D18: =K18 -> 2013 | E18: =L18 -> N | F18: 0 | H18: BG | I18: ENBG_BELENE-1 | J18: NCAP_BND | K18: 2013 | L18: N | M18: 2012
B19: =I19 -> ENBG_BELENE-2 | C19: =J19 -> NCAP_BND | D19: =K19 -> 2014 | E19: =L19 -> FX | F19: 0 | H19: BG | I19: ENBG_BELENE-2 | J19: NCAP_BND | K19: 2014 | L19: FX | M19: 1.06
B20: =I20 -> ENBG_BELENE-2 | C20: =J20 -> NCAP_BND | D20: =K20 -> 2014 | E20: =L20 -> N | F20: 0 | H20: BG | I20: ENBG_BELENE-2 | J20: NCAP_BND | K20: 2014 | L20: N | M20: 2013
B21: ENBG_BELENE-1 | C21: CAP_BND | E21: UP | F21: =M17 -> 1.06 | H21: BG | I21: ENBG_KOZLODUY-7 | J21: CAP_BND | K21: 2026 | L21: UP | M21: 1
B22: ENBG_BELENE-2 | C22: CAP_BND | E22: UP | F22: =M19 -> 1.06 | H22: CZ | I22: ENCZ_DUKOVANY-5 | J22: CAP_BND | K22: 2025 | L22: UP | M22: 1.14077
B23: =I31 -> ENFR_FLAMANVILLE-3 | C23: =J31 -> NCAP_BND | D23: =K31 -> 2016 | E23: =L31 -> FX | F23: 0 | H23: CZ | I23: ENCZ_TEMELIN-3 | J23: NCAP_BND | K23: 2023 | L23: FX | M23: 1.14077
B24: =I32 -> ENFR_FLAMANVILLE-3 | C24: =J32 -> NCAP_BND | D24: =K32 -> 2016 | E24: =L32 -> N | F24: 0 | H24: CZ | I24: ENCZ_TEMELIN-3 | J24: NCAP_BND | K24: 2023 | L24: N | M24: 2022
B25: =B24 -> ENFR_FLAMANVILLE-3 | C25: =C22 -> CAP_BND | E25: UP | F25: =M31 -> 1.63 | H25: CZ | I25: ENCZ_TEMELIN-4 | J25: NCAP_BND | K25: 2024 | L25: FX | M25: 1.14077
H26: CZ | I26: ENCZ_TEMELIN-4 | J26: NCAP_BND | K26: 2024 | L26: N | M26: 2023
H27: FI | I27: ENFI_OLKILUOTO-3 | J27: NCAP_BND | K27: 2013 | L27: FX | M27: 1.6
H28: FI | I28: ENFI_OLKILUOTO-3 | J28: NCAP_BND | K28: 2013 | L28: N | M28: 2012
H29: FI | I29: ENFI_OLKILUOTO-4 | J29: CAP_BND | K29: 2020 | L29: UP | M29: 1.5
H30: FI | I30: ENFI_PYHA-YOKI | J30: CAP_BND | K30: 2020 | L30: UP | M30: 1.5
H31: FR | I31: ENFR_FLAMANVILLE-3 | J31: NCAP_BND | K31: 2016 | L31: FX | M31: 1.63
H32: FR | I32: ENFR_FLAMANVILLE-3 | J32: NCAP_BND | K32: 2016 | L32: N | M32: 2015
H33: HU | I33: ENHU_PAKS-5 | J33: NCAP_BND | K33: 2026 | L33: FX | M33: 1.39535
H34: HU | I34: ENHU_PAKS-5 | J34: NCAP_BND | K34: 2026 | L34: N | M34: 2025
H35: HU | I35: ENHU_PAKS-6 | J35: NCAP_BND | K35: 2031 | L35: FX | M35: 1.39535
H36: HU | I36: ENHU_PAKS-6 | J36: NCAP_BND | K36: 2031 | L36: N | M36: 2030
H37: IT | I37: ENIT_ITALY-1 | J37: CAP_BND | K37: 2020 | L37: UP | M37: 1.65
... H67: UK | I67: ENUK_WYLFA-B | J67: CAP_BND | K67: 2023 | L67: UP | M67: 5

Sheet Note
B3: This scenario udpates the tlife of existing nuclear power plants
B4: The formulas are flexible

Sheet Update
B2: ~TFM_UPD
B3: Attribute | C3: Pset_PN | D3: AllRegions
B4: NCAP_TLIFE | C4: ='Existing plants_SCEN50yrs'!D2 -> ENBE_DOEL-1_00 | D4: ='Existing plants_SCEN60yrs'!H2 -> 51
B5: NCAP_TLIFE | C5: ='Existing plants_SCEN50yrs'!D3 -> ENBE_DOEL-2_00 | D5: ='Existing plants_SCEN60yrs'!H3 -> 50
B6: NCAP_TLIFE | C6: ='Existing plants_SCEN50yrs'!D4 -> ENBE_DOEL-3_00 | D6: ='Existing plants_SCEN60yrs'!H4 -> 40
B7: NCAP_TLIFE | C7: ='Existing plants_SCEN50yrs'!D5 -> ENBE_DOEL-4_00 | D7: ='Existing plants_SCEN60yrs'!H5 -> 40
B8: NCAP_TLIFE | C8: ='Existing plants_SCEN50yrs'!D6 -> ENBE_TIHANGE-1_00 | D8: ='Existing plants_SCEN60yrs'!H6 -> 50
B9: NCAP_TLIFE | C9: ='Existing plants_SCEN50yrs'!D7 -> ENBE_TIHANGE-2_00 | D9: ='Existing plants_SCEN60yrs'!H7 -> 40
B10: NCAP_TLIFE | C10: ='Existing plants_SCEN50yrs'!D8 -> ENBE_TIHANGE-3_00 | D10: ='Existing plants_SCEN60yrs'!H8 -> 40
B11: NCAP_TLIFE | C11: ='Existing plants_SCEN50yrs'!D9 -> ENBG_KOZLODUY-3_00 | D11: ='Existing plants_SCEN60yrs'!H9 -> 26
B12: NCAP_TLIFE | C12: ='Existing plants_SCEN50yrs'!D10 -> ENBG_KOZLODUY-4_00 | D12: ='Existing plants_SCEN60yrs'!H10 -> 24
B13: NCAP_TLIFE | C13: ='Existing plants_SCEN50yrs'!D11 -> ENBG_KOZLODUY-5_00 | D13: ='Existing plants_SCEN60yrs'!H11 -> 60
B14: NCAP_TLIFE | C14: ='Existing plants_SCEN50yrs'!D12 -> ENBG_KOZLODUY-6_00 | D14: ='Existing plants_SCEN60yrs'!H12 -> 60
B15: NCAP_TLIFE | C15: ='Existing plants_SCEN50yrs'!D13 -> ENCH_BEZNAU-1_00 | D15: ='Existing plants_SCEN60yrs'!H13 -> 50
... B157: NCAP_TLIFE | C157: ='Existing plants_SCEN50yrs'!D155 -> ENUK_WYLFA2_00 | D157: ='Existing plants_SCEN60yrs'!H155 -> 41

Sheet ShutdownCurve
B2: Year | C2: Remaining Capacity (40 yrs scenario) | D2: Remaining Capacity (50 yrs scenario) | E2: Remaining Capacity (60 yrs scenario)
B3: 2010 | C3: =SUMIF(Table157[End of life],">="&Table3[[#This Row],[Year]],Table157[Existing capacity GW]) -> 134.455 | D3: =SUMIF(Table15[End of life],">="&Table3[[#This Row],[Year]],Table15[Existing capacity GW]) -> 134.455 | E3: =SUMIF(Table1[End of life],">="&Table3[[#This Row],[Year]],Table1[Existing capacity GW]) -> 134.455
B4: 2011 | C4: =SUMIF(Table157[End of life],">="&Table3[[#This Row],[Year]],Table157[Existing capacity GW]) -> 134.455 | D4: =SUMIF(Table15[End of life],">="&Table3[[#This Row],[Year]],Table15[Existing capacity GW]) -> 134.455 | E4: =SUMIF(Table1[End of life],">="&Table3[[#This Row],[Year]],Table1[Existing capacity GW]) -> 134.455
B5: 2012 | C5: =SUMIF(Table157[End of life],">="&Table3[[#This Row],[Year]],Table157[Existing capacity GW]) -> 125.673 | D5: =SUMIF(Table15[End of life],">="&Table3[[#This Row],[Year]],Table15[Existing capacity GW]) -> 126.119 | E5: =SUMIF(Table1[End of life],">="&Table3[[#This Row],[Year]],Table1[Existing capacity GW]) -> 126.119
B6: 2013 | C6: =SUMIF(Table157[End of life],">="&Table3[[#This Row],[Year]],Table157[Existing capacity GW]) -> 124.966 | D6: =SUMIF(Table15[End of life],">="&Table3[[#This Row],[Year]],Table15[Existing capacity GW]) -> 125.412 | E6: =SUMIF(Table1[End of life],">="&Table3[[#This Row],[Year]],Table1[Existing capacity GW]) -> 125.412
B7: 2014 | C7: =SUMIF(Table157[End of life],">="&Table3[[#This Row],[Year]],Table157[Existing capacity GW]) -> 124.836 | D7: =SUMIF(Table15[End of life],">="&Table3[[#This Row],[Year]],Table15[Existing capacity GW]) -> 125.412 | E7: =SUMIF(Table1[End of life],">="&Table3[[#This Row],[Year]],Table1[Existing capacity GW]) -> 125.412
B8: 2015 | C8: =SUMIF(Table157[End of life],">="&Table3[[#This Row],[Year]],Table157[Existing capacity GW]) -> 124.836 | D8: =SUMIF(Table15[End of life],">="&Table3[[#This Row],[Year]],Table15[Existing capacity GW]) -> 125.412 | E8: =SUMIF(Table1[End of life],">="&Table3[[#This Row],[Year]],Table1[Existing capacity GW]) -> 125.412
B9: 2016 | C9: =SUMIF(Table157[End of life],">="&Table3[[#This Row],[Year]],Table157[Existing capacity GW]) -> 123.071 | D9: =SUMIF(Table15[End of life],">="&Table3[[#This Row],[Year]],Table15[Existing capacity GW]) -> 123.647 | E9: =SUMIF(Table1[End of life],">="&Table3[[#This Row],[Year]],Table1[Existing capacity GW]) -> 123.647
B10: 2017 | C10: =SUMIF(Table157[End of life],">="&Table3[[#This Row],[Year]],Table157[Existing capacity GW]) -> 123.071 | D10: =SUMIF(Table15[End of life],">="&Table3[[#This Row],[Year]],Table15[Existing capacity GW]) -> 123.647 | E10: =SUMIF(Table1[End of life],">="&Table3[[#This Row],[Year]],Table1[Existing capacity GW]) -> 123.647
B11: 2018 | C11: =SUMIF(Table157[End of life],">="&Table3[[#This Row],[Year]],Table157[Existing capacity GW]) -> 119.531 | D11: =SUMIF(Table15[End of life],">="&Table3[[#This Row],[Year]],Table15[Existing capacity GW]) -> 120.603 | E11: =SUMIF(Table1[End of life],">="&Table3[[#This Row],[Year]],Table1[Existing capacity GW]) -> 120.603
B12: 2019 | C12: =SUMIF(Table157[End of life],">="&Table3[[#This Row],[Year]],Table157[Existing capacity GW]) -> 116.358 | D12: =SUMIF(Table15[End of life],">="&Table3[[#This Row],[Year]],Table15[Existing capacity GW]) -> 120.13 | E12: =SUMIF(Table1[End of life],">="&Table3[[#This Row],[Year]],Table1[Existing capacity GW]) -> 120.13
B13: 2020 | C13: =SUMIF(Table157[End of life],">="&Table3[[#This Row],[Year]],Table157[Existing capacity GW]) -> 110.118 | D13: =SUMIF(Table15[End of life],">="&Table3[[#This Row],[Year]],Table15[Existing capacity GW]) -> 115.65 | E13: =SUMIF(Table1[End of life],">="&Table3[[#This Row],[Year]],Table1[Existing capacity GW]) -> 115.65
B14: 2021 | C14: =SUMIF(Table157[End of life],">="&Table3[[#This Row],[Year]],Table157[Existing capacity GW]) -> 97.973 | D14: =SUMIF(Table15[End of life],">="&Table3[[#This Row],[Year]],Table15[Existing capacity GW]) -> 113.269 | E14: =SUMIF(Table1[End of life],">="&Table3[[#This Row],[Year]],Table1[Existing capacity GW]) -> 113.269
... B43: 2050 | C43: =SUMIF(Table157[End of life],">="&Table3[[#This Row],[Year]],Table157[Existing capacity GW]) -> 0 | D43: =SUMIF(Table15[End of life],">="&Table3[[#This Row],[Year]],Table15[Existing capacity GW]) -> 2.576 | E43: =SUMIF(Table1[End of life],">="&Table3[[#This Row],[Year]],Table1[Existing capacity GW]) -> 18.921

Sheet Existing plants_SCEN40yrs
A1: Generic Lifetime | C1: Member State | D1: Process | E1: Start year | F1: Efficiency PJ/tU | G1: Lifetime Option | H1: Tlife yrs | I1: End of life (fixed) | J1: End of life | K1: Existing capacity GW | L1: Comments | M1: Source
A2: 40 | C2: BE | D2: ENBE_DOEL-1_00 | E2: 1974 | F2: 1.3464165 | G2: fixed | H2: =IF(Table157[[#This Row],[Lifetime Option]]="fixed",Table157[[#This Row],[End of life (fixed)]]-Table157[[#This Row],[Start year]],Table268[Generic Lifetime]) -> 51 | I2: 2025 | J2: =IF(Table157[[#This Row],[Lifetime Option]]="fixed",Table157[[#This Row],[End of life (fixed)]],Table157[[#This Row],[Start year]]+Table268[Generic Lifetime]) -> 2025 | K2: 0.433 | M2: http://www.engie.com/en/journalists/press-releases/agreement-conditions-extending-doel-1-doel-2-new-nuclear-contribution-system/
C3: BE | D3: ENBE_DOEL-2_00 | E3: 1975 | F3: 1.3464165 | G3: fixed | H3: =IF(Table157[[#This Row],[Lifetime Option]]="fixed",Table157[[#This Row],[End of life (fixed)]]-Table157[[#This Row],[Start year]],Table268[Generic Lifetime]) -> 50 | I3: 2025 | J3: =IF(Table157[[#This Row],[Lifetime Option]]="fixed",Table157[[#This Row],[End of life (fixed)]],Table157[[#This Row],[Start year]]+Table268[Generic Lifetime]) -> 2025 | K3: 0.433 | M3: http://www.engie.com/en/journalists/press-releases/agreement-conditions-extending-doel-1-doel-2-new-nuclear-contribution-system/
C4: BE | D4: ENBE_DOEL-3_00 | E4: 1982 | F4: 1.4638774 | G4: fixed | H4: =IF(Table157[[#This Row],[Lifetime Option]]="fixed",Table157[[#This Row],[End of life (fixed)]]-Table157[[#This Row],[Start year]],Table268[Generic Lifetime]) -> 40 | I4: 2022 | J4: =IF(Table157[[#This Row],[Lifetime Option]]="fixed",Table157[[#This Row],[End of life (fixed)]],Table157[[#This Row],[Start year]]+Table268[Generic Lifetime]) -> 2022 | K4: 1.006 | L4: uncertain - follow up | M4: http://www.fanc.fgov.be/nl/news/doel-3/tihange-2-next-steps-of-the-review-process/766.aspx
C5: BE | D5: ENBE_DOEL-4_00 | E5: 1985 | F5: 1.4183133 | G5: fixed | H5: =IF(Table157[[#This Row],[Lifetime Option]]="fixed",Table157[[#This Row],[End of life (fixed)]]-Table157[[#This Row],[Start year]],Table268[Generic Lifetime]) -> 40 | I5: 2025 | J5: =IF(Table157[[#This Row],[Lifetime Option]]="fixed",Table157[[#This Row],[End of life (fixed)]],Table157[[#This Row],[Start year]]+Table268[Generic Lifetime]) -> 2025 | K5: 1.039
C6: BE | D6: ENBE_TIHANGE-1_00 | E6: 1975 | F6: 1.3654688 | G6: fixed | H6: =IF(Table157[[#This Row],[Lifetime Option]]="fixed",Table157[[#This Row],[End of life (fixed)]]-Table157[[#This Row],[Start year]],Table268[Generic Lifetime]) -> 50 | I6: 2025 | J6: =IF(Table157[[#This Row],[Lifetime Option]]="fixed",Table157[[#This Row],[End of life (fixed)]],Table157[[#This Row],[Start year]]+Table268[Generic Lifetime]) -> 2025 | K6: 0.962 | M6: http://economie.fgov.be/fr/consommateurs/Energie/Nucleaire/centrales_nucleaires/sortie_nucleaire/#.Vdb00Y7DVE4
C7: BE | D7: ENBE_TIHANGE-2_00 | E7: 1982 | F7: 1.3387206 | G7: fixed | H7: =IF(Table157[[#This Row],[Lifetime Option]]="fixed",Table157[[#This Row],[End of life (fixed)]]-Table157[[#This Row],[Start year]],Table268[Generic Lifetime]) -> 40 | I7: 2022 | J7: =IF(Table157[[#This Row],[Lifetime Option]]="fixed",Table157[[#This Row],[End of life (fixed)]],Table157[[#This Row],[Start year]]+Table268[Generic Lifetime]) -> 2022 | K7: 1.008 | L7: uncertain - follow up | M7: http://www.fanc.fgov.be/nl/news/doel-3/tihange-2-next-steps-of-the-review-process/766.aspx
C8: BE | D8: ENBE_TIHANGE-3_00 | E8: 1985 | F8: 1.417824 | G8: fixed | H8: =IF(Table157[[#This Row],[Lifetime Option]]="fixed",Table157[[#This Row],[End of life (fixed)]]-Table157[[#This Row],[Start year]],Table268[Generic Lifetime]) -> 40 | I8: 2025 | J8: =IF(Table157[[#This Row],[Lifetime Option]]="fixed",Table157[[#This Row],[End of life (fixed)]],Table157[[#This Row],[Start year]]+Table268[Generic Lifetime]) -> 2025 | K8: 1.046
C9: BG | D9: ENBG_KOZLODUY-3_00 | E9: 1980 | F9: 0.77 | G9: fixed | H9: =IF(Table157[[#This Row],[Lifetime Option]]="fixed",Table157[[#This Row],[End of life (fixed)]]-Table157[[#This Row],[Start year]],Table268[Generic Lifetime]) -> 26 | I9: 2006 | J9: =IF(Table157[[#This Row],[Lifetime Option]]="fixed",Table157[[#This Row],[End of life (fixed)]],Table157[[#This Row],[Start year]]+Table268[Generic Lifetime]) -> 2006 | K9: 0.408 | L9: closed
C10: BG | D10: ENBG_KOZLODUY-4_00 | E10: 1982 | F10: 0.77 | G10: fixed | H10: =IF(Table157[[#This Row],[Lifetime Option]]="fixed",Table157[[#This Row],[End of life (fixed)]]-Table157[[#This Row],[Start year]],Table268[Generic Lifetime]) -> 24 | I10: 2006 | J10: =IF(Table157[[#This Row],[Lifetime Option]]="fixed",Table157[[#This Row],[End of life (fixed)]],Table157[[#This Row],[Start year]]+Table268[Generic Lifetime]) -> 2006 | K10: 0.408 | L10: closed
C11: BG | D11: ENBG_KOZLODUY-5_00 | E11: 1987 | F11: 0.7776 | G11: generic | H11: =IF(Table157[[#This Row],[Lifetime Option]]="fixed",Table157[[#This Row],[End of life (fixed)]]-Table157[[#This Row],[Start year]],Table268[Generic Lifetime]) -> 40 | J11: =IF(Table157[[#This Row],[Lifetime Option]]="fixed",Table157[[#This Row],[End of life (fixed)]],Table157[[#This Row],[Start year]]+Table268[Generic Lifetime]) -> 2027 | K11: 0.953 | M11: http://www.world-nuclear.org/info/Country-Profiles/Countries-A-F/Bulgaria/
C12: BG | D12: ENBG_KOZLODUY-6_00 | E12: 1991 | F12: 0.7776 | G12: generic | H12: =IF(Table157[[#This Row],[Lifetime Option]]="fixed",Table157[[#This Row],[End of life (fixed)]]-Table157[[#This Row],[Start year]],Table268[Generic Lifetime]) -> 40 | J12: =IF(Table157[[#This Row],[Lifetime Option]]="fixed",Table157[[#This Row],[End of life (fixed)]],Table157[[#This Row],[Start year]]+Table268[Generic Lifetime]) -> 2031 | K12: 0.953 | M12: http://www.world-nuclear.org/info/Country-Profiles/Countries-A-F/Bulgaria/
C13: CH | D13: ENCH_BEZNAU-1_00 | E13: 1969 | F13: 1.2203044 | G13: fixed | H13: =IF(Table157[[#This Row],[Lifetime Option]]="fixed",Table157[[#This Row],[End of life (fixed)]]-Table157[[#This Row],[Start year]],Table268[Generic Lifetime]) -> 50 | I13: 2019 | J13: =IF(Table157[[#This Row],[Lifetime Option]]="fixed",Table157[[#This Row],[End of life (fixed)]],Table157[[#This Row],[Start year]]+Table268[Generic Lifetime]) -> 2019 | K13: 0.365 | L13: need to follow up political developments | M13: http://www.world-nuclear.org/info/Country-Profiles/Countries-O-S/Switzerland/
C14: CH | D14: ENCH_BEZNAU-2_00 | E14: 1971 | F14: 1.2203044 | G14: fixed | H14: =IF(Table157[[#This Row],[Lifetime Option]]="fixed",Table157[[#This Row],[End of life (fixed)]]-Table157[[#This Row],[Start year]],Table268[Generic Lifetime]) -> 50 | I14: 2021 | J14: =IF(Table157[[#This Row],[Lifetime Option]]="fixed",Table157[[#This Row],[End of life (fixed)]],Table157[[#This Row],[Start year]]+Table268[Generic Lifetime]) -> 2021 | K14: 0.365 | L14: need to follow up political developments | M14: http://www.world-nuclear.org/info/Country-Profiles/Countries-O-S/Switzerland/
C15: CH | D15: ENCH_GOESGEN_00 | E15: 1979 | F15: 1.5489833 | G15: fixed | H15: =IF(Table157[[#This Row],[Lifetime Option]]="fixed",Table157[[#This Row],[End of life (fixed)]]-Table157[[#This Row],[Start year]],Table268[Generic Lifetime]) -> 50 | I15: 2029 | J15: =IF(Table157[[#This Row],[Lifetime Option]]="fixed",Table157[[#This Row],[End of life (fixed)]],Table157[[#This Row],[Start year]]+Table268[Generic Lifetime]) -> 2029 | K15: 0.985 | L15: need to follow up political developments | M15: http://www.world-nuclear.org/info/Country-Profiles/Countries-O-S/Switzerland/
C16: CH | D16: ENCH_LEIBSTADT_00 | E16: 1984 | F16: 1.28484 | G16: fixed | H16: =IF(Table157[[#This Row],[Lifetime Option]]="fixed",Table157[[#This Row],[End of life (fixed)]]-Table157[[#This Row],[Start year]],Table268[Generic Lifetime]) -> 50 | I16: 2034 | J16: =IF(Table157[[#This Row],[Lifetime Option]]="fixed",Table157[[#This Row],[End of life (fixed)]],Table157[[#This Row],[Start year]]+Table268[Generic Lifetime]) -> 2034 | K16: 1.22 | L16: need to follow up political developments | M16: http://www.world-nuclear.org/info/Country-Profiles/Countries-O-S/Switzerland/
C17: CH | D17: ENCH_MUEHLEBERG_00 | E17: 1971 | F17: 1.474392 | G17: fixed | H17: =IF(Table157[[#This Row],[Lifetime Option]]="fixed",Table157[[#This Row],[End of life (fixed)]]-Table157[[#This Row],[Start year]],Table268[Generic Lifetime]) -> 48 | I17: 2019 | J17: =IF(Table157[[#This Row],[Lifetime Option]]="fixed",Table157[[#This Row],[End of life (fixed)]],Table157[[#This Row],[Start year]]+Table268[Generic Lifetime]) -> 2019 | K17: 0.373 | L17: need to follow up political developments | M17: http://www.world-nuclear.org/info/Country-Profiles/Countries-O-S/Switzerland/
C18: CZ | D18: ENCZ_DUKOVANY-1_00 | E18: 1985 | F18: 1.2607488 | G18: generic | H18: =IF(Table157[[#This Row],[Lifetime Option]]="fixed",Table157[[#This Row],[End of life (fixed)]]-Table157[[#This Row],[Start year]],Table268[Generic Lifetime]) -> 40 | J18: =IF(Table157[[#This Row],[Lifetime Option]]="fixed",Table157[[#This Row],[End of life (fixed)]],Table157[[#This Row],[Start year]]+Table268[Generic Lifetime]) -> 2025 | K18: 0.468 | M18: http://www.oecd-nea.org/ndd/pubs/2014/7197-bb-2014.pdf
C19: CZ | D19: ENCZ_DUKOVANY-2_00 | E19: 1986 | F19: 1.2607488 | G19: generic | H19: =IF(Table157[[#This Row],[Lifetime Option]]="fixed",Table157[[#This Row],[End of life (fixed)]]-Table157[[#This Row],[Start year]],Table268[Generic Lifetime]) -> 40 | J19: =IF(Table157[[#This Row],[Lifetime Option]]="fixed",Table157[[#This Row],[End of life (fixed)]],Table157[[#This Row],[Start year]]+Table268[Generic Lifetime]) -> 2026 | K19: 0.471
C20: CZ | D20: ENCZ_DUKOVANY-3_00 | E20: 1986 | F20: 1.3110781 | G20: generic | H20: =IF(Table157[[#This Row],[Lifetime Option]]="fixed",Table157[[#This Row],[End of life (fixed)]]-Table157[[#This Row],[Start year]],Table268[Generic Lifetime]) -> 40 | J20: =IF(Table157[[#This Row],[Lifetime Option]]="fixed",Table157[[#This Row],[End of life (fixed)]],Table157[[#This Row],[Start year]]+Table268[Generic Lifetime]) -> 2026 | K20: 0.468
C21: CZ | D21: ENCZ_DUKOVANY-4_00 | E21: 1987 | F21: 1.2607488 | G21: generic | H21: =IF(Table157[[#This Row],[Lifetime Option]]="fixed",Table157[[#This Row],[End of life (fixed)]]-Table157[[#This Row],[Start year]],Table268[Generic Lifetime]) -> 40 | J21: =IF(Table157[[#This Row],[Lifetime Option]]="fixed",Table157[[#This Row],[End of life (fixed)]],Table157[[#This Row],[Start year]]+Table268[Generic Lifetime]) -> 2027 | K21: 0.471
C22: CZ | D22: ENCZ_TEMELIN-1_00 | E22: 2000 | F22: 1.312848 | G22: generic | H22: =IF(Table157[[#This Row],[Lifetime Option]]="fixed",Table157[[#This Row],[End of life (fixed)]]-Table157[[#This Row],[Start year]],Table268[Generic Lifetime]) -> 40 | J22: =IF(Table157[[#This Row],[Lifetime Option]]="fixed",Table157[[#This Row],[End of life (fixed)]],Table157[[#This Row],[Start year]]+Table268[Generic Lifetime]) -> 2040 | K22: 0.963
C23: CZ | D23: ENCZ_TEMELIN-2_00 | E23: 2002 | F23: 1.312848 | G23: generic | H23: =IF(Table157[[#This Row],[Lifetime Option]]="fixed",Table157[[#This Row],[End of life (fixed)]]-Table157[[#This Row],[Start year]],Table268[Generic Lifetime]) -> 40 | J23: =IF(Table157[[#This Row],[Lifetime Option]]="fixed",Table157[[#This Row],[End of life (fixed)]],Table157[[#This Row],[Start year]]+Table268[Generic Lifetime]) -> 2042 | K23: 0.963
C24: DE | D24: ENDE_BIBLIS-A_00 | E24: 1974 | F24: 0.940896 | G24: fixed | H24: =IF(Table157[[#This Row],[Lifetime Option]]="fixed",Table157[[#This Row],[End of life (fixed)]]-Table157[[#This Row],[Start year]],Table268[Generic Lifetime]) -> 37 | I24: 2011 | J24: =IF(Table157[[#This Row],[Lifetime Option]]="fixed",Table157[[#This Row],[End of life (fixed)]],Table157[[#This Row],[Start year]]+Table268[Generic Lifetime]) -> 2011 | K24: 1.167 | L24: closed
C25: DE | D25: ENDE_BIBLIS-B_00 | E25: 1976 | F25: 0.940896 | G25: fixed | H25: =IF(Table157[[#This Row],[Lifetime Option]]="fixed",Table157[[#This Row],[End of life (fixed)]]-Table157[[#This Row],[Start year]],Table268[Generic Lifetime]) -> 35 | I25: 2011 | J25: =IF(Table157[[#This Row],[Lifetime Option]]="fixed",Table157[[#This Row],[End of life (fixed)]],Table157[[#This Row],[Start year]]+Table268[Generic Lifetime]) -> 2011 | K25: 1.24 | L25: closed
C26: DE | D26: ENDE_BROKDORF_KBR_00 | E26: 1986 | F26: 1.1147815 | G26: fixed | H26: =IF(Table157[[#This Row],[Lifetime Option]]="fixed",Table157[[#This Row],[End of life (fixed)]]-Table157[[#This Row],[Start year]],Table268[Generic Lifetime]) -> 35 | I26: 2021 | J26: =IF(Table157[[#This Row],[Lifetime Option]]="fixed",Table157[[#This Row],[End of life (fixed)]],Table157[[#This Row],[Start year]]+Table268[Generic Lifetime]) -> 2021 | K26: 1.41
C27: DE | D27: ENDE_BRUNSBUETTEL_00 | E27: 1976 | F27: 0.912384 | G27: fixed | H27: =IF(Table157[[#This Row],[Lifetime Option]]="fixed",Table157[[#This Row],[End of life (fixed)]]-Table157[[#This Row],[Start year]],Table268[Generic Lifetime]) -> 35 | I27: 2011 | J27: =IF(Table157[[#This Row],[Lifetime Option]]="fixed",Table157[[#This Row],[End of life (fixed)]],Table157[[#This Row],[Start year]]+Table268[Generic Lifetime]) -> 2011 | K27: 0.771 | L27: closed
C28: DE | D28: ENDE_EMSLAND_KKE_00 | E28: 1988 | F28: 1.0053818 | G28: fixed | H28: =IF(Table157[[#This Row],[Lifetime Option]]="fixed",Table157[[#This Row],[End of life (fixed)]]-Table157[[#This Row],[Start year]],Table268[Generic Lifetime]) -> 34 | I28: 2022 | J28: =IF(Table157[[#This Row],[Lifetime Option]]="fixed",Table157[[#This Row],[End of life (fixed)]],Table157[[#This Row],[Start year]]+Table268[Generic Lifetime]) -> 2022 | K28: 1.335 | M28: capacity according to operator website
C29: DE | D29: ENDE_GRAFENRHEINFELD_KKG_00 | E29: 1981 | F29: 1.0494215 | G29: fixed | H29: =IF(Table157[[#This Row],[Lifetime Option]]="fixed",Table157[[#This Row],[End of life (fixed)]]-Table157[[#This Row],[Start year]],Table268[Generic Lifetime]) -> 34 | I29: 2015 | J29: =IF(Table157[[#This Row],[Lifetime Option]]="fixed",Table157[[#This Row],[End of life (fixed)]],Table157[[#This Row],[Start year]]+Table268[Generic Lifetime]) -> 2015 | K29: 1.275 | L29: closed
C30: DE | D30: ENDE_GROHNDE_KWG_00 | E30: 1984 | F30: 1.07712 | G30: fixed | H30: =IF(Table157[[#This Row],[Lifetime Option]]="fixed",Table157[[#This Row],[End of life (fixed)]]-Table157[[#This Row],[Start year]],Table268[Generic Lifetime]) -> 37 | I30: 2021 | J30: =IF(Table157[[#This Row],[Lifetime Option]]="fixed",Table157[[#This Row],[End of life (fixed)]],Table157[[#This Row],[Start year]]+Table268[Generic Lifetime]) -> 2021 | K30: 1.36
C31: DE | D31: ENDE_GUNDREM-B_GUN-B_00 | E31: 1984 | F31: 0.8316 | G31: fixed | H31: =IF(Table157[[#This Row],[Lifetime Option]]="fixed",Table157[[#This Row],[End of life (fixed)]]-Table157[[#This Row],[Start year]],Table268[Generic Lifetime]) -> 33 | I31: 2017 | J31: =IF(Table157[[#This Row],[Lifetime Option]]="fixed",Table157[[#This Row],[End of life (fixed)]],Table157[[#This Row],[Start year]]+Table268[Generic Lifetime]) -> 2017 | K31: 1.284
C32: DE | D32: ENDE_GUNDREM-C_GUN-C_00 | E32: 1984 | F32: 0.8316 | G32: fixed | H32: =IF(Table157[[#This Row],[Lifetime Option]]="fixed",Table157[[#This Row],[End of life (fixed)]]-Table157[[#This Row],[Start year]],Table268[Generic Lifetime]) -> 37 | I32: 2021 | J32: =IF(Table157[[#This Row],[Lifetime Option]]="fixed",Table157[[#This Row],[End of life (fixed)]],Table157[[#This Row],[Start year]]+Table268[Generic Lifetime]) -> 2021 | K32: 1.288
C33: DE | D33: ENDE_ISAR-1_00 | E33: 1988 | F33: 1.28304 | G33: fixed | H33: =IF(Table157[[#This Row],[Lifetime Option]]="fixed",Table157[[#This Row],[End of life (fixed)]]-Table157[[#This Row],[Start year]],Table268[Generic Lifetime]) -> 23 | I33: 2011 | J33: =IF(Table157[[#This Row],[Lifetime Option]]="fixed",Table157[[#This Row],[End of life (fixed)]],Table157[[#This Row],[Start year]]+Table268[Generic Lifetime]) -> 2011 | K33: 0.878 | L33: closed
C34: DE | D34: ENDE_ISAR-2_KKI2_00 | E34: 1988 | F34: 1.0394248 | G34: fixed | H34: =IF(Table157[[#This Row],[Lifetime Option]]="fixed",Table157[[#This Row],[End of life (fixed)]]-Table157[[#This Row],[Start year]],Table268[Generic Lifetime]) -> 34 | I34: 2022 | J34: =IF(Table157[[#This Row],[Lifetime Option]]="fixed",Table157[[#This Row],[End of life (fixed)]],Table157[[#This Row],[Start year]]+Table268[Generic Lifetime]) -> 2022 | K34: 1.41
C35: DE | D35: ENDE_KRUEMMEL_00 | E35: 1983 | F35: 0.912384 | G35: fixed | H35: =IF(Table157[[#This Row],[Lifetime Option]]="fixed",Table157[[#This Row],[End of life (fixed)]]-Table157[[#This Row],[Start year]],Table268[Generic Lifetime]) -> 28 | I35: 2011 | J35: =IF(Table157[[#This Row],[Lifetime Option]]="fixed",Table157[[#This Row],[End of life (fixed)]],Table157[[#This Row],[Start year]]+Table268[Generic Lifetime]) -> 2011 | K35: 1.26
C36: DE | D36: ENDE_NECKARWEST-2_GKN2_00 | E36: 1989 | F36: 1.4452364 | G36: fixed | H36: =IF(Table157[[#This Row],[Lifetime Option]]="fixed",Table157[[#This Row],[End of life (fixed)]]-Table157[[#This Row],[Start year]],Table268[Generic Lifetime]) -> 33 | I36: 2022 | J36: =IF(Table157[[#This Row],[Lifetime Option]]="fixed",Table157[[#This Row],[End of life (fixed)]],Table157[[#This Row],[Start year]]+Table268[Generic Lifetime]) -> 2022 | K36: 1.31
C37: DE | D37: ENDE_NECKARWESTHEIM-1_00 | E37: 1976 | F37: 1.0463904 | G37: fixed | H37: =IF(Table157[[#This Row],[Lifetime Option]]="fixed",Table157[[#This Row],[End of life (fixed)]]-Table157[[#This Row],[Start year]],Table268[Generic Lifetime]) -> 35 | I37: 2011 | J37: =IF(Table157[[#This Row],[Lifetime Option]]="fixed",Table157[[#This Row],[End of life (fixed)]],Table157[[#This Row],[Start year]]+Table268[Generic Lifetime]) -> 2011 | K37: 0.785 | L37: closed
C38: DE | D38: ENDE_PHILIPPSBURG-1_00 | E38: 1979 | F38: 1.1376288 | G38: fixed | H38: =IF(Table157[[#This Row],[Lifetime Option]]="fixed",Table157[[#This Row],[End of life (fixed)]]-Table157[[#This Row],[Start year]],Table268[Generic Lifetime]) -> 32 | I38: 2011 | J38: =IF(Table157[[#This Row],[Lifetime Option]]="fixed",Table157[[#This Row],[End of life (fixed)]],Table157[[#This Row],[Start year]]+Table268[Generic Lifetime]) -> 2011 | K38: 0.89 | L38: closed
C39: DE | D39: ENDE_PHILIPPSBURG-2_KKP2_00 | E39: 1984 | F39: 1.0596358 | G39: fixed | H39: =IF(Table157[[#This Row],[Lifetime Option]]="fixed",Table157[[#This Row],[End of life (fixed)]]-Table157[[#This Row],[Start year]],Table268[Generic Lifetime]) -> 35 | I39: 2019 | J39: =IF(Table157[[#This Row],[Lifetime Option]]="fixed",Table157[[#This Row],[End of life (fixed)]],Table157[[#This Row],[Start year]]+Table268[Generic Lifetime]) -> 2019 | K39: 1.402
C40: DE | D40: ENDE_UNTERWESER_00 | E40: 1978 | F40: 1.0093248 | G40: fixed | H40: =IF(Table157[[#This Row],[Lifetime Option]]="fixed",Table157[[#This Row],[End of life (fixed)]]-Table157[[#This Row],[Start year]],Table268[Generic Lifetime]) -> 33 | I40: 2011 | J40: =IF(Table157[[#This Row],[Lifetime Option]]="fixed",Table157[[#This Row],[End of life (fixed)]],Table157[[#This Row],[Start year]]+Table268[Generic Lifetime]) -> 2011 | K40: 1.345 | L40: closed
...

Sheet Existing plants_SCEN50yrs
A1: Generic Lifetime | C1: Member State | D1: Process | E1: Start year | F1: Efficiency PJ/tU | G1: Lifetime Option | H1: Tlife yrs | I1: End of life (fixed) | J1: End of life | K1: Existing capacity GW | L1: Comments | M1: Source
A2: 50 | C2: BE | D2: ENBE_DOEL-1_00 | E2: 1974 | F2: 1.3464165 | G2: fixed | H2: =IF(Table15[[#This Row],[Lifetime Option]]="fixed",Table15[[#This Row],[End of life (fixed)]]-Table15[[#This Row],[Start year]],Table26[Generic Lifetime]) -> 51 | I2: 2025 | J2: =IF(Table15[[#This Row],[Lifetime Option]]="fixed",Table15[[#This Row],[End of life (fixed)]],Table15[[#This Row],[Start year]]+Table26[Generic Lifetime]) -> 2025 | K2: 0.433 | M2: http://www.engie.com/en/journalists/press-releases/agreement-conditions-extending-doel-1-doel-2-new-nuclear-contribution-system/
C3: BE | D3: ENBE_DOEL-2_00 | E3: 1975 | F3: 1.3464165 | G3: fixed | H3: =IF(Table15[[#This Row],[Lifetime Option]]="fixed",Table15[[#This Row],[End of life (fixed)]]-Table15[[#This Row],[Start year]],Table26[Generic Lifetime]) -> 50 | I3: 2025 | J3: =IF(Table15[[#This Row],[Lifetime Option]]="fixed",Table15[[#This Row],[End of life (fixed)]],Table15[[#This Row],[Start year]]+Table26[Generic Lifetime]) -> 2025 | K3: 0.433 | M3: http://www.engie.com/en/journalists/press-releases/agreement-conditions-extending-doel-1-doel-2-new-nuclear-contribution-system/
C4: BE | D4: ENBE_DOEL-3_00 | E4: 1982 | F4: 1.4638774 | G4: fixed | H4: =IF(Table15[[#This Row],[Lifetime Option]]="fixed",Table15[[#This Row],[End of life (fixed)]]-Table15[[#This Row],[Start year]],Table26[Generic Lifetime]) -> 40 | I4: 2022 | J4: =IF(Table15[[#This Row],[Lifetime Option]]="fixed",Table15[[#This Row],[End of life (fixed)]],Table15[[#This Row],[Start year]]+Table26[Generic Lifetime]) -> 2022 | K4: 1.006 | L4: uncertain - follow up | M4: http://www.fanc.fgov.be/nl/news/doel-3/tihange-2-next-steps-of-the-review-process/766.aspx
C5: BE | D5: ENBE_DOEL-4_00 | E5: 1985 | F5: 1.4183133 | G5: fixed | H5: =IF(Table15[[#This Row],[Lifetime Option]]="fixed",Table15[[#This Row],[End of life (fixed)]]-Table15[[#This Row],[Start year]],Table26[Generic Lifetime]) -> 40 | I5: 2025 | J5: =IF(Table15[[#This Row],[Lifetime Option]]="fixed",Table15[[#This Row],[End of life (fixed)]],Table15[[#This Row],[Start year]]+Table26[Generic Lifetime]) -> 2025 | K5: 1.039
C6: BE | D6: ENBE_TIHANGE-1_00 | E6: 1975 | F6: 1.3654688 | G6: fixed | H6: =IF(Table15[[#This Row],[Lifetime Option]]="fixed",Table15[[#This Row],[End of life (fixed)]]-Table15[[#This Row],[Start year]],Table26[Generic Lifetime]) -> 50 | I6: 2025 | J6: =IF(Table15[[#This Row],[Lifetime Option]]="fixed",Table15[[#This Row],[End of life (fixed)]],Table15[[#This Row],[Start year]]+Table26[Generic Lifetime]) -> 2025 | K6: 0.962 | M6: http://economie.fgov.be/fr/consommateurs/Energie/Nucleaire/centrales_nucleaires/sortie_nucleaire/#.Vdb00Y7DVE4
C7: BE | D7: ENBE_TIHANGE-2_00 | E7: 1982 | F7: 1.3387206 | G7: fixed | H7: =IF(Table15[[#This Row],[Lifetime Option]]="fixed",Table15[[#This Row],[End of life (fixed)]]-Table15[[#This Row],[Start year]],Table26[Generic Lifetime]) -> 40 | I7: 2022 | J7: =IF(Table15[[#This Row],[Lifetime Option]]="fixed",Table15[[#This Row],[End of life (fixed)]],Table15[[#This Row],[Start year]]+Table26[Generic Lifetime]) -> 2022 | K7: 1.008 | L7: uncertain - follow up | M7: http://www.fanc.fgov.be/nl/news/doel-3/tihange-2-next-steps-of-the-review-process/766.aspx
C8: BE | D8: ENBE_TIHANGE-3_00 | E8: 1985 | F8: 1.417824 | G8: fixed | H8: =IF(Table15[[#This Row],[Lifetime Option]]="fixed",Table15[[#This Row],[End of life (fixed)]]-Table15[[#This Row],[Start year]],Table26[Generic Lifetime]) -> 40 | I8: 2025 | J8: =IF(Table15[[#This Row],[Lifetime Option]]="fixed",Table15[[#This Row],[End of life (fixed)]],Table15[[#This Row],[Start year]]+Table26[Generic Lifetime]) -> 2025 | K8: 1.046
C9: BG | D9: ENBG_KOZLODUY-3_00 | E9: 1980 | F9: 0.77 | G9: fixed | H9: =IF(Table15[[#This Row],[Lifetime Option]]="fixed",Table15[[#This Row],[End of life (fixed)]]-Table15[[#This Row],[Start year]],Table26[Generic Lifetime]) -> 26 | I9: 2006 | J9: =IF(Table15[[#This Row],[Lifetime Option]]="fixed",Table15[[#This Row],[End of life (fixed)]],Table15[[#This Row],[Start year]]+Table26[Generic Lifetime]) -> 2006 | K9: 0.408 | L9: closed
C10: BG | D10: ENBG_KOZLODUY-4_00 | E10: 1982 | F10: 0.77 | G10: fixed | H10: =IF(Table15[[#This Row],[Lifetime Option]]="fixed",Table15[[#This Row],[End of life (fixed)]]-Table15[[#This Row],[Start year]],Table26[Generic Lifetime]) -> 24 | I10: 2006 | J10: =IF(Table15[[#This Row],[Lifetime Option]]="fixed",Table15[[#This Row],[End of life (fixed)]],Table15[[#This Row],[Start year]]+Table26[Generic Lifetime]) -> 2006 | K10: 0.408 | L10: closed
C11: BG | D11: ENBG_KOZLODUY-5_00 | E11: 1987 | F11: 0.7776 | G11: generic | H11: =IF(Table15[[#This Row],[Lifetime Option]]="fixed",Table15[[#This Row],[End of life (fixed)]]-Table15[[#This Row],[Start year]],Table26[Generic Lifetime]) -> 50 | J11: =IF(Table15[[#This Row],[Lifetime Option]]="fixed",Table15[[#This Row],[End of life (fixed)]],Table15[[#This Row],[Start year]]+Table26[Generic Lifetime]) -> 2037 | K11: 0.953 | M11: http://www.world-nuclear.org/info/Country-Profiles/Countries-A-F/Bulgaria/
C12: BG | D12: ENBG_KOZLODUY-6_00 | E12: 1991 | F12: 0.7776 | G12: generic | H12: =IF(Table15[[#This Row],[Lifetime Option]]="fixed",Table15[[#This Row],[End of life (fixed)]]-Table15[[#This Row],[Start year]],Table26[Generic Lifetime]) -> 50 | J12: =IF(Table15[[#This Row],[Lifetime Option]]="fixed",Table15[[#This Row],[End of life (fixed)]],Table15[[#This Row],[Start year]]+Table26[Generic Lifetime]) -> 2041 | K12: 0.953 | M12: http://www.world-nuclear.org/info/Country-Profiles/Countries-A-F/Bulgaria/
C13: CH | D13: ENCH_BEZNAU-1_00 | E13: 1969 | F13: 1.2203044 | G13: fixed | H13: =IF(Table15[[#This Row],[Lifetime Option]]="fixed",Table15[[#This Row],[End of life (fixed)]]-Table15[[#This Row],[Start year]],Table26[Generic Lifetime]) -> 50 | I13: 2019 | J13: =IF(Table15[[#This Row],[Lifetime Option]]="fixed",Table15[[#This Row],[End of life (fixed)]],Table15[[#This Row],[Start year]]+Table26[Generic Lifetime]) -> 2019 | K13: 0.365 | L13: need to follow up political developments | M13: http://www.world-nuclear.org/info/Country-Profiles/Countries-O-S/Switzerland/
C14: CH | D14: ENCH_BEZNAU-2_00 | E14: 1971 | F14: 1.2203044 | G14: fixed | H14: =IF(Table15[[#This Row],[Lifetime Option]]="fixed",Table15[[#This Row],[End of life (fixed)]]-Table15[[#This Row],[Start year]],Table26[Generic Lifetime]) -> 50 | I14: 2021 | J14: =IF(Table15[[#This Row],[Lifetime Option]]="fixed",Table15[[#This Row],[End of life (fixed)]],Table15[[#This Row],[Start year]]+Table26[Generic Lifetime]) -> 2021 | K14: 0.365 | L14: need to follow up political developments | M14: http://www.world-nuclear.org/info/Country-Profiles/Countries-O-S/Switzerland/
C15: CH | D15: ENCH_GOESGEN_00 | E15: 1979 | F15: 1.5489833 | G15: fixed | H15: =IF(Table15[[#This Row],[Lifetime Option]]="fixed",Table15[[#This Row],[End of life (fixed)]]-Table15[[#This Row],[Start year]],Table26[Generic Lifetime]) -> 50 | I15: 2029 | J15: =IF(Table15[[#This Row],[Lifetime Option]]="fixed",Table15[[#This Row],[End of life (fixed)]],Table15[[#This Row],[Start year]]+Table26[Generic Lifetime]) -> 2029 | K15: 0.985 | L15: need to follow up political developments | M15: http://www.world-nuclear.org/info/Country-Profiles/Countries-O-S/Switzerland/
C16: CH | D16: ENCH_LEIBSTADT_00 | E16: 1984 | F16: 1.28484 | G16: fixed | H16: =IF(Table15[[#This Row],[Lifetime Option]]="fixed",Table15[[#This Row],[End of life (fixed)]]-Table15[[#This Row],[Start year]],Table26[Generic Lifetime]) -> 50 | I16: 2034 | J16: =IF(Table15[[#This Row],[Lifetime Option]]="fixed",Table15[[#This Row],[End of life (fixed)]],Table15[[#This Row],[Start year]]+Table26[Generic Lifetime]) -> 2034 | K16: 1.22 | L16: need to follow up political developments | M16: http://www.world-nuclear.org/info/Country-Profiles/Countries-O-S/Switzerland/
C17: CH | D17: ENCH_MUEHLEBERG_00 | E17: 1971 | F17: 1.474392 | G17: fixed | H17: =IF(Table15[[#This Row],[Lifetime Option]]="fixed",Table15[[#This Row],[End of life (fixed)]]-Table15[[#This Row],[Start year]],Table26[Generic Lifetime]) -> 48 | I17: 2019 | J17: =IF(Table15[[#This Row],[Lifetime Option]]="fixed",Table15[[#This Row],[End of life (fixed)]],Table15[[#This Row],[Start year]]+Table26[Generic Lifetime]) -> 2019 | K17: 0.373 | L17: need to follow up political developments | M17: http://www.world-nuclear.org/info/Country-Profiles/Countries-O-S/Switzerland/
C18: CZ | D18: ENCZ_DUKOVANY-1_00 | E18: 1985 | F18: 1.2607488 | G18: generic | H18: =IF(Table15[[#This Row],[Lifetime Option]]="fixed",Table15[[#This Row],[End of life (fixed)]]-Table15[[#This Row],[Start year]],Table26[Generic Lifetime]) -> 50 | J18: =IF(Table15[[#This Row],[Lifetime Option]]="fixed",Table15[[#This Row],[End of life (fixed)]],Table15[[#This Row],[Start year]]+Table26[Generic Lifetime]) -> 2035 | K18: 0.468 | M18: http://www.oecd-nea.org/ndd/pubs/2014/7197-bb-2014.pdf
C19: CZ | D19: ENCZ_DUKOVANY-2_00 | E19: 1986 | F19: 1.2607488 | G19: generic | H19: =IF(Table15[[#This Row],[Lifetime Option]]="fixed",Table15[[#This Row],[End of life (fixed)]]-Table15[[#This Row],[Start year]],Table26[Generic Lifetime]) -> 50 | J19: =IF(Table15[[#This Row],[Lifetime Option]]="fixed",Table15[[#This Row],[End of life (fixed)]],Table15[[#This Row],[Start year]]+Table26[Generic Lifetime]) -> 2036 | K19: 0.471
C20: CZ | D20: ENCZ_DUKOVANY-3_00 | E20: 1986 | F20: 1.3110781 | G20: generic | H20: =IF(Table15[[#This Row],[Lifetime Option]]="fixed",Table15[[#This Row],[End of life (fixed)]]-Table15[[#This Row],[Start year]],Table26[Generic Lifetime]) -> 50 | J20: =IF(Table15[[#This Row],[Lifetime Option]]="fixed",Table15[[#This Row],[End of life (fixed)]],Table15[[#This Row],[Start year]]+Table26[Generic Lifetime]) -> 2036 | K20: 0.468
C21: CZ | D21: ENCZ_DUKOVANY-4_00 | E21: 1987 | F21: 1.2607488 | G21: generic | H21: =IF(Table15[[#This Row],[Lifetime Option]]="fixed",Table15[[#This Row],[End of life (fixed)]]-Table15[[#This Row],[Start year]],Table26[Generic Lifetime]) -> 50 | J21: =IF(Table15[[#This Row],[Lifetime Option]]="fixed",Table15[[#This Row],[End of life (fixed)]],Table15[[#This Row],[Start year]]+Table26[Generic Lifetime]) -> 2037 | K21: 0.471
C22: CZ | D22: ENCZ_TEMELIN-1_00 | E22: 2000 | F22: 1.312848 | G22: generic | H22: =IF(Table15[[#This Row],[Lifetime Option]]="fixed",Table15[[#This Row],[End of life (fixed)]]-Table15[[#This Row],[Start year]],Table26[Generic Lifetime]) -> 50 | J22: =IF(Table15[[#This Row],[Lifetime Option]]="fixed",Table15[[#This Row],[End of life (fixed)]],Table15[[#This Row],[Start year]]+Table26[Generic Lifetime]) -> 2050 | K22: 0.963
C23: CZ | D23: ENCZ_TEMELIN-2_00 | E23: 2002 | F23: 1.312848 | G23: generic | H23: =IF(Table15[[#This Row],[Lifetime Option]]="fixed",Table15[[#This Row],[End of life (fixed)]]-Table15[[#This Row],[Start year]],Table26[Generic Lifetime]) -> 50 | J23: =IF(Table15[[#This Row],[Lifetime Option]]="fixed",Table15[[#This Row],[End of life (fixed)]],Table15[[#This Row],[Start year]]+Table26[Generic Lifetime]) -> 2052 | K23: 0.963
C24: DE | D24: ENDE_BIBLIS-A_00 | E24: 1974 | F24: 0.940896 | G24: fixed | H24: =IF(Table15[[#This Row],[Lifetime Option]]="fixed",Table15[[#This Row],[End of life (fixed)]]-Table15[[#This Row],[Start year]],Table26[Generic Lifetime]) -> 37 | I24: 2011 | J24: =IF(Table15[[#This Row],[Lifetime Option]]="fixed",Table15[[#This Row],[End of life (fixed)]],Table15[[#This Row],[Start year]]+Table26[Generic Lifetime]) -> 2011 | K24: 1.167 | L24: closed
C25: DE | D25: ENDE_BIBLIS-B_00 | E25: 1976 | F25: 0.940896 | G25: fixed | H25: =IF(Table15[[#This Row],[Lifetime Option]]="fixed",Table15[[#This Row],[End of life (fixed)]]-Table15[[#This Row],[Start year]],Table26[Generic Lifetime]) -> 35 | I25: 2011 | J25: =IF(Table15[[#This Row],[Lifetime Option]]="fixed",Table15[[#This Row],[End of life (fixed)]],Table15[[#This Row],[Start year]]+Table26[Generic Lifetime]) -> 2011 | K25: 1.24 | L25: closed
C26: DE | D26: ENDE_BROKDORF_KBR_00 | E26: 1986 | F26: 1.1147815 | G26: fixed | H26: =IF(Table15[[#This Row],[Lifetime Option]]="fixed",Table15[[#This Row],[End of life (fixed)]]-Table15[[#This Row],[Start year]],Table26[Generic Lifetime]) -> 35 | I26: 2021 | J26: =IF(Table15[[#This Row],[Lifetime Option]]="fixed",Table15[[#This Row],[End of life (fixed)]],Table15[[#This Row],[Start year]]+Table26[Generic Lifetime]) -> 2021 | K26: 1.41
C27: DE | D27: ENDE_BRUNSBUETTEL_00 | E27: 1976 | F27: 0.912384 | G27: fixed | H27: =IF(Table15[[#This Row],[Lifetime Option]]="fixed",Table15[[#This Row],[End of life (fixed)]]-Table15[[#This Row],[Start year]],Table26[Generic Lifetime]) -> 35 | I27: 2011 | J27: =IF(Table15[[#This Row],[Lifetime Option]]="fixed",Table15[[#This Row],[End of life (fixed)]],Table15[[#This Row],[Start year]]+Table26[Generic Lifetime]) -> 2011 | K27: 0.771 | L27: closed
C28: DE | D28: ENDE_EMSLAND_KKE_00 | E28: 1988 | F28: 1.0053818 | G28: fixed | H28: =IF(Table15[[#This Row],[Lifetime Option]]="fixed",Table15[[#This Row],[End of life (fixed)]]-Table15[[#This Row],[Start year]],Table26[Generic Lifetime]) -> 34 | I28: 2022 | J28: =IF(Table15[[#This Row],[Lifetime Option]]="fixed",Table15[[#This Row],[End of life (fixed)]],Table15[[#This Row],[Start year]]+Table26[Generic Lifetime]) -> 2022 | K28: 1.335 | M28: capacity according to operator website
C29: DE | D29: ENDE_GRAFENRHEINFELD_KKG_00 | E29: 1981 | F29: 1.0494215 | G29: fixed | H29: =IF(Table15[[#This Row],[Lifetime Option]]="fixed",Table15[[#This Row],[End of life (fixed)]]-Table15[[#This Row],[Start year]],Table26[Generic Lifetime]) -> 34 | I29: 2015 | J29: =IF(Table15[[#This Row],[Lifetime Option]]="fixed",Table15[[#This Row],[End of life (fixed)]],Table15[[#This Row],[Start year]]+Table26[Generic Lifetime]) -> 2015 | K29: 1.275 | L29: closed
C30: DE | D30: ENDE_GROHNDE_KWG_00 | E30: 1984 | F30: 1.07712 | G30: fixed | H30: =IF(Table15[[#This Row],[Lifetime Option]]="fixed",Table15[[#This Row],[End of life (fixed)]]-Table15[[#This Row],[Start year]],Table26[Generic Lifetime]) -> 37 | I30: 2021 | J30: =IF(Table15[[#This Row],[Lifetime Option]]="fixed",Table15[[#This Row],[End of life (fixed)]],Table15[[#This Row],[Start year]]+Table26[Generic Lifetime]) -> 2021 | K30: 1.36
C31: DE | D31: ENDE_GUNDREM-B_GUN-B_00 | E31: 1984 | F31: 0.8316 | G31: fixed | H31: =IF(Table15[[#This Row],[Lifetime Option]]="fixed",Table15[[#This Row],[End of life (fixed)]]-Table15[[#This Row],[Start year]],Table26[Generic Lifetime]) -> 33 | I31: 2017 | J31: =IF(Table15[[#This Row],[Lifetime Option]]="fixed",Table15[[#This Row],[End of life (fixed)]],Table15[[#This Row],[Start year]]+Table26[Generic Lifetime]) -> 2017 | K31: 1.284
C32: DE | D32: ENDE_GUNDREM-C_GUN-C_00 | E32: 1984 | F32: 0.8316 | G32: fixed | H32: =IF(Table15[[#This Row],[Lifetime Option]]="fixed",Table15[[#This Row],[End of life (fixed)]]-Table15[[#This Row],[Start year]],Table26[Generic Lifetime]) -> 37 | I32: 2021 | J32: =IF(Table15[[#This Row],[Lifetime Option]]="fixed",Table15[[#This Row],[End of life (fixed)]],Table15[[#This Row],[Start year]]+Table26[Generic Lifetime]) -> 2021 | K32: 1.288
C33: DE | D33: ENDE_ISAR-1_00 | E33: 1988 | F33: 1.28304 | G33: fixed | H33: =IF(Table15[[#This Row],[Lifetime Option]]="fixed",Table15[[#This Row],[End of life (fixed)]]-Table15[[#This Row],[Start year]],Table26[Generic Lifetime]) -> 23 | I33: 2011 | J33: =IF(Table15[[#This Row],[Lifetime Option]]="fixed",Table15[[#This Row],[End of life (fixed)]],Table15[[#This Row],[Start year]]+Table26[Generic Lifetime]) -> 2011 | K33: 0.878 | L33: closed
C34: DE | D34: ENDE_ISAR-2_KKI2_00 | E34: 1988 | F34: 1.0394248 | G34: fixed | H34: =IF(Table15[[#This Row],[Lifetime Option]]="fixed",Table15[[#This Row],[End of life (fixed)]]-Table15[[#This Row],[Start year]],Table26[Generic Lifetime]) -> 34 | I34: 2022 | J34: =IF(Table15[[#This Row],[Lifetime Option]]="fixed",Table15[[#This Row],[End of life (fixed)]],Table15[[#This Row],[Start year]]+Table26[Generic Lifetime]) -> 2022 | K34: 1.41
C35: DE | D35: ENDE_KRUEMMEL_00 | E35: 1983 | F35: 0.912384 | G35: fixed | H35: =IF(Table15[[#This Row],[Lifetime Option]]="fixed",Table15[[#This Row],[End of life (fixed)]]-Table15[[#This Row],[Start year]],Table26[Generic Lifetime]) -> 28 | I35: 2011 | J35: =IF(Table15[[#This Row],[Lifetime Option]]="fixed",Table15[[#This Row],[End of life (fixed)]],Table15[[#This Row],[Start year]]+Table26[Generic Lifetime]) -> 2011 | K35: 1.26
C36: DE | D36: ENDE_NECKARWEST-2_GKN2_00 | E36: 1989 | F36: 1.4452364 | G36: fixed | H36: =IF(Table15[[#This Row],[Lifetime Option]]="fixed",Table15[[#This Row],[End of life (fixed)]]-Table15[[#This Row],[Start year]],Table26[Generic Lifetime]) -> 33 | I36: 2022 | J36: =IF(Table15[[#This Row],[Lifetime Option]]="fixed",Table15[[#This Row],[End of life (fixed)]],Table15[[#This Row],[Start year]]+Table26[Generic Lifetime]) -> 2022 | K36: 1.31
C37: DE | D37: ENDE_NECKARWESTHEIM-1_00 | E37: 1976 | F37: 1.0463904 | G37: fixed | H37: =IF(Table15[[#This Row],[Lifetime Option]]="fixed",Table15[[#This Row],[End of life (fixed)]]-Table15[[#This Row],[Start year]],Table26[Generic Lifetime]) -> 35 | I37: 2011 | J37: =IF(Table15[[#This Row],[Lifetime Option]]="fixed",Table15[[#This Row],[End of life (fixed)]],Table15[[#This Row],[Start year]]+Table26[Generic Lifetime]) -> 2011 | K37: 0.785 | L37: closed
C38: DE | D38: ENDE_PHILIPPSBURG-1_00 | E38: 1979 | F38: 1.1376288 | G38: fixed | H38: =IF(Table15[[#This Row],[Lifetime Option]]="fixed",Table15[[#This Row],[End of life (fixed)]]-Table15[[#This Row],[Start year]],Table26[Generic Lifetime]) -> 32 | I38: 2011 | J38: =IF(Table15[[#This Row],[Lifetime Option]]="fixed",Table15[[#This Row],[End of life (fixed)]],Table15[[#This Row],[Start year]]+Table26[Generic Lifetime]) -> 2011 | K38: 0.89 | L38: closed
C39: DE | D39: ENDE_PHILIPPSBURG-2_KKP2_00 | E39: 1984 | F39: 1.0596358 | G39: fixed | H39: =IF(Table15[[#This Row],[Lifetime Option]]="fixed",Table15[[#This Row],[End of life (fixed)]]-Table15[[#This Row],[Start year]],Table26[Generic Lifetime]) -> 35 | I39: 2019 | J39: =IF(Table15[[#This Row],[Lifetime Option]]="fixed",Table15[[#This Row],[End of life (fixed)]],Table15[[#This Row],[Start year]]+Table26[Generic Lifetime]) -> 2019 | K39: 1.402
C40: DE | D40: ENDE_UNTERWESER_00 | E40: 1978 | F40: 1.0093248 | G40: fixed | H40: =IF(Table15[[#This Row],[Lifetime Option]]="fixed",Table15[[#This Row],[End of life (fixed)]]-Table15[[#This Row],[Start year]],Table26[Generic Lifetime]) -> 33 | I40: 2011 | J40: =IF(Table15[[#This Row],[Lifetime Option]]="fixed",Table15[[#This Row],[End of life (fixed)]],Table15[[#This Row],[Start year]]+Table26[Generic Lifetime]) -> 2011 | K40: 1.345 | L40: closed
...

Sheet Existing plants_SCEN60yrs
A1: Generic Lifetime | C1: Member State | D1: Process | E1: Start year | F1: Efficiency PJ/tU | G1: Lifetime Option | H1: Tlife yrs | I1: End of life (fixed) | J1: End of life | K1: Existing capacity GW | L1: Comments | M1: Source
A2: 60 | C2: BE | D2: ENBE_DOEL-1_00 | E2: 1974 | F2: 1.3464165 | G2: fixed | H2: =IF(Table1[[#This Row],[Lifetime Option]]="fixed",Table1[[#This Row],[End of life (fixed)]]-Table1[[#This Row],[Start year]],Table2[Generic Lifetime]) -> 51 | I2: 2025 | J2: =IF(Table1[[#This Row],[Lifetime Option]]="fixed",Table1[[#This Row],[End of life (fixed)]],Table1[[#This Row],[Start year]]+Table2[Generic Lifetime]) -> 2025 | K2: 0.433 | M2: http://www.engie.com/en/journalists/press-releases/agreement-conditions-extending-doel-1-doel-2-new-nuclear-contribution-system/
C3: BE | D3: ENBE_DOEL-2_00 | E3: 1975 | F3: 1.3464165 | G3: fixed | H3: =IF(Table1[[#This Row],[Lifetime Option]]="fixed",Table1[[#This Row],[End of life (fixed)]]-Table1[[#This Row],[Start year]],Table2[Generic Lifetime]) -> 50 | I3: 2025 | J3: =IF(Table1[[#This Row],[Lifetime Option]]="fixed",Table1[[#This Row],[End of life (fixed)]],Table1[[#This Row],[Start year]]+Table2[Generic Lifetime]) -> 2025 | K3: 0.433 | M3: http://www.engie.com/en/journalists/press-releases/agreement-conditions-extending-doel-1-doel-2-new-nuclear-contribution-system/
C4: BE | D4: ENBE_DOEL-3_00 | E4: 1982 | F4: 1.4638774 | G4: fixed | H4: =IF(Table1[[#This Row],[Lifetime Option]]="fixed",Table1[[#This Row],[End of life (fixed)]]-Table1[[#This Row],[Start year]],Table2[Generic Lifetime]) -> 40 | I4: 2022 | J4: =IF(Table1[[#This Row],[Lifetime Option]]="fixed",Table1[[#This Row],[End of life (fixed)]],Table1[[#This Row],[Start year]]+Table2[Generic Lifetime]) -> 2022 | K4: 1.006 | L4: uncertain - follow up | M4: http://www.fanc.fgov.be/nl/news/doel-3/tihange-2-next-steps-of-the-review-process/766.aspx
C5: BE | D5: ENBE_DOEL-4_00 | E5: 1985 | F5: 1.4183133 | G5: fixed | H5: =IF(Table1[[#This Row],[Lifetime Option]]="fixed",Table1[[#This Row],[End of life (fixed)]]-Table1[[#This Row],[Start year]],Table2[Generic Lifetime]) -> 40 | I5: 2025 | J5: =IF(Table1[[#This Row],[Lifetime Option]]="fixed",Table1[[#This Row],[End of life (fixed)]],Table1[[#This Row],[Start year]]+Table2[Generic Lifetime]) -> 2025 | K5: 1.039
C6: BE | D6: ENBE_TIHANGE-1_00 | E6: 1975 | F6: 1.3654688 | G6: fixed | H6: =IF(Table1[[#This Row],[Lifetime Option]]="fixed",Table1[[#This Row],[End of life (fixed)]]-Table1[[#This Row],[Start year]],Table2[Generic Lifetime]) -> 50 | I6: 2025 | J6: =IF(Table1[[#This Row],[Lifetime Option]]="fixed",Table1[[#This Row],[End of life (fixed)]],Table1[[#This Row],[Start year]]+Table2[Generic Lifetime]) -> 2025 | K6: 0.962 | M6: http://economie.fgov.be/fr/consommateurs/Energie/Nucleaire/centrales_nucleaires/sortie_nucleaire/#.Vdb00Y7DVE4
C7: BE | D7: ENBE_TIHANGE-2_00 | E7: 1982 | F7: 1.3387206 | G7: fixed | H7: =IF(Table1[[#This Row],[Lifetime Option]]="fixed",Table1[[#This Row],[End of life (fixed)]]-Table1[[#This Row],[Start year]],Table2[Generic Lifetime]) -> 40 | I7: 2022 | J7: =IF(Table1[[#This Row],[Lifetime Option]]="fixed",Table1[[#This Row],[End of life (fixed)]],Table1[[#This Row],[Start year]]+Table2[Generic Lifetime]) -> 2022 | K7: 1.008 | L7: uncertain - follow up | M7: http://www.fanc.fgov.be/nl/news/doel-3/tihange-2-next-steps-of-the-review-process/766.aspx
C8: BE | D8: ENBE_TIHANGE-3_00 | E8: 1985 | F8: 1.417824 | G8: fixed | H8: =IF(Table1[[#This Row],[Lifetime Option]]="fixed",Table1[[#This Row],[End of life (fixed)]]-Table1[[#This Row],[Start year]],Table2[Generic Lifetime]) -> 40 | I8: 2025 | J8: =IF(Table1[[#This Row],[Lifetime Option]]="fixed",Table1[[#This Row],[End of life (fixed)]],Table1[[#This Row],[Start year]]+Table2[Generic Lifetime]) -> 2025 | K8: 1.046
