Workbook

Sheet Final Coeffs_ELC
A2: ~TFM_INS | O2: ETRI2014 data
A3: TimeSlice | B3: LimType | C3: Attribute | D3: Year | E3: Other_Indexes | F3: PSET_CI | G3: Pset_PN | H3: Pset_PD | I3: Cset_CN | J3: AllRegions | R3: Percentage | S3: Residual perecentage
C4: \I: FLO_EMIS | E4: ELCOIL | F4: ELCOIL | G4: EU*,PU*,CO* | H4: *seq*,*CCS* | I4: ELCCO2N | J4: 9.0405204 | L4: ELCCO2N is residual | O4: CCGT Advanced + CCS post combustion | P4: EUCCGASCCSpos20 | R4: 86 | S4: 14
C5: \I: FLO_EMIS | E5: ELCRFG | F5: ELCRFG | G5: EU*,PU*,CO* | H5: *seq*,*CCS* | I5: ELCCO2N | J5: 6.732 | O5: FB lignite + CCS post combustion | P5: EUPCCOLCCSpos20 | R5: 87 | S5: 13
C6: FLO_EMIS | E6: ELCDST | F6: ELCDST | G6: EU*,PU*,CO* | H6: *seq*,*CCS* | I6: ELCCO2N | J6: 8.8683982 | O6: SC PC + CCS post combustion | P6: EUPCCOHCCSpos20 | R6: 87 | S6: 13
C7: \I: FLO_EMIS | E7: ELCHFO | F7: ELCHFO | G7: EU*,PU*,CO* | H7: *seq*,*CCS* | I7: ELCCO2N | J7: 9.288 | O7: IGCC lignite + CCS pre combustion | P7: EUIGCOLCCSpre20 | R7: 89 | S7: 11
C8: FLO_EMIS | E8: ELCGAS | F8: ELCGAS | G8: EU*,PU*,CO* | H8: *seq*,*CCS* | I8: ELCCO2N | J8: 7.854 | O8: SC PC + CCS Oxyfuel | P8: EUPCCOHCCSoxy20 | R8: 90 | S8: 10
C9: \I: FLO_EMIS | E9: ELCDGS | F9: ELCDGS | G9: EU*,PU*,CO* | H9: *seq*,*CCS* | I9: ELCCO2N | J9: 12.984 | O9: IGCC + CCS pre combustion | P9: EUIGCOHCCSpre20 | R9: 88 | S9: 12
C10: FLO_EMIS | E10: ELCWOO | F10: ELCWOO | G10: EU*,PU*,CO* | H10: *seq*,*CCS* | I10: ELCCO2N | J10: -98.56
C11: \I: FLO_EMIS | E11: ELCBGS | F11: ELCBGS | G11: EU*,PU*,CO* | H11: *seq*,*CCS* | I11: ELCCO2N | J11: -84.304
C12: \I: FLO_EMIS | E12: ELCMUN | F12: ELCMUN | G12: EU*,PU*,CO* | H12: *seq*,*CCS* | I12: ELCCO2N | J12: 10.302
C13: \I: FLO_EMIS | E13: ELCSLU | F13: ELCSLU | G13: EU*,PU*,CO* | H13: *seq*,*CCS* | I13: ELCCO2N | J13: 10.302
C14: FLO_EMIS | E14: ELCOIL | F14: ELCOIL | G14: EU*,PU*,H*,CO* | H14: -*seq*,-*CCS* | I14: ELCCO2N | J14: 75.33767
C15: \I: FLO_EMIS | E15: ELCRFG | F15: ELCRFG | G15: EU*,PU*,H*,CO* | H15: -*seq*,-*CCS* | I15: ELCCO2N | J15: 56.1
C16: FLO_EMIS | E16: ELCDST | F16: ELCDST | G16: EU*,PU*,H*,CO* | H16: -*seq*,-*CCS* | I16: ELCCO2N | J16: 73.903318
C17: FLO_EMIS | E17: ELCHFO | F17: ELCHFO | G17: EU*,PU*,H*,CO* | H17: -*seq*,-*CCS* | I17: ELCCO2N | J17: 77.4
C18: FLO_EMIS | E18: ELCGAS | F18: ELCGAS | G18: EU*,PU*,H*,CO* | H18: -*seq*,-*CCS* | I18: ELCCO2N | J18: 56.1
C19: FLO_EMIS | E19: ELCDGS | F19: ELCDGS | G19: EU*,PU*,H*,CO* | H19: -*seq*,-*CCS* | I19: ELCCO2N | J19: 108.2
C20: FLO_EMIS | E20: ELCWOO | F20: ELCWOO | G20: EU*,PU*,H*,CO* | H20: -*seq*,-*CCS* | I20: ELCCO2N | J20: 0
C21: FLO_EMIS | E21: ELCBGS | F21: ELCBGS | G21: EU*,PU*,H*,CO* | H21: -*seq*,-*CCS* | I21: ELCCO2N | J21: 0
... C23: FLO_EMIS | E23: ELCSLU | F23: ELCSLU | G23: EU*,PU*,H*,CO* | H23: -*seq*,-*CCS* | I23: ELCCO2N | J23: 85.85
C24: FLO_EMIS | E24: ELCBFG | F24: ELCBFG | G24: EUSTIISGASCS101 | I24: ELCCO2N | J24: 34.32
C25: FLO_EMIS | E25: ELCBFT | F25: ELCBFT | G25: EUSTIISGASCS101 | I25: ELCCO2N | J25: 107.28
C26: FLO_EMIS | E26: ELCCOG | F26: ELCCOG | G26: EUSTIISGASCS101 | I26: ELCCO2N | J26: 5.4
C27: FLO_EMIS | E27: ELCIIS | F27: ELCIIS | G27: EUSTIISGASCS101 | I27: ELCCO2N | J27: 23.4
C28: FLO_EMIS | E28: ELCCOP | F28: ELCCOP | G28: EUSTIISGASCS101 | I28: ELCCO2N | J28: 14.64
C29: FLO_EMIS | E29: ELCBFG | F29: ELCBFG | G29: EUSTIISGAS101 | I29: ELCCO2N | J29: 286
C30: FLO_EMIS | E30: ELCBFT | F30: ELCBFT | G30: EUSTIISGAS101 | I30: ELCCO2N | J30: 894
C31: FLO_EMIS | E31: ELCCOG | F31: ELCCOG | G31: EUSTIISGAS101 | I31: ELCCO2N | J31: 45
C32: FLO_EMIS | E32: ELCIIS | F32: ELCIIS | G32: EUSTIISGAS101 | I32: ELCCO2N | J32: 195
C33: FLO_EMIS | E33: ELCCOP | F33: ELCCOP | G33: EUSTIISGAS101 | I33: ELCCO2N | J33: 122 | M33: these were before:
C34: \I: FLO_EMIS | E34: ELCOIL | F34: ELCOIL | G34: EU*,PU*,CO* | H34: *seq*,*CCS* | I34: SNKFCO2 | J34: 66.29715 | M34: ELCSCO2N
C35: \I: FLO_EMIS | E35: ELCRFG | F35: ELCRFG | G35: EU*,PU*,CO* | H35: *seq*,*CCS* | I35: SNKFCO2 | J35: 49.368 | M35: ELCSCO2N
C36: FLO_EMIS | E36: ELCDST | F36: ELCDST | G36: EU*,PU*,CO* | H36: *seq*,*CCS* | I36: SNKFCO2 | J36: 65.03492 | M36: ELCSCO2N
C37: \I: FLO_EMIS | E37: ELCHFO | F37: ELCHFO | G37: EU*,PU*,CO* | H37: *seq*,*CCS* | I37: SNKFCO2 | J37: 68.112 | M37: ELCSCO2N
C38: FLO_EMIS | E38: ELCGAS | F38: ELCGAS | G38: EU*,PU*,CO* | H38: *seq*,*CCS* | I38: SNKFCO2 | J38: 48.246 | M38: ELCSCO2N
C39: \I: FLO_EMIS | E39: ELCDGS | F39: ELCDGS | G39: EU*,PU*,CO* | H39: *seq*,*CCS* | I39: SNKFCO2 | J39: 95.216 | M39: ELCSCO2N
C40: FLO_EMIS | E40: ELCWOO | F40: ELCWOO | G40: EU*,PU*,CO* | H40: *seq*,*CCS* | I40: ELCSCO2N | J40: 98.56 | M40: ELCSCO2N
C41: \I: FLO_EMIS | E41: ELCBGS | F41: ELCBGS | G41: EU*,PU*,CO* | H41: *seq*,*CCS* | I41: ELCSCO2N | J41: 84.304 | M41: ELCSCO2N
C42: \I: FLO_EMIS | E42: ELCMUN | F42: ELCMUN | G42: EU*,PU*,CO* | H42: *seq*,*CCS* | I42: SNKFCO2 | J42: 75.548 | M42: ELCSCO2N
...

Sheet Final Coeffs_SUP
A2: ~TFM_INS | J2: Key
A3: TimeSlice | B3: LimType | C3: Attribute | D3: Year | E3: Other_Indexes | F3: Pset_PN | G3: Cset_CN | H3: AllRegions | J3: SCOAH2GC01 | L3: H2 Production-Coal Gasification, big size, centralized | N3: OLD H2 Chain
C4: FLO_EMIS | E4: COAHAR | F4: SCOAH2GC01 | G4: SUPCO2N | H4: 96.1 | J4: SCOAH2GC02 | L4: H2 Production-Coal Gasification, medium size, centralized | N4: FLO_EMIS | P4: COAHAR | Q4: SCOAH2G101 | R4: SUPCO2N | S4: 183.306
C5: FLO_EMIS | E5: COAHAR | F5: SCOAH2GC01 | G5: FOSCO2 | H5: 96.1 | J5: SCOAH2GCC01 | L5: H2 Production-Coal Gasification + Carbon Capture, big size, centralized | N5: FLO_EMIS | P5: COAHAR | Q5: SCOAH2G101 | R5: ETSCO2 | S5: =S4 -> 183.306
C6: FLO_EMIS | E6: COAHAR | F6: SCOAH2GC01 | G6: ETSCO2 | H6: 96.1 | J6: SCOAH2GCC02 | L6: H2 Production-Coal Gasification + Carbon Capture, medium size, centralized | N6: FLO_EMIS | P6: COAHAR | Q6: SCOAH2G110 | R6: SUPCO2N | S6: 5.639
C7: FLO_EMIS | E7: COAHAR | F7: SCOAH2GC02 | G7: SUPCO2N | H7: 96.1 | J7: SBIOH2GD01 | L7: H2 Production-Biomass Gasification, small size, decentralized | N7: FLO_EMIS | P7: COAHAR | Q7: SCOAH2G110 | R7: SUPSCO2N | S7: 177.667
C8: FLO_EMIS | E8: COAHAR | F8: SCOAH2GC02 | G8: FOSCO2 | H8: 96.1 | J8: SBIOH2GC01 | L8: H2 Production-Biomass Gasification, medium size, centralized | N8: FLO_EMIS | P8: COAHAR | Q8: SCOAH2G110 | R8: ETSCO2 | S8: =S6+S7 -> 183.306
C9: FLO_EMIS | E9: COAHAR | F9: SCOAH2GC02 | G9: ETSCO2 | H9: 96.1 | J9: SBIOH2GCC01 | L9: H2 Production-Biomass Gasification + Carbon Capture, medium size, centralized | N9: FLO_EMIS | P9: COAHAR | Q9: SCOAH2G210 | R9: SUPCO2N | S9: 1.83306
C10: FLO_EMIS | E10: COAHAR | F10: SCOAH2GCC01 | G10: SUPCO2N | H10: 9.61 | J10: SGASH2KC01 | L10: H2 Production-Kvaerner Process, centralized | N10: FLO_EMIS | P10: COAHAR | Q10: SCOAH2G210 | R10: SUPSCO2N | S10: 181.47294
C11: FLO_EMIS | E11: COAHAR | F11: SCOAH2GCC01 | G11: FOSCO2 | H11: 9.61 | J11: SBIOH2RC01 | L11: H2 Production-Biomass Steam Reforming, centralized | N11: FLO_EMIS | P11: COAHAR | Q11: SCOAH2G210 | R11: ETSCO2 | S11: =S9+S10 -> 183.306
C12: FLO_EMIS | E12: COAHAR | F12: SCOAH2GCC01 | G12: SNKFCO2 | H12: 86.49 | J12: SGASH2RC01 | L12: H2 Production-Methane Steam Reforming, large size, centralized | N12: FLO_EMIS | P12: GASNAT | Q12: SGASH2101 | R12: SUPCO2N | S12: 84.15
C13: FLO_EMIS | E13: COAHAR | F13: SCOAH2GCC01 | G13: ETSCO2 | H13: 96.1 | J13: SGASH2RC02 | L13: H2 Production-Methane Steam Reforming, small size, centralized | N13: FLO_EMIS | P13: GASNAT | Q13: SGASH2101 | R13: ETSCO2 | S13: =S12 -> 84.15
C14: FLO_EMIS | E14: COAHAR | F14: SCOAH2GCC02 | G14: SUPCO2N | H14: 4.805 | J14: SGASH2RCC01 | L14: H2 Production-Methane Steam Reforming + Carbon Capture, large size, centralized | N14: FLO_EMIS | P14: GASNAT | Q14: SGASH2G2101 | R14: SUPCO2N | S14: 75.735
C15: FLO_EMIS | E15: COAHAR | F15: SCOAH2GCC02 | G15: FOSCO2 | H15: 4.805 | J15: SGASH2RCC02 | L15: H2 Production-Methane Steam Reforming + Carbon Capture, small size, centralized | N15: FLO_EMIS | P15: GASNAT | Q15: SGASH2G2101 | R15: ETSCO2 | S15: =S14 -> 75.735
C16: FLO_EMIS | E16: COAHAR | F16: SCOAH2GCC02 | G16: SNKFCO2 | H16: 91.295 | J16: SGASSH2RC01 | L16: H2 Production-Solar Steam Reforming of Methane, centralized | N16: FLO_EMIS | P16: GASNAT | Q16: SGASH2G301 | R16: SUPCO2N | S16: 0.021317
C17: FLO_EMIS | E17: COAHAR | F17: SCOAH2GCC02 | G17: ETSCO2 | H17: 96.1 | J17: SGASH2RD01 | L17: H2 Production-Methane Steam Reforming, medium size, decentralized | N17: FLO_EMIS | P17: GASNAT | Q17: SGASH2G301 | R17: ETSCO2 | S17: =S16 -> 0.021317
C18: FLO_EMIS | E18: BIOWOOH2 | F18: SBIOH2GCC01 | G18: SUPCO2N | H18: -98.56 | J18: SGASH2RD02 | L18: H2 Production-Methane Steam Reforming, small size, decentralized | N18: FLO_EMIS | P18: OILHFO | Q18: SHFOH2G101 | R18: SUPCO2N | S18: 100.62
C19: FLO_EMIS | E19: BIOWOOH2 | F19: SBIOH2GCC01 | G19: SUPSCO2N | H19: 98.56 | J19: SETHRH2D01 | L19: H2 Production-Ethanol Steam Reforming, decentralized | N19: FLO_EMIS | P19: OILHFO | Q19: SHFOH2G101 | R19: ETSCO2 | S19: =S18 -> 100.62
C20: FLO_EMIS | E20: BIOWOOH2 | F20: SBIOH2GCC01 | G20: ETSCO2 | H20: 0 | J20: SGASSH2RD01 | L20: H2 Production-Solar Steam Reforming of Methane, decentralized | N20: FLO_EMIS | P20: GASNAT | Q20: SSOLH2G130 | R20: SUPCO2N | S20: 84.15
C21: FLO_EMIS | E21: GASNAT | F21: SGASH2KC01 | G21: SUPCO2N | H21: 56.1 | J21: SHFOH2POC01 | L21: H2 Production-Central PO of Heavy Oil (CPO3) | N21: FLO_EMIS | P21: GASNAT | Q21: SSOLH2G130 | R21: ETSCO2 | S21: =S20 -> 84.15
C22: FLO_EMIS | E22: GASNAT | F22: SGASH2KC01 | G22: FOSCO2 | H22: 56.1
C23: FLO_EMIS | E23: GASNAT | F23: SGASH2KC01 | G23: ETSCO2 | H23: 56.1
C24: FLO_EMIS | E24: GASNAT | F24: SGASH2RC01 | G24: SUPCO2N | H24: 56.1
C25: FLO_EMIS | E25: GASNAT | F25: SGASH2RC01 | G25: FOSCO2 | H25: 56.1
C26: FLO_EMIS | E26: GASNAT | F26: SGASH2RC01 | G26: ETSCO2 | H26: 56.1
C27: FLO_EMIS | E27: GASNAT | F27: SGASH2RC02 | G27: SUPCO2N | H27: 56.1
C28: FLO_EMIS | E28: GASNAT | F28: SGASH2RC02 | G28: FOSCO2 | H28: 56.1
C29: FLO_EMIS | E29: GASNAT | F29: SGASH2RC02 | G29: ETSCO2 | H29: 56.1
C30: FLO_EMIS | E30: GASNAT | F30: SGASH2RCC01 | G30: SUPCO2N | H30: 2.805
C31: FLO_EMIS | E31: GASNAT | F31: SGASH2RCC01 | G31: FOSCO2 | H31: 2.805
C32: FLO_EMIS | E32: GASNAT | F32: SGASH2RCC01 | G32: SNKFCO2 | H32: 53.295
C33: FLO_EMIS | E33: GASNAT | F33: SGASH2RCC01 | G33: ETSCO2 | H33: 56.1
... C44: FLO_EMIS | E44: GASNAT | F44: SGASH2RD02 | G44: SUPCO2N | H44: 56.1
C45: FLO_EMIS | E45: GASNAT | F45: SGASH2RD02 | G45: FOSCO2 | H45: 56.1 | L45: FUEL1 | M45: FUEL2 | N45: ETSCO2N | O45: SUPCO2N | P45: SUPSCO2N | Q45: Reference
C46: FLO_EMIS | E46: GASNAT | F46: SGASH2RD02 | G46: ETSCO2 | H46: 56.1 | L46: COAHAR | N46: =O46 -> 183.306 | O46: 183.306 | P46: 0 | Q46: Cascade-Mints D1.1 Fuel cell technologies and H2 production/distribution options. DLR. September 2005.
C47: FLO_EMIS | E47: GASNAT | F47: SGASSH2RD01 | G47: SUPCO2N | H47: 56.1 | L47: COAHAR | N47: =O47 -> 5.639 | O47: =O46-P47 -> 5.639 | P47: 177.667 | Q47: Cascade-Mints D1.1 Fuel cell technologies and H2 production/distribution options. DLR. September 2005.
C48: FLO_EMIS | E48: GASNAT | F48: SGASSH2RD01 | G48: FOSCO2 | H48: 56.1 | L48: COAHAR | N48: =O48 -> 1.83306 | O48: =O46-P48 -> 1.83306 | P48: =O46*0.99 -> 181.47294 | Q48: No data, assumed same EF as SMR small but 99% capture rate
C49: FLO_EMIS | E49: GASNAT | F49: SGASSH2RD01 | G49: ETSCO2 | H49: 56.1 | L49: BIOWOO | M49: ELCHIG | N49: =O49 -> 0 | O49: 0 | P49: 0 | Q49: Cascade-Mints D1.1 Fuel cell technologies and H2 production/distribution options. DLR. September 2005.
C50: FLO_EMIS | E50: OILHFO | F50: SHFOH2POC01 | G50: SUPCO2N | H50: 75.33767 | L50: BIOWOO | N50: =O50 -> 0 | O50: 0 | P50: 0 | Q50: Cascade-Mints D1.1 Fuel cell technologies and H2 production/distribution options. DLR. September 2005.
C51: FLO_EMIS | E51: OILHFO | F51: SHFOH2POC01 | G51: FOSCO2 | H51: 75.33767 | L51: ELCHIG | M51: SUPHTH | N51: =O51 -> 0 | O51: 0 | P51: 0 | Q51: Cascade-Mints D1.1 Fuel cell technologies and H2 production/distribution options. DLR. September 2005.
...

Sheet Final Coeffs_IND
A2: ~TFM_INS | J2: ~TFM_INS
A3: TimeSlice | B3: LimType | C3: Attribute | D3: Year | E3: Other_Indexes | F3: Pset_PN | G3: Cset_CN | H3: AllRegions | J3: TimeSlice | K3: LimType | L3: Attribute | M3: Year | N3: Other_Indexes | O3: Pset_PN | P3: Cset_CN | Q3: AllRegions
C4: FLO_EMIS | E4: INDGAS | F4: IAMADVCAP10 | G4: INDCO2N | H4: 6.72 | L4: FLO_EMIS | N4: INDGAS | O4: IAMADVCAP10 | P4: FOSCO2 | Q4: 6.72
C5: FLO_EMIS | E5: INDGAS | F5: ICMDRYPRD10 | G5: INDCO2N | H5: 6.72 | L5: FLO_EMIS | N5: INDGAS | O5: ICMDRYPRD10 | P5: FOSCO2 | Q5: 6.72
C6: FLO_EMIS | E6: INDCOA | F6: ICMDRYPRD10 | G6: INDCO2N | H6: 11.796 | L6: FLO_EMIS | N6: INDCOA | O6: ICMDRYPRD10 | P6: FOSCO2 | Q6: 11.796
C7: FLO_EMIS | E7: INDGAS | F7: IISDRISPNCS01 | G7: INDCO2N | H7: 17.864 | L7: FLO_EMIS | N7: INDGAS | O7: IISDRISPNCS01 | P7: FOSCO2 | Q7: 17.864
C8: FLO_EMIS | E8: INDCOK | F8: IISBLAFURTGRCS20 | G8: INDCO2N | H8: 24.5014 | L8: FLO_EMIS | N8: INDCOK | O8: IISBLAFURTGRCS20 | P8: FOSCO2 | Q8: 24.5014
C9: FLO_EMIS | E9: INDCOA | F9: IISBLAFURTGRCS20 | G9: INDCO2N | H9: 25.4597 | L9: FLO_EMIS | N9: INDCOA | O9: IISBLAFURTGRCS20 | P9: FOSCO2 | Q9: 25.4597
C10: FLO_EMIS | E10: INDCOK | F10: IISBLAFURCS20 | G10: INDCO2N | H10: 47.3 | L10: FLO_EMIS | N10: INDCOK | O10: IISBLAFURCS20 | P10: FOSCO2 | Q10: 47.3
C11: FLO_EMIS | E11: INDCOA | F11: IISBLAFURCS20 | G11: INDCO2N | H11: 49.15 | L11: FLO_EMIS | N11: INDCOA | O11: IISBLAFURCS20 | P11: FOSCO2 | Q11: 49.15
C12: FLO_EMIS | E12: INDCOA | F12: IISCOREXCS | G12: INDCO2N | H12: 72.8403 | L12: FLO_EMIS | N12: INDCOA | O12: IISCOREXCS | P12: FOSCO2 | Q12: 72.8403
C13: FLO_EMIS | E13: INDCOK | F13: IISCOREXCS | G13: INDCO2N | H13: 70.0986 | L13: FLO_EMIS | N13: INDCOK | O13: IISCOREXCS | P13: FOSCO2 | Q13: 70.0986
C14: FLO_EMIS | E14: INDGAS | F14: IPPHIGQUA10 | G14: INDCO2N | H14: 6.72 | L14: FLO_EMIS | N14: INDGAS | O14: IPPHIGQUA10 | P14: FOSCO2 | Q14: 6.72
C15: FLO_EMIS | E15: INDGAS | F15: IPPLOWQUA10 | G15: INDCO2N | H15: 6.72 | L15: FLO_EMIS | N15: INDGAS | O15: IPPLOWQUA10 | P15: FOSCO2 | Q15: 6.72
... C21: FLO_EMIS | E21: INDHFO | F21: IGHRECYCL10 | G21: INDCO2N | H21: 9.288 | L21: FLO_EMIS | N21: INDHFO | O21: IGHRECYCL10 | P21: FOSCO2 | Q21: 9.288
C22: ENV_ACT | F22: IISBLAFUR00 | G22: INDCO2P | H22: 77 | L22: ENV_ACT | O22: IISBLAFUR00 | P22: FOSCO2 | Q22: 77
C23: ENV_ACT | F23: IISCOREXP00 | G23: INDCO2P | H23: 150 | L23: ENV_ACT | O23: IISCOREXP00 | P23: FOSCO2 | Q23: 150
C24: ENV_ACT | F24: IISDRISPN00 | G24: INDCO2P | H24: 77 | L24: ENV_ACT | O24: IISDRISPN00 | P24: FOSCO2 | Q24: 77
C25: ENV_ACT | F25: IISCYCFUR00 | G25: INDCO2P | H25: 77 | L25: ENV_ACT | O25: IISCYCFUR00 | P25: FOSCO2 | Q25: 77
C26: ENV_ACT | F26: IALHAHERG00 | G26: INDCO2P | H26: 10000 | L26: ENV_ACT | O26: IALHAHERG00 | P26: FOSCO2 | Q26: 10000
C27: ENV_ACT | F27: IALHAHEPF00 | G27: INDCO2P | H27: 1000 | L27: ENV_ACT | O27: IALHAHEPF00 | P27: FOSCO2 | Q27: 1000
C28: ENV_ACT | F28: ICMDRYPRD00 | G28: INDCO2P | H28: 510 | L28: ENV_ACT | O28: ICMDRYPRD00 | P28: FOSCO2 | Q28: 510
C29: ENV_ACT | F29: ICMWETPRD00 | G29: INDCO2P | H29: 510 | L29: ENV_ACT | O29: ICMWETPRD00 | P29: FOSCO2 | Q29: 510
C30: ENV_ACT | F30: IALHAHEPF01 | G30: INDCO2P | H30: 1000 | L30: ENV_ACT | O30: IALHAHEPF01 | P30: FOSCO2 | Q30: 1000
C31: ENV_ACT | F31: IALHAHERG01 | G31: INDCO2P | H31: 10000 | L31: ENV_ACT | O31: IALHAHERG01 | P31: FOSCO2 | Q31: 10000
C32: ENV_ACT | F32: IALHAHERG05 | G32: INDCO2P | H32: 7500 | L32: ENV_ACT | O32: IALHAHERG05 | P32: FOSCO2 | Q32: 7500
C33: ENV_ACT | F33: IALHAHERG10 | G33: INDCO2P | H33: 7500 | L33: ENV_ACT | O33: IALHAHERG10 | P33: FOSCO2 | Q33: 7500
... C39: ENV_ACT | F39: ILMQLMPRO01 | G39: INDCO2P | H39: 786 | L39: ENV_ACT | O39: ILMQLMPRO01 | P39: FOSCO2 | Q39: 786
C40: ENV_ACT | F40: IALHAHERG00 | G40: INDCXFN | H40: 1.25
C41: ENV_ACT | F41: IALHAHEPF00 | G41: INDCXFN | H41: 0.125
C42: ENV_ACT | F42: IALHAHEPF01 | G42: INDCXFN | H42: 0.125
C43: ENV_ACT | F43: IALHAHERG01 | G43: INDCXFN | H43: 1.25
C44: ENV_ACT | F44: IALHAHERG05 | G44: INDCXFN | H44: 1.25
C45: ENV_ACT | F45: IALHAHERG10 | G45: INDCXFN | H45: 1.25
C46: ENV_ACT | F46: IALINERAN01 | G46: INDCXFN | H46: 1.25
C47: ENV_ACT | F47: IALRECYCP01 | G47: INDCXFN | H47: 1.25
C48: ENV_ACT | F48: IALRECYCP05 | G48: INDCXFN | H48: 0.125
C49: ENV_ACT | F49: IALRECYCP10 | G49: INDCXFN | H49: 0.125
C50: FLO_EMIS | E50: INDGAS | F50: IAMADVCAP10 | G50: SNKFCO2 | H50: 49.28
C51: FLO_EMIS | E51: INDGAS | F51: ICMDRYPRD10 | G51: SNKFCO2 | H51: 49.28
...

Sheet EmiFactors_IND
A1: Static coefficients for combustion emissions in industry | I1: Dynamic coefficients for combustion emissions in industry
A2: ~TFM_INS | I2: ~TFM_INS
A3: Attribute | B3: PSET_PN | C3: PSET_CI | D3: Other_Indexes | E3: CSET_CN | F3: AllRegions | I3: Attribute | J3: CSET_CN | K3: Other_Indexes | L3: AllRegions
A4: FLO_EMIS | B4: IND* | C4: =D4 -> COAHAR | D4: COAHAR | E4: SE_INDCO2N | F4: 95 | I4: VDA_EMCB | J4: INDCOA | K4: INDCO2N | L4: 95
A5: FLO_EMIS | B5: IND* | C5: =D5 -> COACOK | D5: COACOK | E5: SE_INDCO2N | F5: 105 | I5: VDA_EMCB | J5: INDCOL | K5: INDCO2N | L5: 105
A6: FLO_EMIS | B6: IND* | C6: =D6 -> COALIG | D6: COALIG | E6: SE_INDCO2N | F6: 110.6 | I6: VDA_EMCB | J6: INDCOB | K6: INDCO2N | L6: 110.6
A7: FLO_EMIS | B7: IND* | C7: =D7 -> COABRO | D7: COABRO | E7: SE_INDCO2N | F7: 110.6 | I7: VDA_EMCB | J7: INDCOK | K7: INDCO2N | L7: 110.6
A8: FLO_EMIS | B8: IND* | C8: =D8 -> OILRFG | D8: OILRFG | E8: SE_INDCO2N | F8: 60 | I8: VDA_EMCB | J8: INDRFG | K8: INDCO2N | L8: 60
A9: FLO_EMIS | B9: IND* | C9: =D9 -> OILLPG | D9: OILLPG | E9: SE_INDCO2N | F9: 65 | I9: VDA_EMCB | J9: INDLPG | K9: INDCO2N | L9: 65
A10: FLO_EMIS | B10: IND* | C10: =D10 -> OILGSL | D10: OILGSL | E10: SE_INDCO2N | F10: 72 | I10: VDA_EMCB | J10: INDLFO | K10: INDCO2N | L10: 74
A11: FLO_EMIS | B11: IND* | C11: =D11 -> OILKER | D11: OILKER | E11: SE_INDCO2N | F11: 74 | I11: VDA_EMCB | J11: INDNAP | K11: INDCO2N | L11: 73.3
A12: FLO_EMIS | B12: IND* | C12: =D12 -> OILNAP | D12: OILNAP | E12: SE_INDCO2N | F12: 73.3 | I12: VDA_EMCB | J12: INDHFO | K12: INDCO2N | L12: 78
A13: FLO_EMIS | B13: IND* | C13: =D13 -> OILDST | D13: OILDST | E13: SE_INDCO2N | F13: 74 | I13: VDA_EMCB | J13: INDNEU | K13: INDCO2N | L13: 0
A14: FLO_EMIS | B14: IND* | C14: =D14 -> OILHFO | D14: OILHFO | E14: SE_INDCO2N | F14: 78 | I14: VDA_EMCB | J14: INDGAS | K14: INDCO2N | L14: 56
A15: FLO_EMIS | B15: IND* | C15: =D15 -> OILNEU | D15: OILNEU | E15: SE_INDCO2N | F15: 0 | I15: VDA_EMCB | J15: INDCOG | K15: INDCO2N | L15: 108.2
... A25: FLO_EMIS | B25: IND* | C25: =D25 -> BIOLIQ | D25: BIOLIQ | E25: SE_INDCO2N | F25: 0 | I25: VDA_EMCB | J25: INDLPG | K25: FOSCO2 | L25: 65
I26: VDA_EMCB | J26: INDLFO | K26: FOSCO2 | L26: 74
I27: VDA_EMCB | J27: INDNAP | K27: FOSCO2 | L27: 73.3
I28: VDA_EMCB | J28: INDHFO | K28: FOSCO2 | L28: 78
I29: VDA_EMCB | J29: INDNEU | K29: FOSCO2 | L29: 0
I30: VDA_EMCB | J30: INDGAS | K30: FOSCO2 | L30: 56
I31: VDA_EMCB | J31: INDCOG | K31: FOSCO2 | L31: 108.2
I32: VDA_EMCB | J32: INDBFG | K32: FOSCO2 | L32: 286
I33: VDA_EMCB | J33: INDBIO | K33: FOSCO2 | L33: 0
I34: VDA_EMCB | J34: INDMUN | K34: FOSCO2 | L34: 45
I35: VDA_EMCB | J35: INDSLU | K35: FOSCO2 | L35: 45

Sheet EmiFactors_TRA
A1: Dynamic coefficients for combustion emissions in transport
A2: ~TFM_INS
A3: Attribute | B3: CSET_CN | C3: Other_Indexes | D3: AllRegions
A4: VDA_EMCB | B4: TRALPG | C4: TRACO2N | D4: =C17 -> 63.1
A5: VDA_EMCB | B5: TRAJTK | C5: TRACO2N | D5: =C48 -> 71.9
A6: VDA_EMCB | B6: TRADST | C6: TRACO2N | D6: =C49 -> 74.1
A7: VDA_EMCB | B7: TRALFO | C7: TRACO2N | D7: =D6 -> 74.1
A8: VDA_EMCB | B8: TRAHFO | C8: TRACO2N | D8: 77.4
A9: VDA_EMCB | B9: TRAGAS | C9: TRACO2N | D9: =C24 -> 74.1
A10: VDA_EMCB | B10: TRAGSLSP95 | C10: TRACO2N | D10: 73.38
A11: VDA_EMCB | B11: TRAGSLE85 | C11: TRACO2N | D11: 71.38
A14: Static coefficients for combustion emissions in transport
A15: ~TFM_INS
A16: Attribute | B16: Other_Indexes | C16: AllRegions | D16: Pset_PN | E16: Pset_PD | F16: Pset_CI | G16: Cset_CN
A17: FLO_EMIS | B17: OILLPG | C17: 63.1 | D17: TRALPG* | F17: OILLPG | G17: SE_TRACO2N
A18: FLO_EMIS | B18: OILHFO | C18: 77.4 | D18: TRAHFO* | F18: =B18 -> OILHFO | G18: SE_TRACO2N
A19: FLO_EMIS | B19: GASNAT | C19: 56.1 | D19: TRAGAS* | F19: =B19 -> GASNAT | G19: SE_TRACO2N
A20: FLO_EMIS | B20: OILKER | C20: 71.9 | D20: BLDJET | F20: =B20 -> OILKER | G20: SE_TRACO2N
A21: FLO_EMIS | B21: OILDST | C21: 74.1 | D21: BLDDSL* | F21: =B21 -> OILDST | G21: SE_TRACO2N
A22: FLO_EMIS | B22: OILGSL | C22: 73.38 | D22: BLDGSL* | F22: =B22 -> OILGSL | G22: SE_TRACO2N
A23: FLO_EMIS | B23: P2LGSL_FOS | C23: 73.38 | D23: BLD_RFNBO_GSL | F23: =B23 -> P2LGSL_FOS | G23: SE_TRACO2N
A24: FLO_EMIS | B24: P2LDST_FOS,SYNDST | C24: 74.1 | D24: BLD_RFNBO_RAI,BLD_RFNBO_DSL | F24: =B24 -> P2LDST_FOS,SYNDST | G24: SE_TRACO2N
A25: FLO_EMIS | B25: P2LKER_FOS,SYNKER | C25: 71.9 | D25: BLD_RFNBO_JET | F25: =B25 -> P2LKER_FOS,SYNKER | G25: SE_TRACO2N
A26: FLO_EMIS | B26: P2LDST_FOS,SYNDST | C26: 74.1 | D26: BLD_RFNBO_NAV | F26: =B26 -> P2LDST_FOS,SYNDST | G26: SE_TRACO2N
A27: FLO_EMIS | B27: GASP2G_FOS | C27: 56.1 | D27: BLD_RFNBO_GAS | F27: =B27 -> GASP2G_FOS | G27: SE_TRACO2N
A28: =A17 -> FLO_EMIS | B28: =B17 -> OILLPG | C28: =C17 -> 63.1 | D28: =D17 -> TRALPG* | F28: =F17 -> OILLPG | G28: FOSCO2
A29: =A18 -> FLO_EMIS | B29: =B18 -> OILHFO | C29: =C18 -> 77.4 | D29: =D18 -> TRAHFO* | F29: =F18 -> OILHFO | G29: FOSCO2
A30: =A19 -> FLO_EMIS | B30: =B19 -> GASNAT | C30: =C19 -> 56.1 | D30: =D19 -> TRAGAS* | F30: =F19 -> GASNAT | G30: FOSCO2
A31: =A20 -> FLO_EMIS | B31: =B20 -> OILKER | C31: =C20 -> 71.9 | D31: =D20 -> BLDJET | F31: =F20 -> OILKER | G31: FOSCO2
A32: =A21 -> FLO_EMIS | B32: =B21 -> OILDST | C32: =C21 -> 74.1 | D32: =D21 -> BLDDSL* | F32: =F21 -> OILDST | G32: FOSCO2
A33: =A22 -> FLO_EMIS | B33: =B22 -> OILGSL | C33: =C22 -> 73.38 | D33: =D22 -> BLDGSL* | F33: =F22 -> OILGSL | G33: FOSCO2
A34: =A23 -> FLO_EMIS | B34: =B23 -> P2LGSL_FOS | C34: =C23 -> 73.38 | D34: =D23 -> BLD_RFNBO_GSL | F34: =F23 -> P2LGSL_FOS | G34: FOSCO2
A35: =A24 -> FLO_EMIS | B35: =B24 -> P2LDST_FOS,SYNDST | C35: =C24 -> 74.1 | D35: =D24 -> BLD_RFNBO_RAI,BLD_RFNBO_DSL | F35: =F24 -> P2LDST_FOS,SYNDST | G35: FOSCO2
A36: =A25 -> FLO_EMIS | B36: =B25 -> P2LKER_FOS,SYNKER | C36: =C25 -> 71.9 | D36: =D25 -> BLD_RFNBO_JET | F36: =F25 -> P2LKER_FOS,SYNKER | G36: FOSCO2
A37: =A26 -> FLO_EMIS | B37: =B26 -> P2LDST_FOS,SYNDST | C37: =C26 -> 74.1 | D37: =D26 -> BLD_RFNBO_NAV | F37: =F26 -> P2LDST_FOS,SYNDST | G37: FOSCO2
A38: =A27 -> FLO_EMIS | B38: =B27 -> GASP2G_FOS | C38: =C27 -> 56.1 | D38: =D27 -> BLD_RFNBO_GAS | F38: =F27 -> GASP2G_FOS | G38: FOSCO2
C42: 77.4 | D42: ktCO2/PJ
C43: 339.1288 | D43: PJ | E43: =C42*C43 -> 26248.569 | F43: ktCO2
C44: =C43*25 -> 8478.22 | D44: kt HFO | E44: =E43/C44 -> 3.096 | F44: ktCO2/ktHFO
A47: *FLO_EMIS | B47: OILGSL | C47: 74 | D47: TAI*,BLD*,TRA* | F47: OILGSL | G47: SE_TRACO2N
...

Sheet EmiFactors_AGR_COM_RSD
A1: Static coefficients for combustion emissions in agriculture fuel use
A2: ~TFM_INS
A3: Attribute | B3: Other_Indexes | C3: AllRegions | D3: Pset_PN | E3: Pset_PD | F3: Pset_CI | G3: Cset_CN
A4: FLO_EMIS | B4: COAHAR | C4: 95 | D4: AGRCOA* | F4: =B4 -> COAHAR | G4: AGRCO2N
A5: FLO_EMIS | B5: OILLPG | C5: 65 | D5: AGRLPG* | F5: OILLPG | G5: AGRCO2N
A6: FLO_EMIS | B6: OILHFO | C6: 78 | D6: AGROIL* | F6: =B6 -> OILHFO | G6: AGRCO2N
A7: FLO_EMIS | B7: GASNAT | C7: 56 | D7: AGRGAS* | F7: =B7 -> GASNAT | G7: AGRCO2N
A8: FLO_EMIS | B8: OILDST | C8: 74 | D8: AGRDST* | F8: =B8 -> OILDST | G8: AGRCO2N
A9: =A4 -> FLO_EMIS | B9: =B4 -> COAHAR | C9: =C4 -> 95 | D9: =D4 -> AGRCOA* | F9: =F4 -> COAHAR | G9: FOSCO2
A10: =A5 -> FLO_EMIS | B10: =B5 -> OILLPG | C10: =C5 -> 65 | D10: =D5 -> AGRLPG* | F10: =F5 -> OILLPG | G10: FOSCO2
A11: =A6 -> FLO_EMIS | B11: =B6 -> OILHFO | C11: =C6 -> 78 | D11: =D6 -> AGROIL* | F11: =F6 -> OILHFO | G11: FOSCO2
A12: =A7 -> FLO_EMIS | B12: =B7 -> GASNAT | C12: =C7 -> 56 | D12: =D7 -> AGRGAS* | F12: =F7 -> GASNAT | G12: FOSCO2
A13: =A8 -> FLO_EMIS | B13: =B8 -> OILDST | C13: =C8 -> 74 | D13: =D8 -> AGRDST* | F13: =F8 -> OILDST | G13: FOSCO2
A15: Static coefficients for combustion emissions in commercial fuel use
A16: ~TFM_INS
A17: Attribute | B17: Other_Indexes | C17: AllRegions | D17: Pset_PN | E17: Pset_PD | F17: Pset_CI | G17: Cset_CN
A18: FLO_EMIS | B18: COAHAR | C18: 95 | D18: COMCOA* | F18: =B18 -> COAHAR | G18: COMCO2N
A19: FLO_EMIS | B19: COACOK | C19: 105 | D19: COMCOA* | F19: =B19 -> COACOK | G19: COMCO2N
A20: FLO_EMIS | B20: COALIG | C20: 110.6 | D20: COMCOA* | F20: =B20 -> COALIG | G20: COMCO2N
A21: FLO_EMIS | B21: COABRO | C21: 110.6 | D21: COMCOA* | F21: =B21 -> COABRO | G21: COMCO2N
A22: FLO_EMIS | B22: OILLPG | C22: 65 | D22: COMLPG* | F22: OILLPG | G22: COMCO2N
A23: FLO_EMIS | B23: OILHFO | C23: 78 | D23: COMOIL* | F23: =B23 -> OILHFO | G23: COMCO2N
A24: FLO_EMIS | B24: OILDST,P2LDST,SYNDST | C24: 74 | D24: COMOIL* | F24: =B24 -> OILDST,P2LDST,SYNDST | G24: COMCO2N
A25: FLO_EMIS | B25: GASNAT,GASP2G | C25: 56 | D25: COMGAS* | F25: =B25 -> GASNAT,GASP2G | G25: COMCO2N
A26: =A18 -> FLO_EMIS | B26: =B18 -> COAHAR | C26: =C18 -> 95 | D26: =D18 -> COMCOA* | F26: =F18 -> COAHAR | G26: FOSCO2
A27: =A19 -> FLO_EMIS | B27: =B19 -> COACOK | C27: =C19 -> 105 | D27: =D19 -> COMCOA* | F27: =F19 -> COACOK | G27: FOSCO2
A28: =A20 -> FLO_EMIS | B28: =B20 -> COALIG | C28: =C20 -> 110.6 | D28: =D20 -> COMCOA* | F28: =F20 -> COALIG | G28: FOSCO2
A29: =A21 -> FLO_EMIS | B29: =B21 -> COABRO | C29: =C21 -> 110.6 | D29: =D21 -> COMCOA* | F29: =F21 -> COABRO | G29: FOSCO2
A30: =A22 -> FLO_EMIS | B30: =B22 -> OILLPG | C30: =C22 -> 65 | D30: =D22 -> COMLPG* | F30: =F22 -> OILLPG | G30: FOSCO2
A31: =A23 -> FLO_EMIS | B31: =B23 -> OILHFO | C31: =C23 -> 78 | D31: =D23 -> COMOIL* | F31: =F23 -> OILHFO | G31: FOSCO2
A32: =A24 -> FLO_EMIS | B32: =B24 -> OILDST,P2LDST,SYNDST | C32: =C24 -> 74 | D32: =D24 -> COMOIL* | F32: =F24 -> OILDST,P2LDST,SYNDST | G32: FOSCO2
A33: =A25 -> FLO_EMIS | B33: =B25 -> GASNAT,GASP2G | C33: =C25 -> 56 | D33: =D25 -> COMGAS* | F33: =F25 -> GASNAT,GASP2G | G33: FOSCO2
A35: Static coefficients for combustion emissions in residential fuel use
A36: ~TFM_INS
A37: Attribute | B37: Other_Indexes | C37: AllRegions | D37: Pset_PN | E37: Pset_PD | F37: Pset_CI | G37: Cset_CN
A38: FLO_EMIS | B38: COAHAR | C38: 95 | D38: RSDCOA* | F38: =B38 -> COAHAR | G38: RSDCO2N
A39: FLO_EMIS | B39: COACOK | C39: 105 | D39: RSDCOA* | F39: =B39 -> COACOK | G39: RSDCO2N
A40: FLO_EMIS | B40: COALIG | C40: 110.6 | D40: RSDCOA* | F40: =B40 -> COALIG | G40: RSDCO2N
A41: FLO_EMIS | B41: COABRO | C41: 110.6 | D41: RSDCOA* | F41: =B41 -> COABRO | G41: RSDCO2N
A42: FLO_EMIS | B42: OILLPG | C42: 65 | D42: RSDLPG* | F42: OILLPG | G42: RSDCO2N
...

Sheet ETS Emissions
B2: ETS Emissions
A3: ~TFM_INS
A4: TimeSlice | B4: LimType | C4: Attribute | D4: Year | E4: Other_Indexes | F4: AllRegions | G4: ='ETS Emissions'!C87 -> AT | H4: ='ETS Emissions'!D87 -> BE | I4: ='ETS Emissions'!E87 -> BG | J4: ='ETS Emissions'!F87 -> CH | K4: ='ETS Emissions'!G87 -> CY | L4: ='ETS Emissions'!H87 -> CZ | M4: ='ETS Emissions'!I87 -> DE | N4: ='ETS Emissions'!J87 -> DK | ... R4: ='ETS Emissions'!N87 -> FR | S4: EL | T4: ='ETS Emissions'!P87 -> HU | U4: ='ETS Emissions'!Q87 -> IE | V4: ='ETS Emissions'!R87 -> IS | W4: ='ETS Emissions'!S87 -> IT | X4: ='ETS Emissions'!T87 -> LT | Y4: ='ETS Emissions'!U87 -> LU | Z4: ='ETS Emissions'!V87 -> LV | AA4: ='ETS Emissions'!W87 -> MT | ... AJ4: ='ETS Emissions'!AF87 -> UK | AK4: AL | AL4: BA | AM4: HR | AN4: KS | AO4: ME | AP4: MK | AQ4: RS | AR4: Pset_Set | AS4: Pset_PN | AT4: Pset_PD | AU4: Pset_CO | AV4: Pset_CI | AW4: Cset_CN | AX4: TechRep_Only | AY4: T_Pos_AndOr | AZ4: T_Neg_AndOr | BA4: C_Pos_AndOr | BB4: C_Neg_AndOr | BC4: T_Pos_Opt | BD4: T_Neg_Opt | BE4: C_Pos_Opt | BF4: C_Neg_Opt
C5: FLO_EMIS | E5: ='ETS Emissions'!B88 -> ELCBGS | F5: =AVERAGE(AD5,AH5,AI5) -> 0 | G5: ='ETS Emissions'!C88 -> 0 | H5: ='ETS Emissions'!D88 -> 0 | I5: ='ETS Emissions'!E88 -> 0 | J5: ='ETS Emissions'!F88 -> 0 | K5: ='ETS Emissions'!G88 -> 0 | L5: ='ETS Emissions'!H88 -> 0 | M5: ='ETS Emissions'!I88 -> 0 | N5: ='ETS Emissions'!J88 -> 0 | ... AQ5: ='ETS Emissions'!AM88 -> 0 | AV5: =E5 -> ELCBGS | AW5: ETSCO2
C6: FLO_EMIS | E6: ='ETS Emissions'!B89 -> ELCCOH | F6: =AVERAGE(AD6,AH6,AI6) -> 96.1 | G6: ='ETS Emissions'!C89 -> 95 | H6: ='ETS Emissions'!D89 -> 98.3 | I6: ='ETS Emissions'!E89 -> 98.3 | J6: ='ETS Emissions'!F89 -> 98.3 | K6: ='ETS Emissions'!G89 -> 98.3 | L6: ='ETS Emissions'!H89 -> 95 | M6: ='ETS Emissions'!I89 -> 98.3 | N6: ='ETS Emissions'!J89 -> 98.3 | ... AQ6: ='ETS Emissions'!AM89 -> 98.3 | AV6: =E6 -> ELCCOH | AW6: ETSCO2
C7: FLO_EMIS | E7: ='ETS Emissions'!B90 -> ELCCOL | F7: =AVERAGE(AD7,AH7,AI7) -> 107.46667 | G7: ='ETS Emissions'!C90 -> 110.6 | H7: ='ETS Emissions'!D90 -> 101.2 | I7: ='ETS Emissions'!E90 -> 101.2 | J7: ='ETS Emissions'!F90 -> 101.2 | K7: ='ETS Emissions'!G90 -> 101.2 | L7: ='ETS Emissions'!H90 -> 110.6 | M7: ='ETS Emissions'!I90 -> 101.2 | N7: ='ETS Emissions'!J90 -> 101.2 | ... AQ7: ='ETS Emissions'!AM90 -> 101.2 | AV7: =E7 -> ELCCOL | AW7: ETSCO2
C8: FLO_EMIS | E8: ELCCOG | F8: ='Final Coeffs_ELC'!J46 -> 39.6 | G8: =F8 -> 39.6 | H8: =G8 -> 39.6 | I8: =H8 -> 39.6 | J8: =I8 -> 39.6 | K8: =J8 -> 39.6 | L8: =K8 -> 39.6 | M8: =L8 -> 39.6 | N8: =M8 -> 39.6 | ... AQ8: =AP8 -> 39.6 | AV8: =E8 -> ELCCOG | AW8: ETSCO2
C9: FLO_EMIS | E9: ='ETS Emissions'!B91 -> ELCDGS | F9: =AVERAGE(AD9,AH9,AI9) -> 108.2 | G9: ='ETS Emissions'!C91 -> 108.2 | H9: ='ETS Emissions'!D91 -> 108.2 | I9: ='ETS Emissions'!E91 -> 108.2 | J9: ='ETS Emissions'!F91 -> 108.2 | K9: ='ETS Emissions'!G91 -> 108.2 | L9: ='ETS Emissions'!H91 -> 108.2 | M9: ='ETS Emissions'!I91 -> 108.2 | N9: ='ETS Emissions'!J91 -> 108.2 | ... AQ9: ='ETS Emissions'!AM91 -> 108.2 | AV9: =E9 -> ELCDGS | AW9: ETSCO2
C10: FLO_EMIS | E10: ='ETS Emissions'!B92 -> ELCDME | F10: =AVERAGE(AD10,AH10,AI10) -> 66.420139 | G10: ='ETS Emissions'!C92 -> 66.420139 | H10: ='ETS Emissions'!D92 -> 66.420139 | I10: ='ETS Emissions'!E92 -> 66.420139 | J10: ='ETS Emissions'!F92 -> 66.420139 | K10: ='ETS Emissions'!G92 -> 66.420139 | L10: ='ETS Emissions'!H92 -> 66.420139 | M10: ='ETS Emissions'!I92 -> 66.420139 | N10: ='ETS Emissions'!J92 -> 66.420139 | ... AQ10: ='ETS Emissions'!AM92 -> 66.420139 | AV10: =E10 -> ELCDME | AW10: ETSCO2
C11: FLO_EMIS | E11: ='ETS Emissions'!B93 -> ELCDST | F11: =AVERAGE(AD11,AH11,AI11) -> 50.166667 | G11: ='ETS Emissions'!C93 -> 74 | H11: ='ETS Emissions'!D93 -> 74.1 | I11: ='ETS Emissions'!E93 -> 74.1 | J11: ='ETS Emissions'!F93 -> 74.1 | K11: ='ETS Emissions'!G93 -> 74.1 | L11: ='ETS Emissions'!H93 -> 79.652174 | M11: ='ETS Emissions'!I93 -> 73.714286 | N11: ='ETS Emissions'!J93 -> 73.935294 | ... AQ11: ='ETS Emissions'!AM93 -> 74.1 | AV11: =E11 -> ELCDST | AW11: ETSCO2
C12: FLO_EMIS | E12: ='ETS Emissions'!B94 -> ELCGAS | F12: =AVERAGE(AD12,AH12,AI12) -> 56.033333 | G12: ='ETS Emissions'!C94 -> 56 | H12: ='ETS Emissions'!D94 -> 56.1 | I12: ='ETS Emissions'!E94 -> 56.1 | J12: ='ETS Emissions'!F94 -> 56.1 | K12: ='ETS Emissions'!G94 -> 56.1 | L12: ='ETS Emissions'!H94 -> 56 | M12: ='ETS Emissions'!I94 -> 56.1 | N12: ='ETS Emissions'!J94 -> 56.1 | ... AQ12: ='ETS Emissions'!AM94 -> 56.1 | AV12: =E12 -> ELCGAS | AW12: ETSCO2
C13: FLO_EMIS | E13: ='ETS Emissions'!B95 -> ELCHFO | F13: =AVERAGE(AD13,AH13,AI13) -> 77.8 | G13: ='ETS Emissions'!C95 -> 78 | H13: ='ETS Emissions'!D95 -> 77.4 | I13: ='ETS Emissions'!E95 -> 77.4 | J13: ='ETS Emissions'!F95 -> 77.4 | K13: ='ETS Emissions'!G95 -> 77.4 | L13: ='ETS Emissions'!H95 -> 78 | M13: ='ETS Emissions'!I95 -> 77.4 | N13: ='ETS Emissions'!J95 -> 77.4 | ... AQ13: ='ETS Emissions'!AM95 -> 77.4 | AV13: =E13 -> ELCHFO | AW13: ETSCO2
C14: FLO_EMIS | E14: ='ETS Emissions'!B96 -> ELCMUN | F14: =AVERAGE(AD14,AH14,AI14) -> 58.616667 | G14: ='ETS Emissions'!C96 -> 45 | H14: ='ETS Emissions'!D96 -> 85.85 | I14: ='ETS Emissions'!E96 -> 85.85 | J14: ='ETS Emissions'!F96 -> 85.85 | K14: ='ETS Emissions'!G96 -> 85.85 | L14: ='ETS Emissions'!H96 -> 45 | M14: ='ETS Emissions'!I96 -> 85.85 | N14: ='ETS Emissions'!J96 -> 85.85 | ... AQ14: ='ETS Emissions'!AM96 -> 85.85 | AV14: =E14 -> ELCMUN | AW14: ETSCO2
C15: FLO_EMIS | E15: ='ETS Emissions'!B97 -> ELCOIL | F15: =AVERAGE(AD15,AH15,AI15) -> 76.948547 | G15: ='ETS Emissions'!C97 -> 77.937888 | H15: ='ETS Emissions'!D97 -> 77.135036 | I15: ='ETS Emissions'!E97 -> 77.350746 | J15: ='ETS Emissions'!F97 -> 74.1 | K15: ='ETS Emissions'!G97 -> 77.3507 | L15: ='ETS Emissions'!H97 -> 77.396226 | M15: ='ETS Emissions'!I97 -> 75.655469 | N15: ='ETS Emissions'!J97 -> 77.121562 | ... AQ15: ='ETS Emissions'!AM97 -> 74.1 | AV15: =E15 -> ELCOIL | AW15: ETSCO2
C16: FLO_EMIS | E16: ='ETS Emissions'!B98 -> ELCRFG | F16: =AVERAGE(AD16,AH16,AI16) -> 58.7 | G16: ='ETS Emissions'!C98 -> 60 | H16: ='ETS Emissions'!D98 -> 56.1 | I16: ='ETS Emissions'!E98 -> 56.1 | J16: ='ETS Emissions'!F98 -> 56.1 | K16: ='ETS Emissions'!G98 -> 56.1 | L16: ='ETS Emissions'!H98 -> 60 | M16: ='ETS Emissions'!I98 -> 56.1 | N16: ='ETS Emissions'!J98 -> 56.1 | ... AQ16: ='ETS Emissions'!AM98 -> 56.1 | AV16: =E16 -> ELCRFG | AW16: ETSCO2
C17: FLO_EMIS | E17: ='ETS Emissions'!B99 -> ELCSLU | F17: =AVERAGE(AD17,AH17,AI17) -> 58.616667 | G17: ='ETS Emissions'!C99 -> 45 | H17: ='ETS Emissions'!D99 -> 85.85 | I17: ='ETS Emissions'!E99 -> 85.85 | J17: ='ETS Emissions'!F99 -> 85.85 | K17: ='ETS Emissions'!G99 -> 85.85 | L17: ='ETS Emissions'!H99 -> 45 | M17: ='ETS Emissions'!I99 -> 85.85 | N17: ='ETS Emissions'!J99 -> 85.85 | ... AQ17: ='ETS Emissions'!AM99 -> 85.85 | AV17: =E17 -> ELCSLU | AW17: ETSCO2
C18: FLO_EMIS | E18: ='ETS Emissions'!B100 -> ELCWOO | F18: =AVERAGE(AD18,AH18,AI18) -> 0 | G18: ='ETS Emissions'!C100 -> 0 | H18: ='ETS Emissions'!D100 -> 0 | I18: ='ETS Emissions'!E100 -> 0 | J18: ='ETS Emissions'!F100 -> 0 | K18: ='ETS Emissions'!G100 -> 0 | L18: ='ETS Emissions'!H100 -> 0 | M18: ='ETS Emissions'!I100 -> 0 | N18: ='ETS Emissions'!J100 -> 0 | ... AQ18: ='ETS Emissions'!AM100 -> 0 | AV18: =E18 -> ELCWOO | AW18: ETSCO2
C19: *
C20: FLO_EMIS | E20: ='ETS Emissions'!B101 -> INDBFG | F20: =AVERAGE(AD20,AH20,AI20) -> 108.2 | G20: ='ETS Emissions'!C101 -> 108.2 | H20: ='ETS Emissions'!D101 -> 108.2 | I20: ='ETS Emissions'!E101 -> 108.2 | J20: ='ETS Emissions'!F101 -> 108.2 | K20: ='ETS Emissions'!G101 -> 108.2 | L20: ='ETS Emissions'!H101 -> 108.2 | M20: ='ETS Emissions'!I101 -> 108.2 | N20: ='ETS Emissions'!J101 -> 108.2 | ... AQ20: ='ETS Emissions'!AM101 -> 108.2 | AS20: IIS*,___IIS*,ICM*,ILM*,IGF*,IGH*,___ICM*,___ILM*,___IGF*,___IGH*,IPL*,IPH*,IPP*,___IPL*,___IPH*,___IPP*,CHP*,EAUT* | AV20: =E20 -> INDBFG | AW20: ETSCO2
C21: FLO_EMIS | E21: ='ETS Emissions'!B102 -> INDBIO | F21: =AVERAGE(AD21,AH21,AI21) -> 0 | G21: ='ETS Emissions'!C102 -> 0 | H21: ='ETS Emissions'!D102 -> 0 | I21: ='ETS Emissions'!E102 -> 0 | J21: ='ETS Emissions'!F102 -> 0 | K21: ='ETS Emissions'!G102 -> 0 | L21: ='ETS Emissions'!H102 -> 0 | M21: ='ETS Emissions'!I102 -> 0 | N21: ='ETS Emissions'!J102 -> 0 | ... AQ21: ='ETS Emissions'!AM102 -> 0 | AS21: IIS*,___IIS*,ICM*,ILM*,IGF*,IGH*,___ICM*,___ILM*,___IGF*,___IGH*,IPL*,IPH*,IPP*,___IPL*,___IPH*,___IPP*,CHP*,EAUT* | AV21: =E21 -> INDBIO | AW21: ETSCO2
C22: FLO_EMIS | E22: ='ETS Emissions'!B103 -> INDCOA | F22: =AVERAGE(AD22,AH22,AI22) -> 96.1 | G22: ='ETS Emissions'!C103 -> 95 | H22: ='ETS Emissions'!D103 -> 98.3 | I22: ='ETS Emissions'!E103 -> 95 | J22: ='ETS Emissions'!F103 -> 98.3 | K22: ='ETS Emissions'!G103 -> 98.3 | L22: ='ETS Emissions'!H103 -> 95 | M22: ='ETS Emissions'!I103 -> 95 | N22: ='ETS Emissions'!J103 -> 98.3 | ... AQ22: ='ETS Emissions'!AM103 -> 95 | AS22: IIS*,___IIS*,ICM*,ILM*,IGF*,IGH*,___ICM*,___ILM*,___IGF*,___IGH*,IPL*,IPH*,IPP*,___IPL*,___IPH*,___IPP*,CHP*,EAUT* | AV22: =E22 -> INDCOA | AW22: ETSCO2
C23: FLO_EMIS | E23: ='ETS Emissions'!B104 -> INDCOB | F23: =AVERAGE(AD23,AH23,AI23) -> 107.46667 | G23: ='ETS Emissions'!C104 -> 110.6 | H23: ='ETS Emissions'!D104 -> 101.2 | I23: ='ETS Emissions'!E104 -> 110.6 | J23: ='ETS Emissions'!F104 -> 101.2 | K23: ='ETS Emissions'!G104 -> 101.2 | L23: ='ETS Emissions'!H104 -> 110.6 | M23: ='ETS Emissions'!I104 -> 110.6 | N23: ='ETS Emissions'!J104 -> 101.2 | ... AQ23: ='ETS Emissions'!AM104 -> 110.6 | AS23: IIS*,___IIS*,ICM*,ILM*,IGF*,IGH*,___ICM*,___ILM*,___IGF*,___IGH*,IPL*,IPH*,IPP*,___IPL*,___IPH*,___IPP*,CHP*,EAUT* | AV23: =E23 -> INDCOB | AW23: ETSCO2
C24: FLO_EMIS | E24: ='ETS Emissions'!B105 -> INDCOG | F24: =AVERAGE(AD24,AH24,AI24) -> 108.2 | G24: ='ETS Emissions'!C105 -> 108.2 | H24: ='ETS Emissions'!D105 -> 108.2 | I24: ='ETS Emissions'!E105 -> 108.2 | J24: ='ETS Emissions'!F105 -> 108.2 | K24: ='ETS Emissions'!G105 -> 108.2 | L24: ='ETS Emissions'!H105 -> 108.2 | M24: ='ETS Emissions'!I105 -> 108.2 | N24: ='ETS Emissions'!J105 -> 108.2 | ... AQ24: ='ETS Emissions'!AM105 -> 108.2 | AS24: IIS*,___IIS*,ICM*,ILM*,IGF*,IGH*,___ICM*,___ILM*,___IGF*,___IGH*,IPL*,IPH*,IPP*,___IPL*,___IPH*,___IPP*,CHP*,EAUT* | AV24: =E24 -> INDCOG | AW24: ETSCO2
C25: FLO_EMIS | E25: ='ETS Emissions'!B106 -> INDCOK | F25: =AVERAGE(AD25,AH25,AI25) -> 107.46667 | G25: ='ETS Emissions'!C106 -> 110.6 | H25: ='ETS Emissions'!D106 -> 101.2 | I25: ='ETS Emissions'!E106 -> 110.6 | J25: ='ETS Emissions'!F106 -> 101.2 | K25: ='ETS Emissions'!G106 -> 101.2 | L25: ='ETS Emissions'!H106 -> 110.6 | M25: ='ETS Emissions'!I106 -> 110.6 | N25: ='ETS Emissions'!J106 -> 101.2 | ... AQ25: ='ETS Emissions'!AM106 -> 110.6 | AS25: IIS*,___IIS*,ICM*,ILM*,IGF*,IGH*,___ICM*,___ILM*,___IGF*,___IGH*,IPL*,IPH*,IPP*,___IPL*,___IPH*,___IPP*,CHP*,EAUT* | AV25: =E25 -> INDCOK | AW25: ETSCO2
C26: FLO_EMIS | E26: ='ETS Emissions'!B107 -> INDCOL | F26: =AVERAGE(AD26,AH26,AI26) -> 101.53333 | G26: ='ETS Emissions'!C107 -> 105 | H26: ='ETS Emissions'!D107 -> 94.6 | I26: ='ETS Emissions'!E107 -> 105 | J26: ='ETS Emissions'!F107 -> 94.6 | K26: ='ETS Emissions'!G107 -> 94.6 | L26: ='ETS Emissions'!H107 -> 105 | M26: ='ETS Emissions'!I107 -> 105 | N26: ='ETS Emissions'!J107 -> 94.6 | ... AQ26: ='ETS Emissions'!AM107 -> 105 | AS26: IIS*,___IIS*,ICM*,ILM*,IGF*,IGH*,___ICM*,___ILM*,___IGF*,___IGH*,IPL*,IPH*,IPP*,___IPL*,___IPH*,___IPP*,CHP*,EAUT* | AV26: =E26 -> INDCOL | AW26: ETSCO2
C27: FLO_EMIS | E27: ='ETS Emissions'!B108 -> INDDME | F27: =AVERAGE(AD27,AH27,AI27) -> 66.420139 | G27: ='ETS Emissions'!C108 -> 66.420139 | H27: ='ETS Emissions'!D108 -> 66.420139 | I27: ='ETS Emissions'!E108 -> 66.420139 | J27: ='ETS Emissions'!F108 -> 66.420139 | K27: ='ETS Emissions'!G108 -> 66.420139 | L27: ='ETS Emissions'!H108 -> 66.420139 | M27: ='ETS Emissions'!I108 -> 66.420139 | N27: ='ETS Emissions'!J108 -> 66.420139 | ... AQ27: ='ETS Emissions'!AM108 -> 66.420139 | AS27: IIS*,___IIS*,ICM*,ILM*,IGF*,IGH*,___ICM*,___ILM*,___IGF*,___IGH*,IPL*,IPH*,IPP*,___IPL*,___IPH*,___IPP*,CHP*,EAUT* | AV27: =E27 -> INDDME | AW27: ETSCO2
C28: FLO_EMIS | E28: ='ETS Emissions'!B109 -> INDGAS | F28: =AVERAGE(AD28,AH28,AI28) -> 63.720668 | G28: ='ETS Emissions'!C109 -> 73.478546 | H28: ='ETS Emissions'!D109 -> 57.348072 | I28: ='ETS Emissions'!E109 -> 63.904669 | J28: ='ETS Emissions'!F109 -> 133.14206 | K28: ='ETS Emissions'!G109 -> 56.1 | L28: ='ETS Emissions'!H109 -> 55.231572 | M28: ='ETS Emissions'!I109 -> 63.259423 | N28: ='ETS Emissions'!J109 -> 68.289121 | ... AQ28: ='ETS Emissions'!AM109 -> 56 | AS28: IIS*,___IIS*,ICM*,ILM*,IGF*,IGH*,___ICM*,___ILM*,___IGF*,___IGH*,IPL*,IPH*,IPP*,___IPL*,___IPH*,___IPP*,CHP*,EAUT* | AV28: =E28 -> INDGAS | AW28: ETSCO2
C29: FLO_EMIS | E29: ='ETS Emissions'!B110 -> INDHFO | F29: =AVERAGE(AD29,AH29,AI29) -> 77.8 | G29: ='ETS Emissions'!C110 -> 78 | H29: ='ETS Emissions'!D110 -> 77.4 | I29: ='ETS Emissions'!E110 -> 78 | J29: ='ETS Emissions'!F110 -> 77.4 | K29: ='ETS Emissions'!G110 -> 77.4 | L29: ='ETS Emissions'!H110 -> 78 | M29: ='ETS Emissions'!I110 -> 78 | N29: ='ETS Emissions'!J110 -> 77.4 | ... AQ29: ='ETS Emissions'!AM110 -> 78 | AS29: IIS*,___IIS*,ICM*,ILM*,IGF*,IGH*,___ICM*,___ILM*,___IGF*,___IGH*,IPL*,IPH*,IPP*,___IPL*,___IPH*,___IPP*,CHP*,EAUT* | AV29: =E29 -> INDHFO | AW29: ETSCO2
C30: FLO_EMIS | E30: ='ETS Emissions'!B111 -> INDLFO | F30: =AVERAGE(AD30,AH30,AI30) -> 74.027149 | G30: ='ETS Emissions'!C111 -> 74 | H30: ='ETS Emissions'!D111 -> 74.062199 | I30: ='ETS Emissions'!E111 -> 74 | J30: ='ETS Emissions'!F111 -> 74.093574 | K30: ='ETS Emissions'!G111 -> 74.1 | L30: ='ETS Emissions'!H111 -> 74 | M30: ='ETS Emissions'!I111 -> 74 | N30: ='ETS Emissions'!J111 -> 74.087724 | ... AQ30: ='ETS Emissions'!AM111 -> 74 | AS30: IIS*,___IIS*,ICM*,ILM*,IGF*,IGH*,___ICM*,___ILM*,___IGF*,___IGH*,IPL*,IPH*,IPP*,___IPL*,___IPH*,___IPP*,CHP*,EAUT* | AV30: =E30 -> INDLFO | AW30: ETSCO2
C31: FLO_EMIS | E31: ='ETS Emissions'!B112 -> INDLPG | F31: =AVERAGE(AD31,AH31,AI31) -> 64.366667 | G31: ='ETS Emissions'!C112 -> 65 | H31: ='ETS Emissions'!D112 -> 63.1 | I31: ='ETS Emissions'!E112 -> 65 | J31: ='ETS Emissions'!F112 -> 63.1 | K31: ='ETS Emissions'!G112 -> 63.1 | L31: ='ETS Emissions'!H112 -> 65 | M31: ='ETS Emissions'!I112 -> 65 | N31: ='ETS Emissions'!J112 -> 63.1 | ... AQ31: ='ETS Emissions'!AM112 -> 65 | AS31: IIS*,___IIS*,ICM*,ILM*,IGF*,IGH*,___ICM*,___ILM*,___IGF*,___IGH*,IPL*,IPH*,IPP*,___IPL*,___IPH*,___IPP*,CHP*,EAUT* | AV31: =E31 -> INDLPG | AW31: ETSCO2
... C36: FLO_EMIS | E36: ='ETS Emissions'!B117 -> INDSLU | F36: =AVERAGE(AD36,AH36,AI36) -> 58.616667 | G36: ='ETS Emissions'!C117 -> 45 | H36: ='ETS Emissions'!D117 -> 85.85 | I36: ='ETS Emissions'!E117 -> 45 | J36: ='ETS Emissions'!F117 -> 85.85 | K36: ='ETS Emissions'!G117 -> 85.85 | L36: ='ETS Emissions'!H117 -> 45 | M36: ='ETS Emissions'!I117 -> 45 | N36: ='ETS Emissions'!J117 -> 85.85 | ... AQ36: ='ETS Emissions'!AM117 -> 45 | AS36: IIS*,___IIS*,ICM*,ILM*,IGF*,IGH*,___ICM*,___ILM*,___IGF*,___IGH*,IPL*,IPH*,IPP*,___IPL*,___IPH*,___IPP*,CHP*,EAUT* | AV36: =E36 -> INDSLU | AW36: ETSCO2
C37: *
C38: FLO_EMIS | E38: ='ETS Emissions'!B118 -> SUPBIO | F38: =AVERAGE(AD38,AH38,AI38) -> 15 | G38: ='ETS Emissions'!C118 -> 0 | H38: ='ETS Emissions'!D118 -> 0 | I38: ='ETS Emissions'!E118 -> 0 | J38: ='ETS Emissions'!F118 -> 0 | K38: ='ETS Emissions'!G118 -> 0 | L38: ='ETS Emissions'!H118 -> 0 | M38: ='ETS Emissions'!I118 -> 0 | N38: ='ETS Emissions'!J118 -> 0 | ... AQ38: ='ETS Emissions'!AM118 -> 0 | AS38: SSCDCOKE*,SSCDRFLX* | AV38: =E38 -> SUPBIO | AW38: ETSCO2
C39: FLO_EMIS | E39: ='ETS Emissions'!B119 -> SUPCOA | F39: =AVERAGE(AD39,AH39,AI39) -> 103.73923 | G39: ='ETS Emissions'!C119 -> 108.2 | H39: ='ETS Emissions'!D119 -> 98.3 | I39: ='ETS Emissions'!E119 -> 108.32 | J39: ='ETS Emissions'!F119 -> 98.3 | K39: ='ETS Emissions'!G119 -> 98.3 | L39: ='ETS Emissions'!H119 -> 108.26316 | M39: ='ETS Emissions'!I119 -> 108.71132 | N39: ='ETS Emissions'!J119 -> 98.3 | ... AQ39: ='ETS Emissions'!AM119 -> 95 | AS39: SSCDCOKE*,SSCDRFLX* | AV39: =E39 -> SUPCOA | AW39: ETSCO2
C40: FLO_EMIS | E40: ='ETS Emissions'!B121 -> SUPGAS | F40: =AVERAGE(AD40,AH40,AI40) -> 0 | G40: ='ETS Emissions'!C121 -> 0 | H40: ='ETS Emissions'!D121 -> 0 | I40: ='ETS Emissions'!E121 -> 0 | J40: ='ETS Emissions'!F121 -> 0 | K40: ='ETS Emissions'!G121 -> 0 | L40: ='ETS Emissions'!H121 -> 3.4875 | M40: ='ETS Emissions'!I121 -> 0 | N40: ='ETS Emissions'!J121 -> 0 | ... AQ40: ='ETS Emissions'!AM121 -> 0 | AS40: SSCDCOKE*,SSCDRFLX* | AV40: =E40 -> SUPGAS | AW40: ETSCO2
C41: FLO_EMIS | E41: ='ETS Emissions'!B122 -> SUPRPG | F41: =AVERAGE(AD41,AH41,AI41) -> 59.05343 | G41: ='ETS Emissions'!C122 -> 60.59081 | H41: ='ETS Emissions'!D122 -> 56.420988 | I41: ='ETS Emissions'!E122 -> 65.064686 | J41: ='ETS Emissions'!F122 -> 70.986937 | K41: ='ETS Emissions'!G122 -> 56.1 | L41: ='ETS Emissions'!H122 -> 60 | M41: ='ETS Emissions'!I122 -> 60.541943 | N41: ='ETS Emissions'!J122 -> 57.520025 | ... AQ41: ='ETS Emissions'!AM122 -> 60 | AS41: SSCDCOKE*,SSCDRFLX* | AV41: =E41 -> SUPRPG | AW41: ETSCO2
C42: FLO_EMIS | E42: ='ETS Emissions'!B123 -> SUPRPP | F42: =AVERAGE(AD42,AH42,AI42) -> 172.20319 | G42: ='ETS Emissions'!C123 -> 85.122385 | H42: ='ETS Emissions'!D123 -> 89.602609 | I42: ='ETS Emissions'!E123 -> 78 | J42: ='ETS Emissions'!F123 -> 111.14766 | K42: ='ETS Emissions'!G123 -> 77.4 | L42: ='ETS Emissions'!H123 -> 119.4341 | M42: ='ETS Emissions'!I123 -> 88.399165 | N42: ='ETS Emissions'!J123 -> 105.46934 | ... AQ42: ='ETS Emissions'!AM123 -> 78 | AS42: SSCDCOKE*,SSCDRFLX* | AV42: =E42 -> SUPRPP | AW42: ETSCO2
C45: FLO_EMIS | E45: =AV45 -> P2LDST_FOS | F45: 74.1 | G45: =$F45 -> 74.1 | H45: =$F45 -> 74.1 | I45: =$F45 -> 74.1 | J45: =$F45 -> 74.1 | K45: =$F45 -> 74.1 | L45: =$F45 -> 74.1 | M45: =$F45 -> 74.1 | N45: =$F45 -> 74.1 | ... AQ45: =$F45 -> 74.1 | AS45: BLD_RFNBO_NAV | AV45: P2LDST_FOS | AW45: ETSCO2
C46: FLO_EMIS | E46: =AV46 -> SYNDST | F46: 74.1 | G46: =$F46 -> 74.1 | H46: =$F46 -> 74.1 | I46: =$F46 -> 74.1 | J46: =$F46 -> 74.1 | K46: =$F46 -> 74.1 | L46: =$F46 -> 74.1 | M46: =$F46 -> 74.1 | N46: =$F46 -> 74.1 | ... AQ46: =$F46 -> 74.1 | AS46: BLD_RFNBO_NAV | AV46: SYNDST | AW46: ETSCO2
C47: FLO_EMIS | E47: =AV47 -> BIONAV | F47: 0 | G47: =$F47 -> 0 | H47: 0 | I47: =$F47 -> 0 | J47: 0 | K47: =$F47 -> 0 | L47: 0 | M47: =$F47 -> 0 | N47: 0 | O47: =$F47 -> 0 | P47: 0 | Q47: =$F47 -> 0 | R47: 0 | S47: =$F47 -> 0 | T47: 0 | U47: =$F47 -> 0 | V47: 0 | W47: =$F47 -> 0 | X47: 0 | Y47: =$F47 -> 0 | Z47: 0 | AA47: =$F47 -> 0 | AB47: 0 | AC47: =$F47 -> 0 | AD47: 0 | AE47: =$F47 -> 0 | AF47: 0 | AG47: =$F47 -> 0 | AH47: 0 | AI47: =$F47 -> 0 | AJ47: 0 | AK47: =$F47 -> 0 | AL47: 0 | AM47: =$F47 -> 0 | AN47: 0 | AO47: =$F47 -> 0 | AP47: 0 | AQ47: =$F47 -> 0 | AS47: TRALFO00 | AV47: BIONAV | AW47: ETSCO2
...

Sheet Biofuel 2nd with CCS
L1: kt/PJ
F2: MJ/kg | G2: PJ | H2: kt carbon | I2: kt CO2 | J2: Captured CO2 | L2: Emission factor wood
B3: BRF2_ETHLGC | C3: Wood | D3: 4.3 | E3: kt | F3: 18 | G3: =D3*F3/1000 -> 0.0774 | H3: =D3*0.5 -> 2.15 | I3: =H3*44/12 -> 7.8833333 | J3: =I3-I4 -> 5.9805333 | L3: =I3/G3 -> 101.85185
C4: Ethanol | D4: 1 | E4: kt | F4: 26.8 | G4: =D4*F4/1000 -> 0.0268 | H4: =I4/(44/12) -> 0.51894545 | I4: =71*G4 -> 1.9028 | L4: =I4/G4 -> 71
D5: =D4/D3 -> 0.23255814 | G5: =G4/G3 -> 0.34625323 | I5: =I4/I3 -> 0.24136998
F7: MJ/kg | G7: PJ | H7: kt carbon | I7: kt CO2 | J7: Captured CO2
B8: BRF2_BTLFTDSL | C8: Wood | D8: 5 | E8: kt | F8: 18 | G8: =D8*F8/1000 -> 0.09 | H8: =D8*0.5 -> 2.5 | I8: =H8*44/12 -> 9.1666667 | J8: =I8-I9 -> 6.3320267 | L8: =I8/G8 -> 101.85185
C9: FT Diesel | D9: 1 | E9: kt | F9: 37.2 | G9: =D9*F9/1000 -> 0.0372 | H9: =I9/(44/12) -> 0.77308364 | I9: =76.2*G9 -> 2.83464 | L9: =I9/G9 -> 76.2
D10: =D9/D8 -> 0.2 | G10: =G9/G8 -> 0.41333333 | I10: =I9/I8 -> 0.30923345

Sheet Negative Emissions
D5: ~TFM_INS
D6: TimeSlice | E6: LimType | F6: Attribute | G6: Year | H6: AllRegions | I6: Pset_Set | J6: Pset_PN | K6: Cset_CN
D7: ANNUAL | E7: N | F7: COM_BNDNET | G7: 0 | H7: -1 | K7: ELCCO2N,ETSCO2,SUPCO2N,TOTCO2
